Workbook

Sheet Base Option
A1: Roofing Contract
A2: Attachment J-0200000-05
A3: Exhibit Line Item Numbers
A4: Solicitation/Contract No.: N40085-26-D-XXXX
A5: ELIN Number | B5: Supplies/Services | C5: Est. Quantity | D5: Unit | F5: Unit Price | G5: Total
B6: ROOF DECKS
A7: A0001 | B7: Remove existing metal roof decks (ALL OR PARTIAL) and replace with new steel roof decking, shall include all closures and accessories. | C7: 200 | D7: SQ | E7: X | G7: =F7*C7 -> 0
B8: Remove existing wood roof deck and replace with new wood decking
A9: A0002 | B9: 1" nominal T & G (treated) | C9: 1200 | D9: BF | E9: X | G9: =F9*C9 -> 0
A10: A0003 | B10: 2" nominal T & G (treated) | C10: 1200 | D10: BF | E10: X | G10: =F10*C10 -> 0
A11: A0004 | B11: 3/4" plywood | C11: 1200 | D11: SF | E11: X | G11: =F11*C11 -> 0
A12: A0005 | B12: 1/2" plywood | C12: 1200 | D12: SF | E12: X | G12: =F12*C12 -> 0
B13: ROOF INSULATION
B14: Remove and replace rigid roof insulation in conjunction with roofing systems specified herein.
A15: A0006 | B15: Remove and replace polyisocyanurate tapered insulation panels | C15: 120 | D15: SQ | E15: X | G15: =F15*C15 -> 0
A16: A0007 | B16: Remove and replace tapered roof insulation | C16: 120 | D16: SQ | E16: X | G16: =F16*C16 -> 0
A17: A0008 | B17: Remove and replace vapor barrier in conjunction with built up roofing system | C17: 120 | D17: SQ | E17: X | G17: =F17*C17 -> 0
A18: A0009 | B18: Remove and replace resin sized building paper (5 lb) | C18: 15 | D18: SQ | E18: X | G18: =F18*C18 -> 0
A19: A0010 | B19: Remove existing cants and replace with new fiberboard cants 4 x 4 | C19: 30 | D19: LF | E19: X | G19: =F19*C19 -> 0
A20: A0011 | B20: Remove existing cants and replace with new treated wood cants 4 x 4 | C20: 90 | D20: LF | E20: X | G20: =F20*C20 -> 0
A21: A0012 | B21: Remove existing Nailers and replace with new treated 2" x 6" wood | C21: 300 | D21: BF | E21: X | G21: =F21*C21 -> 0
B22: SHINGLED ROOF SYSTEMS
B23: Remove existing composition shingles and replace with new composition shingles, shall include starter
A24: A0013 | B24: Twenty Five Year (3 tab ) | C24: 100 | D24: SQ | E24: X | G24: =F24*C24 -> 0
A25: A0014 | B25: Thirty Year (architectural) | C25: 100 | D25: SQ | E25: X | G25: =F25*C25 -> 0
A26: A0015 | B26: Forty Year (architectural) | C26: 100 | D26: SQ | E26: X | G26: =F26*C26 -> 0
A27: A0016 | B27: Remove and dispose of existing composition shingles (all types)(where new shingles are not going to be installed) | C27: 18 | D27: SQ | E27: X | G27: =F27*C27 -> 0
A28: A0017 | B28: Remove and dispose of existing slate shingles. | C28: 18 | D28: SQ | E28: X | G28: =F28*C28 -> 0
A29: A0018 | B29: Remove and re-install existing slate shingles (All or Partial) | C29: 6 | D29: SQ | E29: X | G29: =F29*C29 -> 0
A30: A0019 | B30: Install new slate shingles (Weathering green, Vermont)(All or Partial) | C30: 9 | D30: SQ | E30: X | G30: =F30*C30 -> 0
A31: A0020 | B31: Install new slate shingles (Buckingham)(All or Partial) | C31: 9 | D31: SQ | E31: X | G31: =F31*C31 -> 0
B32: Remove existing preformed metal (All or Partial) roofing and replace with new preformed metal roofing
A33: A0021 | B33: Coated steel | C33: 20 | D33: SQ | E33: X | G33: =F33*C33 -> 0
A34: A0022 | B34: Coated aluminum | C34: 20 | D34: SQ | E34: X | G34: =F34*C34 -> 0
B35: ROOF COATING (ALUMINUM PIGMENTED FIBERED BITUMINOUS ROOF COATING)
A36: A0023 | B36: Coat roofing with aluminum pigmented slate shingles (All or Partial) slate shingles (All or Partial) fibered bitumen roof coating | C36: 100 | D36: SQ | E36: X | G36: =F36*C36 -> 0
B37: Field paint roof mounted equipment
A38: A0024 | B38: Up to 25 SF X in surface area X | C38: 100 | D38: SF | E38: X | G38: =F38*C38 -> 0
A39: A0025 | B39: Over 25 SF X in surface area X | C39: 100 | D39: SF | E39: X | G39: =F39*C39 -> 0
B40: BUILT UP ROOF
...

Sheet Option 1
A1: Roofing Contract
A2: Attachment J-0200000-05
A3: Exhibit Line Item Numbers
A4: Solicitation/Contract No.: N40085-26-D-XXXX
A5: ELIN Number | B5: Supplies/Services | C5: Est. Quantity | D5: Unit | F5: Unit Price | G5: Total
B6: ROOF DECKS
A7: A0001 | B7: Remove existing metal roof decks (ALL OR PARTIAL) and replace with new steel roof decking, shall include all closures and accessories. | C7: 200 | D7: SQ | E7: X | G7: =F7*C7 -> 0
B8: Remove existing wood roof deck and replace with new wood decking
A9: A0002 | B9: 1" nominal T & G (treated) | C9: 1200 | D9: BF | E9: X | G9: =F9*C9 -> 0
A10: A0003 | B10: 2" nominal T & G (treated) | C10: 1200 | D10: BF | E10: X | G10: =F10*C10 -> 0
A11: A0004 | B11: 3/4" plywood | C11: 1200 | D11: SF | E11: X | G11: =F11*C11 -> 0
A12: A0005 | B12: 1/2" plywood | C12: 1200 | D12: SF | E12: X | G12: =F12*C12 -> 0
B13: ROOF INSULATION
B14: Remove and replace rigid roof insulation in conjunction with roofing systems specified herein.
A15: A0006 | B15: Remove and replace polyisocyanurate tapered insulation panels | C15: 120 | D15: SQ | E15: X | G15: =F15*C15 -> 0
A16: A0007 | B16: Remove and replace tapered roof insulation | C16: 120 | D16: SQ | E16: X | G16: =F16*C16 -> 0
A17: A0008 | B17: Remove and replace vapor barrier in conjunction with built up roofing system | C17: 120 | D17: SQ | E17: X | G17: =F17*C17 -> 0
A18: A0009 | B18: Remove and replace resin sized building paper (5 lb) | C18: 15 | D18: SQ | E18: X | G18: =F18*C18 -> 0
A19: A0010 | B19: Remove existing cants and replace with new fiberboard cants 4 x 4 | C19: 30 | D19: LF | E19: X | G19: =F19*C19 -> 0
A20: A0011 | B20: Remove existing cants and replace with new treated wood cants 4 x 4 | C20: 90 | D20: LF | E20: X | G20: =F20*C20 -> 0
A21: A0012 | B21: Remove existing Nailers and replace with new treated 2" x 6" wood | C21: 300 | D21: BF | E21: X | G21: =F21*C21 -> 0
B22: SHINGLED ROOF SYSTEMS
B23: Remove existing composition shingles and replace with new composition shingles, shall include starter
A24: A0013 | B24: Twenty Five Year (3 tab ) | C24: 100 | D24: SQ | E24: X | G24: =F24*C24 -> 0
A25: A0014 | B25: Thirty Year (architectural) | C25: 100 | D25: SQ | E25: X | G25: =F25*C25 -> 0
A26: A0015 | B26: Forty Year (architectural) | C26: 100 | D26: SQ | E26: X | G26: =F26*C26 -> 0
A27: A0016 | B27: Remove and dispose of existing composition shingles (all types)(where new shingles are not going to be installed) | C27: 18 | D27: SQ | E27: X | G27: =F27*C27 -> 0
A28: A0017 | B28: Remove and dispose of existing slate shingles. | C28: 18 | D28: SQ | E28: X | G28: =F28*C28 -> 0
A29: A0018 | B29: Remove and re-install existing slate shingles (All or Partial) | C29: 6 | D29: SQ | E29: X | G29: =F29*C29 -> 0
A30: A0019 | B30: Install new slate shingles (Weathering green, Vermont)(All or Partial) | C30: 9 | D30: SQ | E30: X | G30: =F30*C30 -> 0
A31: A0020 | B31: Install new slate shingles (Buckingham)(All or Partial) | C31: 9 | D31: SQ | E31: X | G31: =F31*C31 -> 0
B32: Remove existing preformed metal (All or Partial) roofing and replace with new preformed metal roofing
A33: A0021 | B33: Coated steel | C33: 20 | D33: SQ | E33: X | G33: =F33*C33 -> 0
A34: A0022 | B34: Coated aluminum | C34: 20 | D34: SQ | E34: X | G34: =F34*C34 -> 0
B35: ROOF COATING (ALUMINUM PIGMENTED FIBERED BITUMINOUS ROOF COATING)
A36: A0023 | B36: Coat roofing with aluminum pigmented slate shingles (All or Partial) slate shingles (All or Partial) fibered bitumen roof coating | C36: 100 | D36: SQ | E36: X | G36: =F36*C36 -> 0
B37: Field paint roof mounted equipment
A38: A0024 | B38: Up to 25 SF X in surface area X | C38: 100 | D38: SF | E38: X | G38: =F38*C38 -> 0
A39: A0025 | B39: Over 25 SF X in surface area X | C39: 100 | D39: SF | E39: X | G39: =F39*C39 -> 0
B40: BUILT UP ROOF
...

Sheet Option 2
A1: Roofing Contract
A2: Attachment J-0200000-05
A3: Exhibit Line Item Numbers
A4: Solicitation/Contract No.: N40085-26-D-XXXX
A5: ELIN Number | B5: Supplies/Services | C5: Est. Quantity | D5: Unit | F5: Unit Price | G5: Total
B6: ROOF DECKS
A7: A0001 | B7: Remove existing metal roof decks (ALL OR PARTIAL) and replace with new steel roof decking, shall include all closures and accessories. | C7: 200 | D7: SQ | E7: X | G7: =F7*C7 -> 0
B8: Remove existing wood roof deck and replace with new wood decking
A9: A0002 | B9: 1" nominal T & G (treated) | C9: 1200 | D9: BF | E9: X | G9: =F9*C9 -> 0
A10: A0003 | B10: 2" nominal T & G (treated) | C10: 1200 | D10: BF | E10: X | G10: =F10*C10 -> 0
A11: A0004 | B11: 3/4" plywood | C11: 1200 | D11: SF | E11: X | G11: =F11*C11 -> 0
A12: A0005 | B12: 1/2" plywood | C12: 1200 | D12: SF | E12: X | G12: =F12*C12 -> 0
B13: ROOF INSULATION
B14: Remove and replace rigid roof insulation in conjunction with roofing systems specified herein.
A15: A0006 | B15: Remove and replace polyisocyanurate tapered insulation panels | C15: 120 | D15: SQ | E15: X | G15: =F15*C15 -> 0
A16: A0007 | B16: Remove and replace tapered roof insulation | C16: 120 | D16: SQ | E16: X | G16: =F16*C16 -> 0
A17: A0008 | B17: Remove and replace vapor barrier in conjunction with built up roofing system | C17: 120 | D17: SQ | E17: X | G17: =F17*C17 -> 0
A18: A0009 | B18: Remove and replace resin sized building paper (5 lb) | C18: 15 | D18: SQ | E18: X | G18: =F18*C18 -> 0
A19: A0010 | B19: Remove existing cants and replace with new fiberboard cants 4 x 4 | C19: 30 | D19: LF | E19: X | G19: =F19*C19 -> 0
A20: A0011 | B20: Remove existing cants and replace with new treated wood cants 4 x 4 | C20: 90 | D20: LF | E20: X | G20: =F20*C20 -> 0
A21: A0012 | B21: Remove existing Nailers and replace with new treated 2" x 6" wood | C21: 300 | D21: BF | E21: X | G21: =F21*C21 -> 0
B22: SHINGLED ROOF SYSTEMS
B23: Remove existing composition shingles and replace with new composition shingles, shall include starter
A24: A0013 | B24: Twenty Five Year (3 tab ) | C24: 100 | D24: SQ | E24: X | G24: =F24*C24 -> 0
A25: A0014 | B25: Thirty Year (architectural) | C25: 100 | D25: SQ | E25: X | G25: =F25*C25 -> 0
A26: A0015 | B26: Forty Year (architectural) | C26: 100 | D26: SQ | E26: X | G26: =F26*C26 -> 0
A27: A0016 | B27: Remove and dispose of existing composition shingles (all types)(where new shingles are not going to be installed) | C27: 18 | D27: SQ | E27: X | G27: =F27*C27 -> 0
A28: A0017 | B28: Remove and dispose of existing slate shingles. | C28: 18 | D28: SQ | E28: X | G28: =F28*C28 -> 0
A29: A0018 | B29: Remove and re-install existing slate shingles (All or Partial) | C29: 6 | D29: SQ | E29: X | G29: =F29*C29 -> 0
A30: A0019 | B30: Install new slate shingles (Weathering green, Vermont)(All or Partial) | C30: 9 | D30: SQ | E30: X | G30: =F30*C30 -> 0
A31: A0020 | B31: Install new slate shingles (Buckingham)(All or Partial) | C31: 9 | D31: SQ | E31: X | G31: =F31*C31 -> 0
B32: Remove existing preformed metal (All or Partial) roofing and replace with new preformed metal roofing
A33: A0021 | B33: Coated steel | C33: 20 | D33: SQ | E33: X | G33: =F33*C33 -> 0
A34: A0022 | B34: Coated aluminum | C34: 20 | D34: SQ | E34: X | G34: =F34*C34 -> 0
B35: ROOF COATING (ALUMINUM PIGMENTED FIBERED BITUMINOUS ROOF COATING)
A36: A0023 | B36: Coat roofing with aluminum pigmented slate shingles (All or Partial) slate shingles (All or Partial) fibered bitumen roof coating | C36: 100 | D36: SQ | E36: X | G36: =F36*C36 -> 0
B37: Field paint roof mounted equipment
A38: A0024 | B38: Up to 25 SF X in surface area X | C38: 100 | D38: SF | E38: X | G38: =F38*C38 -> 0
A39: A0025 | B39: Over 25 SF X in surface area X | C39: 100 | D39: SF | E39: X | G39: =F39*C39 -> 0
B40: BUILT UP ROOF
...

Sheet Option 3
A1: Roofing Contract
A2: Attachment J-0200000-05
A3: Exhibit Line Item Numbers
A4: Solicitation/Contract No.: N40085-26-D-XXXX
A5: ELIN Number | B5: Supplies/Services | C5: Est. Quantity | D5: Unit | F5: Unit Price | G5: Total
B6: ROOF DECKS
A7: A0001 | B7: Remove existing metal roof decks (ALL OR PARTIAL) and replace with new steel roof decking, shall include all closures and accessories. | C7: 200 | D7: SQ | E7: X | G7: =F7*C7 -> 0
B8: Remove existing wood roof deck and replace with new wood decking
A9: A0002 | B9: 1" nominal T & G (treated) | C9: 1200 | D9: BF | E9: X | G9: =F9*C9 -> 0
A10: A0003 | B10: 2" nominal T & G (treated) | C10: 1200 | D10: BF | E10: X | G10: =F10*C10 -> 0
A11: A0004 | B11: 3/4" plywood | C11: 1200 | D11: SF | E11: X | G11: =F11*C11 -> 0
A12: A0005 | B12: 1/2" plywood | C12: 1200 | D12: SF | E12: X | G12: =F12*C12 -> 0
B13: ROOF INSULATION
B14: Remove and replace rigid roof insulation in conjunction with roofing systems specified herein.
A15: A0006 | B15: Remove and replace polyisocyanurate tapered insulation panels | C15: 120 | D15: SQ | E15: X | G15: =F15*C15 -> 0
A16: A0007 | B16: Remove and replace tapered roof insulation | C16: 120 | D16: SQ | E16: X | G16: =F16*C16 -> 0
A17: A0008 | B17: Remove and replace vapor barrier in conjunction with built up roofing system | C17: 120 | D17: SQ | E17: X | G17: =F17*C17 -> 0
A18: A0009 | B18: Remove and replace resin sized building paper (5 lb) | C18: 15 | D18: SQ | E18: X | G18: =F18*C18 -> 0
A19: A0010 | B19: Remove existing cants and replace with new fiberboard cants 4 x 4 | C19: 30 | D19: LF | E19: X | G19: =F19*C19 -> 0
A20: A0011 | B20: Remove existing cants and replace with new treated wood cants 4 x 4 | C20: 90 | D20: LF | E20: X | G20: =F20*C20 -> 0
A21: A0012 | B21: Remove existing Nailers and replace with new treated 2" x 6" wood | C21: 300 | D21: BF | E21: X | G21: =F21*C21 -> 0
B22: SHINGLED ROOF SYSTEMS
B23: Remove existing composition shingles and replace with new composition shingles, shall include starter
A24: A0013 | B24: Twenty Five Year (3 tab ) | C24: 100 | D24: SQ | E24: X | G24: =F24*C24 -> 0
A25: A0014 | B25: Thirty Year (architectural) | C25: 100 | D25: SQ | E25: X | G25: =F25*C25 -> 0
A26: A0015 | B26: Forty Year (architectural) | C26: 100 | D26: SQ | E26: X | G26: =F26*C26 -> 0
A27: A0016 | B27: Remove and dispose of existing composition shingles (all types)(where new shingles are not going to be installed) | C27: 18 | D27: SQ | E27: X | G27: =F27*C27 -> 0
A28: A0017 | B28: Remove and dispose of existing slate shingles. | C28: 18 | D28: SQ | E28: X | G28: =F28*C28 -> 0
A29: A0018 | B29: Remove and re-install existing slate shingles (All or Partial) | C29: 6 | D29: SQ | E29: X | G29: =F29*C29 -> 0
A30: A0019 | B30: Install new slate shingles (Weathering green, Vermont)(All or Partial) | C30: 9 | D30: SQ | E30: X | G30: =F30*C30 -> 0
A31: A0020 | B31: Install new slate shingles (Buckingham)(All or Partial) | C31: 9 | D31: SQ | E31: X | G31: =F31*C31 -> 0
B32: Remove existing preformed metal (All or Partial) roofing and replace with new preformed metal roofing
A33: A0021 | B33: Coated steel | C33: 20 | D33: SQ | E33: X | G33: =F33*C33 -> 0
A34: A0022 | B34: Coated aluminum | C34: 20 | D34: SQ | E34: X | G34: =F34*C34 -> 0
B35: ROOF COATING (ALUMINUM PIGMENTED FIBERED BITUMINOUS ROOF COATING)
A36: A0023 | B36: Coat roofing with aluminum pigmented slate shingles (All or Partial) slate shingles (All or Partial) fibered bitumen roof coating | C36: 100 | D36: SQ | E36: X | G36: =F36*C36 -> 0
B37: Field paint roof mounted equipment
A38: A0024 | B38: Up to 25 SF X in surface area X | C38: 100 | D38: SF | E38: X | G38: =F38*C38 -> 0
A39: A0025 | B39: Over 25 SF X in surface area X | C39: 100 | D39: SF | E39: X | G39: =F39*C39 -> 0
B40: BUILT UP ROOF
...

Sheet Option 4
A1: Roofing Contract
A2: Attachment J-0200000-05
A3: Exhibit Line Item Numbers
A4: Solicitation/Contract No.: N40085-26-D-XXXX
A5: ELIN Number | B5: Supplies/Services | C5: Est. Quantity | D5: Unit | F5: Unit Price | G5: Total
B6: ROOF DECKS
A7: A0001 | B7: Remove existing metal roof decks (ALL OR PARTIAL) and replace with new steel roof decking, shall include all closures and accessories. | C7: 200 | D7: SQ | E7: X | G7: =F7*C7 -> 0
B8: Remove existing wood roof deck and replace with new wood decking
A9: A0002 | B9: 1" nominal T & G (treated) | C9: 1200 | D9: BF | E9: X | G9: =F9*C9 -> 0
A10: A0003 | B10: 2" nominal T & G (treated) | C10: 1200 | D10: BF | E10: X | G10: =F10*C10 -> 0
A11: A0004 | B11: 3/4" plywood | C11: 1200 | D11: SF | E11: X | G11: =F11*C11 -> 0
A12: A0005 | B12: 1/2" plywood | C12: 1200 | D12: SF | E12: X | G12: =F12*C12 -> 0
B13: ROOF INSULATION
B14: Remove and replace rigid roof insulation in conjunction with roofing systems specified herein.
A15: A0006 | B15: Remove and replace polyisocyanurate tapered insulation panels | C15: 120 | D15: SQ | E15: X | G15: =F15*C15 -> 0
A16: A0007 | B16: Remove and replace tapered roof insulation | C16: 120 | D16: SQ | E16: X | G16: =F16*C16 -> 0
A17: A0008 | B17: Remove and replace vapor barrier in conjunction with built up roofing system | C17: 120 | D17: SQ | E17: X | G17: =F17*C17 -> 0
A18: A0009 | B18: Remove and replace resin sized building paper (5 lb) | C18: 15 | D18: SQ | E18: X | G18: =F18*C18 -> 0
A19: A0010 | B19: Remove existing cants and replace with new fiberboard cants 4 x 4 | C19: 30 | D19: LF | E19: X | G19: =F19*C19 -> 0
A20: A0011 | B20: Remove existing cants and replace with new treated wood cants 4 x 4 | C20: 90 | D20: LF | E20: X | G20: =F20*C20 -> 0
A21: A0012 | B21: Remove existing Nailers and replace with new treated 2" x 6" wood | C21: 300 | D21: BF | E21: X | G21: =F21*C21 -> 0
B22: SHINGLED ROOF SYSTEMS
B23: Remove existing composition shingles and replace with new composition shingles, shall include starter
A24: A0013 | B24: Twenty Five Year (3 tab ) | C24: 100 | D24: SQ | E24: X | G24: =F24*C24 -> 0
A25: A0014 | B25: Thirty Year (architectural) | C25: 100 | D25: SQ | E25: X | G25: =F25*C25 -> 0
A26: A0015 | B26: Forty Year (architectural) | C26: 100 | D26: SQ | E26: X | G26: =F26*C26 -> 0
A27: A0016 | B27: Remove and dispose of existing composition shingles (all types)(where new shingles are not going to be installed) | C27: 18 | D27: SQ | E27: X | G27: =F27*C27 -> 0
A28: A0017 | B28: Remove and dispose of existing slate shingles. | C28: 18 | D28: SQ | E28: X | G28: =F28*C28 -> 0
A29: A0018 | B29: Remove and re-install existing slate shingles (All or Partial) | C29: 6 | D29: SQ | E29: X | G29: =F29*C29 -> 0
A30: A0019 | B30: Install new slate shingles (Weathering green, Vermont)(All or Partial) | C30: 9 | D30: SQ | E30: X | G30: =F30*C30 -> 0
A31: A0020 | B31: Install new slate shingles (Buckingham)(All or Partial) | C31: 9 | D31: SQ | E31: X | G31: =F31*C31 -> 0
B32: Remove existing preformed metal (All or Partial) roofing and replace with new preformed metal roofing
A33: A0021 | B33: Coated steel | C33: 20 | D33: SQ | E33: X | G33: =F33*C33 -> 0
A34: A0022 | B34: Coated aluminum | C34: 20 | D34: SQ | E34: X | G34: =F34*C34 -> 0
B35: ROOF COATING (ALUMINUM PIGMENTED FIBERED BITUMINOUS ROOF COATING)
A36: A0023 | B36: Coat roofing with aluminum pigmented slate shingles (All or Partial) slate shingles (All or Partial) fibered bitumen roof coating | C36: 100 | D36: SQ | E36: X | G36: =F36*C36 -> 0
B37: Field paint roof mounted equipment
A38: A0024 | B38: Up to 25 SF X in surface area X | C38: 100 | D38: SF | E38: X | G38: =F38*C38 -> 0
A39: A0025 | B39: Over 25 SF X in surface area X | C39: 100 | D39: SF | E39: X | G39: =F39*C39 -> 0
B40: BUILT UP ROOF
...

Sheet Summary
B2: Roofing Summary
B3: Base Option | D3: ='Base Option'!G182 -> 0
B4: Option Year 1 | D4: ='Option 1'!G182 -> 0
B5: Option Year 2 | D5: ='Option 2'!G182 -> 0
B6: Option year 3 | D6: ='Option 3'!G182 -> 0
B7: Option Year 4 | D7: ='Option 4'!G182 -> 0
B8: Total | D8: =D3+D4+D5+D6+D7 -> 0
