Workbook

Sheet 42-2A Dual - BIG 4
A1: Product Information | Q1: MFC Information | T1: Tracking Customer Information | W1: FSS Information | Z1: FCP Information
A2: SIN# | B2: NDC 1 | C2: NDC2 (4 digits only - Add leading 0, if necessary) | D2: NDC3 | E2: Type "YES" if item is handled by Specialty Distrib. | F2: Generic Name / Strength | G2: Trade Name / Strength | H2: Package Size | I2: Unit of Sale | J2: Quantity in Unit of Sale | K2: Unit Pkg | L2: Quantity in Unit Package | M2: Unit of Measure | N2: FDA Application Number | O2: Country of Origin (See Country Codes Tab) | P2: Commercial List Price ($) | Q2: MFC Price ($) | R2: MFC % Off Comm. List Price | S2: MFC Name | T2: Proposed Tracking Customer (TC) Name | U2: Proposed TC Price ($) | V2: TC % Off Comm. List Price | W2: Proposed BIG 4 Price ($) without IFF | X2: Proposed BIG 4 % Off Comm. List Price w/out IFF | Y2: Proposed BIG 4 Price ($) with IFF | Z2: FCP Price ($) | AA2: Is Proposed Gov't Price w/out IFF Less Than or Equal to FCP?
R3: =IF(ISBLANK(P3)," ",((ROUND(Q3,2)-(ROUND(P3,2)))/(ROUND(P3,2)))) | V3: =IF(ISBLANK(P3)," ",((ROUND(U3,2)-(ROUND(P3,2)))/(ROUND(P3,2)))) | X3: =IF(ISBLANK(P3)," ",((ROUND(W3,2)-(ROUND(P3,2)))/(ROUND(P3,2)))) | Y3: =IF(ISBLANK(W3)," ",(ROUND(W3,2)/0.995)) | AA3: =IF(ISBLANK(W3)," ",IF((ROUND(W3,2))<=(ROUND(Z3,2)),"YES","NO"))
R4: =IF(ISBLANK(P4)," ",((ROUND(Q4,2)-(ROUND(P4,2)))/(ROUND(P4,2)))) | V4: =IF(ISBLANK(P4)," ",((ROUND(U4,2)-(ROUND(P4,2)))/(ROUND(P4,2)))) | X4: =IF(ISBLANK(P4)," ",((ROUND(W4,2)-(ROUND(P4,2)))/(ROUND(P4,2)))) | Y4: =IF(ISBLANK(W4)," ",(ROUND(W4,2)/0.995)) | AA4: =IF(ISBLANK(W4)," ",IF((ROUND(W4,2))<=(ROUND(Z4,2)),"YES","NO"))
R5: =IF(ISBLANK(P5)," ",((ROUND(Q5,2)-(ROUND(P5,2)))/(ROUND(P5,2)))) | V5: =IF(ISBLANK(P5)," ",((ROUND(U5,2)-(ROUND(P5,2)))/(ROUND(P5,2)))) | X5: =IF(ISBLANK(P5)," ",((ROUND(W5,2)-(ROUND(P5,2)))/(ROUND(P5,2)))) | Y5: =IF(ISBLANK(W5)," ",(ROUND(W5,2)/0.995)) | AA5: =IF(ISBLANK(W5)," ",IF((ROUND(W5,2))<=(ROUND(Z5,2)),"YES","NO"))
R6: =IF(ISBLANK(P6)," ",((ROUND(Q6,2)-(ROUND(P6,2)))/(ROUND(P6,2)))) | V6: =IF(ISBLANK(P6)," ",((ROUND(U6,2)-(ROUND(P6,2)))/(ROUND(P6,2)))) | X6: =IF(ISBLANK(P6)," ",((ROUND(W6,2)-(ROUND(P6,2)))/(ROUND(P6,2)))) | Y6: =IF(ISBLANK(W6)," ",(ROUND(W6,2)/0.995)) | AA6: =IF(ISBLANK(W6)," ",IF((ROUND(W6,2))<=(ROUND(Z6,2)),"YES","NO"))
R7: =IF(ISBLANK(P7)," ",((ROUND(Q7,2)-(ROUND(P7,2)))/(ROUND(P7,2)))) | V7: =IF(ISBLANK(P7)," ",((ROUND(U7,2)-(ROUND(P7,2)))/(ROUND(P7,2)))) | X7: =IF(ISBLANK(P7)," ",((ROUND(W7,2)-(ROUND(P7,2)))/(ROUND(P7,2)))) | Y7: =IF(ISBLANK(W7)," ",(ROUND(W7,2)/0.995)) | AA7: =IF(ISBLANK(W7)," ",IF((ROUND(W7,2))<=(ROUND(Z7,2)),"YES","NO")) | AO7: 42-2a | AP7: AM | AQ7: EA
R8: =IF(ISBLANK(P8)," ",((ROUND(Q8,2)-(ROUND(P8,2)))/(ROUND(P8,2)))) | V8: =IF(ISBLANK(P8)," ",((ROUND(U8,2)-(ROUND(P8,2)))/(ROUND(P8,2)))) | X8: =IF(ISBLANK(P8)," ",((ROUND(W8,2)-(ROUND(P8,2)))/(ROUND(P8,2)))) | Y8: =IF(ISBLANK(W8)," ",(ROUND(W8,2)/0.995)) | AA8: =IF(ISBLANK(W8)," ",IF((ROUND(W8,2))<=(ROUND(Z8,2)),"YES","NO")) | AP8: BG | AQ8: F2
R9: =IF(ISBLANK(P9)," ",((ROUND(Q9,2)-(ROUND(P9,2)))/(ROUND(P9,2)))) | V9: =IF(ISBLANK(P9)," ",((ROUND(U9,2)-(ROUND(P9,2)))/(ROUND(P9,2)))) | X9: =IF(ISBLANK(P9)," ",((ROUND(W9,2)-(ROUND(P9,2)))/(ROUND(P9,2)))) | Y9: =IF(ISBLANK(W9)," ",(ROUND(W9,2)/0.995)) | AA9: =IF(ISBLANK(W9)," ",IF((ROUND(W9,2))<=(ROUND(Z9,2)),"YES","NO")) | AP9: BO | AQ9: GM
R10: =IF(ISBLANK(P10)," ",((ROUND(Q10,2)-(ROUND(P10,2)))/(ROUND(P10,2)))) | V10: =IF(ISBLANK(P10)," ",((ROUND(U10,2)-(ROUND(P10,2)))/(ROUND(P10,2)))) | X10: =IF(ISBLANK(P10)," ",((ROUND(W10,2)-(ROUND(P10,2)))/(ROUND(P10,2)))) | Y10: =IF(ISBLANK(W10)," ",(ROUND(W10,2)/0.995)) | AA10: =IF(ISBLANK(W10)," ",IF((ROUND(W10,2))<=(ROUND(Z10,2)),"YES","NO")) | AP10: BX | AQ10: IN
R11: =IF(ISBLANK(P11)," ",((ROUND(Q11,2)-(ROUND(P11,2)))/(ROUND(P11,2)))) | V11: =IF(ISBLANK(P11)," ",((ROUND(U11,2)-(ROUND(P11,2)))/(ROUND(P11,2)))) | X11: =IF(ISBLANK(P11)," ",((ROUND(W11,2)-(ROUND(P11,2)))/(ROUND(P11,2)))) | Y11: =IF(ISBLANK(W11)," ",(ROUND(W11,2)/0.995)) | AA11: =IF(ISBLANK(W11)," ",IF((ROUND(W11,2))<=(ROUND(Z11,2)),"YES","NO")) | AP11: CA | AQ11: LT
R12: =IF(ISBLANK(P12)," ",((ROUND(Q12,2)-(ROUND(P12,2)))/(ROUND(P12,2)))) | V12: =IF(ISBLANK(P12)," ",((ROUND(U12,2)-(ROUND(P12,2)))/(ROUND(P12,2)))) | X12: =IF(ISBLANK(P12)," ",((ROUND(W12,2)-(ROUND(P12,2)))/(ROUND(P12,2)))) | Y12: =IF(ISBLANK(W12)," ",(ROUND(W12,2)/0.995)) | AA12: =IF(ISBLANK(W12)," ",IF((ROUND(W12,2))<=(ROUND(Z12,2)),"YES","NO")) | AP12: CH | AQ12: ML
R13: =IF(ISBLANK(P13)," ",((ROUND(Q13,2)-(ROUND(P13,2)))/(ROUND(P13,2)))) | V13: =IF(ISBLANK(P13)," ",((ROUND(U13,2)-(ROUND(P13,2)))/(ROUND(P13,2)))) | X13: =IF(ISBLANK(P13)," ",((ROUND(W13,2)-(ROUND(P13,2)))/(ROUND(P13,2)))) | Y13: =IF(ISBLANK(W13)," ",(ROUND(W13,2)/0.995)) | AA13: =IF(ISBLANK(W13)," ",IF((ROUND(W13,2))<=(ROUND(Z13,2)),"YES","NO")) | AP13: CL
R14: =IF(ISBLANK(P14)," ",((ROUND(Q14,2)-(ROUND(P14,2)))/(ROUND(P14,2)))) | V14: =IF(ISBLANK(P14)," ",((ROUND(U14,2)-(ROUND(P14,2)))/(ROUND(P14,2)))) | X14: =IF(ISBLANK(P14)," ",((ROUND(W14,2)-(ROUND(P14,2)))/(ROUND(P14,2)))) | Y14: =IF(ISBLANK(W14)," ",(ROUND(W14,2)/0.995)) | AA14: =IF(ISBLANK(W14)," ",IF((ROUND(W14,2))<=(ROUND(Z14,2)),"YES","NO")) | AP14: CN
R15: =IF(ISBLANK(P15)," ",((ROUND(Q15,2)-(ROUND(P15,2)))/(ROUND(P15,2)))) | V15: =IF(ISBLANK(P15)," ",((ROUND(U15,2)-(ROUND(P15,2)))/(ROUND(P15,2)))) | X15: =IF(ISBLANK(P15)," ",((ROUND(W15,2)-(ROUND(P15,2)))/(ROUND(P15,2)))) | Y15: =IF(ISBLANK(W15)," ",(ROUND(W15,2)/0.995)) | AA15: =IF(ISBLANK(W15)," ",IF((ROUND(W15,2))<=(ROUND(Z15,2)),"YES","NO")) | AP15: CQ
R16: =IF(ISBLANK(P16)," ",((ROUND(Q16,2)-(ROUND(P16,2)))/(ROUND(P16,2)))) | V16: =IF(ISBLANK(P16)," ",((ROUND(U16,2)-(ROUND(P16,2)))/(ROUND(P16,2)))) | X16: =IF(ISBLANK(P16)," ",((ROUND(W16,2)-(ROUND(P16,2)))/(ROUND(P16,2)))) | Y16: =IF(ISBLANK(W16)," ",(ROUND(W16,2)/0.995)) | AA16: =IF(ISBLANK(W16)," ",IF((ROUND(W16,2))<=(ROUND(Z16,2)),"YES","NO")) | AP16: CT
R17: =IF(ISBLANK(P17)," ",((ROUND(Q17,2)-(ROUND(P17,2)))/(ROUND(P17,2)))) | V17: =IF(ISBLANK(P17)," ",((ROUND(U17,2)-(ROUND(P17,2)))/(ROUND(P17,2)))) | X17: =IF(ISBLANK(P17)," ",((ROUND(W17,2)-(ROUND(P17,2)))/(ROUND(P17,2)))) | Y17: =IF(ISBLANK(W17)," ",(ROUND(W17,2)/0.995)) | AA17: =IF(ISBLANK(W17)," ",IF((ROUND(W17,2))<=(ROUND(Z17,2)),"YES","NO")) | AP17: DR
R18: =IF(ISBLANK(P18)," ",((ROUND(Q18,2)-(ROUND(P18,2)))/(ROUND(P18,2)))) | V18: =IF(ISBLANK(P18)," ",((ROUND(U18,2)-(ROUND(P18,2)))/(ROUND(P18,2)))) | X18: =IF(ISBLANK(P18)," ",((ROUND(W18,2)-(ROUND(P18,2)))/(ROUND(P18,2)))) | Y18: =IF(ISBLANK(W18)," ",(ROUND(W18,2)/0.995)) | AA18: =IF(ISBLANK(W18)," ",IF((ROUND(W18,2))<=(ROUND(Z18,2)),"YES","NO")) | AP18: EA
R19: =IF(ISBLANK(P19)," ",((ROUND(Q19,2)-(ROUND(P19,2)))/(ROUND(P19,2)))) | V19: =IF(ISBLANK(P19)," ",((ROUND(U19,2)-(ROUND(P19,2)))/(ROUND(P19,2)))) | X19: =IF(ISBLANK(P19)," ",((ROUND(W19,2)-(ROUND(P19,2)))/(ROUND(P19,2)))) | Y19: =IF(ISBLANK(W19)," ",(ROUND(W19,2)/0.995)) | AA19: =IF(ISBLANK(W19)," ",IF((ROUND(W19,2))<=(ROUND(Z19,2)),"YES","NO")) | AP19: KT
R20: =IF(ISBLANK(P20)," ",((ROUND(Q20,2)-(ROUND(P20,2)))/(ROUND(P20,2)))) | V20: =IF(ISBLANK(P20)," ",((ROUND(U20,2)-(ROUND(P20,2)))/(ROUND(P20,2)))) | X20: =IF(ISBLANK(P20)," ",((ROUND(W20,2)-(ROUND(P20,2)))/(ROUND(P20,2)))) | Y20: =IF(ISBLANK(W20)," ",(ROUND(W20,2)/0.995)) | AA20: =IF(ISBLANK(W20)," ",IF((ROUND(W20,2))<=(ROUND(Z20,2)),"YES","NO")) | AP20: PC
R21: =IF(ISBLANK(P21)," ",((ROUND(Q21,2)-(ROUND(P21,2)))/(ROUND(P21,2)))) | V21: =IF(ISBLANK(P21)," ",((ROUND(U21,2)-(ROUND(P21,2)))/(ROUND(P21,2)))) | X21: =IF(ISBLANK(P21)," ",((ROUND(W21,2)-(ROUND(P21,2)))/(ROUND(P21,2)))) | Y21: =IF(ISBLANK(W21)," ",(ROUND(W21,2)/0.995)) | AA21: =IF(ISBLANK(W21)," ",IF((ROUND(W21,2))<=(ROUND(Z21,2)),"YES","NO")) | AP21: PK
R22: =IF(ISBLANK(P22)," ",((ROUND(Q22,2)-(ROUND(P22,2)))/(ROUND(P22,2)))) | V22: =IF(ISBLANK(P22)," ",((ROUND(U22,2)-(ROUND(P22,2)))/(ROUND(P22,2)))) | X22: =IF(ISBLANK(P22)," ",((ROUND(W22,2)-(ROUND(P22,2)))/(ROUND(P22,2)))) | Y22: =IF(ISBLANK(W22)," ",(ROUND(W22,2)/0.995)) | AA22: =IF(ISBLANK(W22)," ",IF((ROUND(W22,2))<=(ROUND(Z22,2)),"YES","NO")) | AP22: RL
R23: =IF(ISBLANK(P23)," ",((ROUND(Q23,2)-(ROUND(P23,2)))/(ROUND(P23,2)))) | V23: =IF(ISBLANK(P23)," ",((ROUND(U23,2)-(ROUND(P23,2)))/(ROUND(P23,2)))) | X23: =IF(ISBLANK(P23)," ",((ROUND(W23,2)-(ROUND(P23,2)))/(ROUND(P23,2)))) | Y23: =IF(ISBLANK(W23)," ",(ROUND(W23,2)/0.995)) | AA23: =IF(ISBLANK(W23)," ",IF((ROUND(W23,2))<=(ROUND(Z23,2)),"YES","NO")) | AP23: TB
R24: =IF(ISBLANK(P24)," ",((ROUND(Q24,2)-(ROUND(P24,2)))/(ROUND(P24,2)))) | V24: =IF(ISBLANK(P24)," ",((ROUND(U24,2)-(ROUND(P24,2)))/(ROUND(P24,2)))) | X24: =IF(ISBLANK(P24)," ",((ROUND(W24,2)-(ROUND(P24,2)))/(ROUND(P24,2)))) | Y24: =IF(ISBLANK(W24)," ",(ROUND(W24,2)/0.995)) | AA24: =IF(ISBLANK(W24)," ",IF((ROUND(W24,2))<=(ROUND(Z24,2)),"YES","NO")) | AP24: VI
R25: =IF(ISBLANK(P25)," ",((ROUND(Q25,2)-(ROUND(P25,2)))/(ROUND(P25,2)))) | V25: =IF(ISBLANK(P25)," ",((ROUND(U25,2)-(ROUND(P25,2)))/(ROUND(P25,2)))) | X25: =IF(ISBLANK(P25)," ",((ROUND(W25,2)-(ROUND(P25,2)))/(ROUND(P25,2)))) | Y25: =IF(ISBLANK(W25)," ",(ROUND(W25,2)/0.995)) | AA25: =IF(ISBLANK(W25)," ",IF((ROUND(W25,2))<=(ROUND(Z25,2)),"YES","NO"))
R26: =IF(ISBLANK(P26)," ",((ROUND(Q26,2)-(ROUND(P26,2)))/(ROUND(P26,2)))) | V26: =IF(ISBLANK(P26)," ",((ROUND(U26,2)-(ROUND(P26,2)))/(ROUND(P26,2)))) | X26: =IF(ISBLANK(P26)," ",((ROUND(W26,2)-(ROUND(P26,2)))/(ROUND(P26,2)))) | Y26: =IF(ISBLANK(W26)," ",(ROUND(W26,2)/0.995)) | AA26: =IF(ISBLANK(W26)," ",IF((ROUND(W26,2))<=(ROUND(Z26,2)),"YES","NO"))
R27: =IF(ISBLANK(P27)," ",((ROUND(Q27,2)-(ROUND(P27,2)))/(ROUND(P27,2)))) | V27: =IF(ISBLANK(P27)," ",((ROUND(U27,2)-(ROUND(P27,2)))/(ROUND(P27,2)))) | X27: =IF(ISBLANK(P27)," ",((ROUND(W27,2)-(ROUND(P27,2)))/(ROUND(P27,2)))) | Y27: =IF(ISBLANK(W27)," ",(ROUND(W27,2)/0.995)) | AA27: =IF(ISBLANK(W27)," ",IF((ROUND(W27,2))<=(ROUND(Z27,2)),"YES","NO"))
R28: =IF(ISBLANK(P28)," ",((ROUND(Q28,2)-(ROUND(P28,2)))/(ROUND(P28,2)))) | V28: =IF(ISBLANK(P28)," ",((ROUND(U28,2)-(ROUND(P28,2)))/(ROUND(P28,2)))) | X28: =IF(ISBLANK(P28)," ",((ROUND(W28,2)-(ROUND(P28,2)))/(ROUND(P28,2)))) | Y28: =IF(ISBLANK(W28)," ",(ROUND(W28,2)/0.995)) | AA28: =IF(ISBLANK(W28)," ",IF((ROUND(W28,2))<=(ROUND(Z28,2)),"YES","NO"))
R29: =IF(ISBLANK(P29)," ",((ROUND(Q29,2)-(ROUND(P29,2)))/(ROUND(P29,2)))) | V29: =IF(ISBLANK(P29)," ",((ROUND(U29,2)-(ROUND(P29,2)))/(ROUND(P29,2)))) | X29: =IF(ISBLANK(P29)," ",((ROUND(W29,2)-(ROUND(P29,2)))/(ROUND(P29,2)))) | Y29: =IF(ISBLANK(W29)," ",(ROUND(W29,2)/0.995)) | AA29: =IF(ISBLANK(W29)," ",IF((ROUND(W29,2))<=(ROUND(Z29,2)),"YES","NO"))
R30: =IF(ISBLANK(P30)," ",((ROUND(Q30,2)-(ROUND(P30,2)))/(ROUND(P30,2)))) | V30: =IF(ISBLANK(P30)," ",((ROUND(U30,2)-(ROUND(P30,2)))/(ROUND(P30,2)))) | X30: =IF(ISBLANK(P30)," ",((ROUND(W30,2)-(ROUND(P30,2)))/(ROUND(P30,2)))) | Y30: =IF(ISBLANK(W30)," ",(ROUND(W30,2)/0.995)) | AA30: =IF(ISBLANK(W30)," ",IF((ROUND(W30,2))<=(ROUND(Z30,2)),"YES","NO"))
R31: =IF(ISBLANK(P31)," ",((ROUND(Q31,2)-(ROUND(P31,2)))/(ROUND(P31,2)))) | V31: =IF(ISBLANK(P31)," ",((ROUND(U31,2)-(ROUND(P31,2)))/(ROUND(P31,2)))) | X31: =IF(ISBLANK(P31)," ",((ROUND(W31,2)-(ROUND(P31,2)))/(ROUND(P31,2)))) | Y31: =IF(ISBLANK(W31)," ",(ROUND(W31,2)/0.995)) | AA31: =IF(ISBLANK(W31)," ",IF((ROUND(W31,2))<=(ROUND(Z31,2)),"YES","NO"))
R32: =IF(ISBLANK(P32)," ",((ROUND(Q32,2)-(ROUND(P32,2)))/(ROUND(P32,2)))) | V32: =IF(ISBLANK(P32)," ",((ROUND(U32,2)-(ROUND(P32,2)))/(ROUND(P32,2)))) | X32: =IF(ISBLANK(P32)," ",((ROUND(W32,2)-(ROUND(P32,2)))/(ROUND(P32,2)))) | Y32: =IF(ISBLANK(W32)," ",(ROUND(W32,2)/0.995)) | AA32: =IF(ISBLANK(W32)," ",IF((ROUND(W32,2))<=(ROUND(Z32,2)),"YES","NO"))
R33: =IF(ISBLANK(P33)," ",((ROUND(Q33,2)-(ROUND(P33,2)))/(ROUND(P33,2)))) | V33: =IF(ISBLANK(P33)," ",((ROUND(U33,2)-(ROUND(P33,2)))/(ROUND(P33,2)))) | X33: =IF(ISBLANK(P33)," ",((ROUND(W33,2)-(ROUND(P33,2)))/(ROUND(P33,2)))) | Y33: =IF(ISBLANK(W33)," ",(ROUND(W33,2)/0.995)) | AA33: =IF(ISBLANK(W33)," ",IF((ROUND(W33,2))<=(ROUND(Z33,2)),"YES","NO"))
R34: =IF(ISBLANK(P34)," ",((ROUND(Q34,2)-(ROUND(P34,2)))/(ROUND(P34,2)))) | V34: =IF(ISBLANK(P34)," ",((ROUND(U34,2)-(ROUND(P34,2)))/(ROUND(P34,2)))) | X34: =IF(ISBLANK(P34)," ",((ROUND(W34,2)-(ROUND(P34,2)))/(ROUND(P34,2)))) | Y34: =IF(ISBLANK(W34)," ",(ROUND(W34,2)/0.995)) | AA34: =IF(ISBLANK(W34)," ",IF((ROUND(W34,2))<=(ROUND(Z34,2)),"YES","NO"))
R35: =IF(ISBLANK(P35)," ",((ROUND(Q35,2)-(ROUND(P35,2)))/(ROUND(P35,2)))) | V35: =IF(ISBLANK(P35)," ",((ROUND(U35,2)-(ROUND(P35,2)))/(ROUND(P35,2)))) | X35: =IF(ISBLANK(P35)," ",((ROUND(W35,2)-(ROUND(P35,2)))/(ROUND(P35,2)))) | Y35: =IF(ISBLANK(W35)," ",(ROUND(W35,2)/0.995)) | AA35: =IF(ISBLANK(W35)," ",IF((ROUND(W35,2))<=(ROUND(Z35,2)),"YES","NO"))
R36: =IF(ISBLANK(P36)," ",((ROUND(Q36,2)-(ROUND(P36,2)))/(ROUND(P36,2)))) | V36: =IF(ISBLANK(P36)," ",((ROUND(U36,2)-(ROUND(P36,2)))/(ROUND(P36,2)))) | X36: =IF(ISBLANK(P36)," ",((ROUND(W36,2)-(ROUND(P36,2)))/(ROUND(P36,2)))) | Y36: =IF(ISBLANK(W36)," ",(ROUND(W36,2)/0.995)) | AA36: =IF(ISBLANK(W36)," ",IF((ROUND(W36,2))<=(ROUND(Z36,2)),"YES","NO"))
... R1002: =IF(ISBLANK(P1002)," ",((ROUND(Q1002,2)-(ROUND(P1002,2)))/(ROUND(P1002,2)))) | V1002: =IF(ISBLANK(P1002)," ",((ROUND(U1002,2)-(ROUND(P1002,2)))/(ROUND(P1002,2)))) | X1002: =IF(ISBLANK(P1002)," ",((ROUND(W1002,2)-(ROUND(P1002,2)))/(ROUND(P1002,2)))) | Y1002: =IF(ISBLANK(W1002)," ",(ROUND(W1002,2)/0.995)) | AA1002: =IF(ISBLANK(W1002)," ",IF((ROUND(W1002,2))<=(ROUND(Z1002,2)),"YES","NO"))

Sheet 42-2A Dual - OGA
A1: Product Information | Q1: MFC Information | T1: Tracking Customer Information | W1: FSS Information
A2: SIN# | B2: NDC1 | C2: NDC2 | D2: NDC3 | E2: Type "YES" if item is handled by Specialty Distrib. | F2: Generic Name / Strength | G2: Trade Name / Strength | H2: Package Size | I2: Unit of Sale | J2: Quantity in Unit of Sale | K2: Unit Pkg | L2: Quantity in Unit Package | M2: Unit of Measure | N2: FDA Application Number | O2: Country of Origin (See Country Codes Tab) | P2: Commercial List Price ($) | Q2: MFC Net Price ($) | R2: MFC % Off Comm. List Price | S2: MFC Name | T2: Proposed Tracking Customer (TC) Name | U2: Proposed TC Price ($) | V2: TC % Off Comm. List Price | W2: Proposed OGA Price ($) without IFF | X2: Proposed OGA % Off Comm. List Price w/out IFF | Y2: Proposed OGA Price ($) with IFF | Z2: Is Proposed BIG4 Price w/out IFF Less Than or Equal to OGA Price w/out IFF?
A3: =IF(ISBLANK('42-2A Dual - BIG 4'!A3)," ",'42-2A Dual - BIG 4'!A3) | B3: =IF(ISBLANK('42-2A Dual - BIG 4'!B3)," ",'42-2A Dual - BIG 4'!B3) | C3: =IF(ISBLANK('42-2A Dual - BIG 4'!C3)," ",'42-2A Dual - BIG 4'!C3) | D3: =IF(ISBLANK('42-2A Dual - BIG 4'!D3)," ",'42-2A Dual - BIG 4'!D3) | E3: =IF(ISBLANK('42-2A Dual - BIG 4'!E3)," ",'42-2A Dual - BIG 4'!E3) | F3: =IF(ISBLANK('42-2A Dual - BIG 4'!F3)," ",'42-2A Dual - BIG 4'!F3) | G3: =IF(ISBLANK('42-2A Dual - BIG 4'!G3)," ",'42-2A Dual - BIG 4'!G3) | H3: =IF(ISBLANK('42-2A Dual - BIG 4'!H3)," ",'42-2A Dual - BIG 4'!H3) | ... S3: =IF(ISBLANK('42-2A Dual - BIG 4'!S3)," ",'42-2A Dual - BIG 4'!S3) | V3: =IFERROR(IF(ISBLANK(P3)," ",((ROUND(U3,2)-(ROUND(P3,2)))/(ROUND(P3,2))))," ") | X3: =IFERROR(IF(ISBLANK(P3)," ",((ROUND(W3,2)-(ROUND(P3,2)))/(ROUND(P3,2))))," ") | Y3: =IF(ISBLANK(W3)," ",(ROUND(W3,2)/0.995)) | Z3: =IF(ISBLANK('42-2A Dual - BIG 4'!W3)," ",IF((ROUND('42-2A Dual - BIG 4'!W3,2))<=(ROUND(W3,2)),"YES","NO"))
A4: =IF(ISBLANK('42-2A Dual - BIG 4'!A4)," ",'42-2A Dual - BIG 4'!A4) | B4: =IF(ISBLANK('42-2A Dual - BIG 4'!B4)," ",'42-2A Dual - BIG 4'!B4) | C4: =IF(ISBLANK('42-2A Dual - BIG 4'!C4)," ",'42-2A Dual - BIG 4'!C4) | D4: =IF(ISBLANK('42-2A Dual - BIG 4'!D4)," ",'42-2A Dual - BIG 4'!D4) | E4: =IF(ISBLANK('42-2A Dual - BIG 4'!E4)," ",'42-2A Dual - BIG 4'!E4) | F4: =IF(ISBLANK('42-2A Dual - BIG 4'!F4)," ",'42-2A Dual - BIG 4'!F4) | G4: =IF(ISBLANK('42-2A Dual - BIG 4'!G4)," ",'42-2A Dual - BIG 4'!G4) | H4: =IF(ISBLANK('42-2A Dual - BIG 4'!H4)," ",'42-2A Dual - BIG 4'!H4) | ... S4: =IF(ISBLANK('42-2A Dual - BIG 4'!S4)," ",'42-2A Dual - BIG 4'!S4) | V4: =IFERROR(IF(ISBLANK(P4)," ",((ROUND(U4,2)-(ROUND(P4,2)))/(ROUND(P4,2))))," ") | X4: =IFERROR(IF(ISBLANK(P4)," ",((ROUND(W4,2)-(ROUND(P4,2)))/(ROUND(P4,2))))," ") | Y4: =IF(ISBLANK(W4)," ",(ROUND(W4,2)/0.995)) | Z4: =IF(ISBLANK('42-2A Dual - BIG 4'!W4)," ",IF((ROUND('42-2A Dual - BIG 4'!W4,2))<=(ROUND(W4,2)),"YES","NO"))
A5: =IF(ISBLANK('42-2A Dual - BIG 4'!A5)," ",'42-2A Dual - BIG 4'!A5) | B5: =IF(ISBLANK('42-2A Dual - BIG 4'!B5)," ",'42-2A Dual - BIG 4'!B5) | C5: =IF(ISBLANK('42-2A Dual - BIG 4'!C5)," ",'42-2A Dual - BIG 4'!C5) | D5: =IF(ISBLANK('42-2A Dual - BIG 4'!D5)," ",'42-2A Dual - BIG 4'!D5) | E5: =IF(ISBLANK('42-2A Dual - BIG 4'!E5)," ",'42-2A Dual - BIG 4'!E5) | F5: =IF(ISBLANK('42-2A Dual - BIG 4'!F5)," ",'42-2A Dual - BIG 4'!F5) | G5: =IF(ISBLANK('42-2A Dual - BIG 4'!G5)," ",'42-2A Dual - BIG 4'!G5) | H5: =IF(ISBLANK('42-2A Dual - BIG 4'!H5)," ",'42-2A Dual - BIG 4'!H5) | ... S5: =IF(ISBLANK('42-2A Dual - BIG 4'!S5)," ",'42-2A Dual - BIG 4'!S5) | V5: =IFERROR(IF(ISBLANK(P5)," ",((ROUND(U5,2)-(ROUND(P5,2)))/(ROUND(P5,2))))," ") | X5: =IFERROR(IF(ISBLANK(P5)," ",((ROUND(W5,2)-(ROUND(P5,2)))/(ROUND(P5,2))))," ") | Y5: =IF(ISBLANK(W5)," ",(ROUND(W5,2)/0.995)) | Z5: =IF(ISBLANK('42-2A Dual - BIG 4'!W5)," ",IF((ROUND('42-2A Dual - BIG 4'!W5,2))<=(ROUND(W5,2)),"YES","NO"))
A6: =IF(ISBLANK('42-2A Dual - BIG 4'!A6)," ",'42-2A Dual - BIG 4'!A6) | B6: =IF(ISBLANK('42-2A Dual - BIG 4'!B6)," ",'42-2A Dual - BIG 4'!B6) | C6: =IF(ISBLANK('42-2A Dual - BIG 4'!C6)," ",'42-2A Dual - BIG 4'!C6) | D6: =IF(ISBLANK('42-2A Dual - BIG 4'!D6)," ",'42-2A Dual - BIG 4'!D6) | E6: =IF(ISBLANK('42-2A Dual - BIG 4'!E6)," ",'42-2A Dual - BIG 4'!E6) | F6: =IF(ISBLANK('42-2A Dual - BIG 4'!F6)," ",'42-2A Dual - BIG 4'!F6) | G6: =IF(ISBLANK('42-2A Dual - BIG 4'!G6)," ",'42-2A Dual - BIG 4'!G6) | H6: =IF(ISBLANK('42-2A Dual - BIG 4'!H6)," ",'42-2A Dual - BIG 4'!H6) | ... S6: =IF(ISBLANK('42-2A Dual - BIG 4'!S6)," ",'42-2A Dual - BIG 4'!S6) | V6: =IFERROR(IF(ISBLANK(P6)," ",((ROUND(U6,2)-(ROUND(P6,2)))/(ROUND(P6,2))))," ") | X6: =IFERROR(IF(ISBLANK(P6)," ",((ROUND(W6,2)-(ROUND(P6,2)))/(ROUND(P6,2))))," ") | Y6: =IF(ISBLANK(W6)," ",(ROUND(W6,2)/0.995)) | Z6: =IF(ISBLANK('42-2A Dual - BIG 4'!W6)," ",IF((ROUND('42-2A Dual - BIG 4'!W6,2))<=(ROUND(W6,2)),"YES","NO"))
A7: =IF(ISBLANK('42-2A Dual - BIG 4'!A7)," ",'42-2A Dual - BIG 4'!A7) | B7: =IF(ISBLANK('42-2A Dual - BIG 4'!B7)," ",'42-2A Dual - BIG 4'!B7) | C7: =IF(ISBLANK('42-2A Dual - BIG 4'!C7)," ",'42-2A Dual - BIG 4'!C7) | D7: =IF(ISBLANK('42-2A Dual - BIG 4'!D7)," ",'42-2A Dual - BIG 4'!D7) | E7: =IF(ISBLANK('42-2A Dual - BIG 4'!E7)," ",'42-2A Dual - BIG 4'!E7) | F7: =IF(ISBLANK('42-2A Dual - BIG 4'!F7)," ",'42-2A Dual - BIG 4'!F7) | G7: =IF(ISBLANK('42-2A Dual - BIG 4'!G7)," ",'42-2A Dual - BIG 4'!G7) | H7: =IF(ISBLANK('42-2A Dual - BIG 4'!H7)," ",'42-2A Dual - BIG 4'!H7) | ... S7: =IF(ISBLANK('42-2A Dual - BIG 4'!S7)," ",'42-2A Dual - BIG 4'!S7) | V7: =IFERROR(IF(ISBLANK(P7)," ",((ROUND(U7,2)-(ROUND(P7,2)))/(ROUND(P7,2))))," ") | X7: =IFERROR(IF(ISBLANK(P7)," ",((ROUND(W7,2)-(ROUND(P7,2)))/(ROUND(P7,2))))," ") | Y7: =IF(ISBLANK(W7)," ",(ROUND(W7,2)/0.995)) | Z7: =IF(ISBLANK('42-2A Dual - BIG 4'!W7)," ",IF((ROUND('42-2A Dual - BIG 4'!W7,2))<=(ROUND(W7,2)),"YES","NO")) | AN7: 42-2a | AO7: AM | AP7: EA
A8: =IF(ISBLANK('42-2A Dual - BIG 4'!A8)," ",'42-2A Dual - BIG 4'!A8) | B8: =IF(ISBLANK('42-2A Dual - BIG 4'!B8)," ",'42-2A Dual - BIG 4'!B8) | C8: =IF(ISBLANK('42-2A Dual - BIG 4'!C8)," ",'42-2A Dual - BIG 4'!C8) | D8: =IF(ISBLANK('42-2A Dual - BIG 4'!D8)," ",'42-2A Dual - BIG 4'!D8) | E8: =IF(ISBLANK('42-2A Dual - BIG 4'!E8)," ",'42-2A Dual - BIG 4'!E8) | F8: =IF(ISBLANK('42-2A Dual - BIG 4'!F8)," ",'42-2A Dual - BIG 4'!F8) | G8: =IF(ISBLANK('42-2A Dual - BIG 4'!G8)," ",'42-2A Dual - BIG 4'!G8) | H8: =IF(ISBLANK('42-2A Dual - BIG 4'!H8)," ",'42-2A Dual - BIG 4'!H8) | ... S8: =IF(ISBLANK('42-2A Dual - BIG 4'!S8)," ",'42-2A Dual - BIG 4'!S8) | V8: =IFERROR(IF(ISBLANK(P8)," ",((ROUND(U8,2)-(ROUND(P8,2)))/(ROUND(P8,2))))," ") | X8: =IFERROR(IF(ISBLANK(P8)," ",((ROUND(W8,2)-(ROUND(P8,2)))/(ROUND(P8,2))))," ") | Y8: =IF(ISBLANK(W8)," ",(ROUND(W8,2)/0.995)) | Z8: =IF(ISBLANK('42-2A Dual - BIG 4'!W8)," ",IF((ROUND('42-2A Dual - BIG 4'!W8,2))<=(ROUND(W8,2)),"YES","NO")) | AO8: BG | AP8: F2
A9: =IF(ISBLANK('42-2A Dual - BIG 4'!A9)," ",'42-2A Dual - BIG 4'!A9) | B9: =IF(ISBLANK('42-2A Dual - BIG 4'!B9)," ",'42-2A Dual - BIG 4'!B9) | C9: =IF(ISBLANK('42-2A Dual - BIG 4'!C9)," ",'42-2A Dual - BIG 4'!C9) | D9: =IF(ISBLANK('42-2A Dual - BIG 4'!D9)," ",'42-2A Dual - BIG 4'!D9) | E9: =IF(ISBLANK('42-2A Dual - BIG 4'!E9)," ",'42-2A Dual - BIG 4'!E9) | F9: =IF(ISBLANK('42-2A Dual - BIG 4'!F9)," ",'42-2A Dual - BIG 4'!F9) | G9: =IF(ISBLANK('42-2A Dual - BIG 4'!G9)," ",'42-2A Dual - BIG 4'!G9) | H9: =IF(ISBLANK('42-2A Dual - BIG 4'!H9)," ",'42-2A Dual - BIG 4'!H9) | ... S9: =IF(ISBLANK('42-2A Dual - BIG 4'!S9)," ",'42-2A Dual - BIG 4'!S9) | V9: =IFERROR(IF(ISBLANK(P9)," ",((ROUND(U9,2)-(ROUND(P9,2)))/(ROUND(P9,2))))," ") | X9: =IFERROR(IF(ISBLANK(P9)," ",((ROUND(W9,2)-(ROUND(P9,2)))/(ROUND(P9,2))))," ") | Y9: =IF(ISBLANK(W9)," ",(ROUND(W9,2)/0.995)) | Z9: =IF(ISBLANK('42-2A Dual - BIG 4'!W9)," ",IF((ROUND('42-2A Dual - BIG 4'!W9,2))<=(ROUND(W9,2)),"YES","NO")) | AO9: BO | AP9: GM
A10: =IF(ISBLANK('42-2A Dual - BIG 4'!A10)," ",'42-2A Dual - BIG 4'!A10) | B10: =IF(ISBLANK('42-2A Dual - BIG 4'!B10)," ",'42-2A Dual - BIG 4'!B10) | C10: =IF(ISBLANK('42-2A Dual - BIG 4'!C10)," ",'42-2A Dual - BIG 4'!C10) | D10: =IF(ISBLANK('42-2A Dual - BIG 4'!D10)," ",'42-2A Dual - BIG 4'!D10) | E10: =IF(ISBLANK('42-2A Dual - BIG 4'!E10)," ",'42-2A Dual - BIG 4'!E10) | F10: =IF(ISBLANK('42-2A Dual - BIG 4'!F10)," ",'42-2A Dual - BIG 4'!F10) | G10: =IF(ISBLANK('42-2A Dual - BIG 4'!G10)," ",'42-2A Dual - BIG 4'!G10) | H10: =IF(ISBLANK('42-2A Dual - BIG 4'!H10)," ",'42-2A Dual - BIG 4'!H10) | ... S10: =IF(ISBLANK('42-2A Dual - BIG 4'!S10)," ",'42-2A Dual - BIG 4'!S10) | V10: =IFERROR(IF(ISBLANK(P10)," ",((ROUND(U10,2)-(ROUND(P10,2)))/(ROUND(P10,2))))," ") | X10: =IFERROR(IF(ISBLANK(P10)," ",((ROUND(W10,2)-(ROUND(P10,2)))/(ROUND(P10,2))))," ") | Y10: =IF(ISBLANK(W10)," ",(ROUND(W10,2)/0.995)) | Z10: =IF(ISBLANK('42-2A Dual - BIG 4'!W10)," ",IF((ROUND('42-2A Dual - BIG 4'!W10,2))<=(ROUND(W10,2)),"YES","NO")) | AO10: BX | AP10: IN
A11: =IF(ISBLANK('42-2A Dual - BIG 4'!A11)," ",'42-2A Dual - BIG 4'!A11) | B11: =IF(ISBLANK('42-2A Dual - BIG 4'!B11)," ",'42-2A Dual - BIG 4'!B11) | C11: =IF(ISBLANK('42-2A Dual - BIG 4'!C11)," ",'42-2A Dual - BIG 4'!C11) | D11: =IF(ISBLANK('42-2A Dual - BIG 4'!D11)," ",'42-2A Dual - BIG 4'!D11) | E11: =IF(ISBLANK('42-2A Dual - BIG 4'!E11)," ",'42-2A Dual - BIG 4'!E11) | F11: =IF(ISBLANK('42-2A Dual - BIG 4'!F11)," ",'42-2A Dual - BIG 4'!F11) | G11: =IF(ISBLANK('42-2A Dual - BIG 4'!G11)," ",'42-2A Dual - BIG 4'!G11) | H11: =IF(ISBLANK('42-2A Dual - BIG 4'!H11)," ",'42-2A Dual - BIG 4'!H11) | ... S11: =IF(ISBLANK('42-2A Dual - BIG 4'!S11)," ",'42-2A Dual - BIG 4'!S11) | V11: =IFERROR(IF(ISBLANK(P11)," ",((ROUND(U11,2)-(ROUND(P11,2)))/(ROUND(P11,2))))," ") | X11: =IFERROR(IF(ISBLANK(P11)," ",((ROUND(W11,2)-(ROUND(P11,2)))/(ROUND(P11,2))))," ") | Y11: =IF(ISBLANK(W11)," ",(ROUND(W11,2)/0.995)) | Z11: =IF(ISBLANK('42-2A Dual - BIG 4'!W11)," ",IF((ROUND('42-2A Dual - BIG 4'!W11,2))<=(ROUND(W11,2)),"YES","NO")) | AO11: CA | AP11: LT
A12: =IF(ISBLANK('42-2A Dual - BIG 4'!A12)," ",'42-2A Dual - BIG 4'!A12) | B12: =IF(ISBLANK('42-2A Dual - BIG 4'!B12)," ",'42-2A Dual - BIG 4'!B12) | C12: =IF(ISBLANK('42-2A Dual - BIG 4'!C12)," ",'42-2A Dual - BIG 4'!C12) | D12: =IF(ISBLANK('42-2A Dual - BIG 4'!D12)," ",'42-2A Dual - BIG 4'!D12) | E12: =IF(ISBLANK('42-2A Dual - BIG 4'!E12)," ",'42-2A Dual - BIG 4'!E12) | F12: =IF(ISBLANK('42-2A Dual - BIG 4'!F12)," ",'42-2A Dual - BIG 4'!F12) | G12: =IF(ISBLANK('42-2A Dual - BIG 4'!G12)," ",'42-2A Dual - BIG 4'!G12) | H12: =IF(ISBLANK('42-2A Dual - BIG 4'!H12)," ",'42-2A Dual - BIG 4'!H12) | ... S12: =IF(ISBLANK('42-2A Dual - BIG 4'!S12)," ",'42-2A Dual - BIG 4'!S12) | V12: =IFERROR(IF(ISBLANK(P12)," ",((ROUND(U12,2)-(ROUND(P12,2)))/(ROUND(P12,2))))," ") | X12: =IFERROR(IF(ISBLANK(P12)," ",((ROUND(W12,2)-(ROUND(P12,2)))/(ROUND(P12,2))))," ") | Y12: =IF(ISBLANK(W12)," ",(ROUND(W12,2)/0.995)) | Z12: =IF(ISBLANK('42-2A Dual - BIG 4'!W12)," ",IF((ROUND('42-2A Dual - BIG 4'!W12,2))<=(ROUND(W12,2)),"YES","NO")) | AO12: CH | AP12: ML
A13: =IF(ISBLANK('42-2A Dual - BIG 4'!A13)," ",'42-2A Dual - BIG 4'!A13) | B13: =IF(ISBLANK('42-2A Dual - BIG 4'!B13)," ",'42-2A Dual - BIG 4'!B13) | C13: =IF(ISBLANK('42-2A Dual - BIG 4'!C13)," ",'42-2A Dual - BIG 4'!C13) | D13: =IF(ISBLANK('42-2A Dual - BIG 4'!D13)," ",'42-2A Dual - BIG 4'!D13) | E13: =IF(ISBLANK('42-2A Dual - BIG 4'!E13)," ",'42-2A Dual - BIG 4'!E13) | F13: =IF(ISBLANK('42-2A Dual - BIG 4'!F13)," ",'42-2A Dual - BIG 4'!F13) | G13: =IF(ISBLANK('42-2A Dual - BIG 4'!G13)," ",'42-2A Dual - BIG 4'!G13) | H13: =IF(ISBLANK('42-2A Dual - BIG 4'!H13)," ",'42-2A Dual - BIG 4'!H13) | ... S13: =IF(ISBLANK('42-2A Dual - BIG 4'!S13)," ",'42-2A Dual - BIG 4'!S13) | V13: =IFERROR(IF(ISBLANK(P13)," ",((ROUND(U13,2)-(ROUND(P13,2)))/(ROUND(P13,2))))," ") | X13: =IFERROR(IF(ISBLANK(P13)," ",((ROUND(W13,2)-(ROUND(P13,2)))/(ROUND(P13,2))))," ") | Y13: =IF(ISBLANK(W13)," ",(ROUND(W13,2)/0.995)) | Z13: =IF(ISBLANK('42-2A Dual - BIG 4'!W13)," ",IF((ROUND('42-2A Dual - BIG 4'!W13,2))<=(ROUND(W13,2)),"YES","NO")) | AO13: CL
A14: =IF(ISBLANK('42-2A Dual - BIG 4'!A14)," ",'42-2A Dual - BIG 4'!A14) | B14: =IF(ISBLANK('42-2A Dual - BIG 4'!B14)," ",'42-2A Dual - BIG 4'!B14) | C14: =IF(ISBLANK('42-2A Dual - BIG 4'!C14)," ",'42-2A Dual - BIG 4'!C14) | D14: =IF(ISBLANK('42-2A Dual - BIG 4'!D14)," ",'42-2A Dual - BIG 4'!D14) | E14: =IF(ISBLANK('42-2A Dual - BIG 4'!E14)," ",'42-2A Dual - BIG 4'!E14) | F14: =IF(ISBLANK('42-2A Dual - BIG 4'!F14)," ",'42-2A Dual - BIG 4'!F14) | G14: =IF(ISBLANK('42-2A Dual - BIG 4'!G14)," ",'42-2A Dual - BIG 4'!G14) | H14: =IF(ISBLANK('42-2A Dual - BIG 4'!H14)," ",'42-2A Dual - BIG 4'!H14) | ... S14: =IF(ISBLANK('42-2A Dual - BIG 4'!S14)," ",'42-2A Dual - BIG 4'!S14) | V14: =IFERROR(IF(ISBLANK(P14)," ",((ROUND(U14,2)-(ROUND(P14,2)))/(ROUND(P14,2))))," ") | X14: =IFERROR(IF(ISBLANK(P14)," ",((ROUND(W14,2)-(ROUND(P14,2)))/(ROUND(P14,2))))," ") | Y14: =IF(ISBLANK(W14)," ",(ROUND(W14,2)/0.995)) | Z14: =IF(ISBLANK('42-2A Dual - BIG 4'!W14)," ",IF((ROUND('42-2A Dual - BIG 4'!W14,2))<=(ROUND(W14,2)),"YES","NO")) | AO14: CN
A15: =IF(ISBLANK('42-2A Dual - BIG 4'!A15)," ",'42-2A Dual - BIG 4'!A15) | B15: =IF(ISBLANK('42-2A Dual - BIG 4'!B15)," ",'42-2A Dual - BIG 4'!B15) | C15: =IF(ISBLANK('42-2A Dual - BIG 4'!C15)," ",'42-2A Dual - BIG 4'!C15) | D15: =IF(ISBLANK('42-2A Dual - BIG 4'!D15)," ",'42-2A Dual - BIG 4'!D15) | E15: =IF(ISBLANK('42-2A Dual - BIG 4'!E15)," ",'42-2A Dual - BIG 4'!E15) | F15: =IF(ISBLANK('42-2A Dual - BIG 4'!F15)," ",'42-2A Dual - BIG 4'!F15) | G15: =IF(ISBLANK('42-2A Dual - BIG 4'!G15)," ",'42-2A Dual - BIG 4'!G15) | H15: =IF(ISBLANK('42-2A Dual - BIG 4'!H15)," ",'42-2A Dual - BIG 4'!H15) | ... S15: =IF(ISBLANK('42-2A Dual - BIG 4'!S15)," ",'42-2A Dual - BIG 4'!S15) | V15: =IFERROR(IF(ISBLANK(P15)," ",((ROUND(U15,2)-(ROUND(P15,2)))/(ROUND(P15,2))))," ") | X15: =IFERROR(IF(ISBLANK(P15)," ",((ROUND(W15,2)-(ROUND(P15,2)))/(ROUND(P15,2))))," ") | Y15: =IF(ISBLANK(W15)," ",(ROUND(W15,2)/0.995)) | Z15: =IF(ISBLANK('42-2A Dual - BIG 4'!W15)," ",IF((ROUND('42-2A Dual - BIG 4'!W15,2))<=(ROUND(W15,2)),"YES","NO")) | AO15: CQ
A16: =IF(ISBLANK('42-2A Dual - BIG 4'!A16)," ",'42-2A Dual - BIG 4'!A16) | B16: =IF(ISBLANK('42-2A Dual - BIG 4'!B16)," ",'42-2A Dual - BIG 4'!B16) | C16: =IF(ISBLANK('42-2A Dual - BIG 4'!C16)," ",'42-2A Dual - BIG 4'!C16) | D16: =IF(ISBLANK('42-2A Dual - BIG 4'!D16)," ",'42-2A Dual - BIG 4'!D16) | E16: =IF(ISBLANK('42-2A Dual - BIG 4'!E16)," ",'42-2A Dual - BIG 4'!E16) | F16: =IF(ISBLANK('42-2A Dual - BIG 4'!F16)," ",'42-2A Dual - BIG 4'!F16) | G16: =IF(ISBLANK('42-2A Dual - BIG 4'!G16)," ",'42-2A Dual - BIG 4'!G16) | H16: =IF(ISBLANK('42-2A Dual - BIG 4'!H16)," ",'42-2A Dual - BIG 4'!H16) | ... S16: =IF(ISBLANK('42-2A Dual - BIG 4'!S16)," ",'42-2A Dual - BIG 4'!S16) | V16: =IFERROR(IF(ISBLANK(P16)," ",((ROUND(U16,2)-(ROUND(P16,2)))/(ROUND(P16,2))))," ") | X16: =IFERROR(IF(ISBLANK(P16)," ",((ROUND(W16,2)-(ROUND(P16,2)))/(ROUND(P16,2))))," ") | Y16: =IF(ISBLANK(W16)," ",(ROUND(W16,2)/0.995)) | Z16: =IF(ISBLANK('42-2A Dual - BIG 4'!W16)," ",IF((ROUND('42-2A Dual - BIG 4'!W16,2))<=(ROUND(W16,2)),"YES","NO")) | AO16: CT
A17: =IF(ISBLANK('42-2A Dual - BIG 4'!A17)," ",'42-2A Dual - BIG 4'!A17) | B17: =IF(ISBLANK('42-2A Dual - BIG 4'!B17)," ",'42-2A Dual - BIG 4'!B17) | C17: =IF(ISBLANK('42-2A Dual - BIG 4'!C17)," ",'42-2A Dual - BIG 4'!C17) | D17: =IF(ISBLANK('42-2A Dual - BIG 4'!D17)," ",'42-2A Dual - BIG 4'!D17) | E17: =IF(ISBLANK('42-2A Dual - BIG 4'!E17)," ",'42-2A Dual - BIG 4'!E17) | F17: =IF(ISBLANK('42-2A Dual - BIG 4'!F17)," ",'42-2A Dual - BIG 4'!F17) | G17: =IF(ISBLANK('42-2A Dual - BIG 4'!G17)," ",'42-2A Dual - BIG 4'!G17) | H17: =IF(ISBLANK('42-2A Dual - BIG 4'!H17)," ",'42-2A Dual - BIG 4'!H17) | ... S17: =IF(ISBLANK('42-2A Dual - BIG 4'!S17)," ",'42-2A Dual - BIG 4'!S17) | V17: =IFERROR(IF(ISBLANK(P17)," ",((ROUND(U17,2)-(ROUND(P17,2)))/(ROUND(P17,2))))," ") | X17: =IFERROR(IF(ISBLANK(P17)," ",((ROUND(W17,2)-(ROUND(P17,2)))/(ROUND(P17,2))))," ") | Y17: =IF(ISBLANK(W17)," ",(ROUND(W17,2)/0.995)) | Z17: =IF(ISBLANK('42-2A Dual - BIG 4'!W17)," ",IF((ROUND('42-2A Dual - BIG 4'!W17,2))<=(ROUND(W17,2)),"YES","NO")) | AO17: DR
A18: =IF(ISBLANK('42-2A Dual - BIG 4'!A18)," ",'42-2A Dual - BIG 4'!A18) | B18: =IF(ISBLANK('42-2A Dual - BIG 4'!B18)," ",'42-2A Dual - BIG 4'!B18) | C18: =IF(ISBLANK('42-2A Dual - BIG 4'!C18)," ",'42-2A Dual - BIG 4'!C18) | D18: =IF(ISBLANK('42-2A Dual - BIG 4'!D18)," ",'42-2A Dual - BIG 4'!D18) | E18: =IF(ISBLANK('42-2A Dual - BIG 4'!E18)," ",'42-2A Dual - BIG 4'!E18) | F18: =IF(ISBLANK('42-2A Dual - BIG 4'!F18)," ",'42-2A Dual - BIG 4'!F18) | G18: =IF(ISBLANK('42-2A Dual - BIG 4'!G18)," ",'42-2A Dual - BIG 4'!G18) | H18: =IF(ISBLANK('42-2A Dual - BIG 4'!H18)," ",'42-2A Dual - BIG 4'!H18) | ... S18: =IF(ISBLANK('42-2A Dual - BIG 4'!S18)," ",'42-2A Dual - BIG 4'!S18) | V18: =IFERROR(IF(ISBLANK(P18)," ",((ROUND(U18,2)-(ROUND(P18,2)))/(ROUND(P18,2))))," ") | X18: =IFERROR(IF(ISBLANK(P18)," ",((ROUND(W18,2)-(ROUND(P18,2)))/(ROUND(P18,2))))," ") | Y18: =IF(ISBLANK(W18)," ",(ROUND(W18,2)/0.995)) | Z18: =IF(ISBLANK('42-2A Dual - BIG 4'!W18)," ",IF((ROUND('42-2A Dual - BIG 4'!W18,2))<=(ROUND(W18,2)),"YES","NO")) | AO18: EA
A19: =IF(ISBLANK('42-2A Dual - BIG 4'!A19)," ",'42-2A Dual - BIG 4'!A19) | B19: =IF(ISBLANK('42-2A Dual - BIG 4'!B19)," ",'42-2A Dual - BIG 4'!B19) | C19: =IF(ISBLANK('42-2A Dual - BIG 4'!C19)," ",'42-2A Dual - BIG 4'!C19) | D19: =IF(ISBLANK('42-2A Dual - BIG 4'!D19)," ",'42-2A Dual - BIG 4'!D19) | E19: =IF(ISBLANK('42-2A Dual - BIG 4'!E19)," ",'42-2A Dual - BIG 4'!E19) | F19: =IF(ISBLANK('42-2A Dual - BIG 4'!F19)," ",'42-2A Dual - BIG 4'!F19) | G19: =IF(ISBLANK('42-2A Dual - BIG 4'!G19)," ",'42-2A Dual - BIG 4'!G19) | H19: =IF(ISBLANK('42-2A Dual - BIG 4'!H19)," ",'42-2A Dual - BIG 4'!H19) | ... S19: =IF(ISBLANK('42-2A Dual - BIG 4'!S19)," ",'42-2A Dual - BIG 4'!S19) | V19: =IFERROR(IF(ISBLANK(P19)," ",((ROUND(U19,2)-(ROUND(P19,2)))/(ROUND(P19,2))))," ") | X19: =IFERROR(IF(ISBLANK(P19)," ",((ROUND(W19,2)-(ROUND(P19,2)))/(ROUND(P19,2))))," ") | Y19: =IF(ISBLANK(W19)," ",(ROUND(W19,2)/0.995)) | Z19: =IF(ISBLANK('42-2A Dual - BIG 4'!W19)," ",IF((ROUND('42-2A Dual - BIG 4'!W19,2))<=(ROUND(W19,2)),"YES","NO")) | AO19: KT
A20: =IF(ISBLANK('42-2A Dual - BIG 4'!A20)," ",'42-2A Dual - BIG 4'!A20) | B20: =IF(ISBLANK('42-2A Dual - BIG 4'!B20)," ",'42-2A Dual - BIG 4'!B20) | C20: =IF(ISBLANK('42-2A Dual - BIG 4'!C20)," ",'42-2A Dual - BIG 4'!C20) | D20: =IF(ISBLANK('42-2A Dual - BIG 4'!D20)," ",'42-2A Dual - BIG 4'!D20) | E20: =IF(ISBLANK('42-2A Dual - BIG 4'!E20)," ",'42-2A Dual - BIG 4'!E20) | F20: =IF(ISBLANK('42-2A Dual - BIG 4'!F20)," ",'42-2A Dual - BIG 4'!F20) | G20: =IF(ISBLANK('42-2A Dual - BIG 4'!G20)," ",'42-2A Dual - BIG 4'!G20) | H20: =IF(ISBLANK('42-2A Dual - BIG 4'!H20)," ",'42-2A Dual - BIG 4'!H20) | ... S20: =IF(ISBLANK('42-2A Dual - BIG 4'!S20)," ",'42-2A Dual - BIG 4'!S20) | V20: =IFERROR(IF(ISBLANK(P20)," ",((ROUND(U20,2)-(ROUND(P20,2)))/(ROUND(P20,2))))," ") | X20: =IFERROR(IF(ISBLANK(P20)," ",((ROUND(W20,2)-(ROUND(P20,2)))/(ROUND(P20,2))))," ") | Y20: =IF(ISBLANK(W20)," ",(ROUND(W20,2)/0.995)) | Z20: =IF(ISBLANK('42-2A Dual - BIG 4'!W20)," ",IF((ROUND('42-2A Dual - BIG 4'!W20,2))<=(ROUND(W20,2)),"YES","NO")) | AO20: PC
A21: =IF(ISBLANK('42-2A Dual - BIG 4'!A21)," ",'42-2A Dual - BIG 4'!A21) | B21: =IF(ISBLANK('42-2A Dual - BIG 4'!B21)," ",'42-2A Dual - BIG 4'!B21) | C21: =IF(ISBLANK('42-2A Dual - BIG 4'!C21)," ",'42-2A Dual - BIG 4'!C21) | D21: =IF(ISBLANK('42-2A Dual - BIG 4'!D21)," ",'42-2A Dual - BIG 4'!D21) | E21: =IF(ISBLANK('42-2A Dual - BIG 4'!E21)," ",'42-2A Dual - BIG 4'!E21) | F21: =IF(ISBLANK('42-2A Dual - BIG 4'!F21)," ",'42-2A Dual - BIG 4'!F21) | G21: =IF(ISBLANK('42-2A Dual - BIG 4'!G21)," ",'42-2A Dual - BIG 4'!G21) | H21: =IF(ISBLANK('42-2A Dual - BIG 4'!H21)," ",'42-2A Dual - BIG 4'!H21) | ... S21: =IF(ISBLANK('42-2A Dual - BIG 4'!S21)," ",'42-2A Dual - BIG 4'!S21) | V21: =IFERROR(IF(ISBLANK(P21)," ",((ROUND(U21,2)-(ROUND(P21,2)))/(ROUND(P21,2))))," ") | X21: =IFERROR(IF(ISBLANK(P21)," ",((ROUND(W21,2)-(ROUND(P21,2)))/(ROUND(P21,2))))," ") | Y21: =IF(ISBLANK(W21)," ",(ROUND(W21,2)/0.995)) | Z21: =IF(ISBLANK('42-2A Dual - BIG 4'!W21)," ",IF((ROUND('42-2A Dual - BIG 4'!W21,2))<=(ROUND(W21,2)),"YES","NO")) | AO21: PK
A22: =IF(ISBLANK('42-2A Dual - BIG 4'!A22)," ",'42-2A Dual - BIG 4'!A22) | B22: =IF(ISBLANK('42-2A Dual - BIG 4'!B22)," ",'42-2A Dual - BIG 4'!B22) | C22: =IF(ISBLANK('42-2A Dual - BIG 4'!C22)," ",'42-2A Dual - BIG 4'!C22) | D22: =IF(ISBLANK('42-2A Dual - BIG 4'!D22)," ",'42-2A Dual - BIG 4'!D22) | E22: =IF(ISBLANK('42-2A Dual - BIG 4'!E22)," ",'42-2A Dual - BIG 4'!E22) | F22: =IF(ISBLANK('42-2A Dual - BIG 4'!F22)," ",'42-2A Dual - BIG 4'!F22) | G22: =IF(ISBLANK('42-2A Dual - BIG 4'!G22)," ",'42-2A Dual - BIG 4'!G22) | H22: =IF(ISBLANK('42-2A Dual - BIG 4'!H22)," ",'42-2A Dual - BIG 4'!H22) | ... S22: =IF(ISBLANK('42-2A Dual - BIG 4'!S22)," ",'42-2A Dual - BIG 4'!S22) | V22: =IFERROR(IF(ISBLANK(P22)," ",((ROUND(U22,2)-(ROUND(P22,2)))/(ROUND(P22,2))))," ") | X22: =IFERROR(IF(ISBLANK(P22)," ",((ROUND(W22,2)-(ROUND(P22,2)))/(ROUND(P22,2))))," ") | Y22: =IF(ISBLANK(W22)," ",(ROUND(W22,2)/0.995)) | Z22: =IF(ISBLANK('42-2A Dual - BIG 4'!W22)," ",IF((ROUND('42-2A Dual - BIG 4'!W22,2))<=(ROUND(W22,2)),"YES","NO")) | AO22: RL
A23: =IF(ISBLANK('42-2A Dual - BIG 4'!A23)," ",'42-2A Dual - BIG 4'!A23) | B23: =IF(ISBLANK('42-2A Dual - BIG 4'!B23)," ",'42-2A Dual - BIG 4'!B23) | C23: =IF(ISBLANK('42-2A Dual - BIG 4'!C23)," ",'42-2A Dual - BIG 4'!C23) | D23: =IF(ISBLANK('42-2A Dual - BIG 4'!D23)," ",'42-2A Dual - BIG 4'!D23) | E23: =IF(ISBLANK('42-2A Dual - BIG 4'!E23)," ",'42-2A Dual - BIG 4'!E23) | F23: =IF(ISBLANK('42-2A Dual - BIG 4'!F23)," ",'42-2A Dual - BIG 4'!F23) | G23: =IF(ISBLANK('42-2A Dual - BIG 4'!G23)," ",'42-2A Dual - BIG 4'!G23) | H23: =IF(ISBLANK('42-2A Dual - BIG 4'!H23)," ",'42-2A Dual - BIG 4'!H23) | ... S23: =IF(ISBLANK('42-2A Dual - BIG 4'!S23)," ",'42-2A Dual - BIG 4'!S23) | V23: =IFERROR(IF(ISBLANK(P23)," ",((ROUND(U23,2)-(ROUND(P23,2)))/(ROUND(P23,2))))," ") | X23: =IFERROR(IF(ISBLANK(P23)," ",((ROUND(W23,2)-(ROUND(P23,2)))/(ROUND(P23,2))))," ") | Y23: =IF(ISBLANK(W23)," ",(ROUND(W23,2)/0.995)) | Z23: =IF(ISBLANK('42-2A Dual - BIG 4'!W23)," ",IF((ROUND('42-2A Dual - BIG 4'!W23,2))<=(ROUND(W23,2)),"YES","NO")) | AO23: TB
A24: =IF(ISBLANK('42-2A Dual - BIG 4'!A24)," ",'42-2A Dual - BIG 4'!A24) | B24: =IF(ISBLANK('42-2A Dual - BIG 4'!B24)," ",'42-2A Dual - BIG 4'!B24) | C24: =IF(ISBLANK('42-2A Dual - BIG 4'!C24)," ",'42-2A Dual - BIG 4'!C24) | D24: =IF(ISBLANK('42-2A Dual - BIG 4'!D24)," ",'42-2A Dual - BIG 4'!D24) | E24: =IF(ISBLANK('42-2A Dual - BIG 4'!E24)," ",'42-2A Dual - BIG 4'!E24) | F24: =IF(ISBLANK('42-2A Dual - BIG 4'!F24)," ",'42-2A Dual - BIG 4'!F24) | G24: =IF(ISBLANK('42-2A Dual - BIG 4'!G24)," ",'42-2A Dual - BIG 4'!G24) | H24: =IF(ISBLANK('42-2A Dual - BIG 4'!H24)," ",'42-2A Dual - BIG 4'!H24) | ... S24: =IF(ISBLANK('42-2A Dual - BIG 4'!S24)," ",'42-2A Dual - BIG 4'!S24) | V24: =IFERROR(IF(ISBLANK(P24)," ",((ROUND(U24,2)-(ROUND(P24,2)))/(ROUND(P24,2))))," ") | X24: =IFERROR(IF(ISBLANK(P24)," ",((ROUND(W24,2)-(ROUND(P24,2)))/(ROUND(P24,2))))," ") | Y24: =IF(ISBLANK(W24)," ",(ROUND(W24,2)/0.995)) | Z24: =IF(ISBLANK('42-2A Dual - BIG 4'!W24)," ",IF((ROUND('42-2A Dual - BIG 4'!W24,2))<=(ROUND(W24,2)),"YES","NO")) | AO24: VI
A25: =IF(ISBLANK('42-2A Dual - BIG 4'!A25)," ",'42-2A Dual - BIG 4'!A25) | B25: =IF(ISBLANK('42-2A Dual - BIG 4'!B25)," ",'42-2A Dual - BIG 4'!B25) | C25: =IF(ISBLANK('42-2A Dual - BIG 4'!C25)," ",'42-2A Dual - BIG 4'!C25) | D25: =IF(ISBLANK('42-2A Dual - BIG 4'!D25)," ",'42-2A Dual - BIG 4'!D25) | E25: =IF(ISBLANK('42-2A Dual - BIG 4'!E25)," ",'42-2A Dual - BIG 4'!E25) | F25: =IF(ISBLANK('42-2A Dual - BIG 4'!F25)," ",'42-2A Dual - BIG 4'!F25) | G25: =IF(ISBLANK('42-2A Dual - BIG 4'!G25)," ",'42-2A Dual - BIG 4'!G25) | H25: =IF(ISBLANK('42-2A Dual - BIG 4'!H25)," ",'42-2A Dual - BIG 4'!H25) | ... S25: =IF(ISBLANK('42-2A Dual - BIG 4'!S25)," ",'42-2A Dual - BIG 4'!S25) | V25: =IFERROR(IF(ISBLANK(P25)," ",((ROUND(U25,2)-(ROUND(P25,2)))/(ROUND(P25,2))))," ") | X25: =IFERROR(IF(ISBLANK(P25)," ",((ROUND(W25,2)-(ROUND(P25,2)))/(ROUND(P25,2))))," ") | Y25: =IF(ISBLANK(W25)," ",(ROUND(W25,2)/0.995)) | Z25: =IF(ISBLANK('42-2A Dual - BIG 4'!W25)," ",IF((ROUND('42-2A Dual - BIG 4'!W25,2))<=(ROUND(W25,2)),"YES","NO"))
A26: =IF(ISBLANK('42-2A Dual - BIG 4'!A26)," ",'42-2A Dual - BIG 4'!A26) | B26: =IF(ISBLANK('42-2A Dual - BIG 4'!B26)," ",'42-2A Dual - BIG 4'!B26) | C26: =IF(ISBLANK('42-2A Dual - BIG 4'!C26)," ",'42-2A Dual - BIG 4'!C26) | D26: =IF(ISBLANK('42-2A Dual - BIG 4'!D26)," ",'42-2A Dual - BIG 4'!D26) | E26: =IF(ISBLANK('42-2A Dual - BIG 4'!E26)," ",'42-2A Dual - BIG 4'!E26) | F26: =IF(ISBLANK('42-2A Dual - BIG 4'!F26)," ",'42-2A Dual - BIG 4'!F26) | G26: =IF(ISBLANK('42-2A Dual - BIG 4'!G26)," ",'42-2A Dual - BIG 4'!G26) | H26: =IF(ISBLANK('42-2A Dual - BIG 4'!H26)," ",'42-2A Dual - BIG 4'!H26) | ... S26: =IF(ISBLANK('42-2A Dual - BIG 4'!S26)," ",'42-2A Dual - BIG 4'!S26) | V26: =IFERROR(IF(ISBLANK(P26)," ",((ROUND(U26,2)-(ROUND(P26,2)))/(ROUND(P26,2))))," ") | X26: =IFERROR(IF(ISBLANK(P26)," ",((ROUND(W26,2)-(ROUND(P26,2)))/(ROUND(P26,2))))," ") | Y26: =IF(ISBLANK(W26)," ",(ROUND(W26,2)/0.995)) | Z26: =IF(ISBLANK('42-2A Dual - BIG 4'!W26)," ",IF((ROUND('42-2A Dual - BIG 4'!W26,2))<=(ROUND(W26,2)),"YES","NO"))
A27: =IF(ISBLANK('42-2A Dual - BIG 4'!A27)," ",'42-2A Dual - BIG 4'!A27) | B27: =IF(ISBLANK('42-2A Dual - BIG 4'!B27)," ",'42-2A Dual - BIG 4'!B27) | C27: =IF(ISBLANK('42-2A Dual - BIG 4'!C27)," ",'42-2A Dual - BIG 4'!C27) | D27: =IF(ISBLANK('42-2A Dual - BIG 4'!D27)," ",'42-2A Dual - BIG 4'!D27) | E27: =IF(ISBLANK('42-2A Dual - BIG 4'!E27)," ",'42-2A Dual - BIG 4'!E27) | F27: =IF(ISBLANK('42-2A Dual - BIG 4'!F27)," ",'42-2A Dual - BIG 4'!F27) | G27: =IF(ISBLANK('42-2A Dual - BIG 4'!G27)," ",'42-2A Dual - BIG 4'!G27) | H27: =IF(ISBLANK('42-2A Dual - BIG 4'!H27)," ",'42-2A Dual - BIG 4'!H27) | ... S27: =IF(ISBLANK('42-2A Dual - BIG 4'!S27)," ",'42-2A Dual - BIG 4'!S27) | V27: =IFERROR(IF(ISBLANK(P27)," ",((ROUND(U27,2)-(ROUND(P27,2)))/(ROUND(P27,2))))," ") | X27: =IFERROR(IF(ISBLANK(P27)," ",((ROUND(W27,2)-(ROUND(P27,2)))/(ROUND(P27,2))))," ") | Y27: =IF(ISBLANK(W27)," ",(ROUND(W27,2)/0.995)) | Z27: =IF(ISBLANK('42-2A Dual - BIG 4'!W27)," ",IF((ROUND('42-2A Dual - BIG 4'!W27,2))<=(ROUND(W27,2)),"YES","NO"))
A28: =IF(ISBLANK('42-2A Dual - BIG 4'!A28)," ",'42-2A Dual - BIG 4'!A28) | B28: =IF(ISBLANK('42-2A Dual - BIG 4'!B28)," ",'42-2A Dual - BIG 4'!B28) | C28: =IF(ISBLANK('42-2A Dual - BIG 4'!C28)," ",'42-2A Dual - BIG 4'!C28) | D28: =IF(ISBLANK('42-2A Dual - BIG 4'!D28)," ",'42-2A Dual - BIG 4'!D28) | E28: =IF(ISBLANK('42-2A Dual - BIG 4'!E28)," ",'42-2A Dual - BIG 4'!E28) | F28: =IF(ISBLANK('42-2A Dual - BIG 4'!F28)," ",'42-2A Dual - BIG 4'!F28) | G28: =IF(ISBLANK('42-2A Dual - BIG 4'!G28)," ",'42-2A Dual - BIG 4'!G28) | H28: =IF(ISBLANK('42-2A Dual - BIG 4'!H28)," ",'42-2A Dual - BIG 4'!H28) | ... S28: =IF(ISBLANK('42-2A Dual - BIG 4'!S28)," ",'42-2A Dual - BIG 4'!S28) | V28: =IFERROR(IF(ISBLANK(P28)," ",((ROUND(U28,2)-(ROUND(P28,2)))/(ROUND(P28,2))))," ") | X28: =IFERROR(IF(ISBLANK(P28)," ",((ROUND(W28,2)-(ROUND(P28,2)))/(ROUND(P28,2))))," ") | Y28: =IF(ISBLANK(W28)," ",(ROUND(W28,2)/0.995)) | Z28: =IF(ISBLANK('42-2A Dual - BIG 4'!W28)," ",IF((ROUND('42-2A Dual - BIG 4'!W28,2))<=(ROUND(W28,2)),"YES","NO"))
A29: =IF(ISBLANK('42-2A Dual - BIG 4'!A29)," ",'42-2A Dual - BIG 4'!A29) | B29: =IF(ISBLANK('42-2A Dual - BIG 4'!B29)," ",'42-2A Dual - BIG 4'!B29) | C29: =IF(ISBLANK('42-2A Dual - BIG 4'!C29)," ",'42-2A Dual - BIG 4'!C29) | D29: =IF(ISBLANK('42-2A Dual - BIG 4'!D29)," ",'42-2A Dual - BIG 4'!D29) | E29: =IF(ISBLANK('42-2A Dual - BIG 4'!E29)," ",'42-2A Dual - BIG 4'!E29) | F29: =IF(ISBLANK('42-2A Dual - BIG 4'!F29)," ",'42-2A Dual - BIG 4'!F29) | G29: =IF(ISBLANK('42-2A Dual - BIG 4'!G29)," ",'42-2A Dual - BIG 4'!G29) | H29: =IF(ISBLANK('42-2A Dual - BIG 4'!H29)," ",'42-2A Dual - BIG 4'!H29) | ... S29: =IF(ISBLANK('42-2A Dual - BIG 4'!S29)," ",'42-2A Dual - BIG 4'!S29) | V29: =IFERROR(IF(ISBLANK(P29)," ",((ROUND(U29,2)-(ROUND(P29,2)))/(ROUND(P29,2))))," ") | X29: =IFERROR(IF(ISBLANK(P29)," ",((ROUND(W29,2)-(ROUND(P29,2)))/(ROUND(P29,2))))," ") | Y29: =IF(ISBLANK(W29)," ",(ROUND(W29,2)/0.995)) | Z29: =IF(ISBLANK('42-2A Dual - BIG 4'!W29)," ",IF((ROUND('42-2A Dual - BIG 4'!W29,2))<=(ROUND(W29,2)),"YES","NO"))
A30: =IF(ISBLANK('42-2A Dual - BIG 4'!A30)," ",'42-2A Dual - BIG 4'!A30) | B30: =IF(ISBLANK('42-2A Dual - BIG 4'!B30)," ",'42-2A Dual - BIG 4'!B30) | C30: =IF(ISBLANK('42-2A Dual - BIG 4'!C30)," ",'42-2A Dual - BIG 4'!C30) | D30: =IF(ISBLANK('42-2A Dual - BIG 4'!D30)," ",'42-2A Dual - BIG 4'!D30) | E30: =IF(ISBLANK('42-2A Dual - BIG 4'!E30)," ",'42-2A Dual - BIG 4'!E30) | F30: =IF(ISBLANK('42-2A Dual - BIG 4'!F30)," ",'42-2A Dual - BIG 4'!F30) | G30: =IF(ISBLANK('42-2A Dual - BIG 4'!G30)," ",'42-2A Dual - BIG 4'!G30) | H30: =IF(ISBLANK('42-2A Dual - BIG 4'!H30)," ",'42-2A Dual - BIG 4'!H30) | ... S30: =IF(ISBLANK('42-2A Dual - BIG 4'!S30)," ",'42-2A Dual - BIG 4'!S30) | V30: =IFERROR(IF(ISBLANK(P30)," ",((ROUND(U30,2)-(ROUND(P30,2)))/(ROUND(P30,2))))," ") | X30: =IFERROR(IF(ISBLANK(P30)," ",((ROUND(W30,2)-(ROUND(P30,2)))/(ROUND(P30,2))))," ") | Y30: =IF(ISBLANK(W30)," ",(ROUND(W30,2)/0.995)) | Z30: =IF(ISBLANK('42-2A Dual - BIG 4'!W30)," ",IF((ROUND('42-2A Dual - BIG 4'!W30,2))<=(ROUND(W30,2)),"YES","NO"))
A31: =IF(ISBLANK('42-2A Dual - BIG 4'!A31)," ",'42-2A Dual - BIG 4'!A31) | B31: =IF(ISBLANK('42-2A Dual - BIG 4'!B31)," ",'42-2A Dual - BIG 4'!B31) | C31: =IF(ISBLANK('42-2A Dual - BIG 4'!C31)," ",'42-2A Dual - BIG 4'!C31) | D31: =IF(ISBLANK('42-2A Dual - BIG 4'!D31)," ",'42-2A Dual - BIG 4'!D31) | E31: =IF(ISBLANK('42-2A Dual - BIG 4'!E31)," ",'42-2A Dual - BIG 4'!E31) | F31: =IF(ISBLANK('42-2A Dual - BIG 4'!F31)," ",'42-2A Dual - BIG 4'!F31) | G31: =IF(ISBLANK('42-2A Dual - BIG 4'!G31)," ",'42-2A Dual - BIG 4'!G31) | H31: =IF(ISBLANK('42-2A Dual - BIG 4'!H31)," ",'42-2A Dual - BIG 4'!H31) | ... S31: =IF(ISBLANK('42-2A Dual - BIG 4'!S31)," ",'42-2A Dual - BIG 4'!S31) | V31: =IFERROR(IF(ISBLANK(P31)," ",((ROUND(U31,2)-(ROUND(P31,2)))/(ROUND(P31,2))))," ") | X31: =IFERROR(IF(ISBLANK(P31)," ",((ROUND(W31,2)-(ROUND(P31,2)))/(ROUND(P31,2))))," ") | Y31: =IF(ISBLANK(W31)," ",(ROUND(W31,2)/0.995)) | Z31: =IF(ISBLANK('42-2A Dual - BIG 4'!W31)," ",IF((ROUND('42-2A Dual - BIG 4'!W31,2))<=(ROUND(W31,2)),"YES","NO"))
A32: =IF(ISBLANK('42-2A Dual - BIG 4'!A32)," ",'42-2A Dual - BIG 4'!A32) | B32: =IF(ISBLANK('42-2A Dual - BIG 4'!B32)," ",'42-2A Dual - BIG 4'!B32) | C32: =IF(ISBLANK('42-2A Dual - BIG 4'!C32)," ",'42-2A Dual - BIG 4'!C32) | D32: =IF(ISBLANK('42-2A Dual - BIG 4'!D32)," ",'42-2A Dual - BIG 4'!D32) | E32: =IF(ISBLANK('42-2A Dual - BIG 4'!E32)," ",'42-2A Dual - BIG 4'!E32) | F32: =IF(ISBLANK('42-2A Dual - BIG 4'!F32)," ",'42-2A Dual - BIG 4'!F32) | G32: =IF(ISBLANK('42-2A Dual - BIG 4'!G32)," ",'42-2A Dual - BIG 4'!G32) | H32: =IF(ISBLANK('42-2A Dual - BIG 4'!H32)," ",'42-2A Dual - BIG 4'!H32) | ... S32: =IF(ISBLANK('42-2A Dual - BIG 4'!S32)," ",'42-2A Dual - BIG 4'!S32) | V32: =IFERROR(IF(ISBLANK(P32)," ",((ROUND(U32,2)-(ROUND(P32,2)))/(ROUND(P32,2))))," ") | X32: =IFERROR(IF(ISBLANK(P32)," ",((ROUND(W32,2)-(ROUND(P32,2)))/(ROUND(P32,2))))," ") | Y32: =IF(ISBLANK(W32)," ",(ROUND(W32,2)/0.995)) | Z32: =IF(ISBLANK('42-2A Dual - BIG 4'!W32)," ",IF((ROUND('42-2A Dual - BIG 4'!W32,2))<=(ROUND(W32,2)),"YES","NO"))
A33: =IF(ISBLANK('42-2A Dual - BIG 4'!A33)," ",'42-2A Dual - BIG 4'!A33) | B33: =IF(ISBLANK('42-2A Dual - BIG 4'!B33)," ",'42-2A Dual - BIG 4'!B33) | C33: =IF(ISBLANK('42-2A Dual - BIG 4'!C33)," ",'42-2A Dual - BIG 4'!C33) | D33: =IF(ISBLANK('42-2A Dual - BIG 4'!D33)," ",'42-2A Dual - BIG 4'!D33) | E33: =IF(ISBLANK('42-2A Dual - BIG 4'!E33)," ",'42-2A Dual - BIG 4'!E33) | F33: =IF(ISBLANK('42-2A Dual - BIG 4'!F33)," ",'42-2A Dual - BIG 4'!F33) | G33: =IF(ISBLANK('42-2A Dual - BIG 4'!G33)," ",'42-2A Dual - BIG 4'!G33) | H33: =IF(ISBLANK('42-2A Dual - BIG 4'!H33)," ",'42-2A Dual - BIG 4'!H33) | ... S33: =IF(ISBLANK('42-2A Dual - BIG 4'!S33)," ",'42-2A Dual - BIG 4'!S33) | V33: =IFERROR(IF(ISBLANK(P33)," ",((ROUND(U33,2)-(ROUND(P33,2)))/(ROUND(P33,2))))," ") | X33: =IFERROR(IF(ISBLANK(P33)," ",((ROUND(W33,2)-(ROUND(P33,2)))/(ROUND(P33,2))))," ") | Y33: =IF(ISBLANK(W33)," ",(ROUND(W33,2)/0.995)) | Z33: =IF(ISBLANK('42-2A Dual - BIG 4'!W33)," ",IF((ROUND('42-2A Dual - BIG 4'!W33,2))<=(ROUND(W33,2)),"YES","NO"))
A34: =IF(ISBLANK('42-2A Dual - BIG 4'!A34)," ",'42-2A Dual - BIG 4'!A34) | B34: =IF(ISBLANK('42-2A Dual - BIG 4'!B34)," ",'42-2A Dual - BIG 4'!B34) | C34: =IF(ISBLANK('42-2A Dual - BIG 4'!C34)," ",'42-2A Dual - BIG 4'!C34) | D34: =IF(ISBLANK('42-2A Dual - BIG 4'!D34)," ",'42-2A Dual - BIG 4'!D34) | E34: =IF(ISBLANK('42-2A Dual - BIG 4'!E34)," ",'42-2A Dual - BIG 4'!E34) | F34: =IF(ISBLANK('42-2A Dual - BIG 4'!F34)," ",'42-2A Dual - BIG 4'!F34) | G34: =IF(ISBLANK('42-2A Dual - BIG 4'!G34)," ",'42-2A Dual - BIG 4'!G34) | H34: =IF(ISBLANK('42-2A Dual - BIG 4'!H34)," ",'42-2A Dual - BIG 4'!H34) | ... S34: =IF(ISBLANK('42-2A Dual - BIG 4'!S34)," ",'42-2A Dual - BIG 4'!S34) | V34: =IFERROR(IF(ISBLANK(P34)," ",((ROUND(U34,2)-(ROUND(P34,2)))/(ROUND(P34,2))))," ") | X34: =IFERROR(IF(ISBLANK(P34)," ",((ROUND(W34,2)-(ROUND(P34,2)))/(ROUND(P34,2))))," ") | Y34: =IF(ISBLANK(W34)," ",(ROUND(W34,2)/0.995)) | Z34: =IF(ISBLANK('42-2A Dual - BIG 4'!W34)," ",IF((ROUND('42-2A Dual - BIG 4'!W34,2))<=(ROUND(W34,2)),"YES","NO"))
A35: =IF(ISBLANK('42-2A Dual - BIG 4'!A35)," ",'42-2A Dual - BIG 4'!A35) | B35: =IF(ISBLANK('42-2A Dual - BIG 4'!B35)," ",'42-2A Dual - BIG 4'!B35) | C35: =IF(ISBLANK('42-2A Dual - BIG 4'!C35)," ",'42-2A Dual - BIG 4'!C35) | D35: =IF(ISBLANK('42-2A Dual - BIG 4'!D35)," ",'42-2A Dual - BIG 4'!D35) | E35: =IF(ISBLANK('42-2A Dual - BIG 4'!E35)," ",'42-2A Dual - BIG 4'!E35) | F35: =IF(ISBLANK('42-2A Dual - BIG 4'!F35)," ",'42-2A Dual - BIG 4'!F35) | G35: =IF(ISBLANK('42-2A Dual - BIG 4'!G35)," ",'42-2A Dual - BIG 4'!G35) | H35: =IF(ISBLANK('42-2A Dual - BIG 4'!H35)," ",'42-2A Dual - BIG 4'!H35) | ... S35: =IF(ISBLANK('42-2A Dual - BIG 4'!S35)," ",'42-2A Dual - BIG 4'!S35) | V35: =IFERROR(IF(ISBLANK(P35)," ",((ROUND(U35,2)-(ROUND(P35,2)))/(ROUND(P35,2))))," ") | X35: =IFERROR(IF(ISBLANK(P35)," ",((ROUND(W35,2)-(ROUND(P35,2)))/(ROUND(P35,2))))," ") | Y35: =IF(ISBLANK(W35)," ",(ROUND(W35,2)/0.995)) | Z35: =IF(ISBLANK('42-2A Dual - BIG 4'!W35)," ",IF((ROUND('42-2A Dual - BIG 4'!W35,2))<=(ROUND(W35,2)),"YES","NO"))
A36: =IF(ISBLANK('42-2A Dual - BIG 4'!A36)," ",'42-2A Dual - BIG 4'!A36) | B36: =IF(ISBLANK('42-2A Dual - BIG 4'!B36)," ",'42-2A Dual - BIG 4'!B36) | C36: =IF(ISBLANK('42-2A Dual - BIG 4'!C36)," ",'42-2A Dual - BIG 4'!C36) | D36: =IF(ISBLANK('42-2A Dual - BIG 4'!D36)," ",'42-2A Dual - BIG 4'!D36) | E36: =IF(ISBLANK('42-2A Dual - BIG 4'!E36)," ",'42-2A Dual - BIG 4'!E36) | F36: =IF(ISBLANK('42-2A Dual - BIG 4'!F36)," ",'42-2A Dual - BIG 4'!F36) | G36: =IF(ISBLANK('42-2A Dual - BIG 4'!G36)," ",'42-2A Dual - BIG 4'!G36) | H36: =IF(ISBLANK('42-2A Dual - BIG 4'!H36)," ",'42-2A Dual - BIG 4'!H36) | ... S36: =IF(ISBLANK('42-2A Dual - BIG 4'!S36)," ",'42-2A Dual - BIG 4'!S36) | V36: =IFERROR(IF(ISBLANK(P36)," ",((ROUND(U36,2)-(ROUND(P36,2)))/(ROUND(P36,2))))," ") | X36: =IFERROR(IF(ISBLANK(P36)," ",((ROUND(W36,2)-(ROUND(P36,2)))/(ROUND(P36,2))))," ") | Y36: =IF(ISBLANK(W36)," ",(ROUND(W36,2)/0.995)) | Z36: =IF(ISBLANK('42-2A Dual - BIG 4'!W36)," ",IF((ROUND('42-2A Dual - BIG 4'!W36,2))<=(ROUND(W36,2)),"YES","NO"))
... A1002: =IF(ISBLANK('42-2A Dual - BIG 4'!A1002)," ",'42-2A Dual - BIG 4'!A1002) | B1002: =IF(ISBLANK('42-2A Dual - BIG 4'!B1002)," ",'42-2A Dual - BIG 4'!B1002) | C1002: =IF(ISBLANK('42-2A Dual - BIG 4'!C1002)," ",'42-2A Dual - BIG 4'!C1002) | D1002: =IF(ISBLANK('42-2A Dual - BIG 4'!D1002)," ",'42-2A Dual - BIG 4'!D1002) | E1002: =IF(ISBLANK('42-2A Dual - BIG 4'!E1002)," ",'42-2A Dual - BIG 4'!E1002) | F1002: =IF(ISBLANK('42-2A Dual - BIG 4'!F1002)," ",'42-2A Dual - BIG 4'!F1002) | G1002: =IF(ISBLANK('42-2A Dual - BIG 4'!G1002)," ",'42-2A Dual - BIG 4'!G1002) | H1002: =IF(ISBLANK('42-2A Dual - BIG 4'!H1002)," ",'42-2A Dual - BIG 4'!H1002) | ... S1002: =IF(ISBLANK('42-2A Dual - BIG 4'!S1002)," ",'42-2A Dual - BIG 4'!S1002) | V1002: =IFERROR(IF(ISBLANK(P1002)," ",((ROUND(U1002,2)-(ROUND(P1002,2)))/(ROUND(P1002,2))))," ") | X1002: =IFERROR(IF(ISBLANK(P1002)," ",((ROUND(W1002,2)-(ROUND(P1002,2)))/(ROUND(P1002,2))))," ") | Y1002: =IF(ISBLANK(W1002)," ",(ROUND(W1002,2)/0.995)) | Z1002: =IF(ISBLANK('42-2A Dual - BIG 4'!W1002)," ",IF((ROUND('42-2A Dual - BIG 4'!W1002,2))<=(ROUND(W1002,2)),"YES","NO"))

Sheet Definitions & Examples
A2: Column G - Package Size: Quantity in Unit of Sale x Quantity in Unit of Package
A4: Columns H & J - Unit of Sale & Unit Package | D4: Column L - Unit of Measure
A5: AM | B5: Ampule | D5: EA | E5: Each
A6: BG | B6: Bag | D6: F2 | E6: Square Feet
A7: BO | B7: Bottle | D7: GM | E7: Gram
A8: BX | B8: Box | D8: IN | E8: Inch
A9: CA | B9: Case | D9: LT | E9: Liter
A10: CH | B10: Container | D10: ML | E10: Milliliter
A11: CL | B11: Cylinder
A12: CN | B12: Can
A13: CQ | B13: Cartridge
A14: CT | B14: Carton
A15: DR | B15: Drum
A16: EA | B16: Each
A17: KT | B17: Kit
A18: PC | B18: Piece
A19: PK | B19: Package
A20: RL | B20: Roll
A21: TB | B21: Tube
A22: VI | B22: Vial
A24: EXAMPLES:
A25: Note: There is no column for strength. It is to be included with the generic and trade names.
A27: Generic Name / Strength | B27: Trade Name / Strength | C27: Package Size | D27: Unit of Sale | E27: Unit of Pkg | F27: Unit of Measure
A29: XXXXXX / 30mg | B29: XXXXXX / 30mg | C29: 1 x 100 | D29: BO | E29: BO | F29: EA
A30: FSS Price is for one bottle containing 100 tablets of 30 mg each.
A33: XXXXXX / 25mg | B33: XXXXXX / 25mg | C33: 10 x 100 | D33: CA | E33: BO | F33: EA
A34: FSS Price is for one case containing 10 boxes of bottles which contain 100 capsules of 25 mg each.
A37: XXXXXX / 0.3% | B37: XXXXXX / 0.3% | C37: 1 x 6 | D37: VI | E37: VI | F37: ML
A38: FSS Price is for one vial containing 6 ml of 0.3% solution.
A41: XXXXXX / 0.3% | B41: XXXXXX / 0.3% | C41: 5 x 6 | D41: BX | E41: VI | F41: ML
A42: FSS Price is for one box containing 5 vials, 6 ml each, of 0.3% solution.
A45: XXXXXX / 0.2% | B45: XXXXXX / 0.2% | C45: 1 x 150 | D45: BO | E45: BO | F45: ML
A46: FSS Price is for one bottle containing 150 ml of 2% suspension.
A49: XXXXXX / 0.1% | B49: XXXXXX / 0.1% | C49: 50 x 150 | D49: CA | E49: BO | F49: ML
A50: FSS Price is for one case of 50 bottles containing 150ml each of 1% strength.
A53: XXXXXX / 0.1% | B53: XXXXXX / 0.1% | C53: 1 x 5 | D53: TB | E53: TB | F53: GM
A54: FSS Price is for one, 5 gram tube containing 1% strength.

Sheet Figure 515.4-2 CSP-1
A1: FIGURE 515.4-2
A2: The Government expects you to provide information required by the format in accordance with the solicitation instructions for Figure 515.4-2 that is, to the best of your knowledge and belief, current, accurate, and complete as of 60 calendar days prior to its submission. The data provided in the price proposal tab and Figure 515.4-2 is current, accurate, and complete as of (enter date in cell to the right). | D2: Enter date in this cell based on instructions to the left.
A3: Provide the date range which represents the start and end date of the transactional data used to populate the MFC and TC columns on the Price Proposal tab as well as Figure 515.4-2 below (enter date in cell to the right). | D3: Enter date range (start and end date) in this cell based on instructions to the left.
A4: Indicate if you have limited your disclosures below to the number of models or product lines which exceed 75% of the actual historical Government sales (commercial sales may be substituted if Government sales are unavailable) value of the special item number (SIN) (enter date in cell to the right). | D4: Enter Yes or No in this cell based on instructions to the left.
A5: Column 1 - Customer | B5: Column 2 - Discount | C5: Column 3 - Quantity/Volume | D5: Column 4 - FOB Terms | E5: Column 5 - Additional Discounts or Concessions
A19: Please reference the instructions for this Figure in the CSP-1 section of the solicitation and in the "Contractor Guide to CSP"
A20: found on our Training web page under the "Prospective Contractors - Solicitation Assistance" section at:
A21: https://www.va.gov/oal/business/fss/training.asp

Sheet NonManufacturers
A2: SIN# | B2: Mfr Name | C2: Mfr Part # | D2: Dealer/Reseller Part # | E2: Product Description | F2: Mfr List Price | G2: Dealer/Reseller % discount off Mfr. List Price
O3: 42-1
O4: 42-2A
O5: 42-2B
O6: 42-3
O7: 42-5
O8: 622
O9: INP

Sheet Country Codes
A1: Country | B1: Code
A2: Afghanistan | B2: AF
A3: Albania | B3: AL
A4: Alberta | B4: XA
A5: Algeria | B5: DZ
A6: American Samoa | B6: AS
A7: Andorra | B7: AD
A8: Angola | B8: AO
A9: Anguilla | B9: AI
A10: Antigua & Barbuda | B10: AG
A11: APO Customs Mail Entry Only | B11: AP
A12: Argentina | B12: AR
... A264: Zimbabwe | B264: ZW

Sheet Price Analysis
J1: BIG 4 | N1: BIG 4 Price Analysis | R1: OGA | U1: OGA Price Analysis
A2: SIN# | B2: NDC1 | C2: NDC2 | D2: NDC3 | E2: Commercial List Price ($) | F2: MFC Price ($) | G2: MFC % Off Comm. List Price | H2: Proposed BIG 4 TC Price ($) | I2: BIG 4 TC % Off Comm. List Price | J2: Proposed BIG 4 Price ($) without IFF | K2: Proposed BIG 4 % Off Comm. Price w/out IFF | L2: FCP Price | M2: Is Proposed BIG 4 Price (w/out IFF) Less Than or Equal to MFC? | N2: Is Proposed BIG 4 Price (w/out IFF) Less Than or Equal to FCP? | O2: Is Proposed BIG 4 Price (w/out IFF) Less Than or Equal to OGA Price (w/out IFF) | P2: Proposed TC Ratio | Q2: Proposed OGA TC Price ($) | R2: OGA TC % Off Comm. List Price | S2: Proposed OGA Price ($) without IFF | T2: Proposed OGA % Off Comm. Price w/out IFF | U2: Is Proposed OGA Price (w/out IFF) Less Than or Equal to MFC? | V2: Proposed TC Ratio
A3: =IF(ISBLANK('42-2A Dual - BIG 4'!A3)," ",'42-2A Dual - BIG 4'!A3) | B3: =IF(ISBLANK('42-2A Dual - BIG 4'!B3)," ",'42-2A Dual - BIG 4'!B3) | C3: =IF(ISBLANK('42-2A Dual - BIG 4'!C3)," ",'42-2A Dual - BIG 4'!C3) | D3: =IF(ISBLANK('42-2A Dual - BIG 4'!D3)," ",'42-2A Dual - BIG 4'!D3) | E3: =IF(ISBLANK('42-2A Dual - BIG 4'!P3)," ",'42-2A Dual - BIG 4'!P3) | F3: =IF(ISBLANK('42-2A Dual - BIG 4'!Q3)," ",'42-2A Dual - BIG 4'!Q3) | G3: =IF(ISBLANK('42-2A Dual - BIG 4'!R3)," ",'42-2A Dual - BIG 4'!R3) | H3: =IF(ISBLANK('42-2A Dual - BIG 4'!U3)," ",'42-2A Dual - BIG 4'!U3) | I3: =IF(ISBLANK('42-2A Dual - BIG 4'!V3)," ",'42-2A Dual - BIG 4'!V3) | J3: =IF(ISBLANK('42-2A Dual - BIG 4'!W3)," ",'42-2A Dual - BIG 4'!W3) | K3: =IF(ISBLANK('42-2A Dual - BIG 4'!X3)," ",'42-2A Dual - BIG 4'!X3) | L3: =IF(ISBLANK('42-2A Dual - BIG 4'!Z3)," ",'42-2A Dual - BIG 4'!Z3) | M3: =IFERROR(IF((ROUND(J3,2))<=(ROUND(F3,2)),"YES","NO")," ") | N3: =IFERROR(IF((ROUND(J3,2))<=(ROUND(L3,2)),"YES","NO")," ") | O3: =IFERROR(IF((ROUND(J3,2))<=(ROUND(S3,2)),"YES","NO")," ") | P3: =IFERROR(IF(ISBLANK(J3)," ",(ROUND(J3,2))/(ROUND(H3,2)))," ") | Q3: =IF(ISBLANK('42-2A Dual - OGA'!U3)," ",'42-2A Dual - OGA'!U3) | R3: =IF(ISBLANK('42-2A Dual - OGA'!V3)," ",'42-2A Dual - OGA'!V3) | S3: =IF(ISBLANK('42-2A Dual - OGA'!W3)," ",'42-2A Dual - OGA'!W3) | T3: =IF(ISBLANK('42-2A Dual - OGA'!X3)," ",'42-2A Dual - OGA'!X3) | U3: =IFERROR(IF((ROUND(S3,2))<=(ROUND(F3,2)),"YES","NO")," ") | V3: =IFERROR(IF(ISBLANK(S3)," ",(ROUND(S3,2))/(ROUND(Q3,2)))," ")
A4: =IF(ISBLANK('42-2A Dual - BIG 4'!A4)," ",'42-2A Dual - BIG 4'!A4) | B4: =IF(ISBLANK('42-2A Dual - BIG 4'!B4)," ",'42-2A Dual - BIG 4'!B4) | C4: =IF(ISBLANK('42-2A Dual - BIG 4'!C4)," ",'42-2A Dual - BIG 4'!C4) | D4: =IF(ISBLANK('42-2A Dual - BIG 4'!D4)," ",'42-2A Dual - BIG 4'!D4) | E4: =IF(ISBLANK('42-2A Dual - BIG 4'!P4)," ",'42-2A Dual - BIG 4'!P4) | F4: =IF(ISBLANK('42-2A Dual - BIG 4'!Q4)," ",'42-2A Dual - BIG 4'!Q4) | G4: =IF(ISBLANK('42-2A Dual - BIG 4'!R4)," ",'42-2A Dual - BIG 4'!R4) | H4: =IF(ISBLANK('42-2A Dual - BIG 4'!U4)," ",'42-2A Dual - BIG 4'!U4) | I4: =IF(ISBLANK('42-2A Dual - BIG 4'!V4)," ",'42-2A Dual - BIG 4'!V4) | J4: =IF(ISBLANK('42-2A Dual - BIG 4'!W4)," ",'42-2A Dual - BIG 4'!W4) | K4: =IF(ISBLANK('42-2A Dual - BIG 4'!X4)," ",'42-2A Dual - BIG 4'!X4) | L4: =IF(ISBLANK('42-2A Dual - BIG 4'!Z4)," ",'42-2A Dual - BIG 4'!Z4) | M4: =IFERROR(IF((ROUND(J4,2))<=(ROUND(F4,2)),"YES","NO")," ") | N4: =IFERROR(IF((ROUND(J4,2))<=(ROUND(L4,2)),"YES","NO")," ") | O4: =IFERROR(IF((ROUND(J4,2))<=(ROUND(S4,2)),"YES","NO")," ") | P4: =IFERROR(IF(ISBLANK(J4)," ",(ROUND(J4,2))/(ROUND(H4,2)))," ") | Q4: =IF(ISBLANK('42-2A Dual - OGA'!U4)," ",'42-2A Dual - OGA'!U4) | R4: =IF(ISBLANK('42-2A Dual - OGA'!V4)," ",'42-2A Dual - OGA'!V4) | S4: =IF(ISBLANK('42-2A Dual - OGA'!W4)," ",'42-2A Dual - OGA'!W4) | T4: =IF(ISBLANK('42-2A Dual - OGA'!X4)," ",'42-2A Dual - OGA'!X4) | U4: =IFERROR(IF((ROUND(S4,2))<=(ROUND(F4,2)),"YES","NO")," ") | V4: =IFERROR(IF(ISBLANK(S4)," ",(ROUND(S4,2))/(ROUND(Q4,2)))," ")
