Workbook
Name ARMOR_KIT_TARGET: #REF!
Name AUMC_TARGET: #REF!
Name BETA_1: #REF!
Name BETA_1old: #REF!
Name BETA_2: #REF!
Name BETA_3: #REF!
Name BETA_4: #REF!
Name BETA_4old: #REF!
Name BETA_5: #REF!
Name BETA_5old: #REF!
Name BETA_6: #REF!
Name BETA_7: #REF!
Name bin: #REF!
Name bin: #REF!
Name bin: #REF!
Name bin: #REF!
Name bin: #REF!
Name CFE_KIT_TARGET: #REF!
Name CFEA_Target: #REF!
Name CLIN: #REF!
Name CLIN10: #REF!
Name COC: '[6]CS by Year - Max Executable'!$B:$B
Name COMBINED: '[6](3.1) Cost Summary - FRP 10 NTE'!$U:$U
Name CONT_OPER_RATIO: #REF!
Name CONT_OPTEMPO_RATIO: #REF!
Name CONTRACT: '[6](3.1) Cost Summary - FRP 10 NTE'!$A:$A
Name COST: #REF!
Name COSTYEAR: '[6]CS by Year - Max Executable'!$O:$O
Name cv: #REF!
Name cv: #REF!
Name cv: #REF!
Name data: #REF!
Name data: #REF!
Name data: #REF!
Name Esc_Carson: #REF!
Name Esc_EXE: #REF!
Name Esc_Irwin: #REF!
Name Esc_JBLM: #REF!
Name Esc_OCONUS: #REF!
Name Esc_WD: #REF!
Name Esc_WSMR: #REF!
Name FCCOM: #REF!
Name FCCOMYEAR: '[6]CS by Year - Max Executable'!$P:$P
Name FPR_AFMOH: #REF!
Name FPR_GA: #REF!
Name FPR_GSOH: #REF!
Name Frng_Carson: #REF!
Name Frng_CBA: #REF!
Name Frng_CBA_HW: #REF!
Name Frng_CONUS: #REF!
Name Frng_EXE: #REF!
Name Frng_EXE_HW: #REF!
Name Frng_Irwin: #REF!
Name Frng_JBLM: #REF!
Name Frng_OCO: #REF!
Name Frng_OCO_OT: #REF!
Name Frng_OCONUS: #REF!
Name Frng_OT: #REF!
Name Frng_WD: #REF!
Name Frng_WD_HW: #REF!

Sheet Template Instructions
A1: AFM East Region
A2: Solicitation No.: | B2: Insert Solicitation Number
A3: Prime Offeror Name: | B3: Insert Prime Offeror Company name
A4: CAGE Code: | B4: Insert Prime Offeror Cage Code
A5: Subcontractor Name: | B5: Insert Sub Name (if applicable)
A7: General Information: The offeror may edit the worksheets to accomodate the offeror's normal accounting and estimating practices; however, the general format of the Cost-Price Template shall remain intact for evaluation purposes. Some Tabs have been pre-populated with formulas to aid the offeror in calculating the proposed price. The offeror is responsible for ensuring that all calculations within each TAB are accurate and reflective of the offeror's proposed price. Separate T&M Rate Table/ worksheets SHALL be completed for every subcontractor, division, subsidiary, and affiliate proposed (The offeror SHALL NOT propose blended prime/subcontract labor rates, prime/division labor rates, prime/subsidiary labor rates, or prime/affiliate labor rates).
A8: Offerors are responsible for ensuring that all calculations are accurate and flow throughout the workbook as required.
A10: TAB # | B10: TAB Title | C10: Cost-Price Template Instructions
A11: 1 | B11: TAB 1. T&M Labor Hours | C11: The Prime Offeror shall utilize the labor hours per labor category and CLIN as delineated in Tab 1. The Offeror shall allocate the TAB 1. labor hours to each team member requiring the use of a given labor category in support of this requirement and in accordance with the Offeror's proposed team structure. The sum of all labor hours proposed (Prime and subcontractor) for each labor category shall equal the labor hours by labor category detailed in TAB 1. The labor hours provided in this TAB are for proposal purposes only.
A13: 2 | B13: TAB 2a. "T&M Schedule_Prime_CONUS" | C13: The Prime Offeror shall enter the proposed CONUS Base Labor Rates, Proposed Health & Welfare rate/hr. (as applicable), Proposed T&M FBLRs, allocated labor hours and total price for each labor category, location and CLIN in the yellow highlighted cells. The Offeror shall provide the requested SCLS (WD/CBA) information for each applicable labor category, location and contract period.
A15: 2a. | B15: T&M Schedule_Prime_OCONUS | C15: The Prime Offeror shall enter the proposed OCONUS T&M FBLRs, allocated labor hours and total price for each labor category, location and CLIN in the yellow highlighted cells.
A17: 3a-3z | B17: T&M Schedule_SUBX_CONUS and T&M Schedule_SUBX_OCONUS | C17: Enter the proposed Subcontractor CONUS and OCONUS T&M FBLRs (through Prime contractor pass-through), allocated labor hours and total price for each labor category, location and CLIN in the yellow highlighted cells of the applicable Tabs. In addition, the Offeror shall provide the requested SCLS (WD/CBA) information for each applicable CONUS labor category. The Prime offeror shall apply the subcontractors proposed FBLRs to the allocated subcontractor labr hours to establish the proposed subcontractors labor price . A separate T&M Rate Table worksheet should be completed for every subcontractor, division, subsidiary, and affiliate proposed (The offeror SHALL NOT propose blended prime/subcontract labor rates, prime/division labor rates, prime/subsidiary labor rates, or prime/affiliate labor rates). The Offeror may need to add additional "T&M_Rate Table SubX" worksheets to accommodate the Offeror's proposed contracting team structure.
A19: 4 | B19: T&M Labor Summary | C19: Enter the requested data in the yellow shaded cells to show the proposed T&M labor price for the prime and each subcontractor for each CLIN. The Offeror is required to provide separate rate tables for each subcontractor, division, subsidiary, and affiliate proposed; therefore, it may be necessary for the Offeror to revise the number of rows to reflect the Offeror's proposed team structure.
A21: 5 | B21: CPFF Labor Hours | C21: The Prime Offeror shall utilize the labor hours per labor category as delineated in Tab 5 for the CPFF CLINs. The Offeror shall allocate the TAB 5. CPFF labor hours to each team member requiring the use of a given labor category in support of this requirement and in accordance with the Offeror's proposed team structure. The sum of all labor hours proposed (Prime and subcontractor) for each labor category shall equal the labor hours by labor category detailed in TAB 5. The labor hours provided in this TAB are for proposal purposes only.
A23: 6a. | B23: CPFF Direct Labor Mapping | C23: The direct labor mapping worksheet is intended for use in the development of the Prime CPFF cost estimate detail and fully burdened labor rate Tables. The labor category mapping is intended for use in populating the offeror's proposed base labor rates into the Direct Labor Base Rates worksheet. (1) Enter the offeror's contractor fiscal year (CFY) from and to dates. (2) Enter the proposed mapping of RFP provided labor categories to the offeror's contractor/corporate labor categories with minimum education and experience to demonstrate that the offeror is proposing qualified CPFF personnel for the effort. Insert additional rows as needed, ensuring the formulas for calculating the "Direct Labor Base Rates" are updated to include the added rows. Also, verify the added rows are included in the calculation of the total of the allocation percentages in the "Percentage Total" row at the bottom of the Labor Category Mapping Total. (3) For every RFP provided abor category identified, calculate the offeror's proposed base labor rate for the CFY identified. (4) If a particular RFP directed labor category rate is a composite of more than one of the offeror’s contractor/corporate labor categories, the offeror shall provide the calculation of the composite with the assigned weightings, identifying percentages the contractor/corporate labor categories are anticipated to work in the RFP labor categories. If a particular RFP directed labor category is comprised of only one contractor/corporate labor category, the offeror shall provide the crosswalk to the offeror’s single contractor/corporate labor category and assign a weighting of 100 percent. Ensure the "Percentage Total" equals 100%. If a "No" is identified in the "Percentage Total = 100" row, ensure: (i) the allocation percentages are correctly identified to contractor/corporate labor categories and (ii) the calculation of the allocation percentage, in the "Percentage Total" row, includes any added rows. (5) The labor rates, identified in the "Base Direct Labor Rates" row shall be used to populate the "Direct Labor Base Rates" worksheet tab 6b. Enter the requested data in the yellow shaded cells. CFY= Contractor Fiscal Year CY= Calendar Year (Jan-Dec)
A25: 6b. | B25: Direct Labor Base Rates | C25: (1) Input the offeror's CFY from and to dates. (2) Provide the offeror's proposed base rates by CFY, identifying the applicable CFY in columns B and C. The direct labor base rates identified in Column B should be equivalent to the direct labor base rates derived in Tab "6a. CPFF Direct Labor Mapping". (3) Input formulas to show the conversion of CFY rates to CY rates for the Base period of performance. (4) Insert the prposed escalation rate for the remaining contract years/CLINs (Option 1-Option 9). (5) The resulting contract period rates are the rates that shall be used to populate and/or calculate the "Tab 6d. CPFF Estimate Detail" and "Tab 6e. CPFF FBLRs" worksheets.
A27: 6c. | B27: Indirect Rates and Fee | C27: "Indirect Rates" Table 1) The Offeror shall input the offeror's CFY from and to dates. (2) The Offeror shall enter the offeror's proposed indirect rates by CFY, identifying the CFY (change the "XXXX" in "CFY XXXX" to the applicable CFY year) in each applicable column. (3) The Offeror shall enter formulas in the appropriate cells to show the conversion of CFY rates to contract period rates. The resulting contract period rates are the rates that shall be used to populate and/or calculate the CPFF Estimate Detail and CPFF FBLRs worksheets. "Fixed Fee" Table (1) The offeror shall enter the fixed fee proposed for the Prime CPFF labor, Prime proposed fixed fee on subcontractor CPFF labor (as applicable) and Subcontractor proposed fixed fee on subcontractor CPFF labor (as applicable).
A29: 6d. | B29: CPFF Estimate Detail | C29: (1) For each CPFF CLIN the Offeror shall insert the proposed labor category, direct labor base rate, estimated labor hours, subcontractor proposed rates, applicable indirect rates (burdens) and proposed fixed fee by contract period/CLIN. (2) The direct labor base rate(s)/hr. and applicable indirect rates shall be equivalent to the direct labor base rates and indirect rates developed in Tab "6b. Direct Labor Base Rates" and Tab "6c. Indirect Rates" for each contract period/CLIN. (3) Each subcontractor proposed to support a CPFF CLIN(s) shall provide "Tab 6d. CPFF Estimate Detail" in the required fully disclosed Cost/Price volume as applicable (Refer to RFP Section L.X.X for subcontractor cost/price volume instructions). (3) The offeror shall input/edit formulas to show how the total proposed price is calculated for each contract period/CLIN. (4) Offeror's shall insert additional rows as needed to support the proposed estimate.
A31: 6e. | B31: CPFF FBLRs | C31: (1) For each CPFF CLIN, Offeror's shall input the fully burdened labor cost per hour, fixed fee per hour and fully burdened labor rate (FBLR) per hour for each proposed labor category. (2) The FBLR's shall coorelate to the direct labor base rates, indirect rates and proposed fixed fee provided in Tabs 6b. Direct Labor Base Rates and 6c. Indirect Rates & Fee for each contract period/CLIN. (3) Each subcontractor proposed to support a CPFF CLIN(s) shall provide this data in the required fully disclosed Cost/Price volume as applicable (Refer to RFP Section L.X.X for subcontractor cost/price volume instructions).. (4) Offeror's shall insert additional rows as needed to support the proposed estimate.
A33: 7. | B33: CLIN Summary | C33: The Offeror shall populate this tab to calculate the Total Proposed Price for each CLIN. The Offeror shall input the proposed firm fixed price (FFP) for each transition-in and transition-out CLIN. The Offeror shall ensure that proposed CLIN costs, fee's and prices provided in this tab reconcile to the CLIN costs, fee's and prices provided in Tabs 1-7 (as applicable). The Offeror shall not deviate from the Travel and ODC/Material values in this TAB . The offeror is responsible for ensuring that all calculations within ALL TABs are accurate and reflective of the offeror's proposed price.

Sheet 1. T&M Labor Hours
A1: AFM East Region
A2: ='Template Instructions'!A2 -> Solicitation No.: | B2: ='Template Instructions'!B2 -> Insert Solicitation Number
A3: ='Template Instructions'!A3 -> Prime Offeror Name: | B3: ='Template Instructions'!B3 -> Insert Prime Offeror Company name
A4: ='Template Instructions'!A4 -> CAGE Code: | B4: ='Template Instructions'!B4 -> Insert Prime Offeror Cage Code
D8: Total CONUS Labor Hours Base Period | N8: Total CONUS Labor Hours Option Period 1 | X8: Total CONUS Labor Hours Option Period 2 | AH8: Total CONUS Labor Hours Option Period 3 | AR8: Total CONUS Labor Hours Option Period 4 | BB8: Total CONUS Labor Hours Option Period 5 | BL8: Total CONUS Labor Hours Option Period 6 | BV8: Total CONUS Labor Hours Option Period 7 | CF8: Total CONUS Labor Hours Option Period 8 | CP8: Total CONUS Labor Hours Option Period 9 | CZ8: Total CONUS Labor Hours Option to Extend | DJ8: Total CONUS Labor Hours All Contract Periods
A9: Contract Labor Category | B9: SCLS WD/CBA Labor Category | C9: SCLS WD/CBA Labor Code | D9: Ft. Campbell, KY | E9: Ft. Drum, NY | F9: APG, MD | G9: Ft. Stewart, GA | H9: Ft. Liberty/Ft. Bragg, NC | I9: Jacksonville, FL | J9: Marietta, GA | K9: Other CONUS Locations | L9: Total | N9: Ft. Campbell, KY | O9: Ft. Drum, NY | P9: APG, MD | Q9: Ft. Stewart, GA | R9: Ft. Liberty/Ft. Bragg, NC | S9: Jacksonville, FL | T9: Marietta, GA | U9: Other CONUS Locations | V9: Total | X9: Ft. Campbell, KY | Y9: Ft. Drum, NY | Z9: APG, MD | AA9: Ft. Stewart, GA | AB9: Ft. Liberty/Ft. Bragg, NC | AC9: Jacksonville, FL | AD9: Marietta, GA | AE9: Other CONUS Locations | AF9: Total | AH9: Ft. Campbell, KY | AI9: Ft. Drum, NY | AJ9: APG, MD | AK9: Ft. Stewart, GA | AL9: Ft. Liberty/Ft. Bragg, NC | AM9: Jacksonville, FL | AN9: Marietta, GA | AO9: Other CONUS Locations | AP9: Total | AR9: Ft. Campbell, KY | AS9: Ft. Drum, NY | AT9: APG, MD | AU9: Ft. Stewart, GA | AV9: Ft. Liberty/Ft. Bragg, NC | AW9: Jacksonville, FL | AX9: Marietta, GA | AY9: Other CONUS Locations | AZ9: Total | BB9: Ft. Campbell, KY | BC9: Ft. Drum, NY | BD9: APG, MD | BE9: Ft. Stewart, GA | BF9: Ft. Liberty/Ft. Bragg, NC | BG9: Jacksonville, FL | BH9: Marietta, GA | BI9: Other CONUS Locations | BJ9: Total | BL9: Ft. Campbell, KY | BM9: Ft. Drum, NY | BN9: APG, MD | BO9: Ft. Stewart, GA | BP9: Ft. Liberty/Ft. Bragg, NC | BQ9: Jacksonville, FL | BR9: Marietta, GA | BS9: Other CONUS Locations | BT9: Total | BV9: Ft. Campbell, KY | BW9: Ft. Drum, NY | BX9: APG, MD | BY9: Ft. Stewart, GA | BZ9: Ft. Liberty/Ft. Bragg, NC | CA9: Jacksonville, FL | CB9: Marietta, GA | CC9: Other CONUS Locations | CD9: Total | CF9: Ft. Campbell, KY | CG9: Ft. Drum, NY | CH9: APG, MD | CI9: Ft. Stewart, GA | CJ9: Ft. Liberty/Ft. Bragg, NC | CK9: Jacksonville, FL | CL9: Marietta, GA | CM9: Other CONUS Locations | CN9: Total | CP9: Ft. Campbell, KY | CQ9: Ft. Drum, NY | CR9: APG, MD | CS9: Ft. Stewart, GA | CT9: Ft. Liberty/Ft. Bragg, NC | CU9: Jacksonville, FL | CV9: Marietta, GA | CW9: Other CONUS Locations | CX9: Total | CZ9: Ft. Campbell, KY | DA9: Ft. Drum, NY | DB9: APG, MD | DC9: Ft. Stewart, GA | DD9: Ft. Liberty/Ft. Bragg, NC | DE9: Jacksonville, FL | DF9: Marietta, GA | DG9: Other CONUS Locations | DH9: Total | DJ9: Ft. Campbell, KY | DK9: Ft. Drum, NY | DL9: APG, MD | DM9: Ft. Stewart, GA | DN9: Ft. Liberty/Ft. Bragg, NC | DO9: Jacksonville, FL | DP9: Marietta, GA | DQ9: Other CONUS Locations | DR9: Total
A10: Aerospace Structural Welder | B10: Aerospace Structural Welder | C10: 23010 | D10: 1912 | E10: 1 | F10: 1 | G10: 1912 | H10: 1912 | I10: 1 | J10: 1 | K10: 1 | L10: =SUM(D10:K10) -> 5741 | N10: 1912 | O10: 1 | P10: 1 | Q10: 1912 | R10: 1912 | S10: 1 | T10: 1 | U10: 1 | V10: =SUM(N10:U10) -> 5741 | X10: 1912 | Y10: 1 | Z10: 1 | AA10: 1912 | AB10: 1912 | AC10: 1 | AD10: 1 | AE10: 1 | AF10: =SUM(X10:AE10) -> 5741 | AH10: 1912 | AI10: 1 | AJ10: 1 | AK10: 1912 | AL10: 1912 | AM10: 1 | AN10: 1 | AO10: 1 | AP10: =SUM(AH10:AO10) -> 5741 | AR10: 1912 | AS10: 1 | AT10: 1 | AU10: 1912 | AV10: 1912 | AW10: 1 | AX10: 1 | AY10: 1 | AZ10: =SUM(AR10:AY10) -> 5741 | BB10: 1912 | BC10: 1 | BD10: 1 | BE10: 1912 | BF10: 1912 | BG10: 1 | BH10: 1 | BI10: 1 | BJ10: =SUM(BB10:BI10) -> 5741 | BL10: 1912 | BM10: 1 | BN10: 1 | BO10: 1912 | BP10: 1912 | BQ10: 1 | BR10: 1 | BS10: 1 | BT10: =SUM(BL10:BS10) -> 5741 | BV10: 1912 | BW10: 1 | BX10: 1 | BY10: 1912 | BZ10: 1912 | CA10: 1 | CB10: 1 | CC10: 1 | CD10: =SUM(BV10:CC10) -> 5741 | CF10: 1912 | CG10: 1 | CH10: 1 | CI10: 1912 | CJ10: 1912 | CK10: 1 | CL10: 1 | CM10: 1 | CN10: =SUM(CF10:CM10) -> 5741 | CP10: 1912 | CQ10: 1 | CR10: 1 | CS10: 1912 | CT10: 1912 | CU10: 1 | CV10: 1 | CW10: 1 | CX10: =SUM(CP10:CW10) -> 5741 | CZ10: =CP10/2 -> 956 | DA10: =CQ10/2 -> 0.5 | DB10: =CR10/2 -> 0.5 | DC10: =CS10/2 -> 956 | DD10: =CT10/2 -> 956 | DE10: =CU10/2 -> 0.5 | DF10: =CV10/2 -> 0.5 | DG10: =CW10/2 -> 0.5 | DH10: =SUM(CZ10:DG10) -> 2870.5 | DJ10: =SUM(D10,N10,X10,AH10,AR10,BB10,BL10,BV10,CF10,CP10,CZ10) -> 20076 | DK10: =SUM(E10,O10,Y10,AI10,AS10,BC10,BM10,BW10,CG10,CQ10,DA10) -> 10.5 | DL10: =SUM(F10,P10,Z10,AJ10,AT10,BD10,BN10,BX10,CH10,CR10,DB10) -> 10.5 | DM10: =SUM(G10,Q10,AA10,AK10,AU10,BE10,BO10,BY10,CI10,CS10,DC10) -> 20076 | DN10: =SUM(H10,R10,AB10,AL10,AV10,BF10,BP10,BZ10,CJ10,CT10,DD10) -> 20076 | DO10: =SUM(I10,S10,AC10,AM10,AW10,BG10,BQ10,CA10,CK10,CU10,DE10) -> 10.5 | DP10: =SUM(J10,T10,AD10,AN10,AX10,BH10,BR10,CB10,CL10,CV10,DF10) -> 10.5 | DQ10: =SUM(K10,U10,AE10,AO10,AY10,BI10,BS10,CC10,CM10,CW10,DG10) -> 10.5 | DR10: =SUM(DJ10:DQ10) -> 60280.5
A11: Aircraft Mechanic Helper | B11: Aircraft Mechanic Helper | C11: 23040 | D11: 1 | E11: 1 | F11: 1 | G11: 1 | H11: 1 | I11: 1 | J11: 1 | K11: 1 | L11: =SUM(D11:K11) -> 8 | N11: 1 | O11: 1 | P11: 1 | Q11: 1 | R11: 1 | S11: 1 | T11: 1 | U11: 1 | V11: =SUM(N11:U11) -> 8 | X11: 1 | Y11: 1 | Z11: 1 | AA11: 1 | AB11: 1 | AC11: 1 | AD11: 1 | AE11: 1 | AF11: =SUM(X11:AE11) -> 8 | AH11: 1 | AI11: 1 | AJ11: 1 | AK11: 1 | AL11: 1 | AM11: 1 | AN11: 1 | AO11: 1 | AP11: =SUM(AH11:AO11) -> 8 | AR11: 1 | AS11: 1 | AT11: 1 | AU11: 1 | AV11: 1 | AW11: 1 | AX11: 1 | AY11: 1 | AZ11: =SUM(AR11:AY11) -> 8 | BB11: 1 | BC11: 1 | BD11: 1 | BE11: 1 | BF11: 1 | BG11: 1 | BH11: 1 | BI11: 1 | BJ11: =SUM(BB11:BI11) -> 8 | BL11: 1 | BM11: 1 | BN11: 1 | BO11: 1 | BP11: 1 | BQ11: 1 | BR11: 1 | BS11: 1 | BT11: =SUM(BL11:BS11) -> 8 | BV11: 1 | BW11: 1 | BX11: 1 | BY11: 1 | BZ11: 1 | CA11: 1 | CB11: 1 | CC11: 1 | CD11: =SUM(BV11:CC11) -> 8 | CF11: 1 | CG11: 1 | CH11: 1 | CI11: 1 | CJ11: 1 | CK11: 1 | CL11: 1 | CM11: 1 | CN11: =SUM(CF11:CM11) -> 8 | CP11: 1 | CQ11: 1 | CR11: 1 | CS11: 1 | CT11: 1 | CU11: 1 | CV11: 1 | CW11: 1 | CX11: =SUM(CP11:CW11) -> 8 | CZ11: =CP11/2 -> 0.5 | DA11: =CQ11/2 -> 0.5 | DB11: =CR11/2 -> 0.5 | DC11: =CS11/2 -> 0.5 | DD11: =CT11/2 -> 0.5 | DE11: =CU11/2 -> 0.5 | DF11: =CV11/2 -> 0.5 | DG11: =CW11/2 -> 0.5 | DH11: =SUM(CZ11:DG11) -> 4 | DJ11: =SUM(D11,N11,X11,AH11,AR11,BB11,BL11,BV11,CF11,CP11,CZ11) -> 10.5 | DK11: =SUM(E11,O11,Y11,AI11,AS11,BC11,BM11,BW11,CG11,CQ11,DA11) -> 10.5 | DL11: =SUM(F11,P11,Z11,AJ11,AT11,BD11,BN11,BX11,CH11,CR11,DB11) -> 10.5 | DM11: =SUM(G11,Q11,AA11,AK11,AU11,BE11,BO11,BY11,CI11,CS11,DC11) -> 10.5 | DN11: =SUM(H11,R11,AB11,AL11,AV11,BF11,BP11,BZ11,CJ11,CT11,DD11) -> 10.5 | DO11: =SUM(I11,S11,AC11,AM11,AW11,BG11,BQ11,CA11,CK11,CU11,DE11) -> 10.5 | DP11: =SUM(J11,T11,AD11,AN11,AX11,BH11,BR11,CB11,CL11,CV11,DF11) -> 10.5 | DQ11: =SUM(K11,U11,AE11,AO11,AY11,BI11,BS11,CC11,CM11,CW11,DG11) -> 10.5 | DR11: =SUM(DJ11:DQ11) -> 84
A12: Aircraft Mechanic I | B12: Aircraft Mechanic I | C12: 23021 | D12: 145310 | E12: 57355 | F12: 1907 | G12: 74564 | H12: 80300 | I12: 17195 | J12: 22932 | K12: 22938 | L12: =SUM(D12:K12) -> 422501 | N12: 145310 | O12: 57355 | P12: 1907 | Q12: 74564 | R12: 80300 | S12: 17195 | T12: 22932 | U12: 22938 | V12: =SUM(N12:U12) -> 422501 | X12: 145310 | Y12: 57355 | Z12: 1907 | AA12: 74564 | AB12: 80300 | AC12: 17195 | AD12: 22932 | AE12: 22938 | AF12: =SUM(X12:AE12) -> 422501 | AH12: 145310 | AI12: 57355 | AJ12: 1907 | AK12: 74564 | AL12: 80300 | AM12: 17195 | AN12: 22932 | AO12: 22938 | AP12: =SUM(AH12:AO12) -> 422501 | AR12: 145310 | AS12: 57355 | AT12: 1907 | AU12: 74564 | AV12: 80300 | AW12: 17195 | AX12: 22932 | AY12: 22938 | AZ12: =SUM(AR12:AY12) -> 422501 | BB12: 145310 | BC12: 57355 | BD12: 1907 | BE12: 74564 | BF12: 80300 | BG12: 17195 | BH12: 22932 | BI12: 22938 | BJ12: =SUM(BB12:BI12) -> 422501 | BL12: 145310 | BM12: 57355 | BN12: 1907 | BO12: 74564 | BP12: 80300 | BQ12: 17195 | BR12: 22932 | BS12: 22938 | BT12: =SUM(BL12:BS12) -> 422501 | BV12: 145310 | BW12: 57355 | BX12: 1907 | BY12: 74564 | BZ12: 80300 | CA12: 17195 | CB12: 22932 | CC12: 22938 | CD12: =SUM(BV12:CC12) -> 422501 | CF12: 145310 | CG12: 57355 | CH12: 1907 | CI12: 74564 | CJ12: 80300 | CK12: 17195 | CL12: 22932 | CM12: 22938 | CN12: =SUM(CF12:CM12) -> 422501 | CP12: 145310 | CQ12: 57355 | CR12: 1907 | CS12: 74564 | CT12: 80300 | CU12: 17195 | CV12: 22932 | CW12: 22938 | CX12: =SUM(CP12:CW12) -> 422501 | CZ12: =CP12/2 -> 72655 | DA12: =CQ12/2 -> 28677.5 | DB12: =CR12/2 -> 953.5 | DC12: =CS12/2 -> 37282 | DD12: =CT12/2 -> 40150 | DE12: =CU12/2 -> 8597.5 | DF12: =CV12/2 -> 11466 | DG12: =CW12/2 -> 11469 | DH12: =SUM(CZ12:DG12) -> 211250.5 | DJ12: =SUM(D12,N12,X12,AH12,AR12,BB12,BL12,BV12,CF12,CP12,CZ12) -> 1525755 | DK12: =SUM(E12,O12,Y12,AI12,AS12,BC12,BM12,BW12,CG12,CQ12,DA12) -> 602227.5 | DL12: =SUM(F12,P12,Z12,AJ12,AT12,BD12,BN12,BX12,CH12,CR12,DB12) -> 20023.5 | DM12: =SUM(G12,Q12,AA12,AK12,AU12,BE12,BO12,BY12,CI12,CS12,DC12) -> 782922 | DN12: =SUM(H12,R12,AB12,AL12,AV12,BF12,BP12,BZ12,CJ12,CT12,DD12) -> 843150 | DO12: =SUM(I12,S12,AC12,AM12,AW12,BG12,BQ12,CA12,CK12,CU12,DE12) -> 180547.5 | DP12: =SUM(J12,T12,AD12,AN12,AX12,BH12,BR12,CB12,CL12,CV12,DF12) -> 240786 | DQ12: =SUM(K12,U12,AE12,AO12,AY12,BI12,BS12,CC12,CM12,CW12,DG12) -> 240849 | DR12: =SUM(DJ12:DQ12) -> 4436260.5
A13: Aircraft Mechanic II | B13: Aircraft Mechanic II | C13: 23022 | D13: 86040 | E13: 19120 | F13: 5736 | G13: 5736 | H13: 40152 | I13: 3824 | J13: 1 | K13: 1 | L13: =SUM(D13:K13) -> 160610 | N13: 86040 | O13: 19120 | P13: 5736 | Q13: 5736 | R13: 40152 | S13: 3824 | T13: 1 | U13: 1 | V13: =SUM(N13:U13) -> 160610 | X13: 86040 | Y13: 19120 | Z13: 5736 | AA13: 5736 | AB13: 40152 | AC13: 3824 | AD13: 1 | AE13: 1 | AF13: =SUM(X13:AE13) -> 160610 | AH13: 86040 | AI13: 19120 | AJ13: 5736 | AK13: 5736 | AL13: 40152 | AM13: 3824 | AN13: 1 | AO13: 1 | AP13: =SUM(AH13:AO13) -> 160610 | AR13: 86040 | AS13: 19120 | AT13: 5736 | AU13: 5736 | AV13: 40152 | AW13: 3824 | AX13: 1 | AY13: 1 | AZ13: =SUM(AR13:AY13) -> 160610 | BB13: 86040 | BC13: 19120 | BD13: 5736 | BE13: 5736 | BF13: 40152 | BG13: 3824 | BH13: 1 | BI13: 1 | BJ13: =SUM(BB13:BI13) -> 160610 | BL13: 86040 | BM13: 19120 | BN13: 5736 | BO13: 5736 | BP13: 40152 | BQ13: 3824 | BR13: 1 | BS13: 1 | BT13: =SUM(BL13:BS13) -> 160610 | BV13: 86040 | BW13: 19120 | BX13: 5736 | BY13: 5736 | BZ13: 40152 | CA13: 3824 | CB13: 1 | CC13: 1 | CD13: =SUM(BV13:CC13) -> 160610 | CF13: 86040 | CG13: 19120 | CH13: 5736 | CI13: 5736 | CJ13: 40152 | CK13: 3824 | CL13: 1 | CM13: 1 | CN13: =SUM(CF13:CM13) -> 160610 | CP13: 86040 | CQ13: 19120 | CR13: 5736 | CS13: 5736 | CT13: 40152 | CU13: 3824 | CV13: 1 | CW13: 1 | CX13: =SUM(CP13:CW13) -> 160610 | CZ13: =CP13/2 -> 43020 | DA13: =CQ13/2 -> 9560 | DB13: =CR13/2 -> 2868 | DC13: =CS13/2 -> 2868 | DD13: =CT13/2 -> 20076 | DE13: =CU13/2 -> 1912 | DF13: =CV13/2 -> 0.5 | DG13: =CW13/2 -> 0.5 | DH13: =SUM(CZ13:DG13) -> 80305 | DJ13: =SUM(D13,N13,X13,AH13,AR13,BB13,BL13,BV13,CF13,CP13,CZ13) -> 903420 | DK13: =SUM(E13,O13,Y13,AI13,AS13,BC13,BM13,BW13,CG13,CQ13,DA13) -> 200760 | DL13: =SUM(F13,P13,Z13,AJ13,AT13,BD13,BN13,BX13,CH13,CR13,DB13) -> 60228 | DM13: =SUM(G13,Q13,AA13,AK13,AU13,BE13,BO13,BY13,CI13,CS13,DC13) -> 60228 | DN13: =SUM(H13,R13,AB13,AL13,AV13,BF13,BP13,BZ13,CJ13,CT13,DD13) -> 421596 | DO13: =SUM(I13,S13,AC13,AM13,AW13,BG13,BQ13,CA13,CK13,CU13,DE13) -> 40152 | DP13: =SUM(J13,T13,AD13,AN13,AX13,BH13,BR13,CB13,CL13,CV13,DF13) -> 10.5 | DQ13: =SUM(K13,U13,AE13,AO13,AY13,BI13,BS13,CC13,CM13,CW13,DG13) -> 10.5 | DR13: =SUM(DJ13:DQ13) -> 1686405
A14: Aircraft Mechanic III | B14: Aircraft Mechanic III | C14: 23023 | D14: 38234 | E14: 7641 | F14: 9549 | G14: 3819 | H14: 7644 | I14: 1902 | J14: 1912 | K14: 5725 | L14: =SUM(D14:K14) -> 76426 | N14: 38234 | O14: 7641 | P14: 9549 | Q14: 3819 | R14: 7644 | S14: 1902 | T14: 1912 | U14: 5725 | V14: =SUM(N14:U14) -> 76426 | X14: 38234 | Y14: 7641 | Z14: 9549 | AA14: 3819 | AB14: 7644 | AC14: 1902 | AD14: 1912 | AE14: 5725 | AF14: =SUM(X14:AE14) -> 76426 | AH14: 38234 | AI14: 7641 | AJ14: 9549 | AK14: 3819 | AL14: 7644 | AM14: 1902 | AN14: 1912 | AO14: 5725 | AP14: =SUM(AH14:AO14) -> 76426 | AR14: 38234 | AS14: 7641 | AT14: 9549 | AU14: 3819 | AV14: 7644 | AW14: 1902 | AX14: 1912 | AY14: 5725 | AZ14: =SUM(AR14:AY14) -> 76426 | BB14: 38234 | BC14: 7641 | BD14: 9549 | BE14: 3819 | BF14: 7644 | BG14: 1902 | BH14: 1912 | BI14: 5725 | BJ14: =SUM(BB14:BI14) -> 76426 | BL14: 38234 | BM14: 7641 | BN14: 9549 | BO14: 3819 | BP14: 7644 | BQ14: 1902 | BR14: 1912 | BS14: 5725 | BT14: =SUM(BL14:BS14) -> 76426 | BV14: 38234 | BW14: 7641 | BX14: 9549 | BY14: 3819 | BZ14: 7644 | CA14: 1902 | CB14: 1912 | CC14: 5725 | CD14: =SUM(BV14:CC14) -> 76426 | CF14: 38234 | CG14: 7641 | CH14: 9549 | CI14: 3819 | CJ14: 7644 | CK14: 1902 | CL14: 1912 | CM14: 5725 | CN14: =SUM(CF14:CM14) -> 76426 | CP14: 38234 | CQ14: 7641 | CR14: 9549 | CS14: 3819 | CT14: 7644 | CU14: 1902 | CV14: 1912 | CW14: 5725 | CX14: =SUM(CP14:CW14) -> 76426 | CZ14: =CP14/2 -> 19117 | DA14: =CQ14/2 -> 3820.5 | DB14: =CR14/2 -> 4774.5 | DC14: =CS14/2 -> 1909.5 | DD14: =CT14/2 -> 3822 | DE14: =CU14/2 -> 951 | DF14: =CV14/2 -> 956 | DG14: =CW14/2 -> 2862.5 | DH14: =SUM(CZ14:DG14) -> 38213 | DJ14: =SUM(D14,N14,X14,AH14,AR14,BB14,BL14,BV14,CF14,CP14,CZ14) -> 401457 | DK14: =SUM(E14,O14,Y14,AI14,AS14,BC14,BM14,BW14,CG14,CQ14,DA14) -> 80230.5 | DL14: =SUM(F14,P14,Z14,AJ14,AT14,BD14,BN14,BX14,CH14,CR14,DB14) -> 100264.5 | DM14: =SUM(G14,Q14,AA14,AK14,AU14,BE14,BO14,BY14,CI14,CS14,DC14) -> 40099.5 | DN14: =SUM(H14,R14,AB14,AL14,AV14,BF14,BP14,BZ14,CJ14,CT14,DD14) -> 80262 | DO14: =SUM(I14,S14,AC14,AM14,AW14,BG14,BQ14,CA14,CK14,CU14,DE14) -> 19971 | DP14: =SUM(J14,T14,AD14,AN14,AX14,BH14,BR14,CB14,CL14,CV14,DF14) -> 20076 | DQ14: =SUM(K14,U14,AE14,AO14,AY14,BI14,BS14,CC14,CM14,CW14,DG14) -> 60112.5 | DR14: =SUM(DJ14:DQ14) -> 802473
A15: Aircraft Painter | B15: Aircraft, Painter | C15: 23050 | D15: 17208 | E15: 1912 | F15: 1 | G15: 1912 | H15: 11472 | I15: 1 | J15: 1 | K15: 1 | L15: =SUM(D15:K15) -> 32508 | N15: 17208 | O15: 1912 | P15: 1 | Q15: 1912 | R15: 11472 | S15: 1 | T15: 1 | U15: 1 | V15: =SUM(N15:U15) -> 32508 | X15: 17208 | Y15: 1912 | Z15: 1 | AA15: 1912 | AB15: 11472 | AC15: 1 | AD15: 1 | AE15: 1 | AF15: =SUM(X15:AE15) -> 32508 | AH15: 17208 | AI15: 1912 | AJ15: 1 | AK15: 1912 | AL15: 11472 | AM15: 1 | AN15: 1 | AO15: 1 | AP15: =SUM(AH15:AO15) -> 32508 | AR15: 17208 | AS15: 1912 | AT15: 1 | AU15: 1912 | AV15: 11472 | AW15: 1 | AX15: 1 | AY15: 1 | AZ15: =SUM(AR15:AY15) -> 32508 | BB15: 17208 | BC15: 1912 | BD15: 1 | BE15: 1912 | BF15: 11472 | BG15: 1 | BH15: 1 | BI15: 1 | BJ15: =SUM(BB15:BI15) -> 32508 | BL15: 17208 | BM15: 1912 | BN15: 1 | BO15: 1912 | BP15: 11472 | BQ15: 1 | BR15: 1 | BS15: 1 | BT15: =SUM(BL15:BS15) -> 32508 | BV15: 17208 | BW15: 1912 | BX15: 1 | BY15: 1912 | BZ15: 11472 | CA15: 1 | CB15: 1 | CC15: 1 | CD15: =SUM(BV15:CC15) -> 32508 | CF15: 17208 | CG15: 1912 | CH15: 1 | CI15: 1912 | CJ15: 11472 | CK15: 1 | CL15: 1 | CM15: 1 | CN15: =SUM(CF15:CM15) -> 32508 | CP15: 17208 | CQ15: 1912 | CR15: 1 | CS15: 1912 | CT15: 11472 | CU15: 1 | CV15: 1 | CW15: 1 | CX15: =SUM(CP15:CW15) -> 32508 | CZ15: =CP15/2 -> 8604 | DA15: =CQ15/2 -> 956 | DB15: =CR15/2 -> 0.5 | DC15: =CS15/2 -> 956 | DD15: =CT15/2 -> 5736 | DE15: =CU15/2 -> 0.5 | DF15: =CV15/2 -> 0.5 | DG15: =CW15/2 -> 0.5 | DH15: =SUM(CZ15:DG15) -> 16254 | DJ15: =SUM(D15,N15,X15,AH15,AR15,BB15,BL15,BV15,CF15,CP15,CZ15) -> 180684 | DK15: =SUM(E15,O15,Y15,AI15,AS15,BC15,BM15,BW15,CG15,CQ15,DA15) -> 20076 | DL15: =SUM(F15,P15,Z15,AJ15,AT15,BD15,BN15,BX15,CH15,CR15,DB15) -> 10.5 | DM15: =SUM(G15,Q15,AA15,AK15,AU15,BE15,BO15,BY15,CI15,CS15,DC15) -> 20076 | DN15: =SUM(H15,R15,AB15,AL15,AV15,BF15,BP15,BZ15,CJ15,CT15,DD15) -> 120456 | DO15: =SUM(I15,S15,AC15,AM15,AW15,BG15,BQ15,CA15,CK15,CU15,DE15) -> 10.5 | DP15: =SUM(J15,T15,AD15,AN15,AX15,BH15,BR15,CB15,CL15,CV15,DF15) -> 10.5 | DQ15: =SUM(K15,U15,AE15,AO15,AY15,BI15,BS15,CC15,CM15,CW15,DG15) -> 10.5 | DR15: =SUM(DJ15:DQ15) -> 341334
A16: Aircraft Servicer | B16: Aircraft Servicer | C16: 23060 | D16: 1 | E16: 1 | F16: 1 | G16: 1 | H16: 1 | I16: 1 | J16: 1 | K16: 1 | L16: =SUM(D16:K16) -> 8 | N16: 1 | O16: 1 | P16: 1 | Q16: 1 | R16: 1 | S16: 1 | T16: 1 | U16: 1 | V16: =SUM(N16:U16) -> 8 | X16: 1 | Y16: 1 | Z16: 1 | AA16: 1 | AB16: 1 | AC16: 1 | AD16: 1 | AE16: 1 | AF16: =SUM(X16:AE16) -> 8 | AH16: 1 | AI16: 1 | AJ16: 1 | AK16: 1 | AL16: 1 | AM16: 1 | AN16: 1 | AO16: 1 | AP16: =SUM(AH16:AO16) -> 8 | AR16: 1 | AS16: 1 | AT16: 1 | AU16: 1 | AV16: 1 | AW16: 1 | AX16: 1 | AY16: 1 | AZ16: =SUM(AR16:AY16) -> 8 | BB16: 1 | BC16: 1 | BD16: 1 | BE16: 1 | BF16: 1 | BG16: 1 | BH16: 1 | BI16: 1 | BJ16: =SUM(BB16:BI16) -> 8 | BL16: 1 | BM16: 1 | BN16: 1 | BO16: 1 | BP16: 1 | BQ16: 1 | BR16: 1 | BS16: 1 | BT16: =SUM(BL16:BS16) -> 8 | BV16: 1 | BW16: 1 | BX16: 1 | BY16: 1 | BZ16: 1 | CA16: 1 | CB16: 1 | CC16: 1 | CD16: =SUM(BV16:CC16) -> 8 | CF16: 1 | CG16: 1 | CH16: 1 | CI16: 1 | CJ16: 1 | CK16: 1 | CL16: 1 | CM16: 1 | CN16: =SUM(CF16:CM16) -> 8 | CP16: 1 | CQ16: 1 | CR16: 1 | CS16: 1 | CT16: 1 | CU16: 1 | CV16: 1 | CW16: 1 | CX16: =SUM(CP16:CW16) -> 8 | CZ16: =CP16/2 -> 0.5 | DA16: =CQ16/2 -> 0.5 | DB16: =CR16/2 -> 0.5 | DC16: =CS16/2 -> 0.5 | DD16: =CT16/2 -> 0.5 | DE16: =CU16/2 -> 0.5 | DF16: =CV16/2 -> 0.5 | DG16: =CW16/2 -> 0.5 | DH16: =SUM(CZ16:DG16) -> 4 | DJ16: =SUM(D16,N16,X16,AH16,AR16,BB16,BL16,BV16,CF16,CP16,CZ16) -> 10.5 | DK16: =SUM(E16,O16,Y16,AI16,AS16,BC16,BM16,BW16,CG16,CQ16,DA16) -> 10.5 | DL16: =SUM(F16,P16,Z16,AJ16,AT16,BD16,BN16,BX16,CH16,CR16,DB16) -> 10.5 | DM16: =SUM(G16,Q16,AA16,AK16,AU16,BE16,BO16,BY16,CI16,CS16,DC16) -> 10.5 | DN16: =SUM(H16,R16,AB16,AL16,AV16,BF16,BP16,BZ16,CJ16,CT16,DD16) -> 10.5 | DO16: =SUM(I16,S16,AC16,AM16,AW16,BG16,BQ16,CA16,CK16,CU16,DE16) -> 10.5 | DP16: =SUM(J16,T16,AD16,AN16,AX16,BH16,BR16,CB16,CL16,CV16,DF16) -> 10.5 | DQ16: =SUM(K16,U16,AE16,AO16,AY16,BI16,BS16,CC16,CM16,CW16,DG16) -> 10.5 | DR16: =SUM(DJ16:DQ16) -> 84
A17: Aircraft Technical Inspector | B17: Aircraft Mechanic III | C17: 23023 | D17: 47800 | E17: 1 | F17: 1912 | G17: 11472 | H17: 21032 | I17: 1912 | J17: 1901 | K17: 1912 | L17: =SUM(D17:K17) -> 87942 | N17: 47800 | O17: 1 | P17: 1912 | Q17: 11472 | R17: 21032 | S17: 1912 | T17: 1901 | U17: 1912 | V17: =SUM(N17:U17) -> 87942 | X17: 47800 | Y17: 1 | Z17: 1912 | AA17: 11472 | AB17: 21032 | AC17: 1912 | AD17: 1901 | AE17: 1912 | AF17: =SUM(X17:AE17) -> 87942 | AH17: 47800 | AI17: 1 | AJ17: 1912 | AK17: 11472 | AL17: 21032 | AM17: 1912 | AN17: 1901 | AO17: 1912 | AP17: =SUM(AH17:AO17) -> 87942 | AR17: 47800 | AS17: 1 | AT17: 1912 | AU17: 11472 | AV17: 21032 | AW17: 1912 | AX17: 1901 | AY17: 1912 | AZ17: =SUM(AR17:AY17) -> 87942 | BB17: 47800 | BC17: 1 | BD17: 1912 | BE17: 11472 | BF17: 21032 | BG17: 1912 | BH17: 1901 | BI17: 1912 | BJ17: =SUM(BB17:BI17) -> 87942 | BL17: 47800 | BM17: 1 | BN17: 1912 | BO17: 11472 | BP17: 21032 | BQ17: 1912 | BR17: 1901 | BS17: 1912 | BT17: =SUM(BL17:BS17) -> 87942 | BV17: 47800 | BW17: 1 | BX17: 1912 | BY17: 11472 | BZ17: 21032 | CA17: 1912 | CB17: 1901 | CC17: 1912 | CD17: =SUM(BV17:CC17) -> 87942 | CF17: 47800 | CG17: 1 | CH17: 1912 | CI17: 11472 | CJ17: 21032 | CK17: 1912 | CL17: 1901 | CM17: 1912 | CN17: =SUM(CF17:CM17) -> 87942 | CP17: 47800 | CQ17: 1 | CR17: 1912 | CS17: 11472 | CT17: 21032 | CU17: 1912 | CV17: 1901 | CW17: 1912 | CX17: =SUM(CP17:CW17) -> 87942 | CZ17: =CP17/2 -> 23900 | DA17: =CQ17/2 -> 0.5 | DB17: =CR17/2 -> 956 | DC17: =CS17/2 -> 5736 | DD17: =CT17/2 -> 10516 | DE17: =CU17/2 -> 956 | DF17: =CV17/2 -> 950.5 | DG17: =CW17/2 -> 956 | DH17: =SUM(CZ17:DG17) -> 43971 | DJ17: =SUM(D17,N17,X17,AH17,AR17,BB17,BL17,BV17,CF17,CP17,CZ17) -> 501900 | DK17: =SUM(E17,O17,Y17,AI17,AS17,BC17,BM17,BW17,CG17,CQ17,DA17) -> 10.5 | DL17: =SUM(F17,P17,Z17,AJ17,AT17,BD17,BN17,BX17,CH17,CR17,DB17) -> 20076 | DM17: =SUM(G17,Q17,AA17,AK17,AU17,BE17,BO17,BY17,CI17,CS17,DC17) -> 120456 | DN17: =SUM(H17,R17,AB17,AL17,AV17,BF17,BP17,BZ17,CJ17,CT17,DD17) -> 220836 | DO17: =SUM(I17,S17,AC17,AM17,AW17,BG17,BQ17,CA17,CK17,CU17,DE17) -> 20076 | DP17: =SUM(J17,T17,AD17,AN17,AX17,BH17,BR17,CB17,CL17,CV17,DF17) -> 19960.5 | DQ17: =SUM(K17,U17,AE17,AO17,AY17,BI17,BS17,CC17,CM17,CW17,DG17) -> 20076 | DR17: =SUM(DJ17:DQ17) -> 923391
A18: Aircraft Worker | B18: Ground Support Equipment Mechanic | C18: 23080 | D18: 5736 | E18: 1 | F18: 1 | G18: 1 | H18: 1912 | I18: 1 | J18: 1 | K18: 1 | L18: =SUM(D18:K18) -> 7654 | N18: 5736 | O18: 1 | P18: 1 | Q18: 1 | R18: 1912 | S18: 1 | T18: 1 | U18: 1 | V18: =SUM(N18:U18) -> 7654 | X18: 5736 | Y18: 1 | Z18: 1 | AA18: 1 | AB18: 1912 | AC18: 1 | AD18: 1 | AE18: 1 | AF18: =SUM(X18:AE18) -> 7654 | AH18: 5736 | AI18: 1 | AJ18: 1 | AK18: 1 | AL18: 1912 | AM18: 1 | AN18: 1 | AO18: 1 | AP18: =SUM(AH18:AO18) -> 7654 | AR18: 5736 | AS18: 1 | AT18: 1 | AU18: 1 | AV18: 1912 | AW18: 1 | AX18: 1 | AY18: 1 | AZ18: =SUM(AR18:AY18) -> 7654 | BB18: 5736 | BC18: 1 | BD18: 1 | BE18: 1 | BF18: 1912 | BG18: 1 | BH18: 1 | BI18: 1 | BJ18: =SUM(BB18:BI18) -> 7654 | BL18: 5736 | BM18: 1 | BN18: 1 | BO18: 1 | BP18: 1912 | BQ18: 1 | BR18: 1 | BS18: 1 | BT18: =SUM(BL18:BS18) -> 7654 | BV18: 5736 | BW18: 1 | BX18: 1 | BY18: 1 | BZ18: 1912 | CA18: 1 | CB18: 1 | CC18: 1 | CD18: =SUM(BV18:CC18) -> 7654 | CF18: 5736 | CG18: 1 | CH18: 1 | CI18: 1 | CJ18: 1912 | CK18: 1 | CL18: 1 | CM18: 1 | CN18: =SUM(CF18:CM18) -> 7654 | CP18: 5736 | CQ18: 1 | CR18: 1 | CS18: 1 | CT18: 1912 | CU18: 1 | CV18: 1 | CW18: 1 | CX18: =SUM(CP18:CW18) -> 7654 | CZ18: =CP18/2 -> 2868 | DA18: =CQ18/2 -> 0.5 | DB18: =CR18/2 -> 0.5 | DC18: =CS18/2 -> 0.5 | DD18: =CT18/2 -> 956 | DE18: =CU18/2 -> 0.5 | DF18: =CV18/2 -> 0.5 | DG18: =CW18/2 -> 0.5 | DH18: =SUM(CZ18:DG18) -> 3827 | DJ18: =SUM(D18,N18,X18,AH18,AR18,BB18,BL18,BV18,CF18,CP18,CZ18) -> 60228 | DK18: =SUM(E18,O18,Y18,AI18,AS18,BC18,BM18,BW18,CG18,CQ18,DA18) -> 10.5 | DL18: =SUM(F18,P18,Z18,AJ18,AT18,BD18,BN18,BX18,CH18,CR18,DB18) -> 10.5 | DM18: =SUM(G18,Q18,AA18,AK18,AU18,BE18,BO18,BY18,CI18,CS18,DC18) -> 10.5 | DN18: =SUM(H18,R18,AB18,AL18,AV18,BF18,BP18,BZ18,CJ18,CT18,DD18) -> 20076 | DO18: =SUM(I18,S18,AC18,AM18,AW18,BG18,BQ18,CA18,CK18,CU18,DE18) -> 10.5 | DP18: =SUM(J18,T18,AD18,AN18,AX18,BH18,BR18,CB18,CL18,CV18,DF18) -> 10.5 | DQ18: =SUM(K18,U18,AE18,AO18,AY18,BI18,BS18,CC18,CM18,CW18,DG18) -> 10.5 | DR18: =SUM(DJ18:DQ18) -> 80367
A19: Aviation Life Support Equipment (ALSE) Technical Inspector | B19: Aircraft Mechanic I | C19: 23021 | D19: 1 | E19: 1 | F19: 1 | G19: 1 | H19: 1 | I19: 1 | J19: 1 | K19: 1 | L19: =SUM(D19:K19) -> 8 | N19: 1 | O19: 1 | P19: 1 | Q19: 1 | R19: 1 | S19: 1 | T19: 1 | U19: 1 | V19: =SUM(N19:U19) -> 8 | X19: 1 | Y19: 1 | Z19: 1 | AA19: 1 | AB19: 1 | AC19: 1 | AD19: 1 | AE19: 1 | AF19: =SUM(X19:AE19) -> 8 | AH19: 1 | AI19: 1 | AJ19: 1 | AK19: 1 | AL19: 1 | AM19: 1 | AN19: 1 | AO19: 1 | AP19: =SUM(AH19:AO19) -> 8 | AR19: 1 | AS19: 1 | AT19: 1 | AU19: 1 | AV19: 1 | AW19: 1 | AX19: 1 | AY19: 1 | AZ19: =SUM(AR19:AY19) -> 8 | BB19: 1 | BC19: 1 | BD19: 1 | BE19: 1 | BF19: 1 | BG19: 1 | BH19: 1 | BI19: 1 | BJ19: =SUM(BB19:BI19) -> 8 | BL19: 1 | BM19: 1 | BN19: 1 | BO19: 1 | BP19: 1 | BQ19: 1 | BR19: 1 | BS19: 1 | BT19: =SUM(BL19:BS19) -> 8 | BV19: 1 | BW19: 1 | BX19: 1 | BY19: 1 | BZ19: 1 | CA19: 1 | CB19: 1 | CC19: 1 | CD19: =SUM(BV19:CC19) -> 8 | CF19: 1 | CG19: 1 | CH19: 1 | CI19: 1 | CJ19: 1 | CK19: 1 | CL19: 1 | CM19: 1 | CN19: =SUM(CF19:CM19) -> 8 | CP19: 1 | CQ19: 1 | CR19: 1 | CS19: 1 | CT19: 1 | CU19: 1 | CV19: 1 | CW19: 1 | CX19: =SUM(CP19:CW19) -> 8 | CZ19: =CP19/2 -> 0.5 | DA19: =CQ19/2 -> 0.5 | DB19: =CR19/2 -> 0.5 | DC19: =CS19/2 -> 0.5 | DD19: =CT19/2 -> 0.5 | DE19: =CU19/2 -> 0.5 | DF19: =CV19/2 -> 0.5 | DG19: =CW19/2 -> 0.5 | DH19: =SUM(CZ19:DG19) -> 4 | DJ19: =SUM(D19,N19,X19,AH19,AR19,BB19,BL19,BV19,CF19,CP19,CZ19) -> 10.5 | DK19: =SUM(E19,O19,Y19,AI19,AS19,BC19,BM19,BW19,CG19,CQ19,DA19) -> 10.5 | DL19: =SUM(F19,P19,Z19,AJ19,AT19,BD19,BN19,BX19,CH19,CR19,DB19) -> 10.5 | DM19: =SUM(G19,Q19,AA19,AK19,AU19,BE19,BO19,BY19,CI19,CS19,DC19) -> 10.5 | DN19: =SUM(H19,R19,AB19,AL19,AV19,BF19,BP19,BZ19,CJ19,CT19,DD19) -> 10.5 | DO19: =SUM(I19,S19,AC19,AM19,AW19,BG19,BQ19,CA19,CK19,CU19,DE19) -> 10.5 | DP19: =SUM(J19,T19,AD19,AN19,AX19,BH19,BR19,CB19,CL19,CV19,DF19) -> 10.5 | DQ19: =SUM(K19,U19,AE19,AO19,AY19,BI19,BS19,CC19,CM19,CW19,DG19) -> 10.5 | DR19: =SUM(DJ19:DQ19) -> 84
A20: Aviation Life Support Equipment (ALSE) Technician | B20: Aircraft Mechanic I | C20: 23021 | D20: 1 | E20: 1 | F20: 1 | G20: 1 | H20: 1 | I20: 1 | J20: 1 | K20: 1 | L20: =SUM(D20:K20) -> 8 | N20: 1 | O20: 1 | P20: 1 | Q20: 1 | R20: 1 | S20: 1 | T20: 1 | U20: 1 | V20: =SUM(N20:U20) -> 8 | X20: 1 | Y20: 1 | Z20: 1 | AA20: 1 | AB20: 1 | AC20: 1 | AD20: 1 | AE20: 1 | AF20: =SUM(X20:AE20) -> 8 | AH20: 1 | AI20: 1 | AJ20: 1 | AK20: 1 | AL20: 1 | AM20: 1 | AN20: 1 | AO20: 1 | AP20: =SUM(AH20:AO20) -> 8 | AR20: 1 | AS20: 1 | AT20: 1 | AU20: 1 | AV20: 1 | AW20: 1 | AX20: 1 | AY20: 1 | AZ20: =SUM(AR20:AY20) -> 8 | BB20: 1 | BC20: 1 | BD20: 1 | BE20: 1 | BF20: 1 | BG20: 1 | BH20: 1 | BI20: 1 | BJ20: =SUM(BB20:BI20) -> 8 | BL20: 1 | BM20: 1 | BN20: 1 | BO20: 1 | BP20: 1 | BQ20: 1 | BR20: 1 | BS20: 1 | BT20: =SUM(BL20:BS20) -> 8 | BV20: 1 | BW20: 1 | BX20: 1 | BY20: 1 | BZ20: 1 | CA20: 1 | CB20: 1 | CC20: 1 | CD20: =SUM(BV20:CC20) -> 8 | CF20: 1 | CG20: 1 | CH20: 1 | CI20: 1 | CJ20: 1 | CK20: 1 | CL20: 1 | CM20: 1 | CN20: =SUM(CF20:CM20) -> 8 | CP20: 1 | CQ20: 1 | CR20: 1 | CS20: 1 | CT20: 1 | CU20: 1 | CV20: 1 | CW20: 1 | CX20: =SUM(CP20:CW20) -> 8 | CZ20: =CP20/2 -> 0.5 | DA20: =CQ20/2 -> 0.5 | DB20: =CR20/2 -> 0.5 | DC20: =CS20/2 -> 0.5 | DD20: =CT20/2 -> 0.5 | DE20: =CU20/2 -> 0.5 | DF20: =CV20/2 -> 0.5 | DG20: =CW20/2 -> 0.5 | DH20: =SUM(CZ20:DG20) -> 4 | DJ20: =SUM(D20,N20,X20,AH20,AR20,BB20,BL20,BV20,CF20,CP20,CZ20) -> 10.5 | DK20: =SUM(E20,O20,Y20,AI20,AS20,BC20,BM20,BW20,CG20,CQ20,DA20) -> 10.5 | DL20: =SUM(F20,P20,Z20,AJ20,AT20,BD20,BN20,BX20,CH20,CR20,DB20) -> 10.5 | DM20: =SUM(G20,Q20,AA20,AK20,AU20,BE20,BO20,BY20,CI20,CS20,DC20) -> 10.5 | DN20: =SUM(H20,R20,AB20,AL20,AV20,BF20,BP20,BZ20,CJ20,CT20,DD20) -> 10.5 | DO20: =SUM(I20,S20,AC20,AM20,AW20,BG20,BQ20,CA20,CK20,CU20,DE20) -> 10.5 | DP20: =SUM(J20,T20,AD20,AN20,AX20,BH20,BR20,CB20,CL20,CV20,DF20) -> 10.5 | DQ20: =SUM(K20,U20,AE20,AO20,AY20,BI20,BS20,CC20,CM20,CW20,DG20) -> 10.5 | DR20: =SUM(DJ20:DQ20) -> 84
A21: Ground Inspector | B21: Ground Support Equipment Mechanic | C21: 23380 | D21: 1 | E21: 1 | F21: 1 | G21: 1 | H21: 1 | I21: 1 | J21: 1 | K21: 1 | L21: =SUM(D21:K21) -> 8 | N21: 1 | O21: 1 | P21: 1 | Q21: 1 | R21: 1 | S21: 1 | T21: 1 | U21: 1 | V21: =SUM(N21:U21) -> 8 | X21: 1 | Y21: 1 | Z21: 1 | AA21: 1 | AB21: 1 | AC21: 1 | AD21: 1 | AE21: 1 | AF21: =SUM(X21:AE21) -> 8 | AH21: 1 | AI21: 1 | AJ21: 1 | AK21: 1 | AL21: 1 | AM21: 1 | AN21: 1 | AO21: 1 | AP21: =SUM(AH21:AO21) -> 8 | AR21: 1 | AS21: 1 | AT21: 1 | AU21: 1 | AV21: 1 | AW21: 1 | AX21: 1 | AY21: 1 | AZ21: =SUM(AR21:AY21) -> 8 | BB21: 1 | BC21: 1 | BD21: 1 | BE21: 1 | BF21: 1 | BG21: 1 | BH21: 1 | BI21: 1 | BJ21: =SUM(BB21:BI21) -> 8 | BL21: 1 | BM21: 1 | BN21: 1 | BO21: 1 | BP21: 1 | BQ21: 1 | BR21: 1 | BS21: 1 | BT21: =SUM(BL21:BS21) -> 8 | BV21: 1 | BW21: 1 | BX21: 1 | BY21: 1 | BZ21: 1 | CA21: 1 | CB21: 1 | CC21: 1 | CD21: =SUM(BV21:CC21) -> 8 | CF21: 1 | CG21: 1 | CH21: 1 | CI21: 1 | CJ21: 1 | CK21: 1 | CL21: 1 | CM21: 1 | CN21: =SUM(CF21:CM21) -> 8 | CP21: 1 | CQ21: 1 | CR21: 1 | CS21: 1 | CT21: 1 | CU21: 1 | CV21: 1 | CW21: 1 | CX21: =SUM(CP21:CW21) -> 8 | CZ21: =CP21/2 -> 0.5 | DA21: =CQ21/2 -> 0.5 | DB21: =CR21/2 -> 0.5 | DC21: =CS21/2 -> 0.5 | DD21: =CT21/2 -> 0.5 | DE21: =CU21/2 -> 0.5 | DF21: =CV21/2 -> 0.5 | DG21: =CW21/2 -> 0.5 | DH21: =SUM(CZ21:DG21) -> 4 | DJ21: =SUM(D21,N21,X21,AH21,AR21,BB21,BL21,BV21,CF21,CP21,CZ21) -> 10.5 | DK21: =SUM(E21,O21,Y21,AI21,AS21,BC21,BM21,BW21,CG21,CQ21,DA21) -> 10.5 | DL21: =SUM(F21,P21,Z21,AJ21,AT21,BD21,BN21,BX21,CH21,CR21,DB21) -> 10.5 | DM21: =SUM(G21,Q21,AA21,AK21,AU21,BE21,BO21,BY21,CI21,CS21,DC21) -> 10.5 | DN21: =SUM(H21,R21,AB21,AL21,AV21,BF21,BP21,BZ21,CJ21,CT21,DD21) -> 10.5 | DO21: =SUM(I21,S21,AC21,AM21,AW21,BG21,BQ21,CA21,CK21,CU21,DE21) -> 10.5 | DP21: =SUM(J21,T21,AD21,AN21,AX21,BH21,BR21,CB21,CL21,CV21,DF21) -> 10.5 | DQ21: =SUM(K21,U21,AE21,AO21,AY21,BI21,BS21,CC21,CM21,CW21,DG21) -> 10.5 | DR21: =SUM(DJ21:DQ21) -> 84
A22: Ground Support Equipment (GSE) Mechanic | B22: Ground Support Equipment Mechanic | C22: 23380 | D22: 11472 | E22: 3824 | F22: 1 | G22: 11472 | H22: 3824 | I22: 1 | J22: 1 | K22: 1 | L22: =SUM(D22:K22) -> 30596 | N22: 11472 | O22: 3824 | P22: 1 | Q22: 11472 | R22: 3824 | S22: 1 | T22: 1 | U22: 1 | V22: =SUM(N22:U22) -> 30596 | X22: 11472 | Y22: 3824 | Z22: 1 | AA22: 11472 | AB22: 3824 | AC22: 1 | AD22: 1 | AE22: 1 | AF22: =SUM(X22:AE22) -> 30596 | AH22: 11472 | AI22: 3824 | AJ22: 1 | AK22: 11472 | AL22: 3824 | AM22: 1 | AN22: 1 | AO22: 1 | AP22: =SUM(AH22:AO22) -> 30596 | AR22: 11472 | AS22: 3824 | AT22: 1 | AU22: 11472 | AV22: 3824 | AW22: 1 | AX22: 1 | AY22: 1 | AZ22: =SUM(AR22:AY22) -> 30596 | BB22: 11472 | BC22: 3824 | BD22: 1 | BE22: 11472 | BF22: 3824 | BG22: 1 | BH22: 1 | BI22: 1 | BJ22: =SUM(BB22:BI22) -> 30596 | BL22: 11472 | BM22: 3824 | BN22: 1 | BO22: 11472 | BP22: 3824 | BQ22: 1 | BR22: 1 | BS22: 1 | BT22: =SUM(BL22:BS22) -> 30596 | BV22: 11472 | BW22: 3824 | BX22: 1 | BY22: 11472 | BZ22: 3824 | CA22: 1 | CB22: 1 | CC22: 1 | CD22: =SUM(BV22:CC22) -> 30596 | CF22: 11472 | CG22: 3824 | CH22: 1 | CI22: 11472 | CJ22: 3824 | CK22: 1 | CL22: 1 | CM22: 1 | CN22: =SUM(CF22:CM22) -> 30596 | CP22: 11472 | CQ22: 3824 | CR22: 1 | CS22: 11472 | CT22: 3824 | CU22: 1 | CV22: 1 | CW22: 1 | CX22: =SUM(CP22:CW22) -> 30596 | CZ22: =CP22/2 -> 5736 | DA22: =CQ22/2 -> 1912 | DB22: =CR22/2 -> 0.5 | DC22: =CS22/2 -> 5736 | DD22: =CT22/2 -> 1912 | DE22: =CU22/2 -> 0.5 | DF22: =CV22/2 -> 0.5 | DG22: =CW22/2 -> 0.5 | DH22: =SUM(CZ22:DG22) -> 15298 | DJ22: =SUM(D22,N22,X22,AH22,AR22,BB22,BL22,BV22,CF22,CP22,CZ22) -> 120456 | DK22: =SUM(E22,O22,Y22,AI22,AS22,BC22,BM22,BW22,CG22,CQ22,DA22) -> 40152 | DL22: =SUM(F22,P22,Z22,AJ22,AT22,BD22,BN22,BX22,CH22,CR22,DB22) -> 10.5 | DM22: =SUM(G22,Q22,AA22,AK22,AU22,BE22,BO22,BY22,CI22,CS22,DC22) -> 120456 | DN22: =SUM(H22,R22,AB22,AL22,AV22,BF22,BP22,BZ22,CJ22,CT22,DD22) -> 40152 | DO22: =SUM(I22,S22,AC22,AM22,AW22,BG22,BQ22,CA22,CK22,CU22,DE22) -> 10.5 | DP22: =SUM(J22,T22,AD22,AN22,AX22,BH22,BR22,CB22,CL22,CV22,DF22) -> 10.5 | DQ22: =SUM(K22,U22,AE22,AO22,AY22,BI22,BS22,CC22,CM22,CW22,DG22) -> 10.5 | DR22: =SUM(DJ22:DQ22) -> 321258
A23: Maintenance Test Pilot | D23: 7648 | E23: 1912 | F23: 1 | G23: 1912 | H23: 3824 | I23: 1 | J23: 1 | K23: 1 | L23: =SUM(D23:K23) -> 15300 | N23: 7648 | O23: 1912 | P23: 1 | Q23: 1912 | R23: 3824 | S23: 1 | T23: 1 | U23: 1 | V23: =SUM(N23:U23) -> 15300 | X23: 7648 | Y23: 1912 | Z23: 1 | AA23: 1912 | AB23: 3824 | AC23: 1 | AD23: 1 | AE23: 1 | AF23: =SUM(X23:AE23) -> 15300 | AH23: 7648 | AI23: 1912 | AJ23: 1 | AK23: 1912 | AL23: 3824 | AM23: 1 | AN23: 1 | AO23: 1 | AP23: =SUM(AH23:AO23) -> 15300 | AR23: 7648 | AS23: 1912 | AT23: 1 | AU23: 1912 | AV23: 3824 | AW23: 1 | AX23: 1 | AY23: 1 | AZ23: =SUM(AR23:AY23) -> 15300 | BB23: 7648 | BC23: 1912 | BD23: 1 | BE23: 1912 | BF23: 3824 | BG23: 1 | BH23: 1 | BI23: 1 | BJ23: =SUM(BB23:BI23) -> 15300 | BL23: 7648 | BM23: 1912 | BN23: 1 | BO23: 1912 | BP23: 3824 | BQ23: 1 | BR23: 1 | BS23: 1 | BT23: =SUM(BL23:BS23) -> 15300 | BV23: 7648 | BW23: 1912 | BX23: 1 | BY23: 1912 | BZ23: 3824 | CA23: 1 | CB23: 1 | CC23: 1 | CD23: =SUM(BV23:CC23) -> 15300 | CF23: 7648 | CG23: 1912 | CH23: 1 | CI23: 1912 | CJ23: 3824 | CK23: 1 | CL23: 1 | CM23: 1 | CN23: =SUM(CF23:CM23) -> 15300 | CP23: 7648 | CQ23: 1912 | CR23: 1 | CS23: 1912 | CT23: 3824 | CU23: 1 | CV23: 1 | CW23: 1 | CX23: =SUM(CP23:CW23) -> 15300 | CZ23: =CP23/2 -> 3824 | DA23: =CQ23/2 -> 956 | DB23: =CR23/2 -> 0.5 | DC23: =CS23/2 -> 956 | DD23: =CT23/2 -> 1912 | DE23: =CU23/2 -> 0.5 | DF23: =CV23/2 -> 0.5 | DG23: =CW23/2 -> 0.5 | DH23: =SUM(CZ23:DG23) -> 7650 | DJ23: =SUM(D23,N23,X23,AH23,AR23,BB23,BL23,BV23,CF23,CP23,CZ23) -> 80304 | DK23: =SUM(E23,O23,Y23,AI23,AS23,BC23,BM23,BW23,CG23,CQ23,DA23) -> 20076 | DL23: =SUM(F23,P23,Z23,AJ23,AT23,BD23,BN23,BX23,CH23,CR23,DB23) -> 10.5 | DM23: =SUM(G23,Q23,AA23,AK23,AU23,BE23,BO23,BY23,CI23,CS23,DC23) -> 20076 | DN23: =SUM(H23,R23,AB23,AL23,AV23,BF23,BP23,BZ23,CJ23,CT23,DD23) -> 40152 | DO23: =SUM(I23,S23,AC23,AM23,AW23,BG23,BQ23,CA23,CK23,CU23,DE23) -> 10.5 | DP23: =SUM(J23,T23,AD23,AN23,AX23,BH23,BR23,CB23,CL23,CV23,DF23) -> 10.5 | DQ23: =SUM(K23,U23,AE23,AO23,AY23,BI23,BS23,CC23,CM23,CW23,DG23) -> 10.5 | DR23: =SUM(DJ23:DQ23) -> 160650
A24: Material Coordinator | B24: Material Coordinator | C24: 21030 | D24: 15296 | E24: 11472 | F24: 1 | G24: 1 | H24: 1 | I24: 1 | J24: 1 | K24: 1 | L24: =SUM(D24:K24) -> 26774 | N24: 15296 | O24: 11472 | P24: 1 | Q24: 1 | R24: 1 | S24: 1 | T24: 1 | U24: 1 | V24: =SUM(N24:U24) -> 26774 | X24: 15296 | Y24: 11472 | Z24: 1 | AA24: 1 | AB24: 1 | AC24: 1 | AD24: 1 | AE24: 1 | AF24: =SUM(X24:AE24) -> 26774 | AH24: 15296 | AI24: 11472 | AJ24: 1 | AK24: 1 | AL24: 1 | AM24: 1 | AN24: 1 | AO24: 1 | AP24: =SUM(AH24:AO24) -> 26774 | AR24: 15296 | AS24: 11472 | AT24: 1 | AU24: 1 | AV24: 1 | AW24: 1 | AX24: 1 | AY24: 1 | AZ24: =SUM(AR24:AY24) -> 26774 | BB24: 15296 | BC24: 11472 | BD24: 1 | BE24: 1 | BF24: 1 | BG24: 1 | BH24: 1 | BI24: 1 | BJ24: =SUM(BB24:BI24) -> 26774 | BL24: 15296 | BM24: 11472 | BN24: 1 | BO24: 1 | BP24: 1 | BQ24: 1 | BR24: 1 | BS24: 1 | BT24: =SUM(BL24:BS24) -> 26774 | BV24: 15296 | BW24: 11472 | BX24: 1 | BY24: 1 | BZ24: 1 | CA24: 1 | CB24: 1 | CC24: 1 | CD24: =SUM(BV24:CC24) -> 26774 | CF24: 15296 | CG24: 11472 | CH24: 1 | CI24: 1 | CJ24: 1 | CK24: 1 | CL24: 1 | CM24: 1 | CN24: =SUM(CF24:CM24) -> 26774 | CP24: 15296 | CQ24: 11472 | CR24: 1 | CS24: 1 | CT24: 1 | CU24: 1 | CV24: 1 | CW24: 1 | CX24: =SUM(CP24:CW24) -> 26774 | CZ24: =CP24/2 -> 7648 | DA24: =CQ24/2 -> 5736 | DB24: =CR24/2 -> 0.5 | DC24: =CS24/2 -> 0.5 | DD24: =CT24/2 -> 0.5 | DE24: =CU24/2 -> 0.5 | DF24: =CV24/2 -> 0.5 | DG24: =CW24/2 -> 0.5 | DH24: =SUM(CZ24:DG24) -> 13387 | DJ24: =SUM(D24,N24,X24,AH24,AR24,BB24,BL24,BV24,CF24,CP24,CZ24) -> 160608 | DK24: =SUM(E24,O24,Y24,AI24,AS24,BC24,BM24,BW24,CG24,CQ24,DA24) -> 120456 | DL24: =SUM(F24,P24,Z24,AJ24,AT24,BD24,BN24,BX24,CH24,CR24,DB24) -> 10.5 | DM24: =SUM(G24,Q24,AA24,AK24,AU24,BE24,BO24,BY24,CI24,CS24,DC24) -> 10.5 | DN24: =SUM(H24,R24,AB24,AL24,AV24,BF24,BP24,BZ24,CJ24,CT24,DD24) -> 10.5 | DO24: =SUM(I24,S24,AC24,AM24,AW24,BG24,BQ24,CA24,CK24,CU24,DE24) -> 10.5 | DP24: =SUM(J24,T24,AD24,AN24,AX24,BH24,BR24,CB24,CL24,CV24,DF24) -> 10.5 | DQ24: =SUM(K24,U24,AE24,AO24,AY24,BI24,BS24,CC24,CM24,CW24,DG24) -> 10.5 | DR24: =SUM(DJ24:DQ24) -> 281127
A25: Non-Destructive Inspection Tech (NDI) II | B25: Non-Destructive Inspection (NDI) Technician II | C25: 92000 | D25: 1912 | E25: 1 | F25: 1 | G25: 1912 | H25: 1 | I25: 1 | J25: 1 | K25: 1 | L25: =SUM(D25:K25) -> 3830 | N25: 1912 | O25: 1 | P25: 1 | Q25: 1912 | R25: 1 | S25: 1 | T25: 1 | U25: 1 | V25: =SUM(N25:U25) -> 3830 | X25: 1912 | Y25: 1 | Z25: 1 | AA25: 1912 | AB25: 1 | AC25: 1 | AD25: 1 | AE25: 1 | AF25: =SUM(X25:AE25) -> 3830 | AH25: 1912 | AI25: 1 | AJ25: 1 | AK25: 1912 | AL25: 1 | AM25: 1 | AN25: 1 | AO25: 1 | AP25: =SUM(AH25:AO25) -> 3830 | AR25: 1912 | AS25: 1 | AT25: 1 | AU25: 1912 | AV25: 1 | AW25: 1 | AX25: 1 | AY25: 1 | AZ25: =SUM(AR25:AY25) -> 3830 | BB25: 1912 | BC25: 1 | BD25: 1 | BE25: 1912 | BF25: 1 | BG25: 1 | BH25: 1 | BI25: 1 | BJ25: =SUM(BB25:BI25) -> 3830 | BL25: 1912 | BM25: 1 | BN25: 1 | BO25: 1912 | BP25: 1 | BQ25: 1 | BR25: 1 | BS25: 1 | BT25: =SUM(BL25:BS25) -> 3830 | BV25: 1912 | BW25: 1 | BX25: 1 | BY25: 1912 | BZ25: 1 | CA25: 1 | CB25: 1 | CC25: 1 | CD25: =SUM(BV25:CC25) -> 3830 | CF25: 1912 | CG25: 1 | CH25: 1 | CI25: 1912 | CJ25: 1 | CK25: 1 | CL25: 1 | CM25: 1 | CN25: =SUM(CF25:CM25) -> 3830 | CP25: 1912 | CQ25: 1 | CR25: 1 | CS25: 1912 | CT25: 1 | CU25: 1 | CV25: 1 | CW25: 1 | CX25: =SUM(CP25:CW25) -> 3830 | CZ25: =CP25/2 -> 956 | DA25: =CQ25/2 -> 0.5 | DB25: =CR25/2 -> 0.5 | DC25: =CS25/2 -> 956 | DD25: =CT25/2 -> 0.5 | DE25: =CU25/2 -> 0.5 | DF25: =CV25/2 -> 0.5 | DG25: =CW25/2 -> 0.5 | DH25: =SUM(CZ25:DG25) -> 1915 | DJ25: =SUM(D25,N25,X25,AH25,AR25,BB25,BL25,BV25,CF25,CP25,CZ25) -> 20076 | DK25: =SUM(E25,O25,Y25,AI25,AS25,BC25,BM25,BW25,CG25,CQ25,DA25) -> 10.5 | DL25: =SUM(F25,P25,Z25,AJ25,AT25,BD25,BN25,BX25,CH25,CR25,DB25) -> 10.5 | DM25: =SUM(G25,Q25,AA25,AK25,AU25,BE25,BO25,BY25,CI25,CS25,DC25) -> 20076 | DN25: =SUM(H25,R25,AB25,AL25,AV25,BF25,BP25,BZ25,CJ25,CT25,DD25) -> 10.5 | DO25: =SUM(I25,S25,AC25,AM25,AW25,BG25,BQ25,CA25,CK25,CU25,DE25) -> 10.5 | DP25: =SUM(J25,T25,AD25,AN25,AX25,BH25,BR25,CB25,CL25,CV25,DF25) -> 10.5 | DQ25: =SUM(K25,U25,AE25,AO25,AY25,BI25,BS25,CC25,CM25,CW25,DG25) -> 10.5 | DR25: =SUM(DJ25:DQ25) -> 40215
A26: Non-Destructive Inspection Tech (NDI) III | B26: Non-Destructive Inspection (NDI) Technician III | C26: 92000 | D26: 1912 | E26: 1 | F26: 1 | G26: 1 | H26: 1912 | I26: 1 | J26: 1 | K26: 1 | L26: =SUM(D26:K26) -> 3830 | N26: 1912 | O26: 1 | P26: 1 | Q26: 1 | R26: 1912 | S26: 1 | T26: 1 | U26: 1 | V26: =SUM(N26:U26) -> 3830 | X26: 1912 | Y26: 1 | Z26: 1 | AA26: 1 | AB26: 1912 | AC26: 1 | AD26: 1 | AE26: 1 | AF26: =SUM(X26:AE26) -> 3830 | AH26: 1912 | AI26: 1 | AJ26: 1 | AK26: 1 | AL26: 1912 | AM26: 1 | AN26: 1 | AO26: 1 | AP26: =SUM(AH26:AO26) -> 3830 | AR26: 1912 | AS26: 1 | AT26: 1 | AU26: 1 | AV26: 1912 | AW26: 1 | AX26: 1 | AY26: 1 | AZ26: =SUM(AR26:AY26) -> 3830 | BB26: 1912 | BC26: 1 | BD26: 1 | BE26: 1 | BF26: 1912 | BG26: 1 | BH26: 1 | BI26: 1 | BJ26: =SUM(BB26:BI26) -> 3830 | BL26: 1912 | BM26: 1 | BN26: 1 | BO26: 1 | BP26: 1912 | BQ26: 1 | BR26: 1 | BS26: 1 | BT26: =SUM(BL26:BS26) -> 3830 | BV26: 1912 | BW26: 1 | BX26: 1 | BY26: 1 | BZ26: 1912 | CA26: 1 | CB26: 1 | CC26: 1 | CD26: =SUM(BV26:CC26) -> 3830 | CF26: 1912 | CG26: 1 | CH26: 1 | CI26: 1 | CJ26: 1912 | CK26: 1 | CL26: 1 | CM26: 1 | CN26: =SUM(CF26:CM26) -> 3830 | CP26: 1912 | CQ26: 1 | CR26: 1 | CS26: 1 | CT26: 1912 | CU26: 1 | CV26: 1 | CW26: 1 | CX26: =SUM(CP26:CW26) -> 3830 | CZ26: =CP26/2 -> 956 | DA26: =CQ26/2 -> 0.5 | DB26: =CR26/2 -> 0.5 | DC26: =CS26/2 -> 0.5 | DD26: =CT26/2 -> 956 | DE26: =CU26/2 -> 0.5 | DF26: =CV26/2 -> 0.5 | DG26: =CW26/2 -> 0.5 | DH26: =SUM(CZ26:DG26) -> 1915 | DJ26: =SUM(D26,N26,X26,AH26,AR26,BB26,BL26,BV26,CF26,CP26,CZ26) -> 20076 | DK26: =SUM(E26,O26,Y26,AI26,AS26,BC26,BM26,BW26,CG26,CQ26,DA26) -> 10.5 | DL26: =SUM(F26,P26,Z26,AJ26,AT26,BD26,BN26,BX26,CH26,CR26,DB26) -> 10.5 | DM26: =SUM(G26,Q26,AA26,AK26,AU26,BE26,BO26,BY26,CI26,CS26,DC26) -> 10.5 | DN26: =SUM(H26,R26,AB26,AL26,AV26,BF26,BP26,BZ26,CJ26,CT26,DD26) -> 20076 | DO26: =SUM(I26,S26,AC26,AM26,AW26,BG26,BQ26,CA26,CK26,CU26,DE26) -> 10.5 | DP26: =SUM(J26,T26,AD26,AN26,AX26,BH26,BR26,CB26,CL26,CV26,DF26) -> 10.5 | DQ26: =SUM(K26,U26,AE26,AO26,AY26,BI26,BS26,CC26,CM26,CW26,DG26) -> 10.5 | DR26: =SUM(DJ26:DQ26) -> 40215
A27: Pilot | D27: 1 | E27: 1 | F27: 1 | G27: 1 | H27: 1 | I27: 1 | J27: 1 | K27: 1 | L27: =SUM(D27:K27) -> 8 | N27: 1 | O27: 1 | P27: 1 | Q27: 1 | R27: 1 | S27: 1 | T27: 1 | U27: 1 | V27: =SUM(N27:U27) -> 8 | X27: 1 | Y27: 1 | Z27: 1 | AA27: 1 | AB27: 1 | AC27: 1 | AD27: 1 | AE27: 1 | AF27: =SUM(X27:AE27) -> 8 | AH27: 1 | AI27: 1 | AJ27: 1 | AK27: 1 | AL27: 1 | AM27: 1 | AN27: 1 | AO27: 1 | AP27: =SUM(AH27:AO27) -> 8 | AR27: 1 | AS27: 1 | AT27: 1 | AU27: 1 | AV27: 1 | AW27: 1 | AX27: 1 | AY27: 1 | AZ27: =SUM(AR27:AY27) -> 8 | BB27: 1 | BC27: 1 | BD27: 1 | BE27: 1 | BF27: 1 | BG27: 1 | BH27: 1 | BI27: 1 | BJ27: =SUM(BB27:BI27) -> 8 | BL27: 1 | BM27: 1 | BN27: 1 | BO27: 1 | BP27: 1 | BQ27: 1 | BR27: 1 | BS27: 1 | BT27: =SUM(BL27:BS27) -> 8 | BV27: 1 | BW27: 1 | BX27: 1 | BY27: 1 | BZ27: 1 | CA27: 1 | CB27: 1 | CC27: 1 | CD27: =SUM(BV27:CC27) -> 8 | CF27: 1 | CG27: 1 | CH27: 1 | CI27: 1 | CJ27: 1 | CK27: 1 | CL27: 1 | CM27: 1 | CN27: =SUM(CF27:CM27) -> 8 | CP27: 1 | CQ27: 1 | CR27: 1 | CS27: 1 | CT27: 1 | CU27: 1 | CV27: 1 | CW27: 1 | CX27: =SUM(CP27:CW27) -> 8 | CZ27: =CP27/2 -> 0.5 | DA27: =CQ27/2 -> 0.5 | DB27: =CR27/2 -> 0.5 | DC27: =CS27/2 -> 0.5 | DD27: =CT27/2 -> 0.5 | DE27: =CU27/2 -> 0.5 | DF27: =CV27/2 -> 0.5 | DG27: =CW27/2 -> 0.5 | DH27: =SUM(CZ27:DG27) -> 4 | DJ27: =SUM(D27,N27,X27,AH27,AR27,BB27,BL27,BV27,CF27,CP27,CZ27) -> 10.5 | DK27: =SUM(E27,O27,Y27,AI27,AS27,BC27,BM27,BW27,CG27,CQ27,DA27) -> 10.5 | DL27: =SUM(F27,P27,Z27,AJ27,AT27,BD27,BN27,BX27,CH27,CR27,DB27) -> 10.5 | DM27: =SUM(G27,Q27,AA27,AK27,AU27,BE27,BO27,BY27,CI27,CS27,DC27) -> 10.5 | DN27: =SUM(H27,R27,AB27,AL27,AV27,BF27,BP27,BZ27,CJ27,CT27,DD27) -> 10.5 | DO27: =SUM(I27,S27,AC27,AM27,AW27,BG27,BQ27,CA27,CK27,CU27,DE27) -> 10.5 | DP27: =SUM(J27,T27,AD27,AN27,AX27,BH27,BR27,CB27,CL27,CV27,DF27) -> 10.5 | DQ27: =SUM(K27,U27,AE27,AO27,AY27,BI27,BS27,CC27,CM27,CW27,DG27) -> 10.5 | DR27: =SUM(DJ27:DQ27) -> 84
A28: Production Control Clerk | B28: Production Control Clerk | C28: 01270 | D28: 1 | E28: 3824 | F28: 1 | G28: 3824 | H28: 3824 | I28: 1 | J28: 1 | K28: 1 | L28: =SUM(D28:K28) -> 11477 | N28: 1 | O28: 3824 | P28: 1 | Q28: 3824 | R28: 3824 | S28: 1 | T28: 1 | U28: 1 | V28: =SUM(N28:U28) -> 11477 | X28: 1 | Y28: 3824 | Z28: 1 | AA28: 3824 | AB28: 3824 | AC28: 1 | AD28: 1 | AE28: 1 | AF28: =SUM(X28:AE28) -> 11477 | AH28: 1 | AI28: 3824 | AJ28: 1 | AK28: 3824 | AL28: 3824 | AM28: 1 | AN28: 1 | AO28: 1 | AP28: =SUM(AH28:AO28) -> 11477 | AR28: 1 | AS28: 3824 | AT28: 1 | AU28: 3824 | AV28: 3824 | AW28: 1 | AX28: 1 | AY28: 1 | AZ28: =SUM(AR28:AY28) -> 11477 | BB28: 1 | BC28: 3824 | BD28: 1 | BE28: 3824 | BF28: 3824 | BG28: 1 | BH28: 1 | BI28: 1 | BJ28: =SUM(BB28:BI28) -> 11477 | BL28: 1 | BM28: 3824 | BN28: 1 | BO28: 3824 | BP28: 3824 | BQ28: 1 | BR28: 1 | BS28: 1 | BT28: =SUM(BL28:BS28) -> 11477 | BV28: 1 | BW28: 3824 | BX28: 1 | BY28: 3824 | BZ28: 3824 | CA28: 1 | CB28: 1 | CC28: 1 | CD28: =SUM(BV28:CC28) -> 11477 | CF28: 1 | CG28: 3824 | CH28: 1 | CI28: 3824 | CJ28: 3824 | CK28: 1 | CL28: 1 | CM28: 1 | CN28: =SUM(CF28:CM28) -> 11477 | CP28: 1 | CQ28: 3824 | CR28: 1 | CS28: 3824 | CT28: 3824 | CU28: 1 | CV28: 1 | CW28: 1 | CX28: =SUM(CP28:CW28) -> 11477 | CZ28: =CP28/2 -> 0.5 | DA28: =CQ28/2 -> 1912 | DB28: =CR28/2 -> 0.5 | DC28: =CS28/2 -> 1912 | DD28: =CT28/2 -> 1912 | DE28: =CU28/2 -> 0.5 | DF28: =CV28/2 -> 0.5 | DG28: =CW28/2 -> 0.5 | DH28: =SUM(CZ28:DG28) -> 5738.5 | DJ28: =SUM(D28,N28,X28,AH28,AR28,BB28,BL28,BV28,CF28,CP28,CZ28) -> 10.5 | DK28: =SUM(E28,O28,Y28,AI28,AS28,BC28,BM28,BW28,CG28,CQ28,DA28) -> 40152 | DL28: =SUM(F28,P28,Z28,AJ28,AT28,BD28,BN28,BX28,CH28,CR28,DB28) -> 10.5 | DM28: =SUM(G28,Q28,AA28,AK28,AU28,BE28,BO28,BY28,CI28,CS28,DC28) -> 40152 | DN28: =SUM(H28,R28,AB28,AL28,AV28,BF28,BP28,BZ28,CJ28,CT28,DD28) -> 40152 | DO28: =SUM(I28,S28,AC28,AM28,AW28,BG28,BQ28,CA28,CK28,CU28,DE28) -> 10.5 | DP28: =SUM(J28,T28,AD28,AN28,AX28,BH28,BR28,CB28,CL28,CV28,DF28) -> 10.5 | DQ28: =SUM(K28,U28,AE28,AO28,AY28,BI28,BS28,CC28,CM28,CW28,DG28) -> 10.5 | DR28: =SUM(DJ28:DQ28) -> 120508.5
A29: Quality Control Inspector | D29: 1 | E29: 19120 | F29: 1 | G29: 1 | H29: 1 | I29: 1 | J29: 1 | K29: 1 | L29: =SUM(D29:K29) -> 19127 | N29: 1 | O29: 19120 | P29: 1 | Q29: 1 | R29: 1 | S29: 1 | T29: 1 | U29: 1 | V29: =SUM(N29:U29) -> 19127 | X29: 1 | Y29: 19120 | Z29: 1 | AA29: 1 | AB29: 1 | AC29: 1 | AD29: 1 | AE29: 1 | AF29: =SUM(X29:AE29) -> 19127 | AH29: 1 | AI29: 19120 | AJ29: 1 | AK29: 1 | AL29: 1 | AM29: 1 | AN29: 1 | AO29: 1 | AP29: =SUM(AH29:AO29) -> 19127 | AR29: 1 | AS29: 19120 | AT29: 1 | AU29: 1 | AV29: 1 | AW29: 1 | AX29: 1 | AY29: 1 | AZ29: =SUM(AR29:AY29) -> 19127 | BB29: 1 | BC29: 19120 | BD29: 1 | BE29: 1 | BF29: 1 | BG29: 1 | BH29: 1 | BI29: 1 | BJ29: =SUM(BB29:BI29) -> 19127 | BL29: 1 | BM29: 19120 | BN29: 1 | BO29: 1 | BP29: 1 | BQ29: 1 | BR29: 1 | BS29: 1 | BT29: =SUM(BL29:BS29) -> 19127 | BV29: 1 | BW29: 19120 | BX29: 1 | BY29: 1 | BZ29: 1 | CA29: 1 | CB29: 1 | CC29: 1 | CD29: =SUM(BV29:CC29) -> 19127 | CF29: 1 | CG29: 19120 | CH29: 1 | CI29: 1 | CJ29: 1 | CK29: 1 | CL29: 1 | CM29: 1 | CN29: =SUM(CF29:CM29) -> 19127 | CP29: 1 | CQ29: 19120 | CR29: 1 | CS29: 1 | CT29: 1 | CU29: 1 | CV29: 1 | CW29: 1 | CX29: =SUM(CP29:CW29) -> 19127 | CZ29: =CP29/2 -> 0.5 | DA29: =CQ29/2 -> 9560 | DB29: =CR29/2 -> 0.5 | DC29: =CS29/2 -> 0.5 | DD29: =CT29/2 -> 0.5 | DE29: =CU29/2 -> 0.5 | DF29: =CV29/2 -> 0.5 | DG29: =CW29/2 -> 0.5 | DH29: =SUM(CZ29:DG29) -> 9563.5 | DJ29: =SUM(D29,N29,X29,AH29,AR29,BB29,BL29,BV29,CF29,CP29,CZ29) -> 10.5 | DK29: =SUM(E29,O29,Y29,AI29,AS29,BC29,BM29,BW29,CG29,CQ29,DA29) -> 200760 | DL29: =SUM(F29,P29,Z29,AJ29,AT29,BD29,BN29,BX29,CH29,CR29,DB29) -> 10.5 | DM29: =SUM(G29,Q29,AA29,AK29,AU29,BE29,BO29,BY29,CI29,CS29,DC29) -> 10.5 | DN29: =SUM(H29,R29,AB29,AL29,AV29,BF29,BP29,BZ29,CJ29,CT29,DD29) -> 10.5 | DO29: =SUM(I29,S29,AC29,AM29,AW29,BG29,BQ29,CA29,CK29,CU29,DE29) -> 10.5 | DP29: =SUM(J29,T29,AD29,AN29,AX29,BH29,BR29,CB29,CL29,CV29,DF29) -> 10.5 | DQ29: =SUM(K29,U29,AE29,AO29,AY29,BI29,BS29,CC29,CM29,CW29,DG29) -> 10.5 | DR29: =SUM(DJ29:DQ29) -> 200833.5
A30: Safety/OSHA Inspector | D30: 1912 | E30: 1 | F30: 1 | G30: 3824 | H30: 3824 | I30: 1 | J30: 1 | K30: 1 | L30: =SUM(D30:K30) -> 9565 | N30: 1912 | O30: 1 | P30: 1 | Q30: 3824 | R30: 3824 | S30: 1 | T30: 1 | U30: 1 | V30: =SUM(N30:U30) -> 9565 | X30: 1912 | Y30: 1 | Z30: 1 | AA30: 3824 | AB30: 3824 | AC30: 1 | AD30: 1 | AE30: 1 | AF30: =SUM(X30:AE30) -> 9565 | AH30: 1912 | AI30: 1 | AJ30: 1 | AK30: 3824 | AL30: 3824 | AM30: 1 | AN30: 1 | AO30: 1 | AP30: =SUM(AH30:AO30) -> 9565 | AR30: 1912 | AS30: 1 | AT30: 1 | AU30: 3824 | AV30: 3824 | AW30: 1 | AX30: 1 | AY30: 1 | AZ30: =SUM(AR30:AY30) -> 9565 | BB30: 1912 | BC30: 1 | BD30: 1 | BE30: 3824 | BF30: 3824 | BG30: 1 | BH30: 1 | BI30: 1 | BJ30: =SUM(BB30:BI30) -> 9565 | BL30: 1912 | BM30: 1 | BN30: 1 | BO30: 3824 | BP30: 3824 | BQ30: 1 | BR30: 1 | BS30: 1 | BT30: =SUM(BL30:BS30) -> 9565 | BV30: 1912 | BW30: 1 | BX30: 1 | BY30: 3824 | BZ30: 3824 | CA30: 1 | CB30: 1 | CC30: 1 | CD30: =SUM(BV30:CC30) -> 9565 | CF30: 1912 | CG30: 1 | CH30: 1 | CI30: 3824 | CJ30: 3824 | CK30: 1 | CL30: 1 | CM30: 1 | CN30: =SUM(CF30:CM30) -> 9565 | CP30: 1912 | CQ30: 1 | CR30: 1 | CS30: 3824 | CT30: 3824 | CU30: 1 | CV30: 1 | CW30: 1 | CX30: =SUM(CP30:CW30) -> 9565 | CZ30: =CP30/2 -> 956 | DA30: =CQ30/2 -> 0.5 | DB30: =CR30/2 -> 0.5 | DC30: =CS30/2 -> 1912 | DD30: =CT30/2 -> 1912 | DE30: =CU30/2 -> 0.5 | DF30: =CV30/2 -> 0.5 | DG30: =CW30/2 -> 0.5 | DH30: =SUM(CZ30:DG30) -> 4782.5 | DJ30: =SUM(D30,N30,X30,AH30,AR30,BB30,BL30,BV30,CF30,CP30,CZ30) -> 20076 | DK30: =SUM(E30,O30,Y30,AI30,AS30,BC30,BM30,BW30,CG30,CQ30,DA30) -> 10.5 | DL30: =SUM(F30,P30,Z30,AJ30,AT30,BD30,BN30,BX30,CH30,CR30,DB30) -> 10.5 | DM30: =SUM(G30,Q30,AA30,AK30,AU30,BE30,BO30,BY30,CI30,CS30,DC30) -> 40152 | DN30: =SUM(H30,R30,AB30,AL30,AV30,BF30,BP30,BZ30,CJ30,CT30,DD30) -> 40152 | DO30: =SUM(I30,S30,AC30,AM30,AW30,BG30,BQ30,CA30,CK30,CU30,DE30) -> 10.5 | DP30: =SUM(J30,T30,AD30,AN30,AX30,BH30,BR30,CB30,CL30,CV30,DF30) -> 10.5 | DQ30: =SUM(K30,U30,AE30,AO30,AY30,BI30,BS30,CC30,CM30,CW30,DG30) -> 10.5 | DR30: =SUM(DJ30:DQ30) -> 100432.5
