Workbook
Name Common: #REF!
Name Consum: #REF!
Name EngRate: #REF!
Name GARate: #REF!
Name GrossProfit: #REF!
Name MatHandle: #REF!
Name Risk: #REF!
Name ShopRate: #REF!

Sheet INSTRUCTIONS
B1: Source Selection Information - See FAR 2.101 and 3.104
B2: KC-135 Center Console Refresh (CCR) Source Selection
B3: Attachment 3A, EPW - PRIME
B4: Notes:
B5: 1. The worksheet tabs highlighted in yellow within Attachment 3A require Offeror input; the cells within each worksheet requiring input are highlighted in yellow
B6: 2. All proposed dollar amounts and labor rates shall be rounded to two decimal places. All proposed rates in percentages shall be rounded to four decimal places (ex. .0755 = 7.55%)
B7: 3. The Total Evaluated Price (TEP) is calculated by multiplying the Best Estimated Quantities (BEQs) by the amounts proposed for the FFP and CPIF CLINs. The TEP will automatically calculate in the "SUMMARY" worksheet
B8: 4. The Total Evaluated Price (TEP) by performance period will automatically calculate on the "TOTAL EVALUATED PRICE ROLLUP" worksheet
B10: Instructions for completing this Pricing Matrix/Cost Model:
B12: Pricing Matrix - FFP CLINs X007 - X016, X020, and X021:
B13: 1 | C13: Offerors are required to input the proposed unit prices into the "FFP CLINs X007-X021" worksheet in ALL yellow highlighted cells (Offeror Name in Cell B1 and dollar amounts in Columns F, J, N, R, V, Z, and AD)
B14: 2 | C14: Offerors are required to input the supporting information and proposed quantities/unit prices for the Production Spares for the B-Kit in the "SPARES-FFP CLIN X021 INPUTS" worksheet. The total amount by period will automatically populate the "FFP CLINs X007-X021" worksheet for CLIN X021
B15: 3 | C15: The extended price for CLINs X007 - X021 will be automatically calculated by multiplying the proposed unit price by the best estimated evaluation quantity
B16: 4 | C16: A subtotal price will be automatically calculated at the bottom of each contract period/year
B17: 5 | C17: The total proposed amounts for the FFP CLINs will automatically populate the "SUMMARY" worksheet, which will ultimately calculate the Total Evaluated Price (TEP)
B19: Cost Model - CPIF CLINs 0001 - 0003:
B20: 1 | C20: Refer to the "Notes" on each CPIF worksheet for specific information/instructions
B21: 2 | C21: The format of the Cost Model worksheets entitled "PRIME CPIF RATES (ALL)", "PRIME CPIF RATE DESC (ALL)", "PRIME CPIF LABOR by TASK", "PRIME CPIF LABOR INPUTS", "PRIME CPIF TOTAL MATERIAL", "PRIME CPIF TOTAL SUB", "PRIME CPIF TOTAL ODC" and "CPIF CLIN 000X-TASK 1.XX INPUTS" may be revised by the Offeror as necessary; if revisions are made, Offerors shall ensure properly linking to corresponding worksheets
B22: 3 | C22: The "CPIF CLIN 000X-TASK 1.XX INPUTS" worksheets are linked to the "PRIME CPIF RATES (ALL)", "PRIME CPIF LABOR INPUTS", "PRIME CPIF TOTAL MATERIAL", "PRIME CPIF TOTAL SUB", and "PRIME CPIF TOTAL ODC" worksheets. Inputs in the "CPIF CLIN 000X-TASK 1.XX INPUTS" worksheets are not required, but the format of these worksheets may be revised, if necessary
B23: 4 | C23: The "CPIF CLIN 000X TOTAL" worksheets are linked to the "CPIF CLIN 000X-TASK 1.XX INPUTS" worksheets; no inputs are required, but the format of these worksheets should be revised to align with "CPIF 000X-TASK 1.XX INPUTS" worksheets, if necessary
B24: 5 | C24: The "CPIF CLIN 000X SUMMARY" worksheets includes links to the "CPIF CLIN 000X-TASK 1.XX INPUTS" worksheets; no inputs required
B25: 6 | C25: The total proposed amounts for the CPIF CLINs will automatically populate the "SUMMARY" worksheet, which will ultimately calculate the TEP; no inputs required
B26: 7 | C26: The minimum fees, maximum fees, and share ratios are provided by the Government in the "CPIF CLIN BREAKDOWN" worksheet. The CPIF CLIN breakout by Target Cost, Target Fee, Target FCCOM, and Target Price will automatically populate the "CPIF CLIN BREAKDOWN" worksheet for each CPIF CLIN based on the Offeror's inputs in the above worksheets; no inputs required.

Sheet CALCULATION METHODOLOGY
A1: KC-135 CCR EXCEL PRICING WORKBOOK (EPW) - CALCULATION METHODOLOGY - PRIME OFFEROR
A2: CLIN | B2: CONTRACT TYPE | C2: DESCRIPTION | D2: CALCULATION METHODOLOGY
A3: EMD
A4: 0001 | B4: CPIF | C4: Development | D4: Proposed target price for EMD CLIN 0001 based on inputs from EMD CPIF worksheets (lot price)
A5: 0002 | B5: CPIF | C5: Simulator Kit | D5: Proposed target price for EMD CLIN 0002 based on inputs from EMD CPIF worksheets (lot price)
A6: 0003 | B6: CPIF | C6: Systems Integration Laboratory (SIL) | D6: Proposed target price for EMD CLIN 0003 based on inputs from EMD CPIF worksheets (lot price)
A7: 0004 | B7: NSP | C7: Contract Data Requirements Lists (CDRLs) | D7: Not evaluated
A8: 0005 | B8: CR-NF | C8: Travel - EMD | D8: Not evaluated
A9: 0006 | B9: NSP | C9: Data/Intellectual Property | D9: Not evaluated
A10: PRODUCTION
A11: X007 | B11: FFP | C11: Production A-Kits | D11: Proposed unit price (fully burdened) multiplied by best estimated quantity of A-Kits for each performance period
A12: X008 | B12: FFP | C12: Production B-Kits | D12: Proposed unit price (fully burdened) multiplied by best estimated quantity of B-Kits for each performance period
A13: X009 | B13: FFP | C13: Support Equipment | D13: Proposed lot price (fully burdened) for Support Equipment for each performance period
A14: X010 | B14: FFP | C14: Installations | D14: Proposed unit price (fully burdened) multiplied by best estimated quantity of Installations for each performance period
A15: X011 | B15: FFP | C15: Production Configuratiaon Control/Engineering Change Orders | D15: Proposed monthly price (fully burdened) multiplied by quantity of months in the performance period
A16: X012 | B16: FFP | C16: Maintenance & Repair Support | D16: Proposed monthly price (fully burdened) multiplied by quantity of months in the performance period
A17: X013 | B17: FFP | C17: Technical Orders | D17: Proposed monthly price (fully burdened) multiplied by quantity of months in the performance period
A18: X014 | B18: FFP | C18: Simulator Kits | D18: Proposed unit price (fully burdened) multiplied by best estimated quantity of Simulator Kits for each performance period
A19: X015 | B19: FFP | C19: SIL | D19: Proposed unit price (fully burdened) multiplied by best estimated quantity of SILs for each performance period
A20: X016 | B20: FFP | C20: Training | D20: Proposed monthly price (fully burdened) multiplied by quantity of months in the performance period
A21: X017 | B21: NSP | C21: Data - Production | D21: Not evaluated
A22: X018 | B22: CR-NF | C22: Travel - Production | D22: Not evaluated
... A25: X021 | B25: FFP | C25: Production Spares | D25: Proposed unit price (fully burdened) multiplied by best estimated quantity of Production Spare Kits (unit price calculated by inputs in the "Spares-FFP CLIN X021 INPUTS" worksheet) for each performance period

Sheet SUMMARY
A1: PRIME OFFEROR | B1: ='FFP CLINs X007-X021'!B1 -> NAME
A3: Notes: Proposed CLIN unit costs/prices are linked to the "CPIF CLIN 000X TOTAL" and "FFP CLINs X007 - X021" worksheets; no input required
A7: KC-135 Center Console Refresh (CCR) Competitive Pricing Matrix SUMMARY | E7: Basic Period (48 months) | I7: Option Period I Performance (12 months) | M7: Option Period II Performance (12 months) | Q7: Option Period III Performance (12 months) | U7: Option Period IV Performance (12 months) | Y7: Option Period V Performance (12 months) | AC7: Option Period VI Performance (12 months)
A8: CLIN Description | B8: Contract Type | C8: Unit of Issue | D8: Basic Period CLIN | E8: Qty/BEQ | F8: Unit Price | G8: Extended Price | H8: Option Period I CLIN | I8: Qty/BEQ | J8: Unit Price | K8: Extended Price | L8: Option Period II CLIN | M8: Qty/BEQ | N8: Unit Price | O8: Extended Price | P8: Option Period III CLIN | Q8: Qty/BEQ | R8: Unit Price | S8: Extended Price | T8: Option Period IV CLIN | U8: Qty/BEQ | V8: Unit Price | W8: Extended Price | X8: Option Period V CLIN | Y8: Qty/BEQ | Z8: Unit Price | AA8: Extended Price | AB8: Option Period VI CLIN | AC8: Qty/BEQ | AD8: Unit Price | AE8: Extended Price | AG8: TOTAL EVALUATED PRICE
A9: EMD | E9: EMD | I9: EMD | M9: EMD | Q9: EMD | U9: EMD | Y9: EMD | AC9: EMD
A10: Development | B10: Cost Plus Incentive Fee (CPIF) | C10: Lot | D10: 0001 | E10: 1 | F10: ='CPIF CLIN 0001 TOTAL'!Q73 -> 0 | G10: =ROUND(E10*F10,0) -> 0 | AG10: =G10 -> 0
A11: Simulator Kit | B11: CPIF | C11: Lot | D11: 0002 | E11: 1 | F11: ='CPIF CLIN 0002 TOTAL'!Q72 -> 0 | G11: =ROUND(E11*F11,0) -> 0 | AG11: =G11 -> 0
A12: Systems Integration Laboratory (SIL) | B12: CPIF | C12: Lot | D12: 0003 | E12: 1 | F12: ='CPIF CLIN 0003 TOTAL'!Q73 -> 0 | G12: =ROUND(E12*F12,0) -> 0 | AG12: =G12 -> 0
A13: Data - EMD | B13: Not Separately Priced (NSP) | C13: N/A | D13: 0004
A14: Travel - EMD | B14: Cost Reimbursable - No Fee (CR-NF) | C14: N/A | D14: 0005
A15: Intellectual Property | B15: NSP | C15: N/A | D15: 0006
A16: PRODUCTION | E16: PRODUCTION | I16: PRODUCTION | M16: PRODUCTION | Q16: PRODUCTION | U16: PRODUCTION | Y16: PRODUCTION | AC16: PRODUCTION
A17: A-Kits - Production | B17: FFP | C17: Each | D17: 0007 | E17: ='FFP CLINs X007-X021'!E12 -> 16 | F17: ='FFP CLINs X007-X021'!F12 -> 0 | G17: =ROUND(E17*F17,0) -> 0 | H17: 1007 | I17: ='FFP CLINs X007-X021'!I12 -> 50 | J17: ='FFP CLINs X007-X021'!J12 -> 0 | K17: =ROUND(I17*J17,0) -> 0 | L17: 2007 | M17: ='FFP CLINs X007-X021'!M12 -> 50 | N17: ='FFP CLINs X007-X021'!N12 -> 0 | O17: =ROUND(M17*N17,0) -> 0 | P17: 3007 | Q17: ='FFP CLINs X007-X021'!Q12 -> 47 | R17: ='FFP CLINs X007-X021'!R12 -> 0 | S17: =ROUND(Q17*R17,0) -> 0 | T17: 4007 | U17: ='FFP CLINs X007-X021'!U12 -> 45 | V17: ='FFP CLINs X007-X021'!V12 -> 0 | W17: =ROUND(U17*V17,0) -> 0 | X17: 5007 | Y17: ='FFP CLINs X007-X021'!Y12 -> 45 | Z17: ='FFP CLINs X007-X021'!Z12 -> 0 | AA17: =ROUND(Y17*Z17,0) -> 0 | AB17: 6007 | AC17: ='FFP CLINs X007-X021'!AC12 -> 53 | AD17: ='FFP CLINs X007-X021'!AD12 -> 0 | AE17: =ROUND(AC17*AD17,0) -> 0 | AG17: =G17+K17+O17+S17+W17+AA17+AE17 -> 0
A18: B-Kits - Production | B18: FFP | C18: Each | D18: 0008 | E18: ='FFP CLINs X007-X021'!E13 -> 12 | F18: ='FFP CLINs X007-X021'!F13 -> 0 | G18: =ROUND(E18*F18,0) -> 0 | H18: 1008 | I18: ='FFP CLINs X007-X021'!I13 -> 45 | J18: ='FFP CLINs X007-X021'!J13 -> 0 | K18: =ROUND(I18*J18,0) -> 0 | L18: 2008 | M18: ='FFP CLINs X007-X021'!M13 -> 45 | N18: ='FFP CLINs X007-X021'!N13 -> 0 | O18: =ROUND(M18*N18,0) -> 0 | P18: 3008 | Q18: ='FFP CLINs X007-X021'!Q13 -> 45 | R18: ='FFP CLINs X007-X021'!R13 -> 0 | S18: =ROUND(Q18*R18,0) -> 0 | T18: 4008 | U18: ='FFP CLINs X007-X021'!U13 -> 45 | V18: ='FFP CLINs X007-X021'!V13 -> 0 | W18: =ROUND(U18*V18,0) -> 0 | X18: 5008 | Y18: ='FFP CLINs X007-X021'!Y13 -> 45 | Z18: ='FFP CLINs X007-X021'!Z13 -> 0 | AA18: =ROUND(Y18*Z18,0) -> 0 | AB18: 6008 | AC18: ='FFP CLINs X007-X021'!AC13 -> 53 | AD18: ='FFP CLINs X007-X021'!AD13 -> 0 | AE18: =ROUND(AC18*AD18,0) -> 0 | AG18: =G18+K18+O18+S18+W18+AA18+AE18 -> 0
A19: Support Equipment - Production | B19: FFP | C19: Lot | D19: 0009 | E19: ='FFP CLINs X007-X021'!E14 -> 1 | F19: ='FFP CLINs X007-X021'!F14 -> 0 | G19: =ROUND(E19*F19,0) -> 0 | H19: 1009 | I19: ='FFP CLINs X007-X021'!I14 -> 1 | J19: ='FFP CLINs X007-X021'!J14 -> 0 | K19: =ROUND(I19*J19,0) -> 0 | L19: 2009 | M19: ='FFP CLINs X007-X021'!M14 -> 1 | N19: ='FFP CLINs X007-X021'!N14 -> 0 | O19: =ROUND(M19*N19,0) -> 0 | P19: 3009 | Q19: ='FFP CLINs X007-X021'!Q14 -> 1 | R19: ='FFP CLINs X007-X021'!R14 -> 0 | S19: =ROUND(Q19*R19,0) -> 0 | T19: 4009 | U19: ='FFP CLINs X007-X021'!U14 -> 1 | V19: ='FFP CLINs X007-X021'!V14 -> 0 | W19: =ROUND(U19*V19,0) -> 0 | X19: 5009 | Y19: ='FFP CLINs X007-X021'!Y14 -> 1 | Z19: ='FFP CLINs X007-X021'!Z14 -> 0 | AA19: =ROUND(Y19*Z19,0) -> 0 | AB19: 6009 | AC19: ='FFP CLINs X007-X021'!AC14 -> 1 | AD19: ='FFP CLINs X007-X021'!AD14 -> 0 | AE19: =ROUND(AC19*AD19,0) -> 0 | AG19: =G19+K19+O19+S19+W19+AA19+AE19 -> 0
A20: Installations | B20: FFP | C20: Each | D20: 0010 | H20: 1010 | I20: ='FFP CLINs X007-X021'!I15 -> 12 | J20: ='FFP CLINs X007-X021'!J15 -> 0 | K20: =ROUND(I20*J20,0) -> 0 | L20: 2010 | M20: ='FFP CLINs X007-X021'!M15 -> 45 | N20: ='FFP CLINs X007-X021'!N15 -> 0 | O20: =ROUND(M20*N20,0) -> 0 | P20: 3010 | Q20: ='FFP CLINs X007-X021'!Q15 -> 45 | R20: ='FFP CLINs X007-X021'!R15 -> 0 | S20: =ROUND(Q20*R20,0) -> 0 | T20: 4010 | U20: ='FFP CLINs X007-X021'!U15 -> 45 | V20: ='FFP CLINs X007-X021'!V15 -> 0 | W20: =ROUND(U20*V20,0) -> 0 | X20: 5010 | Y20: ='FFP CLINs X007-X021'!Y15 -> 45 | Z20: ='FFP CLINs X007-X021'!Z15 -> 0 | AA20: =ROUND(Y20*Z20,0) -> 0 | AB20: 6010 | AC20: ='FFP CLINs X007-X021'!AC15 -> 45 | AD20: ='FFP CLINs X007-X021'!AD15 -> 0 | AE20: =ROUND(AC20*AD20,0) -> 0 | AG20: =K20+O20+S20+W20+AA20+AE20 -> 0
A21: Production Configuratiaon Control/Engineering Change Orders | B21: FFP | C21: Month | D21: 0011 | H21: 1011 | I21: ='FFP CLINs X007-X021'!I16 -> 12 | J21: ='FFP CLINs X007-X021'!J16 -> 0 | K21: =ROUND(I21*J21,0) -> 0 | L21: 2011 | M21: ='FFP CLINs X007-X021'!M16 -> 12 | N21: ='FFP CLINs X007-X021'!N16 -> 0 | O21: =ROUND(M21*N21,0) -> 0 | P21: 3011 | Q21: ='FFP CLINs X007-X021'!Q16 -> 12 | R21: ='FFP CLINs X007-X021'!R16 -> 0 | S21: =ROUND(Q21*R21,0) -> 0 | T21: 4011 | U21: ='FFP CLINs X007-X021'!U16 -> 12 | V21: ='FFP CLINs X007-X021'!V16 -> 0 | W21: =ROUND(U21*V21,0) -> 0 | X21: 5011 | Y21: ='FFP CLINs X007-X021'!Y16 -> 12 | Z21: ='FFP CLINs X007-X021'!Z16 -> 0 | AA21: =ROUND(Y21*Z21,0) -> 0 | AB21: 6011 | AC21: ='FFP CLINs X007-X021'!AC16 -> 12 | AD21: ='FFP CLINs X007-X021'!AD16 -> 0 | AE21: =ROUND(AC21*AD21,0) -> 0 | AG21: =K21+O21+S21+W21+AA21+AE21 -> 0
A22: Maintenance & Repair Support - Production | B22: FFP | C22: Month | D22: 0012 | H22: 1012 | I22: ='FFP CLINs X007-X021'!I17 -> 12 | J22: ='FFP CLINs X007-X021'!J17 -> 0 | K22: =ROUND(I22*J22,0) -> 0 | L22: 2012 | M22: ='FFP CLINs X007-X021'!M17 -> 12 | N22: ='FFP CLINs X007-X021'!N17 -> 0 | O22: =ROUND(M22*N22,0) -> 0 | P22: 3012 | Q22: ='FFP CLINs X007-X021'!Q17 -> 12 | R22: ='FFP CLINs X007-X021'!R17 -> 0 | S22: =ROUND(Q22*R22,0) -> 0 | T22: 4012 | U22: ='FFP CLINs X007-X021'!U17 -> 12 | V22: ='FFP CLINs X007-X021'!V17 -> 0 | W22: =ROUND(U22*V22,0) -> 0 | X22: 5012 | Y22: ='FFP CLINs X007-X021'!Y17 -> 12 | Z22: ='FFP CLINs X007-X021'!Z17 -> 0 | AA22: =ROUND(Y22*Z22,0) -> 0 | AB22: 6012 | AC22: ='FFP CLINs X007-X021'!AC17 -> 12 | AD22: ='FFP CLINs X007-X021'!AD17 -> 0 | AE22: =ROUND(AC22*AD22,0) -> 0 | AG22: =K22+O22+S22+W22+AA22+AE22 -> 0
A23: Technical Orders - Production | B23: FFP | C23: Month | D23: 0013 | H23: 1013 | I23: ='FFP CLINs X007-X021'!I18 -> 12 | J23: ='FFP CLINs X007-X021'!J18 -> 0 | K23: =ROUND(I23*J23,0) -> 0 | L23: 2013 | M23: ='FFP CLINs X007-X021'!M18 -> 12 | N23: ='FFP CLINs X007-X021'!N18 -> 0 | O23: =ROUND(M23*N23,0) -> 0 | P23: 3013 | Q23: ='FFP CLINs X007-X021'!Q18 -> 12 | R23: ='FFP CLINs X007-X021'!R18 -> 0 | S23: =ROUND(Q23*R23,0) -> 0 | T23: 4013 | U23: ='FFP CLINs X007-X021'!U18 -> 12 | V23: ='FFP CLINs X007-X021'!V18 -> 0 | W23: =ROUND(U23*V23,0) -> 0 | X23: 5013 | Y23: ='FFP CLINs X007-X021'!Y18 -> 12 | Z23: ='FFP CLINs X007-X021'!Z18 -> 0 | AA23: =ROUND(Y23*Z23,0) -> 0 | AB23: 6013 | AC23: ='FFP CLINs X007-X021'!AC18 -> 12 | AD23: ='FFP CLINs X007-X021'!AD18 -> 0 | AE23: =ROUND(AC23*AD23,0) -> 0 | AG23: =K23+O23+S23+W23+AA23+AE23 -> 0
A24: Simulator Kits - Production | B24: FFP | C24: Each | D24: 0014 | E24: ='FFP CLINs X007-X021'!E19 -> 3 | F24: ='FFP CLINs X007-X021'!F19 -> 0 | G24: =ROUND(E24*F24,0) -> 0 | H24: 1014 | I24: ='FFP CLINs X007-X021'!I19 -> 6 | J24: ='FFP CLINs X007-X021'!J19 -> 0 | K24: =ROUND(I24*J24,0) -> 0 | L24: 2014 | M24: ='FFP CLINs X007-X021'!M19 -> 6 | N24: ='FFP CLINs X007-X021'!N19 -> 0 | O24: =ROUND(M24*N24,0) -> 0 | P24: 3014 | Q24: ='FFP CLINs X007-X021'!Q19 -> 6 | R24: ='FFP CLINs X007-X021'!R19 -> 0 | S24: =ROUND(Q24*R24,0) -> 0 | T24: 4014 | X24: 5014 | Y24: ='FFP CLINs X007-X021'!Y19 | Z24: ='FFP CLINs X007-X021'!Z19 | AB24: 6014 | AC24: ='FFP CLINs X007-X021'!AC19 | AD24: ='FFP CLINs X007-X021'!AD19 | AG24: =G24+K24+O24+S24 -> 0
A25: SIL - Production | B25: FFP | C25: Each | D25: 0015 | H25: 1015 | L25: 2015 | M25: ='FFP CLINs X007-X021'!M20 -> 1 | N25: ='FFP CLINs X007-X021'!N21 -> 0 | O25: =ROUND(M25*N25,0) -> 0 | P25: 3015 | T25: 4015 | X25: 5015 | Y25: ='FFP CLINs X007-X021'!Y20 | AB25: 6015 | AC25: ='FFP CLINs X007-X021'!AC20 | AD25: ='FFP CLINs X007-X021'!AD21 -> 0 | AG25: =O25 -> 0
A26: Training | B26: FFP | C26: Month | D26: 0016 | E26: ='FFP CLINs X007-X021'!E21 -> 12 | F26: ='FFP CLINs X007-X021'!F21 -> 0 | G26: =ROUND(E26*F26,0) -> 0 | H26: 1016 | I26: ='FFP CLINs X007-X021'!I21 -> 12 | J26: ='FFP CLINs X007-X021'!J21 -> 0 | K26: =ROUND(I26*J26,0) -> 0 | L26: 2016 | M26: ='FFP CLINs X007-X021'!M21 -> 12 | N26: ='FFP CLINs X007-X021'!N21 -> 0 | O26: =ROUND(M26*N26,0) -> 0 | P26: 3016 | Q26: ='FFP CLINs X007-X021'!Q21 -> 12 | R26: ='FFP CLINs X007-X021'!R21 -> 0 | S26: =ROUND(Q26*R26,0) -> 0 | T26: 4016 | U26: ='FFP CLINs X007-X021'!U21 -> 12 | V26: ='FFP CLINs X007-X021'!V21 -> 0 | W26: =ROUND(U26*V26,0) -> 0 | X26: 5016 | Y26: ='FFP CLINs X007-X021'!Y21 -> 12 | Z26: ='FFP CLINs X007-X021'!Z21 -> 0 | AA26: =ROUND(Y26*Z26,0) -> 0 | AB26: 6016 | AC26: ='FFP CLINs X007-X021'!AC21 -> 12 | AD26: ='FFP CLINs X007-X021'!AD21 -> 0 | AE26: =ROUND(AC26*AD26,0) -> 0 | AG26: =G26+K26+O26+S26+W26+AA26+AE26 -> 0
A27: Data - Production | B27: NSP | C27: N/A | D27: 0017 | H27: 1017 | L27: 2017 | P27: 3017 | T27: 4017 | X27: 5017 | AB27: 6017
A28: Travel - Production | B28: CR-NF | C28: N/A | D28: 0018 | H28: 1018 | L28: 2018 | P28: 3018 | T28: 4018 | X28: 5018 | AB28: 6018
A29: Over & Above | B29: CR-NF | C29: N/A | D29: 0019 | H29: 1019 | L29: 2019 | P29: 3019 | T29: 4019 | X29: 8019 | AB29: 6019
A30: Program Management - Production | B30: FFP | C30: Month | D30: 0020 | E30: ='FFP CLINs X007-X021'!E22 -> 12 | F30: ='FFP CLINs X007-X021'!F22 -> 0 | G30: =ROUND(E30*F30,0) -> 0 | H30: 1020 | I30: ='FFP CLINs X007-X021'!I22 -> 12 | J30: ='FFP CLINs X007-X021'!J22 -> 0 | K30: =ROUND(I30*J30,0) -> 0 | L30: 2020 | M30: ='FFP CLINs X007-X021'!M22 -> 12 | N30: ='FFP CLINs X007-X021'!N22 -> 0 | O30: =ROUND(M30*N30,0) -> 0 | P30: 3020 | Q30: ='FFP CLINs X007-X021'!Q22 -> 12 | R30: ='FFP CLINs X007-X021'!R22 -> 0 | S30: =ROUND(Q30*R30,0) -> 0 | T30: 4020 | U30: ='FFP CLINs X007-X021'!U22 -> 12 | V30: ='FFP CLINs X007-X021'!V22 -> 0 | W30: =ROUND(U30*V30,0) -> 0 | X30: 5020 | Y30: ='FFP CLINs X007-X021'!Y22 -> 12 | Z30: ='FFP CLINs X007-X021'!Z22 -> 0 | AA30: =ROUND(Y30*Z30,0) -> 0 | AB30: 6020 | AC30: ='FFP CLINs X007-X021'!AC22 -> 12 | AD30: ='FFP CLINs X007-X021'!AD22 -> 0 | AE30: =ROUND(AC30*AD30,0) -> 0 | AG30: =G30+K30+O30+S30+W30+AA30+AE30 -> 0
A31: Production Spares | B31: FFP | C31: Each | D31: 0021 | E31: ='FFP CLINs X007-X021'!E23 -> 2 | F31: ='FFP CLINs X007-X021'!F23 -> 0 | G31: =ROUND(E31*F31,0) -> 0 | H31: 1021 | I31: ='FFP CLINs X007-X021'!I23 -> 6 | J31: ='FFP CLINs X007-X021'!J23 -> 0 | K31: =ROUND(I31*J31,0) -> 0 | L31: 2021 | M31: ='FFP CLINs X007-X021'!M23 -> 7 | N31: ='FFP CLINs X007-X021'!N23 -> 0 | O31: =ROUND(M31*N31,0) -> 0 | P31: 3021 | Q31: ='FFP CLINs X007-X021'!Q23 -> 8 | R31: ='FFP CLINs X007-X021'!R23 -> 0 | S31: =ROUND(Q31*R31,0) -> 0 | T31: 4021 | U31: ='FFP CLINs X007-X021'!U23 -> 10 | V31: ='FFP CLINs X007-X021'!V23 -> 0 | W31: =ROUND(U31*V31,0) -> 0 | X31: 5021 | Y31: ='FFP CLINs X007-X021'!Y23 -> 10 | Z31: ='FFP CLINs X007-X021'!Z23 -> 0 | AA31: =ROUND(Y31*Z31,0) -> 0 | AB31: 6021 | AC31: ='FFP CLINs X007-X021'!AC23 -> 7 | AD31: ='FFP CLINs X007-X021'!AD23 -> 0 | AE31: =ROUND(AC31*AD31,0) -> 0 | AG31: =G31+K31+O31+S31+W31+AA31+AE31 -> 0
F32: TOTAL | G32: =G10+G11+G12+G17+G18+G19+G24+G26+G30+G31 -> 0 | J32: TOTAL | K32: =K17+K18+K19+K20+K21+K22+K23+K24+K26+K30+K31 -> 0 | N32: TOTAL | O32: =O17+O18+O19+O20+O21+O22+O23+O24+O25+O26+O30+O31 -> 0 | R32: TOTAL | S32: =S17+S18+S19+S20+S21+S22+S23+S24+S26+S30+S31 -> 0 | V32: TOTAL | W32: =W17+W18+W19+W20+W21+W22+W23+W26+W30+W31 -> 0 | Z32: TOTAL | AA32: =AA17+AA18+AA19+AA20+AA21+AA22+AA23+AA26+AA30+AA31 -> 0 | AD32: TOTAL | AE32: =AE17+AE18+AE19+AE20+AE21+AE22+AE23+AE26+AE30+AE31 -> 0 | AG32: =AG10+AG11+AG12+AG17+AG18+AG19+AG20+AG21+AG22+AG23+AG24+AG25+AG26+AG30+AG31 -> 0 | AH32: TOTAL EVALUATED PRICE
AG34: =G32+K32+O32+S32+W32+AA32+AE32 -> 0 | AH34: Double Check

Sheet TOTAL EVALUATED PRICE ROLLUP
A1: PRIME OFFEROR | B1: ='FFP CLINs X007-X021'!B1 -> NAME
A3: PERIOD OF PERFORMANCE | B3: PRICE
A4: ESTIMATED TOTAL PRICE FOR BASIC PERIOD (48 MONTHS) | B4: =SUMMARY!G32 -> 0
A5: ESTIMATED TOTAL PRICE FOR OPTION PERIOD I (12 MONTHS) | B5: =SUMMARY!K32 -> 0
A6: ESTIMATED TOTAL PRICE FOR OPTION PERIOD II (12 MONTHS) | B6: =SUMMARY!O32 -> 0
A7: ESTIMATED TOTAL PRICE FOR OPTION PERIOD III (12 MONTHS) | B7: =SUMMARY!S32 -> 0
A8: ESTIMATED TOTAL PRICE FOR OPTION PERIOD IV (12 MONTHS) | B8: =SUMMARY!W32 -> 0
A9: ESTIMATED TOTAL PRICE FOR OPTION PERIOD V (12 MONTHS) | B9: =SUMMARY!AA32 -> 0
A10: ESTIMATED TOTAL PRICE FOR OPTION PERIOD VI (12 MONTHS) | B10: =SUMMARY!AE32 -> 0
A11: TOTAL EVALUATED PRICE (TEP) = (1) 4-YEAR BASIC PERIOD + (6) 1-YEAR OPTION PERIODS | B11: =SUM(B4:B10) -> 0

Sheet FFP CLINs X007-X021
A1: PRIME OFFEROR | B1: NAME
A3: Notes:
A4: 1. Insert proposed unit prices in all yellow-highlighted cells
A5: 2. All proposed prices shall be rounded to the nearest dollar
A6: 3. All proposed prices shall be proposed sufficiently to ensure adequate coverage of all labor costs, all subcontractor costs, all indirect costs, including G&A, COM, and so forth as well as prime and subcontractor profit in every contract out-year
A7: 4. No format changes on this worksheet are permitted
A9: KC-135 Center Console Refresh (CCR) Competitive Pricing Matrix FFP CLINS | E9: Basic Period (48 months) | I9: Option Period I Performance (12 months) | M9: Option Period II Performance (12 months) | Q9: Option Period III Performance (12 months) | U9: Option Period IV Performance (12 months) | Y9: Option Period V Performance (12 months) | AC9: Option Period VI Performance (12 months)
A10: CLIN Description | B10: Contract Type | C10: Unit of Issue | D10: Basic Period CLIN | E10: BEQ | F10: Unit Price | G10: Extended Price | H10: Option Period I CLIN | I10: BEQ | J10: Unit Price | K10: Extended Price | L10: Option Period II CLIN | M10: BEQ | N10: Unit Price | O10: Extended Price | P10: Option Period III CLIN | Q10: BEQ | R10: Unit Price | S10: Extended Price | T10: Option Period IV CLIN | U10: BEQ | V10: Unit Price | W10: Extended Price | X10: Option Period V CLIN | Y10: BEQ | Z10: Unit Price | AA10: Extended Price | AB10: Option Period VI CLIN | AC10: BEQ | AD10: Unit Price | AE10: Extended Price | AG10: TOTAL EVALUATED PRICE - FFP
A11: PRODUCTION CLINs
A12: Production A-Kits | B12: FFP | C12: Each | D12: 0007 | E12: 16 | F12: 0 | G12: =ROUND(E12*F12,0) -> 0 | H12: 1007 | I12: 50 | J12: 0 | K12: =ROUND(I12*J12,0) -> 0 | L12: 2007 | M12: 50 | N12: 0 | O12: =ROUND(M12*N12,0) -> 0 | P12: 3007 | Q12: 47 | R12: 0 | S12: =ROUND(Q12*R12,0) -> 0 | T12: 4007 | U12: 45 | V12: 0 | W12: =ROUND(U12*V12,0) -> 0 | X12: 5007 | Y12: 45 | Z12: 0 | AA12: =ROUND(Y12*Z12,0) -> 0 | AB12: 6007 | AC12: 53 | AD12: 0 | AE12: =ROUND(AC12*AD12,0) -> 0 | AG12: =G12+K12+O12+S12+W12+AA12+AE12 -> 0
A13: Production B-Kits | B13: FFP | C13: Each | D13: 0008 | E13: 12 | F13: 0 | G13: =ROUND(E13*F13,0) -> 0 | H13: 1008 | I13: 45 | J13: 0 | K13: =ROUND(I13*J13,0) -> 0 | L13: 2008 | M13: 45 | N13: 0 | O13: =ROUND(M13*N13,0) -> 0 | P13: 3008 | Q13: 45 | R13: 0 | S13: =ROUND(Q13*R13,0) -> 0 | T13: 4008 | U13: 45 | V13: 0 | W13: =ROUND(U13*V13,0) -> 0 | X13: 5008 | Y13: 45 | Z13: 0 | AA13: =ROUND(Y13*Z13,0) -> 0 | AB13: 6008 | AC13: 53 | AD13: 0 | AE13: =ROUND(AC13*AD13,0) -> 0 | AG13: =G13+K13+O13+S13+W13+AA13+AE13 -> 0
A14: Production Support Equipment | B14: FFP | C14: Lot | D14: 0009 | E14: 1 | F14: 0 | G14: =ROUND(E14*F14,0) -> 0 | H14: 1009 | I14: 1 | J14: 0 | K14: =ROUND(I14*J14,0) -> 0 | L14: 2009 | M14: 1 | N14: 0 | O14: =ROUND(M14*N14,0) -> 0 | P14: 3009 | Q14: 1 | R14: 0 | S14: =ROUND(Q14*R14,0) -> 0 | T14: 4009 | U14: 1 | V14: 0 | W14: =ROUND(U14*V14,0) -> 0 | X14: 5009 | Y14: 1 | Z14: 0 | AA14: =ROUND(Y14*Z14,0) -> 0 | AB14: 6009 | AC14: 1 | AD14: 0 | AE14: =ROUND(AC14*AD14,0) -> 0 | AG14: =G14+K14+O14+S14+W14+AA14+AE14 -> 0
A15: Installations | B15: FFP | C15: Each | D15: 0010 | H15: 1010 | I15: 12 | J15: 0 | K15: =ROUND(I15*J15,0) -> 0 | L15: 2010 | M15: 45 | N15: 0 | O15: =ROUND(M15*N15,0) -> 0 | P15: 3010 | Q15: 45 | R15: 0 | S15: =ROUND(Q15*R15,0) -> 0 | T15: 4010 | U15: 45 | V15: 0 | W15: =ROUND(U15*V15,0) -> 0 | X15: 5010 | Y15: 45 | Z15: 0 | AA15: =ROUND(Y15*Z15,0) -> 0 | AB15: 6010 | AC15: 45 | AD15: 0 | AE15: =ROUND(AC15*AD15,0) -> 0 | AG15: =K15+O15+S15+W15+AA15+AE15 -> 0
A16: Production Configuration Control/Engineering Change Orders | B16: FFP | C16: Month | D16: 0011 | H16: 1011 | I16: 12 | J16: 0 | K16: =ROUND(I16*J16,0) -> 0 | L16: 2011 | M16: 12 | N16: 0 | O16: =ROUND(M16*N16,0) -> 0 | P16: 3011 | Q16: 12 | R16: 0 | S16: =ROUND(Q16*R16,0) -> 0 | T16: 4011 | U16: 12 | V16: 0 | W16: =ROUND(U16*V16,0) -> 0 | X16: 5011 | Y16: 12 | Z16: 0 | AA16: =ROUND(Y16*Z16,0) -> 0 | AB16: 6011 | AC16: 12 | AD16: 0 | AE16: =ROUND(AC16*AD16,0) -> 0 | AG16: =K16+O16+S16+W16+AA16+AE16 -> 0
A17: Maintenance & Repair Support (including Production SIL) | B17: FFP | C17: Month | D17: 0012 | H17: 1012 | I17: 12 | J17: 0 | K17: =ROUND(I17*J17,0) -> 0 | L17: 2012 | M17: 12 | N17: 0 | O17: =ROUND(M17*N17,0) -> 0 | P17: 3012 | Q17: 12 | R17: 0 | S17: =ROUND(Q17*R17,0) -> 0 | T17: 4012 | U17: 12 | V17: 0 | W17: =ROUND(U17*V17,0) -> 0 | X17: 5012 | Y17: 12 | Z17: 0 | AA17: =ROUND(Y17*Z17,0) -> 0 | AB17: 6012 | AC17: 12 | AD17: 0 | AE17: =ROUND(AC17*AD17,0) -> 0 | AG17: =K17+O17+S17+W17+AA17+AE17 -> 0
A18: Technical Orders | B18: FFP | C18: Month | D18: 0013 | H18: 1013 | I18: 12 | J18: 0 | K18: =ROUND(I18*J18,0) -> 0 | L18: 2013 | M18: 12 | N18: 0 | O18: =ROUND(M18*N18,0) -> 0 | P18: 3013 | Q18: 12 | R18: 0 | S18: =ROUND(Q18*R18,0) -> 0 | T18: 4013 | U18: 12 | V18: 0 | W18: =ROUND(U18*V18,0) -> 0 | X18: 5013 | Y18: 12 | Z18: 0 | AA18: =ROUND(Y18*Z18,0) -> 0 | AB18: 6013 | AC18: 12 | AD18: 0 | AE18: =ROUND(AC18*AD18,0) -> 0 | AG18: =K18+O18+S18+W18+AA18+AE18 -> 0
A19: Production Simulator Kits | B19: FFP | C19: Each | D19: 0014 | E19: 3 | F19: 0 | G19: =ROUND(E19*F19,0) -> 0 | H19: 1014 | I19: 6 | J19: 0 | K19: =ROUND(I19*J19,0) -> 0 | L19: 2014 | M19: 6 | N19: 0 | O19: =ROUND(M19*N19,0) -> 0 | P19: 3014 | Q19: 6 | R19: 0 | S19: =ROUND(Q19*R19,0) -> 0 | T19: 4014 | X19: 5014 | AB19: 6014 | AG19: =K19+O19+S19 -> 0
A20: Production Software Integration Laboratory (SIL) | B20: FFP | C20: Each | D20: 0015 | H20: 1015 | L20: 2015 | M20: 1 | N20: 0 | O20: =ROUND(M20*N20,0) -> 0 | P20: 3015 | T20: 4015 | X20: 5015 | AB20: 6015 | AG20: =O20 -> 0
A21: Training | B21: FFP | C21: Month | D21: 0016 | E21: 12 | F21: 0 | G21: =ROUND(E21*F21,0) -> 0 | H21: 1016 | I21: 12 | J21: 0 | K21: =ROUND(I21*J21,0) -> 0 | L21: 2016 | M21: 12 | N21: 0 | O21: =ROUND(M21*N21,0) -> 0 | P21: 3016 | Q21: 12 | R21: 0 | S21: =ROUND(Q21*R21,0) -> 0 | T21: 4016 | U21: 12 | V21: 0 | W21: =ROUND(U21*V21,0) -> 0 | X21: 5016 | Y21: 12 | Z21: 0 | AA21: =ROUND(Y21*Z21,0) -> 0 | AB21: 6016 | AC21: 12 | AD21: 0 | AE21: =ROUND(AC21*AD21,0) -> 0 | AG21: =G21+K21+O21+S21+W21+AA21+AE21 -> 0
A22: Production Program Management | B22: FFP | C22: Month | D22: 0020 | E22: 12 | F22: 0 | G22: =ROUND(E22*F22,0) -> 0 | H22: 1020 | I22: 12 | J22: 0 | K22: =ROUND(I22*J22,0) -> 0 | L22: 2020 | M22: 12 | N22: 0 | O22: =ROUND(M22*N22,0) -> 0 | P22: 3020 | Q22: 12 | R22: 0 | S22: =ROUND(Q22*R22,0) -> 0 | T22: 4020 | U22: 12 | V22: 0 | W22: =ROUND(U22*V22,0) -> 0 | X22: 5020 | Y22: 12 | Z22: 0 | AA22: =ROUND(Y22*Z22,0) -> 0 | AB22: 6020 | AC22: 12 | AD22: 0 | AE22: =ROUND(AC22*AD22,0) -> 0 | AG22: =G22+K22+O22+S22+W22+AA22+AE22 -> 0
A23: Production Spares* | B23: FFP | C23: Each | D23: 0021 | E23: 2 | F23: ='SPARES-FFP CLIN X021 INPUTS'!F25 -> 0 | G23: =ROUND(E23*F23,0) -> 0 | H23: 1021 | I23: 6 | J23: ='SPARES-FFP CLIN X021 INPUTS'!H25 -> 0 | K23: =ROUND(I23*J23,0) -> 0 | L23: 2021 | M23: 7 | N23: ='SPARES-FFP CLIN X021 INPUTS'!J25 -> 0 | O23: =ROUND(M23*N23,0) -> 0 | P23: 3021 | Q23: 8 | R23: ='SPARES-FFP CLIN X021 INPUTS'!L25 -> 0 | S23: =ROUND(Q23*R23,0) -> 0 | T23: 4021 | U23: 10 | V23: ='SPARES-FFP CLIN X021 INPUTS'!N25 -> 0 | W23: =ROUND(U23*V23,0) -> 0 | X23: 5021 | Y23: 10 | Z23: ='SPARES-FFP CLIN X021 INPUTS'!P25 -> 0 | AA23: =ROUND(Y23*Z23,0) -> 0 | AB23: 6021 | AC23: 7 | AD23: ='SPARES-FFP CLIN X021 INPUTS'!R25 -> 0 | AE23: =ROUND(AC23*AD23,0) -> 0 | AG23: =G23+K23+O23+S23+W23+AA23+AE23 -> 0
A24: *See 'SPARES-FFP CLIN X021 INPUTS' worksheet to input individual components of the spare B-Kits; the extended totals will automatically populate in cells F17, J17, N17, R17, V17, Z17, and AD17) | F24: TOTAL FFP | G24: =G12+G13+G14+G19+G21+G22+G23 -> 0 | J24: TOTAL FFP | K24: =K12+K13+K14+K15+K16+K17+K18+K19+K21+K22+K23 -> 0 | N24: TOTAL FFP | O24: =O12+O13+O14+O15+O16+O17+O18+O19+O20+O21+O22+O23 -> 0 | R24: TOTAL FFP | S24: =S12+S13+S14+S15+S16+S17+S18+S19+S21+S22+S23 -> 0 | V24: TOTAL FFP | W24: =W12+W13+W14+W15+W16+W17+W18+W21+W22+W23 -> 0 | Z24: TOTAL FFP | AA24: =AA12+AA13+AA14+AA15+AA16+AA17+AA18+AA21+AA22+AA23 -> 0 | AD24: TOTAL FFP | AE24: =AE12+AE13+AE14+AE15+AE16+AE17+AE18+AE21+AE22+AE23 -> 0 | AG24: =AG12+AG13+AG14+AG15+AG16+AG17+AG18+AG19+AG20+AG21+AG22+AG23 -> 0 | AH24: TOTAL EVALUATED PRICE - FFP
AG25: =G24+K24+O24+S24+W24+AA24+AE24 -> 0 | AH25: Double Check
AG26: =AG24-AG25 -> 0 | AH26: Difference should be $0

Sheet SPARES-FFP CLIN X021 INPUTS
B1: PRIME OFFEROR | C1: ='FFP CLINs X007-X021'!B1 -> NAME
A3: Notes:
A4: 1. The Offeror is required to list the individual parts within the B-Kit below, along with unit pricing and quantities for the individual parts in each shipset; reference Statement of Work (SOW) Paragraph 13.7.1
A5: 2. The unit prices for B-Kit parts will be multiplied by the proposed quantity to arrive at a total amount for CLIN X021 LRU Spares for each performance period; the total proposed amount for CLIN X021 LRU Spares cannot exceed the total price for the individual B-Kit parts
A6: 3. The Offeror shall provide the required information in the table below (amend as necessary). Additional information may be provided in contractor format. If contractor format is utilized, the information shown in the table below must be included at a minimum.
A7: 4. The Offeror shall ensure the total proposed amounts by period properly link to the "FFP CLINs X007-X021" worksheet for CLIN X021
A8: 5. The total proposed price for CLIN X021 LRU Spares cannot exceed the cumulative price for the individual B-Kit parts
A10: CLIN X021 - LRU Spares (for B-Kits) | E10: Basic Period | G10: Option Period I | I10: Option Period II | K10: Option Period III | M10: Option Period IV | O10: Option Period V | Q10: Option Period VI
A11: NSN | B11: P/N | C11: Item Description | D11: Qty | E11: Unit Price | F11: Extended | G11: Unit Price | H11: Extended | I11: Unit Price | J11: Extended | K11: Unit Price | L11: Extended | M11: Unit Price | N11: Extended | O11: Unit Price | P11: Extended | Q11: Unit Price | R11: Extended
E12: 0 | F12: =D12*E12 -> 0 | G12: 0 | H12: =D12*G12 -> 0 | I12: 0 | J12: =I12*D12 -> 0 | K12: 0 | L12: =D12*K12 -> 0 | M12: 0 | N12: =M12*D12 -> 0 | O12: 0 | P12: =O12*D12 -> 0 | Q12: 0 | R12: =Q12*D12 -> 0
E13: 0 | F13: =D13*E13 -> 0 | G13: 0 | H13: =D13*G13 -> 0 | I13: 0 | J13: =I13*D13 -> 0 | K13: 0 | L13: =D13*K13 -> 0 | M13: 0 | N13: =M13*D13 -> 0 | O13: 0 | P13: =O13*D13 -> 0 | Q13: 0 | R13: =Q13*D13 -> 0
E14: 0 | F14: =D14*E14 -> 0 | G14: 0 | H14: =D14*G14 -> 0 | I14: 0 | J14: =I14*D14 -> 0 | K14: 0 | L14: =D14*K14 -> 0 | M14: 0 | N14: =M14*D14 -> 0 | O14: 0 | P14: =O14*D14 -> 0 | Q14: 0 | R14: =Q14*D14 -> 0
E15: 0 | F15: =D15*E15 -> 0 | G15: 0 | H15: =D15*G15 -> 0 | I15: 0 | J15: =I15*D15 -> 0 | K15: 0 | L15: =D15*K15 -> 0 | M15: 0 | N15: =M15*D15 -> 0 | O15: 0 | P15: =O15*D15 -> 0 | Q15: 0 | R15: =Q15*D15 -> 0
E16: 0 | F16: =D16*E16 -> 0 | G16: 0 | H16: =D16*G16 -> 0 | I16: 0 | J16: =I16*D16 -> 0 | K16: 0 | L16: =D16*K16 -> 0 | M16: 0 | N16: =M16*D16 -> 0 | O16: 0 | P16: =O16*D16 -> 0 | Q16: 0 | R16: =Q16*D16 -> 0
E17: 0 | F17: =D17*E17 -> 0 | G17: 0 | H17: =D17*G17 -> 0 | I17: 0 | J17: =I17*D17 -> 0 | K17: 0 | L17: =D17*K17 -> 0 | M17: 0 | N17: =M17*D17 -> 0 | O17: 0 | P17: =O17*D17 -> 0 | Q17: 0 | R17: =Q17*D17 -> 0
E18: 0 | F18: =D18*E18 -> 0 | G18: 0 | H18: =D18*G18 -> 0 | I18: 0 | J18: =I18*D18 -> 0 | K18: 0 | L18: =D18*K18 -> 0 | M18: 0 | N18: =M18*D18 -> 0 | O18: 0 | P18: =O18*D18 -> 0 | Q18: 0 | R18: =Q18*D18 -> 0
E19: 0 | F19: =D19*E19 -> 0 | G19: 0 | H19: =D19*G19 -> 0 | I19: 0 | J19: =I19*D19 -> 0 | K19: 0 | L19: =D19*K19 -> 0 | M19: 0 | N19: =M19*D19 -> 0 | O19: 0 | P19: =O19*D19 -> 0 | Q19: 0 | R19: =Q19*D19 -> 0
E20: 0 | F20: =D20*E20 -> 0 | G20: 0 | H20: =D20*G20 -> 0 | I20: 0 | J20: =I20*D20 -> 0 | K20: 0 | L20: =D20*K20 -> 0 | M20: 0 | N20: =M20*D20 -> 0 | O20: 0 | P20: =O20*D20 -> 0 | Q20: 0 | R20: =Q20*D20 -> 0
E21: 0 | F21: =D21*E21 -> 0 | G21: 0 | H21: =D21*G21 -> 0 | I21: 0 | J21: =I21*D21 -> 0 | K21: 0 | L21: =D21*K21 -> 0 | M21: 0 | N21: =M21*D21 -> 0 | O21: 0 | P21: =O21*D21 -> 0 | Q21: 0 | R21: =Q21*D21 -> 0
E22: 0 | F22: =D22*E22 -> 0 | G22: 0 | H22: =D22*G22 -> 0 | I22: 0 | J22: =I22*D22 -> 0 | K22: 0 | L22: =D22*K22 -> 0 | M22: 0 | N22: =M22*D22 -> 0 | O22: 0 | P22: =O22*D22 -> 0 | Q22: 0 | R22: =Q22*D22 -> 0
E23: 0 | F23: =D23*E23 -> 0 | G23: 0 | H23: =D23*G23 -> 0 | I23: 0 | J23: =I23*D23 -> 0 | K23: 0 | L23: =D23*K23 -> 0 | M23: 0 | N23: =M23*D23 -> 0 | O23: 0 | P23: =O23*D23 -> 0 | Q23: 0 | R23: =Q23*D23 -> 0
E24: 0 | F24: =D24*E24 -> 0 | G24: 0 | H24: =D24*G24 -> 0 | I24: 0 | J24: =I24*D24 -> 0 | K24: 0 | L24: =D24*K24 -> 0 | M24: 0 | N24: =M24*D24 -> 0 | O24: 0 | P24: =O24*D24 -> 0 | Q24: 0 | R24: =Q24*D24 -> 0
A25: TOTAL | F25: =SUM(F12:F24) -> 0 | H25: =SUM(H12:H24) -> 0 | J25: =SUM(J12:J24) -> 0 | L25: =SUM(L12:L24) -> 0 | N25: =SUM(N12:N24) -> 0 | P25: =SUM(P12:P24) -> 0 | R25: =SUM(R12:R24) -> 0

Sheet PRIME CPIF RATES (ALL)
B1: PRIME OFFEROR | C1: ='FFP CLINs X007-X021'!B1 -> NAME
B3: KC-135 Center Console Refresh (CCR) Prime Contractor Direct Labor and Indirect Rates
B5: Notes:
B6: 1. The format of this worksheet may be revised as required to be consistent with the Prime Offeror's approved Accounting System to include, but not limited to, inserting additional labor categories and revising the indirect rate structure
B7: 2. The Prime Offeror shall propose labor rates and indirect rates in the yellow-highlighted cells below. All proposed labor rates shall be rounded to two (2) decimal places. All rates in percentages shall be rounded to four decimal places (ex. .0755 = 7.55%)
B8: 3. The Prime Offeror shall input the proposed rates and indirect rates below and ensure these cells are linked correctly to the relevant CPIF rate cells on the "CPIF CLIN 0001 - TASK 1.0X" INPUTS", "CPIF CLIN 0002 - TASK 1.0X INPUTS", and "CPIF CLIN 0003 - TASK 1.0X INPUTS" worksheets
B9: 4. The Prime Offeror shall provide descriptions of the labor categories and indirect rates in the "PRIME CPIF Rate Desc (All)" worksheet, in addition to base costs upon which indirect rates apply
B10: 5. The Prime Offeror shall ensure that all labor and indirect rate categories included in the proposal for EMD CLINs 0001, 0002, and 0003 are included in this worksheet
C12: Proposed Direct Labor Rates
C13: Basic (Year 1) | D13: Basic (Year 2) | E13: Basic (Year 3) | F13: Basic (Year 4)
B14: Labor Category | C14: Hourly Rate | D14: Hourly Rate | E14: Hourly Rate | F14: Hourly Rate
B15: Insert all direct labor categories that apply (add more rows if necessary); make changes to below categories accordingly and ensure cells properly link to the 'CPIF CLIN 000X - TASK 1.XX INPUTS' worksheets for CLINs 0001,0002, and 0003
C32: Proposed Indirect Rates/Factors
B33: Indirect Rate Category (Labor) | C33: Basic (Year 1) | D33: Basic (Year 2) | E33: Basic (Year 3) | F33: Basic (Year 4)
B34: Insert all indirect categories that apply to labor costs; make changes to below categories accordingly and ensure cells properly link to the 'CPIF CLIN 000X - TASK 1.XX INPUTS' worksheets (Columns E, I, and M for CLINs 0001,0002, and 0003) and align with the rates reflected in the 'PRIME CPIF Rate Desc (All)' work sheet
B35: Indirect Labor Category: [Labor Fringe]
B36: Indirect Labor Category: [Labor Overhead]
B37: Indirect Labor Category: [G&A]
B38: Indirect Labor Category: [FCCOM]
B39: Indirect Labor Category: [Target Fee]
C41: Proposed Subcontractor Rates/Factors (Burdens added by Prime to Subcontractor Costs)
B42: Indirect Rate Category (Subcontractor) | C42: Basic (Year 1) | D42: Basic (Year 2) | E42: Basic (Year 3) | F42: Basic (Year 4)
B43: Insert all indirect categories that the prime offeror will apply to subcontractor costs; make changes to below categories accordingly and ensure cells link properly to the 'CPIF CLIN 000X - TASK 1.XX INPUTS' worksheets (Columns E, I, and M for CLINs 0001, 0002, and 0003) and align with the rates reflected in the 'PRIME CPIF Rate Desc (All)' work sheet
B44: Indirect Category: [Overhead] | I44: `
B45: Indirect Category: [G&A]
B46: Indirect Category: [FCCOM]
B47: Indirect Category: [Target Fee]
C49: Proposed Material Rates/Factors
B50: Indirect Rate Category (Material) | C50: Basic (Year 1) | D50: Basic (Year 2) | E50: Basic (Year 3) | F50: Basic (Year 4)
B51: Insert all indirect categories that apply to material costs; make changes to below categories accordingly and ensure cells link properly to the 'CPIF CLIN 000X - TASK 1.XX INPUTS' worksheets (Columns, E, I, and M for CLINs 0001, 0002, and 0003) and align with the rates reflected in the 'PRIME CPIF Rate Desc (All)' work sheet
B52: Indirect Category: [Material Overhead]
B53: Indirect Category: [G&A]
B54: Indirect Category: [FCCOM]
B55: Indirect Category: [Target Fee]
C57: Proposed Other Direct Cost (ODC) Rates/Factors
B58: Indirect ODC Category (Other) | C58: Basic (Year 1) | D58: Basic (Year 2) | E58: Basic (Year 3) | F58: Basic (Year 4)
B59: Insert all indirect categories that apply to ODC; make changes to below categories accordingly and ensure cells link properly to the 'CPIF CLIN 000X - TASK 1.XX INPUTS' worksheets (Columns, E, I, and M for CLINs 0001, 0002, and 0003) and align with the rates reflected in the 'PRIME CPIF Rate Desc (All)' work sheet
B60: Indirect Category: [Overhead]
B61: Indirect Category: [G&A]
B62: Indirect Category: [FCCOM]
...

Sheet PRIME CPIF RATE DESC (ALL)
B1: PRIME OFFEROR | C1: ='FFP CLINs X007-X021'!B1 -> NAME
B3: KC-135 Center Console Refresh (CCR) Prime Contractor Direct Labor and Indirect Rates
B5: Notes:
B6: 1. The format of this worksheet may be revised as required to be consistent with the Prime Offeror's approved Accounting System to include, but not limited to, inserting additional labor categories and revising the indirect rate structure
B7: 2. The Prime Offeror shall list all proposed labor categories and provide a summary description for each labor category
B8: 3. The Prime Offeror shall list all proposed indirect rate categories, and provide a summary description of each indirect rate category along with the base cost upon which the indirect rate is applied
B9: 4. The Prime Offeror shall ensure that all labor and indirect rate categories included in the proposal for EMD CLINs 0001, 0002, and 0003 are included in this worksheet
B11: Labor Category and Indirect Rate Descriptions
B13: Labor Category | C13: Description
B14: Example Labor Category: Systems Engineer/Integrator | C14: Conducts comprehensive system-wide review and analysis of all aspects of the development life cycle. Provides expertise in the transition of legacy systems to modernized systems.
B15: ='PRIME CPIF RATES (ALL)'!B16 -> 0
B16: ='PRIME CPIF RATES (ALL)'!B17 -> 0
B17: ='PRIME CPIF RATES (ALL)'!B18 -> 0
B18: ='PRIME CPIF RATES (ALL)'!B19 -> 0
B19: ='PRIME CPIF RATES (ALL)'!B20 -> 0
B20: ='PRIME CPIF RATES (ALL)'!B21 -> 0
B21: ='PRIME CPIF RATES (ALL)'!B22 -> 0
B22: ='PRIME CPIF RATES (ALL)'!B23 -> 0
B23: ='PRIME CPIF RATES (ALL)'!B24 -> 0
B24: ='PRIME CPIF RATES (ALL)'!B25 -> 0
B25: ='PRIME CPIF RATES (ALL)'!B26 -> 0
B26: ='PRIME CPIF RATES (ALL)'!B27 -> 0
... B29: ='PRIME CPIF RATES (ALL)'!B30 -> 0
B31: Indirect Rate Category | C31: Description | D31: Allocation Base (Provide the base upon which the Indirect Rate is applied)
B32: Example: Labor Fringe | C32: Includes employee retirement plans, health insurance, and paid time off for sick leave and vacation | D32: The base for Labor Fringe is total direct labor costs
B33: Labor Fringe
B34: Overhead (Labor)
B35: Overhead (Material)
B36: Overhead (Subcontractor)
B37: Overhead (ODC)
B38: General & Administrative (G&A)
B39: Facilities Capital Cost of Money (FCCOM)
B40: Target Fee

Sheet PRIME CPIF LABOR by TASK
B1: PRIME OFFEROR | C1: ='FFP CLINs X007-X021'!B1 -> NAME
B3: KC-135 Center Console Refresh (CCR) Prime Contractor Labor by Task
B5: Notes:
B6: 1. The format of this worksheet shall be revised to include every WBS (at the sub-task level) with proposed labor (if a WBS does not include proposed labor, do not include below)
B7: 2. At the sub-WBS level, the Prime Offeror shall provide the task to be performed, the labor category proposed to perform this task, the number of Full-Time Equivalents (FTEs) and corresponding labor hours to be utilized, and rationale to support the proposed labor
B8: 3. An example input has been provided in the template below (for illustrative purposes only); offerors shall delete the example in their proposal submission
A10: Task Number | B10: Task | C10: Labor Category | D10: # FTEs/Hours | E10: Rationale
A11: Example - For Illustrative Purposes Only
A12: 1.01 | B12: Development Thru PDR
A13: 1.01.01 | B13: ADD TITLE HERE | C13: ENGINEER I | D13: 2 FTEs x 1,784 hours | E13: To develop engineering plans
C14: ENGINEER II | E14: To evaluate engineering plans
C15: QUALITY SPECIALIST | E15: To evaluate quality of the engineering plans

Sheet PRIME CPIF LABOR INPUTS
B1: PRIME OFFEROR | C1: ='FFP CLINs X007-X021'!B1 -> NAME
B3: Notes:
B4: 1. The format of this worksheet should be revised as required to include all proposed labor by task
B5: 2. The Prime Offeror shall input the proposed labor categories and corresponding labor hours by task (at the sub-task level) in the yellow-highlighted cells below; ensure consistency with the "PRIME LABOR by TASK" worksheet
B6: 3. The Prime Offeror shall ensure that the proposed labor rates properly link to the corresponding labor rates reflected in the "PRIME-CPIF RATES (ALL)" worksheet
B7: 4. The Prime Offeror shall ensure that all labor categories included in the proposal for EMD CLINs 0001, 0002, and 0003 are included in this worksheet
B9: CLIN 0001 DEVELOPMENT, TASK 1.01 DEVELOPMENT THROUGH PDR | D9: PROPOSED COSTS/PRICES - LABOR | H9: PROPOSED COSTS/PRICES - LABOR | L9: PROPOSED COSTS/PRICES - LABOR | P9: PROPOSED COSTS/PRICES - LABOR
D10: Basic Period (Year 1) | H10: Basic Period (Year 2) | L10: Basic Period (Year 3) | P10: Basic Period (Year 4)
B11: Labor Category | C11: Task | D11: Labor Hours | E11: Labor Rates | F11: Direct Labor Cost | H11: Labor Hours | I11: Labor Rates | J11: Direct Labor Cost | L11: Labor Hours | M11: Labor Rates | N11: Direct Labor Cost | P11: Labor Hours | Q11: Labor Rates | R11: Direct Labor Cost
B12: Insert all labor categories that apply; add/delete rows as necessary and ensure cells in Columns E, I, and M are properly linked to the rates in the 'PRIME-CPIF RATES (ALL)' worksheet | C12: Insert applicable task by labor category at sub-task level (ex. 1.01.01, 1.01.02, and so forth); ensure consistency with the 'PRIME LABOR by TASK' worksheet | D12: Insert proposed labor hours by labor category and sub-task | E12: Link corresponding proposed labor rate; ensure the labor rate aligns with 'PRIME CPIF RATES (ALL)' worksheet | H12: Insert proposed labor hours by labor category and sub-task | I12: Link corresponding proposed labor rate; ensure the labor rate aligns with 'PRIME CPIF RATES (ALL)' worksheet | L12: Insert proposed labor hours by labor category and sub-task | M12: Link corresponding proposed labor rate; ensure the labor rate aligns with 'PRIME CPIF RATES (ALL)' worksheet | P12: Insert proposed labor hours by labor category and sub-task | Q12: Link corresponding proposed labor rate; ensure the labor rate aligns with 'PRIME CPIF RATES (ALL)' worksheet
B13: Labor Category : [INSERT LABOR CATEGORY NAME HERE] | C13: 1.01.01 | D13: 0 | E13: 0 | F13: =ROUND(D13*E13,0) -> 0 | H13: 0 | I13: 0 | J13: =ROUND(H13*I13,0) -> 0 | L13: 0 | M13: 0 | N13: =ROUND(L13*M13,0) -> 0 | P13: 0 | Q13: 0 | R13: =ROUND(P13*Q13,0) -> 0
B14: Labor Category : [INSERT LABOR CATEGORY NAME HERE] | D14: 0 | E14: 0 | F14: =ROUND(D14*E14,0) -> 0 | H14: 0 | I14: 0 | J14: =ROUND(H14*I14,0) -> 0 | L14: 0 | M14: 0 | N14: =ROUND(L14*M14,0) -> 0 | P14: 0 | Q14: 0 | R14: =ROUND(P14*Q14,0) -> 0
B15: Labor Category : [INSERT LABOR CATEGORY NAME HERE] | D15: 0 | E15: 0 | F15: =ROUND(D15*E15,0) -> 0 | H15: 0 | I15: 0 | J15: =ROUND(H15*I15,0) -> 0 | L15: 0 | M15: 0 | N15: =ROUND(L15*M15,0) -> 0 | P15: 0 | Q15: 0 | R15: =ROUND(P15*Q15,0) -> 0
B16: Labor Category : [INSERT LABOR CATEGORY NAME HERE] | D16: 0 | E16: 0 | F16: =ROUND(D16*E16,0) -> 0 | H16: 0 | I16: 0 | J16: =ROUND(H16*I16,0) -> 0 | L16: 0 | M16: 0 | N16: =ROUND(L16*M16,0) -> 0 | P16: 0 | Q16: 0 | R16: =ROUND(P16*Q16,0) -> 0
B17: Labor Category : [INSERT LABOR CATEGORY NAME HERE] | D17: 0 | E17: 0 | F17: =ROUND(D17*E17,0) -> 0 | H17: 0 | I17: 0 | J17: =ROUND(H17*I17,0) -> 0 | L17: 0 | M17: 0 | N17: =ROUND(L17*M17,0) -> 0 | P17: 0 | Q17: 0 | R17: =ROUND(P17*Q17,0) -> 0
B18: Labor Category : [INSERT LABOR CATEGORY NAME HERE] | C18: 1.01.02 | D18: 0 | E18: 0 | F18: =ROUND(D18*E18,0) -> 0 | H18: 0 | I18: 0 | J18: =ROUND(H18*I18,0) -> 0 | L18: 0 | M18: 0 | N18: =ROUND(L18*M18,0) -> 0 | P18: 0 | Q18: 0 | R18: =ROUND(P18*Q18,0) -> 0
B19: Labor Category : [INSERT LABOR CATEGORY NAME HERE] | D19: 0 | E19: 0 | F19: =ROUND(D19*E19,0) -> 0 | H19: 0 | I19: 0 | J19: =ROUND(H19*I19,0) -> 0 | L19: 0 | M19: 0 | N19: =ROUND(L19*M19,0) -> 0 | P19: 0 | Q19: 0 | R19: =ROUND(P19*Q19,0) -> 0
B20: Labor Category : [INSERT LABOR CATEGORY NAME HERE] | D20: 0 | E20: 0 | F20: =ROUND(D20*E20,0) -> 0 | H20: 0 | I20: 0 | J20: =ROUND(H20*I20,0) -> 0 | L20: 0 | M20: 0 | N20: =ROUND(L20*M20,0) -> 0 | P20: 0 | Q20: 0 | R20: =ROUND(P20*Q20,0) -> 0
B21: Labor Category : [INSERT LABOR CATEGORY NAME HERE] | D21: 0 | E21: 0 | F21: =ROUND(D21*E21,0) -> 0 | H21: 0 | I21: 0 | J21: =ROUND(H21*I21,0) -> 0 | L21: 0 | M21: 0 | N21: =ROUND(L21*M21,0) -> 0 | P21: 0 | Q21: 0 | R21: =ROUND(P21*Q21,0) -> 0
B22: Labor Category : [INSERT LABOR CATEGORY NAME HERE] | D22: 0 | E22: 0 | F22: =ROUND(D22*E22,0) -> 0 | H22: 0 | I22: 0 | J22: =ROUND(H22*I22,0) -> 0 | L22: 0 | M22: 0 | N22: =ROUND(L22*M22,0) -> 0 | P22: 0 | Q22: 0 | R22: =ROUND(P22*Q22,0) -> 0
B23: Labor Category : [INSERT LABOR CATEGORY NAME HERE] | C23: 1.01.03 | D23: 0 | E23: 0 | F23: =ROUND(D23*E23,0) -> 0 | H23: 0 | I23: 0 | J23: =ROUND(H23*I23,0) -> 0 | L23: 0 | M23: 0 | N23: =ROUND(L23*M23,0) -> 0 | P23: 0 | Q23: 0 | R23: =ROUND(P23*Q23,0) -> 0
B24: Labor Category : [INSERT LABOR CATEGORY NAME HERE] | D24: 0 | E24: 0 | F24: =ROUND(D24*E24,0) -> 0 | H24: 0 | I24: 0 | J24: =ROUND(H24*I24,0) -> 0 | L24: 0 | M24: 0 | N24: =ROUND(L24*M24,0) -> 0 | P24: 0 | Q24: 0 | R24: =ROUND(P24*Q24,0) -> 0
B25: Labor Category : [INSERT LABOR CATEGORY NAME HERE] | D25: 0 | E25: 0 | F25: =ROUND(D25*E25,0) -> 0 | H25: 0 | I25: 0 | J25: =ROUND(H25*I25,0) -> 0 | L25: 0 | M25: 0 | N25: =ROUND(L25*M25,0) -> 0 | P25: 0 | Q25: 0 | R25: =ROUND(P25*Q25,0) -> 0
B26: Labor Category : [INSERT LABOR CATEGORY NAME HERE] | D26: 0 | E26: 0 | F26: =ROUND(D26*E26,0) -> 0 | H26: 0 | I26: 0 | J26: =ROUND(H26*I26,0) -> 0 | L26: 0 | M26: 0 | N26: =ROUND(L26*M26,0) -> 0 | P26: 0 | Q26: 0 | R26: =ROUND(P26*Q26,0) -> 0
B27: Labor Category : [INSERT LABOR CATEGORY NAME HERE] | D27: 0 | E27: 0 | F27: =ROUND(D27*E27,0) -> 0 | H27: 0 | I27: 0 | J27: =ROUND(H27*I27,0) -> 0 | L27: 0 | M27: 0 | N27: =ROUND(L27*M27,0) -> 0 | P27: 0 | Q27: 0 | R27: =ROUND(P27*Q27,0) -> 0
B28: TOTAL DIRECT LABOR HOURS/COST | D28: =SUM(D13:D27) -> 0 | F28: =ROUND(SUM(F13:F27),0) -> 0 | H28: =SUM(H13:H27) -> 0 | J28: =ROUND(SUM(J13:J27),0) -> 0 | L28: =SUM(L13:L27) -> 0 | N28: =ROUND(SUM(N13:N27),0) -> 0 | P28: =SUM(P13:P27) -> 0 | R28: =ROUND(SUM(R13:R27),0) -> 0
B30: CLIN 0001 DEVELOPMENT, TASK 1.02 DEVELOPMENT FROM PDR TO CDR | D30: PROPOSED COSTS/PRICES - LABOR | H30: PROPOSED COSTS/PRICES - LABOR | L30: PROPOSED COSTS/PRICES - LABOR | P30: PROPOSED COSTS/PRICES - LABOR
D31: =D10 -> Basic Period (Year 1) | H31: =H10 -> Basic Period (Year 2) | L31: =L10 -> Basic Period (Year 3) | P31: =P10 -> Basic Period (Year 4)
B32: Labor Category | C32: Task | D32: Labor Hours | E32: Labor Rates | F32: Direct Labor Cost | H32: Labor Hours | I32: Labor Rates | J32: Direct Labor Cost | L32: Labor Hours | M32: Labor Rates | N32: Direct Labor Cost | P32: Labor Hours | Q32: Labor Rates | R32: Direct Labor Cost
B33: Insert all labor categories that apply; add/delete rows as necessary and ensure cells in Columns E, I, and M are properly linked to the rates in the 'PRIME-CPIF RATES (ALL)' worksheet | C33: Insert applicable task by labor category at sub-task level (ex. 1.01.01, 1.01.02, and so forth); ensure consistency with the 'PRIME LABOR by TASK' worksheet | D33: Insert proposed labor hours by labor category and sub-task | E33: Link corresponding proposed labor rate; ensure the labor rate aligns with 'PRIME CPIF RATES (ALL)' worksheet | H33: Insert proposed labor hours by labor category and sub-task | I33: Link corresponding proposed labor rate; ensure the labor rate aligns with 'PRIME CPIF RATES (ALL)' worksheet | L33: Insert proposed labor hours by labor category and sub-task | M33: Link corresponding proposed labor rate; ensure the labor rate aligns with 'PRIME CPIF RATES (ALL)' worksheet | P33: Insert proposed labor hours by labor category and sub-task | Q33: Link corresponding proposed labor rate; ensure the labor rate aligns with 'PRIME CPIF RATES (ALL)' worksheet
B34: ='PRIME CPIF RATES (ALL)'!B18 -> 0 | C34: 1.02.01 | D34: 0 | E34: 0 | F34: =ROUND(D34*E34,0) -> 0 | H34: 0 | I34: 0 | J34: =ROUND(H34*I34,0) -> 0 | L34: 0 | M34: 0 | N34: =ROUND(L34*M34,0) -> 0 | P34: 0 | Q34: 0 | R34: =ROUND(P34*Q34,0) -> 0
B35: Labor Category : [INSERT LABOR CATEGORY NAME HERE] | D35: 0 | E35: 0 | F35: =ROUND(D35*E35,0) -> 0 | H35: 0 | I35: 0 | J35: =ROUND(H35*I35,0) -> 0 | L35: 0 | M35: 0 | N35: =ROUND(L35*M35,0) -> 0 | P35: 0 | Q35: 0 | R35: =ROUND(P35*Q35,0) -> 0
B36: Labor Category : [INSERT LABOR CATEGORY NAME HERE] | D36: 0 | E36: 0 | F36: =ROUND(D36*E36,0) -> 0 | H36: 0 | I36: 0 | J36: =ROUND(H36*I36,0) -> 0 | L36: 0 | M36: 0 | N36: =ROUND(L36*M36,0) -> 0 | P36: 0 | Q36: 0 | R36: =ROUND(P36*Q36,0) -> 0
B37: Labor Category : [INSERT LABOR CATEGORY NAME HERE] | D37: 0 | E37: 0 | F37: =ROUND(D37*E37,0) -> 0 | H37: 0 | I37: 0 | J37: =ROUND(H37*I37,0) -> 0 | L37: 0 | M37: 0 | N37: =ROUND(L37*M37,0) -> 0 | P37: 0 | Q37: 0 | R37: =ROUND(P37*Q37,0) -> 0
B38: Labor Category : [INSERT LABOR CATEGORY NAME HERE] | D38: 0 | E38: 0 | F38: =ROUND(D38*E38,0) -> 0 | H38: 0 | I38: 0 | J38: =ROUND(H38*I38,0) -> 0 | L38: 0 | M38: 0 | N38: =ROUND(L38*M38,0) -> 0 | P38: 0 | Q38: 0 | R38: =ROUND(P38*Q38,0) -> 0
B39: Labor Category : [INSERT LABOR CATEGORY NAME HERE] | C39: 1.02.02 | D39: 0 | E39: 0 | F39: =ROUND(D39*E39,0) -> 0 | H39: 0 | I39: 0 | J39: =ROUND(H39*I39,0) -> 0 | L39: 0 | M39: 0 | N39: =ROUND(L39*M39,0) -> 0 | P39: 0 | Q39: 0 | R39: =ROUND(P39*Q39,0) -> 0
B40: Labor Category : [INSERT LABOR CATEGORY NAME HERE] | D40: 0 | E40: 0 | F40: =ROUND(D40*E40,0) -> 0 | H40: 0 | I40: 0 | J40: =ROUND(H40*I40,0) -> 0 | L40: 0 | M40: 0 | N40: =ROUND(L40*M40,0) -> 0 | P40: 0 | Q40: 0 | R40: =ROUND(P40*Q40,0) -> 0
B41: Labor Category : [INSERT LABOR CATEGORY NAME HERE] | D41: 0 | E41: 0 | F41: =ROUND(D41*E41,0) -> 0 | H41: 0 | I41: 0 | J41: =ROUND(H41*I41,0) -> 0 | L41: 0 | M41: 0 | N41: =ROUND(L41*M41,0) -> 0 | P41: 0 | Q41: 0 | R41: =ROUND(P41*Q41,0) -> 0
B42: Labor Category : [INSERT LABOR CATEGORY NAME HERE] | D42: 0 | E42: 0 | F42: =ROUND(D42*E42,0) -> 0 | H42: 0 | I42: 0 | J42: =ROUND(H42*I42,0) -> 0 | L42: 0 | M42: 0 | N42: =ROUND(L42*M42,0) -> 0 | P42: 0 | Q42: 0 | R42: =ROUND(P42*Q42,0) -> 0
B43: Labor Category : [INSERT LABOR CATEGORY NAME HERE] | D43: 0 | E43: 0 | F43: =ROUND(D43*E43,0) -> 0 | H43: 0 | I43: 0 | J43: =ROUND(H43*I43,0) -> 0 | L43: 0 | M43: 0 | N43: =ROUND(L43*M43,0) -> 0 | P43: 0 | Q43: 0 | R43: =ROUND(P43*Q43,0) -> 0
...

Sheet PRIME CPIF TOTAL MATERIAL
B1: PRIME OFFEROR | C1: ='FFP CLINs X007-X021'!B1 -> NAME
B3: Notes:
B4: 1. In Contractor format, the Prime Offeror shall provide data other than cost or pricing data in a Consolidated Bill of Material (CBOM) for all Material costs associated with EMD CLINs 0001, 0002, and 0003 (at the subtask level), in accordance with RFP Section L, Paragraph 7.3.2.
B5: 2. Populate the yellow-highlighted cells below to summarize the proposed material costs by CLIN/Task (the totals by CLIN/Task shall match the other than cost and pricing data provided in the CBOM)
B6: 3. Total Material costs by Task provided below are linked to each applicable worksheet (ex. "CPIF CLIN 0001 - TASK 1.01 INPUTS", "CPIF CLIN 0001 - TASK 1.02 INPUTS" and so forth); the Offeror shall ensure the cells are properly linked.
A8: KC-135 Center Console Refresh (CCR) - Proposed Material Summary CLINs 0001, 0002, and 0003 (CPIF) | E8: Basic Period - Year 1 | G8: Basic Period - Year 2 | I8: Basic Period - Year 3 | K8: Basic Period - Year 4
A9: TASK | E9: Total Proposed Material Costs (CPIF) | G9: Total Proposed Material Costs (CPIF) | I9: Total Proposed Material Costs (CPIF) | K9: Total Proposed Material Costs (CPIF) | M9: Total Material Costs (CPIF)
A10: 1.0 | B10: Development
A11: 1.01 | C11: Development through PDR | D11: 0001 | M11: =E11+G11+I11+K11 -> 0
A12: 1.02 | C12: Development from PDR to CDR | D12: 0001 | M12: =E12+G12+I12+K12 -> 0
A13: 1.03 | C13: System Test and Evaluation | D13: 0001 | M13: =E13+G13+I13+K13 -> 0
A14: 1.04 | C14: Material - Development Kits (COTS and Developmental) | D14: 0001 | M14: =E14+G14+I14+K14 -> 0
A15: 1.05 | C15: Prototype Support, Installation, and Checkout | D15: 0001 | M15: =E15+G15+I15+K15 -> 0
A16: 1.06 | C16: Qualification, Developmental, and Operational Testing | D16: 0001 | M16: =E16+G16+I16+K16 -> 0
A17: 1.07 | C17: Material - Development Spares | D17: 0001 | M17: =E17+G17+I17+K17 -> 0
A18: 1.08 | C18: Black Label HW & SW Certification | D18: 0001 | M18: =E18+G18+I18+K18 -> 0
A19: 1.09 | C19: Systems Engineering and Program Management | D19: 0001 | M19: =E19+G19+I19+K19 -> 0
A20: 1.1 | C20: Aircrew and maintenance training | D20: 0001 | M20: =E20+G20+I20+K20 -> 0
A21: 1.11 | C21: Support Equipment | D21: 0001 | M21: =E21+G21+I21+K21 -> 0
C22: Total CPIF CLIN 0001 | E22: =SUM(E11:E21) -> 0 | G22: =SUM(G11:G21) -> 0 | I22: =SUM(I11:I21) -> 0 | K22: =SUM(K11:K21) -> 0 | M22: =E22+G22+I22+K22 -> 0
A23: 1.0 | B23: Simulator Kit
A24: 1.01 | C24: Support required to determine elements of Simulator Kit | D24: 0002 | M24: =E24+G24+I24+K24 -> 0
A25: 1.02 | C25: Material - 1 Simulator kit (Ref Section L) | D25: 0002 | M25: =E25+G25+I25+K25 -> 0
A26: 1.03 | C26: Delivery of material to Simulator SPO | D26: 0002 | M26: =E26+G26+I26+K26 -> 0
C27: Total CPIF CLIN 0002 | E27: =E24+E25+E26 -> 0 | G27: =G24+G25+G26 -> 0 | I27: =I24+I25+I26 -> 0 | K27: =K24+K25+K26 -> 0 | M27: =E27+G27+I27+K27 -> 0
A28: 1.0 | B28: Systems Integration Laboratory
A29: 1.01 | C29: Development Labor to Have an Operational SIL | D29: 0003 | M29: =E29+G29+I29+K29 -> 0
A30: 1.02 | C30: Material - Contractor Procured Material for SIL | D30: 0003 | M30: =E30+G30+I30+K30 -> 0
A31: 1.03 | C31: Material - Anticipated Required GFE | D31: 0003 | M31: =E31+G31+I31+K31 -> 0
A32: 1.04 | C32: Delivery of SIL to Government | D32: 0003 | M32: =E32+G32+I32+K32 -> 0
C33: Total CPIF CLIN 0003 | E33: =E29+E30+E31+E32 -> 0 | G33: =G29+G30+G31+G32 -> 0 | I33: =I29+I30+I31+I32 -> 0 | K33: =K29+K30+K31+K32 -> 0 | M33: =E33+G33+I33+K33 -> 0
E35: =E22+E27+E33 -> 0 | G35: =G22+G27+G33 -> 0 | I35: =I22+I27+I33 -> 0 | K35: =K22+K27+K33 -> 0 | M35: =M22+M27+M33 -> 0 | N35: Total Material Costs (CPIF)
M37: =E35+G35+I35+K35 -> 0 | N37: Double Check
M38: =M35-M37 -> 0 | N38: Difference should be $0

Sheet PRIME CPIF TOTAL SUB
B1: PRIME OFFEROR | C1: ='FFP CLINs X007-X021'!B1 -> NAME
B3: Notes:
B4: 1. The Prime Offeror shall provide other than cost and pricing data for all proposed subcontractor costs associated with EMD CLINs 0001, 0002, and 0003; for each Major Subcontractor (valued at $2.5M+), a separate cost model shall be submitted (see file entitled "ATTACHMENT 3B EXCEL PRICING WORKBOOK - SUB")
B5: 2. Populate the yellow-highlighted cells below to summarize the proposed subcontractor costs by CLIN/Task
B6: 3. Total subcontractor costs by Task provided below are linked to each applicable worksheet (ex. "CPIF CLIN 0001 - TASK 1.01 INPUTS", "CPIF CLIN 0001 - TASK 1.02 INPUTS" and so forth); the Offeror shall ensure the cells are properly linked.
A8: KC-135 Center Console Refresh (CCR) - Proposed Subcontractor Summary CLINs 0001, 0002, and 0003 (CPIF) | E8: Basic Period - Year 1 | G8: Basic Period - Year 2 | I8: Basic Period - Year 3 | K8: Basic Period - Year 4
A9: TASK | E9: Total Proposed Subcontractor Costs (CPIF) | G9: Total Proposed Subcontractor Costs (CPIF) | I9: Total Proposed Subcontractor Costs (CPIF) | K9: Total Proposed Subcontractor Costs (CPIF) | M9: Total Subcontractor Costs (CPIF)
A10: 1.0 | B10: Development
A11: 1.01 | C11: Development through PDR | D11: 0001 | M11: =E11+G11+I11+K11 -> 0
A12: 1.02 | C12: Development from PDR to CDR | D12: 0001 | M12: =E12+G12+I12+K12 -> 0
A13: 1.03 | C13: System Test and Evaluation | D13: 0001 | M13: =E13+G13+I13+K13 -> 0
A14: 1.04 | C14: Material - Development Kits (COTS and Developmental) | D14: 0001 | M14: =E14+G14+I14+K14 -> 0
A15: 1.05 | C15: Prototype Support, Installation, and Checkout | D15: 0001 | M15: =E15+G15+I15+K15 -> 0
A16: 1.06 | C16: Qualification, Developmental, and Operational Testing | D16: 0001 | M16: =E16+G16+I16+K16 -> 0
A17: 1.07 | C17: Material - Development Spares | D17: 0001 | M17: =E17+G17+I17+K17 -> 0
A18: 1.08 | C18: Black Label HW & SW Certification | D18: 0001 | M18: =E18+G18+I18+K18 -> 0
A19: 1.09 | C19: Systems Engineering and Program Management | D19: 0001 | M19: =E19+G19+I19+K19 -> 0
A20: 1.1 | C20: Aircrew and maintenance training | D20: 0001 | M20: =E20+G20+I20+K20 -> 0
A21: 1.11 | C21: Support Equipment | D21: 0001 | M21: =E21+G21+I21+K21 -> 0
C22: Total CPIF CLIN 0001 | E22: =SUM(E11:E21) -> 0 | G22: =SUM(G11:G21) -> 0 | I22: =SUM(I11:I21) -> 0 | K22: =SUM(K11:K21) -> 0 | M22: =E22+G22+I22+K22 -> 0
A23: 1.0 | B23: Simulator Kit
A24: 1.01 | C24: Support required to determine elements of Simulator Kit | D24: 0002 | M24: =E24+G24+I24+K24 -> 0
A25: 1.02 | C25: Material - 1 Simulator kit (Ref Section L) | D25: 0002 | M25: =E25+G25+I25+K25 -> 0
A26: 1.03 | C26: Delivery of material to Simulator SPO | D26: 0002 | M26: =E26+G26+I26+K26 -> 0
C27: Total CPIF CLIN 0002 | E27: =E24+E25+E26 -> 0 | G27: =G24+G25+G26 -> 0 | I27: =I24+I25+I26 -> 0 | K27: =K24+K25+K26 -> 0 | M27: =E27+G27+I27+K27 -> 0
A28: 1.0 | B28: Systems Integration Laboratory
A29: 1.01 | C29: Development Labor to Have an Operational SIL | D29: 0003 | M29: =E29+G29+I29+K29 -> 0
A30: 1.02 | C30: Material - Contractor Procured Material for SIL | D30: 0003 | M30: =E30+G30+I30+K30 -> 0
