Workbook

Sheet Subcontractor Instructions
A1: INSTRUCTIONS TO SUBCONTRACTORS
A3: General
A4: 1 | B4: The subcontractor shall complete this Government Format Pricing Model (GFPM-Subs).
A5: 2 | B5: All proposed direct labor rates shall be in line with justifying data (historical/incurred costs, salary survey, BLS OES etc.) for each identified locality.
A6: 3 | B6: The subcontractor GFPM will be utilized for each subcontractor to show its compliance with providing a full labor buildup, per labor category and to ensure compliance with the Government provided floor rates.
A7: "Subcontractor Labor Build" Tab
A8: 1 | B8: All subcontractors must provide the subcontractor GFPM to the prime offeror for submittal to the Government as part of the prime offeror proposal OR each subcontractor must submit this file directly to the Government.
A9: 2 | B9: Subcontractor input is required in all applicable cells highlighted in yellow.
A10: 3 | B10: The "Labor Categories & Hours" table (columns A - F) contain all of the performance locations and labor categories that the USG anticipates to be necessary for completion of this effort. Offerors shall input the proposed number of hours in column F that will be completed by the subcontractor for each applicable labor category being performed by the subcontractor.
A11: 3a | B11: In the "Subcontractor Labor" table (columns H - V), subcontractors are required to submit fully burdened labor rates for each of the labor categories that the subcontractor is performing (Column S). Subcontractors shall insert all of the cost elements (direct labor, DBA Insurance, fringe benefit costs, labor overhead costs, general & administrative cost, fee etc.) that make up all of the fully burdened labor rates proposed (Columns I - R). If necessary, subcontractors may submit additional cost data in it's own format to further justify the proposed single elements of the prime labor costs.
A12: 3b | B12: Subcontractors shall insert direct labor rates in Ordering Period 1 for the applicable labor categories (I5 - I36). Note: Per section L of the RTOP, the proposed direct labor rates must meet or exceed the USG floor rates, referenced in Ordering Period 1 (H5 - H36).
A13: 3c | B13: Some labor categories are listed more than once as identified by the ID#. These labor categories shall have the same proposed labor rates in all locations within the same ordering period. For example, in Ordering Period 1, ID 002 appears in row 6, row 16, and row 17. The proposed direct labor, indirect labor, fee, and resulting FBLR shall be the same for ID 002 in rows 6, rows 16, and row 17.
A14: 3d | B14: Subcontractors that do not account for Defense Base Act (DBA) Insurance in its indirect rates shall utilize column K to input its DBA Insurance premium for all applicable OCONUS labor categories.
A15: 4 | B15: In the event a subcontractor proposes a direct labor rate below the floor rate in error, the subcontractor GFPM corrects this error by utilizing the floor rate (as calculated by the pre-populated formula in column J) to compute the subcontractor costs that contribute to the subcontractor proposed FBLR in column S.
A16: 5 | B16: The fee formula in column R restricts subcontractors from proposing negative fee percentages.
A17: 6 | B17: Particular cells are locked and cannot be edited. Cells highlighted in yellow can be modified to fit a subcontractors accounting methods, however, the Government has included pre-populated formulas if applicable.
A18: 7 | B18: The FBLR proposed in column S should be consistent with the FBLR provided to the prime for the primes submittal of its proposal.
A19: "Escalation" Tab
A20: 1 | B20: This tab provides the data for the labor escalation rates which apply to all ordering periods of performance.
A21: 2 | B21: Per section L of the RFP, for evaluation purposes only, this solicitation has set a minimum escalation for each period of performance. Subcontractors may choose to increase this rate in column C of the escalation tab, but shall not propose an escalation rate which is below the USG minimum.
A22: "DBA" Tab
A23: 1 | B23: Subcontractors with accounting practices that include DBA Insurance in its indirect rates shall use this tab to provide evidence that DBA expenses are included as part of indirect costs within the proposed FBLR (i.e. identify the pool expense and indirect rate associated with DBA), showing how the DBA Insurance is accounted for.
A24: "Sub FBLR" Tab
A25: 1 | B25: To promote consistency between subcontractor files and prime offeror files, the Government has provided a FBLR Summary tab within the Subcontractor GFPM for the subcontractor to be able to more easily transfer its proposed FBLRs for each Ordering Period, to the prime offeror for the prime offeror to include in its proposal.
A26: 2 | B26: The Hours and FBLRs (columns F & G) are automatically populated in this tab, as they are pulled directly from the 'Subcontractor Labor Build' tab.

Sheet Subcontractor Labor Build
A1: Ordering Period 1:
A2: Ordering Period 1 Labor Categories & Hours | H2: Subcontractor Labor
A3: Service | B3: ID | C3: Labor Category | D3: Reference | E3: Location | F3: Proposed Hours | H3: (Floor Rate) | I3: Direct Labor (Proposed) | J3: Direct Labor (Calculation) | K3: DBA | L3: Fringe Benefit | M3: Labor OH | N3: Other OH | O3: G&A | P3: FCCOM | Q3: Cost | R3: Fee | S3: FBLR | T3: Total Cost | U3: Total Fee | V3: Total Price
A4: CONUS
A5: Program Management | B5: 1 | C5: Project Management Specialist | D5: H.3.11 | E5: CONUS | H5: 48.44 | J5: =IF(F5>0,IF($I5<$H5,$H5,$I5),0) -> 0 | L5: =(J5*$L$4) -> 0 | M5: =(L5+J5)*$M$4 -> 0 | N5: =(J5+L5)*$N$4 -> 0 | O5: =(L5+J5+M5+N5)*$O$4 -> 0 | P5: =(J5+L5+M5+N5+O5)*$P$4 -> 0 | Q5: =SUM(J5:P5) -> 0 | R5: =IF($R$4<0,"N/A",(Q5-P5)*$R$4) -> 0 | S5: =SUM(Q5:R5) -> 0 | T5: =Q5*F5 -> 0 | U5: =R5*F5 -> 0 | V5: =S5*F5 -> 0
A6: Field Service Representative (FSR) | B6: 2 | C6: Field Service Representative | D6: H.3.8 | E6: CONUS | H6: 35.83 | J6: =IF(F6>0,IF($I6<$H6,$H6,$I6),0) -> 0 | L6: =(J6*$L$4) -> 0 | M6: =(L6+J6)*$M$4 -> 0 | N6: =(J6+L6)*$N$4 -> 0 | O6: =(L6+J6+M6+N6)*$O$4 -> 0 | P6: =(J6+L6+M6+N6+O6)*$P$4 -> 0 | Q6: =SUM(J6:P6) -> 0 | R6: =IF($R$4<0,"N/A",(Q6-P6)*$R$4) -> 0 | S6: =SUM(Q6:R6) -> 0 | T6: =Q6*F6 -> 0 | U6: =R6*F6 -> 0 | V6: =S6*F6 -> 0
B7: 3 | C7: Field Service Mechanic | D7: H.3.9 | E7: CONUS | H7: 30.76 | J7: =IF(F7>0,IF($I7<$H7,$H7,$I7),0) -> 0 | L7: =(J7*$L$4) -> 0 | M7: =(L7+J7)*$M$4 -> 0 | N7: =(J7+L7)*$N$4 -> 0 | O7: =(L7+J7+M7+N7)*$O$4 -> 0 | P7: =(J7+L7+M7+N7+O7)*$P$4 -> 0 | Q7: =SUM(J7:P7) -> 0 | R7: =IF($R$4<0,"N/A",(Q7-P7)*$R$4) -> 0 | S7: =SUM(Q7:R7) -> 0 | T7: =Q7*F7 -> 0 | U7: =R7*F7 -> 0 | V7: =S7*F7 -> 0
A8: Deprocessing | B8: 4 | C8: Heavy Equipment Mechanic | D8: H.3.4 | E8: CONUS | H8: 30.76 | J8: =IF(F8>0,IF($I8<$H8,$H8,$I8),0) -> 0 | L8: =(J8*$L$4) -> 0 | M8: =(L8+J8)*$M$4 -> 0 | N8: =(J8+L8)*$N$4 -> 0 | O8: =(L8+J8+M8+N8)*$O$4 -> 0 | P8: =(J8+L8+M8+N8+O8)*$P$4 -> 0 | Q8: =SUM(J8:P8) -> 0 | R8: =IF($R$4<0,"N/A",(Q8-P8)*$R$4) -> 0 | S8: =SUM(Q8:R8) -> 0 | T8: =Q8*F8 -> 0 | U8: =R8*F8 -> 0 | V8: =S8*F8 -> 0
B9: 5 | C9: Material Handling Specialist | D9: H.3.3 | E9: CONUS | H9: 27.78 | J9: =IF(F9>0,IF($I9<$H9,$H9,$I9),0) -> 0 | L9: =(J9*$L$4) -> 0 | M9: =(L9+J9)*$M$4 -> 0 | N9: =(J9+L9)*$N$4 -> 0 | O9: =(L9+J9+M9+N9)*$O$4 -> 0 | P9: =(J9+L9+M9+N9+O9)*$P$4 -> 0 | Q9: =SUM(J9:P9) -> 0 | R9: =IF($R$4<0,"N/A",(Q9-P9)*$R$4) -> 0 | S9: =SUM(Q9:R9) -> 0 | T9: =Q9*F9 -> 0 | U9: =R9*F9 -> 0 | V9: =S9*F9 -> 0
B10: 6 | C10: Inspector | D10: H.3.9 | E10: CONUS | H10: 24.98 | J10: =IF(F10>0,IF($I10<$H10,$H10,$I10),0) -> 0 | L10: =(J10*$L$4) -> 0 | M10: =(L10+J10)*$M$4 -> 0 | N10: =(J10+L10)*$N$4 -> 0 | O10: =(L10+J10+M10+N10)*$O$4 -> 0 | P10: =(J10+L10+M10+N10+O10)*$P$4 -> 0 | Q10: =SUM(J10:P10) -> 0 | R10: =IF($R$4<0,"N/A",(Q10-P10)*$R$4) -> 0 | S10: =SUM(Q10:R10) -> 0 | T10: =Q10*F10 -> 0 | U10: =R10*F10 -> 0 | V10: =S10*F10 -> 0
B11: 7 | C11: Supply/Procurement Specialist | D11: H.3.2 | E11: CONUS | H11: 35.7 | J11: =IF(F11>0,IF($I11<$H11,$H11,$I11),0) -> 0 | L11: =(J11*$L$4) -> 0 | M11: =(L11+J11)*$M$4 -> 0 | N11: =(J11+L11)*$N$4 -> 0 | O11: =(L11+J11+M11+N11)*$O$4 -> 0 | P11: =(J11+L11+M11+N11+O11)*$P$4 -> 0 | Q11: =SUM(J11:P11) -> 0 | R11: =IF($R$4<0,"N/A",(Q11-P11)*$R$4) -> 0 | S11: =SUM(Q11:R11) -> 0 | T11: =Q11*F11 -> 0 | U11: =R11*F11 -> 0 | V11: =S11*F11 -> 0
B12: 8 | C12: Welder | D12: H.3.5 | E12: CONUS | H12: 24.52 | J12: =IF(F12>0,IF($I12<$H12,$H12,$I12),0) -> 0 | L12: =(J12*$L$4) -> 0 | M12: =(L12+J12)*$M$4 -> 0 | N12: =(J12+L12)*$N$4 -> 0 | O12: =(L12+J12+M12+N12)*$O$4 -> 0 | P12: =(J12+L12+M12+N12+O12)*$P$4 -> 0 | Q12: =SUM(J12:P12) -> 0 | R12: =IF($R$4<0,"N/A",(Q12-P12)*$R$4) -> 0 | S12: =SUM(Q12:R12) -> 0 | T12: =Q12*F12 -> 0 | U12: =R12*F12 -> 0 | V12: =S12*F12 -> 0
A13: New Equipment Training (NET) / Displaced Equipment Training (DET) | B13: 9 | C13: Instructor | D13: H.3.7 | E13: CONUS | H13: 25.89 | J13: =IF(F13>0,IF($I13<$H13,$H13,$I13),0) -> 0 | L13: =(J13*$L$4) -> 0 | M13: =(L13+J13)*$M$4 -> 0 | N13: =(J13+L13)*$N$4 -> 0 | O13: =(L13+J13+M13+N13)*$O$4 -> 0 | P13: =(J13+L13+M13+N13+O13)*$P$4 -> 0 | Q13: =SUM(J13:P13) -> 0 | R13: =IF($R$4<0,"N/A",(Q13-P13)*$R$4) -> 0 | S13: =SUM(Q13:R13) -> 0 | T13: =Q13*F13 -> 0 | U13: =R13*F13 -> 0 | V13: =S13*F13 -> 0
A14: Total Package Fielding (TPF) | B14: 4 | C14: Heavy Equipment Mechanic | D14: H.3.4 | E14: CONUS | H14: 30.76 | J14: =IF(F14>0,IF($I14<$H14,$H14,$I14),0) -> 0 | L14: =(J14*$L$4) -> 0 | M14: =(L14+J14)*$M$4 -> 0 | N14: =(J14+L14)*$N$4 -> 0 | O14: =(L14+J14+M14+N14)*$O$4 -> 0 | P14: =(J14+L14+M14+N14+O14)*$P$4 -> 0 | Q14: =SUM(J14:P14) -> 0 | R14: =IF($R$4<0,"N/A",(Q14-P14)*$R$4) -> 0 | S14: =SUM(Q14:R14) -> 0 | T14: =Q14*F14 -> 0 | U14: =R14*F14 -> 0 | V14: =S14*F14 -> 0
B15: 5 | C15: Material Handling Specialist | D15: H.3.3 | E15: CONUS | H15: 27.78 | J15: =IF(F15>0,IF($I15<$H15,$H15,$I15),0) -> 0 | L15: =(J15*$L$4) -> 0 | M15: =(L15+J15)*$M$4 -> 0 | N15: =(J15+L15)*$N$4 -> 0 | O15: =(L15+J15+M15+N15)*$O$4 -> 0 | P15: =(J15+L15+M15+N15+O15)*$P$4 -> 0 | Q15: =SUM(J15:P15) -> 0 | R15: =IF($R$4<0,"N/A",(Q15-P15)*$R$4) -> 0 | S15: =SUM(Q15:R15) -> 0 | T15: =Q15*F15 -> 0 | U15: =R15*F15 -> 0 | V15: =S15*F15 -> 0
B16: 6 | C16: Inspector | D16: H.3.9 | E16: CONUS | H16: 24.98 | J16: =IF(F16>0,IF($I16<$H16,$H16,$I16),0) -> 0 | L16: =(J16*$L$4) -> 0 | M16: =(L16+J16)*$M$4 -> 0 | N16: =(J16+L16)*$N$4 -> 0 | O16: =(L16+J16+M16+N16)*$O$4 -> 0 | P16: =(J16+L16+M16+N16+O16)*$P$4 -> 0 | Q16: =SUM(J16:P16) -> 0 | R16: =IF($R$4<0,"N/A",(Q16-P16)*$R$4) -> 0 | S16: =SUM(Q16:R16) -> 0 | T16: =Q16*F16 -> 0 | U16: =R16*F16 -> 0 | V16: =S16*F16 -> 0
B17: 2 | C17: Field Service Representative | D17: H.3.8 | E17: CONUS | H17: 30.76 | J17: =IF(F17>0,IF($I17<$H17,$H17,$I17),0) -> 0 | L17: =(J17*$L$4) -> 0 | M17: =(L17+J17)*$M$4 -> 0 | N17: =(J17+L17)*$N$4 -> 0 | O17: =(L17+J17+M17+N17)*$O$4 -> 0 | P17: =(J17+L17+M17+N17+O17)*$P$4 -> 0 | Q17: =SUM(J17:P17) -> 0 | R17: =IF($R$4<0,"N/A",(Q17-P17)*$R$4) -> 0 | S17: =SUM(Q17:R17) -> 0 | T17: =Q17*F17 -> 0 | U17: =R17*F17 -> 0 | V17: =S17*F17 -> 0
A18: Modification Work Order (MWO) Installation | B18: 2 | C18: Field Service Representative | D18: H.3.8 | E18: CONUS | H18: 30.76 | J18: =IF(F18>0,IF($I18<$H18,$H18,$I18),0) -> 0 | L18: =(J18*$L$4) -> 0 | M18: =(L18+J18)*$M$4 -> 0 | N18: =(J18+L18)*$N$4 -> 0 | O18: =(L18+J18+M18+N18)*$O$4 -> 0 | P18: =(J18+L18+M18+N18+O18)*$P$4 -> 0 | Q18: =SUM(J18:P18) -> 0 | R18: =IF($R$4<0,"N/A",(Q18-P18)*$R$4) -> 0 | S18: =SUM(Q18:R18) -> 0 | T18: =Q18*F18 -> 0 | U18: =R18*F18 -> 0 | V18: =S18*F18 -> 0
B19: 10 | C19: MWO Installer | D19: H.3.6 | E19: CONUS | H19: 30.76 | J19: =IF(F19>0,IF($I19<$H19,$H19,$I19),0) -> 0 | L19: =(J19*$L$4) -> 0 | M19: =(L19+J19)*$M$4 -> 0 | N19: =(J19+L19)*$N$4 -> 0 | O19: =(L19+J19+M19+N19)*$O$4 -> 0 | P19: =(J19+L19+M19+N19+O19)*$P$4 -> 0 | Q19: =SUM(J19:P19) -> 0 | R19: =IF($R$4<0,"N/A",(Q19-P19)*$R$4) -> 0 | S19: =SUM(Q19:R19) -> 0 | T19: =Q19*F19 -> 0 | U19: =R19*F19 -> 0 | V19: =S19*F19 -> 0
B20: 6 | C20: Inspector | D20: H.3.10 | E20: CONUS | H20: 29.28 | J20: =IF(F20>0,IF($I20<$H20,$H20,$I20),0) -> 0 | L20: =(J20*$L$4) -> 0 | M20: =(L20+J20)*$M$4 -> 0 | N20: =(J20+L20)*$N$4 -> 0 | O20: =(L20+J20+M20+N20)*$O$4 -> 0 | P20: =(J20+L20+M20+N20+O20)*$P$4 -> 0 | Q20: =SUM(J20:P20) -> 0 | R20: =IF($R$4<0,"N/A",(Q20-P20)*$R$4) -> 0 | S20: =SUM(Q20:R20) -> 0 | T20: =Q20*F20 -> 0 | U20: =R20*F20 -> 0 | V20: =S20*F20 -> 0
B21: 8 | C21: Welder | D21: H.3.5 | E21: CONUS | H21: 24.52 | J21: =IF(F21>0,IF($I21<$H21,$H21,$I21),0) -> 0 | L21: =(J21*$L$4) -> 0 | M21: =(L21+J21)*$M$4 -> 0 | N21: =(J21+L21)*$N$4 -> 0 | O21: =(L21+J21+M21+N21)*$O$4 -> 0 | P21: =(J21+L21+M21+N21+O21)*$P$4 -> 0 | Q21: =SUM(J21:P21) -> 0 | R21: =IF($R$4<0,"N/A",(Q21-P21)*$R$4) -> 0 | S21: =SUM(Q21:R21) -> 0 | T21: =Q21*F21 -> 0 | U21: =R21*F21 -> 0 | V21: =S21*F21 -> 0
A22: OCONUS
A23: Field Service Representative (FSR) | B23: 11 | C23: Field Service Representative | D23: H.3.8 | E23: OCONUS | H23: 35.83 | J23: =IF(F23>0,IF($I23<$H23,$H23,$I23),0) -> 0 | K23: =(J23*$K$4) -> 0 | L23: =(J23+K23)*$L$4 -> 0 | M23: =(J23+K23+L23)*$M$4 -> 0 | N23: =(J23+K23+L23)*$N$4 -> 0 | O23: =(J23+K23+L23+M23+N23)*$O$4 -> 0 | P23: =(J23+L23+M23+N23+O23)*$P$4 -> 0 | Q23: =SUM(J23:P23) -> 0 | R23: =IF($R$4<0,"N/A",(Q23-P23)*$R$4) -> 0 | S23: =SUM(Q23:R23) -> 0 | T23: =Q23*F23 -> 0 | U23: =R23*F23 -> 0 | V23: =S23*F23 -> 0
B24: 12 | C24: Field Service Mechanic | D24: H.3.9 | E24: OCONUS | H24: 30.76
A25: Deprocessing | B25: 13 | C25: Heavy Equipment Mechanic | D25: H.3.4 | E25: OCONUS | H25: 32.298 | J25: =IF(F25>0,IF($I25<$H25,$H25,$I25),0) -> 0 | K25: =(J25*$K$4) -> 0 | L25: =(J25+K25)*$L$4 -> 0 | M25: =(J25+K25+L25)*$M$4 -> 0 | N25: =(J25+K25+L25)*$N$4 -> 0 | O25: =(J25+K25+L25+M25+N25)*$O$4 -> 0 | P25: =(J25+L25+M25+N25+O25)*$P$4 -> 0 | Q25: =SUM(J25:P25) -> 0 | R25: =IF($R$4<0,"N/A",(Q25-P25)*$R$4) -> 0 | S25: =SUM(Q25:R25) -> 0 | T25: =Q25*F25 -> 0 | U25: =R25*F25 -> 0 | V25: =S25*F25 -> 0
B26: 14 | C26: Material Handling Specialist | D26: H.3.3 | E26: OCONUS | H26: 29.169 | J26: =IF(F26>0,IF($I26<$H26,$H26,$I26),0) -> 0 | K26: =(J26*$K$4) -> 0 | L26: =(J26+K26)*$L$4 -> 0 | M26: =(J26+K26+L26)*$M$4 -> 0 | N26: =(J26+K26+L26)*$N$4 -> 0 | O26: =(J26+K26+L26+M26+N26)*$O$4 -> 0 | P26: =(J26+L26+M26+N26+O26)*$P$4 -> 0 | Q26: =SUM(J26:P26) -> 0 | R26: =IF($R$4<0,"N/A",(Q26-P26)*$R$4) -> 0 | S26: =SUM(Q26:R26) -> 0 | T26: =Q26*F26 -> 0 | U26: =R26*F26 -> 0 | V26: =S26*F26 -> 0
B27: 15 | C27: Inspector | D27: H.3.9 | E27: OCONUS | H27: 30.744 | J27: =IF(F27>0,IF($I27<$H27,$H27,$I27),0) -> 0 | K27: =(J27*$K$4) -> 0 | L27: =(J27+K27)*$L$4 -> 0 | M27: =(J27+K27+L27)*$M$4 -> 0 | N27: =(J27+K27+L27)*$N$4 -> 0 | O27: =(J27+K27+L27+M27+N27)*$O$4 -> 0 | P27: =(J27+L27+M27+N27+O27)*$P$4 -> 0 | Q27: =SUM(J27:P27) -> 0 | R27: =IF($R$4<0,"N/A",(Q27-P27)*$R$4) -> 0 | S27: =SUM(Q27:R27) -> 0 | T27: =Q27*F27 -> 0 | U27: =R27*F27 -> 0 | V27: =S27*F27 -> 0
B28: 16 | C28: Supply/Procurement Specialist | D28: H.3.2 | E28: OCONUS | H28: 37.485 | J28: =IF(F28>0,IF($I28<$H28,$H28,$I28),0) -> 0 | K28: =(J28*$K$4) -> 0 | L28: =(J28+K28)*$L$4 -> 0 | M28: =(J28+K28+L28)*$M$4 -> 0 | N28: =(J28+K28+L28)*$N$4 -> 0 | O28: =(J28+K28+L28+M28+N28)*$O$4 -> 0 | P28: =(J28+L28+M28+N28+O28)*$P$4 -> 0 | Q28: =SUM(J28:P28) -> 0 | R28: =IF($R$4<0,"N/A",(Q28-P28)*$R$4) -> 0 | S28: =SUM(Q28:R28) -> 0 | T28: =Q28*F28 -> 0 | U28: =R28*F28 -> 0 | V28: =S28*F28 -> 0
B29: 17 | C29: Welder | D29: H.3.5 | E29: OCONUS | H29: 25.746 | J29: =IF(F29>0,IF($I29<$H29,$H29,$I29),0) -> 0 | K29: =(J29*$K$4) -> 0 | L29: =(J29+K29)*$L$4 -> 0 | M29: =(J29+K29+L29)*$M$4 -> 0 | N29: =(J29+K29+L29)*$N$4 -> 0 | O29: =(J29+K29+L29+M29+N29)*$O$4 -> 0 | P29: =(J29+L29+M29+N29+O29)*$P$4 -> 0 | Q29: =SUM(J29:P29) -> 0 | R29: =IF($R$4<0,"N/A",(Q29-P29)*$R$4) -> 0 | S29: =SUM(Q29:R29) -> 0 | T29: =Q29*F29 -> 0 | U29: =R29*F29 -> 0 | V29: =S29*F29 -> 0
A30: New Equipment Training (NET) / Displaced Equipment Training (DET) | B30: 18 | C30: Instructor | D30: H.3.7 | E30: OCONUS | H30: 27.1845 | J30: =IF(F30>0,IF($I30<$H30,$H30,$I30),0) -> 0 | K30: =(J30*$K$4) -> 0 | L30: =(J30+K30)*$L$4 -> 0 | M30: =(J30+K30+L30)*$M$4 -> 0 | N30: =(J30+K30+L30)*$N$4 -> 0 | O30: =(J30+K30+L30+M30+N30)*$O$4 -> 0 | P30: =(J30+L30+M30+N30+O30)*$P$4 -> 0 | Q30: =SUM(J30:P30) -> 0 | R30: =IF($R$4<0,"N/A",(Q30-P30)*$R$4) -> 0 | S30: =SUM(Q30:R30) -> 0 | T30: =Q30*F30 -> 0 | U30: =R30*F30 -> 0 | V30: =S30*F30 -> 0
A31: Total Package Fielding (TPF) | B31: 13 | C31: Heavy Equipment Mechanic | D31: H.3.4 | E31: OCONUS | H31: 32.298 | J31: =IF(F31>0,IF($I31<$H31,$H31,$I31),0) -> 0 | K31: =(J31*$K$4) -> 0 | L31: =(J31+K31)*$L$4 -> 0 | M31: =(J31+K31+L31)*$M$4 -> 0 | N31: =(J31+K31+L31)*$N$4 -> 0 | O31: =(J31+K31+L31+M31+N31)*$O$4 -> 0 | P31: =(J31+L31+M31+N31+O31)*$P$4 -> 0 | Q31: =SUM(J31:P31) -> 0 | R31: =IF($R$4<0,"N/A",(Q31-P31)*$R$4) -> 0 | S31: =SUM(Q31:R31) -> 0 | T31: =Q31*F31 -> 0 | U31: =R31*F31 -> 0 | V31: =S31*F31 -> 0
B32: 14 | C32: Material Handling Specialist | D32: H.3.3 | E32: OCONUS | H32: 29.169 | J32: =IF(F32>0,IF($I32<$H32,$H32,$I32),0) -> 0 | K32: =(J32*$K$4) -> 0 | L32: =(J32+K32)*$L$4 -> 0 | M32: =(J32+K32+L32)*$M$4 -> 0 | N32: =(J32+K32+L32)*$N$4 -> 0 | O32: =(J32+K32+L32+M32+N32)*$O$4 -> 0 | P32: =(J32+L32+M32+N32+O32)*$P$4 -> 0 | Q32: =SUM(J32:P32) -> 0 | R32: =IF($R$4<0,"N/A",(Q32-P32)*$R$4) -> 0 | S32: =SUM(Q32:R32) -> 0 | T32: =Q32*F32 -> 0 | U32: =R32*F32 -> 0 | V32: =S32*F32 -> 0
B33: 15 | C33: Inspector | D33: H.3.10 | E33: OCONUS | H33: 30.744 | J33: =IF(F33>0,IF($I33<$H33,$H33,$I33),0) -> 0 | K33: =(J33*$K$4) -> 0 | L33: =(J33+K33)*$L$4 -> 0 | M33: =(J33+K33+L33)*$M$4 -> 0 | N33: =(J33+K33+L33)*$N$4 -> 0 | O33: =(J33+K33+L33+M33+N33)*$O$4 -> 0 | P33: =(J33+L33+M33+N33+O33)*$P$4 -> 0 | Q33: =SUM(J33:P33) -> 0 | R33: =IF($R$4<0,"N/A",(Q33-P33)*$R$4) -> 0 | S33: =SUM(Q33:R33) -> 0 | T33: =Q33*F33 -> 0 | U33: =R33*F33 -> 0 | V33: =S33*F33 -> 0
B34: 11 | C34: Field Service Representative | D34: H.3.8 | E34: OCONUS | H34: 32.298 | J34: =IF(F34>0,IF($I34<$H34,$H34,$I34),0) -> 0 | K34: =(J34*$K$4) -> 0 | L34: =(J34+K34)*$L$4 -> 0 | M34: =(J34+K34+L34)*$M$4 -> 0 | N34: =(J34+K34+L34)*$N$4 -> 0 | O34: =(J34+K34+L34+M34+N34)*$O$4 -> 0 | P34: =(J34+L34+M34+N34+O34)*$P$4 -> 0 | Q34: =SUM(J34:P34) -> 0 | R34: =IF($R$4<0,"N/A",(Q34-P34)*$R$4) -> 0 | S34: =SUM(Q34:R34) -> 0 | T34: =Q34*F34 -> 0 | U34: =R34*F34 -> 0 | V34: =S34*F34 -> 0
A35: Modification Work Order (MWO) Installation | B35: 11 | C35: Field Service Representative | D35: H.3.8 | E35: OCONUS | H35: 32.298 | J35: =IF(F35>0,IF($I35<$H35,$H35,$I35),0) -> 0 | K35: =(J35*$K$4) -> 0 | L35: =(J35+K35)*$L$4 -> 0 | M35: =(J35+K35+L35)*$M$4 -> 0 | N35: =(J35+K35+L35)*$N$4 -> 0 | O35: =(J35+K35+L35+M35+N35)*$O$4 -> 0 | P35: =(J35+L35+M35+N35+O35)*$P$4 -> 0 | Q35: =SUM(J35:P35) -> 0 | R35: =IF($R$4<0,"N/A",(Q35-P35)*$R$4) -> 0 | S35: =SUM(Q35:R35) -> 0 | T35: =Q35*F35 -> 0 | U35: =R35*F35 -> 0 | V35: =S35*F35 -> 0
B36: 19 | C36: MWO Installer | D36: H.3.6 | E36: OCONUS | H36: 32.298 | J36: =IF(F36>0,IF($I36<$H36,$H36,$I36),0) -> 0 | K36: =(J36*$K$4) -> 0 | L36: =(J36+K36)*$L$4 -> 0 | M36: =(J36+K36+L36)*$M$4 -> 0 | N36: =(J36+K36+L36)*$N$4 -> 0 | O36: =(J36+K36+L36+M36+N36)*$O$4 -> 0 | P36: =(J36+L36+M36+N36+O36)*$P$4 -> 0 | Q36: =SUM(J36:P36) -> 0 | R36: =IF($R$4<0,"N/A",(Q36-P36)*$R$4) -> 0 | S36: =SUM(Q36:R36) -> 0 | T36: =Q36*F36 -> 0 | U36: =R36*F36 -> 0 | V36: =S36*F36 -> 0
B37: 15 | C37: Inspector | D37: H.3.10 | E37: OCONUS | H37: 30.744 | J37: =IF(F37>0,IF($I37<$H37,$H37,$I37),0) -> 0 | K37: =(J37*$K$4) -> 0 | L37: =(J37+K37)*$L$4 -> 0 | M37: =(J37+K37+L37)*$M$4 -> 0 | N37: =(J37+K37+L37)*$N$4 -> 0 | O37: =(J37+K37+L37+M37+N37)*$O$4 -> 0 | P37: =(J37+L37+M37+N37+O37)*$P$4 -> 0 | Q37: =SUM(J37:P37) -> 0 | R37: =IF($R$4<0,"N/A",(Q37-P37)*$R$4) -> 0 | S37: =SUM(Q37:R37) -> 0 | T37: =Q37*F37 -> 0 | U37: =R37*F37 -> 0 | V37: =S37*F37 -> 0
B38: 17 | C38: Welder | D38: H.3.5 | E38: OCONUS | H38: 25.746 | J38: =IF(F38>0,IF($I38<$H38,$H38,$I38),0) -> 0 | K38: =(J38*$K$4) -> 0 | L38: =(J38+K38)*$L$4 -> 0 | M38: =(J38+K38+L38)*$M$4 -> 0 | N38: =(J38+K38+L38)*$N$4 -> 0 | O38: =(J38+K38+L38+M38+N38)*$O$4 -> 0 | P38: =(J38+L38+M38+N38+O38)*$P$4 -> 0 | Q38: =SUM(J38:P38) -> 0 | R38: =IF($R$4<0,"N/A",(Q38-P38)*$R$4) -> 0 | S38: =SUM(Q38:R38) -> 0 | T38: =Q38*F38 -> 0 | U38: =R38*F38 -> 0 | V38: =S38*F38 -> 0
A39: Ordering Period 2:
A40: Ordering Period 2 Labor Categories & Hours | H40: Subcontractor Labor
...

Sheet Escalation
A1: POP | B1: Minimum Escalation | C1: Proposed Escalation | D1: Calculated Escalation
A2: Ordering Period 2 | B2: 0.026 | D2: =IF($C2<$B2,$B2,$C2) -> 0.026
A3: Ordering Period 3 | B3: 0.026 | D3: =IF($C3<$B3,$B3,$C3) -> 0.026
A4: Ordering Period 4 | B4: 0.026 | D4: =IF($C4<$B4,$B4,$C4) -> 0.026
A5: Ordering Period 5 | B5: 0.026 | D5: =IF($C5<$B5,$B5,$C5) -> 0.026

Sheet DBA
A1: Subcontractors with accounting practices that include DBA Insurance in its indirect rates shall use this tab to provide evidence that DBA expenses are included as part of indirect costs within the proposed FBLR (i.e. identify the pool expense and indirect rate associated with DBA), showing how the DBA Insurance is accounted for.

Sheet Sub FBLR
A1: Service | B1: ID | C1: Labor Category | D1: Reference | E1: Location | F1: Hours | G1: SUB FBLR
A2: Ordering Period 1
A3: CONUS
A4: Program Management | B4: 1 | C4: Project Management Specialist | E4: CONUS | F4: ='Subcontractor Labor Build'!F5 -> 0 | G4: ='Subcontractor Labor Build'!S5 -> 0
A5: Field Service Representative (FSR) | B5: 2 | C5: Field Service Representative | E5: CONUS | F5: ='Subcontractor Labor Build'!F6 -> 0 | G5: ='Subcontractor Labor Build'!S6 -> 0
B6: 3 | C6: Field Service Mechanic | E6: CONUS | F6: ='Subcontractor Labor Build'!F7 -> 0 | G6: ='Subcontractor Labor Build'!S7 -> 0
A7: Deprocessing | B7: 4 | C7: Heavy Equipment Mechanic | E7: CONUS | F7: ='Subcontractor Labor Build'!F8 -> 0 | G7: ='Subcontractor Labor Build'!S8 -> 0
B8: 5 | C8: Material Handling Specialist | E8: CONUS | F8: ='Subcontractor Labor Build'!F9 -> 0 | G8: ='Subcontractor Labor Build'!S9 -> 0
B9: 6 | C9: Inspector | E9: CONUS | F9: ='Subcontractor Labor Build'!F10 -> 0 | G9: ='Subcontractor Labor Build'!S10 -> 0
B10: 7 | C10: Supply/Procurement Specialist | E10: CONUS | F10: ='Subcontractor Labor Build'!F11 -> 0 | G10: ='Subcontractor Labor Build'!S11 -> 0
B11: 8 | C11: Welder | E11: CONUS | F11: ='Subcontractor Labor Build'!F12 -> 0 | G11: ='Subcontractor Labor Build'!S12 -> 0
A12: New Equipment Training (NET) / Displaced Equipment Training (DET) | B12: 9 | C12: Instructor | E12: CONUS | F12: ='Subcontractor Labor Build'!F13 -> 0 | G12: ='Subcontractor Labor Build'!S13 -> 0
A13: Total Package Fielding (TPF) | B13: 4 | C13: Heavy Equipment Mechanic | E13: CONUS | F13: ='Subcontractor Labor Build'!F14 -> 0 | G13: ='Subcontractor Labor Build'!S14 -> 0
B14: 5 | C14: Material Handling Specialist | E14: CONUS | F14: ='Subcontractor Labor Build'!F15 -> 0 | G14: ='Subcontractor Labor Build'!S15 -> 0
B15: 6 | C15: Inspector | E15: CONUS | F15: ='Subcontractor Labor Build'!F16 -> 0 | G15: ='Subcontractor Labor Build'!S16 -> 0
B16: 2 | C16: Field Service Representative | E16: CONUS | F16: ='Subcontractor Labor Build'!F17 -> 0 | G16: ='Subcontractor Labor Build'!S17 -> 0
A17: Modification Work Order (MWO) Installation | B17: 2 | C17: Field Service Representative | E17: CONUS | F17: ='Subcontractor Labor Build'!F18 -> 0 | G17: ='Subcontractor Labor Build'!S18 -> 0
B18: 10 | C18: MWO Installer | E18: CONUS | F18: ='Subcontractor Labor Build'!F19 -> 0 | G18: ='Subcontractor Labor Build'!S19 -> 0
B19: 6 | C19: Inspector | E19: CONUS | F19: ='Subcontractor Labor Build'!F20 -> 0 | G19: ='Subcontractor Labor Build'!S20 -> 0
B20: 8 | C20: Welder | E20: CONUS | F20: ='Subcontractor Labor Build'!F21 -> 0 | G20: ='Subcontractor Labor Build'!S21 -> 0
A21: OCONUS
A22: Field Service Representative (FSR) | B22: 11 | C22: Field Service Representative | E22: OCONUS | F22: ='Subcontractor Labor Build'!F23 -> 0 | G22: ='Subcontractor Labor Build'!S23 -> 0
B23: 12 | C23: Field Service Mechanic | E23: OCONUS | F23: ='Subcontractor Labor Build'!F24 -> 0 | G23: ='Subcontractor Labor Build'!S24 -> 0
A24: Deprocessing | B24: 13 | C24: Heavy Equipment Mechanic | E24: OCONUS | F24: ='Subcontractor Labor Build'!F25 -> 0 | G24: ='Subcontractor Labor Build'!S25 -> 0
B25: 14 | C25: Material Handling Specialist | E25: OCONUS | F25: ='Subcontractor Labor Build'!F26 -> 0 | G25: ='Subcontractor Labor Build'!S26 -> 0
B26: 15 | C26: Inspector | E26: OCONUS | F26: ='Subcontractor Labor Build'!F27 -> 0 | G26: ='Subcontractor Labor Build'!S27 -> 0
B27: 16 | C27: Supply/Procurement Specialist | E27: OCONUS | F27: ='Subcontractor Labor Build'!F28 -> 0 | G27: ='Subcontractor Labor Build'!S28 -> 0
B28: 17 | C28: Welder | E28: OCONUS | F28: ='Subcontractor Labor Build'!F29 -> 0 | G28: ='Subcontractor Labor Build'!S29 -> 0
A29: New Equipment Training (NET) / Displaced Equipment Training (DET) | B29: 18 | C29: Instructor | E29: OCONUS | F29: ='Subcontractor Labor Build'!F30 -> 0 | G29: ='Subcontractor Labor Build'!S30 -> 0
A30: Total Package Fielding (TPF) | B30: 13 | C30: Heavy Equipment Mechanic | E30: OCONUS | F30: ='Subcontractor Labor Build'!F31 -> 0 | G30: ='Subcontractor Labor Build'!S31 -> 0
B31: 14 | C31: Material Handling Specialist | E31: OCONUS | F31: ='Subcontractor Labor Build'!F32 -> 0 | G31: ='Subcontractor Labor Build'!S32 -> 0
B32: 15 | C32: Inspector | E32: OCONUS | F32: ='Subcontractor Labor Build'!F33 -> 0 | G32: ='Subcontractor Labor Build'!S33 -> 0
B33: 11 | C33: Field Service Representative | E33: OCONUS | F33: ='Subcontractor Labor Build'!F34 -> 0 | G33: ='Subcontractor Labor Build'!S34 -> 0
A34: Modification Work Order (MWO) Installation | B34: 11 | C34: Field Service Representative | E34: OCONUS | F34: ='Subcontractor Labor Build'!F35 -> 0 | G34: ='Subcontractor Labor Build'!S35 -> 0
B35: 19 | C35: MWO Installer | E35: OCONUS | F35: ='Subcontractor Labor Build'!F36 -> 0 | G35: ='Subcontractor Labor Build'!S36 -> 0
B36: 15 | C36: Inspector | E36: OCONUS | F36: ='Subcontractor Labor Build'!F37 -> 0 | G36: ='Subcontractor Labor Build'!S37 -> 0
B37: 17 | C37: Welder | E37: OCONUS | F37: ='Subcontractor Labor Build'!F38 -> 0 | G37: ='Subcontractor Labor Build'!S38 -> 0
A38: Ordering Period 2
A39: CONUS
A40: Program Management | B40: 1 | C40: Project Management Specialist | E40: CONUS | F40: ='Subcontractor Labor Build'!F43 -> 0 | G40: ='Subcontractor Labor Build'!S43 -> 0
...
