Workbook

Sheet Instructions 
A3: CLIN 1 and Clin 3 | B3: Second Opinion Examination & Schedule Award/Impairment Ratings will share pricing rates
B4: On each performance period tab, enter the proposed rate by specialty and location in the appropriate cells indicated as the tier 1 pricing (highlighed in blue).
B5: The Table will average all individual entries to a single rate.
B6: The summary tab will apply this average rate to volume estimates to calculate the proposed CLIN 1 and CLIN 3 prices.
B7: The Government will use the summary tab for evaluation purposes.
B8: As offerors' summary prices reach similarity, the government will consider individual pricing on the performance period tab.
A10: CLIN 2 | B10: IME Examination pricing rate
B11: On each performance period tab, enter the proposed rate by specialty and location in the appropriate cells indicated as the tier 1 pricing (highlighed in blue).
B12: The Table will average all individual entries to a single rate.
B13: The summary tab will apply this average rate to volume estimates to calculate the proposed CLIN 2 prices.
B14: The Government will use the summary tab for evaluation purposes.
B15: As offerors' summary prices reach similarity, the government will consider individual pricing on the performance period tab.
A17: CLIN 4 | B17: Supplemental Report pricing rate
B18: On each performance period tab, enter the proposed fixed rate for all supplemental reports indicated as the tier 1 pricing (highlighed in blue).
B19: The summary tab will apply this fixed rate to volume estimates to calculate the proposed CLIN 4 prices.
B20: The Government will use the summary tab for evaluation purposes.
A22: CLIN 5 | B22: File Review Surgical pricing rate
B23: On each performance period tab, enter the proposed rate by file size in the appropriate cells indicated as the tier 1 pricing (highlighed in blue).
B24: The Table will average all individual entries to a single rate.
B25: The summary tab will apply this average rate to volume estimates to calculate the proposed CLIN 5 prices.
B26: The Government will use the summary tab for evaluation purposes.
B27: As offerors' summary prices reach similarity, the government will consider individual pricing on the performance period tab.
A29: CLIN 6 | B29: File Review--Impairment pricing rate
B30: On each performance period tab, enter the proposed rate by file size in the appropriate cells indicated as the tier 1 pricing (highlighed in blue).
B31: The Table will average all individual entries to a single rate.
B32: The summary tab will apply this average rate to volume estimates to calculate the proposed CLIN 6 prices.
B33: The Government will use the summary tab for evaluation purposes.
B34: As offerors' summary prices reach similarity, the government will consider individual pricing on the performance period tab.
A36: CLIN 7 | B36: File Review Other pricing rate
B37: On each performance period tab, enter the proposed rate by file size in the appropriate cells indicated as the tier 1 pricing (highlighed in blue).
B38: The Table will average all individual entries to a single rate.
B39: The summary tab will apply this average rate to volume estimates to calculate the proposed CLIN 7 prices.
B40: The Government will use the summary tab for evaluation purposes.
B41: As offerors' summary prices reach similarity, the government will consider individual pricing on the performance period tab.
A44: CLIN 8 and 9 | B44: The Government will provide a set not to exceed value common to all offerors, based on historical volumes and mandatory government pricing for the components of these CLINS
B45: Travel/Transpiration is governed by the Federal Travel Regulation (FTR) issued by the General Services Administration (GSA)
B46: Claimant No-Show/Government Cancelations less than 24 hour notice are set at $200 per instance.
B47: Interpreter Services are set by OWCP fee schedule
B48: Diagnostic Tests are set by OWCP fee schedule
B49: All other ancillary services are set by OWCP fee schedule

Sheet Base Period
A1: RFP 1605C3-25-R-00007 - Directed Medical Services for the Division of Federal Employees Compensation
A2: CLIN 0001 Second Opinion Examination & CLIN 0003 Schedule Award/Impairment Ratings
B3: Tier 1 (Base Price) | I3: Tier 2 (Incentive Price)
A4: State/Location | B4: Orthopedic surgery Price per exam | C4: Pulmonary Medicine Price Per exam | D4: Otolaryngology Price per exam | E4: Neurology price per exam | F4: Psychiatry Price per exam | G4: Other Specialists price per exam | I4: Orthopedic surgery Price per exam | J4: Pulmonary Medicine Price Per exam | K4: Otolaryngology Price per exam | L4: Neurology price per exam | M4: Psychiatry Price per exam | N4: Other Specialists price per exam
A5: Puerto Rico | B5: 0 | C5: 0 | D5: 0 | E5: 0 | F5: 0 | G5: 0 | I5: =B5*1.1 -> 0 | J5: =C5*1.1 -> 0 | K5: =D5*1.1 -> 0 | L5: =E5*1.1 -> 0 | M5: =F5*1.1 -> 0 | N5: =G5*1.1 -> 0
A6: Virgin Islands | B6: 0 | C6: 0 | D6: 0 | E6: 0 | F6: 0 | G6: 0 | I6: =B6*1.1 -> 0 | J6: =C6*1.1 -> 0 | K6: =D6*1.1 -> 0 | L6: =E6*1.1 -> 0 | M6: =F6*1.1 -> 0 | N6: =G6*1.1 -> 0
A7: All other Territories or Possessions | B7: 0 | C7: 0 | D7: 0 | E7: 0 | F7: 0 | G7: 0 | I7: =B7*1.1 -> 0 | J7: =C7*1.1 -> 0 | K7: =D7*1.1 -> 0 | L7: =E7*1.1 -> 0 | M7: =F7*1.1 -> 0 | N7: =G7*1.1 -> 0
A8: AK | B8: 0 | C8: 0 | D8: 0 | E8: 0 | F8: 0 | G8: 0 | I8: =B8*1.1 -> 0 | J8: =C8*1.1 -> 0 | K8: =D8*1.1 -> 0 | L8: =E8*1.1 -> 0 | M8: =F8*1.1 -> 0 | N8: =G8*1.1 -> 0
A9: AL | B9: 0 | C9: 0 | D9: 0 | E9: 0 | F9: 0 | G9: 0 | I9: =B9*1.1 -> 0 | J9: =C9*1.1 -> 0 | K9: =D9*1.1 -> 0 | L9: =E9*1.1 -> 0 | M9: =F9*1.1 -> 0 | N9: =G9*1.1 -> 0
A10: AR | B10: 0 | C10: 0 | D10: 0 | E10: 0 | F10: 0 | G10: 0 | I10: =B10*1.1 -> 0 | J10: =C10*1.1 -> 0 | K10: =D10*1.1 -> 0 | L10: =E10*1.1 -> 0 | M10: =F10*1.1 -> 0 | N10: =G10*1.1 -> 0
A11: AZ | B11: 0 | C11: 0 | D11: 0 | E11: 0 | F11: 0 | G11: 0 | I11: =B11*1.1 -> 0 | J11: =C11*1.1 -> 0 | K11: =D11*1.1 -> 0 | L11: =E11*1.1 -> 0 | M11: =F11*1.1 -> 0 | N11: =G11*1.1 -> 0
A12: CA | B12: 0 | C12: 0 | D12: 0 | E12: 0 | F12: 0 | G12: 0 | I12: =B12*1.1 -> 0 | J12: =C12*1.1 -> 0 | K12: =D12*1.1 -> 0 | L12: =E12*1.1 -> 0 | M12: =F12*1.1 -> 0 | N12: =G12*1.1 -> 0
A13: CT | B13: 0 | C13: 0 | D13: 0 | E13: 0 | F13: 0 | G13: 0 | I13: =B13*1.1 -> 0 | J13: =C13*1.1 -> 0 | K13: =D13*1.1 -> 0 | L13: =E13*1.1 -> 0 | M13: =F13*1.1 -> 0 | N13: =G13*1.1 -> 0
A14: CO | B14: 0 | C14: 0 | D14: 0 | E14: 0 | F14: 0 | G14: 0 | I14: =B14*1.1 -> 0 | J14: =C14*1.1 -> 0 | K14: =D14*1.1 -> 0 | L14: =E14*1.1 -> 0 | M14: =F14*1.1 -> 0 | N14: =G14*1.1 -> 0
A15: DC | B15: 0 | C15: 0 | D15: 0 | E15: 0 | F15: 0 | G15: 0 | I15: =B15*1.1 -> 0 | J15: =C15*1.1 -> 0 | K15: =D15*1.1 -> 0 | L15: =E15*1.1 -> 0 | M15: =F15*1.1 -> 0 | N15: =G15*1.1 -> 0
A16: DE | B16: 0 | C16: 0 | D16: 0 | E16: 0 | F16: 0 | G16: 0 | I16: =B16*1.1 -> 0 | J16: =C16*1.1 -> 0 | K16: =D16*1.1 -> 0 | L16: =E16*1.1 -> 0 | M16: =F16*1.1 -> 0 | N16: =G16*1.1 -> 0
... A62: WY | B62: 0 | C62: 0 | D62: 0 | E62: 0 | F62: 0 | G62: 0 | I62: =B62*1.1 -> 0 | J62: =C62*1.1 -> 0 | K62: =D62*1.1 -> 0 | L62: =E62*1.1 -> 0 | M62: =F62*1.1 -> 0 | N62: =G62*1.1 -> 0
A63: Average | B63: =AVERAGE(B5:G62) -> 0
A65: CLIN 0002 IME examination
B66: Tier 1 (Base Price) | I66: Tier 2 (Incentive Price)
A67: State/Location | B67: Orthopedic surgery Price per exam | C67: Pulmonary Medicine Price Per exam | D67: Otolaryngology Price per exam | E67: Neurology price per exam | F67: Psychiatry Price per exam | G67: Other Specialists price per exam | I67: Orthopedic surgery Price per exam | J67: Pulmonary Medicine Price Per exam | K67: Otolaryngology Price per exam | L67: Neurology price per exam | M67: Psychiatry Price per exam | N67: Other Specialists price per exam
A68: Puerto Rico | B68: 0 | C68: 0 | D68: 0 | E68: 0 | F68: 0 | G68: 0 | I68: =B68*1.1 -> 0 | J68: =C68*1.1 -> 0 | K68: =D68*1.1 -> 0 | L68: =E68*1.1 -> 0 | M68: =F68*1.1 -> 0 | N68: =G68*1.1 -> 0
A69: Virgin Islands | B69: 0 | C69: 0 | D69: 0 | E69: 0 | F69: 0 | G69: 0 | I69: =B69*1.1 -> 0 | J69: =C69*1.1 -> 0 | K69: =D69*1.1 -> 0 | L69: =E69*1.1 -> 0 | M69: =F69*1.1 -> 0 | N69: =G69*1.1 -> 0
A70: All other Territories or Possessions | B70: 0 | C70: 0 | D70: 0 | E70: 0 | F70: 0 | G70: 0 | I70: =B70*1.1 -> 0 | J70: =C70*1.1 -> 0 | K70: =D70*1.1 -> 0 | L70: =E70*1.1 -> 0 | M70: =F70*1.1 -> 0 | N70: =G70*1.1 -> 0
A71: AK | B71: 0 | C71: 0 | D71: 0 | E71: 0 | F71: 0 | G71: 0 | I71: =B71*1.1 -> 0 | J71: =C71*1.1 -> 0 | K71: =D71*1.1 -> 0 | L71: =E71*1.1 -> 0 | M71: =F71*1.1 -> 0 | N71: =G71*1.1 -> 0
A72: AL | B72: 0 | C72: 0 | D72: 0 | E72: 0 | F72: 0 | G72: 0 | I72: =B72*1.1 -> 0 | J72: =C72*1.1 -> 0 | K72: =D72*1.1 -> 0 | L72: =E72*1.1 -> 0 | M72: =F72*1.1 -> 0 | N72: =G72*1.1 -> 0
A73: AR | B73: 0 | C73: 0 | D73: 0 | E73: 0 | F73: 0 | G73: 0 | I73: =B73*1.1 -> 0 | J73: =C73*1.1 -> 0 | K73: =D73*1.1 -> 0 | L73: =E73*1.1 -> 0 | M73: =F73*1.1 -> 0 | N73: =G73*1.1 -> 0
A74: AZ | B74: 0 | C74: 0 | D74: 0 | E74: 0 | F74: 0 | G74: 0 | I74: =B74*1.1 -> 0 | J74: =C74*1.1 -> 0 | K74: =D74*1.1 -> 0 | L74: =E74*1.1 -> 0 | M74: =F74*1.1 -> 0 | N74: =G74*1.1 -> 0
A75: CA | B75: 0 | C75: 0 | D75: 0 | E75: 0 | F75: 0 | G75: 0 | I75: =B75*1.1 -> 0 | J75: =C75*1.1 -> 0 | K75: =D75*1.1 -> 0 | L75: =E75*1.1 -> 0 | M75: =F75*1.1 -> 0 | N75: =G75*1.1 -> 0
A76: CT | B76: 0 | C76: 0 | D76: 0 | E76: 0 | F76: 0 | G76: 0 | I76: =B76*1.1 -> 0 | J76: =C76*1.1 -> 0 | K76: =D76*1.1 -> 0 | L76: =E76*1.1 -> 0 | M76: =F76*1.1 -> 0 | N76: =G76*1.1 -> 0
A77: CO | B77: 0 | C77: 0 | D77: 0 | E77: 0 | F77: 0 | G77: 0 | I77: =B77*1.1 -> 0 | J77: =C77*1.1 -> 0 | K77: =D77*1.1 -> 0 | L77: =E77*1.1 -> 0 | M77: =F77*1.1 -> 0 | N77: =G77*1.1 -> 0
A78: DC | B78: 0 | C78: 0 | D78: 0 | E78: 0 | F78: 0 | G78: 0 | I78: =B78*1.1 -> 0 | J78: =C78*1.1 -> 0 | K78: =D78*1.1 -> 0 | L78: =E78*1.1 -> 0 | M78: =F78*1.1 -> 0 | N78: =G78*1.1 -> 0
A79: DE | B79: 0 | C79: 0 | D79: 0 | E79: 0 | F79: 0 | G79: 0 | I79: =B79*1.1 -> 0 | J79: =C79*1.1 -> 0 | K79: =D79*1.1 -> 0 | L79: =E79*1.1 -> 0 | M79: =F79*1.1 -> 0 | N79: =G79*1.1 -> 0
... A125: WY | B125: 0 | C125: 0 | D125: 0 | E125: 0 | F125: 0 | G125: 0 | I125: =B125*1.1 -> 0 | J125: =C125*1.1 -> 0 | K125: =D125*1.1 -> 0 | L125: =E125*1.1 -> 0 | M125: =F125*1.1 -> 0 | N125: =G125*1.1 -> 0
A126: Average | B126: =AVERAGE(B68:G125) -> 0
B130: Tier 1 (Base Price) | D130: Tier 2 (Incentive Price)
A132: CLIN 0004 Supplemental Reports | B132: Price per report
A133: CLIN 0004 Supplemental Reports | B133: 0 | D133: =B133*1.1 -> 0
A136: CLIN 0005 File Review Surgical | B136: Price per review
A137: CLIN 0005 File Review Surgical (0-100 Pages) | B137: 0 | D137: =B137*1.1 -> 0
...

Sheet Option Period 1
A1: RFP 1605C3-25-R-01007 - Directed Medical Services for the Division of Federal Employees Compensation
A2: CLIN 1001 Second Opinion Examination & CLIN 1003 Schedule Award/Impairment Ratings
B3: Tier 1 (Base Price) | I3: Tier 2 (Incentive Price)
A4: State/Location | B4: Orthopedic surgery Price per exam | C4: Pulmonary Medicine Price Per exam | D4: Otolaryngology Price per exam | E4: Neurology price per exam | F4: Psychiatry Price per exam | G4: Other Specialists price per exam | I4: Orthopedic surgery Price per exam | J4: Pulmonary Medicine Price Per exam | K4: Otolaryngology Price per exam | L4: Neurology price per exam | M4: Psychiatry Price per exam | N4: Other Specialists price per exam
A5: Puerto Rico | B5: 0 | C5: 0 | D5: 0 | E5: 0 | F5: 0 | G5: 0 | I5: =B5*1.1 -> 0 | J5: =C5*1.1 -> 0 | K5: =D5*1.1 -> 0 | L5: =E5*1.1 -> 0 | M5: =F5*1.1 -> 0 | N5: =G5*1.1 -> 0
A6: Virgin Islands | B6: 0 | C6: 0 | D6: 0 | E6: 0 | F6: 0 | G6: 0 | I6: =B6*1.1 -> 0 | J6: =C6*1.1 -> 0 | K6: =D6*1.1 -> 0 | L6: =E6*1.1 -> 0 | M6: =F6*1.1 -> 0 | N6: =G6*1.1 -> 0
A7: All other Territories or Possessions | B7: 0 | C7: 0 | D7: 0 | E7: 0 | F7: 0 | G7: 0 | I7: =B7*1.1 -> 0 | J7: =C7*1.1 -> 0 | K7: =D7*1.1 -> 0 | L7: =E7*1.1 -> 0 | M7: =F7*1.1 -> 0 | N7: =G7*1.1 -> 0
A8: AK | B8: 0 | C8: 0 | D8: 0 | E8: 0 | F8: 0 | G8: 0 | I8: =B8*1.1 -> 0 | J8: =C8*1.1 -> 0 | K8: =D8*1.1 -> 0 | L8: =E8*1.1 -> 0 | M8: =F8*1.1 -> 0 | N8: =G8*1.1 -> 0
A9: AL | B9: 0 | C9: 0 | D9: 0 | E9: 0 | F9: 0 | G9: 0 | I9: =B9*1.1 -> 0 | J9: =C9*1.1 -> 0 | K9: =D9*1.1 -> 0 | L9: =E9*1.1 -> 0 | M9: =F9*1.1 -> 0 | N9: =G9*1.1 -> 0
A10: AR | B10: 0 | C10: 0 | D10: 0 | E10: 0 | F10: 0 | G10: 0 | I10: =B10*1.1 -> 0 | J10: =C10*1.1 -> 0 | K10: =D10*1.1 -> 0 | L10: =E10*1.1 -> 0 | M10: =F10*1.1 -> 0 | N10: =G10*1.1 -> 0
A11: AZ | B11: 0 | C11: 0 | D11: 0 | E11: 0 | F11: 0 | G11: 0 | I11: =B11*1.1 -> 0 | J11: =C11*1.1 -> 0 | K11: =D11*1.1 -> 0 | L11: =E11*1.1 -> 0 | M11: =F11*1.1 -> 0 | N11: =G11*1.1 -> 0
A12: CA | B12: 0 | C12: 0 | D12: 0 | E12: 0 | F12: 0 | G12: 0 | I12: =B12*1.1 -> 0 | J12: =C12*1.1 -> 0 | K12: =D12*1.1 -> 0 | L12: =E12*1.1 -> 0 | M12: =F12*1.1 -> 0 | N12: =G12*1.1 -> 0
A13: CT | B13: 0 | C13: 0 | D13: 0 | E13: 0 | F13: 0 | G13: 0 | I13: =B13*1.1 -> 0 | J13: =C13*1.1 -> 0 | K13: =D13*1.1 -> 0 | L13: =E13*1.1 -> 0 | M13: =F13*1.1 -> 0 | N13: =G13*1.1 -> 0
A14: CO | B14: 0 | C14: 0 | D14: 0 | E14: 0 | F14: 0 | G14: 0 | I14: =B14*1.1 -> 0 | J14: =C14*1.1 -> 0 | K14: =D14*1.1 -> 0 | L14: =E14*1.1 -> 0 | M14: =F14*1.1 -> 0 | N14: =G14*1.1 -> 0
A15: DC | B15: 0 | C15: 0 | D15: 0 | E15: 0 | F15: 0 | G15: 0 | I15: =B15*1.1 -> 0 | J15: =C15*1.1 -> 0 | K15: =D15*1.1 -> 0 | L15: =E15*1.1 -> 0 | M15: =F15*1.1 -> 0 | N15: =G15*1.1 -> 0
A16: DE | B16: 0 | C16: 0 | D16: 0 | E16: 0 | F16: 0 | G16: 0 | I16: =B16*1.1 -> 0 | J16: =C16*1.1 -> 0 | K16: =D16*1.1 -> 0 | L16: =E16*1.1 -> 0 | M16: =F16*1.1 -> 0 | N16: =G16*1.1 -> 0
... A62: WY | B62: 0 | C62: 0 | D62: 0 | E62: 0 | F62: 0 | G62: 0 | I62: =B62*1.1 -> 0 | J62: =C62*1.1 -> 0 | K62: =D62*1.1 -> 0 | L62: =E62*1.1 -> 0 | M62: =F62*1.1 -> 0 | N62: =G62*1.1 -> 0
A63: Average | B63: =AVERAGE(B5:G62) -> 0
A65: CLIN 1002 IME examination
B66: Tier 1 (Base Price) | I66: Tier 2 (Incentive Price)
A67: State/Location | B67: Orthopedic surgery Price per exam | C67: Pulmonary Medicine Price Per exam | D67: Otolaryngology Price per exam | E67: Neurology price per exam | F67: Psychiatry Price per exam | G67: Other Specialists price per exam | I67: Orthopedic surgery Price per exam | J67: Pulmonary Medicine Price Per exam | K67: Otolaryngology Price per exam | L67: Neurology price per exam | M67: Psychiatry Price per exam | N67: Other Specialists price per exam
A68: Puerto Rico | B68: 0 | C68: 0 | D68: 0 | E68: 0 | F68: 0 | G68: 0 | I68: =B68*1.1 -> 0 | J68: =C68*1.1 -> 0 | K68: =D68*1.1 -> 0 | L68: =E68*1.1 -> 0 | M68: =F68*1.1 -> 0 | N68: =G68*1.1 -> 0
A69: Virgin Islands | B69: 0 | C69: 0 | D69: 0 | E69: 0 | F69: 0 | G69: 0 | I69: =B69*1.1 -> 0 | J69: =C69*1.1 -> 0 | K69: =D69*1.1 -> 0 | L69: =E69*1.1 -> 0 | M69: =F69*1.1 -> 0 | N69: =G69*1.1 -> 0
A70: All other Territories or Possessions | B70: 0 | C70: 0 | D70: 0 | E70: 0 | F70: 0 | G70: 0 | I70: =B70*1.1 -> 0 | J70: =C70*1.1 -> 0 | K70: =D70*1.1 -> 0 | L70: =E70*1.1 -> 0 | M70: =F70*1.1 -> 0 | N70: =G70*1.1 -> 0
A71: AK | B71: 0 | C71: 0 | D71: 0 | E71: 0 | F71: 0 | G71: 0 | I71: =B71*1.1 -> 0 | J71: =C71*1.1 -> 0 | K71: =D71*1.1 -> 0 | L71: =E71*1.1 -> 0 | M71: =F71*1.1 -> 0 | N71: =G71*1.1 -> 0
A72: AL | B72: 0 | C72: 0 | D72: 0 | E72: 0 | F72: 0 | G72: 0 | I72: =B72*1.1 -> 0 | J72: =C72*1.1 -> 0 | K72: =D72*1.1 -> 0 | L72: =E72*1.1 -> 0 | M72: =F72*1.1 -> 0 | N72: =G72*1.1 -> 0
A73: AR | B73: 0 | C73: 0 | D73: 0 | E73: 0 | F73: 0 | G73: 0 | I73: =B73*1.1 -> 0 | J73: =C73*1.1 -> 0 | K73: =D73*1.1 -> 0 | L73: =E73*1.1 -> 0 | M73: =F73*1.1 -> 0 | N73: =G73*1.1 -> 0
A74: AZ | B74: 0 | C74: 0 | D74: 0 | E74: 0 | F74: 0 | G74: 0 | I74: =B74*1.1 -> 0 | J74: =C74*1.1 -> 0 | K74: =D74*1.1 -> 0 | L74: =E74*1.1 -> 0 | M74: =F74*1.1 -> 0 | N74: =G74*1.1 -> 0
A75: CA | B75: 0 | C75: 0 | D75: 0 | E75: 0 | F75: 0 | G75: 0 | I75: =B75*1.1 -> 0 | J75: =C75*1.1 -> 0 | K75: =D75*1.1 -> 0 | L75: =E75*1.1 -> 0 | M75: =F75*1.1 -> 0 | N75: =G75*1.1 -> 0
A76: CT | B76: 0 | C76: 0 | D76: 0 | E76: 0 | F76: 0 | G76: 0 | I76: =B76*1.1 -> 0 | J76: =C76*1.1 -> 0 | K76: =D76*1.1 -> 0 | L76: =E76*1.1 -> 0 | M76: =F76*1.1 -> 0 | N76: =G76*1.1 -> 0
A77: CO | B77: 0 | C77: 0 | D77: 0 | E77: 0 | F77: 0 | G77: 0 | I77: =B77*1.1 -> 0 | J77: =C77*1.1 -> 0 | K77: =D77*1.1 -> 0 | L77: =E77*1.1 -> 0 | M77: =F77*1.1 -> 0 | N77: =G77*1.1 -> 0
A78: DC | B78: 0 | C78: 0 | D78: 0 | E78: 0 | F78: 0 | G78: 0 | I78: =B78*1.1 -> 0 | J78: =C78*1.1 -> 0 | K78: =D78*1.1 -> 0 | L78: =E78*1.1 -> 0 | M78: =F78*1.1 -> 0 | N78: =G78*1.1 -> 0
A79: DE | B79: 0 | C79: 0 | D79: 0 | E79: 0 | F79: 0 | G79: 0 | I79: =B79*1.1 -> 0 | J79: =C79*1.1 -> 0 | K79: =D79*1.1 -> 0 | L79: =E79*1.1 -> 0 | M79: =F79*1.1 -> 0 | N79: =G79*1.1 -> 0
... A125: WY | B125: 0 | C125: 0 | D125: 0 | E125: 0 | F125: 0 | G125: 0 | I125: =B125*1.1 -> 0 | J125: =C125*1.1 -> 0 | K125: =D125*1.1 -> 0 | L125: =E125*1.1 -> 0 | M125: =F125*1.1 -> 0 | N125: =G125*1.1 -> 0
A126: Average | B126: =AVERAGE(B68:G125) -> 0
B130: Tier 1 (Base Price) | D130: Tier 2 (Incentive Price)
A132: CLIN 1004 Supplemental Reports | B132: Price per report
A133: CLIN 1004 Supplemental Reports | B133: 0 | D133: =B133*1.1 -> 0
A136: CLIN 1005 File Review Surgical | B136: Price per review
A137: CLIN 1005 File Review Surgical (0-100 Pages) | B137: 0 | D137: =B137*1.1 -> 0
...

Sheet Option Period 2
A1: RFP 1605C3-25-R-00007 - Directed Medical Services for the Division of Federal Employees Compensation
A2: CLIN 2001 Second Opinion Examination & CLIN 2003 Schedule Award/Impairment Ratings
B3: Tier 1 (Base Price) | I3: Tier 2 (Incentive Price)
A4: State/Location | B4: Orthopedic surgery Price per exam | C4: Pulmonary Medicine Price Per exam | D4: Otolaryngology Price per exam | E4: Neurology price per exam | F4: Psychiatry Price per exam | G4: Other Specialists price per exam | I4: Orthopedic surgery Price per exam | J4: Pulmonary Medicine Price Per exam | K4: Otolaryngology Price per exam | L4: Neurology price per exam | M4: Psychiatry Price per exam | N4: Other Specialists price per exam
A5: Puerto Rico | B5: 0 | C5: 0 | D5: 0 | E5: 0 | F5: 0 | G5: 0 | I5: =B5*1.1 -> 0 | J5: =C5*1.1 -> 0 | K5: =D5*1.1 -> 0 | L5: =E5*1.1 -> 0 | M5: =F5*1.1 -> 0 | N5: =G5*1.1 -> 0
A6: Virgin Islands | B6: 0 | C6: 0 | D6: 0 | E6: 0 | F6: 0 | G6: 0 | I6: =B6*1.1 -> 0 | J6: =C6*1.1 -> 0 | K6: =D6*1.1 -> 0 | L6: =E6*1.1 -> 0 | M6: =F6*1.1 -> 0 | N6: =G6*1.1 -> 0
A7: All other Territories or Possessions | B7: 0 | C7: 0 | D7: 0 | E7: 0 | F7: 0 | G7: 0 | I7: =B7*1.1 -> 0 | J7: =C7*1.1 -> 0 | K7: =D7*1.1 -> 0 | L7: =E7*1.1 -> 0 | M7: =F7*1.1 -> 0 | N7: =G7*1.1 -> 0
A8: AK | B8: 0 | C8: 0 | D8: 0 | E8: 0 | F8: 0 | G8: 0 | I8: =B8*1.1 -> 0 | J8: =C8*1.1 -> 0 | K8: =D8*1.1 -> 0 | L8: =E8*1.1 -> 0 | M8: =F8*1.1 -> 0 | N8: =G8*1.1 -> 0
A9: AL | B9: 0 | C9: 0 | D9: 0 | E9: 0 | F9: 0 | G9: 0 | I9: =B9*1.1 -> 0 | J9: =C9*1.1 -> 0 | K9: =D9*1.1 -> 0 | L9: =E9*1.1 -> 0 | M9: =F9*1.1 -> 0 | N9: =G9*1.1 -> 0
A10: AR | B10: 0 | C10: 0 | D10: 0 | E10: 0 | F10: 0 | G10: 0 | I10: =B10*1.1 -> 0 | J10: =C10*1.1 -> 0 | K10: =D10*1.1 -> 0 | L10: =E10*1.1 -> 0 | M10: =F10*1.1 -> 0 | N10: =G10*1.1 -> 0
A11: AZ | B11: 0 | C11: 0 | D11: 0 | E11: 0 | F11: 0 | G11: 0 | I11: =B11*1.1 -> 0 | J11: =C11*1.1 -> 0 | K11: =D11*1.1 -> 0 | L11: =E11*1.1 -> 0 | M11: =F11*1.1 -> 0 | N11: =G11*1.1 -> 0
A12: CA | B12: 0 | C12: 0 | D12: 0 | E12: 0 | F12: 0 | G12: 0 | I12: =B12*1.1 -> 0 | J12: =C12*1.1 -> 0 | K12: =D12*1.1 -> 0 | L12: =E12*1.1 -> 0 | M12: =F12*1.1 -> 0 | N12: =G12*1.1 -> 0
A13: CT | B13: 0 | C13: 0 | D13: 0 | E13: 0 | F13: 0 | G13: 0 | I13: =B13*1.1 -> 0 | J13: =C13*1.1 -> 0 | K13: =D13*1.1 -> 0 | L13: =E13*1.1 -> 0 | M13: =F13*1.1 -> 0 | N13: =G13*1.1 -> 0
A14: CO | B14: 0 | C14: 0 | D14: 0 | E14: 0 | F14: 0 | G14: 0 | I14: =B14*1.1 -> 0 | J14: =C14*1.1 -> 0 | K14: =D14*1.1 -> 0 | L14: =E14*1.1 -> 0 | M14: =F14*1.1 -> 0 | N14: =G14*1.1 -> 0
A15: DC | B15: 0 | C15: 0 | D15: 0 | E15: 0 | F15: 0 | G15: 0 | I15: =B15*1.1 -> 0 | J15: =C15*1.1 -> 0 | K15: =D15*1.1 -> 0 | L15: =E15*1.1 -> 0 | M15: =F15*1.1 -> 0 | N15: =G15*1.1 -> 0
A16: DE | B16: 0 | C16: 0 | D16: 0 | E16: 0 | F16: 0 | G16: 0 | I16: =B16*1.1 -> 0 | J16: =C16*1.1 -> 0 | K16: =D16*1.1 -> 0 | L16: =E16*1.1 -> 0 | M16: =F16*1.1 -> 0 | N16: =G16*1.1 -> 0
... A62: WY | B62: 0 | C62: 0 | D62: 0 | E62: 0 | F62: 0 | G62: 0 | I62: =B62*1.1 -> 0 | J62: =C62*1.1 -> 0 | K62: =D62*1.1 -> 0 | L62: =E62*1.1 -> 0 | M62: =F62*1.1 -> 0 | N62: =G62*1.1 -> 0
A63: Average | B63: =AVERAGE(B5:G62) -> 0
A65: CLIN 2002 IME examination
B66: Tier 1 (Base Price) | I66: Tier 2 (Incentive Price)
A67: State/Location | B67: Orthopedic surgery Price per exam | C67: Pulmonary Medicine Price Per exam | D67: Otolaryngology Price per exam | E67: Neurology price per exam | F67: Psychiatry Price per exam | G67: Other Specialists price per exam | I67: Orthopedic surgery Price per exam | J67: Pulmonary Medicine Price Per exam | K67: Otolaryngology Price per exam | L67: Neurology price per exam | M67: Psychiatry Price per exam | N67: Other Specialists price per exam
A68: Puerto Rico | C68: 0 | D68: 0 | E68: 0 | F68: 0 | G68: 0 | I68: =B68*1.1 -> 0 | J68: =C68*1.1 -> 0 | K68: =D68*1.1 -> 0 | L68: =E68*1.1 -> 0 | M68: =F68*1.1 -> 0 | N68: =G68*1.1 -> 0
A69: Virgin Islands | B69: 0 | C69: 0 | D69: 0 | E69: 0 | F69: 0 | G69: 0 | I69: =B69*1.1 -> 0 | J69: =C69*1.1 -> 0 | K69: =D69*1.1 -> 0 | L69: =E69*1.1 -> 0 | M69: =F69*1.1 -> 0 | N69: =G69*1.1 -> 0
A70: All other Territories or Possessions | B70: 0 | C70: 0 | D70: 0 | E70: 0 | F70: 0 | G70: 0 | I70: =B70*1.1 -> 0 | J70: =C70*1.1 -> 0 | K70: =D70*1.1 -> 0 | L70: =E70*1.1 -> 0 | M70: =F70*1.1 -> 0 | N70: =G70*1.1 -> 0
A71: AK | B71: 0 | C71: 0 | D71: 0 | E71: 0 | F71: 0 | G71: 0 | I71: =B71*1.1 -> 0 | J71: =C71*1.1 -> 0 | K71: =D71*1.1 -> 0 | L71: =E71*1.1 -> 0 | M71: =F71*1.1 -> 0 | N71: =G71*1.1 -> 0
A72: AL | B72: 0 | C72: 0 | D72: 0 | E72: 0 | F72: 0 | G72: 0 | I72: =B72*1.1 -> 0 | J72: =C72*1.1 -> 0 | K72: =D72*1.1 -> 0 | L72: =E72*1.1 -> 0 | M72: =F72*1.1 -> 0 | N72: =G72*1.1 -> 0
A73: AR | B73: 0 | C73: 0 | D73: 0 | E73: 0 | F73: 0 | G73: 0 | I73: =B73*1.1 -> 0 | J73: =C73*1.1 -> 0 | K73: =D73*1.1 -> 0 | L73: =E73*1.1 -> 0 | M73: =F73*1.1 -> 0 | N73: =G73*1.1 -> 0
A74: AZ | B74: 0 | C74: 0 | D74: 0 | E74: 0 | F74: 0 | G74: 0 | I74: =B74*1.1 -> 0 | J74: =C74*1.1 -> 0 | K74: =D74*1.1 -> 0 | L74: =E74*1.1 -> 0 | M74: =F74*1.1 -> 0 | N74: =G74*1.1 -> 0
A75: CA | B75: 0 | C75: 0 | D75: 0 | E75: 0 | F75: 0 | G75: 0 | I75: =B75*1.1 -> 0 | J75: =C75*1.1 -> 0 | K75: =D75*1.1 -> 0 | L75: =E75*1.1 -> 0 | M75: =F75*1.1 -> 0 | N75: =G75*1.1 -> 0
A76: CT | B76: 0 | C76: 0 | D76: 0 | E76: 0 | F76: 0 | G76: 0 | I76: =B76*1.1 -> 0 | J76: =C76*1.1 -> 0 | K76: =D76*1.1 -> 0 | L76: =E76*1.1 -> 0 | M76: =F76*1.1 -> 0 | N76: =G76*1.1 -> 0
A77: CO | B77: 0 | C77: 0 | D77: 0 | E77: 0 | F77: 0 | G77: 0 | I77: =B77*1.1 -> 0 | J77: =C77*1.1 -> 0 | K77: =D77*1.1 -> 0 | L77: =E77*1.1 -> 0 | M77: =F77*1.1 -> 0 | N77: =G77*1.1 -> 0
A78: DC | B78: 0 | C78: 0 | D78: 0 | E78: 0 | F78: 0 | G78: 0 | I78: =B78*1.1 -> 0 | J78: =C78*1.1 -> 0 | K78: =D78*1.1 -> 0 | L78: =E78*1.1 -> 0 | M78: =F78*1.1 -> 0 | N78: =G78*1.1 -> 0
A79: DE | B79: 0 | C79: 0 | D79: 0 | E79: 0 | F79: 0 | G79: 0 | I79: =B79*1.1 -> 0 | J79: =C79*1.1 -> 0 | K79: =D79*1.1 -> 0 | L79: =E79*1.1 -> 0 | M79: =F79*1.1 -> 0 | N79: =G79*1.1 -> 0
A80: FL North | B80: 0 | C80: 0 | D80: 0 | E80: 0 | F80: 0 | G80: 0 | I80: =B80*1.1 -> 0 | J80: =C80*1.1 -> 0 | K80: =D80*1.1 -> 0 | L80: =E80*1.1 -> 0 | M80: =F80*1.1 -> 0 | N80: =G80*1.1 -> 0
... A125: WY | B125: 0 | C125: 0 | D125: 0 | E125: 0 | F125: 0 | G125: 0 | I125: =B125*1.1 -> 0 | J125: =C125*1.1 -> 0 | K125: =D125*1.1 -> 0 | L125: =E125*1.1 -> 0 | M125: =F125*1.1 -> 0 | N125: =G125*1.1 -> 0
A126: Average | B126: =AVERAGE(B68:G125) -> 0
B130: Tier 1 (Base Price) | D130: Tier 2 (Incentive Price)
A132: CLIN 2004 Supplemental Reports | B132: Price per report
A133: CLIN 2004 Supplemental Reports | B133: 0 | D133: =B133*1.1 -> 0
A136: CLIN 2005 File Review Surgical | B136: Price per review
...

Sheet Option Period 3
A1: RFP 1605C3-25-R-00007 - Directed Medical Services for the Division of Federal Employees Compensation
A2: CLIN 3001 Second Opinion Examination & CLIN 3003 Schedule Award/Impairment Ratings
B3: Tier 1 (Base Price) | I3: Tier 2 (Incentive Price)
A4: State/Location | B4: Orthopedic surgery Price per exam | C4: Pulmonary Medicine Price Per exam | D4: Otolaryngology Price per exam | E4: Neurology price per exam | F4: Psychiatry Price per exam | G4: Other Specialists price per exam | I4: Orthopedic surgery Price per exam | J4: Pulmonary Medicine Price Per exam | K4: Otolaryngology Price per exam | L4: Neurology price per exam | M4: Psychiatry Price per exam | N4: Other Specialists price per exam
A5: Puerto Rico | B5: 0 | C5: 0 | D5: 0 | E5: 0 | F5: 0 | G5: 0 | I5: =B5*1.1 -> 0 | J5: =C5*1.1 -> 0 | K5: =D5*1.1 -> 0 | L5: =E5*1.1 -> 0 | M5: =F5*1.1 -> 0 | N5: =G5*1.1 -> 0
A6: Virgin Islands | B6: 0 | C6: 0 | D6: 0 | E6: 0 | F6: 0 | G6: 0 | I6: =B6*1.1 -> 0 | J6: =C6*1.1 -> 0 | K6: =D6*1.1 -> 0 | L6: =E6*1.1 -> 0 | M6: =F6*1.1 -> 0 | N6: =G6*1.1 -> 0
A7: All other Territories or Possessions | B7: 0 | C7: 0 | D7: 0 | E7: 0 | F7: 0 | G7: 0 | I7: =B7*1.1 -> 0 | J7: =C7*1.1 -> 0 | K7: =D7*1.1 -> 0 | L7: =E7*1.1 -> 0 | M7: =F7*1.1 -> 0 | N7: =G7*1.1 -> 0
A8: AK | B8: 0 | C8: 0 | D8: 0 | E8: 0 | F8: 0 | G8: 0 | I8: =B8*1.1 -> 0 | J8: =C8*1.1 -> 0 | K8: =D8*1.1 -> 0 | L8: =E8*1.1 -> 0 | M8: =F8*1.1 -> 0 | N8: =G8*1.1 -> 0
A9: AL | B9: 0 | C9: 0 | D9: 0 | E9: 0 | F9: 0 | G9: 0 | I9: =B9*1.1 -> 0 | J9: =C9*1.1 -> 0 | K9: =D9*1.1 -> 0 | L9: =E9*1.1 -> 0 | M9: =F9*1.1 -> 0 | N9: =G9*1.1 -> 0
A10: AR | B10: 0 | C10: 0 | D10: 0 | E10: 0 | F10: 0 | G10: 0 | I10: =B10*1.1 -> 0 | J10: =C10*1.1 -> 0 | K10: =D10*1.1 -> 0 | L10: =E10*1.1 -> 0 | M10: =F10*1.1 -> 0 | N10: =G10*1.1 -> 0
A11: AZ | B11: 0 | C11: 0 | D11: 0 | E11: 0 | F11: 0 | G11: 0 | I11: =B11*1.1 -> 0 | J11: =C11*1.1 -> 0 | K11: =D11*1.1 -> 0 | L11: =E11*1.1 -> 0 | M11: =F11*1.1 -> 0 | N11: =G11*1.1 -> 0
A12: CA | B12: 0 | C12: 0 | D12: 0 | E12: 0 | F12: 0 | G12: 0 | I12: =B12*1.1 -> 0 | J12: =C12*1.1 -> 0 | K12: =D12*1.1 -> 0 | L12: =E12*1.1 -> 0 | M12: =F12*1.1 -> 0 | N12: =G12*1.1 -> 0
A13: CT | B13: 0 | C13: 0 | D13: 0 | E13: 0 | F13: 0 | G13: 0 | I13: =B13*1.1 -> 0 | J13: =C13*1.1 -> 0 | K13: =D13*1.1 -> 0 | L13: =E13*1.1 -> 0 | M13: =F13*1.1 -> 0 | N13: =G13*1.1 -> 0
A14: CO | B14: 0 | C14: 0 | D14: 0 | E14: 0 | F14: 0 | G14: 0 | I14: =B14*1.1 -> 0 | J14: =C14*1.1 -> 0 | K14: =D14*1.1 -> 0 | L14: =E14*1.1 -> 0 | M14: =F14*1.1 -> 0 | N14: =G14*1.1 -> 0
A15: DC | B15: 0 | C15: 0 | D15: 0 | E15: 0 | F15: 0 | G15: 0 | I15: =B15*1.1 -> 0 | J15: =C15*1.1 -> 0 | K15: =D15*1.1 -> 0 | L15: =E15*1.1 -> 0 | M15: =F15*1.1 -> 0 | N15: =G15*1.1 -> 0
A16: DE | B16: 0 | C16: 0 | D16: 0 | E16: 0 | F16: 0 | G16: 0 | I16: =B16*1.1 -> 0 | J16: =C16*1.1 -> 0 | K16: =D16*1.1 -> 0 | L16: =E16*1.1 -> 0 | M16: =F16*1.1 -> 0 | N16: =G16*1.1 -> 0
... A62: WY | B62: 0 | C62: 0 | D62: 0 | E62: 0 | F62: 0 | G62: 0 | I62: =B62*1.1 -> 0 | J62: =C62*1.1 -> 0 | K62: =D62*1.1 -> 0 | L62: =E62*1.1 -> 0 | M62: =F62*1.1 -> 0 | N62: =G62*1.1 -> 0
A63: Average | B63: =AVERAGE(B5:G62) -> 0
A65: CLIN 3002 IME examination
B66: Tier 1 (Base Price) | I66: Tier 2 (Incentive Price)
A67: State/Location | B67: Orthopedic surgery Price per exam | C67: Pulmonary Medicine Price Per exam | D67: Otolaryngology Price per exam | E67: Neurology price per exam | F67: Psychiatry Price per exam | G67: Other Specialists price per exam | I67: Orthopedic surgery Price per exam | J67: Pulmonary Medicine Price Per exam | K67: Otolaryngology Price per exam | L67: Neurology price per exam | M67: Psychiatry Price per exam | N67: Other Specialists price per exam
A68: Puerto Rico | B68: 0 | C68: 0 | D68: 0 | E68: 0 | F68: 0 | G68: 0 | I68: =B68*1.1 -> 0 | J68: =C68*1.1 -> 0 | K68: =D68*1.1 -> 0 | L68: =E68*1.1 -> 0 | M68: =F68*1.1 -> 0 | N68: =G68*1.1 -> 0
A69: Virgin Islands | B69: 0 | C69: 0 | D69: 0 | E69: 0 | F69: 0 | G69: 0 | I69: =B69*1.1 -> 0 | J69: =C69*1.1 -> 0 | K69: =D69*1.1 -> 0 | L69: =E69*1.1 -> 0 | M69: =F69*1.1 -> 0 | N69: =G69*1.1 -> 0
A70: All other Territories or Possessions | B70: 0 | C70: 0 | D70: 0 | E70: 0 | F70: 0 | G70: 0 | I70: =B70*1.1 -> 0 | J70: =C70*1.1 -> 0 | K70: =D70*1.1 -> 0 | L70: =E70*1.1 -> 0 | M70: =F70*1.1 -> 0 | N70: =G70*1.1 -> 0
A71: AK | B71: 0 | C71: 0 | D71: 0 | E71: 0 | F71: 0 | G71: 0 | I71: =B71*1.1 -> 0 | J71: =C71*1.1 -> 0 | K71: =D71*1.1 -> 0 | L71: =E71*1.1 -> 0 | M71: =F71*1.1 -> 0 | N71: =G71*1.1 -> 0
A72: AL | B72: 0 | C72: 0 | D72: 0 | E72: 0 | F72: 0 | G72: 0 | I72: =B72*1.1 -> 0 | J72: =C72*1.1 -> 0 | K72: =D72*1.1 -> 0 | L72: =E72*1.1 -> 0 | M72: =F72*1.1 -> 0 | N72: =G72*1.1 -> 0
A73: AR | B73: 0 | C73: 0 | D73: 0 | E73: 0 | F73: 0 | G73: 0 | I73: =B73*1.1 -> 0 | J73: =C73*1.1 -> 0 | K73: =D73*1.1 -> 0 | L73: =E73*1.1 -> 0 | M73: =F73*1.1 -> 0 | N73: =G73*1.1 -> 0
A74: AZ | B74: 0 | C74: 0 | D74: 0 | E74: 0 | F74: 0 | G74: 0 | I74: =B74*1.1 -> 0 | J74: =C74*1.1 -> 0 | K74: =D74*1.1 -> 0 | L74: =E74*1.1 -> 0 | M74: =F74*1.1 -> 0 | N74: =G74*1.1 -> 0
A75: CA | B75: 0 | C75: 0 | D75: 0 | E75: 0 | F75: 0 | G75: 0 | I75: =B75*1.1 -> 0 | J75: =C75*1.1 -> 0 | K75: =D75*1.1 -> 0 | L75: =E75*1.1 -> 0 | M75: =F75*1.1 -> 0 | N75: =G75*1.1 -> 0
A76: CT | B76: 0 | C76: 0 | D76: 0 | E76: 0 | F76: 0 | G76: 0 | I76: =B76*1.1 -> 0 | J76: =C76*1.1 -> 0 | K76: =D76*1.1 -> 0 | L76: =E76*1.1 -> 0 | M76: =F76*1.1 -> 0 | N76: =G76*1.1 -> 0
A77: CO | B77: 0 | C77: 0 | D77: 0 | E77: 0 | F77: 0 | G77: 0 | I77: =B77*1.1 -> 0 | J77: =C77*1.1 -> 0 | K77: =D77*1.1 -> 0 | L77: =E77*1.1 -> 0 | M77: =F77*1.1 -> 0 | N77: =G77*1.1 -> 0
A78: DC | B78: 0 | C78: 0 | D78: 0 | E78: 0 | F78: 0 | G78: 0 | I78: =B78*1.1 -> 0 | J78: =C78*1.1 -> 0 | K78: =D78*1.1 -> 0 | L78: =E78*1.1 -> 0 | M78: =F78*1.1 -> 0 | N78: =G78*1.1 -> 0
A79: DE | B79: 0 | C79: 0 | D79: 0 | E79: 0 | F79: 0 | G79: 0 | I79: =B79*1.1 -> 0 | J79: =C79*1.1 -> 0 | K79: =D79*1.1 -> 0 | L79: =E79*1.1 -> 0 | M79: =F79*1.1 -> 0 | N79: =G79*1.1 -> 0
... A125: WY | B125: 0 | C125: 0 | D125: 0 | E125: 0 | F125: 0 | G125: 0 | I125: =B125*1.1 -> 0 | J125: =C125*1.1 -> 0 | K125: =D125*1.1 -> 0 | L125: =E125*1.1 -> 0 | M125: =F125*1.1 -> 0 | N125: =G125*1.1 -> 0
A126: Average | B126: =AVERAGE(B68:G125) -> 0
B130: Tier 1 (Base Price) | D130: Tier 2 (Incentive Price)
A132: CLIN 3004 Supplemental Reports | B132: Price per report
A133: CLIN 3004 Supplemental Reports | B133: 0 | D133: =B133*1.1 -> 0
A136: CLIN 3005 File Review Surgical | B136: Price per review
A137: CLIN 3005 File Review Surgical (0-100 Pages) | B137: 0 | D137: =B137*1.1 -> 0
...

Sheet Option Period 4
A1: RFP 1605C3-25-R-00007 - Directed Medical Services for the Division of Federal Employees Compensation
A2: CLIN 4001 Second Opinion Examination & CLIN 4003 Schedule Award/Impairment Ratings
B3: Tier 1 (Base Price) | I3: Tier 2 (Incentive Price)
A4: State/Location | B4: Orthopedic surgery Price per exam | C4: Pulmonary Medicine Price Per exam | D4: Otolaryngology Price per exam | E4: Neurology price per exam | F4: Psychiatry Price per exam | G4: Other Specialists price per exam | I4: Orthopedic surgery Price per exam | J4: Pulmonary Medicine Price Per exam | K4: Otolaryngology Price per exam | L4: Neurology price per exam | M4: Psychiatry Price per exam | N4: Other Specialists price per exam
A5: Puerto Rico | B5: 0 | C5: 0 | D5: 0 | E5: 0 | F5: 0 | G5: 0 | I5: =B5*1.1 -> 0 | J5: =C5*1.1 -> 0 | K5: =D5*1.1 -> 0 | L5: =E5*1.1 -> 0 | M5: =F5*1.1 -> 0 | N5: =G5*1.1 -> 0
A6: Virgin Islands | B6: 0 | C6: 0 | D6: 0 | E6: 0 | F6: 0 | G6: 0 | I6: =B6*1.1 -> 0 | J6: =C6*1.1 -> 0 | K6: =D6*1.1 -> 0 | L6: =E6*1.1 -> 0 | M6: =F6*1.1 -> 0 | N6: =G6*1.1 -> 0
A7: All other Territories or Possessions | B7: 0 | C7: 0 | D7: 0 | E7: 0 | F7: 0 | G7: 0 | I7: =B7*1.1 -> 0 | J7: =C7*1.1 -> 0 | K7: =D7*1.1 -> 0 | L7: =E7*1.1 -> 0 | M7: =F7*1.1 -> 0 | N7: =G7*1.1 -> 0
A8: AK | B8: 0 | C8: 0 | D8: 0 | E8: 0 | F8: 0 | G8: 0 | I8: =B8*1.1 -> 0 | J8: =C8*1.1 -> 0 | K8: =D8*1.1 -> 0 | L8: =E8*1.1 -> 0 | M8: =F8*1.1 -> 0 | N8: =G8*1.1 -> 0
A9: AL | B9: 0 | C9: 0 | D9: 0 | E9: 0 | F9: 0 | G9: 0 | I9: =B9*1.1 -> 0 | J9: =C9*1.1 -> 0 | K9: =D9*1.1 -> 0 | L9: =E9*1.1 -> 0 | M9: =F9*1.1 -> 0 | N9: =G9*1.1 -> 0
A10: AR | B10: 0 | C10: 0 | D10: 0 | E10: 0 | F10: 0 | G10: 0 | I10: =B10*1.1 -> 0 | J10: =C10*1.1 -> 0 | K10: =D10*1.1 -> 0 | L10: =E10*1.1 -> 0 | M10: =F10*1.1 -> 0 | N10: =G10*1.1 -> 0
A11: AZ | B11: 0 | C11: 0 | D11: 0 | E11: 0 | F11: 0 | G11: 0 | I11: =B11*1.1 -> 0 | J11: =C11*1.1 -> 0 | K11: =D11*1.1 -> 0 | L11: =E11*1.1 -> 0 | M11: =F11*1.1 -> 0 | N11: =G11*1.1 -> 0
A12: CA | B12: 0 | C12: 0 | D12: 0 | E12: 0 | F12: 0 | G12: 0 | I12: =B12*1.1 -> 0 | J12: =C12*1.1 -> 0 | K12: =D12*1.1 -> 0 | L12: =E12*1.1 -> 0 | M12: =F12*1.1 -> 0 | N12: =G12*1.1 -> 0
A13: CT | B13: 0 | C13: 0 | D13: 0 | E13: 0 | F13: 0 | G13: 0 | I13: =B13*1.1 -> 0 | J13: =C13*1.1 -> 0 | K13: =D13*1.1 -> 0 | L13: =E13*1.1 -> 0 | M13: =F13*1.1 -> 0 | N13: =G13*1.1 -> 0
A14: CO | B14: 0 | C14: 0 | D14: 0 | E14: 0 | F14: 0 | G14: 0 | I14: =B14*1.1 -> 0 | J14: =C14*1.1 -> 0 | K14: =D14*1.1 -> 0 | L14: =E14*1.1 -> 0 | M14: =F14*1.1 -> 0 | N14: =G14*1.1 -> 0
A15: DC | B15: 0 | C15: 0 | D15: 0 | E15: 0 | F15: 0 | G15: 0 | I15: =B15*1.1 -> 0 | J15: =C15*1.1 -> 0 | K15: =D15*1.1 -> 0 | L15: =E15*1.1 -> 0 | M15: =F15*1.1 -> 0 | N15: =G15*1.1 -> 0
A16: DE | B16: 0 | C16: 0 | D16: 0 | E16: 0 | F16: 0 | G16: 0 | I16: =B16*1.1 -> 0 | J16: =C16*1.1 -> 0 | K16: =D16*1.1 -> 0 | L16: =E16*1.1 -> 0 | M16: =F16*1.1 -> 0 | N16: =G16*1.1 -> 0
... A62: WY | B62: 0 | C62: 0 | D62: 0 | E62: 0 | F62: 0 | G62: 0 | I62: =B62*1.1 -> 0 | J62: =C62*1.1 -> 0 | K62: =D62*1.1 -> 0 | L62: =E62*1.1 -> 0 | M62: =F62*1.1 -> 0 | N62: =G62*1.1 -> 0
A63: Average | B63: =AVERAGE(B5:G62) -> 0
A65: CLIN 4002 IME examination
B66: Tier 1 (Base Price) | I66: Tier 2 (Incentive Price)
A67: State/Location | B67: Orthopedic surgery Price per exam | C67: Pulmonary Medicine Price Per exam | D67: Otolaryngology Price per exam | E67: Neurology price per exam | F67: Psychiatry Price per exam | G67: Other Specialists price per exam | I67: Orthopedic surgery Price per exam | J67: Pulmonary Medicine Price Per exam | K67: Otolaryngology Price per exam | L67: Neurology price per exam | M67: Psychiatry Price per exam | N67: Other Specialists price per exam
A68: Puerto Rico | B68: 0 | C68: 0 | D68: 0 | E68: 0 | F68: 0 | G68: 0 | I68: =B68*1.1 -> 0 | J68: =C68*1.1 -> 0 | K68: =D68*1.1 -> 0 | L68: =E68*1.1 -> 0 | M68: =F68*1.1 -> 0 | N68: =G68*1.1 -> 0
A69: Virgin Islands | B69: 0 | C69: 0 | D69: 0 | E69: 0 | F69: 0 | G69: 0 | I69: =B69*1.1 -> 0 | J69: =C69*1.1 -> 0 | K69: =D69*1.1 -> 0 | L69: =E69*1.1 -> 0 | M69: =F69*1.1 -> 0 | N69: =G69*1.1 -> 0
A70: All other Territories or Possessions | B70: 0 | C70: 0 | D70: 0 | E70: 0 | F70: 0 | G70: 0 | I70: =B70*1.1 -> 0 | J70: =C70*1.1 -> 0 | K70: =D70*1.1 -> 0 | L70: =E70*1.1 -> 0 | M70: =F70*1.1 -> 0 | N70: =G70*1.1 -> 0
A71: AK | B71: 0 | C71: 0 | D71: 0 | E71: 0 | F71: 0 | G71: 0 | I71: =B71*1.1 -> 0 | J71: =C71*1.1 -> 0 | K71: =D71*1.1 -> 0 | L71: =E71*1.1 -> 0 | M71: =F71*1.1 -> 0 | N71: =G71*1.1 -> 0
A72: AL | B72: 0 | C72: 0 | D72: 0 | E72: 0 | F72: 0 | G72: 0 | I72: =B72*1.1 -> 0 | J72: =C72*1.1 -> 0 | K72: =D72*1.1 -> 0 | L72: =E72*1.1 -> 0 | M72: =F72*1.1 -> 0 | N72: =G72*1.1 -> 0
A73: AR | B73: 0 | C73: 0 | D73: 0 | E73: 0 | F73: 0 | G73: 0 | I73: =B73*1.1 -> 0 | J73: =C73*1.1 -> 0 | K73: =D73*1.1 -> 0 | L73: =E73*1.1 -> 0 | M73: =F73*1.1 -> 0 | N73: =G73*1.1 -> 0
A74: AZ | B74: 0 | C74: 0 | D74: 0 | E74: 0 | F74: 0 | G74: 0 | I74: =B74*1.1 -> 0 | J74: =C74*1.1 -> 0 | K74: =D74*1.1 -> 0 | L74: =E74*1.1 -> 0 | M74: =F74*1.1 -> 0 | N74: =G74*1.1 -> 0
A75: CA | B75: 0 | C75: 0 | D75: 0 | E75: 0 | F75: 0 | G75: 0 | I75: =B75*1.1 -> 0 | J75: =C75*1.1 -> 0 | K75: =D75*1.1 -> 0 | L75: =E75*1.1 -> 0 | M75: =F75*1.1 -> 0 | N75: =G75*1.1 -> 0
A76: CT | B76: 0 | C76: 0 | D76: 0 | E76: 0 | F76: 0 | G76: 0 | I76: =B76*1.1 -> 0 | J76: =C76*1.1 -> 0 | K76: =D76*1.1 -> 0 | L76: =E76*1.1 -> 0 | M76: =F76*1.1 -> 0 | N76: =G76*1.1 -> 0
A77: CO | B77: 0 | C77: 0 | D77: 0 | E77: 0 | F77: 0 | G77: 0 | I77: =B77*1.1 -> 0 | J77: =C77*1.1 -> 0 | K77: =D77*1.1 -> 0 | L77: =E77*1.1 -> 0 | M77: =F77*1.1 -> 0 | N77: =G77*1.1 -> 0
A78: DC | B78: 0 | C78: 0 | D78: 0 | E78: 0 | F78: 0 | G78: 0 | I78: =B78*1.1 -> 0 | J78: =C78*1.1 -> 0 | K78: =D78*1.1 -> 0 | L78: =E78*1.1 -> 0 | M78: =F78*1.1 -> 0 | N78: =G78*1.1 -> 0
A79: DE | B79: 0 | C79: 0 | D79: 0 | E79: 0 | F79: 0 | G79: 0 | I79: =B79*1.1 -> 0 | J79: =C79*1.1 -> 0 | K79: =D79*1.1 -> 0 | L79: =E79*1.1 -> 0 | M79: =F79*1.1 -> 0 | N79: =G79*1.1 -> 0
... A125: WY | B125: 0 | C125: 0 | D125: 0 | E125: 0 | F125: 0 | G125: 0 | I125: =B125*1.1 -> 0 | J125: =C125*1.1 -> 0 | K125: =D125*1.1 -> 0 | L125: =E125*1.1 -> 0 | M125: =F125*1.1 -> 0 | N125: =G125*1.1 -> 0
A126: Average | B126: =AVERAGE(B68:G125) -> 0
B130: Tier 1 (Base Price) | D130: Tier 2 (Incentive Price)
A132: CLIN 4004 Supplemental Reports | B132: Price per report
A133: CLIN 4004 Supplemental Reports | B133: 0 | D133: =B133*1.1 -> 0
A136: CLIN 4005 File Review Surgical | B136: Price per review
A137: CLIN 4005 File Review Surgical (0-100 Pages) | B137: 0 | D137: =B137*1.1 -> 0
...

Sheet Summary
B1: RFP 1605C3-25-R-00007 - Directed Medical Services for the Division of Federal Employees Compensation
B2: Note the volumes listed in the Quantity column represent estimated annual volumes and are for evaluations only.
B4: Base Period:
B5: DESCRIPTION OF WORK | C5: Quantity | D5: UOM | E5: Average Price per Unit | F5: SUBTOTALS
A7: 0001 | B7: Medical Second Opinion and Examination Services | C7: 16560 | D7: Case | E7: ='Base Period'!B63 -> 0 | F7: =SUM(C7*E7) -> 0
A8: 0002 | B8: IME | C8: 1162 | D8: Case | E8: ='Base Period'!B126 -> 0 | F8: =SUM(C8*E8) -> 0
A9: 0003 | B9: Schedule Award/Impairment Ratings | C9: 2315 | D9: Case | E9: ='Base Period'!B63 -> 0 | F9: =E9*C9 -> 0
A10: 0004 | B10: Supplemental Reports | C10: 1500 | D10: Each | E10: ='Base Period'!B133 -> 0 | F10: =SUM(C10*E10) -> 0
A11: 0005 | B11: File Review Surgical | C11: 7004 | D11: Each | E11: ='Base Period'!B142 -> 0 | F11: =SUM(C11*E11) -> 0
A12: 0006 | B12: File Review Impairment Rating, IME File Review | C12: 10102 | D12: Case | E12: ='Base Period'!B150 -> 0 | F12: =SUM(C12*E12) -> 0
A13: 0007 | B13: File Review Other | C13: 1236 | D13: Case | E13: ='Base Period'!B158 -> 0 | F13: =SUM(C13*E13) -> 0
A14: 0008 | B14: Travel/Transportation* (NTE ceiling) | C14: 1 | D14: Fee | E14: Pay Per FTR mileage reimbursement rates | F14: 379940
A15: 0009 | B15: Other Direct Cost - Canceled Appointments**, Interpretive Services*, Diagnostic Tests* (NTE Ceiling) | C15: 1 | D15: Fee | E15: Billed/Paid at the fixed rate of $200 Per OWCP CPT Code | F15: 3000000
C17: Sub-Total Base Period | F17: =SUM(F7:F15) -> 3379940
B19: Option Period One:
B20: DESCRIPTION OF WORK | C20: Quantity | D20: UOM | E20: Average Price per Unit | F20: SUBTOTALS
A22: 1001 | B22: Medical Second Opinion and Examination Services | C22: 16560 | D22: Case | E22: ='Option Period 1'!B63 -> 0 | F22: =SUM(C22*E22) -> 0
A23: 1002 | B23: IME | C23: 1162 | D23: Case | E23: ='Option Period 1'!B126 -> 0 | F23: =SUM(C23*E23) -> 0
A24: 1003 | B24: Schedule Award/Impairment Ratings | C24: 2315 | D24: Case | E24: ='Option Period 1'!B63 -> 0 | F24: =SUM(C24*E24) -> 0
A25: 1004 | B25: Supplemental Reports | C25: 1500 | D25: Each | E25: ='Option Period 1'!B133 -> 0 | F25: =SUM(C25*E25) -> 0
A26: 1005 | B26: File Review Surgical | C26: 7004 | D26: Each | E26: ='Option Period 1'!B142 -> 0 | F26: =SUM(C26*E26) -> 0
A27: 1006 | B27: File Review Impairment Rating, IME File Review | C27: 10102 | D27: Case | E27: ='Option Period 1'!B150 -> 0 | F27: =SUM(C27*E27) -> 0
A28: 1007 | B28: File Review Other | C28: 1236 | D28: Case | E28: ='Option Period 1'!B158 -> 0 | F28: =SUM(C28*E28) -> 0
A29: 1008 | B29: Travel/Transportation* (NTE ceiling) | C29: 1 | D29: Fee | E29: Pay Per FTR mileage reimbursement rates | F29: 379940
A30: 1009 | B30: Other Direct Cost - Canceled Appointments**, Interpretive Services*, Diagnostic Tests* (NTE Ceiling) | C30: 1 | D30: Fee | E30: =E15 -> Billed/Paid at the fixed rate of $200 Per OWCP CPT Code | F30: 3000000
C32: Sub-Total Option Period One | F32: =SUM(F22:F30) -> 3379940
B34: Option Period Two:
B35: DESCRIPTION OF WORK | C35: Quantity | D35: UOM | E35: Average Price per Unit | F35: SUBTOTALS
A37: 2001 | B37: Medical Second Opinion and Examination Services | C37: 16560 | D37: Case | E37: ='Option Period 2'!B63 -> 0 | F37: =E37*C37 -> 0
A38: 2002 | B38: IME | C38: 1162 | D38: Case | E38: ='Option Period 2'!B126 -> 0 | F38: =E38*C38 -> 0
A39: 2003 | B39: Schedule Award/Impairment Ratings | C39: 2315 | D39: Case | E39: ='Option Period 2'!B63 -> 0 | F39: =E39*C39 -> 0
A40: 2004 | B40: Supplemental Reports | C40: 1500 | D40: Each | E40: ='Option Period 2'!B133 -> 0 | F40: =E40*C40 -> 0
A41: 2005 | B41: File Review Surgical | C41: 7004 | D41: Each | E41: ='Option Period 2'!B142 -> 0 | F41: =E41*C41 -> 0
A42: 2006 | B42: File Review Impairment Rating, IME File Review | C42: 10102 | D42: Case | E42: ='Option Period 2'!B150 -> 0 | F42: =E42*C42 -> 0
A43: 2007 | B43: File Review Other | C43: 1236 | D43: Case | E43: ='Option Period 2'!B158 -> 0 | F43: =E43*C43 -> 0
A44: 2008 | B44: Travel/Transportation* (NTE ceiling) | C44: 1 | D44: Fee | E44: Pay Per FTR mileage reimbursement rates | F44: 379940
A45: 2009 | B45: Other Direct Cost - Canceled Appointments**, Interpretive Services*, Diagnostic Tests* (NTE Ceiling) | C45: 1 | D45: Fee | E45: =E30 -> Billed/Paid at the fixed rate of $200 Per OWCP CPT Code | F45: 3000000
C47: Sub-Total Option Period Two | F47: =SUM(F37:F46) -> 3379940
B49: Option Period Three:
B50: DESCRIPTION OF WORK | C50: Quantity | D50: UOM | E50: Average Price per Unit | F50: SUBTOTALS
...
