Workbook

Sheet Base Option
A1: Roofing Contract
A2: Attachment J-0200000-05
A3: Exhibit Line Item Numbers
A4: Base Option
A5: Solicitation/Contract No.: N40085-26-D-XXXX
B6: Philadelphia Roofing Contract
A7: ELIN Number | B7: Supplies/Services | C7: Est. Quantity | D7: Unit | F7: Unit Price | G7: Total
B8: ROOF DECKS
A9: A0001 | B9: Remove existing metal roof decks (ALL OR PARTIAL) and replace with new steel roof decking, shall include all closures and accessories. | C9: 3 | D9: SQ | E9: X | G9: =F9*C9 -> 0
B10: Remove existing wood roof deck and replace with new wood decking
A11: A0002 | B11: 1" nominal T & G (treated) | C11: 40 | D11: BF | E11: X | G11: =F11*C11 -> 0
A12: A0003 | B12: 2" nominal T & G (treated) | C12: 40 | D12: BF | E12: X | G12: =F12*C12 -> 0
A13: A0004 | B13: 3/4" plywood | C13: 40 | D13: SF | E13: X | G13: =F13*C13 -> 0
A14: A0005 | B14: 1/2" plywood | C14: 25 | D14: SF | E14: X | G14: =F14*C14 -> 0
B15: ROOF INSULATION
B16: Remove and replace rigid roof insulation in conjunction with roofing systems specified herein. Average 1”x12”x12”
A17: A0006 | B17: Remove and replace polyisocyanurate tapered insulation panels | C17: 10 | D17: BF | E17: X | G17: =F17*C17 -> 0
A18: A0007 | B18: Remove and replace tapered roof insulation | C18: 10 | D18: BF | E18: X | G18: =F18*C18 -> 0
A19: A0008 | B19: Remove and replace vapor barrier in conjunction with built up roofing system | C19: 10 | D19: SQ | E19: X | G19: =F19*C19 -> 0
A20: A0009 | B20: Remove and replace resin sized building paper (5 lb.) | C20: 5 | D20: SQ | E20: X | G20: =F20*C20 -> 0
A21: A0010 | B21: Remove existing cants and replace with new fiberboard cants 4 x 4 | C21: 30 | D21: LF | E21: X | G21: =F21*C21 -> 0
A22: A0011 | B22: Remove existing cants and replace with new treated wood cants 4 x 4 | C22: 30 | D22: LF | E22: X | G22: =F22*C22 -> 0
A23: A0012 | B23: Remove existing Nailers and replace with new treated 2" x 6" wood | C23: 100 | D23: BF | E23: X | G23: =F23*C23 -> 0
B24: SHINGLED ROOF SYSTEMS
B25: Remove existing composition shingles and replace with new composition shingles, shall include starter
A26: A0013 | B26: Twenty Five Year (3 tab ) | C26: 10 | D26: SQ | E26: X | G26: =F26*C26 -> 0
A27: A0014 | B27: Thirty Year (architectural) | C27: 6 | D27: SQ | E27: X | G27: =F27*C27 -> 0
A28: A0015 | B28: Forty Year (architectural) | C28: 6 | D28: SQ | E28: X | G28: =F28*C28 -> 0
A29: A0016 | B29: Remove and dispose of existing composition shingles (all types)(where new shingles are not going to be installed) | C29: 6 | D29: SQ | E29: X | G29: =F29*C29 -> 0
A30: A0017 | B30: Remove and dispose of existing slate shingles. | C30: 6 | D30: SQ | E30: X | G30: =F30*C30 -> 0
A31: A0018 | B31: Remove and re-install existing slate shingles (All or Partial) | C31: 2 | D31: SQ | E31: X | G31: =F31*C31 -> 0
A32: A0019 | B32: Install new slate shingles (Weathering green, Vermont)(All or Partial) | C32: 3 | D32: SQ | E32: X | G32: =F32*C32 -> 0
A33: A0020 | B33: Install new slate shingles (Buckingham)(All or Partial) | C33: 3 | D33: SQ | E33: X | G33: =F33*C33 -> 0
B34: Remove existing preformed metal (All or Partial) roofing and replace with new preformed metal roofing
A35: A0021 | B35: Coated steel | C35: 20 | D35: SQ | E35: X | G35: =F35*C35 -> 0
A36: A0022 | B36: Coated aluminum | C36: 20 | D36: SQ | E36: X | G36: =F36*C36 -> 0
A37: A0023 | B37: Left Blank Intentionally
B38: Field paint roof mounted equipment
A39: A0024 | B39: Up to 25 SF X in surface area X | C39: 12 | D39: SF | E39: X | G39: =F39*C39 -> 0
A40: A0025 | B40: Over 25 SF X in surface area X | C40: 12 | D40: SF | E40: X | G40: =F40*C40 -> 0
...

Sheet Option Year 1
A1: Roofing Contract
A2: Attachment J-0200000-05
A3: Exhibit Line Item Numbers
A4: Option Year 1
A5: Solicitation/Contract No.: N40085-26-D-XXXX
B6: Philadelphia Roofing Contract
A7: ELIN Number | B7: Supplies/Services | C7: Est. Quantity | D7: Unit | F7: Unit Price | G7: Total
B8: ROOF DECKS
A9: B0001 | B9: Remove existing metal roof decks (ALL OR PARTIAL) and replace with new steel roof decking, shall include all closures and accessories. | C9: 3 | D9: SQ | E9: X | F9: ='Base Option'!F9+'Base Option'!F9*3% -> 0 | G9: =F9*C9 -> 0
B10: Remove existing wood roof deck and replace with new wood decking
A11: B0002 | B11: 1" nominal T & G (treated) | C11: 40 | D11: BF | E11: X | F11: ='Base Option'!F11+'Base Option'!F11*3% -> 0 | G11: =F11*C11 -> 0
A12: B0003 | B12: 2" nominal T & G (treated) | C12: 40 | D12: BF | E12: X | F12: ='Base Option'!F12+'Base Option'!F12*3% -> 0 | G12: =F12*C12 -> 0
A13: B0004 | B13: 3/4" plywood | C13: 40 | D13: SF | E13: X | F13: ='Base Option'!F13+'Base Option'!F13*3% -> 0 | G13: =F13*C13 -> 0
A14: B0005 | B14: 1/2" plywood | C14: 25 | D14: SF | E14: X | F14: ='Base Option'!F14+'Base Option'!F14*3% -> 0 | G14: =F14*C14 -> 0
B15: ROOF INSULATION
B16: Remove and replace rigid roof insulation in conjunction with roofing systems specified herein. Average 1”x12”x12”
A17: B0006 | B17: Remove and replace polyisocyanurate tapered insulation panels | C17: 10 | D17: BF | E17: X | F17: ='Base Option'!F17+'Base Option'!F17*3% -> 0 | G17: =F17*C17 -> 0
A18: B0007 | B18: Remove and replace tapered roof insulation | C18: 10 | D18: BF | E18: X | F18: ='Base Option'!F18+'Base Option'!F18*3% -> 0 | G18: =F18*C18 -> 0
A19: B0008 | B19: Remove and replace vapor barrier in conjunction with built up roofing system | C19: 10 | D19: SQ | E19: X | F19: ='Base Option'!F19+'Base Option'!F19*3% -> 0 | G19: =F19*C19 -> 0
A20: B0009 | B20: Remove and replace resin sized building paper (5 lb.) | C20: 5 | D20: SQ | E20: X | F20: ='Base Option'!F20+'Base Option'!F20*3% -> 0 | G20: =F20*C20 -> 0
A21: B0010 | B21: Remove existing cants and replace with new fiberboard cants 4 x 4 | C21: 30 | D21: LF | E21: X | F21: ='Base Option'!F21+'Base Option'!F21*3% -> 0 | G21: =F21*C21 -> 0
A22: B0011 | B22: Remove existing cants and replace with new treated wood cants 4 x 4 | C22: 30 | D22: LF | E22: X | F22: ='Base Option'!F22+'Base Option'!F22*3% -> 0 | G22: =F22*C22 -> 0
A23: B0012 | B23: Remove existing Nailers and replace with new treated 2" x 6" wood | C23: 100 | D23: BF | E23: X | F23: ='Base Option'!F23+'Base Option'!F23*3% -> 0 | G23: =F23*C23 -> 0
B24: SHINGLED ROOF SYSTEMS
B25: Remove existing composition shingles and replace with new composition shingles, shall include starter
A26: B0013 | B26: Twenty Five Year (3 tab ) | C26: 10 | D26: SQ | E26: X | F26: ='Base Option'!F26+'Base Option'!F26*3% -> 0 | G26: =F26*C26 -> 0
A27: B0014 | B27: Thirty Year (architectural) | C27: 6 | D27: SQ | E27: X | F27: ='Base Option'!F27+'Base Option'!F27*3% -> 0 | G27: =F27*C27 -> 0
A28: B0015 | B28: Forty Year (architectural) | C28: 6 | D28: SQ | E28: X | F28: ='Base Option'!F28+'Base Option'!F28*3% -> 0 | G28: =F28*C28 -> 0
A29: B0016 | B29: Remove and dispose of existing composition shingles (all types)(where new shingles are not going to be installed) | C29: 6 | D29: SQ | E29: X | F29: ='Base Option'!F29+'Base Option'!F29*3% -> 0 | G29: =F29*C29 -> 0
A30: B0017 | B30: Remove and dispose of existing slate shingles. | C30: 6 | D30: SQ | E30: X | F30: ='Base Option'!F30+'Base Option'!F30*3% -> 0 | G30: =F30*C30 -> 0
A31: B0018 | B31: Remove and re-install existing slate shingles (All or Partial) | C31: 2 | D31: SQ | E31: X | F31: ='Base Option'!F31+'Base Option'!F31*3% -> 0 | G31: =F31*C31 -> 0
A32: B0019 | B32: Install new slate shingles (Weathering green, Vermont)(All or Partial) | C32: 3 | D32: SQ | E32: X | F32: ='Base Option'!F32+'Base Option'!F32*3% -> 0 | G32: =F32*C32 -> 0
A33: B0020 | B33: Install new slate shingles (Buckingham)(All or Partial) | C33: 3 | D33: SQ | E33: X | F33: ='Base Option'!F33+'Base Option'!F33*3% -> 0 | G33: =F33*C33 -> 0
B34: Remove existing preformed metal (All or Partial) roofing and replace with new preformed metal roofing
A35: B0021 | B35: Coated steel | C35: 20 | D35: SQ | E35: X | F35: ='Base Option'!F35+'Base Option'!F35*3% -> 0 | G35: =F35*C35 -> 0
A36: B0022 | B36: Coated aluminum | C36: 20 | D36: SQ | E36: X | F36: ='Base Option'!F36+'Base Option'!F36*3% -> 0 | G36: =F36*C36 -> 0
A37: B0023 | B37: Left Blank Intentionally
B38: Field paint roof mounted equipment
A39: B0024 | B39: Up to 25 SF X in surface area X | C39: 12 | D39: SF | E39: X | F39: ='Base Option'!F39+'Base Option'!F39*3% -> 0 | G39: =F39*C39 -> 0
A40: B0025 | B40: Over 25 SF X in surface area X | C40: 12 | D40: SF | E40: X | F40: ='Base Option'!F40+'Base Option'!F40*3% -> 0 | G40: =F40*C40 -> 0
...

Sheet Option Year 2
A1: Roofing Contract
A2: Attachment J-0200000-05
A3: Exhibit Line Item Numbers
A4: Option Year 2
A5: Solicitation/Contract No.: N40085-26-D-XXXX
B6: Philadelphia Roofing Contract
A7: ELIN Number | B7: Supplies/Services | C7: Est. Quantity | D7: Unit | F7: Unit Price | G7: Total
B8: ROOF DECKS
A9: C0001 | B9: Remove existing metal roof decks (ALL OR PARTIAL) and replace with new steel roof decking, shall include all closures and accessories. | C9: 3 | D9: SQ | E9: X | F9: ='Option Year 1'!F9+'Option Year 1'!F9*3% -> 0 | G9: =F9*C9 -> 0
B10: Remove existing wood roof deck and replace with new wood decking
A11: C0002 | B11: 1" nominal T & G (treated) | C11: 40 | D11: BF | E11: X | F11: ='Option Year 1'!F11+'Option Year 1'!F11*3% -> 0 | G11: =F11*C11 -> 0
A12: C0003 | B12: 2" nominal T & G (treated) | C12: 40 | D12: BF | E12: X | F12: ='Option Year 1'!F12+'Option Year 1'!F12*3% -> 0 | G12: =F12*C12 -> 0
A13: C0004 | B13: 3/4" plywood | C13: 40 | D13: SF | E13: X | F13: ='Option Year 1'!F13+'Option Year 1'!F13*3% -> 0 | G13: =F13*C13 -> 0
A14: C0005 | B14: 1/2" plywood | C14: 25 | D14: SF | E14: X | F14: ='Option Year 1'!F14+'Option Year 1'!F14*3% -> 0 | G14: =F14*C14 -> 0
B15: ROOF INSULATION | F15: ='Option Year 1'!F15+'Option Year 1'!F15*3% -> 0
B16: Remove and replace rigid roof insulation in conjunction with roofing systems specified herein. Average 1”x12”x12” | F16: ='Option Year 1'!F16+'Option Year 1'!F16*3% -> 0
A17: C0006 | B17: Remove and replace polyisocyanurate tapered insulation panels | C17: 10 | D17: BF | E17: X | F17: ='Option Year 1'!F17+'Option Year 1'!F17*3% -> 0 | G17: =F17*C17 -> 0
A18: C0007 | B18: Remove and replace tapered roof insulation | C18: 10 | D18: BF | E18: X | F18: ='Option Year 1'!F18+'Option Year 1'!F18*3% -> 0 | G18: =F18*C18 -> 0
A19: C0008 | B19: Remove and replace vapor barrier in conjunction with built up roofing system | C19: 10 | D19: SQ | E19: X | F19: ='Option Year 1'!F19+'Option Year 1'!F19*3% -> 0 | G19: =F19*C19 -> 0
A20: C0009 | B20: Remove and replace resin sized building paper (5 lb.) | C20: 5 | D20: SQ | E20: X | F20: ='Option Year 1'!F20+'Option Year 1'!F20*3% -> 0 | G20: =F20*C20 -> 0
A21: C0010 | B21: Remove existing cants and replace with new fiberboard cants 4 x 4 | C21: 30 | D21: LF | E21: X | F21: ='Option Year 1'!F21+'Option Year 1'!F21*3% -> 0 | G21: =F21*C21 -> 0
A22: C0011 | B22: Remove existing cants and replace with new treated wood cants 4 x 4 | C22: 30 | D22: LF | E22: X | F22: ='Option Year 1'!F22+'Option Year 1'!F22*3% -> 0 | G22: =F22*C22 -> 0
A23: C0012 | B23: Remove existing Nailers and replace with new treated 2" x 6" wood | C23: 100 | D23: BF | E23: X | F23: ='Option Year 1'!F23+'Option Year 1'!F23*3% -> 0 | G23: =F23*C23 -> 0
B24: SHINGLED ROOF SYSTEMS | F24: ='Option Year 1'!F24+'Option Year 1'!F24*3% -> 0
B25: Remove existing composition shingles and replace with new composition shingles, shall include starter | F25: ='Option Year 1'!F25+'Option Year 1'!F25*3% -> 0
A26: C0013 | B26: Twenty Five Year (3 tab ) | C26: 10 | D26: SQ | E26: X | F26: ='Option Year 1'!F26+'Option Year 1'!F26*3% -> 0 | G26: =F26*C26 -> 0
A27: C0014 | B27: Thirty Year (architectural) | C27: 6 | D27: SQ | E27: X | F27: ='Option Year 1'!F27+'Option Year 1'!F27*3% -> 0 | G27: =F27*C27 -> 0
A28: C0015 | B28: Forty Year (architectural) | C28: 6 | D28: SQ | E28: X | F28: ='Option Year 1'!F28+'Option Year 1'!F28*3% -> 0 | G28: =F28*C28 -> 0
A29: C0016 | B29: Remove and dispose of existing composition shingles (all types)(where new shingles are not going to be installed) | C29: 6 | D29: SQ | E29: X | F29: ='Option Year 1'!F29+'Option Year 1'!F29*3% -> 0 | G29: =F29*C29 -> 0
A30: C0017 | B30: Remove and dispose of existing slate shingles. | C30: 6 | D30: SQ | E30: X | F30: ='Option Year 1'!F30+'Option Year 1'!F30*3% -> 0 | G30: =F30*C30 -> 0
A31: C0018 | B31: Remove and re-install existing slate shingles (All or Partial) | C31: 2 | D31: SQ | E31: X | F31: ='Option Year 1'!F31+'Option Year 1'!F31*3% -> 0 | G31: =F31*C31 -> 0
A32: C0019 | B32: Install new slate shingles (Weathering green, Vermont)(All or Partial) | C32: 3 | D32: SQ | E32: X | F32: ='Option Year 1'!F32+'Option Year 1'!F32*3% -> 0 | G32: =F32*C32 -> 0
A33: C0020 | B33: Install new slate shingles (Buckingham)(All or Partial) | C33: 3 | D33: SQ | E33: X | F33: ='Option Year 1'!F33+'Option Year 1'!F33*3% -> 0 | G33: =F33*C33 -> 0
B34: Remove existing preformed metal (All or Partial) roofing and replace with new preformed metal roofing | F34: ='Option Year 1'!F34+'Option Year 1'!F34*3% -> 0
A35: C0021 | B35: Coated steel | C35: 20 | D35: SQ | E35: X | F35: ='Option Year 1'!F35+'Option Year 1'!F35*3% -> 0 | G35: =F35*C35 -> 0
A36: C0022 | B36: Coated aluminum | C36: 20 | D36: SQ | E36: X | F36: ='Option Year 1'!F36+'Option Year 1'!F36*3% -> 0 | G36: =F36*C36 -> 0
A37: C0023 | B37: Left Blank Intentionally
B38: Field paint roof mounted equipment | F38: ='Option Year 1'!F38+'Option Year 1'!F38*3% -> 0
A39: C0024 | B39: Up to 25 SF X in surface area X | C39: 12 | D39: SF | E39: X | F39: ='Option Year 1'!F39+'Option Year 1'!F39*3% -> 0 | G39: =F39*C39 -> 0
A40: C0025 | B40: Over 25 SF X in surface area X | C40: 12 | D40: SF | E40: X | F40: ='Option Year 1'!F40+'Option Year 1'!F40*3% -> 0 | G40: =F40*C40 -> 0
...

Sheet Option Year 3
A1: Roofing Contract
A2: Attachment J-0200000-05
A3: Exhibit Line Item Numbers
A4: Option Year 3
A5: Solicitation/Contract No.: N40085-26-D-XXXX
B6: Philadelphia Roofing Contract
A7: ELIN Number | B7: Supplies/Services | C7: Est. Quantity | D7: Unit | F7: Unit Price | G7: Total
B8: ROOF DECKS
A9: D0001 | B9: Remove existing metal roof decks (ALL OR PARTIAL) and replace with new steel roof decking, shall include all closures and accessories. | C9: 3 | D9: SQ | E9: X | F9: ='Option Year 2'!F9+'Option Year 2'!F9*3% -> 0 | G9: =F9*C9 -> 0
B10: Remove existing wood roof deck and replace with new wood decking
A11: D0002 | B11: 1" nominal T & G (treated) | C11: 40 | D11: BF | E11: X | F11: ='Option Year 2'!F11+'Option Year 2'!F11*3% -> 0 | G11: =F11*C11 -> 0
A12: D0003 | B12: 2" nominal T & G (treated) | C12: 40 | D12: BF | E12: X | F12: ='Option Year 2'!F12+'Option Year 2'!F12*3% -> 0 | G12: =F12*C12 -> 0
A13: D0004 | B13: 3/4" plywood | C13: 40 | D13: SF | E13: X | F13: ='Option Year 2'!F13+'Option Year 2'!F13*3% -> 0 | G13: =F13*C13 -> 0
A14: D0005 | B14: 1/2" plywood | C14: 25 | D14: SF | E14: X | F14: ='Option Year 2'!F14+'Option Year 2'!F14*3% -> 0 | G14: =F14*C14 -> 0
B15: ROOF INSULATION | F15: ='Option Year 2'!F15+'Option Year 2'!F15*3% -> 0
B16: Remove and replace rigid roof insulation in conjunction with roofing systems specified herein. Average 1”x12”x12” | F16: ='Option Year 2'!F16+'Option Year 2'!F16*3% -> 0
A17: D0006 | B17: Remove and replace polyisocyanurate tapered insulation panels | C17: 10 | D17: BF | E17: X | F17: ='Option Year 2'!F17+'Option Year 2'!F17*3% -> 0 | G17: =F17*C17 -> 0
A18: D0007 | B18: Remove and replace tapered roof insulation | C18: 10 | D18: BF | E18: X | F18: ='Option Year 2'!F18+'Option Year 2'!F18*3% -> 0 | G18: =F18*C18 -> 0
A19: D0008 | B19: Remove and replace vapor barrier in conjunction with built up roofing system | C19: 10 | D19: SQ | E19: X | F19: ='Option Year 2'!F19+'Option Year 2'!F19*3% -> 0 | G19: =F19*C19 -> 0
A20: D0009 | B20: Remove and replace resin sized building paper (5 lb.) | C20: 5 | D20: SQ | E20: X | F20: ='Option Year 2'!F20+'Option Year 2'!F20*3% -> 0 | G20: =F20*C20 -> 0
A21: D0010 | B21: Remove existing cants and replace with new fiberboard cants 4 x 4 | C21: 30 | D21: LF | E21: X | F21: ='Option Year 2'!F21+'Option Year 2'!F21*3% -> 0 | G21: =F21*C21 -> 0
A22: D0011 | B22: Remove existing cants and replace with new treated wood cants 4 x 4 | C22: 30 | D22: LF | E22: X | F22: ='Option Year 2'!F22+'Option Year 2'!F22*3% -> 0 | G22: =F22*C22 -> 0
A23: D0012 | B23: Remove existing Nailers and replace with new treated 2" x 6" wood | C23: 100 | D23: BF | E23: X | F23: ='Option Year 2'!F23+'Option Year 2'!F23*3% -> 0 | G23: =F23*C23 -> 0
B24: SHINGLED ROOF SYSTEMS | F24: ='Option Year 2'!F24+'Option Year 2'!F24*3% -> 0
B25: Remove existing composition shingles and replace with new composition shingles, shall include starter | F25: ='Option Year 2'!F25+'Option Year 2'!F25*3% -> 0
A26: D0013 | B26: Twenty Five Year (3 tab ) | C26: 10 | D26: SQ | E26: X | F26: ='Option Year 2'!F26+'Option Year 2'!F26*3% -> 0 | G26: =F26*C26 -> 0
A27: D0014 | B27: Thirty Year (architectural) | C27: 6 | D27: SQ | E27: X | F27: ='Option Year 2'!F27+'Option Year 2'!F27*3% -> 0 | G27: =F27*C27 -> 0
A28: D0015 | B28: Forty Year (architectural) | C28: 6 | D28: SQ | E28: X | F28: ='Option Year 2'!F28+'Option Year 2'!F28*3% -> 0 | G28: =F28*C28 -> 0
A29: D0016 | B29: Remove and dispose of existing composition shingles (all types)(where new shingles are not going to be installed) | C29: 6 | D29: SQ | E29: X | F29: ='Option Year 2'!F29+'Option Year 2'!F29*3% -> 0 | G29: =F29*C29 -> 0
A30: D0017 | B30: Remove and dispose of existing slate shingles. | C30: 6 | D30: SQ | E30: X | F30: ='Option Year 2'!F30+'Option Year 2'!F30*3% -> 0 | G30: =F30*C30 -> 0
A31: D0018 | B31: Remove and re-install existing slate shingles (All or Partial) | C31: 2 | D31: SQ | E31: X | F31: ='Option Year 2'!F31+'Option Year 2'!F31*3% -> 0 | G31: =F31*C31 -> 0
A32: D0019 | B32: Install new slate shingles (Weathering green, Vermont)(All or Partial) | C32: 3 | D32: SQ | E32: X | F32: ='Option Year 2'!F32+'Option Year 2'!F32*3% -> 0 | G32: =F32*C32 -> 0
A33: D0020 | B33: Install new slate shingles (Buckingham)(All or Partial) | C33: 3 | D33: SQ | E33: X | F33: ='Option Year 2'!F33+'Option Year 2'!F33*3% -> 0 | G33: =F33*C33 -> 0
B34: Remove existing preformed metal (All or Partial) roofing and replace with new preformed metal roofing | F34: ='Option Year 2'!F34+'Option Year 2'!F34*3% -> 0
A35: D0021 | B35: Coated steel | C35: 20 | D35: SQ | E35: X | F35: ='Option Year 2'!F35+'Option Year 2'!F35*3% -> 0 | G35: =F35*C35 -> 0
A36: D0022 | B36: Coated aluminum | C36: 20 | D36: SQ | E36: X | F36: ='Option Year 2'!F36+'Option Year 2'!F36*3% -> 0 | G36: =F36*C36 -> 0
A37: D0023
B38: Field paint roof mounted equipment | F38: ='Option Year 2'!F38+'Option Year 2'!F38*3% -> 0
A39: D0024 | B39: Up to 25 SF X in surface area X | C39: 12 | D39: SF | E39: X | F39: ='Option Year 2'!F39+'Option Year 2'!F39*3% -> 0 | G39: =F39*C39 -> 0
A40: D0025 | B40: Over 25 SF X in surface area X | C40: 12 | D40: SF | E40: X | F40: ='Option Year 2'!F40+'Option Year 2'!F40*3% -> 0 | G40: =F40*C40 -> 0
...

Sheet Option Year 4
A1: Roofing Contract
A2: Attachment J-0200000-05
A3: Exhibit Line Item Numbers
A4: Option Year 4
A5: Solicitation/Contract No.: N40085-26-D-XXXX
B6: Philadelphia Roofing Contract
A7: ELIN Number | B7: Supplies/Services | C7: Est. Quantity | D7: Unit | F7: Unit Price | G7: Total
B8: ROOF DECKS
A9: E0001 | B9: Remove existing metal roof decks (ALL OR PARTIAL) and replace with new steel roof decking, shall include all closures and accessories. | C9: 3 | D9: SQ | E9: X | G9: =F9*C9 -> 0
B10: Remove existing wood roof deck and replace with new wood decking
A11: E0002 | B11: 1" nominal T & G (treated) | C11: 40 | D11: BF | E11: X | G11: =F11*C11 -> 0
A12: E0003 | B12: 2" nominal T & G (treated) | C12: 40 | D12: BF | E12: X | G12: =F12*C12 -> 0
A13: E0004 | B13: 3/4" plywood | C13: 40 | D13: SF | E13: X | G13: =F13*C13 -> 0
A14: E0005 | B14: 1/2" plywood | C14: 25 | D14: SF | E14: X | G14: =F14*C14 -> 0
B15: ROOF INSULATION
B16: Remove and replace rigid roof insulation in conjunction with roofing systems specified herein. Average 1”x12”x12”
A17: E0006 | B17: Remove and replace polyisocyanurate tapered insulation panels | C17: 10 | D17: BF | E17: X | G17: =F17*C17 -> 0
A18: E0007 | B18: Remove and replace tapered roof insulation | C18: 10 | D18: BF | E18: X | G18: =F18*C18 -> 0
A19: E0008 | B19: Remove and replace vapor barrier in conjunction with built up roofing system | C19: 10 | D19: SQ | E19: X | G19: =F19*C19 -> 0
A20: E0009 | B20: Remove and replace resin sized building paper (5 lb.) | C20: 5 | D20: SQ | E20: X | G20: =F20*C20 -> 0
A21: E0010 | B21: Remove existing cants and replace with new fiberboard cants 4 x 4 | C21: 30 | D21: LF | E21: X | G21: =F21*C21 -> 0
A22: E0011 | B22: Remove existing cants and replace with new treated wood cants 4 x 4 | C22: 30 | D22: LF | E22: X | G22: =F22*C22 -> 0
A23: E0012 | B23: Remove existing Nailers and replace with new treated 2" x 6" wood | C23: 100 | D23: BF | E23: X | G23: =F23*C23 -> 0
B24: SHINGLED ROOF SYSTEMS
B25: Remove existing composition shingles and replace with new composition shingles, shall include starter
A26: E0013 | B26: Twenty Five Year (3 tab ) | C26: 10 | D26: SQ | E26: X | G26: =F26*C26 -> 0
A27: E0014 | B27: Thirty Year (architectural) | C27: 6 | D27: SQ | E27: X | G27: =F27*C27 -> 0
A28: E0015 | B28: Forty Year (architectural) | C28: 6 | D28: SQ | E28: X | G28: =F28*C28 -> 0
A29: E0016 | B29: Remove and dispose of existing composition shingles (all types)(where new shingles are not going to be installed) | C29: 6 | D29: SQ | E29: X | G29: =F29*C29 -> 0
A30: E0017 | B30: Remove and dispose of existing slate shingles. | C30: 6 | D30: SQ | E30: X | G30: =F30*C30 -> 0
A31: E0018 | B31: Remove and re-install existing slate shingles (All or Partial) | C31: 2 | D31: SQ | E31: X | G31: =F31*C31 -> 0
A32: E0019 | B32: Install new slate shingles (Weathering green, Vermont)(All or Partial) | C32: 3 | D32: SQ | E32: X | G32: =F32*C32 -> 0
A33: E0020 | B33: Install new slate shingles (Buckingham)(All or Partial) | C33: 3 | D33: SQ | E33: X | G33: =F33*C33 -> 0
B34: Remove existing preformed metal (All or Partial) roofing and replace with new preformed metal roofing
A35: E0021 | B35: Coated steel | C35: 20 | D35: SQ | E35: X | G35: =F35*C35 -> 0
A36: E0022 | B36: Coated aluminum | C36: 20 | D36: SQ | E36: X | G36: =F36*C36 -> 0
A37: E0023 | B37: Left Blank intentionally
B38: Field paint roof mounted equipment
A39: E0024 | B39: Up to 25 SF X in surface area X | C39: 12 | D39: SF | E39: X | G39: =F39*C39 -> 0
A40: E0025 | B40: Over 25 SF X in surface area X | C40: 12 | D40: SF | E40: X | G40: =F40*C40 -> 0
...

Sheet Summary
B2: Roofing Summary
B3: Base Option | D3: ='Base Option'!G368 -> 0
B4: Option Year 1 | D4: ='Option Year 1'!G368 -> 0
B5: Option Year 2 | D5: ='Option Year 2'!G368 -> 0
B6: Option year 3 | D6: ='Option Year 3'!G368 -> 0
B7: Option Year 4 | D7: ='Option Year 4'!G369 -> 0
B8: Total | D8: =D3+D4+D5+D6+D7 -> 0
