Workbook

Sheet Pricing Matrix
B1: TYPE OF CURRENCY: Euro
B2: Offeror Name: | D2: Orderin Year I | G2: 1 May 2026 - 30 Apr 2027 | I2: Orderin Year II | L2: 1 May 2027 - 30 Apr 2028 | N2: Orderin Year III | Q2: 1 May 2028 - 30 Apr 2029 | S2: Orderin Year IV | V2: 1 May 2029 - 30 Apr 2030 | X2: Orderin Year V | AA2: 1 May 2030 - 30 Apr 2031 | AC2: Option to Extend services FAR 52.217-8 | AF2: 1 May 2031 - 31 Oct 2031
C3: CLIN Description | D3: QTY | E3: Unit Description | F3: Unit Price | G3: Extended Price | J3: QTY | K3: Unit Price | L3: Extended Price | O3: QTY | P3: Unit Price | Q3: Extended Price | T3: QTY | U3: Unit Price | V3: Extended Price | Y3: QTY | Z3: Unit Price | AA3: Extended Price | AD3: QTY | AE3: Unit Price | AF3: Extended Price
A4: 1 | B4: SCHEDULE I OUTBOUND SERVICES
A5: 2 | B5: A001 | C5: Complete Service - OUTBOUND (HHG) | I5: A101 | N5: A201 | S5: A301 | X5: A401 | AC5: A501
A6: 3 | B6: A001AA | C6: AREA 1 - At Owner's Residence: Container, Commercial Spec ASTM | D6: 1550 | E6: NCWT | G6: =IF(D6="",0,D6*F6) -> 0 | I6: A101AA | J6: 1550 | L6: =IF(J6="",0,J6*K6) -> 0 | N6: A201AA | O6: 1550 | Q6: =IF(O6="",0,O6*P6) -> 0 | S6: A301AA | T6: 1550 | V6: =IF(T6="",0,T6*U6) -> 0 | X6: A401AA | Y6: 1550 | AA6: =IF(Y6="",0,Y6*Z6) -> 0 | AC6: A501AA | AD6: =Y6/2 -> 775 | AE6: =Z6 -> 0 | AF6: =IF(AD6="",0,AD6*AE6) -> 0
A7: 4 | B7: A001AB | C7: AREA II At Owner's Residence: Container, Commercial Spec ASTM | D7: 350 | E7: NCWT | G7: =IF(D7="",0,D7*F7) -> 0 | I7: A101AB | J7: 350 | L7: =IF(J7="",0,J7*K7) -> 0 | N7: A201AB | O7: 350 | Q7: =IF(O7="",0,O7*P7) -> 0 | S7: A301AB | T7: 350 | V7: =IF(T7="",0,T7*U7) -> 0 | X7: A401AB | Y7: 350 | AA7: =IF(Y7="",0,Y7*Z7) -> 0 | AC7: A501AB | AD7: =Y7/2 -> 175 | AE7: =Z7 -> 0 | AF7: =IF(AD7="",0,AD7*AE7) -> 0
A8: 5 | B8: A001AC | C8: AREA III At Owner's Residence: Container, Commercial Spec ASTM | D8: 130 | E8: NCWT | G8: =IF(D8="",0,D8*F8) -> 0 | I8: A101AC | J8: 130 | L8: =IF(J8="",0,J8*K8) -> 0 | N8: A201AC | O8: 130 | Q8: =IF(O8="",0,O8*P8) -> 0 | S8: A301AC | T8: 130 | V8: =IF(T8="",0,T8*U8) -> 0 | X8: A401AC | Y8: 130 | AA8: =IF(Y8="",0,Y8*Z8) -> 0 | AC8: A501AC | AD8: =Y8/2 -> 65 | AE8: =Z8 -> 0 | AF8: =IF(AD8="",0,AD8*AE8) -> 0
A9: 6 | B9: A001AD | C9: AREA IV At Owner's Residence: Container, Commercial Spec ASTM | D9: 50 | E9: NCWT | G9: =IF(D9="",0,D9*F9) -> 0 | I9: A101AD | J9: 50 | L9: =IF(J9="",0,J9*K9) -> 0 | N9: A201AD | O9: 50 | Q9: =IF(O9="",0,O9*P9) -> 0 | S9: A301AD | T9: 50 | V9: =IF(T9="",0,T9*U9) -> 0 | X9: A401AD | Y9: 50 | AA9: =IF(Y9="",0,Y9*Z9) -> 0 | AC9: A501AD | AD9: =Y9/2 -> 25 | AE9: =Z9 -> 0 | AF9: =IF(AD9="",0,AD9*AE9) -> 0
A10: 7 | B10: A002 | C10: Complete Service - OUTBOUND Unaccompanied Bagggage | I10: A102 | N10: A202 | S10: A302 | X10: A402 | AC10: A502
A11: 8 | B11: A002AA | C11: AREA I Contractor - Furnished Containers Overseas Pack Overflow | D11: 50 | E11: NCWT | G11: =IF(D11="",0,D11*F11) -> 0 | I11: A102AA | J11: 50 | L11: =IF(J11="",0,J11*K11) -> 0 | N11: A202AA | O11: 50 | Q11: =IF(O11="",0,O11*P11) -> 0 | S11: A302AA | T11: 50 | V11: =IF(T11="",0,T11*U11) -> 0 | X11: A402AA | Y11: 50 | AA11: =IF(Y11="",0,Y11*Z11) -> 0 | AC11: A502AA | AD11: =Y11/2 -> 25 | AE11: =Z11 -> 0 | AF11: =IF(AD11="",0,AD11*AE11) -> 0
A12: 9 | B12: A002AB | C12: AREA II Contractor - Furnished Containers Overseas Pack Overflow | D12: 20 | E12: NCWT | G12: =IF(D12="",0,D12*F12) -> 0 | I12: A102AB | J12: 20 | L12: =IF(J12="",0,J12*K12) -> 0 | N12: A202AB | O12: 20 | Q12: =IF(O12="",0,O12*P12) -> 0 | S12: A302AB | T12: 20 | V12: =IF(T12="",0,T12*U12) -> 0 | X12: A402AB | Y12: 20 | AA12: =IF(Y12="",0,Y12*Z12) -> 0 | AC12: A502AB | AD12: =Y12/2 -> 10 | AE12: =Z12 -> 0 | AF12: =IF(AD12="",0,AD12*AE12) -> 0
A13: 10 | B13: A002AC | C13: AREA III Contractor - Furnished Containers Overseas Pack Overflow: | D13: 40 | E13: NCWT | G13: =IF(D13="",0,D13*F13) -> 0 | I13: A102AC | J13: 40 | L13: =IF(J13="",0,J13*K13) -> 0 | N13: A202AC | O13: 40 | Q13: =IF(O13="",0,O13*P13) -> 0 | S13: A302AC | T13: 40 | V13: =IF(T13="",0,T13*U13) -> 0 | X13: A402AC | Y13: 40 | AA13: =IF(Y13="",0,Y13*Z13) -> 0 | AC13: A502AC | AD13: =Y13/2 -> 20 | AE13: =Z13 -> 0 | AF13: =IF(AD13="",0,AD13*AE13) -> 0
A14: 11 | B14: A002AD | C14: AREA IV Contractor - Furnished Containers Overseas Pack Overflow: | D14: 10 | E14: NCWT | G14: =IF(D14="",0,D14*F14) -> 0 | I14: A102AD | J14: 10 | L14: =IF(J14="",0,J14*K14) -> 0 | N14: A202AD | O14: 10 | Q14: =IF(O14="",0,O14*P14) -> 0 | S14: A302AD | T14: 10 | V14: =IF(T14="",0,T14*U14) -> 0 | X14: A402AD | Y14: 10 | AA14: =IF(Y14="",0,Y14*Z14) -> 0 | AC14: A502AD | AD14: =Y14/2 -> 5 | AE14: =Z14 -> 0 | AF14: =IF(AD14="",0,AD14*AE14) -> 0
A15: 12 | B15: A003 | C15: Complete Service - OUTBOUND Unaccompanied Bagggage | I15: A103 | N15: A203 | S15: A303 | X15: A403 | AC15: A503
A16: 13 | B16: AA003AA | C16: AREA I Government - Furnished Containers: Drayage Inc. | D16: 15 | E16: NCWT | G16: =IF(D16="",0,D16*F16) -> 0 | I16: AA103AA | J16: 15 | L16: =IF(J16="",0,J16*K16) -> 0 | N16: AA203AA | O16: 15 | Q16: =IF(O16="",0,O16*P16) -> 0 | S16: AA303AA | T16: 15 | V16: =IF(T16="",0,T16*U16) -> 0 | X16: AA403AA | Y16: 15 | AA16: =IF(Y16="",0,Y16*Z16) -> 0 | AC16: AA503AA | AD16: =Y16/2 -> 7.5 | AE16: =Z16 -> 0 | AF16: =IF(AD16="",0,AD16*AE16) -> 0
A17: 14 | B17: AA003AB | C17: AREA I Contractor - Furnished Containers: Drayage Inc. | D17: 600 | E17: NCWT | G17: =IF(D17="",0,D17*F17) -> 0 | I17: AA103AB | J17: 600 | L17: =IF(J17="",0,J17*K17) -> 0 | N17: AA203AB | O17: 600 | Q17: =IF(O17="",0,O17*P17) -> 0 | S17: AA303AB | T17: 600 | V17: =IF(T17="",0,T17*U17) -> 0 | X17: AA403AB | Y17: 600 | AA17: =IF(Y17="",0,Y17*Z17) -> 0 | AC17: AA503AB | AD17: =Y17/2 -> 300 | AE17: =Z17 -> 0 | AF17: =IF(AD17="",0,AD17*AE17) -> 0
A18: 15 | B18: AA003AC | C18: AREA II Government - Furnished Containers: Drayage Inc. | D18: 10 | E18: NCWT | G18: =IF(D18="",0,D18*F18) -> 0 | I18: AA103AC | J18: 10 | L18: =IF(J18="",0,J18*K18) -> 0 | N18: AA203AC | O18: 10 | Q18: =IF(O18="",0,O18*P18) -> 0 | S18: AA303AC | T18: 10 | V18: =IF(T18="",0,T18*U18) -> 0 | X18: AA403AC | Y18: 10 | AA18: =IF(Y18="",0,Y18*Z18) -> 0 | AC18: AA503AC | AD18: =Y18/2 -> 5 | AE18: =Z18 -> 0 | AF18: =IF(AD18="",0,AD18*AE18) -> 0
A19: 16 | B19: AA003AD | C19: AREA II Contractor - Furnished Containers: Drayage Inc. | D19: 10 | E19: NCWT | G19: =IF(D19="",0,D19*F19) -> 0 | I19: AA103AD | J19: 10 | L19: =IF(J19="",0,J19*K19) -> 0 | N19: AA203AD | O19: 10 | Q19: =IF(O19="",0,O19*P19) -> 0 | S19: AA303AD | T19: 10 | V19: =IF(T19="",0,T19*U19) -> 0 | X19: AA403AD | Y19: 10 | AA19: =IF(Y19="",0,Y19*Z19) -> 0 | AC19: AA503AD | AD19: =Y19/2 -> 5 | AE19: =Z19 -> 0 | AF19: =IF(AD19="",0,AD19*AE19) -> 0
A20: 17 | B20: AA003AE | C20: AREA III Government - Furnished Containers: Drayage Inc. | D20: 10 | E20: NCWT | G20: =IF(D20="",0,D20*F20) -> 0 | I20: AA103AE | J20: 10 | L20: =IF(J20="",0,J20*K20) -> 0 | N20: AA203AE | O20: 10 | Q20: =IF(O20="",0,O20*P20) -> 0 | S20: AA303AE | T20: 10 | V20: =IF(T20="",0,T20*U20) -> 0 | X20: AA403AE | Y20: 10 | AA20: =IF(Y20="",0,Y20*Z20) -> 0 | AC20: AA503AE | AD20: =Y20/2 -> 5 | AE20: =Z20 -> 0 | AF20: =IF(AD20="",0,AD20*AE20) -> 0
A21: 18 | B21: AA003AF | C21: AREA III Contractor - Furnished Containers: Drayage Inc. | D21: 300 | E21: NCWT | G21: =IF(D21="",0,D21*F21) -> 0 | I21: AA103AF | J21: 300 | L21: =IF(J21="",0,J21*K21) -> 0 | N21: AA203AF | O21: 300 | Q21: =IF(O21="",0,O21*P21) -> 0 | S21: AA303AF | T21: 300 | V21: =IF(T21="",0,T21*U21) -> 0 | X21: AA403AF | Y21: 300 | AA21: =IF(Y21="",0,Y21*Z21) -> 0 | AC21: AA503AF | AD21: =Y21/2 -> 150 | AE21: =Z21 -> 0 | AF21: =IF(AD21="",0,AD21*AE21) -> 0
A22: 19 | B22: AA003AG | C22: AREA IV Government - Furnished Containers: Drayage Inc. | D22: 10 | E22: NCWT | G22: =IF(D22="",0,D22*F22) -> 0 | I22: AA103AG | J22: 10 | L22: =IF(J22="",0,J22*K22) -> 0 | N22: AA203AG | O22: 10 | Q22: =IF(O22="",0,O22*P22) -> 0 | S22: AA303AG | T22: 10 | V22: =IF(T22="",0,T22*U22) -> 0 | X22: AA403AG | Y22: 10 | AA22: =IF(Y22="",0,Y22*Z22) -> 0 | AC22: AA503AG | AD22: =Y22/2 -> 5 | AE22: =Z22 -> 0 | AF22: =IF(AD22="",0,AD22*AE22) -> 0
A23: 20 | B23: AA003AH | C23: AREA IV Contractor - Furnished Containers: Drayage Inc. | D23: 10 | E23: NCWT | G23: =IF(D23="",0,D23*F23) -> 0 | I23: AA103AH | J23: 10 | L23: =IF(J23="",0,J23*K23) -> 0 | N23: AA203AH | O23: 10 | Q23: =IF(O23="",0,O23*P23) -> 0 | S23: AA303AH | T23: 10 | V23: =IF(T23="",0,T23*U23) -> 0 | X23: AA403AH | Y23: 10 | AA23: =IF(Y23="",0,Y23*Z23) -> 0 | AC23: AA503AH | AD23: =Y23/2 -> 5 | AE23: =Z23 -> 0 | AF23: =IF(AD23="",0,AD23*AE23) -> 0
A24: 21 | B24: A004 | C24: OUTBOUND SERVICES - Unaccompanied Bagggage packed by member/employee | I24: A104 | N24: A204 | S24: A304 | X24: A404 | AC24: A504
A25: 22 | B25: A004AA | C25: AREA I Government - Furnished Containers: Drayage Inc. | D25: 5 | E25: GCWT | G25: =IF(D25="",0,D25*F25) -> 0 | I25: A104AA | J25: 5 | L25: =IF(J25="",0,J25*K25) -> 0 | N25: A204AA | O25: 5 | Q25: =IF(O25="",0,O25*P25) -> 0 | S25: A304AA | T25: 5 | V25: =IF(T25="",0,T25*U25) -> 0 | X25: A404AA | Y25: 5 | AA25: =IF(Y25="",0,Y25*Z25) -> 0 | AC25: A504AA | AD25: =Y25/2 -> 2.5 | AE25: =Z25 -> 0 | AF25: =IF(AD25="",0,AD25*AE25) -> 0
A26: 23 | B26: A004AB | C26: AREA I Contractor - Furnished Containers: Drayage Inc. | D26: 10 | E26: GCWT | G26: =IF(D26="",0,D26*F26) -> 0 | I26: A104AB | J26: 10 | L26: =IF(J26="",0,J26*K26) -> 0 | N26: A204AB | O26: 10 | Q26: =IF(O26="",0,O26*P26) -> 0 | S26: A304AB | T26: 10 | V26: =IF(T26="",0,T26*U26) -> 0 | X26: A404AB | Y26: 10 | AA26: =IF(Y26="",0,Y26*Z26) -> 0 | AC26: A504AB | AD26: =Y26/2 -> 5 | AE26: =Z26 -> 0 | AF26: =IF(AD26="",0,AD26*AE26) -> 0
A27: 24 | B27: A004AC | C27: AREA II Government - Furnished Containers: Drayage Inc. | D27: 5 | E27: GCWT | G27: =IF(D27="",0,D27*F27) -> 0 | I27: A104AC | J27: 5 | L27: =IF(J27="",0,J27*K27) -> 0 | N27: A204AC | O27: 5 | Q27: =IF(O27="",0,O27*P27) -> 0 | S27: A304AC | T27: 5 | V27: =IF(T27="",0,T27*U27) -> 0 | X27: A404AC | Y27: 5 | AA27: =IF(Y27="",0,Y27*Z27) -> 0 | AC27: A504AC | AD27: =Y27/2 -> 2.5 | AE27: =Z27 -> 0 | AF27: =IF(AD27="",0,AD27*AE27) -> 0
A28: 25 | B28: A004AD | C28: AREA II Contractor - Furnished Containers: Drayage Inc. | D28: 5 | E28: GCWT | G28: =IF(D28="",0,D28*F28) -> 0 | I28: A104AD | J28: 5 | L28: =IF(J28="",0,J28*K28) -> 0 | N28: A204AD | O28: 5 | Q28: =IF(O28="",0,O28*P28) -> 0 | S28: A304AD | T28: 5 | V28: =IF(T28="",0,T28*U28) -> 0 | X28: A404AD | Y28: 5 | AA28: =IF(Y28="",0,Y28*Z28) -> 0 | AC28: A504AD | AD28: =Y28/2 -> 2.5 | AE28: =Z28 -> 0 | AF28: =IF(AD28="",0,AD28*AE28) -> 0
A29: 26 | B29: A004AE | C29: AREA III Government - Furnished Containers: Drayage Inc. | D29: 5 | E29: GCWT | G29: =IF(D29="",0,D29*F29) -> 0 | I29: A104AE | J29: 5 | L29: =IF(J29="",0,J29*K29) -> 0 | N29: A204AE | O29: 5 | Q29: =IF(O29="",0,O29*P29) -> 0 | S29: A304AE | T29: 5 | V29: =IF(T29="",0,T29*U29) -> 0 | X29: A404AE | Y29: 5 | AA29: =IF(Y29="",0,Y29*Z29) -> 0 | AC29: A504AE | AD29: =Y29/2 -> 2.5 | AE29: =Z29 -> 0 | AF29: =IF(AD29="",0,AD29*AE29) -> 0
A30: 27 | B30: A004AF | C30: AREA III Contractor - Furnished Containers: Drayage Inc. | D30: 5 | E30: GCWT | G30: =IF(D30="",0,D30*F30) -> 0 | I30: A104AF | J30: 5 | L30: =IF(J30="",0,J30*K30) -> 0 | N30: A204AF | O30: 5 | Q30: =IF(O30="",0,O30*P30) -> 0 | S30: A304AF | T30: 5 | V30: =IF(T30="",0,T30*U30) -> 0 | X30: A404AF | Y30: 5 | AA30: =IF(Y30="",0,Y30*Z30) -> 0 | AC30: A504AF | AD30: =Y30/2 -> 2.5 | AE30: =Z30 -> 0 | AF30: =IF(AD30="",0,AD30*AE30) -> 0
A31: 28 | B31: A004AG | C31: AREA IV Government - Furnished Containers: Drayage Inc. | D31: 5 | E31: GCWT | G31: =IF(D31="",0,D31*F31) -> 0 | I31: A104AG | J31: 5 | L31: =IF(J31="",0,J31*K31) -> 0 | N31: A204AG | O31: 5 | Q31: =IF(O31="",0,O31*P31) -> 0 | S31: A304AG | T31: 5 | V31: =IF(T31="",0,T31*U31) -> 0 | X31: A404AG | Y31: 5 | AA31: =IF(Y31="",0,Y31*Z31) -> 0 | AC31: A504AG | AD31: =Y31/2 -> 2.5 | AE31: =Z31 -> 0 | AF31: =IF(AD31="",0,AD31*AE31) -> 0
A32: 29 | B32: A004AH | C32: AREA IV Contractor - Furnished Containers: Drayage Inc. | D32: 5 | E32: GCWT | G32: =IF(D32="",0,D32*F32) -> 0 | I32: A104AH | J32: 5 | L32: =IF(J32="",0,J32*K32) -> 0 | N32: A204AH | O32: 5 | Q32: =IF(O32="",0,O32*P32) -> 0 | S32: A304AH | T32: 5 | V32: =IF(T32="",0,T32*U32) -> 0 | X32: A404AH | Y32: 5 | AA32: =IF(Y32="",0,Y32*Z32) -> 0 | AC32: A504AH | AD32: =Y32/2 -> 2.5 | AE32: =Z32 -> 0 | AF32: =IF(AD32="",0,AD32*AE32) -> 0
A33: 30 | B33: A005 | C33: OUTBOUND SERVICES - Unaccompanied Bagggage | I33: A105 | N33: A205 | S33: A305 | X33: A405 | AC33: A505
A34: 31 | B34: A005AA | C34: AREA I Containerization Not Required: Drayage included | D34: 50 | E34: GCWT | G34: =IF(D34="",0,D34*F34) -> 0 | I34: A105AA | J34: 50 | L34: =IF(J34="",0,J34*K34) -> 0 | N34: A205AA | O34: 50 | Q34: =IF(O34="",0,O34*P34) -> 0 | S34: A305AA | T34: 50 | V34: =IF(T34="",0,T34*U34) -> 0 | X34: A405AA | Y34: 50 | AA34: =IF(Y34="",0,Y34*Z34) -> 0 | AC34: A505AA | AD34: =Y34/2 -> 25 | AE34: =Z34 -> 0 | AF34: =IF(AD34="",0,AD34*AE34) -> 0
A35: 32 | B35: A005AB | C35: AREA 1 Containerization Required: Drayage included | D35: 150 | E35: NCWT | G35: =IF(D35="",0,D35*F35) -> 0 | I35: A105AB | J35: 150 | L35: =IF(J35="",0,J35*K35) -> 0 | N35: A205AB | O35: 150 | Q35: =IF(O35="",0,O35*P35) -> 0 | S35: A305AB | T35: 150 | V35: =IF(T35="",0,T35*U35) -> 0 | X35: A405AB | Y35: 150 | AA35: =IF(Y35="",0,Y35*Z35) -> 0 | AC35: A505AB | AD35: =Y35/2 -> 75 | AE35: =Z35 -> 0 | AF35: =IF(AD35="",0,AD35*AE35) -> 0
A36: 33 | B36: A006 | C36: Expensive and Valuable Items ALL AREAS | I36: A106 | N36: A206 | S36: A306 | X36: A406 | AC36: A506
A37: 34 | B37: A006AA | C37: DRAYAGE INCLUDED | D37: 50 | E37: NCWT | G37: =IF(D37="",0,D37*F37) -> 0 | I37: A106AA | J37: 50 | L37: =IF(J37="",0,J37*K37) -> 0 | N37: A206AA | O37: 50 | Q37: =IF(O37="",0,O37*P37) -> 0 | S37: A306AA | T37: 50 | V37: =IF(T37="",0,T37*U37) -> 0 | X37: A406AA | Y37: 50 | AA37: =IF(Y37="",0,Y37*Z37) -> 0 | AC37: A506AA | AD37: =Y37/2 -> 25 | AE37: =Z37 -> 0 | AF37: =IF(AD37="",0,AD37*AE37) -> 0
A38: 35 | B38: A006AB | C38: DRAYAGE NOT INCLUDED | D38: 150 | E38: NCWT | G38: =IF(D38="",0,D38*F38) -> 0 | I38: A106AB | J38: 150 | L38: =IF(J38="",0,J38*K38) -> 0 | N38: A206AB | O38: 150 | Q38: =IF(O38="",0,O38*P38) -> 0 | S38: A306AB | T38: 150 | V38: =IF(T38="",0,T38*U38) -> 0 | X38: A406AB | Y38: 150 | AA38: =IF(Y38="",0,Y38*Z38) -> 0 | AC38: A506AB | AD38: =Y38/2 -> 75 | AE38: =Z38 -> 0 | AF38: =IF(AD38="",0,AD38*AE38) -> 0
A39: 36 | B39: A007 | C39: STORAGE ALL AREAS | D39: 600 | E39: NCWT | G39: =IF(D39="",0,D39*F39) -> 0 | I39: A107 | J39: 600 | L39: =IF(J39="",0,J39*K39) -> 0 | N39: A207 | O39: 600 | Q39: =IF(O39="",0,O39*P39) -> 0 | S39: A307 | T39: 600 | V39: =IF(T39="",0,T39*U39) -> 0 | X39: A407 | Y39: 600 | AA39: =IF(Y39="",0,Y39*Z39) -> 0 | AC39: A507 | AD39: =Y39/2 -> 300 | AE39: =Z39 -> 0 | AF39: =IF(AD39="",0,AD39*AE39) -> 0
A40: 37 | B40: A008 | C40: CONTAINERS ALL AREAS | I40: A108 | N40: A208 | S40: A308 | X40: A408 | AC40: A508
...

Sheet Summary
A1: Period | B1: Dates | C1: Amount €
A2: Orderin Year I | B2: 1 May 2026 - 30 Apr 2027 | C2: ='Pricing Matrix'!G124 -> 0
A3: Orderin Year II | B3: 1 May 2027 - 30 Apr 2028 | C3: ='Pricing Matrix'!L124 -> 0
A4: Orderin Year III | B4: 1 May 2028 - 30 Apr 2029 | C4: ='Pricing Matrix'!Q124 -> 0
A5: Orderin Year IV | B5: 1 May 2029 - 30 Apr 2030 | C5: ='Pricing Matrix'!V124 -> 0
A6: Orderin Year V | B6: 1 May 2030 - 30 Apr 2031 | C6: ='Pricing Matrix'!AA124 -> 0
A7: Total CLIN 0001 | C7: =SUM(C2:C6) -> 0
A9: FAR 52.217-8 | B9: 1 May 2031 - 31 Oct 2031 | C9: ='Pricing Matrix'!AF124 -> 0
A10: Total CLIN 0002 | C10: =C9 -> 0
A12: Total Quote | C12: =C7+C10 -> 0
