Workbook
Name FY_Total: BASE!$F$78
Name FY_Total: 'OPT 1'!$F$37
Name FY_Total: 'OPT 2'!$F$37
Name FY_Total: 'OPT 3'!$F$37
Name FY_Total: 'OPT 4'!$F$37

Sheet Summary
A1: PRICE DETAILS WITH OPTIONS
A2: CUI
A5: Summary data, below, is autopulated from the yearly worksheets. Do not edit this section.
A6: SUMMARY DATA | E6: TOTAL
A7: BASE: | E7: =BASE!FY_Total -> 0
D8: OPTION 1 | E8: ='OPT 1'!F78 -> 0
D9: OPTION 2 | E9: ='OPT 2'!F78 -> 0
D10: OPTION 3 | E10: ='OPT 3'!F78 -> 0
D11: OPTION 4 | E11: ='OPT 4'!F78 -> 0
D12: Option (6) months: | E12: ='52.217-8'!F78 -> 0
A14: PROCUREMENT TOTAL: | E14: =SUM(E7:E13) -> 0
C17: CUI

Sheet BASE
C1: CUI
B2: BASE PRICING
B3: POP : 01 APRIL 2026 TO 31 MARCH 2027
B4: =[1]Summary!C6 -> 0
B5: =[1]Summary!C7 -> FFP
B6: Total | D6: =FY_Total -> 0
B8: LOCATION/ACCOUNT 850 M13-5313 001 0564
B9: QTY | C9: DESCRIPTION | D9: MONTHS | E9: Charge | F9: Amount
B10: 3 | C10: Foreign Directory Listing | D10: 12 | E10: 0 | F10: =B10*D10*E10 -> 0
B11: SUBTOTAL | F11: =SUM(F10:F10) -> 0
B13: LOCATION/ACCOUNT 865 M38-8015 001 1868
B14: QTY | C14: DESCRIPTION | D14: MONTHS | E14: Charge | F14: Amount
B15: 1 | C15: MemoryCall Annc 6 Minutes | D15: 12 | E15: 0 | F15: =B15*D15*E15 -> 0
B16: 1 | C16: Surrogate Client Number (Voice Messaging ID Number) | D16: 12 | E16: 0 | F16: =B16*D16*E16 -> 0
B17: SUBTOTAL | F17: =SUM(F15:F16) -> 0
B19: LOCATION/ACCOUNT 850 230-3056 116 0561
B20: QTY | C20: DESCRIPTION | D20: MONTHS | E20: Charge | F20: Amount
B21: 2 | C21: Business Flat-Rate MultiLine | D21: 12 | E21: 0 | F21: =B21*D21*E21 -> 0
B22: 2 | C22: Federal Subscriber Line Charge | D22: 12 | E22: 0 | F22: =B22*D22*E22 -> 0
B23: 2 | C23: Federal Universal Svc Fee-Mult | D23: 12 | E23: 0 | F23: =B23*D23*E23 -> 0
B24: SUBTOTAL | F24: =SUM(F21:F23) -> 0
B26: LOCATION/ACCOUNT 850 230-3897 843 0565
B27: QTY | C27: DESCRIPTION | D27: MONTHS | E27: Charge | F27: Amount
B28: 1 | C28: Business Flat-Rate MultiLine | D28: 12 | E28: 0 | F28: =B28*D28*E28 -> 0
B29: 1 | C29: Federal Subscriber Line Charge | D29: 12 | E29: 0 | F29: =B29*D29*E29 -> 0
B30: 1 | C30: Federal Universal Svc Fee-Mult | D30: 12 | E30: 0 | F30: =B30*D30*E30 -> 0
B31: SUBTOTAL | F31: =SUM(F28:F30) -> 0
B33: LOCATION/ACCOUNT 850 230-5606 247 0560
B34: QTY | C34: DESCRIPTION | D34: MONTHS | E34: Charge | F34: Amount
B35: 1 | C35: Business Flat-Rate MultiLine | D35: 12 | E35: 0 | F35: =B35*D35*E35 -> 0
B36: 1 | C36: Federal Subscriber Line Charge | D36: 12 | E36: 0 | F36: =B36*D36*E36 -> 0
B37: 1 | C37: Federal Universal Svc Fee-Mult | D37: 12 | E37: 0 | F37: =B37*D37*E37 -> 0
B38: SUBTOTAL | F38: =SUM(F35:F37) -> 0
B40: LOCATION/ACCOUNT 850 233-3669 756 0566
B41: QTY | C41: DESCRIPTION | D41: MONTHS | E41: Charge | F41: Amount
B42: 1 | C42: Business Flat-Rate MultiLine | D42: 12 | E42: 0 | F42: =B42*D42*E42 -> 0
B43: 1 | C43: Federal Subscriber Line Charge | D43: 12 | E43: 0 | F43: =B43*D43*E43 -> 0
B44: 1 | C44: Federal Universal Svc Fee-Mult | D44: 12 | E44: 0 | F44: =B44*D44*E44 -> 0
B45: SUBTOTAL | F45: =SUM(F42:F44) -> 0
B47: LOCATION/ACCOUNT 850 234-2863 224 0562
...

Sheet OPT 1
C1: CUI
B2: OPTION 1 PRICING
B3: POP : 01 APRIL 2027 TO 31 MARCH 2028
B4: =[1]Summary!C6 -> 0
B5: =[1]Summary!C7 -> FFP
B6: Total | D6: =FY_Total -> 0
B8: LOCATION/ACCOUNT 850 M13-5313 001 0564
B9: QTY | C9: DESCRIPTION | D9: MONTHS | E9: Charge | F9: Amount
B10: 3 | C10: Foreign Directory Listing | D10: 12 | E10: 0 | F10: =B10*D10*E10 -> 0
B11: SUBTOTAL | F11: =SUM(F10:F10) -> 0
B13: LOCATION/ACCOUNT 865 M38-8015 001 1868
B14: QTY | C14: DESCRIPTION | D14: MONTHS | E14: Charge | F14: Amount
B15: 1 | C15: MemoryCall Annc 6 Minutes | D15: 12 | E15: 0 | F15: =B15*D15*E15 -> 0
B16: 1 | C16: Surrogate Client Number (Voice Messaging ID Number) | D16: 12 | E16: 0 | F16: =B16*D16*E16 -> 0
B17: SUBTOTAL | F17: =SUM(F15:F16) -> 0
B19: LOCATION/ACCOUNT 850 230-3056 116 0561
B20: QTY | C20: DESCRIPTION | D20: MONTHS | E20: Charge | F20: Amount
B21: 2 | C21: Business Flat-Rate MultiLine | D21: 12 | E21: 0 | F21: =B21*D21*E21 -> 0
B22: 2 | C22: Federal Subscriber Line Charge | D22: 12 | E22: 0 | F22: =B22*D22*E22 -> 0
B23: 2 | C23: Federal Universal Svc Fee-Mult | D23: 12 | E23: 0 | F23: =B23*D23*E23 -> 0
B24: SUBTOTAL | F24: =SUM(F21:F23) -> 0
B26: LOCATION/ACCOUNT 850 230-3897 843 0565
B27: QTY | C27: DESCRIPTION | D27: MONTHS | E27: Charge | F27: Amount
B28: 1 | C28: Business Flat-Rate MultiLine | D28: 12 | E28: 0 | F28: =B28*D28*E28 -> 0
B29: 1 | C29: Federal Subscriber Line Charge | D29: 12 | E29: 0 | F29: =B29*D29*E29 -> 0
B30: 1 | C30: Federal Universal Svc Fee-Mult | D30: 12 | E30: 0 | F30: =B30*D30*E30 -> 0
B31: SUBTOTAL | F31: =SUM(F28:F30) -> 0
B33: LOCATION/ACCOUNT 850 230-5606 247 0560
B34: QTY | C34: DESCRIPTION | D34: MONTHS | E34: Charge | F34: Amount
B35: 1 | C35: Business Flat-Rate MultiLine | D35: 12 | E35: 0 | F35: =B35*D35*E35 -> 0
B36: 1 | C36: Federal Subscriber Line Charge | D36: 12 | E36: 0 | F36: =B36*D36*E36 -> 0
B37: 1 | C37: Federal Universal Svc Fee-Mult | D37: 12 | E37: 0 | F37: =B37*D37*E37 -> 0
B38: SUBTOTAL | F38: =SUM(F35:F37) -> 0
B40: LOCATION/ACCOUNT 850 233-3669 756 0566
B41: QTY | C41: DESCRIPTION | D41: MONTHS | E41: Charge | F41: Amount
B42: 1 | C42: Business Flat-Rate MultiLine | D42: 12 | E42: 0 | F42: =B42*D42*E42 -> 0
B43: 1 | C43: Federal Subscriber Line Charge | D43: 12 | E43: 0 | F43: =B43*D43*E43 -> 0
B44: 1 | C44: Federal Universal Svc Fee-Mult | D44: 12 | E44: 0 | F44: =B44*D44*E44 -> 0
B45: SUBTOTAL | F45: =SUM(F42:F44) -> 0
B47: LOCATION/ACCOUNT 850 234-2863 224 0562
...

Sheet OPT 2
C1: CUI
B2: OPTION 2 PRICING
B3: POP : 01 APRIL 2028 TO 31 MARCH 2029
B4: =[1]Summary!C6 -> 0
B5: =[1]Summary!C7 -> FFP
B6: Total | D6: =FY_Total -> 0
B8: LOCATION/ACCOUNT 850 M13-5313 001 0564
B9: QTY | C9: DESCRIPTION | D9: MONTHS | E9: Charge | F9: Amount
B10: 3 | C10: Foreign Directory Listing | D10: 12 | E10: 0 | F10: =B10*D10*E10 -> 0
B11: SUBTOTAL | F11: =SUM(F10:F10) -> 0
B13: LOCATION/ACCOUNT 865 M38-8015 001 1868
B14: QTY | C14: DESCRIPTION | D14: MONTHS | E14: Charge | F14: Amount
B15: 1 | C15: MemoryCall Annc 6 Minutes | D15: 12 | E15: 0 | F15: =B15*D15*E15 -> 0
B16: 1 | C16: Surrogate Client Number (Voice Messaging ID Number) | D16: 12 | E16: 0 | F16: =B16*D16*E16 -> 0
B17: SUBTOTAL | F17: =SUM(F15:F16) -> 0
B19: LOCATION/ACCOUNT 850 230-3056 116 0561
B20: QTY | C20: DESCRIPTION | D20: MONTHS | E20: Charge | F20: Amount
B21: 2 | C21: Business Flat-Rate MultiLine | D21: 12 | E21: 0 | F21: =B21*D21*E21 -> 0
B22: 2 | C22: Federal Subscriber Line Charge | D22: 12 | E22: 0 | F22: =B22*D22*E22 -> 0
B23: 2 | C23: Federal Universal Svc Fee-Mult | D23: 12 | E23: 0 | F23: =B23*D23*E23 -> 0
B24: SUBTOTAL | F24: =SUM(F21:F23) -> 0
B26: LOCATION/ACCOUNT 850 230-3897 843 0565
B27: QTY | C27: DESCRIPTION | D27: MONTHS | E27: Charge | F27: Amount
B28: 1 | C28: Business Flat-Rate MultiLine | D28: 12 | E28: 0 | F28: =B28*D28*E28 -> 0
B29: 1 | C29: Federal Subscriber Line Charge | D29: 12 | E29: 0 | F29: =B29*D29*E29 -> 0
B30: 1 | C30: Federal Universal Svc Fee-Mult | D30: 12 | E30: 0 | F30: =B30*D30*E30 -> 0
B31: SUBTOTAL | F31: =SUM(F28:F30) -> 0
B33: LOCATION/ACCOUNT 850 230-5606 247 0560
B34: QTY | C34: DESCRIPTION | D34: MONTHS | E34: Charge | F34: Amount
B35: 1 | C35: Business Flat-Rate MultiLine | D35: 12 | E35: 0 | F35: =B35*D35*E35 -> 0
B36: 1 | C36: Federal Subscriber Line Charge | D36: 12 | E36: 0 | F36: =B36*D36*E36 -> 0
B37: 1 | C37: Federal Universal Svc Fee-Mult | D37: 12 | E37: 0 | F37: =B37*D37*E37 -> 0
B38: SUBTOTAL | F38: =SUM(F35:F37) -> 0
B40: LOCATION/ACCOUNT 850 233-3669 756 0566
B41: QTY | C41: DESCRIPTION | D41: MONTHS | E41: Charge | F41: Amount
B42: 1 | C42: Business Flat-Rate MultiLine | D42: 12 | E42: 0 | F42: =B42*D42*E42 -> 0
B43: 1 | C43: Federal Subscriber Line Charge | D43: 12 | E43: 0 | F43: =B43*D43*E43 -> 0
B44: 1 | C44: Federal Universal Svc Fee-Mult | D44: 12 | E44: 0 | F44: =B44*D44*E44 -> 0
B45: SUBTOTAL | F45: =SUM(F42:F44) -> 0
B47: LOCATION/ACCOUNT 850 234-2863 224 0562
...

Sheet OPT 3
C1: CUI
B2: OPTION 3 PRICING
B3: POP : 01 APRIL 2029 TO 31 MARCH 2030
B4: =[1]Summary!C6 -> 0
B5: =[1]Summary!C7 -> FFP
B6: Total | D6: =FY_Total -> 0
B8: LOCATION/ACCOUNT 850 M13-5313 001 0564
B9: QTY | C9: DESCRIPTION | D9: MONTHS | E9: Charge | F9: Amount
B10: 3 | C10: Foreign Directory Listing | D10: 12 | E10: 0 | F10: =B10*D10*E10 -> 0
B11: SUBTOTAL | F11: =SUM(F10:F10) -> 0
B13: LOCATION/ACCOUNT 865 M38-8015 001 1868
B14: QTY | C14: DESCRIPTION | D14: MONTHS | E14: Charge | F14: Amount
B15: 1 | C15: MemoryCall Annc 6 Minutes | D15: 12 | E15: 0 | F15: =B15*D15*E15 -> 0
B16: 1 | C16: Surrogate Client Number (Voice Messaging ID Number) | D16: 12 | E16: 0 | F16: =B16*D16*E16 -> 0
B17: SUBTOTAL | F17: =SUM(F15:F16) -> 0
B19: LOCATION/ACCOUNT 850 230-3056 116 0561
B20: QTY | C20: DESCRIPTION | D20: MONTHS | E20: Charge | F20: Amount
B21: 2 | C21: Business Flat-Rate MultiLine | D21: 12 | E21: 0 | F21: =B21*D21*E21 -> 0
B22: 2 | C22: Federal Subscriber Line Charge | D22: 12 | E22: 0 | F22: =B22*D22*E22 -> 0
B23: 2 | C23: Federal Universal Svc Fee-Mult | D23: 12 | E23: 0 | F23: =B23*D23*E23 -> 0
B24: SUBTOTAL | F24: =SUM(F21:F23) -> 0
B26: LOCATION/ACCOUNT 850 230-3897 843 0565
B27: QTY | C27: DESCRIPTION | D27: MONTHS | E27: Charge | F27: Amount
B28: 1 | C28: Business Flat-Rate MultiLine | D28: 12 | E28: 0 | F28: =B28*D28*E28 -> 0
B29: 1 | C29: Federal Subscriber Line Charge | D29: 12 | E29: 0 | F29: =B29*D29*E29 -> 0
B30: 1 | C30: Federal Universal Svc Fee-Mult | D30: 12 | E30: 0 | F30: =B30*D30*E30 -> 0
B31: SUBTOTAL | F31: =SUM(F28:F30) -> 0
B33: LOCATION/ACCOUNT 850 230-5606 247 0560
B34: QTY | C34: DESCRIPTION | D34: MONTHS | E34: Charge | F34: Amount
B35: 1 | C35: Business Flat-Rate MultiLine | D35: 12 | E35: 0 | F35: =B35*D35*E35 -> 0
B36: 1 | C36: Federal Subscriber Line Charge | D36: 12 | E36: 0 | F36: =B36*D36*E36 -> 0
B37: 1 | C37: Federal Universal Svc Fee-Mult | D37: 12 | E37: 0 | F37: =B37*D37*E37 -> 0
B38: SUBTOTAL | F38: =SUM(F35:F37) -> 0
B40: LOCATION/ACCOUNT 850 233-3669 756 0566
B41: QTY | C41: DESCRIPTION | D41: MONTHS | E41: Charge | F41: Amount
B42: 1 | C42: Business Flat-Rate MultiLine | D42: 12 | E42: 0 | F42: =B42*D42*E42 -> 0
B43: 1 | C43: Federal Subscriber Line Charge | D43: 12 | E43: 0 | F43: =B43*D43*E43 -> 0
B44: 1 | C44: Federal Universal Svc Fee-Mult | D44: 12 | E44: 0 | F44: =B44*D44*E44 -> 0
B45: SUBTOTAL | F45: =SUM(F42:F44) -> 0
B47: LOCATION/ACCOUNT 850 234-2863 224 0562
...

Sheet OPT 4
C1: CUI
B2: OPTION 4 PRICING
B3: POP : 01 APRIL 2030 TO 31 MARCH 2031
B4: =[1]Summary!C6 -> 0
B5: =[1]Summary!C7 -> FFP
B6: Total | D6: =FY_Total -> 0
B8: LOCATION/ACCOUNT 850 M13-5313 001 0564
B9: QTY | C9: DESCRIPTION | D9: MONTHS | E9: Charge | F9: Amount
B10: 3 | C10: Foreign Directory Listing | D10: 12 | E10: 0 | F10: =B10*D10*E10 -> 0
B11: SUBTOTAL | F11: =SUM(F10:F10) -> 0
B13: LOCATION/ACCOUNT 865 M38-8015 001 1868
B14: QTY | C14: DESCRIPTION | D14: MONTHS | E14: Charge | F14: Amount
B15: 1 | C15: MemoryCall Annc 6 Minutes | D15: 12 | E15: 0 | F15: =B15*D15*E15 -> 0
B16: 1 | C16: Surrogate Client Number (Voice Messaging ID Number) | D16: 12 | E16: 0 | F16: =B16*D16*E16 -> 0
B17: SUBTOTAL | F17: =SUM(F15:F16) -> 0
B19: LOCATION/ACCOUNT 850 230-3056 116 0561
B20: QTY | C20: DESCRIPTION | D20: MONTHS | E20: Charge | F20: Amount
B21: 2 | C21: Business Flat-Rate MultiLine | D21: 12 | E21: 0 | F21: =B21*D21*E21 -> 0
B22: 2 | C22: Federal Subscriber Line Charge | D22: 12 | E22: 0 | F22: =B22*D22*E22 -> 0
B23: 2 | C23: Federal Universal Svc Fee-Mult | D23: 12 | E23: 0 | F23: =B23*D23*E23 -> 0
B24: SUBTOTAL | F24: =SUM(F21:F23) -> 0
B26: LOCATION/ACCOUNT 850 230-3897 843 0565
B27: QTY | C27: DESCRIPTION | D27: MONTHS | E27: Charge | F27: Amount
B28: 1 | C28: Business Flat-Rate MultiLine | D28: 12 | E28: 0 | F28: =B28*D28*E28 -> 0
B29: 1 | C29: Federal Subscriber Line Charge | D29: 12 | E29: 0 | F29: =B29*D29*E29 -> 0
B30: 1 | C30: Federal Universal Svc Fee-Mult | D30: 12 | E30: 0 | F30: =B30*D30*E30 -> 0
B31: SUBTOTAL | F31: =SUM(F28:F30) -> 0
B33: LOCATION/ACCOUNT 850 230-5606 247 0560
B34: QTY | C34: DESCRIPTION | D34: MONTHS | E34: Charge | F34: Amount
B35: 1 | C35: Business Flat-Rate MultiLine | D35: 12 | E35: 0 | F35: =B35*D35*E35 -> 0
B36: 1 | C36: Federal Subscriber Line Charge | D36: 12 | E36: 0 | F36: =B36*D36*E36 -> 0
B37: 1 | C37: Federal Universal Svc Fee-Mult | D37: 12 | E37: 0 | F37: =B37*D37*E37 -> 0
B38: SUBTOTAL | F38: =SUM(F35:F37) -> 0
B40: LOCATION/ACCOUNT 850 233-3669 756 0566
B41: QTY | C41: DESCRIPTION | D41: MONTHS | E41: Charge | F41: Amount
B42: 1 | C42: Business Flat-Rate MultiLine | D42: 12 | E42: 0 | F42: =B42*D42*E42 -> 0
B43: 1 | C43: Federal Subscriber Line Charge | D43: 12 | E43: 0 | F43: =B43*D43*E43 -> 0
B44: 1 | C44: Federal Universal Svc Fee-Mult | D44: 12 | E44: 0 | F44: =B44*D44*E44 -> 0
B45: SUBTOTAL | F45: =SUM(F42:F44) -> 0
B47: LOCATION/ACCOUNT 850 234-2863 224 0562
...

Sheet 52.217-8
C1: CUI
B2: 52.217-8 PRICING
B3: POP : 01 APRIL 2031 TO 30 SEPTEMBER 2031
B4: =[1]Summary!C6 -> 0
B5: =[1]Summary!C7 -> FFP
B6: Total | D6: =F37 -> 0
B8: LOCATION/ACCOUNT 850 M13-5313 001 0564
B9: QTY | C9: DESCRIPTION | D9: MONTHS | E9: Charge | F9: Amount
B10: 3 | C10: Foreign Directory Listing | D10: 6 | E10: 0 | F10: =B10*D10*E10 -> 0
B11: SUBTOTAL | F11: =SUM(F10:F10) -> 0
B13: LOCATION/ACCOUNT 865 M38-8015 001 1868
B14: QTY | C14: DESCRIPTION | D14: MONTHS | E14: Charge | F14: Amount
B15: 1 | C15: MemoryCall Annc 6 Minutes | D15: 6 | E15: 0 | F15: =B15*D15*E15 -> 0
B16: 1 | C16: Surrogate Client Number (Voice Messaging ID Number) | D16: 6 | E16: 0 | F16: =B16*D16*E16 -> 0
B17: SUBTOTAL | F17: =SUM(F15:F16) -> 0
B19: LOCATION/ACCOUNT 850 230-3056 116 0561
B20: QTY | C20: DESCRIPTION | D20: MONTHS | E20: Charge | F20: Amount
B21: 2 | C21: Business Flat-Rate MultiLine | D21: 6 | E21: 0 | F21: =B21*D21*E21 -> 0
B22: 2 | C22: Federal Subscriber Line Charge | D22: 6 | E22: 0 | F22: =B22*D22*E22 -> 0
B23: 2 | C23: Federal Universal Svc Fee-Mult | D23: 6 | E23: 0 | F23: =B23*D23*E23 -> 0
B24: SUBTOTAL | F24: =SUM(F21:F23) -> 0
B26: LOCATION/ACCOUNT 850 230-3897 843 0565
B27: QTY | C27: DESCRIPTION | D27: MONTHS | E27: Charge | F27: Amount
B28: 1 | C28: Business Flat-Rate MultiLine | D28: 6 | E28: 0 | F28: =B28*D28*E28 -> 0
B29: 1 | C29: Federal Subscriber Line Charge | D29: 6 | E29: 0 | F29: =B29*D29*E29 -> 0
B30: 1 | C30: Federal Universal Svc Fee-Mult | D30: 6 | E30: 0 | F30: =B30*D30*E30 -> 0
B31: SUBTOTAL | F31: =SUM(F28:F30) -> 0
B33: LOCATION/ACCOUNT 850 230-5606 247 0560
B34: QTY | C34: DESCRIPTION | D34: MONTHS | E34: Charge | F34: Amount
B35: 1 | C35: Business Flat-Rate MultiLine | D35: 6 | E35: 0 | F35: =B35*D35*E35 -> 0
B36: 1 | C36: Federal Subscriber Line Charge | D36: 6 | E36: 0 | F36: =B36*D36*E36 -> 0
B37: 1 | C37: Federal Universal Svc Fee-Mult | D37: 6 | E37: 0 | F37: =B37*D37*E37 -> 0
B38: SUBTOTAL | F38: =SUM(F35:F37) -> 0
B40: LOCATION/ACCOUNT 850 233-3669 756 0566
B41: QTY | C41: DESCRIPTION | D41: MONTHS | E41: Charge | F41: Amount
B42: 1 | C42: Business Flat-Rate MultiLine | D42: 6 | E42: 0 | F42: =B42*D42*E42 -> 0
B43: 1 | C43: Federal Subscriber Line Charge | D43: 6 | E43: 0 | F43: =B43*D43*E43 -> 0
B44: 1 | C44: Federal Universal Svc Fee-Mult | D44: 6 | E44: 0 | F44: =B44*D44*E44 -> 0
B45: SUBTOTAL | F45: =SUM(F42:F44) -> 0
B47: LOCATION/ACCOUNT 850 234-2863 224 0562
...
