Workbook

Sheet Schedule
A1: SCHEDULE OF WORK
A2: (TO BE COMPLETED AND SUBMITTED WITH THE OFFER)
A4: ITEM NO. | B4: SUPPLIES/SERVICES | E4: AMOUNT
A6: 0001 | B6: BASE PERIOD - RECURRING WORK
B7: Price to perform Recurring work, for the 12-month Base Period, in accordance with all the terms of this contract. | D7: $ | E7: ='Base Recurring'!F144 -> 0
A9: 0002 | B9: BASE PERIOD - NON-RECURRING WORK
B10: Price to perform Non-Recurring work, for the 12-month Base Period, in accordance with all the terms of this contract. | C10: EST | D10: $ | E10: ='Base Non-Recurring '!G17 -> 108000
B12: TOTAL PRICE FOR CONTRACT LINE ITEM NUMBERS
B13: (CLINs) 0001 AND 0002 (BASE PERIOD) | D13: $ | E13: =SUM(E7,E10) -> 108000
A16: 0003 | B16: OPTION PERIOD ONE - RECURRING WORK
B17: Price to perform Recurring work, for the 12-month Option Period One, in accordance with all the terms of this contract. | D17: $ | E17: ='OY 1 Recurring'!F144 -> 0
A19: 0004 | B19: OPTION PERIOD ONE - NON-RECURRING WORK
B20: Price to perform Non-Recurring work, for the 12-month Option Period One, in accordance with all the terms of this contract. | C20: EST | D20: $ | E20: ='OY 1 Non-Recurring'!G17 -> 108000
B22: TOTAL PRICE FOR CONTRACT LINE ITEM NUMBERS
B23: (CLINs) 0003 AND 0004 (OPTION PERIOD ONE) | D23: $ | E23: =SUM(E17,E20) -> 108000
A26: 0005 | B26: OPTION PERIOD TWO - RECURRING WORK
B27: Price to perform Recurring work, for the 12-month Option Period Two, in accordance with all the terms of this contract. | D27: $ | E27: ='OY 2 Recurring'!F144 -> 0
A29: 0006 | B29: OPTION PERIOD TWO - NON-RECURRING WORK
B30: Price to perform Non-Recurring work, for the 12-month Option Period Two, in accordance with all the terms of this contract. | C30: EST | D30: $ | E30: ='OY 2 Non-Recurring'!G17 -> 108000
B32: TOTAL PRICE FOR CONTRACT LINE ITEM NUMBERS
B33: (CLINs) 0005 AND 0006 (OPTION PERIOD TWO) | D33: $ | E33: =SUM(E27,E30) -> 108000
A36: 0007 | B36: OPTION PERIOD THREE - RECURRING WORK
B37: Price to perform Recurring work, for the 12-month Option Period Three in accordance with all the terms of this contract. | D37: $ | E37: ='OY 3 Recurring'!F144 -> 0
A39: 0008 | B39: OPTION PERIOD THREE - NON-RECURRING WORK
B40: Price to perform Non-Recurring work, for the 12-month Option Period Three in accordance with all the terms of this contract. | C40: EST | D40: $ | E40: ='OY 3 Non-Recurring'!G17 -> 108000
B42: TOTAL PRICE FOR CONTRACT LINE ITEM NUMBERS
B43: (CLINs) 0007 AND 0008 (OPTION PERIOD THREE) | D43: $ | E43: =SUM(E37,E40) -> 108000
A46: 0009 | B46: OPTION PERIOD FOUR - RECURRING WORK
B47: Price to perform Recurring work, for the 12-month Option Period Four in accordance with all the terms of this contract. | D47: $ | E47: ='OY 4 Recurring'!F144 -> 0
A49: 0010 | B49: OPTION PERIOD FOUR - NON-RECURRING WORK
B50: Price to perform Non-Recurring work, for the 12-month Option Period Four in accordance with all the terms of this contract. | C50: EST | D50: $ | E50: ='OY 4 Non-Recurring'!G17 -> 108000
B52: TOTAL PRICE FOR CONTRACT LINE ITEM NUMBERS
B53: (CLINs) 0009 AND 0010 (OPTION PERIOD FOUR) | D53: $ | E53: =SUM(E47,E50) -> 108000
A56: 0011 | B56: OPTION TO EXTEND SERVICES- RECURRING WORK
B57: Price to perform Recurring work, for the 6-month Option to Extend Services in accordance with all the terms of this contract | D57: $ | E57: ='Opt to Extend Recurring'!F144 -> 0
A59: 0012 | B59: OPTION TO EXTEND SERVICES - NON-RECURRING WORK
B60: Price to perform non-recurring work, for the 6-month Option to Extend Services, in accordance with all the terms of this contract. | C60: EST | D60: $ | E60: ='Opt Extend Non-Recurring '!G17 -> 54000
B62: TOTAL PRICE FOR CONTRACT LINE ITEM NUMBERS
B63: (CLINs) 0011 AND 0012 (OPTION TO EXTEND SERVICES) | D63: $ | E63: =SUM(E57,E60) -> 54000
B66: TOTAL PRICE FOR CONTRACT LINE ITEM NUMBERS
...

Sheet Base Recurring
H1: OFFERER PROPOSED UNIT PRICE Enter proposed unit price in this column. Price will automatically copy to the UNIT PRICE cell rounded to two decimal places.
A2: ATTACHMENT 0200000-12
A3: EXHIBIT LINE ITEM NUMBERS
A4: SOLICITATION/CONTRACT #N62478-25-D-2431
A5: EXHIBIT A - CLIN 9000
A7: Line Item 0001 Recurring Work - Base Period
A8: PROVIDE PRICES FOR FACILITY INVESTMENT - RECURRING WORK - IN ACCORDANCE WITH SPEC ITEM 3
A9: ELINs A001 through A016
A10: ELIN /Sub ELIN | B10: Description | C10: Quantity | D10: Unit of Issue | E10: Unit Price | F10: Total | G10: CAC
A11: A001 | B11: PHNSY - FACILITY VENTILATION INTAKE AND EXHAUST FILTERS AND DUST COLLECTOR FILTER CARTRIDGES
A12: A001AA | B12: Emergency Service Orders, Spec Item 3.1.1 | C12: 12 | D12: MO | E12: =ROUND(H12,2) -> 0 | F12: =C12*E12 -> 0
A13: A001AB | B13: Urgent Service Orders, Spec item 3.1.2 | C13: 12 | D13: MO | E13: =ROUND(H13,2) -> 0 | F13: =C13*E13 -> 0
A14: A001AC | B14: Routine Service Orders, Spec Item 3.1.3 | C14: 12 | D14: MO | E14: =ROUND(H14,2) -> 0 | F14: =C14*E14 -> 0
A15: A001AD | B15: Perform Semiannual Maintenance and Filter Servicing for Building 1704 IAW Annex 1502000 Spec Item 3.2.1 and Attachment 1502000-02. | C15: 2 | D15: SA | E15: =ROUND(H15,2) -> 0 | F15: =C15*E15 -> 0
A16: A001AE | B16: Perform Semi-Annual Maintenance and Exhaust Filter Servicing for Buildings 1701 and 1703 only IAW Annex 1502000 Spec Item 3.2.1 and Attachment 1502000-02 | C16: 2 | D16: SA | E16: =ROUND(H16,2) -> 0 | F16: =C16*E16 -> 0
A17: A001AF | B17: Perform Annual Maintenance and Filter Servicing for Buildings 1701 and 1703 IAW Annex 1502000 Spec Item 3.2.1 and Attachment 1502000-02 | C17: 1 | D17: A | E17: =ROUND(H17,2) -> 0 | F17: =C17*E17 -> 0
B18: Subtotal - PHNSY -Facility Ventilation Intake and Exhaust Filters and Dust Collector Filter Cartridges | F18: =SUM(F12:F17) -> 0
A20: A002 | B20: CNRH WATER SYSTEMS MAINTENANCE (Swimming Pools and Water Fountain)
A21: A002AA | B21: Emergency Service Orders, Spec Item 3.1.1 | C21: 12 | D21: MO | E21: =ROUND(H21,2) -> 0 | F21: =C21*E21 -> 0
A22: A002AB | B22: Urgent Service Orders, Spec item 3.1.2 | C22: 12 | D22: MO | E22: =ROUND(H22,2) -> 0 | F22: =C22*E22 -> 0
A23: A002AC | B23: Routine Service Orders, Spec Item 3.1.3 | C23: 12 | D23: MO | E23: =ROUND(H23,2) -> 0 | F23: =C23*E23 -> 0
A24: A002AD | B24: Provide Recurring Maintenance for Memorial Fountain - 1695 IAW Annex 1502000 Spec Item 3.2.2 and Attachments 1502000-03 and 1502000-04 | C24: 12 | D24: MO | E24: =ROUND(H24,2) -> 0 | F24: =C24*E24 -> 0
A25: A002AE | B25: Provide Recurring Maintenance for Advanced SEAL Delivery System (ASDS) Facility - Building 995 IAW Annex 1502000 Spec Item 3.2.2 and Attachments 1502000-03 and 1502000-04 | C25: 12 | D25: MO | E25: =ROUND(H25,2) -> 0 | F25: =C25*E25 -> 0
A26: A002AF | B26: Provide Recurring Maintenance for Advanced SEAL Delivery System (ASDS) Facility - Building 1062 IAW Annex 1502000 Spec Item 3.2.2 and Attachments 1502000-03 and 1502000-04 | C26: 12 | D26: MO | E26: =H26 -> 0 | F26: =E26*C26 -> 0
B27: Subtotal - CNRH WATER SYSTEMS MAINTENANCE (Swimming Pools and Water Fountain) | F27: =SUM(F21:F26) -> 0
A30: A003 | B30: MCBH - WATER SYSTEMS MAINTENANCE (Swimming Pools)
A31: A003AA | B31: Emergency Service Orders, Spec Item 3.1.1 | C31: 12 | D31: MO | E31: =ROUND(H31,2) -> 0 | F31: =C31*E31 -> 0
A32: A003AB | B32: Urgent Service Orders, Spec item 3.1.2 | C32: 12 | D32: MO | E32: =ROUND(H32,2) -> 0 | F32: =C32*E32 -> 0
A33: A003AC | B33: Routine Service Orders, Spec Item 3.1.3 | C33: 12 | D33: MO | E33: =ROUND(H33,2) -> 0 | F33: =C33*E33 -> 0
A34: A003AD | B34: Provide Recurring Maintenance for Camp Smith Base Acitivity Swimming Pool - Facility No. 125 IAW Annex 1502000 Spec Item 3.2.2 and Attachments 1502000-03 and 1502000-04 | C34: 12 | D34: MO | E34: =ROUND(H34,2) -> 0 | F34: =C34*E34 -> 0
A35: A003AE | B35: Provide Recurring Maintenance for Manana Housing Area Swimming Pool and Wading Pool - Facility No. 840 IAW Annex 1502000 Spec Item 3.2.2 and Attachments 1502000-03 and 1502000-04 | C35: 12 | D35: MO | E35: =ROUND(H35,2) -> 0 | F35: =C35*E35 -> 0
B36: Subtotal - MCBH WATER SYSTEMS MAINTENANCE (Swimming Pools) | F36: =SUM(F31:F35) -> 0
A38: A004 | B38: MWR - WATER SYSTEMS MAINTENANCE (Swimming Pools)
A39: A004AA | B39: Emergency Service Orders, Spec Item 3.1.1 | C39: 12 | D39: MO | E39: =ROUND(H39,2) -> 0 | F39: =C39*E39 -> 0
A40: A004AB | B40: Urgent Service Orders, Spec item 3.1.2 | C40: 12 | D40: MO | E40: =ROUND(H40,2) -> 0 | F40: =C40*E40 -> 0
A41: A004AC | B41: Routine Service Orders, Spec Item 3.1.3 | C41: 12 | D41: MO | E41: =ROUND(H41,2) -> 0 | F41: =C41*E41 -> 0
A42: A004AD | B42: Provide Recurring Maintenance for Arizona Pool IAW Annex 1502000 Spec Item 3.2.2 and Attachments 1502000-03 and 1502000-04 | C42: 12 | D42: MO | E42: =ROUND(H42,2) -> 0 | F42: =C42*E42 -> 0
A43: A004AE | B43: Provide Recurring Maintenance for Hickam Family Pool IAW Annex 1502000 Spec Item 3.2.2 and Attachments 1502000-03 and 1502000-04 | C43: 12 | D43: MO | E43: =ROUND(H43,2) -> 0 | F43: =C43*E43 -> 0
A44: A004AF | B44: Provide Recurring Maintenance for Hickam Training Pool IAW Annex 1502000 Spec Item 3.2.2 and Attachments 1502000-03 and 1502000-04 | C44: 12 | D44: MO | E44: =ROUND(H44,2) -> 0 | F44: =C44*E44 -> 0
A45: A004AG | B45: Provide Recurring Maintenance for Scott Pool IAW Annex 1502000 Spec Item 3.2.2 and Attachments 1502000-03 and 1502000-04 | C45: 12 | D45: MO | E45: =ROUND(H45,2) -> 0 | F45: =C45*E45 -> 0
...

Sheet Base Non-Recurring 
A1: ATTACHMENT 0200000-12 | I1: OFFERER PROPOSED UNIT PRICE Enter proposed unit price in this column. Price will automatically copy to the UNIT PRICE cell rounded to two decimal places.
A2: EXHIBIT LINE ITEM NUMBERS
A3: SOLICITATION/CONTRACT # N62478-25-R-2431
A4: EXHIBIT A - CLIN 9000
A6: Line Item 0002 Nonrecurring Work- Base Period
A7: PROVIDE PRICES TO PERFORM NONRECURRING WORK IN ACCORDANCE WITH SECTION C, SPEC ITEM 4
A8: ELINs A700 through A704
A9: ELIN | B9: Description | C9: Description Extended | D9: Est. Qty | E9: Unit of Issue | F9: Unit Price | G9: Extended Price | H9: IMAP CAC
A10: A700 | B10: Unit Priced Labor Hour Work - MUST BE NEGOTIATED BY KO | C10: The Contractor shall perform all UPL work in accordance with the scope and delivery schedule negotiated per each task order. Refer to: Annex 0200000 Managmenent and Administration, Specification Items 2.15.2 Unit Priced Labor (UPL)Work (Negotiated) for description of UPL Work and 2.15.2.1.1 Labor Requirements. Refer to: Annex 0200000 Managmenent and Administration, Attachment 0200000-01 - Definitions and Acronyms for description of Unit Priced Labor (UPL) Hour. Task order completion times will be specified on each task order. | D10: 2500 | E10: HR | F10: =ROUND(I10,2) -> 0 | G10: =SUM(F10*D10) -> 0 | H10: 717S
A11: A701 | B11: Direct Material and Construction Equipment -MUST BE NEGOTIATED BY KO | C11: The Contractor shall provide all materials and construction equipment to perform Unit Priced Labor work per the scope and delivery schedule specified in the order. Refer to: Annex 0200000 Managmenent and Administration, Specification Items 2.15.2 Unit Priced Labor (UPL)Work (Negotiated) for description of UPL Work and 2.15.2.1.2 Direct Material and Construction Equipment Requirements. Refer to: Annex 0200000 Managmenent and Administration, Attachment 0200000-01 - Definitions and Acronyms for description of Direct Material Costs and Construction Equipment. Task order completion times will be specified on each task order. | D11: 108000 | E11: DO | F11: 1 | G11: =SUM(D11*F11) -> 108000 | H11: 717S
A12: A702 | B12: FILTER MAINT | C12: One Time - Facility Ventilation Intake & Exhaust Filters & Dust Collector Filter Cartridges. Services equal to one regularly scheduled Recurring Work service. | D12: 2 | E12: EA | F12: =ROUND(I12,2) -> 0 | G12: =SUM(F12*D12) -> 0 | H12: 717S
A13: A703 | B13: LOCKSMITH | C13: Providing of key duplication services. Services shall be same as available to the general public and prices shall be as low or lower than those charged the Contractor’s most favored customer for comparable quantities under similar terms and conditions, in addition to any discounts for prompt payment. | D13: 100 | E13: EA | F13: =ROUND(I13,2) -> 0 | G13: =SUM(F13*D13) -> 0 | H13: 717S
A14: ELIN | B14: Description | C14: Description Extended | D14: Est. Qty | E14: Unit of Issue | F14: Coefficient(1) | G14: Total Amount | H14: IMAP CAC
A15: A704 | B15: Unit Price - Coefficient(1) | C15: Contractor's coefficient used to adjust the Unit Prices provided in the Unit Price List Attachment 0200000-18 | D15: 10000 | E15: DO | F15: =ROUND(I15,2) -> 0 | G15: =SUM(D15*F15) -> 0
B17: TOTAL LINE ITEMS ELINs A700 through A704 | G17: =SUM(G10:G13,G15) -> 108000
B18: (Enter this amount into Section B, Item No. 0002, Net Amount)
A21: Notes:
A22: (1) | B22: Submit coefficient in accordance with Annex 0200000, Spec Item 2.15.2.3. The coefficient for Unit Prices shall be the offeror's adjustment to the Government's unit prices. The coefficient must incorporate all projected and potential costs including overhead, profit, insurance, and all other contingencies. There will be no adjustments to the coefficient after award of the contract. The coefficient shall not include any allowance for any contingency to cover increased cost in the Service Contract Labor Standards wage rates for which adjustment is provided under FAR 52.222-43.
B33: Abbreviations:
B34: DO | C34: Dollars
B35: EA | C35: Each
B36: HR | C36: Hour

Sheet OY 1 Recurring
H1: OFFERER PROPOSED UNIT PRICE Enter proposed unit price in this column. Price will automatically copy to the UNIT PRICE cell rounded to two decimal places.
A2: ATTACHMENT 0200000-13
A3: EXHIBIT LINE ITEM NUMBERS
A4: SOLICITATION/CONTRACT #N62478-25-D-2431
A5: EXHIBIT B - CLIN 9001
A7: Line Item 0003 Recurring Work - Option Period One
A8: PROVIDE PRICES FOR FACILITY INVESTMENT - RECURRING WORK - IN ACCORDANCE WITH SPEC ITEM 3
A9: ELINs B001 through B016
A10: ELIN /Sub ELIN | B10: Description | C10: Quantity | D10: Unit of Issue | E10: Unit Price | F10: Total | G10: CAC
A11: B001 | B11: PHNSY - FACILITY VENTILATION INTAKE AND EXHAUST FILTERS AND DUST COLLECTOR FILTER CARTRIDGES
A12: B001AA | B12: Emergency Service Orders, Spec Item 3.1.1 | C12: 12 | D12: MO | E12: =ROUND(H12,2) -> 0 | F12: =C12*E12 -> 0
A13: B001AB | B13: Urgent Service Orders, Spec item 3.1.2 | C13: 12 | D13: MO | E13: =ROUND(H13,2) -> 0 | F13: =C13*E13 -> 0
A14: B001AC | B14: Routine Service Orders, Spec Item 3.1.3 | C14: 12 | D14: MO | E14: =ROUND(H14,2) -> 0 | F14: =C14*E14 -> 0
A15: B001AD | B15: Perform Semiannual Maintenance and Filter Servicing for Building 1704 IAW Annex 1502000 Spec Item 3.2.1 and Attachment 1502000-02. | C15: 2 | D15: SA | E15: =ROUND(H15,2) -> 0 | F15: =C15*E15 -> 0
A16: B001AE | B16: Perform Semi-Annual Maintenance and Exhaust Filter Servicing for Buildings 1701 and 1703 only IAW Annex 1502000 Spec Item 3.2.1 and Attachment 1502000-02 | C16: 2 | D16: SA | E16: =ROUND(H16,2) -> 0 | F16: =C16*E16 -> 0
A17: B001AF | B17: Perform Annual Maintenance and Filter Servicing for Buildings 1701 and 1703 IAW Annex 1502000 Spec Item 3.2.1 and Attachment 1502000-02 | C17: 1 | D17: A | E17: =ROUND(H17,2) -> 0 | F17: =C17*E17 -> 0
B18: Subtotal - PHNSY -Facility Ventilation Intake and Exhaust Filters and Dust Collector Filter Cartridges | F18: =SUM(F12:F17) -> 0
A20: B002 | B20: CNRH WATER SYSTEMS MAINTENANCE (Swimming Pools and Water Fountain)
A21: B002AA | B21: Emergency Service Orders, Spec Item 3.1.1 | C21: 12 | D21: MO | E21: =ROUND(H21,2) -> 0 | F21: =C21*E21 -> 0
A22: B002AB | B22: Urgent Service Orders, Spec item 3.1.2 | C22: 12 | D22: MO | E22: =ROUND(H22,2) -> 0 | F22: =C22*E22 -> 0
A23: B002AC | B23: Routine Service Orders, Spec Item 3.1.3 | C23: 12 | D23: MO | E23: =ROUND(H23,2) -> 0 | F23: =C23*E23 -> 0
A24: B002AD | B24: Provide Recurring Maintenance for Memorial Fountain - 1695 IAW Annex 1502000 Spec Item 3.2.2 and Attachments 1502000-03 and 1502000-04 | C24: 12 | D24: MO | E24: =ROUND(H24,2) -> 0 | F24: =C24*E24 -> 0
A25: B002AE | B25: Provide Recurring Maintenance for Advanced SEAL Delivery System (ASDS) Facility - Building 995 IAW Annex 1502000 Spec Item 3.2.2 and Attachments 1502000-03 and 1502000-04 | C25: 12 | D25: MO | E25: =ROUND(H25,2) -> 0 | F25: =C25*E25 -> 0
A26: B002AF | B26: Provide Recurring Maintenance for Advanced SEAL Delivery System (ASDS) Facility - Building 1062 IAW Annex 1502000 Spec Item 3.2.2 and Attachments 1502000-03 and 1502000-04 | C26: 12 | D26: MO | E26: =H26 -> 0 | F26: =E26*C26 -> 0
B27: Subtotal - CNRH WATER SYSTEMS MAINTENANCE (Swimming Pools and Water Fountain) | F27: =SUM(F21:F26) -> 0
A30: B003 | B30: MCBH - WATER SYSTEMS MAINTENANCE (Swimming Pools)
A31: B003AA | B31: Emergency Service Orders, Spec Item 3.1.1 | C31: 12 | D31: MO | E31: =ROUND(H31,2) -> 0 | F31: =C31*E31 -> 0
A32: B003AB | B32: Urgent Service Orders, Spec item 3.1.2 | C32: 12 | D32: MO | E32: =ROUND(H32,2) -> 0 | F32: =C32*E32 -> 0
A33: B003AC | B33: Routine Service Orders, Spec Item 3.1.3 | C33: 12 | D33: MO | E33: =ROUND(H33,2) -> 0 | F33: =C33*E33 -> 0
A34: B003AD | B34: Provide Recurring Maintenance for Camp Smith Base Acitivity Swimming Pool - Facility No. 125 IAW Annex 1502000 Spec Item 3.2.2 and Attachments 1502000-03 and 1502000-04 | C34: 12 | D34: MO | E34: =ROUND(H34,2) -> 0 | F34: =C34*E34 -> 0
A35: B003AE | B35: Provide Recurring Maintenance for Manana Housing Area Swimming Pool and Wading Pool - Facility No. 840 IAW Annex 1502000 Spec Item 3.2.2 and Attachments 1502000-03 and 1502000-04 | C35: 12 | D35: MO | E35: =ROUND(H35,2) -> 0 | F35: =C35*E35 -> 0
B36: Subtotal - MCBH WATER SYSTEMS MAINTENANCE (Swimming Pools) | F36: =SUM(F31:F35) -> 0
A38: B004 | B38: MWR - WATER SYSTEMS MAINTENANCE (Swimming Pools)
A39: B004AA | B39: Emergency Service Orders, Spec Item 3.1.1 | C39: 12 | D39: MO | E39: =ROUND(H39,2) -> 0 | F39: =C39*E39 -> 0
A40: B004AB | B40: Urgent Service Orders, Spec item 3.1.2 | C40: 12 | D40: MO | E40: =ROUND(H40,2) -> 0 | F40: =C40*E40 -> 0
A41: B004AC | B41: Routine Service Orders, Spec Item 3.1.3 | C41: 12 | D41: MO | E41: =ROUND(H41,2) -> 0 | F41: =C41*E41 -> 0
A42: B004AD | B42: Provide Recurring Maintenance for Arizona Pool IAW Annex 1502000 Spec Item 3.2.2 and Attachments 1502000-03 and 1502000-04 | C42: 12 | D42: MO | E42: =ROUND(H42,2) -> 0 | F42: =C42*E42 -> 0
A43: B004AE | B43: Provide Recurring Maintenance for Hickam Family Pool IAW Annex 1502000 Spec Item 3.2.2 and Attachments 1502000-03 and 1502000-04 | C43: 12 | D43: MO | E43: =ROUND(H43,2) -> 0 | F43: =C43*E43 -> 0
A44: B004AF | B44: Provide Recurring Maintenance for Hickam Training Pool IAW Annex 1502000 Spec Item 3.2.2 and Attachments 1502000-03 and 1502000-04 | C44: 12 | D44: MO | E44: =ROUND(H44,2) -> 0 | F44: =C44*E44 -> 0
A45: B004AG | B45: Provide Recurring Maintenance for Scott Pool IAW Annex 1502000 Spec Item 3.2.2 and Attachments 1502000-03 and 1502000-04 | C45: 12 | D45: MO | E45: =ROUND(H45,2) -> 0 | F45: =C45*E45 -> 0
...

Sheet OY 1 Non-Recurring
A1: ATTACHMENT 0200000-13 | I1: OFFERER PROPOSED UNIT PRICE Enter proposed unit price in this column. Price will automatically copy to the UNIT PRICE cell rounded to two decimal places.
A2: EXHIBIT LINE ITEM NUMBERS
A3: SOLICITATION/CONTRACT # N62478-25-R-2431
A4: EXHIBIT B - CLIN 9001
A6: Line Item 0004 Nonrecurring Work- Option Period One
A7: PROVIDE PRICES TO PERFORM NONRECURRING WORK IN ACCORDANCE WITH SECTION C, SPEC ITEM 4
A8: ELINs B700 through B704
A9: ELIN | B9: Description | C9: Description Extended | D9: Est. Qty | E9: Unit of Issue | F9: Unit Price | G9: Extended Price | H9: IMAP CAC
A10: B700 | B10: Unit Priced Labor Hour Work - MUST BE NEGOTIATED BY KO | C10: The Contractor shall perform all UPL work in accordance with the scope and delivery schedule negotiated per each task order. Refer to: Annex 0200000 Managmenent and Administration, Specification Items 2.15.2 Unit Priced Labor (UPL)Work (Negotiated) for description of UPL Work and 2.15.2.1.1 Labor Requirements. Refer to: Annex 0200000 Managmenent and Administration, Attachment 0200000-01 - Definitions and Acronyms for description of Unit Priced Labor (UPL) Hour. Task order completion times will be specified on each task order. | D10: 2500 | E10: HR | F10: =ROUND(I10,2) -> 0 | G10: =SUM(F10*D10) -> 0 | H10: 717S
A11: B701 | B11: Direct Material and Construction Equipment -MUST BE NEGOTIATED BY KO | C11: The Contractor shall provide all materials and construction equipment to perform Unit Priced Labor work per the scope and delivery schedule specified in the order. Refer to: Annex 0200000 Managmenent and Administration, Specification Items 2.15.2 Unit Priced Labor (UPL)Work (Negotiated) for description of UPL Work and 2.15.2.1.2 Direct Material and Construction Equipment Requirements. Refer to: Annex 0200000 Managmenent and Administration, Attachment 0200000-01 - Definitions and Acronyms for description of Direct Material Costs and Construction Equipment. Task order completion times will be specified on each task order. | D11: 108000 | E11: DO | F11: 1 | G11: =SUM(D11*F11) -> 108000 | H11: 717S
A12: B702 | B12: FILTER MAINT | C12: One Time - Facility Ventilation Intake & Exhaust Filters & Dust Collector Filter Cartridges. Services equal to one regularly scheduled Recurring Work service. | D12: 2 | E12: EA | F12: =ROUND(I12,2) -> 0 | G12: =SUM(F12*D12) -> 0 | H12: 717S
A13: B703 | B13: LOCKSMITH | C13: Providing of key duplication services. Services shall be same as available to the general public and prices shall be as low or lower than those charged the Contractor’s most favored customer for comparable quantities under similar terms and conditions, in addition to any discounts for prompt payment. | D13: 100 | E13: EA | F13: =ROUND(I13,2) -> 0 | G13: =SUM(F13*D13) -> 0 | H13: 717S
A14: ELIN | B14: Description | C14: Description Extended | D14: Est. Qty | E14: Unit of Issue | F14: Coefficient(1) | G14: Total Amount | H14: IMAP CAC
A15: B704 | B15: Unit Price - Coefficient(1) | C15: Contractor's coefficient used to adjust the Unit Prices provided in the Unit Price List Attachment 0200000-18 | D15: 10000 | E15: DO | F15: =ROUND(I15,2) -> 0 | G15: =SUM(D15*F15) -> 0
B17: TOTAL LINE ITEMS ELINs B700 through B704 | G17: =SUM(G10:G13,G15) -> 108000
B18: (Enter this amount into Section B, Item No. 0004, Net Amount)
A21: Notes:
A22: (1) | B22: Submit coefficient in accordance with Annex 0200000, Spec Item 2.15.2.3. The coefficient for Unit Prices shall be the offeror's adjustment to the Government's unit prices. The coefficient must incorporate all projected and potential costs including overhead, profit, insurance, and all other contingencies. There will be no adjustments to the coefficient after award of the contract. The coefficient shall not include any allowance for any contingency to cover increased cost in the Service Contract Labor Standards wage rates for which adjustment is provided under FAR 52.222-43.
B33: Abbreviations:
B34: DO | C34: Dollars
B35: EA | C35: Each
B36: HR | C36: Hour

Sheet OY 2 Recurring
H1: OFFERER PROPOSED UNIT PRICE Enter proposed unit price in this column. Price will automatically copy to the UNIT PRICE cell rounded to two decimal places.
A2: ATTACHMENT 0200000-14
A3: EXHIBIT LINE ITEM NUMBERS
A4: SOLICITATION/CONTRACT #N62478-25-D-2431
A5: EXHIBIT C - CLIN 9002
A7: Line Item 0005 Recurring Work - Option Period Two
A8: PROVIDE PRICES FOR FACILITY INVESTMENT - RECURRING WORK - IN ACCORDANCE WITH SPEC ITEM 3
A9: ELINs C001 through C016
A10: ELIN /Sub ELIN | B10: Description | C10: Quantity | D10: Unit of Issue | E10: Unit Price | F10: Total | G10: CAC
A11: C001 | B11: PHNSY - FACILITY VENTILATION INTAKE AND EXHAUST FILTERS AND DUST COLLECTOR FILTER CARTRIDGES
A12: C001AA | B12: Emergency Service Orders, Spec Item 3.1.1 | C12: 12 | D12: MO | E12: =ROUND(H12,2) -> 0 | F12: =C12*E12 -> 0
A13: C001AB | B13: Urgent Service Orders, Spec item 3.1.2 | C13: 12 | D13: MO | E13: =ROUND(H13,2) -> 0 | F13: =C13*E13 -> 0
A14: C001AC | B14: Routine Service Orders, Spec Item 3.1.3 | C14: 12 | D14: MO | E14: =ROUND(H14,2) -> 0 | F14: =C14*E14 -> 0
A15: C001AD | B15: Perform Semiannual Maintenance and Filter Servicing for Building 1704 IAW Annex 1502000 Spec Item 3.2.1 and Attachment 1502000-02. | C15: 2 | D15: SA | E15: =ROUND(H15,2) -> 0 | F15: =C15*E15 -> 0
A16: C001AE | B16: Perform Semi-Annual Maintenance and Exhaust Filter Servicing for Buildings 1701 and 1703 only IAW Annex 1502000 Spec Item 3.2.1 and Attachment 1502000-02 | C16: 2 | D16: SA | E16: =ROUND(H16,2) -> 0 | F16: =C16*E16 -> 0
A17: C001AF | B17: Perform Annual Maintenance and Filter Servicing for Buildings 1701 and 1703 IAW Annex 1502000 Spec Item 3.2.1 and Attachment 1502000-02 | C17: 1 | D17: A | E17: =ROUND(H17,2) -> 0 | F17: =C17*E17 -> 0
B18: Subtotal - PHNSY -Facility Ventilation Intake and Exhaust Filters and Dust Collector Filter Cartridges | F18: =SUM(F12:F17) -> 0
A20: C002 | B20: CNRH WATER SYSTEMS MAINTENANCE (Swimming Pools and Water Fountain)
A21: C002AA | B21: Emergency Service Orders, Spec Item 3.1.1 | C21: 12 | D21: MO | E21: =ROUND(H21,2) -> 0 | F21: =C21*E21 -> 0
A22: C002AB | B22: Urgent Service Orders, Spec item 3.1.2 | C22: 12 | D22: MO | E22: =ROUND(H22,2) -> 0 | F22: =C22*E22 -> 0
A23: C002AC | B23: Routine Service Orders, Spec Item 3.1.3 | C23: 12 | D23: MO | E23: =ROUND(H23,2) -> 0 | F23: =C23*E23 -> 0
A24: C002AD | B24: Provide Recurring Maintenance for Memorial Fountain - 1695 IAW Annex 1502000 Spec Item 3.2.2 and Attachments 1502000-03 and 1502000-04 | C24: 12 | D24: MO | E24: =ROUND(H24,2) -> 0 | F24: =C24*E24 -> 0
A25: C002AE | B25: Provide Recurring Maintenance for Advanced SEAL Delivery System (ASDS) Facility - Building 995 IAW Annex 1502000 Spec Item 3.2.2 and Attachments 1502000-03 and 1502000-04 | C25: 12 | D25: MO | E25: =ROUND(H25,2) -> 0 | F25: =C25*E25 -> 0
A26: C002AF | B26: Provide Recurring Maintenance for Advanced SEAL Delivery System (ASDS) Facility - Building 1062 IAW Annex 1502000 Spec Item 3.2.2 and Attachments 1502000-03 and 1502000-04 | C26: 12 | D26: MO | E26: =H26 -> 0 | F26: =E26*C26 -> 0
B27: Subtotal - CNRH WATER SYSTEMS MAINTENANCE (Swimming Pools and Water Fountain) | F27: =SUM(F21:F26) -> 0
A30: C003 | B30: MCBH - WATER SYSTEMS MAINTENANCE (Swimming Pools)
A31: C003AA | B31: Emergency Service Orders, Spec Item 3.1.1 | C31: 12 | D31: MO | E31: =ROUND(H31,2) -> 0 | F31: =C31*E31 -> 0
A32: C003AB | B32: Urgent Service Orders, Spec item 3.1.2 | C32: 12 | D32: MO | E32: =ROUND(H32,2) -> 0 | F32: =C32*E32 -> 0
A33: C003AC | B33: Routine Service Orders, Spec Item 3.1.3 | C33: 12 | D33: MO | E33: =ROUND(H33,2) -> 0 | F33: =C33*E33 -> 0
A34: C003AD | B34: Provide Recurring Maintenance for Camp Smith Base Acitivity Swimming Pool - Facility No. 125 IAW Annex 1502000 Spec Item 3.2.2 and Attachments 1502000-03 and 1502000-04 | C34: 12 | D34: MO | E34: =ROUND(H34,2) -> 0 | F34: =C34*E34 -> 0
A35: C003AE | B35: Provide Recurring Maintenance for Manana Housing Area Swimming Pool and Wading Pool - Facility No. 840 IAW Annex 1502000 Spec Item 3.2.2 and Attachments 1502000-03 and 1502000-04 | C35: 12 | D35: MO | E35: =ROUND(H35,2) -> 0 | F35: =C35*E35 -> 0
B36: Subtotal - MCBH WATER SYSTEMS MAINTENANCE (Swimming Pools) | F36: =SUM(F31:F35) -> 0
A38: C004 | B38: MWR - WATER SYSTEMS MAINTENANCE (Swimming Pools)
A39: C004AA | B39: Emergency Service Orders, Spec Item 3.1.1 | C39: 12 | D39: MO | E39: =ROUND(H39,2) -> 0 | F39: =C39*E39 -> 0
A40: C004AB | B40: Urgent Service Orders, Spec item 3.1.2 | C40: 12 | D40: MO | E40: =ROUND(H40,2) -> 0 | F40: =C40*E40 -> 0
A41: C004AC | B41: Routine Service Orders, Spec Item 3.1.3 | C41: 12 | D41: MO | E41: =ROUND(H41,2) -> 0 | F41: =C41*E41 -> 0
A42: C004AD | B42: Provide Recurring Maintenance for Arizona Pool IAW Annex 1502000 Spec Item 3.2.2 and Attachments 1502000-03 and 1502000-04 | C42: 12 | D42: MO | E42: =ROUND(H42,2) -> 0 | F42: =C42*E42 -> 0
A43: C004AE | B43: Provide Recurring Maintenance for Hickam Family Pool IAW Annex 1502000 Spec Item 3.2.2 and Attachments 1502000-03 and 1502000-04 | C43: 12 | D43: MO | E43: =ROUND(H43,2) -> 0 | F43: =C43*E43 -> 0
A44: C004AF | B44: Provide Recurring Maintenance for Hickam Training Pool IAW Annex 1502000 Spec Item 3.2.2 and Attachments 1502000-03 and 1502000-04 | C44: 12 | D44: MO | E44: =ROUND(H44,2) -> 0 | F44: =C44*E44 -> 0
A45: C004AG | B45: Provide Recurring Maintenance for Scott Pool IAW Annex 1502000 Spec Item 3.2.2 and Attachments 1502000-03 and 1502000-04 | C45: 12 | D45: MO | E45: =ROUND(H45,2) -> 0 | F45: =C45*E45 -> 0
...

Sheet OY 2 Non-Recurring
A1: ATTACHMENT 0200000-14 | I1: OFFERER PROPOSED UNIT PRICE Enter proposed unit price in this column. Price will automatically copy to the UNIT PRICE cell rounded to two decimal places.
A2: EXHIBIT LINE ITEM NUMBERS
A3: SOLICITATION/CONTRACT # N62478-25-R-2431
A4: EXHIBIT C - CLIN 9002
A6: Line Item 0006 Nonrecurring Work- Option Period Two
A7: PROVIDE PRICES TO PERFORM NONRECURRING WORK IN ACCORDANCE WITH SECTION C, SPEC ITEM 4
A8: ELINs C700 through C704
A9: ELIN | B9: Description | C9: Description Extended | D9: Est. Qty | E9: Unit of Issue | F9: Unit Price | G9: Extended Price | H9: IMAP CAC
A10: C700 | B10: Unit Priced Labor Hour Work - MUST BE NEGOTIATED BY KO | C10: The Contractor shall perform all UPL work in accordance with the scope and delivery schedule negotiated per each task order. Refer to: Annex 0200000 Managmenent and Administration, Specification Items 2.15.2 Unit Priced Labor (UPL)Work (Negotiated) for description of UPL Work and 2.15.2.1.1 Labor Requirements. Refer to: Annex 0200000 Managmenent and Administration, Attachment 0200000-01 - Definitions and Acronyms for description of Unit Priced Labor (UPL) Hour. Task order completion times will be specified on each task order. | D10: 2500 | E10: HR | F10: =ROUND(I10,2) -> 0 | G10: =SUM(F10*D10) -> 0 | H10: 717S
A11: C701 | B11: Direct Material and Construction Equipment -MUST BE NEGOTIATED BY KO | C11: The Contractor shall provide all materials and construction equipment to perform Unit Priced Labor work per the scope and delivery schedule specified in the order. Refer to: Annex 0200000 Managmenent and Administration, Specification Items 2.15.2 Unit Priced Labor (UPL)Work (Negotiated) for description of UPL Work and 2.15.2.1.2 Direct Material and Construction Equipment Requirements. Refer to: Annex 0200000 Managmenent and Administration, Attachment 0200000-01 - Definitions and Acronyms for description of Direct Material Costs and Construction Equipment. Task order completion times will be specified on each task order. | D11: 108000 | E11: DO | F11: 1 | G11: =SUM(D11*F11) -> 108000 | H11: 717S
A12: C702 | B12: FILTER MAINT | C12: One Time - Facility Ventilation Intake & Exhaust Filters & Dust Collector Filter Cartridges. Services equal to one regularly scheduled Recurring Work service. | D12: 2 | E12: EA | F12: =ROUND(I12,2) -> 0 | G12: =SUM(F12*D12) -> 0 | H12: 717S
A13: C703 | B13: LOCKSMITH | C13: Providing of key duplication services. Services shall be same as available to the general public and prices shall be as low or lower than those charged the Contractor’s most favored customer for comparable quantities under similar terms and conditions, in addition to any discounts for prompt payment. | D13: 100 | E13: EA | F13: =ROUND(I13,2) -> 0 | G13: =SUM(F13*D13) -> 0 | H13: 717S
A14: ELIN | B14: Description | C14: Description Extended | D14: Est. Qty | E14: Unit of Issue | F14: Coefficient(1) | G14: Total Amount | H14: IMAP CAC
A15: C704 | B15: Unit Price - Coefficient(1) | C15: Contractor's coefficient used to adjust the Unit Prices provided in the Unit Price List Attachment 0200000-18 | D15: 10000 | E15: DO | F15: =ROUND(I15,2) -> 0 | G15: =SUM(D15*F15) -> 0
B17: TOTAL LINE ITEMS ELINs C700 through C704 | G17: =SUM(G10:G13,G15) -> 108000
B18: (Enter this amount into Section B, Item No. 0006, Net Amount)
A21: Notes:
A22: (1) | B22: Submit coefficient in accordance with Annex 0200000, Spec Item 2.15.2.3. The coefficient for Unit Prices shall be the offeror's adjustment to the Government's unit prices. The coefficient must incorporate all projected and potential costs including overhead, profit, insurance, and all other contingencies. There will be no adjustments to the coefficient after award of the contract. The coefficient shall not include any allowance for any contingency to cover increased cost in the Service Contract Labor Standards wage rates for which adjustment is provided under FAR 52.222-43.
B33: Abbreviations:
B34: DO | C34: Dollars
B35: EA | C35: Each
B36: HR | C36: Hour

Sheet OY 3 Recurring
H1: OFFERER PROPOSED UNIT PRICE Enter proposed unit price in this column. Price will automatically copy to the UNIT PRICE cell rounded to two decimal places.
A2: ATTACHMENT 0200000-15
A3: EXHIBIT LINE ITEM NUMBERS
A4: SOLICITATION/CONTRACT #N62478-25-D-2431
A5: EXHIBIT D - CLIN 9003
A7: Line Item 0007 Recurring Work - Option Period Three
A8: PROVIDE PRICES FOR FACILITY INVESTMENT - RECURRING WORK - IN ACCORDANCE WITH SPEC ITEM 3
A9: ELINs D001 through D016
A10: ELIN /Sub ELIN | B10: Description | C10: Quantity | D10: Unit of Issue | E10: Unit Price | F10: Total | G10: CAC
A11: D001 | B11: PHNSY - FACILITY VENTILATION INTAKE AND EXHAUST FILTERS AND DUST COLLECTOR FILTER CARTRIDGES
A12: D001AA | B12: Emergency Service Orders, Spec Item 3.1.1 | C12: 12 | D12: MO | E12: =ROUND(H12,2) -> 0 | F12: =C12*E12 -> 0
A13: D001AB | B13: Urgent Service Orders, Spec item 3.1.2 | C13: 12 | D13: MO | E13: =ROUND(H13,2) -> 0 | F13: =C13*E13 -> 0
A14: D001AC | B14: Routine Service Orders, Spec Item 3.1.3 | C14: 12 | D14: MO | E14: =ROUND(H14,2) -> 0 | F14: =C14*E14 -> 0
A15: D001AD | B15: Perform Semiannual Maintenance and Filter Servicing for Building 1704 IAW Annex 1502000 Spec Item 3.2.1 and Attachment 1502000-02. | C15: 2 | D15: SA | E15: =ROUND(H15,2) -> 0 | F15: =C15*E15 -> 0
A16: D001AE | B16: Perform Semi-Annual Maintenance and Exhaust Filter Servicing for Buildings 1701 and 1703 only IAW Annex 1502000 Spec Item 3.2.1 and Attachment 1502000-02 | C16: 2 | D16: SA | E16: =ROUND(H16,2) -> 0 | F16: =C16*E16 -> 0
A17: D001AF | B17: Perform Annual Maintenance and Filter Servicing for Buildings 1701 and 1703 IAW Annex 1502000 Spec Item 3.2.1 and Attachment 1502000-02 | C17: 1 | D17: A | E17: =ROUND(H17,2) -> 0 | F17: =C17*E17 -> 0
B18: Subtotal - PHNSY -Facility Ventilation Intake and Exhaust Filters and Dust Collector Filter Cartridges | F18: =SUM(F12:F17) -> 0
A20: D002 | B20: CNRH WATER SYSTEMS MAINTENANCE (Swimming Pools and Water Fountain)
A21: D002AA | B21: Emergency Service Orders, Spec Item 3.1.1 | C21: 12 | D21: MO | E21: =ROUND(H21,2) -> 0 | F21: =C21*E21 -> 0
A22: D002AB | B22: Urgent Service Orders, Spec item 3.1.2 | C22: 12 | D22: MO | E22: =ROUND(H22,2) -> 0 | F22: =C22*E22 -> 0
A23: D002AC | B23: Routine Service Orders, Spec Item 3.1.3 | C23: 12 | D23: MO | E23: =ROUND(H23,2) -> 0 | F23: =C23*E23 -> 0
A24: D002AD | B24: Provide Recurring Maintenance for Memorial Fountain - 1695 IAW Annex 1502000 Spec Item 3.2.2 and Attachments 1502000-03 and 1502000-04 | C24: 12 | D24: MO | E24: =ROUND(H24,2) -> 0 | F24: =C24*E24 -> 0
A25: D002AE | B25: Provide Recurring Maintenance for Advanced SEAL Delivery System (ASDS) Facility - Building 995 IAW Annex 1502000 Spec Item 3.2.2 and Attachments 1502000-03 and 1502000-04 | C25: 12 | D25: MO | E25: =ROUND(H25,2) -> 0 | F25: =C25*E25 -> 0
A26: D002AF | B26: Provide Recurring Maintenance for Advanced SEAL Delivery System (ASDS) Facility - Building 1062 IAW Annex 1502000 Spec Item 3.2.2 and Attachments 1502000-03 and 1502000-04 | C26: 12 | D26: MO | E26: =H26 -> 0 | F26: =E26*C26 -> 0
B27: Subtotal - CNRH WATER SYSTEMS MAINTENANCE (Swimming Pools and Water Fountain) | F27: =SUM(F21:F26) -> 0
A30: D003 | B30: MCBH - WATER SYSTEMS MAINTENANCE (Swimming Pools)
A31: D003AA | B31: Emergency Service Orders, Spec Item 3.1.1 | C31: 12 | D31: MO | E31: =ROUND(H31,2) -> 0 | F31: =C31*E31 -> 0
A32: D003AB | B32: Urgent Service Orders, Spec item 3.1.2 | C32: 12 | D32: MO | E32: =ROUND(H32,2) -> 0 | F32: =C32*E32 -> 0
A33: D003AC | B33: Routine Service Orders, Spec Item 3.1.3 | C33: 12 | D33: MO | E33: =ROUND(H33,2) -> 0 | F33: =C33*E33 -> 0
A34: D003AD | B34: Provide Recurring Maintenance for Camp Smith Base Acitivity Swimming Pool - Facility No. 125 IAW Annex 1502000 Spec Item 3.2.2 and Attachments 1502000-03 and 1502000-04 | C34: 12 | D34: MO | E34: =ROUND(H34,2) -> 0 | F34: =C34*E34 -> 0
A35: D003AE | B35: Provide Recurring Maintenance for Manana Housing Area Swimming Pool and Wading Pool - Facility No. 840 IAW Annex 1502000 Spec Item 3.2.2 and Attachments 1502000-03 and 1502000-04 | C35: 12 | D35: MO | E35: =ROUND(H35,2) -> 0 | F35: =C35*E35 -> 0
B36: Subtotal - MCBH WATER SYSTEMS MAINTENANCE (Swimming Pools) | F36: =SUM(F31:F35) -> 0
A38: D004 | B38: MWR - WATER SYSTEMS MAINTENANCE (Swimming Pools)
A39: D004AA | B39: Emergency Service Orders, Spec Item 3.1.1 | C39: 12 | D39: MO | E39: =ROUND(H39,2) -> 0 | F39: =C39*E39 -> 0
A40: D004AB | B40: Urgent Service Orders, Spec item 3.1.2 | C40: 12 | D40: MO | E40: =ROUND(H40,2) -> 0 | F40: =C40*E40 -> 0
A41: D004AC | B41: Routine Service Orders, Spec Item 3.1.3 | C41: 12 | D41: MO | E41: =ROUND(H41,2) -> 0 | F41: =C41*E41 -> 0
A42: D004AD | B42: Provide Recurring Maintenance for Arizona Pool IAW Annex 1502000 Spec Item 3.2.2 and Attachments 1502000-03 and 1502000-04 | C42: 12 | D42: MO | E42: =ROUND(H42,2) -> 0 | F42: =C42*E42 -> 0
A43: D004AE | B43: Provide Recurring Maintenance for Hickam Family Pool IAW Annex 1502000 Spec Item 3.2.2 and Attachments 1502000-03 and 1502000-04 | C43: 12 | D43: MO | E43: =ROUND(H43,2) -> 0 | F43: =C43*E43 -> 0
A44: D004AF | B44: Provide Recurring Maintenance for Hickam Training Pool IAW Annex 1502000 Spec Item 3.2.2 and Attachments 1502000-03 and 1502000-04 | C44: 12 | D44: MO | E44: =ROUND(H44,2) -> 0 | F44: =C44*E44 -> 0
A45: D004AG | B45: Provide Recurring Maintenance for Scott Pool IAW Annex 1502000 Spec Item 3.2.2 and Attachments 1502000-03 and 1502000-04 | C45: 12 | D45: MO | E45: =ROUND(H45,2) -> 0 | F45: =C45*E45 -> 0
...

Sheet OY 3 Non-Recurring
A1: ATTACHMENT 0200000-15 | I1: OFFERER PROPOSED UNIT PRICE Enter proposed unit price in this column. Price will automatically copy to the UNIT PRICE cell rounded to two decimal places.
A2: EXHIBIT LINE ITEM NUMBERS
A3: SOLICITATION/CONTRACT # N62478-25-R-2431
A4: EXHIBIT D - CLIN 9003
A6: Line Item 0008 Nonrecurring Work- Option Period Three
A7: PROVIDE PRICES TO PERFORM NONRECURRING WORK IN ACCORDANCE WITH SECTION C, SPEC ITEM 4
A8: ELINs D700 through D704
A9: ELIN | B9: Description | C9: Description Extended | D9: Est. Qty | E9: Unit of Issue | F9: Unit Price | G9: Extended Price | H9: IMAP CAC
A10: D700 | B10: Unit Priced Labor Hour Work - MUST BE NEGOTIATED BY KO | C10: The Contractor shall perform all UPL work in accordance with the scope and delivery schedule negotiated per each task order. Refer to: Annex 0200000 Managmenent and Administration, Specification Items 2.15.2 Unit Priced Labor (UPL)Work (Negotiated) for description of UPL Work and 2.15.2.1.1 Labor Requirements. Refer to: Annex 0200000 Managmenent and Administration, Attachment 0200000-01 - Definitions and Acronyms for description of Unit Priced Labor (UPL) Hour. Task order completion times will be specified on each task order. | D10: 2500 | E10: HR | F10: =ROUND(I10,2) -> 0 | G10: =SUM(F10*D10) -> 0 | H10: 717S
A11: D701 | B11: Direct Material and Construction Equipment -MUST BE NEGOTIATED BY KO | C11: The Contractor shall provide all materials and construction equipment to perform Unit Priced Labor work per the scope and delivery schedule specified in the order. Refer to: Annex 0200000 Managmenent and Administration, Specification Items 2.15.2 Unit Priced Labor (UPL)Work (Negotiated) for description of UPL Work and 2.15.2.1.2 Direct Material and Construction Equipment Requirements. Refer to: Annex 0200000 Managmenent and Administration, Attachment 0200000-01 - Definitions and Acronyms for description of Direct Material Costs and Construction Equipment. Task order completion times will be specified on each task order. | D11: 108000 | E11: DO | F11: 1 | G11: =SUM(D11*F11) -> 108000 | H11: 717S
A12: D702 | B12: FILTER MAINT | C12: One Time - Facility Ventilation Intake & Exhaust Filters & Dust Collector Filter Cartridges. Services equal to one regularly scheduled Recurring Work service. | D12: 2 | E12: EA | F12: =ROUND(I12,2) -> 0 | G12: =SUM(F12*D12) -> 0 | H12: 717S
A13: D703 | B13: LOCKSMITH | C13: Providing of key duplication services. Services shall be same as available to the general public and prices shall be as low or lower than those charged the Contractor’s most favored customer for comparable quantities under similar terms and conditions, in addition to any discounts for prompt payment. | D13: 100 | E13: EA | F13: =ROUND(I13,2) -> 0 | G13: =SUM(F13*D13) -> 0 | H13: 717S
A14: ELIN | B14: Description | C14: Description Extended | D14: Est. Qty | E14: Unit of Issue | F14: Coefficient(1) | G14: Total Amount | H14: IMAP CAC
A15: D704 | B15: Unit Price - Coefficient(1) | C15: Contractor's coefficient used to adjust the Unit Prices provided in the Unit Price List Attachment 0200000-18 | D15: 10000 | E15: DO | F15: =ROUND(I15,2) -> 0 | G15: =SUM(D15*F15) -> 0
B17: TOTAL LINE ITEMS ELINs D700 through D704 | G17: =SUM(G10:G13,G15) -> 108000
B18: (Enter this amount into Section B, Item No. 0008, Net Amount)
A21: Notes:
A22: (1) | B22: Submit coefficient in accordance with Annex 0200000, Spec Item 2.15.2.3. The coefficient for Unit Prices shall be the offeror's adjustment to the Government's unit prices. The coefficient must incorporate all projected and potential costs including overhead, profit, insurance, and all other contingencies. There will be no adjustments to the coefficient after award of the contract. The coefficient shall not include any allowance for any contingency to cover increased cost in the Service Contract Labor Standards wage rates for which adjustment is provided under FAR 52.222-43.
B33: Abbreviations:
B34: DO | C34: Dollars
B35: EA | C35: Each
B36: HR | C36: Hour

Sheet OY 4 Recurring
H1: OFFERER PROPOSED UNIT PRICE Enter proposed unit price in this column. Price will automatically copy to the UNIT PRICE cell rounded to two decimal places.
A2: ATTACHMENT 0200000-16
A3: EXHIBIT LINE ITEM NUMBERS
A4: SOLICITATION/CONTRACT #N62478-25-D-2431
A5: EXHIBIT E - CLIN 9004
A7: Line Item 0009 Recurring Work - Option Period Four
A8: PROVIDE PRICES FOR FACILITY INVESTMENT - RECURRING WORK - IN ACCORDANCE WITH SPEC ITEM 3
A9: ELINs E001 through E016
A10: ELIN /Sub ELIN | B10: Description | C10: Quantity | D10: Unit of Issue | E10: Unit Price | F10: Total | G10: CAC
A11: E001 | B11: PHNSY - FACILITY VENTILATION INTAKE AND EXHAUST FILTERS AND DUST COLLECTOR FILTER CARTRIDGES
A12: E001AA | B12: Emergency Service Orders, Spec Item 3.1.1 | C12: 12 | D12: MO | E12: =ROUND(H12,2) -> 0 | F12: =C12*E12 -> 0
A13: E001AB | B13: Urgent Service Orders, Spec item 3.1.2 | C13: 12 | D13: MO | E13: =ROUND(H13,2) -> 0 | F13: =C13*E13 -> 0
A14: E001AC | B14: Routine Service Orders, Spec Item 3.1.3 | C14: 12 | D14: MO | E14: =ROUND(H14,2) -> 0 | F14: =C14*E14 -> 0
A15: E001AD | B15: Perform Semiannual Maintenance and Filter Servicing for Building 1704 IAW Annex 1502000 Spec Item 3.2.1 and Attachment 1502000-02. | C15: 2 | D15: SA | E15: =ROUND(H15,2) -> 0 | F15: =C15*E15 -> 0
A16: E001AE | B16: Perform Semi-Annual Maintenance and Exhaust Filter Servicing for Buildings 1701 and 1703 only IAW Annex 1502000 Spec Item 3.2.1 and Attachment 1502000-02 | C16: 2 | D16: SA | E16: =ROUND(H16,2) -> 0 | F16: =C16*E16 -> 0
A17: E001AF | B17: Perform Annual Maintenance and Filter Servicing for Buildings 1701 and 1703 IAW Annex 1502000 Spec Item 3.2.1 and Attachment 1502000-02 | C17: 1 | D17: A | E17: =ROUND(H17,2) -> 0 | F17: =C17*E17 -> 0
B18: Subtotal - PHNSY -Facility Ventilation Intake and Exhaust Filters and Dust Collector Filter Cartridges | F18: =SUM(F12:F17) -> 0
A20: E002 | B20: CNRH WATER SYSTEMS MAINTENANCE (Swimming Pools and Water Fountain)
A21: E002AA | B21: Emergency Service Orders, Spec Item 3.1.1 | C21: 12 | D21: MO | E21: =ROUND(H21,2) -> 0 | F21: =C21*E21 -> 0
A22: E002AB | B22: Urgent Service Orders, Spec item 3.1.2 | C22: 12 | D22: MO | E22: =ROUND(H22,2) -> 0 | F22: =C22*E22 -> 0
A23: E002AC | B23: Routine Service Orders, Spec Item 3.1.3 | C23: 12 | D23: MO | E23: =ROUND(H23,2) -> 0 | F23: =C23*E23 -> 0
A24: E002AD | B24: Provide Recurring Maintenance for Memorial Fountain - 1695 IAW Annex 1502000 Spec Item 3.2.2 and Attachments 1502000-03 and 1502000-04 | C24: 12 | D24: MO | E24: =ROUND(H24,2) -> 0 | F24: =C24*E24 -> 0
A25: E002AE | B25: Provide Recurring Maintenance for Advanced SEAL Delivery System (ASDS) Facility - Building 995 IAW Annex 1502000 Spec Item 3.2.2 and Attachments 1502000-03 and 1502000-04 | C25: 12 | D25: MO | E25: =ROUND(H25,2) -> 0 | F25: =C25*E25 -> 0
A26: E002AF | B26: Provide Recurring Maintenance for Advanced SEAL Delivery System (ASDS) Facility - Building 1062 IAW Annex 1502000 Spec Item 3.2.2 and Attachments 1502000-03 and 1502000-04 | C26: 12 | D26: MO | E26: =H26 -> 0 | F26: =E26*C26 -> 0
B27: Subtotal - CNRH WATER SYSTEMS MAINTENANCE (Swimming Pools and Water Fountain) | F27: =SUM(F21:F26) -> 0
A30: E003 | B30: MCBH - WATER SYSTEMS MAINTENANCE (Swimming Pools)
A31: E003AA | B31: Emergency Service Orders, Spec Item 3.1.1 | C31: 12 | D31: MO | E31: =ROUND(H31,2) -> 0 | F31: =C31*E31 -> 0
A32: E003AB | B32: Urgent Service Orders, Spec item 3.1.2 | C32: 12 | D32: MO | E32: =ROUND(H32,2) -> 0 | F32: =C32*E32 -> 0
A33: E003AC | B33: Routine Service Orders, Spec Item 3.1.3 | C33: 12 | D33: MO | E33: =ROUND(H33,2) -> 0 | F33: =C33*E33 -> 0
A34: E003AD | B34: Provide Recurring Maintenance for Camp Smith Base Acitivity Swimming Pool - Facility No. 125 IAW Annex 1502000 Spec Item 3.2.2 and Attachments 1502000-03 and 1502000-04 | C34: 12 | D34: MO | E34: =ROUND(H34,2) -> 0 | F34: =C34*E34 -> 0
A35: E003AE | B35: Provide Recurring Maintenance for Manana Housing Area Swimming Pool and Wading Pool - Facility No. 840 IAW Annex 1502000 Spec Item 3.2.2 and Attachments 1502000-03 and 1502000-04 | C35: 12 | D35: MO | E35: =ROUND(H35,2) -> 0 | F35: =C35*E35 -> 0
B36: Subtotal - MCBH WATER SYSTEMS MAINTENANCE (Swimming Pools) | F36: =SUM(F31:F35) -> 0
A38: E004 | B38: MWR - WATER SYSTEMS MAINTENANCE (Swimming Pools)
A39: E004AA | B39: Emergency Service Orders, Spec Item 3.1.1 | C39: 12 | D39: MO | E39: =ROUND(H39,2) -> 0 | F39: =C39*E39 -> 0
A40: E004AB | B40: Urgent Service Orders, Spec item 3.1.2 | C40: 12 | D40: MO | E40: =ROUND(H40,2) -> 0 | F40: =C40*E40 -> 0
A41: E004AC | B41: Routine Service Orders, Spec Item 3.1.3 | C41: 12 | D41: MO | E41: =ROUND(H41,2) -> 0 | F41: =C41*E41 -> 0
A42: E004AD | B42: Provide Recurring Maintenance for Arizona Pool IAW Annex 1502000 Spec Item 3.2.2 and Attachments 1502000-03 and 1502000-04 | C42: 12 | D42: MO | E42: =ROUND(H42,2) -> 0 | F42: =C42*E42 -> 0
A43: E004AE | B43: Provide Recurring Maintenance for Hickam Family Pool IAW Annex 1502000 Spec Item 3.2.2 and Attachments 1502000-03 and 1502000-04 | C43: 12 | D43: MO | E43: =ROUND(H43,2) -> 0 | F43: =C43*E43 -> 0
A44: E004AF | B44: Provide Recurring Maintenance for Hickam Training Pool IAW Annex 1502000 Spec Item 3.2.2 and Attachments 1502000-03 and 1502000-04 | C44: 12 | D44: MO | E44: =ROUND(H44,2) -> 0 | F44: =C44*E44 -> 0
A45: E004AG | B45: Provide Recurring Maintenance for Scott Pool IAW Annex 1502000 Spec Item 3.2.2 and Attachments 1502000-03 and 1502000-04 | C45: 12 | D45: MO | E45: =ROUND(H45,2) -> 0 | F45: =C45*E45 -> 0
...

Sheet OY 4 Non-Recurring
A1: ATTACHMENT 0200000-16 | I1: OFFERER PROPOSED UNIT PRICE Enter proposed unit price in this column. Price will automatically copy to the UNIT PRICE cell rounded to two decimal places.
A2: EXHIBIT LINE ITEM NUMBERS
A3: SOLICITATION/CONTRACT # N62478-25-R-2431
A4: EXHIBIT E - CLIN 9004
A6: Line Item 0010 Nonrecurring Work- Option Period Four
A7: PROVIDE PRICES TO PERFORM NONRECURRING WORK IN ACCORDANCE WITH SECTION C, SPEC ITEM 4
A8: ELINs E700 through E704
A9: ELIN | B9: Description | C9: Description Extended | D9: Est. Qty | E9: Unit of Issue | F9: Unit Price | G9: Extended Price | H9: IMAP CAC
A10: E700 | B10: Unit Priced Labor Hour Work - MUST BE NEGOTIATED BY KO | C10: The Contractor shall perform all UPL work in accordance with the scope and delivery schedule negotiated per each task order. Refer to: Annex 0200000 Managmenent and Administration, Specification Items 2.15.2 Unit Priced Labor (UPL)Work (Negotiated) for description of UPL Work and 2.15.2.1.1 Labor Requirements. Refer to: Annex 0200000 Managmenent and Administration, Attachment 0200000-01 - Definitions and Acronyms for description of Unit Priced Labor (UPL) Hour. Task order completion times will be specified on each task order. | D10: 2500 | E10: HR | F10: =ROUND(I10,2) -> 0 | G10: =SUM(F10*D10) -> 0 | H10: 717S
A11: E701 | B11: Direct Material and Construction Equipment -MUST BE NEGOTIATED BY KO | C11: The Contractor shall provide all materials and construction equipment to perform Unit Priced Labor work per the scope and delivery schedule specified in the order. Refer to: Annex 0200000 Managmenent and Administration, Specification Items 2.15.2 Unit Priced Labor (UPL)Work (Negotiated) for description of UPL Work and 2.15.2.1.2 Direct Material and Construction Equipment Requirements. Refer to: Annex 0200000 Managmenent and Administration, Attachment 0200000-01 - Definitions and Acronyms for description of Direct Material Costs and Construction Equipment. Task order completion times will be specified on each task order. | D11: 108000 | E11: DO | F11: 1 | G11: =SUM(D11*F11) -> 108000 | H11: 717S
A12: E702 | B12: FILTER MAINT | C12: One Time - Facility Ventilation Intake & Exhaust Filters & Dust Collector Filter Cartridges. Services equal to one regularly scheduled Recurring Work service. | D12: 2 | E12: EA | F12: =ROUND(I12,2) -> 0 | G12: =SUM(F12*D12) -> 0 | H12: 717S
A13: E703 | B13: LOCKSMITH | C13: Providing of key duplication services. Services shall be same as available to the general public and prices shall be as low or lower than those charged the Contractor’s most favored customer for comparable quantities under similar terms and conditions, in addition to any discounts for prompt payment. | D13: 100 | E13: EA | F13: =ROUND(I13,2) -> 0 | G13: =SUM(F13*D13) -> 0 | H13: 717S
A14: ELIN | B14: Description | C14: Description Extended | D14: Est. Qty | E14: Unit of Issue | F14: Coefficient(1) | G14: Total Amount | H14: IMAP CAC
A15: E704 | B15: Unit Price - Coefficient(1) | C15: Contractor's coefficient used to adjust the Unit Prices provided in the Unit Price List Attachment 0200000-18 | D15: 10000 | E15: DO | F15: =ROUND(I15,2) -> 0 | G15: =SUM(D15*F15) -> 0
B17: TOTAL LINE ITEMS ELINs E700 through E704 | G17: =SUM(G10:G13,G15) -> 108000
B18: (Enter this amount into Section B, Item No. 0010, Net Amount)
A21: Notes:
A22: (1) | B22: Submit coefficient in accordance with Annex 0200000, Spec Item 2.15.2.3. The coefficient for Unit Prices shall be the offeror's adjustment to the Government's unit prices. The coefficient must incorporate all projected and potential costs including overhead, profit, insurance, and all other contingencies. There will be no adjustments to the coefficient after award of the contract. The coefficient shall not include any allowance for any contingency to cover increased cost in the Service Contract Labor Standards wage rates for which adjustment is provided under FAR 52.222-43.
B33: Abbreviations:
B34: DO | C34: Dollars
B35: EA | C35: Each
B36: HR | C36: Hour

Sheet Opt to Extend Recurring
H1: OFFERER PROPOSED UNIT PRICE Enter proposed unit price in this column. Price will automatically copy to the UNIT PRICE cell rounded to two decimal places.
A2: ATTACHMENT 0200000-17
A3: EXHIBIT LINE ITEM NUMBERS
A4: SOLICITATION/CONTRACT #N62478-25-D-2431
A5: EXHIBIT F - CLIN 9005
A7: Line Item 0011 Recurring Work - Option To Extend Services
A8: PROVIDE PRICES FOR FACILITY INVESTMENT - RECURRING WORK - IN ACCORDANCE WITH SPEC ITEM 3
A9: ELINs F001 through F016
A10: ELIN /Sub ELIN | B10: Description | C10: Quantity | D10: Unit of Issue | E10: Unit Price | F10: Total | G10: CAC
A11: F001 | B11: PHNSY - FACILITY VENTILATION INTAKE AND EXHAUST FILTERS AND DUST COLLECTOR FILTER CARTRIDGES
A12: F001AA | B12: Emergency Service Orders, Spec Item 3.1.1 | C12: 6 | D12: MO | E12: =ROUND(H12,2) -> 0 | F12: =C12*E12 -> 0
A13: F001AB | B13: Urgent Service Orders, Spec item 3.1.2 | C13: 6 | D13: MO | E13: =ROUND(H13,2) -> 0 | F13: =C13*E13 -> 0
A14: F001AC | B14: Routine Service Orders, Spec Item 3.1.3 | C14: 6 | D14: MO | E14: =ROUND(H14,2) -> 0 | F14: =C14*E14 -> 0
A15: F001AD | B15: Perform Semiannual Maintenance and Filter Servicing for Building 1704 IAW Annex 1502000 Spec Item 3.2.1 and Attachment 1502000-02. | C15: 1 | D15: SA | E15: =ROUND(H15,2) -> 0 | F15: =C15*E15 -> 0
A16: F001AE | B16: Perform Semi-Annual Maintenance and Exhaust Filter Servicing for Buildings 1701 and 1703 only IAW Annex 1502000 Spec Item 3.2.1 and Attachment 1502000-02 | C16: 1 | D16: SA | E16: =ROUND(H16,2) -> 0 | F16: =C16*E16 -> 0
A17: F001AF | B17: Perform Annual Maintenance and Filter Servicing for Buildings 1701 and 1703 IAW Annex 1502000 Spec Item 3.2.1 and Attachment 1502000-02 | C17: 1 | D17: A | E17: =ROUND(H17,2) -> 0 | F17: =C17*E17 -> 0
B18: Subtotal - PHNSY -Facility Ventilation Intake and Exhaust Filters and Dust Collector Filter Cartridges | F18: =SUM(F12:F17) -> 0
A20: F002 | B20: CNRH WATER SYSTEMS MAINTENANCE (Swimming Pools and Water Fountain)
A21: F002AA | B21: Emergency Service Orders, Spec Item 3.1.1 | C21: 6 | D21: MO | E21: =ROUND(H21,2) -> 0 | F21: =C21*E21 -> 0
A22: F002AB | B22: Urgent Service Orders, Spec item 3.1.2 | C22: 6 | D22: MO | E22: =ROUND(H22,2) -> 0 | F22: =C22*E22 -> 0
A23: F002AC | B23: Routine Service Orders, Spec Item 3.1.3 | C23: 6 | D23: MO | E23: =ROUND(H23,2) -> 0 | F23: =C23*E23 -> 0
A24: F002AD | B24: Provide Recurring Maintenance for Memorial Fountain - 1695 IAW Annex 1502000 Spec Item 3.2.2 and Attachments 1502000-03 and 1502000-04 | C24: 6 | D24: MO | E24: =ROUND(H24,2) -> 0 | F24: =C24*E24 -> 0
A25: F002AE | B25: Provide Recurring Maintenance for Advanced SEAL Delivery System (ASDS) Facility - Building 995 IAW Annex 1502000 Spec Item 3.2.2 and Attachments 1502000-03 and 1502000-04 | C25: 6 | D25: MO | E25: =ROUND(H25,2) -> 0 | F25: =C25*E25 -> 0
A26: F002AF | B26: Provide Recurring Maintenance for Advanced SEAL Delivery System (ASDS) Facility - Building 1062 IAW Annex 1502000 Spec Item 3.2.2 and Attachments 1502000-03 and 1502000-04 | C26: 6 | D26: MO | E26: =H26 -> 0 | F26: =E26*C26 -> 0
B27: Subtotal - CNRH WATER SYSTEMS MAINTENANCE (Swimming Pools and Water Fountain) | F27: =SUM(F21:F26) -> 0
A30: F003 | B30: MCBH - WATER SYSTEMS MAINTENANCE (Swimming Pools)
A31: F003AA | B31: Emergency Service Orders, Spec Item 3.1.1 | C31: 6 | D31: MO | E31: =ROUND(H31,2) -> 0 | F31: =C31*E31 -> 0
A32: F003AB | B32: Urgent Service Orders, Spec item 3.1.2 | C32: 6 | D32: MO | E32: =ROUND(H32,2) -> 0 | F32: =C32*E32 -> 0
A33: F003AC | B33: Routine Service Orders, Spec Item 3.1.3 | C33: 6 | D33: MO | E33: =ROUND(H33,2) -> 0 | F33: =C33*E33 -> 0
A34: F003AD | B34: Provide Recurring Maintenance for Camp Smith Base Acitivity Swimming Pool - Facility No. 125 IAW Annex 1502000 Spec Item 3.2.2 and Attachments 1502000-03 and 1502000-04 | C34: 6 | D34: MO | E34: =ROUND(H34,2) -> 0 | F34: =C34*E34 -> 0
A35: F003AE | B35: Provide Recurring Maintenance for Manana Housing Area Swimming Pool and Wading Pool - Facility No. 840 IAW Annex 1502000 Spec Item 3.2.2 and Attachments 1502000-03 and 1502000-04 | C35: 6 | D35: MO | E35: =ROUND(H35,2) -> 0 | F35: =C35*E35 -> 0
B36: Subtotal - MCBH WATER SYSTEMS MAINTENANCE (Swimming Pools) | F36: =SUM(F31:F35) -> 0
A38: F004 | B38: MWR - WATER SYSTEMS MAINTENANCE (Swimming Pools)
A39: F004AA | B39: Emergency Service Orders, Spec Item 3.1.1 | C39: 6 | D39: MO | E39: =ROUND(H39,2) -> 0 | F39: =C39*E39 -> 0
A40: F004AB | B40: Urgent Service Orders, Spec item 3.1.2 | C40: 6 | D40: MO | E40: =ROUND(H40,2) -> 0 | F40: =C40*E40 -> 0
A41: F004AC | B41: Routine Service Orders, Spec Item 3.1.3 | C41: 6 | D41: MO | E41: =ROUND(H41,2) -> 0 | F41: =C41*E41 -> 0
A42: F004AD | B42: Provide Recurring Maintenance for Arizona Pool IAW Annex 1502000 Spec Item 3.2.2 and Attachments 1502000-03 and 1502000-04 | C42: 6 | D42: MO | E42: =ROUND(H42,2) -> 0 | F42: =C42*E42 -> 0
A43: F004AE | B43: Provide Recurring Maintenance for Hickam Family Pool IAW Annex 1502000 Spec Item 3.2.2 and Attachments 1502000-03 and 1502000-04 | C43: 6 | D43: MO | E43: =ROUND(H43,2) -> 0 | F43: =C43*E43 -> 0
A44: F004AF | B44: Provide Recurring Maintenance for Hickam Training Pool IAW Annex 1502000 Spec Item 3.2.2 and Attachments 1502000-03 and 1502000-04 | C44: 6 | D44: MO | E44: =ROUND(H44,2) -> 0 | F44: =C44*E44 -> 0
A45: F004AG | B45: Provide Recurring Maintenance for Scott Pool IAW Annex 1502000 Spec Item 3.2.2 and Attachments 1502000-03 and 1502000-04 | C45: 6 | D45: MO | E45: =ROUND(H45,2) -> 0 | F45: =C45*E45 -> 0
...

Sheet Opt Extend Non-Recurring 
A1: ATTACHMENT 0200000-17 | I1: OFFERER PROPOSED UNIT PRICE Enter proposed unit price in this column. Price will automatically copy to the UNIT PRICE cell rounded to two decimal places.
A2: EXHIBIT LINE ITEM NUMBERS
A3: SOLICITATION/CONTRACT # N62478-25-R-2431
A4: EXHIBIT F - CLIN 9005
A6: Line Item 0012 Nonrecurring Work- Option To Extend Services
A7: PROVIDE PRICES TO PERFORM NONRECURRING WORK IN ACCORDANCE WITH SECTION C, SPEC ITEM 4
A8: ELINs F700 through F704
A9: ELIN | B9: Description | C9: Description Extended | D9: Est. Qty | E9: Unit of Issue | F9: Unit Price | G9: Extended Price | H9: IMAP CAC
A10: F700 | B10: Unit Priced Labor Hour Work - MUST BE NEGOTIATED BY KO | C10: The Contractor shall perform all UPL work in accordance with the scope and delivery schedule negotiated per each task order. Refer to: Annex 0200000 Managmenent and Administration, Specification Items 2.15.2 Unit Priced Labor (UPL)Work (Negotiated) for description of UPL Work and 2.15.2.1.1 Labor Requirements. Refer to: Annex 0200000 Managmenent and Administration, Attachment 0200000-01 - Definitions and Acronyms for description of Unit Priced Labor (UPL) Hour. Task order completion times will be specified on each task order. | D10: 1250 | E10: HR | F10: =ROUND(I10,2) -> 0 | G10: =SUM(F10*D10) -> 0 | H10: 717S
A11: F701 | B11: Direct Material and Construction Equipment -MUST BE NEGOTIATED BY KO | C11: The Contractor shall provide all materials and construction equipment to perform Unit Priced Labor work per the scope and delivery schedule specified in the order. Refer to: Annex 0200000 Managmenent and Administration, Specification Items 2.15.2 Unit Priced Labor (UPL)Work (Negotiated) for description of UPL Work and 2.15.2.1.2 Direct Material and Construction Equipment Requirements. Refer to: Annex 0200000 Managmenent and Administration, Attachment 0200000-01 - Definitions and Acronyms for description of Direct Material Costs and Construction Equipment. Task order completion times will be specified on each task order. | D11: 54000 | E11: DO | F11: 1 | G11: =SUM(D11*F11) -> 54000 | H11: 717S
A12: F702 | B12: FILTER MAINT | C12: One Time - Facility Ventilation Intake & Exhaust Filters & Dust Collector Filter Cartridges. Services equal to one regularly scheduled Recurring Work service. | D12: 1 | E12: EA | F12: =ROUND(I12,2) -> 0 | G12: =SUM(F12*D12) -> 0 | H12: 717S
