Workbook

Sheet Synopsis of Line Items
B1: Solicitation No. N4008525R2559
B2: INDEFINITE DELIVERY, INDEFINITE QUANTITY CONSTRUCTION CONTRACT FOR CONSTRUCTION MAINTENANCE FOR RIGID PAVING AT THE VARIOUS NAVAL FACILITIES THROUGHOUT HAMPTON ROADS, VIRGINIA
B4: EXHIBIT LINE ITEM NUMBERS
B5: EXHIBIT LINE ITEM NUMBERS DESCRIPTION OF WORK FOR SUPPLIES/SERVICES (Applicable to Exhibits A, B, C, D, E - attached)
B7: Contractor shall verify scope of work for each line item as defined in Section C Descriptions and Specifications, Section C, Contract No. N4008525R2559, Construction Maintenance for Rigid Paving at Various Federal Activities in the Hampton Roads Region
A9: ELIN | B9: Description | C9: Est. Qty | D9: Unit
B11: INDEFINITE QUANTITY (IQ) WORK ITEMS - CLIN 0001
A13: A001 | B13: SITE PREPERATION WORK (UFGS 01 57 19 Temporary Environmental Controls)
B15: Each line item under "Site Preparation Work" shall include all Material, Equipment, Labor, Suprevision, Sub-Contractor cost, Bonding, and Overhead to complete the following tasks: A) Provide the original installation of the required items. B) Maintain the required items in such a maner that they provide the required service, and are neet and sightly. C) At the end of the job all remaining material shall be removed from government property, and the job area returned to its pre work condition.
A17: A00101 | B17: Temparory chain link fencing fencing, 6 ft hight minimum | C17: 500 | D17: LF
A18: A00102 | B18: Dust control for disturbed soil or haul roads | C18: 500 | D18: 1000-SY
A19: A00103 | B19: Temporary diversion dikes | C19: 300 | D19: LF
A20: A00104 | B20: Silt fencing | C20: 10000 | D20: LF
A21: A00105 | B21: Storm drain inlet silt protection | C21: 300 | D21: EA
A22: A00106 | B22: Barricades: Low profile barricades as required to close movement areas to aircraft in order to safely perform work. | C22: 3000 | D22: LF
A23: A00107 | B23: Temporary Runway and Helipad "X" Closure markings. (typically made of yellow plywood) | C23: 25 | D23: EA
A25: A002 | B25: DEMOLITION, REMOVAL, AND DISPOSAL.
B27: Saw cutting (00101): a. Saw cut to up to 4 inch depth per LF when ordered per task order. When cuts are not to full depth of the material, materials can be broken off at the bottom of the saw cut ordered. Where a depth of cut less than 4 inches is all that is required the contractor will be paid as if a full 4 inch depth cut was made but the contractor will assume all risk of damage to material to remain in the event that they choose to use less than the entire 4 inch depth of cut. Where directed by the government to use less than full 4 inch depth cuts the Government will assume the risk of damage to material to remain in place.
B28: b. Includes saw cutting by large machine, or by hand saw where large machines cannot reach, protection of surrounding property, dust containment, proper disposal of debris off of Government property, water if needed where Government fixtures are not accessible, barricades, flagmen, and all safety related equipment to provide saw cutting.
B29: c. A demo plan is required for each task order requiring saw cutting. A demo plan should show the who (operator or person in charge, persons contacted for scheduling, etc., what (equipment to be used, including safety equipment, when (dates, times, and room numbers etc.) and how the job will start and end including all safety precautions.
B30: d. If the material to be cut is more than 4 inches in thickness but less than 12 inches in thickness the contractor will be paid the bid price per inch depth for the cuts made. (i.e. quantity/depth directed); ex. 15 LF * 8 inch depth = 120 LF-in
A32: A00201 | B32: Sawcutting (Per LF per inch depth; 4 inch min. depth to be paid except as noted in d.) (Section 02 41 00) | C32: 55000 | D32: LF-IN
B34: Concrete and Bituminous Pavement Removal (00102-00104): a. Break up and remove, by breaking into manageable pieces, plain or reinforced concrete (portland or asphalt). Load, haul and properly dispose of off of Government property. Includes protection of surrounding property, dust containment, disposal of debris, providing and placing barricades, flagmen, a demo plan, and all safety related equipment to provide concrete (portland or asphalt) removal.
B35: b. In some cases the task may require the contractor to use jackhammers and buggy, or light and heavy equipment to break up and remove materials from areas where normal equipment cannot be operated such as alleyways, and between railroad tracks. Concrete may be plain or reinforced and will be ordered on separate line items.
B36: c. Fabric found during the removal of Portland or asphalt concrete shall be removed as part of the work requirement at no additional cost to the Government.
B37: d. All material shall be removed and disposed at the contractor's expense.
A39: A00202 | B39: Concrete Removal-Plain (Section 02 41 00) | C39: 2500 | D39: CY
A41: A00203 | B41: Concrete Removal-Reinf (Section 02 41 00) | C41: 2500 | D41: CY
A43: A00204 | B43: Bituminous Pavement Removal (Section 02 41 00) | C43: 10000 | D43: CY
B45: Milling of Bituminous Pavement (00105): a. Mill existing bituminous pavement with Government approved milling machine (square yard per inch). Load milled materials into dump trucks, sweep with broom tractor, or by hand. Milling operations in aircraft operating areas must use a vacuum powered sweeper truck to minimize foreign object damage (FOD). Contain and recycle bituminous pavement materials milled off of Government property. Remove and properly dispose of debris caused by milling off of Government property. Includes protection of surrounding property, dust containment, disposal of debris, providing and placing barricades, flagmen, a demo plan, and all safety related equipment to Mill existing bituminous pavement.
B46: b. All material shall be removed and disposed at the contractor's expense.
A48: A00205 | B48: Milling of Bituminous Pavement (Section 32 01 16.17) | C48: 200000 | D48: SY-IN
B50: Rubber and Paint Removal (00106-00110): a. Remove 90 percent of all visible rubber and remove 85 or 100 percent of loose, flaking paint with Government approved high-pressure rubber and paint removal equipment, and properly dispose of debris off of Government property. Contractor shall be responsible for repairing any damage caused by the removal work.
B51: b. All material shall be removed and disposed at the contractor's expense.
A53: A00206 | B53: Rubber Removal 1 To 75,000 SF (Section 32 01 11.51) | C53: 100000 | D53: SF
A55: A00207 | B55: Rubber Removal 75,001 To 200,000 SF (Section 32 01 11.51) | C55: 200000 | D55: SF
A57: A00208 | B57: Rubber Removal 200,001 and Above (Section 32 01 11.51) | C57: 1402000 | D57: SF
A59: A00209 | B59: Paint Removal Contractor Disposal 85% (Section 32 01 11.51) | C59: 82000 | D59: SF
A61: A00210 | B61: Paint Removal Contractor Disposal 100% (Section 32 01 11.51) | C61: 20000 | D61: SF
B63: Aircraft Tiedown Removal (00111): a. Includes protection of surrounding property, dust containment, disposal of debris off of Government property, providing and placing barricades, flagmen, a demo plan, and all safety-related equipment.
...

Sheet Summary
C3: SUMMARY PAGE
C6: Option | E6: Total
C8: BASE YEAR | E8: =SUM('Base Year '!G249:G250) -> 250000
C10: OPTION ONE | E10: =SUM('Option One '!G248:G249) -> 250000
C12: OPTION TWO | E12: =SUM('Option Two '!G248:G249) -> 250000
C14: OPTION THREE | E14: =SUM('Option Three'!G248:G249) -> 250000
C16: OPTION FOUR | E16: =SUM('Option Four'!G248:G249) -> 250000
C19: TOTAL | E19: =SUM(E8:E16) -> 1250000

Sheet Base Year 
A1: Solicitation No. N4008525R2559
A2: INDEFINITE DELIVERY, INDEFINITE QUANTITY CONSTRUCTION CONTRACT FOR RIGID PAVING REPAIR AND REPLACMENT AT VARIOUS NAVAL FACILITIES THROUGHOUT HAMPTON ROADS, VIRGINIA
A3: EXHIBIT A, EXHIBIT LINE ITEMS
A4: SCHEDULE OF PRICES FOR SUPPLIES/SERVICES
A6: INDEFINITE QUANTITY (IQ) WORK ITEMS - BASE YEAR - CLIN 0001
A8: ELIN | B8: Description | C8: Est. Qty | D8: Unit | F8: Unit Price | G8: Extended Price
A10: A001 | B10: SITE PREPERATION WORK (UFGS 01 57 19 Temporary Environmental Controls)
A12: A00101 | B12: Temparory chain link fencing fencing, 6 ft hight minimum | C12: 500 | D12: LF | G12: =C12*F12 -> 0
A14: A00102 | B14: Dust control for disturbed soil or haul roads | C14: 500 | D14: 1000-SY | G14: =C14*F14 -> 0
A16: A00103 | B16: Temporary diversion dikes | C16: 300 | D16: LF | G16: =C16*F16 -> 0
A18: A00104 | B18: Silt fencing | C18: 10000 | D18: LF | G18: =C18*F18 -> 0
A20: A00105 | B20: Storm drain inlet silt protection | C20: 300 | D20: EA | G20: =C20*F20 -> 0
A22: A00106 | B22: Barricades: Low profile barricades as required to close movement areas to aircraft in order to safely perform work. | C22: 3000 | D22: LF | G22: =C22*F22 -> 0
A24: A00107 | B24: Temporary Runway and Helipad "X" Closure markings. (typically made of yellow plywood) | C24: 25 | D24: EA | G24: =C24*F24 -> 0
A26: A002 | B26: DEMOLITION, REMOVAL, AND DISPOSAL
A28: A00201 | B28: Sawcutting (Per LF up to 4 inches deep) | C28: 55000 | D28: LF-IN | G28: =C28*F28 -> 0
A30: A00202 | B30: Concrete Removal-Plain | C30: 2500 | D30: CY | G30: =C30*F30 -> 0
A32: A00203 | B32: Concrete Removal-Reinf | C32: 2500 | D32: CY | G32: =C32*F32 -> 0
A34: A00204 | B34: Bituminous Pavement Removal | C34: 10000 | D34: CY | G34: =C34*F34 -> 0
A36: A00205 | B36: Milling of Bituminous Pavement | C36: 200000 | D36: SY-IN | G36: =C36*F36 -> 0
A38: A00206 | B38: Rubber Removal 1 To 75,000 SF | C38: 100000 | D38: SF | G38: =C38*F38 -> 0
A40: A00207 | B40: Rubber Removal 75,001 To 200,000 SF | C40: 200000 | D40: SF | G40: =C40*F40 -> 0
A42: A00208 | B42: Rubber Removal 200,001 and Above | C42: 1402000 | D42: SF | G42: =C42*F42 -> 0
A44: A00209 | B44: Paint Removal Contractor Disposal (85%) | C44: 82000 | D44: SF | G44: =C44*F44 -> 0
A46: A00210 | B46: Paint Removal Contractor Disposal (100%) | C46: 20000 | D46: SF | G46: =C46*F46 -> 0
A48: A00211 | B48: Remove Aircraft Tiedown (Includes Saw cutting) | C48: 50 | D48: EA | G48: =C48*F48 -> 0
A50: A003 | B50: EXCAVATION AND GRADING
A52: A00301 | B52: Excavation and Grading | C52: 1000 | D52: CY | G52: =C52*F52 -> 0
A54: A00302 | B54: Hand Excavation | C54: 200 | D54: CY | G54: =C54*F54 -> 0
A56: A00303 | B56: Furnish and Install Topsoil | C56: 100 | D56: CY | G56: =C56*F56 -> 0
A58: A00304 | B58: Overhaul | C58: 100 | D58: MI | G58: =C58*F58 -> 0
A60: A00305 | B60: Import and Placement of Suitable Soil | C60: 250 | D60: CY | G60: =C60*F60 -> 0
A62: A00306 | B62: Import and Placement of Select Granular Fill | C62: 250 | D62: CY | G62: =C62*F62 -> 0
A64: A00307 | B64: Import and Placement of VDOT 21A/B Crushed Stone | C64: 250 | D64: CY | G64: =C64*F64 -> 0
A66: A00308 | B66: Import and Placement of VDOT 57 Crushed Stone | C66: 250 | D66: CY | G66: =C66*F66 -> 0
A68: A00309 | B68: Removal of accumulated Sediments and Debris | C68: 1000 | D68: TON | G68: =C68*F68 -> 0
A70: A00310 | B70: Repair, rehabilitation, or replacement of ditches or fills | C70: 7260 | D70: SY | G70: =C70*F70 -> 0
A72: A004 | B72: FABRICS
A74: A00401 | B74: Soil Reinforcement Fabric | C74: 1000 | D74: SY | G74: =C74*F74 -> 0
A76: A00402 | B76: Geotextile | C76: 1000 | D76: SY | G76: =C76*F76 -> 0
...

Sheet Option One 
A1: Solicitation No. N4008525R2559
A2: INDEFINITE DELIVERY, INDEFINITE QUANTITY CONSTRUCTION CONTRACT FOR RIGID PAVING REPAIR AND REPLACMENT AT VARIOUS NAVAL FACILITIES THROUGHOUT HAMPTON ROADS, VIRGINIA
A3: EXHIBIT B, EXHIBIT LINE ITEMS
A4: SCHEDULE OF PRICES FOR SUPPLIES/SERVICES
A6: INDEFINITE QUANTITY (IQ) WORK ITEMS - Option One - CLIN 0002
A8: ELIN | B8: Description | C8: Est. Qty | D8: Unit | F8: Unit Price | G8: Extended Price
A10: B001 | B10: SITE PREPERATION WORK (UFGS 01 57 19 Temporary Environmental Controls)
A12: B00101 | B12: Temparory chain link fencing fencing, 6 ft hight minimum | C12: 500 | D12: LF | G12: =C12*F12 -> 0
A14: B00102 | B14: Dust control for disturbed soil or haul roads | C14: 500 | D14: 1000-SY | G14: =C14*F14 -> 0
A16: B00103 | B16: Temporary diversion dikes | C16: 300 | D16: LF | G16: =C16*F16 -> 0
A18: B00104 | B18: Silt fencing | C18: 10000 | D18: LF | G18: =C18*F18 -> 0
A20: B00105 | B20: Storm drain inlet silt protection | C20: 300 | D20: EA | G20: =C20*F20 -> 0
A22: B00106 | B22: Barricades: Low profile barricades as required to close movement areas to aircraft in order to safely perform work. | C22: 3000 | D22: LF | G22: =C22*F22 -> 0
A24: B00107 | B24: Temporary Runway and Helipad "X" Closure markings. (typically made of yellow plywood) | C24: 25 | D24: EA | G24: =C24*F24 -> 0
A26: B002 | B26: DEMOLITION, REMOVAL, AND DISPOSAL
A28: B00201 | B28: Sawcutting (Per LF up to 4 inches deep) | C28: 55000 | D28: LF-IN | G28: =C28*F28 -> 0
A30: B00202 | B30: Concrete Removal-Plain | C30: 2500 | D30: CY | G30: =C30*F30 -> 0
A32: B00203 | B32: Concrete Removal-Reinf | C32: 2500 | D32: CY | G32: =C32*F32 -> 0
A34: B00204 | B34: Bituminous Pavement Removal | C34: 10000 | D34: CY | G34: =C34*F34 -> 0
A36: B00205 | B36: Milling of Bituminous Pavement | C36: 200000 | D36: SY-IN | G36: =C36*F36 -> 0
A38: B00206 | B38: Rubber Removal 1 To 75,000 SF | C38: 100000 | D38: SF | G38: =C38*F38 -> 0
A40: B00207 | B40: Rubber Removal 75,001 To 200,000 SF | C40: 200000 | D40: SF | G40: =C40*F40 -> 0
A42: B00208 | B42: Rubber Removal 200,001 and Above | C42: 1402000 | D42: SF | G42: =C42*F42 -> 0
A44: B00209 | B44: Paint Removal Contractor Disposal (85%) | C44: 82000 | D44: SF | G44: =C44*F44 -> 0
A46: B00210 | B46: Paint Removal Contractor Disposal (100%) | C46: 20000 | D46: SF | G46: =C46*F46 -> 0
A48: B00211 | B48: Remove Aircraft Tiedown (Includes Saw cutting) | C48: 50 | D48: EA | G48: =C48*F48 -> 0
A50: B003 | B50: EXCAVATION AND GRADING
A52: B00301 | B52: Excavation and Grading | C52: 1000 | D52: CY | G52: =C52*F52 -> 0
A54: B00302 | B54: Hand Excavation | C54: 200 | D54: CY | G54: =C54*F54 -> 0
A56: B00303 | B56: Furnish and Install Topsoil | C56: 100 | D56: CY | G56: =C56*F56 -> 0
A58: B00304 | B58: Overhaul | C58: 100 | D58: MI | G58: =C58*F58 -> 0
A60: B00305 | B60: Import and Placement of Suitable Soil | C60: 250 | D60: CY | G60: =C60*F60 -> 0
A62: B00306 | B62: Import and Placement of Select Granular Fill | C62: 250 | D62: CY | G62: =C62*F62 -> 0
A64: B00307 | B64: Import and Placement of VDOT 21A/B Crushed Stone | C64: 250 | D64: CY | G64: =C64*F64 -> 0
A66: B00308 | B66: Import and Placement of VDOT 57 Crushed Stone | C66: 250 | D66: CY | G66: =C66*F66 -> 0
A68: B00309 | B68: Removal of accumulated Sediments and Debris | C68: 1000 | D68: TON | G68: =C68*F68 -> 0
A70: B00310 | B70: Repair, rehabilitation, or replacement of ditches or fills | C70: 7260 | D70: SY | G70: =C70*F70 -> 0
A72: B004 | B72: FABRICS
A74: B00401 | B74: Soil Reinforcement Fabric | C74: 1000 | D74: SY | G74: =C74*F74 -> 0
A76: B00402 | B76: Geotextile | C76: 1000 | D76: SY | G76: =C76*F76 -> 0
...

Sheet Option Two 
A1: Solicitation No. N4008525R2559
A2: INDEFINITE DELIVERY, INDEFINITE QUANTITY CONSTRUCTION CONTRACT FOR RIGID PAVING REPAIR AND REPLACMENT AT VARIOUS NAVAL FACILITIES THROUGHOUT HAMPTON ROADS, VIRGINIA
A3: EXHIBIT C, EXHIBIT LINE ITEMS
A4: SCHEDULE OF PRICES FOR SUPPLIES/SERVICES
A6: INDEFINITE QUANTITY (IQ) WORK ITEMS - Option Two - CLIN 0003
A8: ELIN | B8: Description | C8: Est. Qty | D8: Unit | F8: Unit Price | G8: Extended Price
A10: C001 | B10: SITE PREPERATION WORK (UFGS 01 57 19 Temporary Environmental Controls)
A12: C00101 | B12: Temparory chain link fencing fencing, 6 ft hight minimum | C12: 500 | D12: LF | G12: =C12*F12 -> 0
A14: C00102 | B14: Dust control for disturbed soil or haul roads | C14: 500 | D14: 1000-SY | G14: =C14*F14 -> 0
A16: C00103 | B16: Temporary diversion dikes | C16: 300 | D16: LF | G16: =C16*F16 -> 0
A18: C00104 | B18: Silt fencing | C18: 10000 | D18: LF | G18: =C18*F18 -> 0
A20: C00105 | B20: Storm drain inlet silt protection | C20: 300 | D20: EA | G20: =C20*F20 -> 0
A22: C00106 | B22: Barricades: Low profile barricades as required to close movement areas to aircraft in order to safely perform work. | C22: 3000 | D22: LF | G22: =C22*F22 -> 0
A24: C00107 | B24: Temporary Runway and Helipad "X" Closure markings. (typically made of yellow plywood) | C24: 25 | D24: EA | G24: =C24*F24 -> 0
A26: C002 | B26: DEMOLITION, REMOVAL, AND DISPOSAL
A28: C00201 | B28: Sawcutting (Per LF up to 4 inches deep) | C28: 55000 | D28: LF-IN | G28: =C28*F28 -> 0
A30: C00202 | B30: Concrete Removal-Plain | C30: 2500 | D30: CY | G30: =C30*F30 -> 0
A32: C00203 | B32: Concrete Removal-Reinf | C32: 2500 | D32: CY | G32: =C32*F32 -> 0
A34: C00204 | B34: Bituminous Pavement Removal | C34: 10000 | D34: CY | G34: =C34*F34 -> 0
A36: C00205 | B36: Milling of Bituminous Pavement | C36: 200000 | D36: SY-IN | G36: =C36*F36 -> 0
A38: C00206 | B38: Rubber Removal 1 To 75,000 SF | C38: 100000 | D38: SF | G38: =C38*F38 -> 0
A40: C00207 | B40: Rubber Removal 75,001 To 200,000 SF | C40: 200000 | D40: SF | G40: =C40*F40 -> 0
A42: C00208 | B42: Rubber Removal 200,001 and Above | C42: 1402000 | D42: SF | G42: =C42*F42 -> 0
A44: C00209 | B44: Paint Removal Contractor Disposal (85%) | C44: 82000 | D44: SF | G44: =C44*F44 -> 0
A46: C00210 | B46: Paint Removal Contractor Disposal (100%) | C46: 20000 | D46: SF | G46: =C46*F46 -> 0
A48: C00211 | B48: Remove Aircraft Tiedown (Includes Saw cutting) | C48: 50 | D48: EA | G48: =C48*F48 -> 0
A50: C003 | B50: EXCAVATION AND GRADING
A52: C00301 | B52: Excavation and Grading | C52: 1000 | D52: CY | G52: =C52*F52 -> 0
A54: C00302 | B54: Hand Excavation | C54: 200 | D54: CY | G54: =C54*F54 -> 0
A56: C00303 | B56: Furnish and Install Topsoil | C56: 100 | D56: CY | G56: =C56*F56 -> 0
A58: C00304 | B58: Overhaul | C58: 100 | D58: MI | G58: =C58*F58 -> 0
A60: C00305 | B60: Import and Placement of Suitable Soil | C60: 250 | D60: CY | G60: =C60*F60 -> 0
A62: C00306 | B62: Import and Placement of Select Granular Fill | C62: 250 | D62: CY | G62: =C62*F62 -> 0
A64: C00307 | B64: Import and Placement of VDOT 21A/B Crushed Stone | C64: 250 | D64: CY | G64: =C64*F64 -> 0
A66: C00308 | B66: Import and Placement of VDOT 57 Crushed Stone | C66: 250 | D66: CY | G66: =C66*F66 -> 0
A68: C00309 | B68: Removal of accumulated Sediments and Debris | C68: 1000 | D68: TON | G68: =C68*F68 -> 0
A70: C00310 | B70: Repair, rehabilitation, or replacement of ditches or fills | C70: 7260 | D70: SY | G70: =C70*F70 -> 0
A72: C004 | B72: FABRICS
A74: C00401 | B74: Soil Reinforcement Fabric | C74: 1000 | D74: SY | G74: =C74*F74 -> 0
A76: C00402 | B76: Geotextile | C76: 1000 | D76: SY | G76: =C76*F76 -> 0
...

Sheet Option Three
A1: Solicitation No. N4008525R2559
A2: INDEFINITE DELIVERY, INDEFINITE QUANTITY CONSTRUCTION CONTRACT FOR RIGID PAVING REPAIR AND REPLACMENT AT VARIOUS NAVAL FACILITIES THROUGHOUT HAMPTON ROADS, VIRGINIA
A3: EXHIBIT D, EXHIBIT LINE ITEMS
A4: SCHEDULE OF PRICES FOR SUPPLIES/SERVICES
A6: INDEFINITE QUANTITY (IQ) WORK ITEMS - Option Three - CLIN 0004
A8: ELIN | B8: Description | C8: Est. Qty | D8: Unit | F8: Unit Price | G8: Extended Price
A10: D001 | B10: SITE PREPERATION WORK (UFGS 01 57 19 Temporary Environmental Controls)
A12: D00101 | B12: Temparory chain link fencing fencing, 6 ft hight minimum | C12: 500 | D12: LF | G12: =C12*F12 -> 0
A14: D00102 | B14: Dust control for disturbed soil or haul roads | C14: 500 | D14: 1000-SY | G14: =C14*F14 -> 0
A16: D00103 | B16: Temporary diversion dikes | C16: 300 | D16: LF | G16: =C16*F16 -> 0
A18: D00104 | B18: Silt fencing | C18: 10000 | D18: LF | G18: =C18*F18 -> 0
A20: D00105 | B20: Storm drain inlet silt protection | C20: 300 | D20: EA | G20: =C20*F20 -> 0
A22: D00106 | B22: Barricades: Low profile barricades as required to close movement areas to aircraft in order to safely perform work. | C22: 3000 | D22: LF | G22: =C22*F22 -> 0
A24: D00107 | B24: Temporary Runway and Helipad "X" Closure markings. (typically made of yellow plywood) | C24: 25 | D24: EA | G24: =C24*F24 -> 0
A26: D002 | B26: DEMOLITION, REMOVAL, AND DISPOSAL
A28: D00201 | B28: Sawcutting (Per LF up to 4 inches deep) | C28: 55000 | D28: LF-IN | G28: =C28*F28 -> 0
A30: D00202 | B30: Concrete Removal-Plain | C30: 2500 | D30: CY | G30: =C30*F30 -> 0
A32: D00203 | B32: Concrete Removal-Reinf | C32: 2500 | D32: CY | G32: =C32*F32 -> 0
A34: D00204 | B34: Bituminous Pavement Removal | C34: 10000 | D34: CY | G34: =C34*F34 -> 0
A36: D00205 | B36: Milling of Bituminous Pavement | C36: 200000 | D36: SY-IN | G36: =C36*F36 -> 0
A38: D00206 | B38: Rubber Removal 1 To 75,000 SF | C38: 100000 | D38: SF | G38: =C38*F38 -> 0
A40: D00207 | B40: Rubber Removal 75,001 To 200,000 SF | C40: 200000 | D40: SF | G40: =C40*F40 -> 0
A42: D00208 | B42: Rubber Removal 200,001 and Above | C42: 1402000 | D42: SF | G42: =C42*F42 -> 0
A44: D00209 | B44: Paint Removal Contractor Disposal (85%) | C44: 82000 | D44: SF | G44: =C44*F44 -> 0
A46: D00210 | B46: Paint Removal Contractor Disposal (100%) | C46: 20000 | D46: SF | G46: =C46*F46 -> 0
A48: D00211 | B48: Remove Aircraft Tiedown (Includes Saw cutting) | C48: 50 | D48: EA | G48: =C48*F48 -> 0
A50: D003 | B50: EXCAVATION AND GRADING
A52: D00301 | B52: Excavation and Grading | C52: 1000 | D52: CY | G52: =C52*F52 -> 0
A54: D00302 | B54: Hand Excavation | C54: 200 | D54: CY | G54: =C54*F54 -> 0
A56: D00303 | B56: Furnish and Install Topsoil | C56: 100 | D56: CY | G56: =C56*F56 -> 0
A58: D00304 | B58: Overhaul | C58: 100 | D58: MI | G58: =C58*F58 -> 0
A60: D00305 | B60: Import and Placement of Suitable Soil | C60: 250 | D60: CY | G60: =C60*F60 -> 0
A62: D00306 | B62: Import and Placement of Select Granular Fill | C62: 250 | D62: CY | G62: =C62*F62 -> 0
A64: D00307 | B64: Import and Placement of VDOT 21A/B Crushed Stone | C64: 250 | D64: CY | G64: =C64*F64 -> 0
A66: D00308 | B66: Import and Placement of VDOT 57 Crushed Stone | C66: 250 | D66: CY | G66: =C66*F66 -> 0
A68: D00309 | B68: Removal of accumulated Sediments and Debris | C68: 1000 | D68: TON | G68: =C68*F68 -> 0
A70: D00310 | B70: Repair, rehabilitation, or replacement of ditches or fills | C70: 7260 | D70: SY | G70: =C70*F70 -> 0
A72: D004 | B72: FABRICS
A74: D00401 | B74: Soil Reinforcement Fabric | C74: 1000 | D74: SY | G74: =C74*F74 -> 0
A76: D00402 | B76: Geotextile | C76: 1000 | D76: SY | G76: =C76*F76 -> 0
...

Sheet Option Four
A1: Solicitation No. N4008525R2559
A2: INDEFINITE DELIVERY, INDEFINITE QUANTITY CONSTRUCTION CONTRACT FOR RIGID PAVING REPAIR AND REPLACMENT AT VARIOUS NAVAL FACILITIES THROUGHOUT HAMPTON ROADS, VIRGINIA
A3: EXHIBIT E, EXHIBIT LINE ITEMS
A4: SCHEDULE OF PRICES FOR SUPPLIES/SERVICES
A6: INDEFINITE QUANTITY (IQ) WORK ITEMS - Option Four - CLIN 0005
A8: ELIN | B8: Description | C8: Est. Qty | D8: Unit | F8: Unit Price | G8: Extended Price
A10: E001 | B10: SITE PREPERATION WORK (UFGS 01 57 19 Temporary Environmental Controls)
A12: E00101 | B12: Temparory chain link fencing fencing, 6 ft hight minimum | C12: 500 | D12: LF | G12: =C12*F12 -> 0
A14: E00102 | B14: Dust control for disturbed soil or haul roads | C14: 500 | D14: 1000-SY | G14: =C14*F14 -> 0
A16: E00103 | B16: Temporary diversion dikes | C16: 300 | D16: LF | G16: =C16*F16 -> 0
A18: E00104 | B18: Silt fencing | C18: 10000 | D18: LF | G18: =C18*F18 -> 0
A20: E00105 | B20: Storm drain inlet silt protection | C20: 300 | D20: EA | G20: =C20*F20 -> 0
A22: E00106 | B22: Barricades: Low profile barricades as required to close movement areas to aircraft in order to safely perform work. | C22: 3000 | D22: LF | G22: =C22*F22 -> 0
A24: E00107 | B24: Temporary Runway and Helipad "X" Closure markings. (typically made of yellow plywood) | C24: 25 | D24: EA | G24: =C24*F24 -> 0
A26: E002 | B26: DEMOLITION, REMOVAL, AND DISPOSAL
A28: E00201 | B28: Sawcutting (Per LF up to 4 inches deep) | C28: 55000 | D28: LF-IN | G28: =C28*F28 -> 0
A30: E00202 | B30: Concrete Removal-Plain | C30: 2500 | D30: CY | G30: =C30*F30 -> 0
A32: E00203 | B32: Concrete Removal-Reinf | C32: 2500 | D32: CY | G32: =C32*F32 -> 0
A34: E00204 | B34: Bituminous Pavement Removal | C34: 10000 | D34: CY | G34: =C34*F34 -> 0
A36: E00205 | B36: Milling of Bituminous Pavement | C36: 200000 | D36: SY-IN | G36: =C36*F36 -> 0
A38: E00206 | B38: Rubber Removal 1 To 75,000 SF | C38: 100000 | D38: SF | G38: =C38*F38 -> 0
A40: E00207 | B40: Rubber Removal 75,001 To 200,000 SF | C40: 200000 | D40: SF | G40: =C40*F40 -> 0
A42: E00208 | B42: Rubber Removal 200,001 and Above | C42: 1402000 | D42: SF | G42: =C42*F42 -> 0
A44: E00209 | B44: Paint Removal Contractor Disposal (85%) | C44: 82000 | D44: SF | G44: =C44*F44 -> 0
A46: E00210 | B46: Paint Removal Contractor Disposal (100%) | C46: 20000 | D46: SF | G46: =C46*F46 -> 0
A48: E00211 | B48: Remove Aircraft Tiedown (Includes Saw cutting) | C48: 50 | D48: EA | G48: =C48*F48 -> 0
A50: E003 | B50: EXCAVATION AND GRADING
A52: E00301 | B52: Excavation and Grading | C52: 1000 | D52: CY | G52: =C52*F52 -> 0
A54: E00302 | B54: Hand Excavation | C54: 200 | D54: CY | G54: =C54*F54 -> 0
A56: E00303 | B56: Furnish and Install Topsoil | C56: 100 | D56: CY | G56: =C56*F56 -> 0
A58: E00304 | B58: Overhaul | C58: 100 | D58: MI | G58: =C58*F58 -> 0
A60: E00305 | B60: Import and Placement of Suitable Soil | C60: 250 | D60: CY | G60: =C60*F60 -> 0
A62: E00306 | B62: Import and Placement of Select Granular Fill | C62: 250 | D62: CY | G62: =C62*F62 -> 0
A64: E00307 | B64: Import and Placement of VDOT 21A/B Crushed Stone | C64: 250 | D64: CY | G64: =C64*F64 -> 0
A66: E00308 | B66: Import and Placement of VDOT 57 Crushed Stone | C66: 250 | D66: CY | G66: =C66*F66 -> 0
A68: E00309 | B68: Removal of accumulated Sediments and Debris | C68: 1000 | D68: TON | G68: =C68*F68 -> 0
A70: E00310 | B70: Repair, rehabilitation, or replacement of ditches or fills | C70: 7260 | D70: SY | G70: =C70*F70 -> 0
A72: E004 | B72: FABRICS
A74: E00401 | B74: Soil Reinforcement Fabric | C74: 1000 | D74: SY | G74: =C74*F74 -> 0
A76: E00402 | B76: Geotextile | C76: 1000 | D76: SY | G76: =C76*F76 -> 0
...
