Workbook

Sheet Instructions
B1: B-52J Commercial Engine Replacement Program (CERP) Kit Production
B2: Pricing Matrix Instructions - DRAFT
A4: 1 | B4: Enter Offeror name in Cell B1 of the "Pricing Matrix:" Enter proposed unit prices in the "Pricing Matrix" worksheet in ALL yellow highlighted cells. Enter all proposed rates into the Rates Table in the "Pricing Matrix" worksheet.
B5: Note: The gray-highlighted cells in the Pricing Matrix are linked to the Rate Table and will populate automatically. The extended price is calculated by adding 100% to the proposed indirect/burden rates and multiplying by the evaluation dollar estimate.
B6: Example: A proposed Prime Material Handling Rate of 7.55% in the Rate Table is included in the Pricing Matrix on the applicable CLIN as 107.55%.
A7: 2 | B7: Complete the worksheets for Long Lead Parts Group A, B, and E and follow the instructions included in the worksheet.
A8: 3 | B8: Rounding: All proposed dollar amounts shall be rounded to the nearest cent. All proposed labor rates shall be rounded to the nearest cent. All indirect/burden rates shall be rounded to four decimal places and entered as a percentage (ex. 0.0755 = 7.55%) in the rate table. At the CLIN level, the rate will be entered as 100% plus the proposed rate (ex. 7.55% is entered as 107.55%).
A9: 4 | B9: For a detailed breakdown of how the extended price for each CLIN and the Total Evaluated Price (TEP) is calculated, refer to the "Calculation Methodology" worksheet.
A10: 5 | B10: The X reference for the CLINs in Column A will become the number of the applicable basic period or option period as labeled in Row 4. For example, CLIN X001 will be 0001 for the Basic Period (Year 1), 1001 for Basic Period (Year 2), and 2001 for Basic Period (Year 3), etc.
A11: 6 | B11: The following Notes are also included in the Pricing Matrix worksheet.
B12: Note 1: | C12: ='Pricing Matrix'!B58 -> Engineering, Administrative, and Fabrication labor rates will be applied to the applicable CLIN based on the TDP update. Reference Requirements Update Process Change Document for details.
B13: Note 2: | C13: ='Pricing Matrix'!B60 -> The Prime Material Handling Rate or Subcontractor Material Handling Rate will be applied as applicable for CLINs X011-X014, and X018 during contract execution.
C14: ='Pricing Matrix'!B61 -> For evaluation purposes, CLINs X011-X013 apply the Prime Material Handling Rate and CLINs X014 and X018 apply the Subcontractor Material Handling Rate.
B15: Note 3: | C15: ='Pricing Matrix'!B63 -> While fixed hourly labor rates are being used for evaluation purposes, the proposed overtime or premium rates may be required during the life of the contract and will be utilized and applied as applicable.
B16: Note 4: | C16: ='Pricing Matrix'!B65 -> Quantities in the Pricing Matrix, are notional, and actual quantities may vary during contract performance based on funding availability and program constraints.
B17: Note 5: | C17: ='Pricing Matrix'!B67 -> All rates should be proposed sufficiently to ensure adequate coverage of all labor costs, all indirect costs, including G&A, COM, and so forth as well as prime and subcontractor profit in every contract out-year.
B18: Note 5: | C18: ='Pricing Matrix'!B69 -> The quantity of 1 each in Basic Year 1 for CLINs X008 - X010 is for evaluation purposes only and may not be required during contract execution.

Sheet Calculation Methodology
A1: B-52J Commercial Engine Replacement Program (CERP) Kit Production
A3: CLIN | B3: Description | C3: Calculation Methodology
A5: ='Pricing Matrix'!A8 -> X001 | B5: ='Pricing Matrix'!C8 -> Program/Manufacturing Management | C5: Proposed monthly unit price per year is multiplied by the by the applicable number of months to establish the extended price for each year. The sum of the extended prices for all years equals the total CLIN price.
A6: ='Pricing Matrix'!A9 -> X002 | B6: ='Pricing Matrix'!C9 -> Integrated Logistics Support
A7: ='Pricing Matrix'!A10 -> X003 | B7: ='Pricing Matrix'!C10 -> FSR Support - Tinker AFB (Depot)
A8: ='Pricing Matrix'!A11 -> X004 | B8: ='Pricing Matrix'!C11 -> Travel and Per Diem - To Be Negotiated (TBN) Per Occurrence - Travel G&A Rate | C8: The proposed Travel G&A rate per year is multiplied by the Evaluation Travel Dollars per year as applicable to establish the extended price for each year. The sum of the extended prices for all years equals the total CLIN price.
A9: ='Pricing Matrix'!A12 -> X005 | B9: ='Pricing Matrix'!C12 -> Lot 1 Kit Group #A | C9: Proposed unit price per year is multiplied by the by the estimated quantity per year to establish the extended price for each year. The sum of the extended prices for all years equals the total CLIN price.
A10: ='Pricing Matrix'!A13 -> X005AA | B10: ='Pricing Matrix'!C13 -> Long Lead Parts
A11: ='Pricing Matrix'!A14 -> X005AB | B11: ='Pricing Matrix'!C14 -> Non-Long Lead Parts
A12: ='Pricing Matrix'!A15 -> X006 | B12: ='Pricing Matrix'!C15 -> Lot 1 Kit Group #B
A13: ='Pricing Matrix'!A16 -> X006AA | B13: ='Pricing Matrix'!C16 -> Long Lead Parts
A14: ='Pricing Matrix'!A17 -> X006AB | B14: ='Pricing Matrix'!C17 -> Non-Long Lead Parts
A15: ='Pricing Matrix'!A18 -> X007 | B15: ='Pricing Matrix'!C18 -> Lot 1 Kit Group #E
A16: ='Pricing Matrix'!A19 -> X007AA | B16: ='Pricing Matrix'!C19 -> Long Lead Parts
A17: ='Pricing Matrix'!A20 -> X007AB | B17: ='Pricing Matrix'!C20 -> Non-Long Lead Parts
A18: ='Pricing Matrix'!A22 -> X008 | B18: ='Pricing Matrix'!C22 -> Lots 2-6 Kit Group #A | C18: The proposed unit price per year is multiplied by the evaluation quantity per year as applicable to establish the extended price for each year. The sum of the extended prices for all years equals the total CLIN price.
A19: ='Pricing Matrix'!A23 -> X009 | B19: ='Pricing Matrix'!C23 -> Lots 2-6 Kit Group #B
A20: ='Pricing Matrix'!A24 -> X010 | B20: ='Pricing Matrix'!C24 -> Lots 2-6 Kit Group #E
A21: ='Pricing Matrix'!A29 -> X011 | B21: ='Pricing Matrix'!C29 -> Spare Parts - TBN Per Occurrence - Prime or Subcontractor Material Handling Rates - See Note 2 Below | C21: The proposed applicable Prime or Subcontractor Material Handling Rate per year is multiplied by the Evaluation Material Dollars per year as applicable to establish the extended price for each year. The sum of the extended prices for all years equals the total CLIN price.
A22: ='Pricing Matrix'!A30 -> X012 | B22: ='Pricing Matrix'!C30 -> Peculiar Support Equipment - TBN Per Occurrence - Prime or Subcontractor Material Handling Rates - See Note 2 Below
A23: ='Pricing Matrix'!A31 -> X013 | B23: ='Pricing Matrix'!C31 -> Production Tooling - TBN Per Occurrence - Prime or Subcontractor Material Handling Rates - See Note 2 Below
A24: ='Pricing Matrix'!A32 -> X014 | B24: ='Pricing Matrix'!C32 -> Common Support Equipment - TBN Per Occurrence - Prime or Subcontractor Material Handling Rates - See Note 2 Below
A25: ='Pricing Matrix'!A33 -> X015 | B25: ='Pricing Matrix'!C33 -> Data (Not Separately Priced) | C25: NOT EVALUATED
A26: ='Pricing Matrix'!A34 -> X016 | B26: ='Pricing Matrix'!C34 -> Data (Separately Priced) - TBN Per Occurrence - Engineering Fixed Hourly Labor Rates | C26: The proposed Engineering Fixed Hourly Labor Rate per year is multiplied by the Evaluation Labor Hours per year as applicable to establish the extended price for each year. The sum of the extended prices for all years equals the total CLIN price.
A27: ='Pricing Matrix'!A35 -> X017 | B27: ='Pricing Matrix'!C35 -> Over & Above Labor - TBN Per Occurrence - Engineering Fixed Hourly Labor Rates
A28: ='Pricing Matrix'!A36 -> X018 | B28: ='Pricing Matrix'!C36 -> Over & Above Materials - TBN Per Occurrence - Prime or Subcontractor Material Handling Rates - See Note 2 Below | C28: The proposed applicable Subcontractor Material Handling Rate per year is multiplied by the Evaluation Material Dollars per year as applicable to establish the extended price for each year. The sum of the extended prices for all years equals the total CLIN price.
A29: ='Pricing Matrix'!A37 -> X019 | B29: ='Pricing Matrix'!C37 -> Over & Above Storage - TBN Per Occurrence - Transportation/Shipping G&A Rate | C29: The proposed Transportation/Shipping G&A rate per year is multiplied by Evaluation Transportation/Shipping Dollars per year as applicable to establish the extended price for each year. The sum of the extended prices for all years equals the total CLIN price.
A30: ='Pricing Matrix'!A38 -> X020 | B30: ='Pricing Matrix'!C38 -> Over & Above Shipping - TBN Per Occurrence - Transportation/Shipping G&A Rate
A31: ='Pricing Matrix'!A39 -> X021 | B31: ='Pricing Matrix'!C39 -> Over & Above Travel - TBN Per Occurrence - Travel G&A Rate | C31: The proposed Travel G&A rate per year is multiplied by the Evaluation Travel Dollars per year as applicable to establish the extended price for each year. The sum of the extended prices for all years equals the total CLIN price.
B33: Total Evaluated Price (TEP) | C33: The sum of the total price for all CLINs for the Basic Period Years 1-4 and all Option Period Years 5-10.
A35: The TEP is for evaluation purposes only and is not the contract award amount.

Sheet Pricing Matrix
A1: Offeror: | B1: Insert Offeror Name | F1: DRAFT PRICING MATRIX 31 March 2026
E2: The estimated quantities expressed below are for evaluation purposes and may vary during contract execution.
A3: Review the Instructions Worksheet before completing the Pricing Matrix | E3: Note: The quantities provided below will be updated with the final RFP release.
F4: CLINs 00XX | I4: CLINs 10XX | L4: CLINs 20XX | O4: CLINs 30XX | R4: CLINs 40XX | U4: CLINs 50XX | X4: CLINs 60XX | AA4: CLINs 70XX | AD4: CLINs 800X | AG4: CLINs 90XX
C5: B-52J Commercial Engine Replacement Program (CERP) Kit Production | E5: Basic Period (Year 1) | H5: Basic Period (Year 2) | K5: Basic Period (Year 3) | N5: Basic Period (Year 4) | Q5: Option Period 1 (Year 5) | T5: Option Period 2 (Year 6) | W5: Option Period 3 (Year 7) | Z5: Option Period 4 (Year 8) | AC5: Option Period 5 (Year 9) | AF5: Option Period 6 (Year 10)
A6: CLIN | B6: Contract Type | C6: Description | D6: Unit of Issue | E6: Qty | F6: Unit Price | G6: Extended Price | H6: Qty | I6: Unit Price | J6: Extended Price | K6: Qty | L6: Unit Price | M6: Extended Price | N6: Qty | O6: Unit Price | P6: Extended Price | Q6: Qty | R6: Unit Price | S6: Extended Price | T6: Qty | U6: Unit Price | V6: Extended Price | W6: Qty | X6: Unit Price | Y6: Extended Price | Z6: Qty | AA6: Unit Price | AB6: Extended Price | AC6: Qty | AD6: Unit Price | AE6: Extended Price | AF6: Qty | AG6: Unit Price | AH6: Extended Price | AJ6: Total Evaluated Price | AK6: CLIN
A8: X001 | B8: FFP | C8: Program/Manufacturing Management | D8: MO | E8: 12 | G8: =ROUND((ROUND((F8),2)*E8),2) -> 0 | H8: 12 | J8: =ROUND((ROUND((I8),2)*H8),2) -> 0 | K8: 12 | M8: =ROUND((ROUND((L8),2)*K8),2) -> 0 | N8: 12 | P8: =ROUND((ROUND((O8),2)*N8),2) -> 0 | Q8: 12 | S8: =ROUND((ROUND((R8),2)*Q8),2) -> 0 | T8: 12 | V8: =ROUND((ROUND((U8),2)*T8),2) -> 0 | W8: 12 | Y8: =ROUND((ROUND((X8),2)*W8),2) -> 0 | Z8: 12 | AB8: =ROUND((ROUND((AA8),2)*Z8),2) -> 0 | AC8: 12 | AE8: =ROUND((ROUND((AD8),2)*AC8),2) -> 0 | AF8: 12 | AH8: =ROUND((ROUND((AG8),2)*AF8),2) -> 0 | AJ8: =G8+J8+M8+P8+S8+V8+Y8+AB8+AE8+AH8 -> 0 | AK8: =A8 -> X001
A9: X002 | B9: FFP | C9: Integrated Logistics Support | D9: MO | E9: 12 | G9: =ROUND((ROUND((F9),2)*E9),2) -> 0 | H9: 12 | J9: =ROUND((ROUND((I9),2)*H9),2) -> 0 | K9: 12 | M9: =ROUND((ROUND((L9),2)*K9),2) -> 0 | N9: 12 | P9: =ROUND((ROUND((O9),2)*N9),2) -> 0 | Q9: 12 | S9: =ROUND((ROUND((R9),2)*Q9),2) -> 0 | T9: 12 | V9: =ROUND((ROUND((U9),2)*T9),2) -> 0 | W9: 12 | Y9: =ROUND((ROUND((X9),2)*W9),2) -> 0 | Z9: 12 | AB9: =ROUND((ROUND((AA9),2)*Z9),2) -> 0 | AC9: 12 | AE9: =ROUND((ROUND((AD9),2)*AC9),2) -> 0 | AF9: 12 | AH9: =ROUND((ROUND((AG9),2)*AF9),2) -> 0 | AJ9: =G9+J9+M9+P9+S9+V9+Y9+AB9+AE9+AH9 -> 0 | AK9: =A9 -> X002
A10: X003 | B10: FFP | C10: FSR Support - Tinker AFB (Depot) | D10: MO | E10: 12 | G10: =ROUND((ROUND((F10),2)*E10),2) -> 0 | H10: 12 | J10: =ROUND((ROUND((I10),2)*H10),2) -> 0 | K10: 12 | M10: =ROUND((ROUND((L10),2)*K10),2) -> 0 | N10: 12 | P10: =ROUND((ROUND((O10),2)*N10),2) -> 0 | Q10: 12 | S10: =ROUND((ROUND((R10),2)*Q10),2) -> 0 | T10: 12 | V10: =ROUND((ROUND((U10),2)*T10),2) -> 0 | W10: 12 | Y10: =ROUND((ROUND((X10),2)*W10),2) -> 0 | Z10: 12 | AB10: =ROUND((ROUND((AA10),2)*Z10),2) -> 0 | AC10: 12 | AE10: =ROUND((ROUND((AD10),2)*AC10),2) -> 0 | AF10: 12 | AH10: =ROUND((ROUND((AG10),2)*AF10),2) -> 0 | AJ10: =G10+J10+M10+P10+S10+V10+Y10+AB10+AE10+AH10 -> 0 | AK10: =A10 -> X003
A11: X004 | B11: TBN (FFP) | C11: Travel and Per Diem - To Be Negotiated (TBN) Per Occurrence - Travel G&A Rate | D11: EA | E11: 1000 | F11: =F54+1 -> 1 | G11: =ROUND((ROUND((F11),4)*E11),2) -> 1000 | H11: 1000 | I11: =I54+1 -> 1 | J11: =ROUND((ROUND((I11),4)*H11),2) -> 1000 | K11: 1000 | L11: =L54+1 -> 1 | M11: =ROUND((ROUND((L11),4)*K11),2) -> 1000 | N11: 1000 | O11: =O54+1 -> 1 | P11: =ROUND((ROUND((O11),4)*N11),2) -> 1000 | Q11: 1000 | R11: =R54+1 -> 1 | S11: =ROUND((ROUND((R11),4)*Q11),2) -> 1000 | T11: 1000 | U11: =U54+1 -> 1 | V11: =ROUND((ROUND((U11),4)*T11),2) -> 1000 | W11: 1000 | X11: =X54+1 -> 1 | Y11: =ROUND((ROUND((X11),4)*W11),2) -> 1000 | Z11: 1000 | AA11: =AA54+1 -> 1 | AB11: =ROUND((ROUND((AA11),4)*Z11),2) -> 1000 | AC11: 1000 | AD11: =AD54+1 -> 1 | AE11: =ROUND((ROUND((AD11),4)*AC11),2) -> 1000 | AF11: 1000 | AG11: =AG54+1 -> 1 | AH11: =ROUND((ROUND((AG11),4)*AF11),2) -> 1000 | AJ11: =G11+J11+M11+P11+S11+V11+Y11+AB11+AE11+AH11 -> 10000 | AK11: =A11 -> X004
A12: X005 | C12: Lot 1 Kit Group #A | AK12: =A12 -> X005
A13: X005AA | B13: FFP | C13: Long Lead Parts | D13: EA | E13: 5 | G13: =ROUND((ROUND((F13),2)*E13),2) -> 0 | I13: 0 | J13: =ROUND((ROUND((I13),2)*H13),2) -> 0 | M13: =ROUND((ROUND((L13),2)*K13),2) -> 0 | O13: 0 | P13: =ROUND((ROUND((O13),2)*N13),2) -> 0 | R13: 0 | S13: =ROUND((ROUND((R13),2)*Q13),2) -> 0 | U13: 0 | V13: =ROUND((ROUND((U13),2)*T13),2) -> 0 | X13: 0 | Y13: =ROUND((ROUND((X13),2)*W13),2) -> 0 | AA13: 0 | AB13: =ROUND((ROUND((AA13),2)*Z13),2) -> 0 | AD13: 0 | AE13: =ROUND((ROUND((AD13),2)*AC13),2) -> 0 | AG13: 0 | AH13: =ROUND((ROUND((AG13),2)*AF13),2) -> 0 | AJ13: =G13 -> 0 | AK13: =A13 -> X005AA
A14: X005AB | B14: FFP | C14: Non-Long Lead Parts | D14: EA | E14: 5 | G14: =ROUND((ROUND((F14),2)*E14),2) -> 0 | I14: 0 | J14: =ROUND((ROUND((I14),2)*H14),2) -> 0 | L14: 0 | M14: =ROUND((ROUND((L14),2)*K14),2) -> 0 | O14: 0 | P14: =ROUND((ROUND((O14),2)*N14),2) -> 0 | R14: 0 | S14: =ROUND((ROUND((R14),2)*Q14),2) -> 0 | U14: 0 | V14: =ROUND((ROUND((U14),2)*T14),2) -> 0 | X14: 0 | Y14: =ROUND((ROUND((X14),2)*W14),2) -> 0 | AA14: 0 | AB14: =ROUND((ROUND((AA14),2)*Z14),2) -> 0 | AD14: 0 | AE14: =ROUND((ROUND((AD14),2)*AC14),2) -> 0 | AG14: 0 | AH14: =ROUND((ROUND((AG14),2)*AF14),2) -> 0 | AJ14: =G14+J14+M14+P14 -> 0 | AK14: =A14 -> X005AB
A15: X006 | C15: Lot 1 Kit Group #B | AK15: =A15 -> X006
A16: X006AA | B16: FFP | C16: Long Lead Parts | D16: EA | E16: 5 | G16: =ROUND((ROUND((F16),2)*E16),2) -> 0 | I16: 0 | J16: =ROUND((ROUND((I16),2)*H16),2) -> 0 | M16: =ROUND((ROUND((L16),2)*K16),2) -> 0 | O16: 0 | P16: =ROUND((ROUND((O16),2)*N16),2) -> 0 | R16: 0 | S16: =ROUND((ROUND((R16),2)*Q16),2) -> 0 | U16: 0 | V16: =ROUND((ROUND((U16),2)*T16),2) -> 0 | X16: 0 | Y16: =ROUND((ROUND((X16),2)*W16),2) -> 0 | AA16: 0 | AB16: =ROUND((ROUND((AA16),2)*Z16),2) -> 0 | AD16: 0 | AE16: =ROUND((ROUND((AD16),2)*AC16),2) -> 0 | AG16: 0 | AH16: =ROUND((ROUND((AG16),2)*AF16),2) -> 0 | AJ16: =G16 -> 0 | AK16: =A16 -> X006AA
A17: X006AB | B17: FFP | C17: Non-Long Lead Parts | D17: EA | E17: 5 | G17: =ROUND((ROUND((F17),2)*E17),2) -> 0 | I17: 0 | J17: =ROUND((ROUND((I17),2)*H17),2) -> 0 | L17: 0 | M17: =ROUND((ROUND((L17),2)*K17),2) -> 0 | O17: 0 | P17: =ROUND((ROUND((O17),2)*N17),2) -> 0 | R17: 0 | S17: =ROUND((ROUND((R17),2)*Q17),2) -> 0 | U17: 0 | V17: =ROUND((ROUND((U17),2)*T17),2) -> 0 | X17: 0 | Y17: =ROUND((ROUND((X17),2)*W17),2) -> 0 | AA17: 0 | AB17: =ROUND((ROUND((AA17),2)*Z17),2) -> 0 | AD17: 0 | AE17: =ROUND((ROUND((AD17),2)*AC17),2) -> 0 | AG17: 0 | AH17: =ROUND((ROUND((AG17),2)*AF17),2) -> 0 | AJ17: =G17+J17+M17+P17 -> 0 | AK17: =A17 -> X006AB
A18: X007 | C18: Lot 1 Kit Group #E | AK18: =A18 -> X007
A19: X007AA | B19: FFP | C19: Long Lead Parts | D19: EA | E19: 5 | G19: =ROUND((ROUND((F19),2)*E19),2) -> 0 | I19: 0 | J19: =ROUND((ROUND((I19),2)*H19),2) -> 0 | M19: =ROUND((ROUND((L19),2)*K19),2) -> 0 | O19: 0 | P19: =ROUND((ROUND((O19),2)*N19),2) -> 0 | R19: 0 | S19: =ROUND((ROUND((R19),2)*Q19),2) -> 0 | U19: 0 | V19: =ROUND((ROUND((U19),2)*T19),2) -> 0 | X19: 0 | Y19: =ROUND((ROUND((X19),2)*W19),2) -> 0 | AA19: 0 | AB19: =ROUND((ROUND((AA19),2)*Z19),2) -> 0 | AD19: 0 | AE19: =ROUND((ROUND((AD19),2)*AC19),2) -> 0 | AG19: 0 | AH19: =ROUND((ROUND((AG19),2)*AF19),2) -> 0 | AJ19: =G19 -> 0 | AK19: =A19 -> X007AA
A20: X007AB | B20: FFP | C20: Non-Long Lead Parts | D20: EA | E20: 5 | G20: =ROUND((ROUND((F20),2)*E20),2) -> 0 | I20: 0 | J20: =ROUND((ROUND((I20),2)*H20),2) -> 0 | L20: 0 | M20: =ROUND((ROUND((L20),2)*K20),2) -> 0 | O20: 0 | P20: =ROUND((ROUND((O20),2)*N20),2) -> 0 | R20: 0 | S20: =ROUND((ROUND((R20),2)*Q20),2) -> 0 | U20: 0 | V20: =ROUND((ROUND((U20),2)*T20),2) -> 0 | X20: 0 | Y20: =ROUND((ROUND((X20),2)*W20),2) -> 0 | AA20: 0 | AB20: =ROUND((ROUND((AA20),2)*Z20),2) -> 0 | AD20: 0 | AE20: =ROUND((ROUND((AD20),2)*AC20),2) -> 0 | AG20: 0 | AH20: =ROUND((ROUND((AG20),2)*AF20),2) -> 0 | AJ20: =G20+J20+M20+P20 -> 0 | AK20: =A20 -> X007AB
C21: Lots 2-6 Kits | E21: See Note 6
A22: X008 | B22: FPEPA | C22: Lots 2-6 Kit Group #A | D22: EA | E22: 1 | G22: =ROUND((ROUND((F22),2)*E22),2) -> 0 | H22: 12 | J22: =ROUND((ROUND((I22),2)*H22),2) -> 0 | K22: 17 | M22: =ROUND((ROUND((L22),2)*K22),2) -> 0 | N22: 17 | P22: =ROUND((ROUND((O22),2)*N22),2) -> 0 | Q22: 12 | S22: =ROUND((ROUND((R22),2)*Q22),2) -> 0 | T22: 11 | V22: =ROUND((ROUND((U22),2)*T22),2) -> 0 | W22: 1 | Y22: =ROUND((ROUND((X22),2)*W22),2) -> 0 | Z22: 1 | AB22: =ROUND((ROUND((AA22),2)*Z22),2) -> 0 | AC22: 1 | AE22: =ROUND((ROUND((AD22),2)*AC22),2) -> 0 | AF22: 1 | AH22: =ROUND((ROUND((AG22),2)*AF22),2) -> 0 | AJ22: =G22+J22+M22+P22+S22+V22+Y22+AB22+AE22+AH22 -> 0 | AK22: =A22 -> X008
A23: X009 | B23: FPEPA | C23: Lots 2-6 Kit Group #B | D23: EA | E23: 1 | G23: =ROUND((ROUND((F23),2)*E23),2) -> 0 | H23: 12 | J23: =ROUND((ROUND((I23),2)*H23),2) -> 0 | K23: 17 | M23: =ROUND((ROUND((L23),2)*K23),2) -> 0 | N23: 17 | P23: =ROUND((ROUND((O23),2)*N23),2) -> 0 | Q23: 12 | S23: =ROUND((ROUND((R23),2)*Q23),2) -> 0 | T23: 11 | V23: =ROUND((ROUND((U23),2)*T23),2) -> 0 | W23: 1 | Y23: =ROUND((ROUND((X23),2)*W23),2) -> 0 | Z23: 1 | AB23: =ROUND((ROUND((AA23),2)*Z23),2) -> 0 | AC23: 1 | AE23: =ROUND((ROUND((AD23),2)*AC23),2) -> 0 | AF23: 1 | AH23: =ROUND((ROUND((AG23),2)*AF23),2) -> 0 | AJ23: =G23+J23+M23+P23+S23+V23+Y23+AB23+AE23+AH23 -> 0 | AK23: =A23 -> X009
A24: X010 | B24: FPEPA | C24: Lots 2-6 Kit Group #E | D24: EA | E24: 1 | G24: =ROUND((ROUND((F24),2)*E24),2) -> 0 | H24: 12 | J24: =ROUND((ROUND((I24),2)*H24),2) -> 0 | K24: 17 | M24: =ROUND((ROUND((L24),2)*K24),2) -> 0 | N24: 17 | P24: =ROUND((ROUND((O24),2)*N24),2) -> 0 | Q24: 12 | S24: =ROUND((ROUND((R24),2)*Q24),2) -> 0 | T24: 11 | V24: =ROUND((ROUND((U24),2)*T24),2) -> 0 | W24: 1 | Y24: =ROUND((ROUND((X24),2)*W24),2) -> 0 | Z24: 1 | AB24: =ROUND((ROUND((AA24),2)*Z24),2) -> 0 | AC24: 1 | AE24: =ROUND((ROUND((AD24),2)*AC24),2) -> 0 | AF24: 1 | AH24: =ROUND((ROUND((AG24),2)*AF24),2) -> 0 | AJ24: =G24+J24+M24+P24+S24+V24+Y24+AB24+AE24+AH24 -> 0 | AK24: =A24 -> X010
C25: Technical Data Package (TDP) Updates See Note 1 Below
C26: Engineering Fixed Hourly Rate | E26: 160 | F26: =F46 -> 0 | G26: =ROUND((ROUND((F26),2)*E26),2) -> 0 | H26: 1 | I26: =I46 -> 0 | J26: =ROUND((ROUND((I26),2)*H26),2) -> 0 | K26: 1 | L26: =L46 -> 0 | M26: =ROUND((ROUND((L26),2)*K26),2) -> 0 | N26: 1 | O26: =O46 -> 0 | P26: =ROUND((ROUND((O26),2)*N26),2) -> 0 | Q26: 1 | R26: =R46 -> 0 | S26: =ROUND((ROUND((R26),2)*Q26),2) -> 0 | T26: 1 | U26: =U46 -> 0 | V26: =ROUND((ROUND((U26),2)*T26),2) -> 0 | W26: 1 | X26: =X46 -> 0 | Y26: =ROUND((ROUND((X26),2)*W26),2) -> 0 | Z26: 1 | AA26: =AA46 -> 0 | AB26: =ROUND((ROUND((AA26),2)*Z26),2) -> 0 | AC26: 1 | AD26: =AD46 -> 0 | AE26: =ROUND((ROUND((AD26),2)*AC26),2) -> 0 | AF26: 1 | AG26: =AG46 -> 0 | AH26: =ROUND((ROUND((AG26),2)*AF26),2) -> 0 | AJ26: =G26+J26+M26+P26+S26+V26+Y26+AB26+AE26+AH26 -> 0
C27: Administrative Fixed Hourly Rate | E27: 35 | F27: =F43 -> 0 | G27: =ROUND((ROUND((F27),2)*E27),2) -> 0 | H27: 1 | I27: =I43 -> 0 | J27: =ROUND((ROUND((I27),2)*H27),2) -> 0 | K27: 1 | L27: =L43 -> 0 | M27: =ROUND((ROUND((L27),2)*K27),2) -> 0 | N27: 1 | O27: =O43 -> 0 | P27: =ROUND((ROUND((O27),2)*N27),2) -> 0 | Q27: 1 | R27: =R43 -> 0 | S27: =ROUND((ROUND((R27),2)*Q27),2) -> 0 | T27: 1 | U27: =U43 -> 0 | V27: =ROUND((ROUND((U27),2)*T27),2) -> 0 | W27: 1 | X27: =X43 -> 0 | Y27: =ROUND((ROUND((X27),2)*W27),2) -> 0 | Z27: 1 | AA27: =AA43 -> 0 | AB27: =ROUND((ROUND((AA27),2)*Z27),2) -> 0 | AC27: 1 | AD27: =AD43 -> 0 | AE27: =ROUND((ROUND((AD27),2)*AC27),2) -> 0 | AF27: 1 | AG27: =AG43 -> 0 | AH27: =ROUND((ROUND((AG27),2)*AF27),2) -> 0 | AJ27: =G27+J27+M27+P27+S27+V27+Y27+AB27+AE27+AH27 -> 0
C28: Fabrication Fixed Hourly Rate | E28: 165 | F28: =F49 -> 0 | G28: =ROUND((ROUND((F28),2)*E28),2) -> 0 | H28: 1 | I28: =I49 -> 0 | J28: =ROUND((ROUND((I28),2)*H28),2) -> 0 | K28: 1 | L28: =L49 -> 0 | M28: =ROUND((ROUND((L28),2)*K28),2) -> 0 | N28: 1 | O28: =O49 -> 0 | P28: =ROUND((ROUND((O28),2)*N28),2) -> 0 | Q28: 1 | R28: =R49 -> 0 | S28: =ROUND((ROUND((R28),2)*Q28),2) -> 0 | T28: 1 | U28: =U49 -> 0 | V28: =ROUND((ROUND((U28),2)*T28),2) -> 0 | W28: 1 | X28: =X49 -> 0 | Y28: =ROUND((ROUND((X28),2)*W28),2) -> 0 | Z28: 1 | AA28: =AA49 -> 0 | AB28: =ROUND((ROUND((AA28),2)*Z28),2) -> 0 | AC28: 1 | AD28: =AD49 -> 0 | AE28: =ROUND((ROUND((AD28),2)*AC28),2) -> 0 | AF28: 1 | AG28: =AG49 -> 0 | AH28: =ROUND((ROUND((AG28),2)*AF28),2) -> 0 | AJ28: =G28+J28+M28+P28+S28+V28+Y28+AB28+AE28+AH28 -> 0
A29: X011 | B29: TBN (FFP) | C29: Spare Parts - TBN Per Occurrence - Prime or Subcontractor Material Handling Rates - See Note 2 Below | D29: EA | E29: 1000 | F29: =F52+1 -> 1 | G29: =ROUND((ROUND((F29),4)*E29),2) -> 1000 | H29: 1000 | I29: =I52+1 -> 1 | J29: =ROUND((ROUND((I29),4)*H29),2) -> 1000 | K29: 1000 | L29: =L52+1 -> 1 | M29: =ROUND((ROUND((L29),4)*K29),2) -> 1000 | N29: 1000 | O29: =O52+1 -> 1 | P29: =ROUND((ROUND((O29),4)*N29),2) -> 1000 | Q29: 1000 | R29: =R52+1 -> 1 | S29: =ROUND((ROUND((R29),4)*Q29),2) -> 1000 | T29: 1000 | U29: =U52+1 -> 1 | V29: =ROUND((ROUND((U29),4)*T29),2) -> 1000 | W29: 1000 | X29: =X52+1 -> 1 | Y29: =ROUND((ROUND((X29),4)*W29),2) -> 1000 | Z29: 1000 | AA29: =AA52+1 -> 1 | AB29: =ROUND((ROUND((AA29),4)*Z29),2) -> 1000 | AC29: 1000 | AD29: =AD52+1 -> 1 | AE29: =ROUND((ROUND((AD29),4)*AC29),2) -> 1000 | AF29: 1000 | AG29: =AG52+1 -> 1 | AH29: =ROUND((ROUND((AG29),4)*AF29),2) -> 1000 | AJ29: =G29+J29+M29+P29+S29+V29+Y29+AB29+AE29+AH29 -> 10000 | AK29: =A29 -> X011
A30: X012 | B30: TBN (FFP) | C30: Peculiar Support Equipment - TBN Per Occurrence - Prime or Subcontractor Material Handling Rates - See Note 2 Below | D30: EA | E30: 1000 | F30: =F52+1 -> 1 | G30: =ROUND((ROUND((F30),4)*E30),2) -> 1000 | H30: 1000 | I30: =I52+1 -> 1 | J30: =ROUND((ROUND((I30),4)*H30),2) -> 1000 | K30: 1000 | L30: =L52+1 -> 1 | M30: =ROUND((ROUND((L30),4)*K30),2) -> 1000 | N30: 1000 | O30: =O52+1 -> 1 | P30: =ROUND((ROUND((O30),4)*N30),2) -> 1000 | Q30: 1000 | R30: =R52+1 -> 1 | S30: =ROUND((ROUND((R30),4)*Q30),2) -> 1000 | T30: 1000 | U30: =U52+1 -> 1 | V30: =ROUND((ROUND((U30),4)*T30),2) -> 1000 | W30: 1000 | X30: =X52+1 -> 1 | Y30: =ROUND((ROUND((X30),4)*W30),2) -> 1000 | Z30: 1000 | AA30: =AA52+1 -> 1 | AB30: =ROUND((ROUND((AA30),4)*Z30),2) -> 1000 | AC30: 1000 | AD30: =AD52+1 -> 1 | AE30: =ROUND((ROUND((AD30),4)*AC30),2) -> 1000 | AF30: 1000 | AG30: =AG52+1 -> 1 | AH30: =ROUND((ROUND((AG30),4)*AF30),2) -> 1000 | AJ30: =G30+J30+M30+P30+S30+V30+Y30+AB30+AE30+AH30 -> 10000 | AK30: =A30 -> X012
A31: X013 | B31: TBN (FFP) | C31: Production Tooling - TBN Per Occurrence - Prime or Subcontractor Material Handling Rates - See Note 2 Below | D31: EA | E31: 1000 | F31: =F52+1 -> 1 | G31: =ROUND((ROUND((F31),4)*E31),2) -> 1000 | H31: 1000 | I31: =I52+1 -> 1 | J31: =ROUND((ROUND((I31),4)*H31),2) -> 1000 | K31: 1000 | L31: =L52+1 -> 1 | M31: =ROUND((ROUND((L31),4)*K31),2) -> 1000 | N31: 1000 | O31: =O52+1 -> 1 | P31: =ROUND((ROUND((O31),4)*N31),2) -> 1000 | Q31: 1000 | R31: =R52+1 -> 1 | S31: =ROUND((ROUND((R31),4)*Q31),2) -> 1000 | T31: 1000 | U31: =U52+1 -> 1 | V31: =ROUND((ROUND((U31),4)*T31),2) -> 1000 | W31: 1000 | X31: =X52+1 -> 1 | Y31: =ROUND((ROUND((X31),4)*W31),2) -> 1000 | Z31: 1000 | AA31: =AA52+1 -> 1 | AB31: =ROUND((ROUND((AA31),4)*Z31),2) -> 1000 | AC31: 1000 | AD31: =AD52+1 -> 1 | AE31: =ROUND((ROUND((AD31),4)*AC31),2) -> 1000 | AF31: 1000 | AG31: =AG52+1 -> 1 | AH31: =ROUND((ROUND((AG31),4)*AF31),2) -> 1000 | AJ31: =G31+J31+M31+P31+S31+V31+Y31+AB31+AE31+AH31 -> 10000 | AK31: =A31 -> X013
A32: X014 | B32: TBN (FFP) | C32: Common Support Equipment - TBN Per Occurrence - Prime or Subcontractor Material Handling Rates - See Note 2 Below | D32: EA | E32: 1000 | F32: =F53+1 -> 1 | G32: =ROUND((ROUND((F32),4)*E32),2) -> 1000 | H32: 1000 | I32: =I53+1 -> 1 | J32: =ROUND((ROUND((I32),4)*H32),2) -> 1000 | K32: 1000 | L32: =L53+1 -> 1 | M32: =ROUND((ROUND((L32),4)*K32),2) -> 1000 | N32: 1000 | O32: =O53+1 -> 1 | P32: =ROUND((ROUND((O32),4)*N32),2) -> 1000 | Q32: 1000 | R32: =R53+1 -> 1 | S32: =ROUND((ROUND((R32),4)*Q32),2) -> 1000 | T32: 1000 | U32: =U53+1 -> 1 | V32: =ROUND((ROUND((U32),4)*T32),2) -> 1000 | W32: 1000 | X32: =X53+1 -> 1 | Y32: =ROUND((ROUND((X32),4)*W32),2) -> 1000 | Z32: 1000 | AA32: =AA53+1 -> 1 | AB32: =ROUND((ROUND((AA32),4)*Z32),2) -> 1000 | AC32: 1000 | AD32: =AD53+1 -> 1 | AE32: =ROUND((ROUND((AD32),4)*AC32),2) -> 1000 | AF32: 1000 | AG32: =AG53+1 -> 1 | AH32: =ROUND((ROUND((AG32),4)*AF32),2) -> 1000 | AJ32: =G32+J32+M32+P32+S32+V32+Y32+AB32+AE32+AH32 -> 10000 | AK32: =A32 -> X014
A33: X015 | B33: NSP | C33: Data (Not Separately Priced) | D33: EA | AK33: =A33 -> X015
A34: X016 | B34: TBN (FFP) | C34: Data (Separately Priced) - TBN Per Occurrence - Engineering Fixed Hourly Labor Rates | D34: EA | E34: 180 | F34: =F46 -> 0 | G34: =ROUND((ROUND((F34),2)*E34),2) -> 0 | H34: 180 | I34: =I46 -> 0 | J34: =ROUND((ROUND((I34),2)*H34),2) -> 0 | K34: 40 | L34: =L46 -> 0 | M34: =ROUND((ROUND((L34),2)*K34),2) -> 0 | N34: 40 | O34: =O46 -> 0 | P34: =ROUND((ROUND((O34),2)*N34),2) -> 0 | Q34: 40 | R34: =R46 -> 0 | S34: =ROUND((ROUND((R34),2)*Q34),2) -> 0 | T34: 40 | U34: =U46 -> 0 | V34: =ROUND((ROUND((U34),2)*T34),2) -> 0 | W34: 40 | X34: =X46 -> 0 | Y34: =ROUND((ROUND((X34),2)*W34),2) -> 0 | Z34: 40 | AA34: =AA46 -> 0 | AB34: =ROUND((ROUND((AA34),2)*Z34),2) -> 0 | AC34: 40 | AD34: =AD46 -> 0 | AE34: =ROUND((ROUND((AD34),2)*AC34),2) -> 0 | AF34: 40 | AG34: =AG46 -> 0 | AH34: =ROUND((ROUND((AG34),2)*AF34),2) -> 0 | AJ34: =G34+J34+M34+P34+S34+V34+Y34+AB34+AE34+AH34 -> 0 | AK34: =A34 -> X016
A35: X017 | B35: TBN (FFP) | C35: Over & Above Labor - TBN Per Occurrence - Engineering Fixed Hourly Labor Rates | D35: EA | E35: 180 | F35: =F46 -> 0 | G35: =ROUND((ROUND((F35),2)*E35),2) -> 0 | H35: 180 | I35: =I46 -> 0 | J35: =ROUND((ROUND((I35),2)*H35),2) -> 0 | K35: 40 | L35: =L46 -> 0 | M35: =ROUND((ROUND((L35),2)*K35),2) -> 0 | N35: 40 | O35: =O46 -> 0 | P35: =ROUND((ROUND((O35),2)*N35),2) -> 0 | Q35: 40 | R35: =R46 -> 0 | S35: =ROUND((ROUND((R35),2)*Q35),2) -> 0 | T35: 40 | U35: =U46 -> 0 | V35: =ROUND((ROUND((U35),2)*T35),2) -> 0 | W35: 40 | X35: =X46 -> 0 | Y35: =ROUND((ROUND((X35),2)*W35),2) -> 0 | Z35: 40 | AA35: =AA46 -> 0 | AB35: =ROUND((ROUND((AA35),2)*Z35),2) -> 0 | AC35: 40 | AD35: =AD46 -> 0 | AE35: =ROUND((ROUND((AD35),2)*AC35),2) -> 0 | AF35: 40 | AG35: =AG46 -> 0 | AH35: =ROUND((ROUND((AG35),2)*AF35),2) -> 0 | AJ35: =G35+J35+M35+P35+S35+V35+Y35+AB35+AE35+AH35 -> 0 | AK35: =A35 -> X017
A36: X018 | B36: TBN (FFP) | C36: Over & Above Materials - TBN Per Occurrence - Prime or Subcontractor Material Handling Rates - See Note 2 Below | D36: EA | E36: 1000 | F36: =F53+1 -> 1 | G36: =ROUND((ROUND((F36),4)*E36),2) -> 1000 | H36: 1000 | I36: =I53+1 -> 1 | J36: =ROUND((ROUND((I36),4)*H36),2) -> 1000 | K36: 1000 | L36: =L53+1 -> 1 | M36: =ROUND((ROUND((L36),4)*K36),2) -> 1000 | N36: 1000 | O36: =O53+1 -> 1 | P36: =ROUND((ROUND((O36),4)*N36),2) -> 1000 | Q36: 1000 | R36: =R53+1 -> 1 | S36: =ROUND((ROUND((R36),4)*Q36),2) -> 1000 | T36: 1000 | U36: =U53+1 -> 1 | V36: =ROUND((ROUND((U36),4)*T36),2) -> 1000 | W36: 1000 | X36: =X53+1 -> 1 | Y36: =ROUND((ROUND((X36),4)*W36),2) -> 1000 | Z36: 1000 | AA36: =AA53+1 -> 1 | AB36: =ROUND((ROUND((AA36),4)*Z36),2) -> 1000 | AC36: 1000 | AD36: =AD53+1 -> 1 | AE36: =ROUND((ROUND((AD36),4)*AC36),2) -> 1000 | AF36: 1000 | AG36: =AG53+1 -> 1 | AH36: =ROUND((ROUND((AG36),4)*AF36),2) -> 1000 | AJ36: =G36+J36+M36+P36+S36+V36+Y36+AB36+AE36+AH36 -> 10000 | AK36: =A36 -> X018
A37: X019 | B37: TBN (FFP) | C37: Over & Above Storage - TBN Per Occurrence - Transportation/Shipping G&A Rate | D37: EA | E37: 1000 | F37: =F55+1 -> 1 | G37: =ROUND((ROUND((F37),4)*E37),2) -> 1000 | H37: 1000 | I37: =I55+1 -> 1 | J37: =ROUND((ROUND((I37),4)*H37),2) -> 1000 | K37: 1000 | L37: =L55+1 -> 1 | M37: =ROUND((ROUND((L37),4)*K37),2) -> 1000 | N37: 1000 | O37: =O55+1 -> 1 | P37: =ROUND((ROUND((O37),4)*N37),2) -> 1000 | Q37: 1000 | R37: =R55+1 -> 1 | S37: =ROUND((ROUND((R37),4)*Q37),2) -> 1000 | T37: 1000 | U37: =U55+1 -> 1 | V37: =ROUND((ROUND((U37),4)*T37),2) -> 1000 | W37: 1000 | X37: =X55+1 -> 1 | Y37: =ROUND((ROUND((X37),4)*W37),2) -> 1000 | Z37: 1000 | AA37: =AA55+1 -> 1 | AB37: =ROUND((ROUND((AA37),4)*Z37),2) -> 1000 | AC37: 1000 | AD37: =AD55+1 -> 1 | AE37: =ROUND((ROUND((AD37),4)*AC37),2) -> 1000 | AF37: 1000 | AG37: =AG55+1 -> 1 | AH37: =ROUND((ROUND((AG37),4)*AF37),2) -> 1000 | AJ37: =G37+J37+M37+P37+S37+V37+Y37+AB37+AE37+AH37 -> 10000 | AK37: =A37 -> X019
A38: X020 | B38: TBN (FFP) | C38: Over & Above Shipping - TBN Per Occurrence - Transportation/Shipping G&A Rate | D38: EA | E38: 1000 | F38: =F55+1 -> 1 | G38: =ROUND((ROUND((F38),4)*E38),2) -> 1000 | H38: 1000 | I38: =I55+1 -> 1 | J38: =ROUND((ROUND((I38),4)*H38),2) -> 1000 | K38: 1000 | L38: =L55+1 -> 1 | M38: =ROUND((ROUND((L38),4)*K38),2) -> 1000 | N38: 1000 | O38: =O55+1 -> 1 | P38: =ROUND((ROUND((O38),4)*N38),2) -> 1000 | Q38: 1000 | R38: =R55+1 -> 1 | S38: =ROUND((ROUND((R38),4)*Q38),2) -> 1000 | T38: 1000 | U38: =U55+1 -> 1 | V38: =ROUND((ROUND((U38),4)*T38),2) -> 1000 | W38: 1000 | X38: =X55+1 -> 1 | Y38: =ROUND((ROUND((X38),4)*W38),2) -> 1000 | Z38: 1000 | AA38: =AA55+1 -> 1 | AB38: =ROUND((ROUND((AA38),4)*Z38),2) -> 1000 | AC38: 1000 | AD38: =AD55+1 -> 1 | AE38: =ROUND((ROUND((AD38),4)*AC38),2) -> 1000 | AF38: 1000 | AG38: =AG55+1 -> 1 | AH38: =ROUND((ROUND((AG38),4)*AF38),2) -> 1000 | AJ38: =G38+J38+M38+P38+S38+V38+Y38+AB38+AE38+AH38 -> 10000 | AK38: =A38 -> X020
A39: X021 | B39: TBN (FFP) | C39: Over & Above Travel - TBN Per Occurrence - Travel G&A Rate | D39: EA | E39: 1000 | F39: =F54+1 -> 1 | G39: =ROUND((ROUND((F39),4)*E39),2) -> 1000 | H39: 1000 | I39: =I54+1 -> 1 | J39: =ROUND((ROUND((I39),4)*H39),2) -> 1000 | K39: 1000 | L39: =L54+1 -> 1 | M39: =ROUND((ROUND((L39),4)*K39),2) -> 1000 | N39: 1000 | O39: =O54+1 -> 1 | P39: =ROUND((ROUND((O39),4)*N39),2) -> 1000 | Q39: 1000 | R39: =R54+1 -> 1 | S39: =ROUND((ROUND((R39),4)*Q39),2) -> 1000 | T39: 1000 | U39: =U54+1 -> 1 | V39: =ROUND((ROUND((U39),4)*T39),2) -> 1000 | W39: 1000 | X39: =X54+1 -> 1 | Y39: =ROUND((ROUND((X39),4)*W39),2) -> 1000 | Z39: 1000 | AA39: =AA54+1 -> 1 | AB39: =ROUND((ROUND((AA39),4)*Z39),2) -> 1000 | AC39: 1000 | AD39: =AD54+1 -> 1 | AE39: =ROUND((ROUND((AD39),4)*AC39),2) -> 1000 | AF39: 1000 | AG39: =AG54+1 -> 1 | AH39: =ROUND((ROUND((AG39),4)*AF39),2) -> 1000 | AJ39: =G39+J39+M39+P39+S39+V39+Y39+AB39+AE39+AH39 -> 10000 | AK39: =A39 -> X021
C40: TOTAL | G40: =SUM(G8:G39) -> 9000 | J40: =SUM(J8:J39) -> 9000 | M40: =SUM(M8:M39) -> 9000 | P40: =SUM(P8:P39) -> 9000 | S40: =SUM(S8:S39) -> 9000 | V40: =SUM(V8:V39) -> 9000 | Y40: =SUM(Y8:Y39) -> 9000 | AB40: =SUM(AB8:AB39) -> 9000 | AE40: =SUM(AE8:AE39) -> 9000 | AH40: =SUM(AH8:AH39) -> 9000 | AJ40: =SUM(AJ8:AJ39) -> 90000
AJ41: =G40+J40+M40+P40+S40+V40+Y40+AB40+AE40+AH40 -> 90000 | AK41: cross check
...

Sheet Long Lead Parts Grp A
A1: Offeror: | C1: ='Pricing Matrix'!B1 -> Insert Offeror Name | D1: ='Pricing Matrix'!F1 -> DRAFT PRICING MATRIX 31 March 2026
A2: INSTRUCTIONS - Fill in the yellow highlighted cells as follows:
A3: Insert the Description of Long Lead Parts for Lot 1 Kit Group #A in Column C. Insert the Proposed Unit Prices (Column E) and Proposed Quantities (Column F) for the Basic Period Year 1. Offerors may insert additional rows as needed.
A4: Enter the total price for CLIN X005AA in the corresponding cell (proposed unit price) in the Pricing Matrix spreadsheet for Basic Period Year 1.
C6: B-52J CERP Kit Production
E7: Basic Period (Year 1)
A8: CLIN | B8: Contract Type | C8: Description | D8: Unit of Issue | E8: Proposed Unit Price | F8: Proposed Quantity | G8: Extended Total
A9: X005 | C9: Lot 1 Kit Group #A - Long Lead Parts
A10: X005AA | B10: FFP | D10: EA | G10: =ROUND((E10*F10),2) -> 0
A11: X005AA | B11: FFP | D11: EA | G11: =ROUND((E11*F11),2) -> 0
A12: X005AA | B12: FFP | D12: EA | G12: =ROUND((E12*F12),2) -> 0
A13: X005AA | B13: FFP | D13: EA | G13: =ROUND((E13*F13),2) -> 0
A14: X005AA | B14: FFP | D14: EA | G14: =ROUND((E14*F14),2) -> 0
A15: X005AA | B15: FFP | D15: EA | G15: =ROUND((E15*F15),2) -> 0
A16: X005AA | B16: FFP | D16: EA | G16: =ROUND((E16*F16),2) -> 0
A17: X005AA | B17: FFP | D17: EA | G17: =ROUND((E17*F17),2) -> 0
A18: X005AA | B18: FFP | D18: EA | G18: =ROUND((E18*F18),2) -> 0
A19: X005AA | B19: FFP | D19: EA | G19: =ROUND((E19*F19),2) -> 0
A20: X005AA | B20: FFP | D20: EA | G20: =ROUND((E20*F20),2) -> 0
A21: X005AA | B21: FFP | D21: EA | G21: =ROUND((E21*F21),2) -> 0
... A62: X005AA | B62: FFP | D62: EA | G62: =ROUND((E62*F62),2) -> 0
C63: Total CLIN X005AA | G63: =SUM(G10:G62) -> 0

Sheet Long Lead Parts Grp B
A1: Offeror: | C1: ='Pricing Matrix'!B1 -> Insert Offeror Name | D1: ='Pricing Matrix'!F1 -> DRAFT PRICING MATRIX 31 March 2026
A2: INSTRUCTIONS - Fill in the yellow highlighted cells as follows:
A3: Insert the Description of Long Lead Parts for Lot 1 Kit Group #B in Column C. Insert the Proposed Unit Prices (Column E) and Proposed Quantities (Column F) for the Basic Period Year 1. Offerors may insert additional rows as needed.
A4: Enter the total price for CLIN X006AA in the corresponding cell (proposed unit price) in the Pricing Matrix spreadsheet for Basic Period Year 1.
C6: B-52J CERP Kit Production
E7: Basic Period (Year 1)
A8: CLIN | B8: Contract Type | C8: Description | D8: Unit of Issue | E8: Proposed Unit Price | F8: Proposed Quantity | G8: Extended Total
A9: X006 | C9: Lot 1 Kit Group #B - Long Lead Parts
A10: X006AA | B10: FFP | D10: EA | G10: =ROUND((E10*F10),2) -> 0
A11: X006AA | B11: FFP | D11: EA | G11: =ROUND((E11*F11),2) -> 0
A12: X006AA | B12: FFP | D12: EA | G12: =ROUND((E12*F12),2) -> 0
A13: X006AA | B13: FFP | D13: EA | G13: =ROUND((E13*F13),2) -> 0
A14: X006AA | B14: FFP | D14: EA | G14: =ROUND((E14*F14),2) -> 0
A15: X006AA | B15: FFP | D15: EA | G15: =ROUND((E15*F15),2) -> 0
A16: X006AA | B16: FFP | D16: EA | G16: =ROUND((E16*F16),2) -> 0
A17: X006AA | B17: FFP | D17: EA | G17: =ROUND((E17*F17),2) -> 0
A18: X006AA | B18: FFP | D18: EA | G18: =ROUND((E18*F18),2) -> 0
A19: X006AA | B19: FFP | D19: EA | G19: =ROUND((E19*F19),2) -> 0
A20: X006AA | B20: FFP | D20: EA | G20: =ROUND((E20*F20),2) -> 0
A21: X006AA | B21: FFP | D21: EA | G21: =ROUND((E21*F21),2) -> 0
... A62: X006AA | B62: FFP | D62: EA | G62: =ROUND((E62*F62),2) -> 0
C63: Total CLIN X006AA | G63: =SUM(G10:G62) -> 0

Sheet Long Lead Parts Grp E
A1: Offeror: | C1: ='Pricing Matrix'!B1 -> Insert Offeror Name | D1: ='Pricing Matrix'!F1 -> DRAFT PRICING MATRIX 31 March 2026
A2: INSTRUCTIONS - Fill in the yellow highlighted cells as follows:
A3: Insert the Description of Long Lead Parts for Lot 1 Kit Group #E in Column C. Insert the Proposed Unit Prices (Column E) and Proposed Quantities (Column F) for the Basic Period Year 1. Offerors may insert additional rows as needed.
A4: Enter the total price for CLIN X007AA in the corresponding cell (proposed unit price) in the Pricing Matrix spreadsheet for Basic Period Year 1.
C6: B-52J CERP Kit Production
E7: Basic Period (Year 1)
A8: CLIN | B8: Contract Type | C8: Description | D8: Unit of Issue | E8: Proposed Unit Price | F8: Proposed Quantity | G8: Extended Total
A9: X007 | C9: Lot 1 Kit Group #E - Long Lead Parts
A10: X007AA | B10: FFP | D10: EA | G10: =ROUND((E10*F10),2) -> 0
A11: X007AA | B11: FFP | D11: EA | G11: =ROUND((E11*F11),2) -> 0
A12: X007AA | B12: FFP | D12: EA | G12: =ROUND((E12*F12),2) -> 0
A13: X007AA | B13: FFP | D13: EA | G13: =ROUND((E13*F13),2) -> 0
A14: X007AA | B14: FFP | D14: EA | G14: =ROUND((E14*F14),2) -> 0
A15: X007AA | B15: FFP | D15: EA | G15: =ROUND((E15*F15),2) -> 0
A16: X007AA | B16: FFP | D16: EA | G16: =ROUND((E16*F16),2) -> 0
A17: X007AA | B17: FFP | D17: EA | G17: =ROUND((E17*F17),2) -> 0
A18: X007AA | B18: FFP | D18: EA | G18: =ROUND((E18*F18),2) -> 0
A19: X007AA | B19: FFP | D19: EA | G19: =ROUND((E19*F19),2) -> 0
A20: X007AA | B20: FFP | D20: EA | G20: =ROUND((E20*F20),2) -> 0
A21: X007AA | B21: FFP | D21: EA | G21: =ROUND((E21*F21),2) -> 0
... A62: X007AA | B62: FFP | D62: EA | G62: =ROUND((E62*F62),2) -> 0
C63: Total CLIN X007AA | G63: =SUM(G10:G62) -> 0
