Workbook

Sheet 1-Service Provider Info
A1: ATTACHMENT J-0200000-05 SERVICE PROVIDER INFORMATION
A3: Interface: Service Provider
A4: VERSION #: | B4: V1
A5: Current as of: | B5: 1/24/2025
A9: Version History
A10: V1 - Updated to reflect current interface in MAXIMO
A23: TABS
A24: 1-Service Provider Info | B24: This Sheet
A25: 2-Service Provider Field List | B25: Service Provider Template Data Format Information
A26: 3-Service Provider - Template | B26: Sample Excel Format

Sheet 2-Service Provider Field List
A1: ATTACHMENT J-0200000-05 SERVICE PROVIDER INFORMATION
A3: =+'1-Service Provider Info'!A3 -> Interface: Service Provider
A4: =CONCATENATE('1-Service Provider Info'!A4," ",'1-Service Provider Info'!B4) -> VERSION #: V1
A5: =CONCATENATE('1-Service Provider Info'!A5," ",'1-Service Provider Info'!B5) -> Current as of: 1/24/2025
A6: Service Provider (BOSC1) is a pipe delimited file.
A7: Position | B7: Name | C7: Required | D7: Length Limit | E7: Data Format Note | F7: Field Definition | G7: Content Notes | H7: NAVFAC MAXIMO_FIELD
A8: 1 | B8: Approved Date | C8: N | D8: 10 | E8: MM/DD/YYYY hh:mm:ss | F8: The Date on which the Work Order was last approved. If the file contains an Approved Date, then this date will be pulled over to the record. If the Approved Date in the file is null, then the Reported Date plus one minute will be displayed in the record. | H8: APPROVEDDATE
A9: =+A8+1 -> 2 | B9: Work Type | C9: Y | D9: 15 | E9: Must match Value List in Maximo. (Cross-walked field.). Must match Crosswalk | F9: Identifies the work order's type. Example types are: preventive maintenance, corrective maintenance, emergency maintenance, capital project, and event report. | G9: Value list in REFERENCE SPREADSHEET -or- a valid work types will be specified at contract start | H9: WORKTYPE
A10: =+A9+1 -> 3 | B10: Customer Reference Number | C10: Y | D10: 10 | F10: Contractors internal work order tracking number. Will update Record if Value is found in Maximo otherwise new record (Work order) will be created. | H10: SERVPRVREFCODE
A11: =+A10+1 -> 4 | B11: Description | C11: Y | D11: 150 | F11: Describes the work order. If the Description is null, in the inbound file, then this field is defaulted to CROSSWALK value. | H11: DESCRIPTION
A12: =+A11+1 -> 5 | B12: Location | C12: Y | D12: 30 | E12: Must match Value List in Maximo | F12: Identifies the work order's location. This is not necessarily the asset's location, however, if an asset is entered, its location will default here. - If the Location is null, in the inbound file, then this field is defaulted to the site's base location. | G12: Value list in REFERENCE SPREADSHEET | H12: LOCATION
A13: =+A12+1 -> 6 | B13: Reported By | C13: N | D13: 62 | E13: Must match Value List in Maximo | F13: Identifies the person reporting the work order. | G13: Value list in REFERENCE SPREADSHEET -or- a valid identifier will be specified at contract start | H13: REPORTEDBY
A14: =+A13+1 -> 7 | B14: Master System | C14: N | D14: N/A | E14: Not used | H14: N/A
A15: =+A14+1 -> 8 | B15: Status | C15: Y | D15: 16 | E15: (Cross-walked field.) Must match Crosswalk | F15: Status of the work order, for example, in progress, waiting on material, waiting for approval, completed, or closed. | G15: Value list in REFERENCE SPREADSHEET -or- a valid identifier will be specified at contract start | H15: STATUS
A16: =+A15+1 -> 9 | B16: Status Date | C16: Y | D16: 10 | E16: MM/DD/YYYY hh:mm:ss | H16: STATUSDATE
A17: =+A16+1 -> 10 | B17: Priority | C17: Y | D17: 12 | E17: (Cross-walked field.) Must match Crosswalk | F17: Identifies the importance of the work order, from 0-999, where 0 is the lowest priority and 999 is the highest. If the Priority is null, in the inbound file, then this field is defaulted. | G17: Value list in REFERENCE SPREADSHEET | H17: WOPRIORITY
A18: =+A17+1 -> 11 | B18: Actual Start | C18: N | D18: 10 | E18: MM/DD/YYYY hh:mm:ss | H18: ACTSTART
A19: =+A18+1 -> 12 | B19: Actual Finish | C19: N | D19: 10 | E19: MM/DD/YYYY hh:mm:ss | H19: ACTFINISH
A20: =+A19+1 -> 13 | B20: Supervisor | C20: N | D20: 30 | E20: Must match Value List in Maximo | G20: Value list in REFERENCE SPREADSHEET -or- a valid identifier will be specified at contract start | H20: SUPERVISOR
A21: =+A20+1 -> 14 | B21: Labor Hours(Actual) | C21: Y | D21: 8 | E21: Number (2 decimal places) | H21: ACTLABHRS
A22: =+A21+1 -> 15 | B22: Labor Cost(Actual) | C22: Y | D22: 10 | E22: Number (2 decimal places) | H22: ACTLABCOST
A23: =+A22+1 -> 16 | B23: Material Cost(Actual) | C23: Y | D23: 10 | E23: Number (2 decimal places) | H23: ACTMATCOST
A24: =+A23+1 -> 17 | B24: Duration | C24: N | D24: 8 | E24: Number (2 decimal places) | F24: Estimated remaining number of hours needed to complete the work. | H24: ESTDUR
A25: =+A24+1 -> 18 | B25: Asset | C25: N | D25: 25 | E25: Must match an existing ASSETNUM in Maximo | F25: The asset number used must exist in NAVFAC MAXIMO prior to submission, or the record will be rejected. | G25: Value list in REFERENCE SPREADSHEET | H25: ASSETNUM
A26: =+A25+1 -> 19 | B26: Target Finish | C26: N | D26: 10 | E26: MM/DD/YYYY hh:mm:ss | H26: TARGCOMPDATE
A27: =+A26+1 -> 20 | B27: Target Start | C27: N | D27: 10 | E27: MM/DD/YYYY hh:mm:ss | H27: TARGSTARTDATE
A28: =+A27+1 -> 21 | B28: Reported Date | C28: Y | D28: 10 | E28: MM/DD/YYYY hh:mm:ss | H28: REPORTDATE
A29: =+A28+1 -> 22 | B29: Lead | C29: N | D29: 30 | E29: Must match Value List in Maximo | F29: Lead person responsible for the work. | G29: Value list in REFERENCE SPREADSHEET | H29: LEAD
A30: =+A29+1 -> 23 | B30: Scheduled Start | C30: N | D30: 10 | E30: MM/DD/YYYY hh:mm:ss | H30: SCHEDSTART
A31: =+A30+1 -> 24 | B31: Scheduled Finish | C31: N | D31: 10 | E31: MM/DD/YYYY hh:mm:ss | H31: SCHEDFINISH
A32: =+A31+1 -> 25 | B32: Modified Date | C32: Y | D32: 10 | E32: LEAVE BLANK | F32: Leave blank/Do Not Use | G32: Leave blank/Do Not Use | H32: CHANGEDATE
A33: =+A32+1 -> 26 | B33: Modified By | C33: Y | D33: 30 | E33: LEAVE BLANK | F33: Leave blank/Do Not Use | G33: Leave blank/Do Not Use | H33: CHANGEBY
A34: =+A33+1 -> 27 | B34: PMNEXTDUEDATE | C34: N | D34: 4 | E34: MM/DD/YYYY hh:mm:ss | H34: PMNEXTDUEDATE
A35: =+A34+1 -> 28 | B35: Is Task? | C35: Y | D35: 1 | F35: Yes or No | H35: ISTASK
A36: =+A35+1 -> 29 | B36: Parent WO | C36: N | D36: 10 | E36: Length Limit: 250 | F36: Must exist in NAVFAC MAXIMO prior to submission or the record will be rejected. | G36: Must exist in NAVFAC MAXIMO prior to submission or the record will be rejected. | H36: PARENT
A37: =+A36+1 -> 30 | B37: Work Order | C37: N | D37: 10 | E37: Must match Value List in Maximo | F37: Used in updating record status on existing records. | H37: WONUM
A38: =+A37+1 -> 31 | B38: Detail Location | C38: N | D38: 250 | H38: DETAILLOC
A39: =+A38+1 -> 32 | B39: CLIN | C39: N | D39: 30 | F39: Contract Line Item Number | H39: CLIN
A40: =+A39+1 -> 33 | B40: Customer Ref Code | C40: N | D40: 8 | E40: Must match Value List in Maximo | G40: Value list in REFERENCE SPREADSHEET | H40: CUSTOMERCODE
A41: =+A40+1 -> 34 | B41: Sub Work Type | C41: N | D41: 15 | E41: (Cross-walked field). Must match Crosswalk | F41: Defaulted field based on the value of worktype | H41: SUBWORKTYPE
...

Sheet 3-Service Provider-Template
A1: ATTACHMENT J-0200000-05 SERVICE PROVIDER INFORMATION | T1: ATTACHMENT J-0200000-05 SERVICE PROVIDER INFORMATION
A3: =+'1-Service Provider Info'!A3 -> Interface: Service Provider
A4: =CONCATENATE('1-Service Provider Info'!A4," ",'1-Service Provider Info'!B4) -> VERSION #: V1
A5: =CONCATENATE('1-Service Provider Info'!A5," ",'1-Service Provider Info'!B5) -> Current as of: 1/24/2025
A7: Position | B7: 1 | C7: 2 | D7: 3 | E7: 4 | F7: 5 | G7: 6 | H7: 7 | I7: 8 | J7: 9 | K7: 10 | L7: 11 | M7: 12 | N7: 13 | O7: 14 | P7: 15 | Q7: 16 | R7: 17 | S7: 18 | T7: 19 | U7: 20 | V7: 21 | W7: 22 | X7: 23 | Y7: 24 | Z7: 25 | AA7: 26 | AB7: 27 | AC7: 28 | AD7: 29 | AE7: 30 | AF7: 31 | AG7: 32 | AH7: 33 | AI7: 34 | AJ7: 35
A8: Name | B8: Approved Date | C8: Work Type | D8: Customer Reference Number | E8: Description | F8: Location | G8: Reported By | H8: Master System | I8: Status | J8: Status Date | K8: Priority | L8: Actual Start | M8: Actual Finish | N8: Supervisor | O8: Labor Hours (Actual) | P8: Labor Cost (Actual) | Q8: Material Cost (Actual) | R8: Duration | S8: Asset | T8: Target Finish | U8: Target Start | V8: Reported Date | W8: Lead | X8: Scheduled Start | Y8: Scheduled Finish | Z8: Modified Date | AA8: Modified By | AB8: PMNEXTDUEDATE | AC8: Is Task? | AD8: Parent WO | AE8: Work Order | AF8: Detail Location | AG8: CLIN | AH8: Customer Ref Code | AI8: Sub Work Type | AJ8: Work Center
A9: Required Field(s) | B9: N | C9: Y | D9: Y | E9: Y | F9: Y | G9: N | H9: N | I9: Y | J9: Y | K9: Y | L9: N | M9: N | N9: N | O9: Y | P9: Y | Q9: Y | R9: N | S9: N | T9: N | U9: N | V9: Y | W9: N | X9: N | Y9: N | Z9: Y | AA9: Y | AB9: N | AC9: Y | AD9: N | AE9: N | AF9: N | AG9: N | AH9: N | AI9: N | AJ9: N
