Workbook

Sheet Summary- All Periods
A2: Attachment J-0200000-10
A3: Exhibit Line Item Numbers
A4: Solicitation/Contract No.: N40080-25-R-4580
A5: Regional Grounds and Pavement Clearance
A6: ELIN SUMMARY TABLE
A9: Summary - Recurring Work
A10: Period of Performance | B10: Total Price
A11: Base Period | B11: ='Base Recurring'!H284 -> 0
A12: Option Period 1 | B12: ='Option 1 Recurring '!H255 -> 0
A13: Option Period 2 | B13: ='Option 2 Recurring'!H255 -> 0
A14: Option Period 3 | B14: ='Option 3 Recurring'!H255 -> 0
A15: Option Period 4 | B15: ='Option 4 Recurring'!H260 -> 0
A16: 6 Month Option | B16: =' 6 Month Option Recurring '!#REF! -> #REF!
A17: Total: | B17: =SUM(B11:B16) -> #REF!
A20: Summary - Non-recurring Work
A21: Period of Performance | B21: Total Price
A22: Base Period | B22: ='Base Non-Recurring'!G139 -> 0
A23: Option Period 1 | B23: ='Option1 Non-Recurring '!G139 -> 0
A24: Option Period 2 | B24: ='Option 2 Non-Recurring'!G139 -> 0
A25: Option Period 3 | B25: ='Option 3 Non-Recurring'!G139 -> 0
A26: Option Period 4 | B26: ='Option 4 Non-Recurring'!G139 -> 0
A27: 6 Month Option | B27: ='6 Month Option Non-Recurring'!G139 -> 0
A28: Total: | B28: =SUM(B22:B27) -> 0
A31: Summary - Recurring and Non-recurring Work
A32: Period of Performance | B32: Total Price
A33: Base Period | B33: =B11+B22 -> 0
A34: Option Period 1 | B34: =B12+B23 -> 0
A35: Option Period 2 | B35: =B13+B24 -> 0
A36: Option Period 3 | B36: =B14+B25 -> 0
A37: Option Period 4 | B37: =B15+B26 -> 0
A38: 6 Month Option | B38: =B16+B27 -> #REF!
A39: Total: | B39: =SUM(B33:B38) -> #REF!

Sheet Base Recurring
D1: Attachment J-0200000-10
D2: Exhibit Line Item Numbers
D3: Solicitation/Contract No.: N40080-25-R-4580
D4: Regional Grounds and Pavement Clearance
A5: Line Item 0001 - Recurring Work - Base Period
A6: Provide Prices for Recurring Work in accordance with Section C, Spec Item 3
A7: ELIN/Sub-ELINs A100 through A700
A8: ELIN/ Sub-ELIN | B8: Annex/Sub-annex | C8: Spec Item | D8: Description | E8: Quantity | F8: Unit of Measure | G8: Unit Price | H8: Total Price
A9: 1503050- Grounds Maintenance
A10: A100 | D10: PWD Washingtion
A11: A101 | B11: 1503050 | D11: Washington Navy Yard (WNY)(Region Funded)- Grounds Maintennace
A12: A101 AA | B12: 1503050 | C12: 3.1 | D12: WNY- Improved Grounds (Prestige) | E12: 12 | F12: MO | G12: =H12/E12 -> 0 | H12: 0
A13: A101 AB | B13: 1503050 | C13: 3.1 | D13: WNY- Improved Grounds (Standard Lawn)- Reserved | E13: 12 | F13: MO | G13: =H13/E13 -> 0 | H13: 0
A14: A101 AC | B14: 1503050 | C14: 3.1 | D14: WNY- Improved Grounds (Standard Field)- Reserved | E14: 12 | F14: MO | G14: =H14/E14 -> 0 | H14: 0
A15: A101 AD | B15: 1503050 | C15: 3.2 | D15: WNY- Operational Areas- Reserved | E15: 12 | F15: MO | G15: =H15/E15 -> 0 | H15: 0
A16: A101 AE | B16: 1503050 | C16: 3.3 | D16: WNY- Storm Drain Systems | E16: 12 | F16: MO | G16: =H16/E16 -> 0 | H16: 0
A17: A101 AF | B17: 1503050 | C17: 3.5 | D17: WNY- Debris Removal | E17: 12 | F17: MO | G17: =H17/E17 -> 0 | H17: 0
A18: A101 AG | B18: 1503050 | C18: 3.6 | D18: WNY- Destructive Weather-Reserved | E18: 12 | F18: MO | G18: =H18/E18 -> 0 | H18: 0
A19: A101 AH | B19: 1503050 | C19: 3.7 | D19: WNY- Interior Plant Maintenance-Reserved | E19: 12 | F19: MO | G19: =H19/E19 -> 0 | H19: 0
D20: Washington Navy Yard (WNY)(Regiona Funded) (A101) Subtotal | E20: 12 | F20: MO | G20: =SUM(G12:G19) -> 0 | H20: =SUM(H12:H19) -> 0
A21: A102 | B21: 1503050 | D21: Arlington Service Center (ASC)(Region Funded)- Grounds Maintenance
A22: A102 AA | B22: 1503050 | C22: 3.1 | D22: ASC- Improved Grounds (Prestige)- Reserved | E22: 12 | F22: MO | G22: 0 | H22: 0
A23: A102 AB | B23: 1503050 | C23: 3.1 | D23: ASC- Improved Grounds (Standard Lawn) | E23: 12 | F23: MO | G23: =H23/E23 -> 0 | H23: 0
A24: A102 AC | B24: 1503050 | C24: 3.1 | D24: ASC- Improved Grounds (Standard Field) | E24: 12 | F24: MO | G24: =H24/E24 -> 0 | H24: 0
A25: A102 AD | B25: 1503050 | C25: 3.2 | D25: ASC- Operational Areas- Reserved | E25: 12 | F25: MO | G25: =H25/E25 -> 0 | H25: 0
A26: A102 AE | B26: 1503050 | C26: 3.3 | D26: ASC- Storm Drain Systems- Reserved | E26: 12 | F26: MO | G26: =H26/E26 -> 0 | H26: 0
A27: A102 AF | B27: 1503050 | C27: 3.5 | D27: ASC- Debris Removal | E27: 12 | F27: MO | G27: =H27/E27 -> 0 | H27: 0
A28: A102 AG | B28: 1503050 | C28: 3.6 | D28: ASC- Destructive Weather- Reserved | E28: 12 | F28: MO | G28: =H28/E28 -> 0 | H28: 0
A29: A102 AH | B29: 1503050 | C29: 3.7 | D29: ASC- Interior Plant Maintenance-Reserved | E29: 12 | F29: MO | G29: =H29/E29 -> 0 | H29: 0
D30: Arlington (ASC)(Region Funded) (A102) Subtotal | E30: 12 | F30: MO | G30: =SUM(G22:G29) -> 0 | H30: =SUM(H22:H29) -> 0
A31: A103 | B31: 1503050 | D31: Naval Observatory (USNO) (Region Funded)- Grounds Maintenance
A32: A103 AA | B32: 1503050 | C32: 3.1 | D32: USNO- Improved Grounds (Prestige)- Reserved | E32: 12 | F32: MO | G32: =H32/E32 -> 0 | H32: 0
A33: A103 AB | B33: 1503050 | C33: 3.1 | D33: USNO- Improved Grounds (Standard Lawn) | E33: 12 | F33: MO | G33: =H33/E33 -> 0 | H33: 0
A34: A103 AC | B34: 1503050 | C34: 3.1 | D34: USNO- Improved Grounds (Standard Field)- Reserved | E34: 12 | F34: MO | G34: =H34/E34 -> 0 | H34: 0
A35: A103 AD | B35: 1503050 | C35: 3.2 | D35: USNO- Operational Areas- Reserved | E35: 12 | F35: MO | G35: =H35/E35 -> 0 | H35: 0
A36: A103 AE | B36: 1503050 | C36: 3.3 | D36: USNO- Storm Drain Systems-Reserved | E36: 12 | F36: MO | G36: =H36/E36 -> 0 | H36: 0
A37: A103 AF | B37: 1503050 | C37: 3.5 | D37: USNO- Debris Removal | E37: 12 | F37: MO | G37: =H37/E37 -> 0 | H37: 0
A38: A103 AG | B38: 1503050 | C38: 3.6 | D38: USNO- Destructive Weather-Reserved | E38: 12 | F38: MO | G38: =H38/E38 -> 0 | H38: 0
A39: A103 AH | B39: 1503050 | C39: 3.7 | D39: USNO- Interior Plant Maintenance- Reserved | E39: 12 | F39: MO | G39: =H39/E39 -> 0 | H39: 0
D40: Naval Observatory (USNO) (Region Funded) (A103) Subtotal | E40: 12 | F40: MO | G40: =SUM(G32:G39) -> 0 | H40: =SUM(H32:H39) -> 0
...

Sheet Base Non-Recurring
C1: Attachment J-0200000-10
C2: Exhibit Line Item Numbers
C3: Solicitation/Contract No.: N40080-25-R-4580
C4: Regional Grounds and Pavement Clearance
A5: Line Item 0002 - Non-Recurring Work - Base Period
A6: Provide Prices for Recurring Work in accordance with Section C, Spec Item 4
A7: ELIN A900 through A1026
A10: ELIN | B10: Product Name (120 Characters) | C10: Description Extended | D10: Estimated Quantity | E10: Unit of Issue | F10: Unit Price | G10: Total Price
A11: A900 | B11: Underbrushing | C11: All brush, weeds, and small trees (3 inches and below in diameter at ground level) shall be cut back to within 1 inch of ground level. Work shall be completed within 10 calendar days. | D11: 10000 | E11: SY | F11: 0 | G11: =D11*F11 -> 0
A12: A901 | B12: Field Mowing | C12: Vegetation shall be mowed in accordance with J-1503050-04. All debris shall be removed upon completion of mowing. Work shall be completed within 20 calendar days. | D12: 500 | E12: AC | F12: 0 | G12: =D12*F12 -> 0
A13: A902 | B13: Special Event Grass Cutting | C13: Grass shall be mowed and trimmed to a uniform height. Clippings and debris shall be removed. Complete all work within 3 calendar days. | D13: 1000 | E13: AC | F13: 0 | G13: =D13*F13 -> 0
A14: A903 | B14: Special Event Edging | C14: Edging to provide a uniform edged cut. All clippings shall be removed. Complete all work within 3 calendar days. | D14: 50000 | E14: LF | F14: 0 | G14: =D14*F14 -> 0
A15: A904 | B15: Special Event Raking | C15: Rake and remove leaves, pine straw and pinecones, limbs, and other debris from the specified area. All debris shall be removed the same day as raked. Work to be completed in 5 calendar days. | D15: 200000 | E15: SY | F15: 0 | G15: =D15*F15 -> 0
A16: A905 | B16: Large Tree and Stump Removal | C16: Remove trees above 18 inches in diameter measured at 4.5 feet above ground level. Remove stumps to 12 inches below ground level and remove roots to 4 inches below level ground extending to six feet from tree. Treat to prevent regrowth. Backfill all excavated holes and replant with the same type of vegetation as surrounding area. Work shall be completed within 10 calendar days. | D16: 100 | E16: EA | F16: 0 | G16: =D16*F16 -> 0
A17: A906 | B17: Medium Tree and Stump Removal | C17: Remove trees 6 to 18 inches in diameter measured at 4.5 feet above ground level. Remove stumps to 12 inches below ground level and remove roots to 4 inches below level ground extending to six feet from tree. Treat to prevent regrowth. Backfill all excavated holes and replant with the same type of vegetation as surrounding area. Work shall be completed within 7 calendar days. | D17: 100 | E17: EA | F17: 0 | G17: =D17*F17 -> 0
A18: A907 | B18: Small Tree and Stump Removal | C18: Remove trees 6 to 18 inches in diameter measured at 4.5 feet above ground level. Remove stumps to 12 inches below ground level and remove roots to 4 inches below level ground extending to six feet from tree. Treat to prevent regrowth. Backfill all excavated holes and replant with the same type of vegetation as surrounding area. Work shall be completed within 7 calendar days. | D18: 100 | E18: EA | F18: 0 | G18: =D18*F18 -> 0
A19: A908 | B19: Large Shrub and Stump Removal | C19: Remove shrubs above 15-gallon and/or above 48 inches high. Remove stumps to 6 inches below ground level and remove all exposed roots. Treat to prevent regrowth. Backfill all excavated holes and replant with the same type of vegetation as surrounding area. | D19: 100 | E19: EA | F19: 0 | G19: =D19*F19 -> 0
A20: A909 | B20: Medium Shrub and Stump Removal | C20: Remove shrubs between 5 and 15-gallon and/or between 18 and 48 inches high. Remove stumps to 6 inches below ground level and remove all exposed roots. Treat to prevent regrowth. Backfill all excavated holes and replant with the same type of vegetation as surrounding area. Shrubs are sized based on the standard growing plant container capacity and plant height above ground level. Work shall be | D20: 200 | E20: EA | F20: 0 | G20: =D20*F20 -> 0
A21: A910 | B21: Small Shrub and Stump Removal | C21: Remove shrubs up to 5-gallon and/or up to 18 inches high. Remove stumps to 6 inches below ground level and remove all exposed roots. Treat to prevent regrowth. Backfill all excavated holes and replant with the same type of vegetation as surrounding area. Shrubs are sized based on the standard growing plant container capacity and plant height above ground level. Work shall be completed within 3 calendar days. | D21: 200 | E21: EA | F21: 0 | G21: =D21*F21 -> 0
A22: A911 | B22: Large Tree Pruning | C22: Prune trees above 15 feet high according to their natural growth characteristics leaving them well shaped and balanced, and to promote proper health and growth. Retain typical growth habit of individual plant with as much height and spread as is practical. Pruning shall be accomplished by or under the guidance of a certified Arborist. Work shall be completed within 1 calendar day. | D22: 25 | E22: EA | F22: 0 | G22: =D22*F22 -> 0
... A135: A1024 | B135: Ice / Snow De-Icing Navy Exchange (Parking Garage, Roads and Sidewalks) | C135: Deicing material(s) shall be evenly placed to the full surface area of roads, parking areas, sidewalks, and building entrances following the cessation of ice/snow precipitation or freezing event. Building entrances include walkways, steps, exterior stairways, and porches. Only Government approved deicing materials shall be used and per manufacturer recommendation. Services provided will be provided in accordance with attachment J-1503060-05(f) Performance Criteria. | D135: 12 | E135: EA | F135: 0 | G135: =D135*F135 -> 0
A136: A1025 | B136: Unit Priced Labor Work - MUST BE NEGOTIATED BY KO | C136: Provide labor to perform all Unit Priced Labor work subject to the Service Contract Act per the scope and delivery schedule specified in the order. A Fixed Burden Rate shall be established and entered in Unit Price column. The existing rate in Unit Price is soley listed for demostration purposes. Unit Price must be adjusted for bid evaluation. Quantities shall not exceed ELIN Total Cost. | D136: =G136-F136 -> 0 | E136: HR | F136: 0 | G136: 0
A137: A1026 | B137: Material Costs- MUST BE NEGOTIATED BY KO | C137: Provide all materials and equipment to perform Unit Priced Labor work per the scope and delivery schedule specified in the order. Use only with ELIN A1027 Material Unit Cost shall be established and entered in Unit Price column. The existing rate in Unit Price is soley listed for demostration purposes. Unit Price must be adjusted for bid evaluation. Quantities shall not exceed ELIN Total Cost. | D137: =G137-F137 -> 0 | E137: EA | F137: 0 | G137: 0
A138: A1027 | B138: Clean Gutters and/or roof drains - NSWC - Indian Head | C138: The Contractor shall clean out drains and gutters. Services shall be performed at NSWC - Indian Head and Stump Neck. | D138: 180000 | E138: LF | F138: 0 | G138: 0
A139: Total Indefinte Quantity Price Base Period (A900 - A1026) | G139: =SUM(G11:G138) -> 0

Sheet Option 1 Recurring 
D1: Attachment J-0200000-10
D2: Exhibit Line Item Numbers
D3: Solicitation/Contract No.: N40080-25-R-4580
D4: Regional Grounds and Pavement Clearance
A5: Line Item 0001 - Recurring Work - Base Period
A6: Provide Prices for Recurring Work in accordance with Section C, Spec Item 3
A7: ELIN/Sub-ELINs B100 through B700
A8: ELIN/ Sub-ELIN | B8: Annex/Sub-annex | C8: Spec Item | D8: Description | E8: Quantity | F8: Unit of Measure | G8: Unit Price | H8: Total Price
A9: 1503050- Grounds Maintenance
A10: B100 | D10: PWD Washingtion
A11: B101 | B11: 1503050 | D11: Washington Navy Yard (WNY)(Region Funded)- Grounds Maintennace
A12: B101 AA | B12: 1503050 | C12: 3.1 | D12: WNY- Improved Grounds (Prestige) | E12: 12 | F12: MO | G12: =H12/E12 -> 0 | H12: 0
A13: B101 AB | B13: 1503050 | C13: 3.1 | D13: WNY- Improved Grounds (Standard Lawn)- Reserved | E13: 12 | F13: MO | G13: =H13/E13 -> 0 | H13: 0
A14: B101 AC | B14: 1503050 | C14: 3.1 | D14: WNY- Improved Grounds (Standard Field)- Reserved | E14: 12 | F14: MO | G14: =H14/E14 -> 0 | H14: 0
A15: B101 AD | B15: 1503050 | C15: 3.2 | D15: WNY- Operational Areas- Reserved | E15: 12 | F15: MO | G15: =H15/E15 -> 0 | H15: 0
A16: B101 AE | B16: 1503050 | C16: 3.3 | D16: WNY- Storm Drain Systems | E16: 12 | F16: MO | G16: =H16/E16 -> 0 | H16: 0
A17: B101 AF | B17: 1503050 | C17: 3.5 | D17: WNY- Debris Removal | E17: 12 | F17: MO | G17: =H17/E17 -> 0 | H17: 0
A18: B101 AG | B18: 1503050 | C18: 3.6 | D18: WNY- Destructive Weather-Reserved | E18: 12 | F18: MO | G18: =H18/E18 -> 0 | H18: 0
A19: B101 AH | B19: 1503050 | C19: 3.7 | D19: WNY- Interior Plant Maintenance-Reserved | E19: 12 | F19: MO | G19: =H19/E19 -> 0 | H19: 0
D20: Washington Navy Yard (WNY)(Regiona Funded) (B101) Subtotal | E20: 12 | F20: MO | G20: =SUM(G12:G19) -> 0 | H20: =SUM(H12:H19) -> 0
A21: B102 | B21: 1503050 | D21: Arlington Service Center (ASC)(Region Funded)- Grounds Maintenance
A22: B102 AA | B22: 1503050 | C22: 3.1 | D22: ASC- Improved Grounds (Prestige)- Reserved | E22: 12 | F22: MO | G22: 0 | H22: 0
A23: B102 AB | B23: 1503050 | C23: 3.1 | D23: ASC- Improved Grounds (Standard Lawn) | E23: 12 | F23: MO | G23: =H23/E23 -> 0 | H23: 0
A24: B102 AC | B24: 1503050 | C24: 3.1 | D24: ASC- Improved Grounds (Standard Field) | E24: 12 | F24: MO | G24: =H24/E24 -> 0 | H24: 0
A25: B102 AD | B25: 1503050 | C25: 3.2 | D25: ASC- Operational Areas- Reserved | E25: 12 | F25: MO | G25: =H25/E25 -> 0 | H25: 0
A26: B102 AE | B26: 1503050 | C26: 3.3 | D26: ASC- Storm Drain Systems- Reserved | E26: 12 | F26: MO | G26: =H26/E26 -> 0 | H26: 0
A27: B102 AF | B27: 1503050 | C27: 3.5 | D27: ASC- Debris Removal | E27: 12 | F27: MO | G27: =H27/E27 -> 0 | H27: 0
A28: B102 AG | B28: 1503050 | C28: 3.6 | D28: ASC- Destructive Weather- Reserved | E28: 12 | F28: MO | G28: =H28/E28 -> 0 | H28: 0
A29: B102 AH | B29: 1503050 | C29: 3.7 | D29: ASC- Interior Plant Maintenance-Reserved | E29: 12 | F29: MO | G29: =H29/E29 -> 0 | H29: 0
D30: Arlington (ASC)(Region Funded) (B102) Subtotal | E30: 12 | F30: MO | G30: =SUM(G22:G29) -> 0 | H30: =SUM(H22:H29) -> 0
A31: B103 | B31: 1503050 | D31: Naval Observatory (USNO) (Region Funded)- Grounds Maintenance
A32: B103 AA | B32: 1503050 | C32: 3.1 | D32: USNO- Improved Grounds (Prestige)- Reserved | E32: 12 | F32: MO | G32: =H32/E32 -> 0 | H32: 0
A33: B103 AB | B33: 1503050 | C33: 3.1 | D33: USNO- Improved Grounds (Standard Lawn) | E33: 12 | F33: MO | G33: =H33/E33 -> 0 | H33: 0
A34: B103 AC | B34: 1503050 | C34: 3.1 | D34: USNO- Improved Grounds (Standard Field)- Reserved | E34: 12 | F34: MO | G34: =H34/E34 -> 0 | H34: 0
A35: B103 AD | B35: 1503050 | C35: 3.2 | D35: USNO- Operational Areas- Reserved | E35: 12 | F35: MO | G35: =H35/E35 -> 0 | H35: 0
A36: B103 AE | B36: 1503050 | C36: 3.3 | D36: USNO- Storm Drain Systems-Reserved | E36: 12 | F36: MO | G36: =H36/E36 -> 0 | H36: 0
A37: B103 AF | B37: 1503050 | C37: 3.5 | D37: USNO- Debris Removal | E37: 12 | F37: MO | G37: =H37/E37 -> 0 | H37: 0
A38: B103 AG | B38: 1503050 | C38: 3.6 | D38: USNO- Destructive Weather-Reserved | E38: 12 | F38: MO | G38: =H38/E38 -> 0 | H38: 0
A39: B103 AH | B39: 1503050 | C39: 3.7 | D39: USNO- Interior Plant Maintenance- Reserved | E39: 12 | F39: MO | G39: =H39/E39 -> 0 | H39: 0
D40: Naval Observatory (USNO) (Region Funded) (B103) Subtotal | E40: 12 | F40: MO | G40: =SUM(G32:G39) -> 0 | H40: =SUM(H32:H39) -> 0
...

Sheet Option1 Non-Recurring 
C1: Attachment J-0200000-10
C2: Exhibit Line Item Numbers
C3: Solicitation/Contract No.: N40080-25-R-4580
C4: Regional Grounds and Pavement Clearance
A5: Line Item 0002 - Non-Recurring Work - Option Period 1
A6: Provide Prices for Recurring Work in accordance with Section C, Spec Item 4
A7: ELIN B900 through B1026
A10: ELIN | B10: Product Name (120 Characters) | C10: Description Extended | D10: Estimated Quantity | E10: Unit of Issue | F10: Unit Price | G10: Total Price
A11: B900 | B11: Underbrushing | C11: All brush, weeds, and small trees (3 inches and below in diameter at ground level) shall be cut back to within 1 inch of ground level. Work shall be completed within 10 calendar days. | D11: 10000 | E11: SY | F11: 0 | G11: =D11*F11 -> 0
A12: B901 | B12: Field Mowing | C12: Vegetation shall be mowed in accordance with J-1503050-04. All debris shall be removed upon completion of mowing. Work shall be completed within 20 calendar days. | D12: 500 | E12: AC | F12: 0 | G12: =D12*F12 -> 0
A13: B902 | B13: Special Event Grass Cutting | C13: Grass shall be mowed and trimmed to a uniform height. Clippings and debris shall be removed. Complete all work within 3 calendar days. | D13: 1000 | E13: AC | F13: 0 | G13: =D13*F13 -> 0
A14: B903 | B14: Special Event Edging | C14: Edging to provide a uniform edged cut. All clippings shall be removed. Complete all work within 3 calendar days. | D14: 50000 | E14: LF | F14: 0 | G14: =D14*F14 -> 0
A15: B904 | B15: Special Event Raking | C15: Rake and remove leaves, pine straw and pinecones, limbs, and other debris from the specified area. All debris shall be removed the same day as raked. Work to be completed in 5 calendar days. | D15: 200000 | E15: SY | F15: 0 | G15: =D15*F15 -> 0
A16: B905 | B16: Large Tree and Stump Removal | C16: Remove trees above 18 inches in diameter measured at 4.5 feet above ground level. Remove stumps to 12 inches below ground level and remove roots to 4 inches below level ground extending to six feet from tree. Treat to prevent regrowth. Backfill all excavated holes and replant with the same type of vegetation as surrounding area. Work shall be completed within 10 calendar days. | D16: 100 | E16: EA | F16: 0 | G16: =D16*F16 -> 0
A17: B906 | B17: Medium Tree and Stump Removal | C17: Remove trees 6 to 18 inches in diameter measured at 4.5 feet above ground level. Remove stumps to 12 inches below ground level and remove roots to 4 inches below level ground extending to six feet from tree. Treat to prevent regrowth. Backfill all excavated holes and replant with the same type of vegetation as surrounding area. Work shall be completed within 7 calendar days. | D17: 100 | E17: EA | F17: 0 | G17: =D17*F17 -> 0
A18: B907 | B18: Small Tree and Stump Removal | C18: Remove trees 6 to 18 inches in diameter measured at 4.5 feet above ground level. Remove stumps to 12 inches below ground level and remove roots to 4 inches below level ground extending to six feet from tree. Treat to prevent regrowth. Backfill all excavated holes and replant with the same type of vegetation as surrounding area. Work shall be completed within 7 calendar days. | D18: 100 | E18: EA | F18: 0 | G18: =D18*F18 -> 0
A19: B908 | B19: Large Shrub and Stump Removal | C19: Remove shrubs above 15-gallon and/or above 48 inches high. Remove stumps to 6 inches below ground level and remove all exposed roots. Treat to prevent regrowth. Backfill all excavated holes and replant with the same type of vegetation as surrounding area. | D19: 100 | E19: EA | F19: 0 | G19: =D19*F19 -> 0
A20: B909 | B20: Medium Shrub and Stump Removal | C20: Remove shrubs between 5 and 15-gallon and/or between 18 and 48 inches high. Remove stumps to 6 inches below ground level and remove all exposed roots. Treat to prevent regrowth. Backfill all excavated holes and replant with the same type of vegetation as surrounding area. Shrubs are sized based on the standard growing plant container capacity and plant height above ground level. Work shall be | D20: 200 | E20: EA | F20: 0 | G20: =D20*F20 -> 0
A21: B910 | B21: Small Shrub and Stump Removal | C21: Remove shrubs up to 5-gallon and/or up to 18 inches high. Remove stumps to 6 inches below ground level and remove all exposed roots. Treat to prevent regrowth. Backfill all excavated holes and replant with the same type of vegetation as surrounding area. Shrubs are sized based on the standard growing plant container capacity and plant height above ground level. Work shall be completed within 3 calendar days. | D21: 200 | E21: EA | F21: 0 | G21: =D21*F21 -> 0
A22: B911 | B22: Large Tree Pruning | C22: Prune trees above 15 feet high according to their natural growth characteristics leaving them well shaped and balanced, and to promote proper health and growth. Retain typical growth habit of individual plant with as much height and spread as is practical. Pruning shall be accomplished by or under the guidance of a certified Arborist. Work shall be completed within 1 calendar day. | D22: 25 | E22: EA | F22: 0 | G22: =D22*F22 -> 0
... A135: B1024 | B135: Ice / Snow De-Icing Navy Exchange (Parking Garage, Roads and Sidewalks) | C135: Deicing material(s) shall be evenly placed to the full surface area of roads, parking areas, sidewalks, and building entrances following the cessation of ice/snow precipitation or freezing event. Building entrances include walkways, steps, exterior stairways, and porches. Only Government approved deicing materials shall be used and per manufacturer recommendation. Services provided will be provided in accordance with attachment J-1503060-05(f) Performance Criteria. | D135: 12 | E135: EA | F135: 0 | G135: =D135*F135 -> 0
A136: B1025 | B136: Unit Priced Labor Work - MUST BE NEGOTIATED BY KO | C136: Provide labor to perform all Unit Priced Labor work subject to the Service Contract Act per the scope and delivery schedule specified in the order. A Fixed Burden Rate shall be established and entered in Unit Price column. The existing rate in Unit Price is soley listed for demostration purposes. Unit Price must be adjusted for bid evaluation. Quantities shall not exceed ELIN Total Cost. | D136: =G136-F136 -> 0 | E136: HR | F136: 0 | G136: 0
A137: B1026 | B137: Material Costs- MUST BE NEGOTIATED BY KO | C137: Provide all materials and equipment to perform Unit Priced Labor work per the scope and delivery schedule specified in the order. Use only with ELIN A1027 Material Unit Cost shall be established and entered in Unit Price column. The existing rate in Unit Price is soley listed for demostration purposes. Unit Price must be adjusted for bid evaluation. Quantities shall not exceed ELIN Total Cost. | D137: =G137-F137 -> 0 | E137: EA | F137: 0 | G137: 0
A138: B1027 | B138: Clean Gutters and/or roof drains - NSWC - Indian Head | C138: The Contractor shall clean out drains and gutters. Services shall be performed at NSWC - Indian Head and Stump Neck. | D138: 180000 | E138: LF | F138: 0 | G138: 0
A139: Total Indefinte Quantity Price Option Period 1 (B900 - B1026) | G139: =SUM(G11:G138) -> 0

Sheet Option 2 Recurring
D1: Attachment J-0200000-10
D2: Exhibit Line Item Numbers
D3: Solicitation/Contract No.: N40080-25-R-4580
D4: Regional Grounds and Pavement Clearance
A5: Line Item 0001 - Recurring Work - Base Period
A6: Provide Prices for Recurring Work in accordance with Section C, Spec Item 3
A7: ELIN/Sub-ELINs C100 through C700
A8: ELIN/ Sub-ELIN | B8: Annex/Sub-annex | C8: Spec Item | D8: Description | E8: Quantity | F8: Unit of Measure | G8: Unit Price | H8: Total Price
A9: 1503050- Grounds Maintenance
A10: C100 | D10: PWD Washingtion
A11: C101 | B11: 1503050 | D11: Washington Navy Yard (WNY)(Region Funded)- Grounds Maintennace
A12: C101 AA | B12: 1503050 | C12: 3.1 | D12: WNY- Improved Grounds (Prestige) | E12: 12 | F12: MO | G12: =H12/E12 -> 0 | H12: 0
A13: C101 AB | B13: 1503050 | C13: 3.1 | D13: WNY- Improved Grounds (Standard Lawn)- Reserved | E13: 12 | F13: MO | G13: =H13/E13 -> 0 | H13: 0
A14: C101 AC | B14: 1503050 | C14: 3.1 | D14: WNY- Improved Grounds (Standard Field)- Reserved | E14: 12 | F14: MO | G14: =H14/E14 -> 0 | H14: 0
A15: C101 AD | B15: 1503050 | C15: 3.2 | D15: WNY- Operational Areas- Reserved | E15: 12 | F15: MO | G15: =H15/E15 -> 0 | H15: 0
A16: C101 AE | B16: 1503050 | C16: 3.3 | D16: WNY- Storm Drain Systems | E16: 12 | F16: MO | G16: =H16/E16 -> 0 | H16: 0
A17: C101 AF | B17: 1503050 | C17: 3.5 | D17: WNY- Debris Removal | E17: 12 | F17: MO | G17: =H17/E17 -> 0 | H17: 0
A18: C101 AG | B18: 1503050 | C18: 3.6 | D18: WNY- Destructive Weather-Reserved | E18: 12 | F18: MO | G18: =H18/E18 -> 0 | H18: 0
A19: C101 AH | B19: 1503050 | C19: 3.7 | D19: WNY- Interior Plant Maintenance-Reserved | E19: 12 | F19: MO | G19: =H19/E19 -> 0 | H19: 0
D20: Washington Navy Yard (WNY)(Regiona Funded) (C101) Subtotal | E20: 12 | F20: MO | G20: =SUM(G12:G19) -> 0 | H20: =SUM(H12:H19) -> 0
A21: C102 | B21: 1503050 | D21: Arlington Service Center (ASC)(Region Funded)- Grounds Maintenance
A22: C102 AA | B22: 1503050 | C22: 3.1 | D22: ASC- Improved Grounds (Prestige)- Reserved | E22: 12 | F22: MO | G22: 0 | H22: 0
A23: C102 AB | B23: 1503050 | C23: 3.1 | D23: ASC- Improved Grounds (Standard Lawn) | E23: 12 | F23: MO | G23: =H23/E23 -> 0 | H23: 0
A24: C102 AC | B24: 1503050 | C24: 3.1 | D24: ASC- Improved Grounds (Standard Field) | E24: 12 | F24: MO | G24: =H24/E24 -> 0 | H24: 0
A25: C102 AD | B25: 1503050 | C25: 3.2 | D25: ASC- Operational Areas- Reserved | E25: 12 | F25: MO | G25: =H25/E25 -> 0 | H25: 0
A26: C102 AE | B26: 1503050 | C26: 3.3 | D26: ASC- Storm Drain Systems- Reserved | E26: 12 | F26: MO | G26: =H26/E26 -> 0 | H26: 0
A27: C102 AF | B27: 1503050 | C27: 3.5 | D27: ASC- Debris Removal | E27: 12 | F27: MO | G27: =H27/E27 -> 0 | H27: 0
A28: C102 AG | B28: 1503050 | C28: 3.6 | D28: ASC- Destructive Weather- Reserved | E28: 12 | F28: MO | G28: =H28/E28 -> 0 | H28: 0
A29: C102 AH | B29: 1503050 | C29: 3.7 | D29: ASC- Interior Plant Maintenance-Reserved | E29: 12 | F29: MO | G29: =H29/E29 -> 0 | H29: 0
D30: Arlington (ASC)(Region Funded) (C102) Subtotal | E30: 12 | F30: MO | G30: =SUM(G22:G29) -> 0 | H30: =SUM(H22:H29) -> 0
A31: C103 | B31: 1503050 | D31: Naval Observatory (USNO) (Region Funded)- Grounds Maintenance
A32: C103 AA | B32: 1503050 | C32: 3.1 | D32: USNO- Improved Grounds (Prestige)- Reserved | E32: 12 | F32: MO | G32: =H32/E32 -> 0 | H32: 0
A33: C103 AB | B33: 1503050 | C33: 3.1 | D33: USNO- Improved Grounds (Standard Lawn) | E33: 12 | F33: MO | G33: =H33/E33 -> 0 | H33: 0
A34: C103 AC | B34: 1503050 | C34: 3.1 | D34: USNO- Improved Grounds (Standard Field)- Reserved | E34: 12 | F34: MO | G34: =H34/E34 -> 0 | H34: 0
A35: C103 AD | B35: 1503050 | C35: 3.2 | D35: USNO- Operational Areas- Reserved | E35: 12 | F35: MO | G35: =H35/E35 -> 0 | H35: 0
A36: C103 AE | B36: 1503050 | C36: 3.3 | D36: USNO- Storm Drain Systems-Reserved | E36: 12 | F36: MO | G36: =H36/E36 -> 0 | H36: 0
A37: C103 AF | B37: 1503050 | C37: 3.5 | D37: USNO- Debris Removal | E37: 12 | F37: MO | G37: =H37/E37 -> 0 | H37: 0
A38: C103 AG | B38: 1503050 | C38: 3.6 | D38: USNO- Destructive Weather-Reserved | E38: 12 | F38: MO | G38: =H38/E38 -> 0 | H38: 0
A39: C103 AH | B39: 1503050 | C39: 3.7 | D39: USNO- Interior Plant Maintenance- Reserved | E39: 12 | F39: MO | G39: =H39/E39 -> 0 | H39: 0
D40: Naval Observatory (USNO) (Region Funded) (C103) Subtotal | E40: 12 | F40: MO | G40: =SUM(G32:G39) -> 0 | H40: =SUM(H32:H39) -> 0
...

Sheet Option 2 Non-Recurring
C1: Attachment J-0200000-10
C2: Exhibit Line Item Numbers
C3: Solicitation/Contract No.: N40080-25-R-4580
C4: Regional Grounds and Pavement Clearance
A5: Line Item 0002 - Non-Recurring Work - Option Period 2
A6: Provide Prices for Recurring Work in accordance with Section C, Spec Item 4
A7: ELIN C900 through C1026
A10: ELIN | B10: Product Name (120 Characters) | C10: Description Extended | D10: Estimated Quantity | E10: Unit of Issue | F10: Unit Price | G10: Total Price
A11: C900 | B11: Underbrushing | C11: All brush, weeds, and small trees (3 inches and below in diameter at ground level) shall be cut back to within 1 inch of ground level. Work shall be completed within 10 calendar days. | D11: 10000 | E11: SY | F11: 0 | G11: =D11*F11 -> 0
A12: C901 | B12: Field Mowing | C12: Vegetation shall be mowed in accordance with J-1503050-04. All debris shall be removed upon completion of mowing. Work shall be completed within 20 calendar days. | D12: 500 | E12: AC | F12: 0 | G12: =D12*F12 -> 0
A13: C902 | B13: Special Event Grass Cutting | C13: Grass shall be mowed and trimmed to a uniform height. Clippings and debris shall be removed. Complete all work within 3 calendar days. | D13: 1000 | E13: AC | F13: 0 | G13: =D13*F13 -> 0
A14: C903 | B14: Special Event Edging | C14: Edging to provide a uniform edged cut. All clippings shall be removed. Complete all work within 3 calendar days. | D14: 50000 | E14: LF | F14: 0 | G14: =D14*F14 -> 0
A15: C904 | B15: Special Event Raking | C15: Rake and remove leaves, pine straw and pinecones, limbs, and other debris from the specified area. All debris shall be removed the same day as raked. Work to be completed in 5 calendar days. | D15: 200000 | E15: SY | F15: 0 | G15: =D15*F15 -> 0
A16: C905 | B16: Large Tree and Stump Removal | C16: Remove trees above 18 inches in diameter measured at 4.5 feet above ground level. Remove stumps to 12 inches below ground level and remove roots to 4 inches below level ground extending to six feet from tree. Treat to prevent regrowth. Backfill all excavated holes and replant with the same type of vegetation as surrounding area. Work shall be completed within 10 calendar days. | D16: 100 | E16: EA | F16: 0 | G16: =D16*F16 -> 0
A17: C906 | B17: Medium Tree and Stump Removal | C17: Remove trees 6 to 18 inches in diameter measured at 4.5 feet above ground level. Remove stumps to 12 inches below ground level and remove roots to 4 inches below level ground extending to six feet from tree. Treat to prevent regrowth. Backfill all excavated holes and replant with the same type of vegetation as surrounding area. Work shall be completed within 7 calendar days. | D17: 100 | E17: EA | F17: 0 | G17: =D17*F17 -> 0
A18: C907 | B18: Small Tree and Stump Removal | C18: Remove trees 6 to 18 inches in diameter measured at 4.5 feet above ground level. Remove stumps to 12 inches below ground level and remove roots to 4 inches below level ground extending to six feet from tree. Treat to prevent regrowth. Backfill all excavated holes and replant with the same type of vegetation as surrounding area. Work shall be completed within 7 calendar days. | D18: 100 | E18: EA | F18: 0 | G18: =D18*F18 -> 0
A19: C908 | B19: Large Shrub and Stump Removal | C19: Remove shrubs above 15-gallon and/or above 48 inches high. Remove stumps to 6 inches below ground level and remove all exposed roots. Treat to prevent regrowth. Backfill all excavated holes and replant with the same type of vegetation as surrounding area. | D19: 100 | E19: EA | F19: 0 | G19: =D19*F19 -> 0
A20: C909 | B20: Medium Shrub and Stump Removal | C20: Remove shrubs between 5 and 15-gallon and/or between 18 and 48 inches high. Remove stumps to 6 inches below ground level and remove all exposed roots. Treat to prevent regrowth. Backfill all excavated holes and replant with the same type of vegetation as surrounding area. Shrubs are sized based on the standard growing plant container capacity and plant height above ground level. Work shall be | D20: 200 | E20: EA | F20: 0 | G20: =D20*F20 -> 0
A21: C910 | B21: Small Shrub and Stump Removal | C21: Remove shrubs up to 5-gallon and/or up to 18 inches high. Remove stumps to 6 inches below ground level and remove all exposed roots. Treat to prevent regrowth. Backfill all excavated holes and replant with the same type of vegetation as surrounding area. Shrubs are sized based on the standard growing plant container capacity and plant height above ground level. Work shall be completed within 3 calendar days. | D21: 200 | E21: EA | F21: 0 | G21: =D21*F21 -> 0
A22: C911 | B22: Large Tree Pruning | C22: Prune trees above 15 feet high according to their natural growth characteristics leaving them well shaped and balanced, and to promote proper health and growth. Retain typical growth habit of individual plant with as much height and spread as is practical. Pruning shall be accomplished by or under the guidance of a certified Arborist. Work shall be completed within 1 calendar day. | D22: 25 | E22: EA | F22: 0 | G22: =D22*F22 -> 0
... A135: C1024 | B135: Ice / Snow De-Icing Navy Exchange (Parking Garage, Roads and Sidewalks) | C135: Deicing material(s) shall be evenly placed to the full surface area of roads, parking areas, sidewalks, and building entrances following the cessation of ice/snow precipitation or freezing event. Building entrances include walkways, steps, exterior stairways, and porches. Only Government approved deicing materials shall be used and per manufacturer recommendation. Services provided will be provided in accordance with attachment J-1503060-05(f) Performance Criteria. | D135: 12 | E135: EA | F135: 0 | G135: =D135*F135 -> 0
A136: C1025 | B136: Unit Priced Labor Work - MUST BE NEGOTIATED BY KO | C136: Provide labor to perform all Unit Priced Labor work subject to the Service Contract Act per the scope and delivery schedule specified in the order. A Fixed Burden Rate shall be established and entered in Unit Price column. The existing rate in Unit Price is soley listed for demostration purposes. Unit Price must be adjusted for bid evaluation. Quantities shall not exceed ELIN Total Cost. | D136: =G136-F136 -> 0 | E136: HR | F136: 0 | G136: 0
A137: C1026 | B137: Material Costs- MUST BE NEGOTIATED BY KO | C137: Provide all materials and equipment to perform Unit Priced Labor work per the scope and delivery schedule specified in the order. Use only with ELIN A1027 Material Unit Cost shall be established and entered in Unit Price column. The existing rate in Unit Price is soley listed for demostration purposes. Unit Price must be adjusted for bid evaluation. Quantities shall not exceed ELIN Total Cost. | D137: =G137-F137 -> 0 | E137: EA | F137: 0 | G137: 0
A138: C1027 | B138: Clean Gutters and/or roof drains - NSWC - Indian Head | C138: The Contractor shall clean out drains and gutters. Services shall be performed at NSWC - Indian Head and Stump Neck. | D138: 180000 | E138: LF | F138: 0 | G138: 0
A139: Total Indefinte Quantity Price Option Period 2 (C900 - C1026) | G139: =SUM(G11:G138) -> 0

Sheet Option 3 Recurring
D1: Attachment J-0200000-10
D2: Exhibit Line Item Numbers
D3: Solicitation/Contract No.: N40080-25-R-4580
D4: Regional Grounds and Pavement Clearance
A5: Line Item 0001 - Recurring Work - Base Period
A6: Provide Prices for Recurring Work in accordance with Section C, Spec Item 3
A7: ELIN/Sub-ELINs D100 through D700
A8: ELIN/ Sub-ELIN | B8: Annex/Sub-annex | C8: Spec Item | D8: Description | E8: Quantity | F8: Unit of Measure | G8: Unit Price | H8: Total Price
A9: 1503050- Grounds Maintenance
A10: D100 | D10: PWD Washingtion
A11: D101 | B11: 1503050 | D11: Washington Navy Yard (WNY)(Region Funded)- Grounds Maintennace
A12: D101 AA | B12: 1503050 | C12: 3.1 | D12: WNY- Improved Grounds (Prestige) | E12: 12 | F12: MO | G12: =H12/E12 -> 0 | H12: 0
A13: D101 AB | B13: 1503050 | C13: 3.1 | D13: WNY- Improved Grounds (Standard Lawn)- Reserved | E13: 12 | F13: MO | G13: =H13/E13 -> 0 | H13: 0
A14: D101 AC | B14: 1503050 | C14: 3.1 | D14: WNY- Improved Grounds (Standard Field)- Reserved | E14: 12 | F14: MO | G14: =H14/E14 -> 0 | H14: 0
A15: D101 AD | B15: 1503050 | C15: 3.2 | D15: WNY- Operational Areas- Reserved | E15: 12 | F15: MO | G15: =H15/E15 -> 0 | H15: 0
A16: D101 AE | B16: 1503050 | C16: 3.3 | D16: WNY- Storm Drain Systems | E16: 12 | F16: MO | G16: =H16/E16 -> 0 | H16: 0
A17: D101 AF | B17: 1503050 | C17: 3.5 | D17: WNY- Debris Removal | E17: 12 | F17: MO | G17: =H17/E17 -> 0 | H17: 0
A18: D101 AG | B18: 1503050 | C18: 3.6 | D18: WNY- Destructive Weather-Reserved | E18: 12 | F18: MO | G18: =H18/E18 -> 0 | H18: 0
A19: D101 AH | B19: 1503050 | C19: 3.7 | D19: WNY- Interior Plant Maintenance-Reserved | E19: 12 | F19: MO | G19: =H19/E19 -> 0 | H19: 0
D20: Washington Navy Yard (WNY)(Regiona Funded) (D101) Subtotal | E20: 12 | F20: MO | G20: =SUM(G12:G19) -> 0 | H20: =SUM(H12:H19) -> 0
A21: D102 | B21: 1503050 | D21: Arlington Service Center (ASC)(Region Funded)- Grounds Maintenance
A22: D102 AA | B22: 1503050 | C22: 3.1 | D22: ASC- Improved Grounds (Prestige)- Reserved | E22: 12 | F22: MO | G22: 0 | H22: 0
A23: D102 AB | B23: 1503050 | C23: 3.1 | D23: ASC- Improved Grounds (Standard Lawn) | E23: 12 | F23: MO | G23: =H23/E23 -> 0 | H23: 0
A24: D102 AC | B24: 1503050 | C24: 3.1 | D24: ASC- Improved Grounds (Standard Field) | E24: 12 | F24: MO | G24: =H24/E24 -> 0 | H24: 0
A25: D102 AD | B25: 1503050 | C25: 3.2 | D25: ASC- Operational Areas- Reserved | E25: 12 | F25: MO | G25: =H25/E25 -> 0 | H25: 0
A26: D102 AE | B26: 1503050 | C26: 3.3 | D26: ASC- Storm Drain Systems- Reserved | E26: 12 | F26: MO | G26: =H26/E26 -> 0 | H26: 0
A27: D102 AF | B27: 1503050 | C27: 3.5 | D27: ASC- Debris Removal | E27: 12 | F27: MO | G27: =H27/E27 -> 0 | H27: 0
A28: D102 AG | B28: 1503050 | C28: 3.6 | D28: ASC- Destructive Weather- Reserved | E28: 12 | F28: MO | G28: =H28/E28 -> 0 | H28: 0
A29: D102 AH | B29: 1503050 | C29: 3.7 | D29: ASC- Interior Plant Maintenance-Reserved | E29: 12 | F29: MO | G29: =H29/E29 -> 0 | H29: 0
D30: Arlington (ASC)(Region Funded) (D102) Subtotal | E30: 12 | F30: MO | G30: =SUM(G22:G29) -> 0 | H30: =SUM(H22:H29) -> 0
A31: D103 | B31: 1503050 | D31: Naval Observatory (USNO) (Region Funded)- Grounds Maintenance
A32: D103 AA | B32: 1503050 | C32: 3.1 | D32: USNO- Improved Grounds (Prestige)- Reserved | E32: 12 | F32: MO | G32: =H32/E32 -> 0 | H32: 0
A33: D103 AB | B33: 1503050 | C33: 3.1 | D33: USNO- Improved Grounds (Standard Lawn) | E33: 12 | F33: MO | G33: =H33/E33 -> 0 | H33: 0
A34: D103 AC | B34: 1503050 | C34: 3.1 | D34: USNO- Improved Grounds (Standard Field)- Reserved | E34: 12 | F34: MO | G34: =H34/E34 -> 0 | H34: 0
A35: D103 AD | B35: 1503050 | C35: 3.2 | D35: USNO- Operational Areas- Reserved | E35: 12 | F35: MO | G35: =H35/E35 -> 0 | H35: 0
A36: D103 AE | B36: 1503050 | C36: 3.3 | D36: USNO- Storm Drain Systems-Reserved | E36: 12 | F36: MO | G36: =H36/E36 -> 0 | H36: 0
A37: D103 AF | B37: 1503050 | C37: 3.5 | D37: USNO- Debris Removal | E37: 12 | F37: MO | G37: =H37/E37 -> 0 | H37: 0
A38: D103 AG | B38: 1503050 | C38: 3.6 | D38: USNO- Destructive Weather-Reserved | E38: 12 | F38: MO | G38: =H38/E38 -> 0 | H38: 0
A39: D103 AH | B39: 1503050 | C39: 3.7 | D39: USNO- Interior Plant Maintenance- Reserved | E39: 12 | F39: MO | G39: =H39/E39 -> 0 | H39: 0
D40: Naval Observatory (USNO) (Region Funded) (D103) Subtotal | E40: 12 | F40: MO | G40: =SUM(G32:G39) -> 0 | H40: =SUM(H32:H39) -> 0
...

Sheet Option 3 Non-Recurring
C1: Attachment J-0200000-10
C2: Exhibit Line Item Numbers
C3: Solicitation/Contract No.: N40080-25-R-4580
C4: Regional Grounds and Pavement Clearance
A5: Line Item 0002 - Non-Recurring Work - Option Period 3
A6: Provide Prices for Recurring Work in accordance with Section C, Spec Item 4
A7: ELIN D900 through D1026
A10: ELIN | B10: Product Name (120 Characters) | C10: Description Extended | D10: Estimated Quantity | E10: Unit of Issue | F10: Unit Price | G10: Total Price
A11: D900 | B11: Underbrushing | C11: All brush, weeds, and small trees (3 inches and below in diameter at ground level) shall be cut back to within 1 inch of ground level. Work shall be completed within 10 calendar days. | D11: 10000 | E11: SY | F11: 0 | G11: =D11*F11 -> 0
A12: D901 | B12: Field Mowing | C12: Vegetation shall be mowed in accordance with J-1503050-04. All debris shall be removed upon completion of mowing. Work shall be completed within 20 calendar days. | D12: 500 | E12: AC | F12: 0 | G12: =D12*F12 -> 0
A13: D902 | B13: Special Event Grass Cutting | C13: Grass shall be mowed and trimmed to a uniform height. Clippings and debris shall be removed. Complete all work within 3 calendar days. | D13: 1000 | E13: AC | F13: 0 | G13: =D13*F13 -> 0
A14: D903 | B14: Special Event Edging | C14: Edging to provide a uniform edged cut. All clippings shall be removed. Complete all work within 3 calendar days. | D14: 50000 | E14: LF | F14: 0 | G14: =D14*F14 -> 0
A15: D904 | B15: Special Event Raking | C15: Rake and remove leaves, pine straw and pinecones, limbs, and other debris from the specified area. All debris shall be removed the same day as raked. Work to be completed in 5 calendar days. | D15: 200000 | E15: SY | F15: 0 | G15: =D15*F15 -> 0
A16: D905 | B16: Large Tree and Stump Removal | C16: Remove trees above 18 inches in diameter measured at 4.5 feet above ground level. Remove stumps to 12 inches below ground level and remove roots to 4 inches below level ground extending to six feet from tree. Treat to prevent regrowth. Backfill all excavated holes and replant with the same type of vegetation as surrounding area. Work shall be completed within 10 calendar days. | D16: 100 | E16: EA | F16: 0 | G16: =D16*F16 -> 0
A17: D906 | B17: Medium Tree and Stump Removal | C17: Remove trees 6 to 18 inches in diameter measured at 4.5 feet above ground level. Remove stumps to 12 inches below ground level and remove roots to 4 inches below level ground extending to six feet from tree. Treat to prevent regrowth. Backfill all excavated holes and replant with the same type of vegetation as surrounding area. Work shall be completed within 7 calendar days. | D17: 100 | E17: EA | F17: 0 | G17: =D17*F17 -> 0
A18: D907 | B18: Small Tree and Stump Removal | C18: Remove trees 6 to 18 inches in diameter measured at 4.5 feet above ground level. Remove stumps to 12 inches below ground level and remove roots to 4 inches below level ground extending to six feet from tree. Treat to prevent regrowth. Backfill all excavated holes and replant with the same type of vegetation as surrounding area. Work shall be completed within 7 calendar days. | D18: 100 | E18: EA | F18: 0 | G18: =D18*F18 -> 0
A19: D908 | B19: Large Shrub and Stump Removal | C19: Remove shrubs above 15-gallon and/or above 48 inches high. Remove stumps to 6 inches below ground level and remove all exposed roots. Treat to prevent regrowth. Backfill all excavated holes and replant with the same type of vegetation as surrounding area. | D19: 100 | E19: EA | F19: 0 | G19: =D19*F19 -> 0
A20: D909 | B20: Medium Shrub and Stump Removal | C20: Remove shrubs between 5 and 15-gallon and/or between 18 and 48 inches high. Remove stumps to 6 inches below ground level and remove all exposed roots. Treat to prevent regrowth. Backfill all excavated holes and replant with the same type of vegetation as surrounding area. Shrubs are sized based on the standard growing plant container capacity and plant height above ground level. Work shall be | D20: 200 | E20: EA | F20: 0 | G20: =D20*F20 -> 0
A21: D910 | B21: Small Shrub and Stump Removal | C21: Remove shrubs up to 5-gallon and/or up to 18 inches high. Remove stumps to 6 inches below ground level and remove all exposed roots. Treat to prevent regrowth. Backfill all excavated holes and replant with the same type of vegetation as surrounding area. Shrubs are sized based on the standard growing plant container capacity and plant height above ground level. Work shall be completed within 3 calendar days. | D21: 200 | E21: EA | F21: 0 | G21: =D21*F21 -> 0
A22: D911 | B22: Large Tree Pruning | C22: Prune trees above 15 feet high according to their natural growth characteristics leaving them well shaped and balanced, and to promote proper health and growth. Retain typical growth habit of individual plant with as much height and spread as is practical. Pruning shall be accomplished by or under the guidance of a certified Arborist. Work shall be completed within 1 calendar day. | D22: 25 | E22: EA | F22: 0 | G22: =D22*F22 -> 0
... A135: D1024 | B135: Ice / Snow De-Icing Navy Exchange (Parking Garage, Roads and Sidewalks) | C135: Deicing material(s) shall be evenly placed to the full surface area of roads, parking areas, sidewalks, and building entrances following the cessation of ice/snow precipitation or freezing event. Building entrances include walkways, steps, exterior stairways, and porches. Only Government approved deicing materials shall be used and per manufacturer recommendation. Services provided will be provided in accordance with attachment J-1503060-05(f) Performance Criteria. | D135: 12 | E135: EA | F135: 0 | G135: =D135*F135 -> 0
A136: D1025 | B136: Unit Priced Labor Work - MUST BE NEGOTIATED BY KO | C136: Provide labor to perform all Unit Priced Labor work subject to the Service Contract Act per the scope and delivery schedule specified in the order. A Fixed Burden Rate shall be established and entered in Unit Price column. The existing rate in Unit Price is soley listed for demostration purposes. Unit Price must be adjusted for bid evaluation. Quantities shall not exceed ELIN Total Cost. | D136: =G136-F136 -> 0 | E136: HR | F136: 0 | G136: 0
A137: D1026 | B137: Material Costs- MUST BE NEGOTIATED BY KO | C137: Provide all materials and equipment to perform Unit Priced Labor work per the scope and delivery schedule specified in the order. Use only with ELIN A1027 Material Unit Cost shall be established and entered in Unit Price column. The existing rate in Unit Price is soley listed for demostration purposes. Unit Price must be adjusted for bid evaluation. Quantities shall not exceed ELIN Total Cost. | D137: =G137-F137 -> 0 | E137: EA | F137: 0 | G137: 0
A138: D1027 | B138: Clean Gutters and/or roof drains - NSWC - Indian Head | C138: The Contractor shall clean out drains and gutters. Services shall be performed at NSWC - Indian Head and Stump Neck. | D138: 180000 | E138: LF | F138: 0 | G138: 0
A139: Total Indefinte Quantity Price Option Period 3 (D900 - D1026) | G139: =SUM(G11:G138) -> 0

Sheet Option 4 Recurring
D1: Attachment J-0200000-10
D2: Exhibit Line Item Numbers
D3: Solicitation/Contract No.: N40080-25-R-4580
D4: Regional Grounds and Pavement Clearance
A5: Line Item 0001 - Recurring Work - Base Period
A6: Provide Prices for Recurring Work in accordance with Section C, Spec Item 3
A7: ELIN/Sub-ELINs E100 through E700
A8: ELIN/ Sub-ELIN | B8: Annex/Sub-annex | C8: Spec Item | D8: Description | E8: Quantity | F8: Unit of Measure | G8: Unit Price | H8: Total Price
A9: 1503050- Grounds Maintenance
A10: E100 | D10: PWD Washingtion
A11: E101 | B11: 1503050 | D11: Washington Navy Yard (WNY)(Region Funded)- Grounds Maintennace
A12: E101 AA | B12: 1503050 | C12: 3.1 | D12: WNY- Improved Grounds (Prestige) | E12: 12 | F12: MO | G12: =H12/E12 -> 0 | H12: 0
A13: E101 AB | B13: 1503050 | C13: 3.1 | D13: WNY- Improved Grounds (Standard Lawn)- Reserved | E13: 12 | F13: MO | G13: =H13/E13 -> 0 | H13: 0
A14: E101 AC | B14: 1503050 | C14: 3.1 | D14: WNY- Improved Grounds (Standard Field)- Reserved | E14: 12 | F14: MO | G14: =H14/E14 -> 0 | H14: 0
A15: E101 AD | B15: 1503050 | C15: 3.2 | D15: WNY- Operational Areas- Reserved | E15: 12 | F15: MO | G15: =H15/E15 -> 0 | H15: 0
A16: E101 AE | B16: 1503050 | C16: 3.3 | D16: WNY- Storm Drain Systems | E16: 12 | F16: MO | G16: =H16/E16 -> 0 | H16: 0
A17: E101 AF | B17: 1503050 | C17: 3.5 | D17: WNY- Debris Removal | E17: 12 | F17: MO | G17: =H17/E17 -> 0 | H17: 0
A18: E101 AG | B18: 1503050 | C18: 3.6 | D18: WNY- Destructive Weather-Reserved | E18: 12 | F18: MO | G18: =H18/E18 -> 0 | H18: 0
A19: E101 AH | B19: 1503050 | C19: 3.7 | D19: WNY- Interior Plant Maintenance-Reserved | E19: 12 | F19: MO | G19: =H19/E19 -> 0 | H19: 0
D20: Washington Navy Yard (WNY)(Regiona Funded) (E101) Subtotal | E20: 12 | F20: MO | G20: =SUM(G12:G19) -> 0 | H20: =SUM(H12:H19) -> 0
A21: E102 | B21: 1503050 | D21: Arlington Service Center (ASC)(Region Funded)- Grounds Maintenance
A22: E102 AA | B22: 1503050 | C22: 3.1 | D22: ASC- Improved Grounds (Prestige)- Reserved | E22: 12 | F22: MO | G22: 0 | H22: 0
A23: E102 AB | B23: 1503050 | C23: 3.1 | D23: ASC- Improved Grounds (Standard Lawn) | E23: 12 | F23: MO | G23: =H23/E23 -> 0 | H23: 0
A24: E102 AC | B24: 1503050 | C24: 3.1 | D24: ASC- Improved Grounds (Standard Field) | E24: 12 | F24: MO | G24: =H24/E24 -> 0 | H24: 0
A25: E102 AD | B25: 1503050 | C25: 3.2 | D25: ASC- Operational Areas- Reserved | E25: 12 | F25: MO | G25: =H25/E25 -> 0 | H25: 0
A26: E102 AE | B26: 1503050 | C26: 3.3 | D26: ASC- Storm Drain Systems- Reserved | E26: 12 | F26: MO | G26: =H26/E26 -> 0 | H26: 0
A27: E102 AF | B27: 1503050 | C27: 3.5 | D27: ASC- Debris Removal | E27: 12 | F27: MO | G27: =H27/E27 -> 0 | H27: 0
A28: E102 AG | B28: 1503050 | C28: 3.6 | D28: ASC- Destructive Weather- Reserved | E28: 12 | F28: MO | G28: =H28/E28 -> 0 | H28: 0
A29: E102 AH | B29: 1503050 | C29: 3.7 | D29: ASC- Interior Plant Maintenance-Reserved | E29: 12 | F29: MO | G29: =H29/E29 -> 0 | H29: 0
D30: Arlington (ASC)(Region Funded) (E102) Subtotal | E30: 12 | F30: MO | G30: =SUM(G22:G29) -> 0 | H30: =SUM(H22:H29) -> 0
A31: E103 | B31: 1503050 | D31: Naval Observatory (USNO) (Region Funded)- Grounds Maintenance
A32: E103 AA | B32: 1503050 | C32: 3.1 | D32: USNO- Improved Grounds (Prestige)- Reserved | E32: 12 | F32: MO | G32: =H32/E32 -> 0 | H32: 0
A33: E103 AB | B33: 1503050 | C33: 3.1 | D33: USNO- Improved Grounds (Standard Lawn) | E33: 12 | F33: MO | G33: =H33/E33 -> 0 | H33: 0
A34: E103 AC | B34: 1503050 | C34: 3.1 | D34: USNO- Improved Grounds (Standard Field)- Reserved | E34: 12 | F34: MO | G34: =H34/E34 -> 0 | H34: 0
A35: E103 AD | B35: 1503050 | C35: 3.2 | D35: USNO- Operational Areas- Reserved | E35: 12 | F35: MO | G35: =H35/E35 -> 0 | H35: 0
A36: E103 AE | B36: 1503050 | C36: 3.3 | D36: USNO- Storm Drain Systems-Reserved | E36: 12 | F36: MO | G36: =H36/E36 -> 0 | H36: 0
A37: E103 AF | B37: 1503050 | C37: 3.5 | D37: USNO- Debris Removal | E37: 12 | F37: MO | G37: =H37/E37 -> 0 | H37: 0
A38: E103 AG | B38: 1503050 | C38: 3.6 | D38: USNO- Destructive Weather-Reserved | E38: 12 | F38: MO | G38: =H38/E38 -> 0 | H38: 0
A39: E103 AH | B39: 1503050 | C39: 3.7 | D39: USNO- Interior Plant Maintenance- Reserved | E39: 12 | F39: MO | G39: =H39/E39 -> 0 | H39: 0
D40: Naval Observatory (USNO) (Region Funded) (E103) Subtotal | E40: 12 | F40: MO | G40: =SUM(G32:G39) -> 0 | H40: =SUM(H32:H39) -> 0
...

Sheet Option 4 Non-Recurring
C1: Attachment J-0200000-10
C2: Exhibit Line Item Numbers
C3: Solicitation/Contract No.: N40080-25-R-4580
C4: Regional Grounds and Pavement Clearance
A5: Line Item 0002 - Non-Recurring Work - Option Period 4
A6: Provide Prices for Recurring Work in accordance with Section C, Spec Item 4
A7: ELIN E900 through E1026
A10: ELIN | B10: Product Name (120 Characters) | C10: Description Extended | D10: Estimated Quantity | E10: Unit of Issue | F10: Unit Price | G10: Total Price
A11: E900 | B11: Underbrushing | C11: All brush, weeds, and small trees (3 inches and below in diameter at ground level) shall be cut back to within 1 inch of ground level. Work shall be completed within 10 calendar days. | D11: 10000 | E11: SY | F11: 0 | G11: =D11*F11 -> 0
A12: E901 | B12: Field Mowing | C12: Vegetation shall be mowed in accordance with J-1503050-04. All debris shall be removed upon completion of mowing. Work shall be completed within 20 calendar days. | D12: 500 | E12: AC | F12: 0 | G12: =D12*F12 -> 0
A13: E902 | B13: Special Event Grass Cutting | C13: Grass shall be mowed and trimmed to a uniform height. Clippings and debris shall be removed. Complete all work within 3 calendar days. | D13: 1000 | E13: AC | F13: 0 | G13: =D13*F13 -> 0
A14: E903 | B14: Special Event Edging | C14: Edging to provide a uniform edged cut. All clippings shall be removed. Complete all work within 3 calendar days. | D14: 50000 | E14: LF | F14: 0 | G14: =D14*F14 -> 0
A15: E904 | B15: Special Event Raking | C15: Rake and remove leaves, pine straw and pinecones, limbs, and other debris from the specified area. All debris shall be removed the same day as raked. Work to be completed in 5 calendar days. | D15: 200000 | E15: SY | F15: 0 | G15: =D15*F15 -> 0
A16: E905 | B16: Large Tree and Stump Removal | C16: Remove trees above 18 inches in diameter measured at 4.5 feet above ground level. Remove stumps to 12 inches below ground level and remove roots to 4 inches below level ground extending to six feet from tree. Treat to prevent regrowth. Backfill all excavated holes and replant with the same type of vegetation as surrounding area. Work shall be completed within 10 calendar days. | D16: 100 | E16: EA | F16: 0 | G16: =D16*F16 -> 0
A17: E906 | B17: Medium Tree and Stump Removal | C17: Remove trees 6 to 18 inches in diameter measured at 4.5 feet above ground level. Remove stumps to 12 inches below ground level and remove roots to 4 inches below level ground extending to six feet from tree. Treat to prevent regrowth. Backfill all excavated holes and replant with the same type of vegetation as surrounding area. Work shall be completed within 7 calendar days. | D17: 100 | E17: EA | F17: 0 | G17: =D17*F17 -> 0
A18: E907 | B18: Small Tree and Stump Removal | C18: Remove trees 6 to 18 inches in diameter measured at 4.5 feet above ground level. Remove stumps to 12 inches below ground level and remove roots to 4 inches below level ground extending to six feet from tree. Treat to prevent regrowth. Backfill all excavated holes and replant with the same type of vegetation as surrounding area. Work shall be completed within 7 calendar days. | D18: 100 | E18: EA | F18: 0 | G18: =D18*F18 -> 0
A19: E908 | B19: Large Shrub and Stump Removal | C19: Remove shrubs above 15-gallon and/or above 48 inches high. Remove stumps to 6 inches below ground level and remove all exposed roots. Treat to prevent regrowth. Backfill all excavated holes and replant with the same type of vegetation as surrounding area. | D19: 100 | E19: EA | F19: 0 | G19: =D19*F19 -> 0
A20: E909 | B20: Medium Shrub and Stump Removal | C20: Remove shrubs between 5 and 15-gallon and/or between 18 and 48 inches high. Remove stumps to 6 inches below ground level and remove all exposed roots. Treat to prevent regrowth. Backfill all excavated holes and replant with the same type of vegetation as surrounding area. Shrubs are sized based on the standard growing plant container capacity and plant height above ground level. Work shall be | D20: 200 | E20: EA | F20: 0 | G20: =D20*F20 -> 0
A21: E910 | B21: Small Shrub and Stump Removal | C21: Remove shrubs up to 5-gallon and/or up to 18 inches high. Remove stumps to 6 inches below ground level and remove all exposed roots. Treat to prevent regrowth. Backfill all excavated holes and replant with the same type of vegetation as surrounding area. Shrubs are sized based on the standard growing plant container capacity and plant height above ground level. Work shall be completed within 3 calendar days. | D21: 200 | E21: EA | F21: 0 | G21: =D21*F21 -> 0
A22: E911 | B22: Large Tree Pruning | C22: Prune trees above 15 feet high according to their natural growth characteristics leaving them well shaped and balanced, and to promote proper health and growth. Retain typical growth habit of individual plant with as much height and spread as is practical. Pruning shall be accomplished by or under the guidance of a certified Arborist. Work shall be completed within 1 calendar day. | D22: 25 | E22: EA | F22: 0 | G22: =D22*F22 -> 0
... A135: E1024 | B135: Ice / Snow De-Icing Navy Exchange (Parking Garage, Roads and Sidewalks) | C135: Deicing material(s) shall be evenly placed to the full surface area of roads, parking areas, sidewalks, and building entrances following the cessation of ice/snow precipitation or freezing event. Building entrances include walkways, steps, exterior stairways, and porches. Only Government approved deicing materials shall be used and per manufacturer recommendation. Services provided will be provided in accordance with attachment J-1503060-05(f) Performance Criteria. | D135: 12 | E135: EA | F135: 0 | G135: =D135*F135 -> 0
A136: E1025 | B136: Unit Priced Labor Work - MUST BE NEGOTIATED BY KO | C136: Provide labor to perform all Unit Priced Labor work subject to the Service Contract Act per the scope and delivery schedule specified in the order. A Fixed Burden Rate shall be established and entered in Unit Price column. The existing rate in Unit Price is soley listed for demostration purposes. Unit Price must be adjusted for bid evaluation. Quantities shall not exceed ELIN Total Cost. | D136: =G136-F136 -> 0 | E136: HR | F136: 0 | G136: 0
A137: E1026 | B137: Material Costs- MUST BE NEGOTIATED BY KO | C137: Provide all materials and equipment to perform Unit Priced Labor work per the scope and delivery schedule specified in the order. Use only with ELIN A1027 Material Unit Cost shall be established and entered in Unit Price column. The existing rate in Unit Price is soley listed for demostration purposes. Unit Price must be adjusted for bid evaluation. Quantities shall not exceed ELIN Total Cost. | D137: =G137-F137 -> 0 | E137: EA | F137: 0 | G137: 0
A138: E1027 | B138: Clean Gutters and/or roof drains - NSWC - Indian Head | C138: The Contractor shall clean out drains and gutters. Services shall be performed at NSWC - Indian Head and Stump Neck. | D138: 180000 | E138: LF | F138: 0 | G138: 0
A139: Total Indefinte Quantity Price Option Period 4 (E900 - E1026) | G139: =SUM(G11:G138) -> 0

Sheet  6 Month Option Recurring 
D1: Attachment J-0200000-10
D2: Exhibit Line Item Numbers
D3: Solicitation/Contract No.: N40080-25-R-4580
D4: Regional Grounds and Pavement Clearance
A5: Line Item 0001 - Recurring Work - Base Period
A6: Provide Prices for Recurring Work in accordance with Section C, Spec Item 3
A7: ELIN/Sub-ELINs F100 through F700
A8: ELIN/ Sub-ELIN | B8: Annex/Sub-annex | C8: Spec Item | D8: Description | E8: Quantity | F8: Unit of Measure | G8: Unit Price | H8: Total Price
A9: 1503050- Grounds Maintenance
A10: F100 | D10: PWD Washingtion
A11: F101 | B11: 1503050 | D11: Washington Navy Yard (WNY)(Region Funded)- Grounds Maintennace
A12: F101 AA | B12: 1503050 | C12: 3.1 | D12: WNY- Improved Grounds (Prestige) | E12: 6 | F12: MO | G12: =H12/E12 -> 0 | H12: 0
A13: F101 AB | B13: 1503050 | C13: 3.1 | D13: WNY- Improved Grounds (Standard Lawn)- Reserved | E13: 6 | F13: MO | G13: =H13/E13 -> 0 | H13: 0
