Workbook

Sheet Overview - Pricing
A2: DOI Org | B2: Total Annual Price Information
A3: BIA | B3: =BIA!J59 -> 0
A4: BIE | B4: =BIE!J34 -> 0
A5: BLM | B5: =BLM!J62 -> 0
A6: BOR | B6: =BOR!J367 -> 0
A7: BSEE | B7: =BSEE!J29 -> 0
A8: FWS | B8: =FWS!J37 -> 0
A9: OIG | B9: =OIG!J42 -> 0
A10: USGS | B10: =USGS!J36 -> 0
A11: NPS | B11: =NPS!J69 -> 0
A12: DOI IBC | B12: ='DOI IBC'!J58 -> 0
A13: Consolidated DOI Contact Center | B13: ='DOI OCIO'!J10 -> 0
A14: TOTAL | B14: =SUM(B3:B13) -> 0

Sheet Pivot - Quantities per Org
A1: Row Labels | B1: Sum of Quantity Desired
A2: E3-CX-ST-T1NBD | B2: 15529
A3: Cisco Support Enhanced 8x5xNBD for Switching | B3: 15529
A4: BIA | B4: 222
A5: BIE | B5: 1019
A6: BLM | B6: 934
A7: BSEE | B7: 2489
A8: FWS | B8: 1011
A9: NPS | B9: 8105
A10: OIG | B10: 221
A11: USGS | B11: 1528
A12: E3S-ISE-PRM | B12: 10390
A13: ISE Premier | B13: 10390
... A1022: NPS | B1022: 0
A1023: (blank)
A1024: (blank)
A1025: IBC
A1026: (blank)
A1027: E3-CX-ADD-T2SWE | B1027: 0
A1028: SVCS Portfolio T2 Secure AddOns SWSSENHCD SW Support - OP | B1028: 0
A1029: OIG | B1029: 0
A1030: E3-CX-ISE-T3SWP | B1030: 0
A1031: SVCS Portfolio T3 ISE SWSS Premium SW Support – OnPrem | B1031: 0
A1032: BIA | B1032: 0
A1033: Grand Total | B1033: 75368

Sheet Consolidated Data
A1: Solution Area | B1: Type | C1: Suite | D1: Part Number | E1: Description | F1: Quantity Desired | G1: License Tiers | H1: Service Tier | I1: Bureau | J1: Unit Price | K1: Total Price
A2: Cisco Networking | B2: Software | C2: Meraki FedRamp Moderate - Network Infrastructure | D2: E3N-FED-MR-E | E2: Meraki FedRamp MR Essentials Subscription EA 3 LIC | F2: 100 | G2: NA | I2: BIA | J2: =BIA!I2 -> 0 | K2: =BIA!J2 -> 0
A3: Cisco Networking | B3: Software | C3: Cisco Networking FedRamp Moderate - Switching | D3: E3N-FED-CS-AC1-L-E | E3: Cisco Switching FedRamp EA 3.0 LIC Access Tier 1 Large | F3: 1 | G3: Essential | I3: BIA | J3: =BIA!I3 -> 0 | K3: =BIA!J3 -> 0
A4: Cisco Networking | B4: Software | C4: Cisco Networking FedRamp Moderate - Switching | D4: E3N-FED-CS-AC1-M-E | E4: Cisco Switching FedRamp EA 3.0 LIC Access Tier 1 Medium | F4: 1 | G4: Essential | I4: BIA | J4: =BIA!I4 -> 0 | K4: =BIA!J4 -> 0
A5: Cisco Networking | B5: Software | C5: Cisco Networking FedRamp Moderate - Switching | D5: E3N-FED-CS-CO-MO-A | E5: Cisco Switching Advantage FedRamp EA 3.0 LIC Core Modular | F5: 1 | G5: Advantage | I5: BIA | J5: =BIA!I5 -> 0 | K5: =BIA!J5 -> 0
A6: Cisco Networking | B6: Software | C6: Cisco Networking FedRamp Moderate - Switching | D6: SVS-E3S-CS-GMEAEMB | E6: Cisco Support Standard for Cisco Network Subscription | F6: 1 | G6: NA | I6: BIA | J6: =BIA!I6 -> 0 | K6: =BIA!J6 -> 0
A7: Cisco Networking | B7: Software | C7: Cisco Networking FedRamp Moderate - Wireless | D7: SVS-E3S-CW-GMEAEMB | E7: Cisco Support Standard for Cisco Network Subscription | F7: 1 | G7: NA | I7: BIA | J7: =BIA!I7 -> 0 | K7: =BIA!J7 -> 0
A8: Cisco Networking | B8: Software | C8: Cisco Networking FedRamp Moderate - Wireless | D8: E3N-FED-CW-E | E8: Cisco Wireless FedRamp EA 3.0 LIC | F8: 1 | G8: Essential | I8: BIA | J8: =BIA!I8 -> 0 | K8: =BIA!J8 -> 0
A9: Cloud Networking | B9: Software | C9: Nexus Switching | D9: E3N-DCN-S | E9: Support for Cisco Data Center EA for Data Center Networking | F9: 1 | G9: NA | I9: BIA | J9: =BIA!I9 -> 0 | K9: =BIA!J9 -> 0
A10: Cloud Networking | B10: Software | C10: Nexus Switching | D10: E3N-N9300-XF-E | E10: Nexus 9300 XF 10G or higher (up to 3.6T) | F10: 19 | G10: Essential | I10: BIA | J10: =BIA!I10 -> 0 | K10: =BIA!J10 -> 0
A11: Cloud Networking | B11: Software | C11: Nexus Switching | D11: E3N-N9500-M816-E | E11: Nexus 9500 8 or 16 Slot | F11: 1 | G11: Essential | I11: BIA | J11: =BIA!I11 -> 0 | K11: =BIA!J11 -> 0
A12: Cisco DNA Software | B12: Software | C12: Cisco DNA Switching | D12: E3N-C9300X2-E | E12: C9300X 24-Port DNA EA | F12: 7 | G12: Essential | I12: BIA | J12: =BIA!I12 -> 0 | K12: =BIA!J12 -> 0
A13: Cisco DNA Software | B13: Software | C13: Cisco DNA Switching | D13: E3N-C93001-E | E13: C9300 24-Port DNA EA | F13: 24 | G13: Essential | I13: BIA | J13: =BIA!I13 -> 0 | K13: =BIA!J13 -> 0
... A23: Cisco DNA Software | B23: Software | C23: Cisco DNA Wireless | D23: E3N-AIR-S | E23: Cisco Support Standard for EA DNA Wireless | F23: 1 | G23: NA | I23: BIA | J23: =BIA!I23 -> 0 | K23: =BIA!J23 -> 0
A24: Zero Trust | B24: Software | C24: Duo | D24: SVS-E3-DUOF-B | E24: Cisco Support Standard for Duo Fed | F24: 1 | I24: BIA | J24: =BIA!I24 -> 0 | K24: =BIA!J24 -> 0
A25: Zero Trust | B25: Software | C25: Duo | D25: E3S-DUO-F-ES | E25: Security EA3.0 - Duo Fed Essentials | F25: 100 | I25: BIA | J25: =BIA!I25 -> 0 | K25: =BIA!J25 -> 0
A26: Zero Trust | B26: Software | C26: Identity Services Engine (ISE) | D26: E3S-ISE-PRM | E26: ISE Premier | F26: 100 | I26: BIA | J26: =BIA!I26 -> 0 | K26: =BIA!J26 -> 0
A27: Zero Trust | B27: Software | C27: Identity Services Engine (ISE) | D27: SVS-E3S-ISE-B | E27: Cisco Support Standard for ISE | F27: 1 | I27: BIA | J27: =BIA!I27 -> 0 | K27: =BIA!J27 -> 0
A28: Zero Trust | B28: Software | C28: Identity Services Engine (ISE) | D28: E3S-ISE-ESS | E28: ISE Essentials | F28: 100 | I28: BIA | J28: =BIA!I28 -> 0 | K28: =BIA!J28 -> 0
A29: Cloud and Network Security | B29: Software | C29: Secure Firewall | D29: SVS-E3S-SFW-B | E29: Cisco Support Standard for Cisco Secure Firewall | F29: 1 | I29: BIA | J29: =BIA!I29 -> 0 | K29: =BIA!J29 -> 0
A30: Cloud and Network Security | B30: Software | C30: Secure Firewall | D30: E3S-SFW-FPR2110T | E30: FPR2110T Threat Defense Threat, Malware,URL | F30: 15 | I30: BIA | J30: =BIA!I30 -> 0 | K30: =BIA!J30 -> 0
A31: Cloud and Network Security | B31: Software | C31: Secure Firewall | D31: E3S-SFW-FPR4125T | E31: FPR4125 Threat Defense Threat, Malware,URL | F31: 2 | I31: BIA | J31: =BIA!I31 -> 0 | K31: =BIA!J31 -> 0
A32: Networking Support & Lifecycle Services | B32: Services | C32: Services: Cisco DNA SD-WAN & Routing | D32: E3-CX-ENWAN-L1PERP | E32: Cisco Support Enhanced Perpetual for ENTWAN | F32: 110 | H32: Support Enhanced | I32: BIA | J32: =BIA!I32 -> 0 | K32: =BIA!J32 -> 0
A33: Networking Support & Lifecycle Services | B33: Services | C33: Services: Cisco DNA SD-WAN & Routing | D33: E3-CX-ENTWAN-T1NBD | E33: Cisco Support Enhanced 8x5xNBD for ENTWAN | F33: 242 | H33: Support Enhanced | I33: BIA | J33: =BIA!I33 -> 0 | K33: =BIA!J33 -> 0
A34: Networking Support & Lifecycle Services | B34: Services | C34: Services: Nexus Switching | D34: E3-CX-DCN-L1SWPERP | E34: Cisco Support Enhanced Perpetual for Nexus Switching | F34: 14 | H34: - | I34: BIA | J34: =BIA!I34 -> 0 | K34: =BIA!J34 -> 0
A35: Networking Support & Lifecycle Services | B35: Services | C35: Services: Nexus Switching | D35: E3-CX-DCN-T1NBD | E35: Cisco Support Enhanced 8x5xNBD for Nexus Switching | F35: 669 | H35: - | I35: BIA | J35: =BIA!I35 -> 0 | K35: =BIA!J35 -> 0
A36: Networking Support & Lifecycle Services | B36: Services | C36: Services: SAN Switching | D36: E3-CX-MDS-T1NBD | E36: Cisco Support Enhanced 8x5xNBD for SAN Switching | F36: 57 | H36: - | I36: BIA | J36: =BIA!I36 -> 0 | K36: =BIA!J36 -> 0
A37: Networking Support & Lifecycle Services | B37: Services | C37: Services: Cisco DNA Wireless | D37: E3-CX-AIR-T1NBD | E37: Cisco Support Enhanced 8x5xNBD for Wireless | F37: 1 | H37: Support Enhanced | I37: BIA | J37: =BIA!I37 -> 0 | K37: =BIA!J37 -> 0
A38: Networking Support & Lifecycle Services | B38: Services | C38: Services: Cisco DNA Wireless | D38: E3-CXST-AIR-T1SWP | E38: Cisco Support Enhanced SW for Wireless | F38: 0 | H38: Support Enhanced | I38: BIA | J38: =BIA!I38 -> 0 | K38: =BIA!J38 -> 0
A39: Networking Support & Lifecycle Services | B39: Services | C39: Services: Cisco DNA Wireless | D39: E3-CX-EAMSC | E39: SVCS Portfolio EA Management Service Cisco | F39: 0 | H39: Support Enhanced | I39: BIA | J39: =BIA!I39 -> 0 | K39: =BIA!J39 -> 0
A40: Networking Support & Lifecycle Services | B40: Services | C40: Services: Cisco DNA Switching | D40: E3-CX-ST-T14HR | E40: Cisco Support Enhanced 24x7x4 for Switching | F40: 163 | H40: Support Enhanced | I40: BIA | J40: =BIA!I40 -> 0 | K40: =BIA!J40 -> 0
A41: Networking Support & Lifecycle Services | B41: Services | C41: Services: Cisco DNA Switching | D41: E3-CX-ST-T1NBD | E41: Cisco Support Enhanced 8x5xNBD for Switching | F41: 222 | H41: Support Enhanced | I41: BIA | J41: =BIA!I41 -> 0 | K41: =BIA!J41 -> 0
A42: Networking Support & Lifecycle Services | B42: Services | C42: Services: Cisco DNA Switching | D42: E3-CX-ST-T1SWT | E42: Cisco Support Enhanced SW for Switching | F42: 0 | H42: Support Enhanced | I42: BIA | J42: =BIA!I42 -> 0 | K42: =BIA!J42 -> 0
A43: Networking Support & Lifecycle Services | B43: Services | C43: Services: Cisco DNA Switching | D43: E3-CX-EAMSC | E43: SVCS Portfolio EA Management Service Cisco | F43: 0 | H43: Support Enhanced | I43: BIA | J43: =BIA!I43 -> 0 | K43: =BIA!J43 -> 0
... A51: Zero Trust Services | B51: Services | C51: Services: Duo Fed Essentials | D51: E3-CX-EAMSC | E51: SVCS Portfolio EA Management Service Cisco | F51: 0 | H51: Support Signature | I51: BIA | J51: =BIA!I51 -> 0 | K51: =BIA!J51 -> 0
A52: CON-ECMUS-CUBETRDE | B52: Services | D52: CUBE-T-RED | E52: ^CUBE - 1 Redundant Trunk Session License | F52: 42 | I52: BIA | J52: =BIA!I52 -> 0 | K52: =BIA!J52 -> 0
A53: CON-ECMUS-CUBETRDE | B53: Services | D53: CUBE-T-RED | E53: ^CUBE - 1 Redundant Trunk Session License | F53: 42 | I53: BIA | J53: =BIA!I53 -> 0 | K53: =BIA!J53 -> 0
A54: CON-SSSNT-BE7MM5K9 | B54: Services | D54: BE7M-M5-K9 | E54: ^Cisco Business Edition 7000M (M5) Appliance, Export Restr SW | F54: 1 | I54: BIA | J54: =BIA!I54 -> 0 | K54: =BIA!J54 -> 0
A55: CON-L1NBD-VG45XK14 | B55: Services | D55: VG450-144FXS/K9 | E55: Cisco VG450 144 FXS Bundle | F55: 1 | I55: BIA | J55: =BIA!I55 -> 0 | K55: =BIA!J55 -> 0
A56: CON-SSSNT-BE79M5KH | B56: Services | D56: BE7H-M5-K9 | E56: ^Cisco Business Edition 7000H (M5) Appliance, Export Restr SW | F56: 1 | I56: BIA | J56: =BIA!I56 -> 0 | K56: =BIA!J56 -> 0
...

Sheet BIA
A1: Solution Area | B1: Type | C1: Suite | D1: Part Number | E1: Description | F1: Quantity Desired | G1: License Tiers | H1: Service Tier | I1: Unit Price | J1: Total Price
A2: Cisco Networking | B2: Software | C2: Meraki FedRamp Moderate - Network Infrastructure | D2: E3N-FED-MR-E | E2: Meraki FedRamp MR Essentials Subscription EA 3 LIC | F2: 100 | G2: NA | J2: =I2*F2 -> 0
A3: Cisco Networking | B3: Software | C3: Cisco Networking FedRamp Moderate - Switching | D3: E3N-FED-CS-AC1-L-E | E3: Cisco Switching FedRamp EA 3.0 LIC Access Tier 1 Large | F3: 1 | G3: Essential | J3: =I3*F3 -> 0
A4: Cisco Networking | B4: Software | C4: Cisco Networking FedRamp Moderate - Switching | D4: E3N-FED-CS-AC1-M-E | E4: Cisco Switching FedRamp EA 3.0 LIC Access Tier 1 Medium | F4: 1 | G4: Essential | J4: =I4*F4 -> 0
A5: Cisco Networking | B5: Software | C5: Cisco Networking FedRamp Moderate - Switching | D5: E3N-FED-CS-CO-MO-A | E5: Cisco Switching Advantage FedRamp EA 3.0 LIC Core Modular | F5: 1 | G5: Advantage | J5: =I5*F5 -> 0
A6: Cisco Networking | B6: Software | C6: Cisco Networking FedRamp Moderate - Switching | D6: SVS-E3S-CS-GMEAEMB | E6: Cisco Support Standard for Cisco Network Subscription | F6: 1 | G6: NA | J6: =I6*F6 -> 0
A7: Cisco Networking | B7: Software | C7: Cisco Networking FedRamp Moderate - Wireless | D7: SVS-E3S-CW-GMEAEMB | E7: Cisco Support Standard for Cisco Network Subscription | F7: 1 | G7: NA | J7: =I7*F7 -> 0
A8: Cisco Networking | B8: Software | C8: Cisco Networking FedRamp Moderate - Wireless | D8: E3N-FED-CW-E | E8: Cisco Wireless FedRamp EA 3.0 LIC | F8: 1 | G8: Essential | J8: =I8*F8 -> 0
A9: Cloud Networking | B9: Software | C9: Nexus Switching | D9: E3N-DCN-S | E9: Support for Cisco Data Center EA for Data Center Networking | F9: 1 | G9: NA | J9: =I9*F9 -> 0
A10: Cloud Networking | B10: Software | C10: Nexus Switching | D10: E3N-N9300-XF-E | E10: Nexus 9300 XF 10G or higher (up to 3.6T) | F10: 19 | G10: Essential | J10: =I10*F10 -> 0
A11: Cloud Networking | B11: Software | C11: Nexus Switching | D11: E3N-N9500-M816-E | E11: Nexus 9500 8 or 16 Slot | F11: 1 | G11: Essential | J11: =I11*F11 -> 0
A12: Cisco DNA Software | B12: Software | C12: Cisco DNA Switching | D12: E3N-C9300X2-E | E12: C9300X 24-Port DNA EA | F12: 7 | G12: Essential | J12: =I12*F12 -> 0
A13: Cisco DNA Software | B13: Software | C13: Cisco DNA Switching | D13: E3N-C93001-E | E13: C9300 24-Port DNA EA | F13: 24 | G13: Essential | J13: =I13*F13 -> 0
... A23: Cisco DNA Software | B23: Software | C23: Cisco DNA Wireless | D23: E3N-AIR-S | E23: Cisco Support Standard for EA DNA Wireless | F23: 1 | G23: NA | J23: =I23*F23 -> 0
A24: Zero Trust | B24: Software | C24: Duo | D24: SVS-E3-DUOF-B | E24: Cisco Support Standard for Duo Fed | F24: 1 | J24: =I24*F24 -> 0
A25: Zero Trust | B25: Software | C25: Duo | D25: E3S-DUO-F-ES | E25: Security EA3.0 - Duo Fed Essentials | F25: 100 | J25: =I25*F25 -> 0
A26: Zero Trust | B26: Software | C26: Identity Services Engine (ISE) | D26: E3S-ISE-PRM | E26: ISE Premier | F26: 100 | J26: =I26*F26 -> 0
A27: Zero Trust | B27: Software | C27: Identity Services Engine (ISE) | D27: SVS-E3S-ISE-B | E27: Cisco Support Standard for ISE | F27: 1 | J27: =I27*F27 -> 0
A28: Zero Trust | B28: Software | C28: Identity Services Engine (ISE) | D28: E3S-ISE-ESS | E28: ISE Essentials | F28: 100 | J28: =I28*F28 -> 0
A29: Cloud and Network Security | B29: Software | C29: Secure Firewall | D29: SVS-E3S-SFW-B | E29: Cisco Support Standard for Cisco Secure Firewall | F29: 1 | J29: =I29*F29 -> 0
A30: Cloud and Network Security | B30: Software | C30: Secure Firewall | D30: E3S-SFW-FPR2110T | E30: FPR2110T Threat Defense Threat, Malware,URL | F30: 15 | J30: =I30*F30 -> 0
A31: Cloud and Network Security | B31: Software | C31: Secure Firewall | D31: E3S-SFW-FPR4125T | E31: FPR4125 Threat Defense Threat, Malware,URL | F31: 2 | J31: =I31*F31 -> 0
A32: Networking Support & Lifecycle Services | B32: Services | C32: Services: Cisco DNA SD-WAN & Routing | D32: E3-CX-ENWAN-L1PERP | E32: Cisco Support Enhanced Perpetual for ENTWAN | F32: 110 | H32: Support Enhanced | J32: =I32*F32 -> 0
A33: Networking Support & Lifecycle Services | B33: Services | C33: Services: Cisco DNA SD-WAN & Routing | D33: E3-CX-ENTWAN-T1NBD | E33: Cisco Support Enhanced 8x5xNBD for ENTWAN | F33: 242 | H33: Support Enhanced | J33: =I33*F33 -> 0
A34: Networking Support & Lifecycle Services | B34: Services | C34: Services: Nexus Switching | D34: E3-CX-DCN-L1SWPERP | E34: Cisco Support Enhanced Perpetual for Nexus Switching | F34: 14 | H34: - | J34: =I34*F34 -> 0
A35: Networking Support & Lifecycle Services | B35: Services | C35: Services: Nexus Switching | D35: E3-CX-DCN-T1NBD | E35: Cisco Support Enhanced 8x5xNBD for Nexus Switching | F35: 669 | H35: - | J35: =I35*F35 -> 0
A36: Networking Support & Lifecycle Services | B36: Services | C36: Services: SAN Switching | D36: E3-CX-MDS-T1NBD | E36: Cisco Support Enhanced 8x5xNBD for SAN Switching | F36: 57 | H36: - | J36: =I36*F36 -> 0
A37: Networking Support & Lifecycle Services | B37: Services | C37: Services: Cisco DNA Wireless | D37: E3-CX-AIR-T1NBD | E37: Cisco Support Enhanced 8x5xNBD for Wireless | F37: 1 | H37: Support Enhanced | J37: =I37*F37 -> 0
A38: Networking Support & Lifecycle Services | B38: Services | C38: Services: Cisco DNA Wireless | D38: E3-CXST-AIR-T1SWP | E38: Cisco Support Enhanced SW for Wireless | F38: 0 | H38: Support Enhanced | J38: =I38*F38 -> 0
A39: Networking Support & Lifecycle Services | B39: Services | C39: Services: Cisco DNA Wireless | D39: E3-CX-EAMSC | E39: SVCS Portfolio EA Management Service Cisco | F39: 0 | H39: Support Enhanced | J39: =I39*F39 -> 0
A40: Networking Support & Lifecycle Services | B40: Services | C40: Services: Cisco DNA Switching | D40: E3-CX-ST-T14HR | E40: Cisco Support Enhanced 24x7x4 for Switching | F40: 163 | H40: Support Enhanced | J40: =I40*F40 -> 0
A41: Networking Support & Lifecycle Services | B41: Services | C41: Services: Cisco DNA Switching | D41: E3-CX-ST-T1NBD | E41: Cisco Support Enhanced 8x5xNBD for Switching | F41: 222 | H41: Support Enhanced | J41: =I41*F41 -> 0
A42: Networking Support & Lifecycle Services | B42: Services | C42: Services: Cisco DNA Switching | D42: E3-CX-ST-T1SWT | E42: Cisco Support Enhanced SW for Switching | F42: 0 | H42: Support Enhanced | J42: =I42*F42 -> 0
A43: Networking Support & Lifecycle Services | B43: Services | C43: Services: Cisco DNA Switching | D43: E3-CX-EAMSC | E43: SVCS Portfolio EA Management Service Cisco | F43: 0 | H43: Support Enhanced | J43: =I43*F43 -> 0
... A51: Zero Trust Services | B51: Services | C51: Services: Duo Fed Essentials | D51: E3-CX-EAMSC | E51: SVCS Portfolio EA Management Service Cisco | F51: 0 | H51: Support Signature | J51: =I51*F51 -> 0
A52: CON-ECMUS-CUBETRDE | B52: Services | D52: CUBE-T-RED | E52: ^CUBE - 1 Redundant Trunk Session License | F52: 42 | J52: =I52*F52 -> 0
A53: CON-ECMUS-CUBETRDE | B53: Services | D53: CUBE-T-RED | E53: ^CUBE - 1 Redundant Trunk Session License | F53: 42 | J53: =I53*F53 -> 0
A54: CON-SSSNT-BE7MM5K9 | B54: Services | D54: BE7M-M5-K9 | E54: ^Cisco Business Edition 7000M (M5) Appliance, Export Restr SW | F54: 1 | J54: =I54*F54 -> 0
A55: CON-L1NBD-VG45XK14 | B55: Services | D55: VG450-144FXS/K9 | E55: Cisco VG450 144 FXS Bundle | F55: 1 | J55: =I55*F55 -> 0
A56: CON-SSSNT-BE79M5KH | B56: Services | D56: BE7H-M5-K9 | E56: ^Cisco Business Edition 7000H (M5) Appliance, Export Restr SW | F56: 1 | J56: =I56*F56 -> 0
...

Sheet BIE
A1: Solution Area | B1: Type | C1: Suite | D1: Part Number | E1: Description | F1: Quantity Desired | G1: License Tiers | H1: Service Tier | I1: Unit Price | J1: Total Price
A2: Cisco Networking | B2: Software | C2: Meraki FedRamp Moderate - Network Infrastructure | D2: E3N-FED-MR-E | E2: Meraki FedRamp MR Essentials Subscription EA 3 LIC | F2: 100 | G2: NA | J2: =I2*F2 -> 0
A3: Cisco Networking | B3: Software | C3: Cisco Networking FedRamp Moderate - Switching | D3: E3N-FED-CS-AC1-L-E | E3: Cisco Switching FedRamp EA 3.0 LIC Access Tier 1 Large | F3: 1 | G3: Essential | J3: =I3*F3 -> 0
A4: Cisco Networking | B4: Software | C4: Cisco Networking FedRamp Moderate - Switching | D4: E3N-FED-CS-AC1-M-E | E4: Cisco Switching FedRamp EA 3.0 LIC Access Tier 1 Medium | F4: 1 | G4: Essential | J4: =I4*F4 -> 0
A5: Cisco Networking | B5: Software | C5: Cisco Networking FedRamp Moderate - Switching | D5: E3N-FED-CS-CO-MO-A | E5: Cisco Switching Advantage FedRamp EA 3.0 LIC Core Modular | F5: 1 | G5: Advantage | J5: =I5*F5 -> 0
A6: Cisco Networking | B6: Software | C6: Cisco Networking FedRamp Moderate - Switching | D6: SVS-E3S-CS-GMEAEMB | E6: Cisco Support Standard for Cisco Network Subscription | F6: 1 | G6: NA | J6: =I6*F6 -> 0
A7: Cisco DNA Software | B7: Software | C7: Cisco DNA Switching | D7: E3N-C92001-E | E7: C9200 24-Port DNA EA | F7: 5 | G7: Essential | J7: =I7*F7 -> 0
A8: Cisco DNA Software | B8: Software | C8: Cisco DNA Switching | D8: E3N-C9300L1-E | E8: C9300L 24-Port DNA EA | F8: 83 | G8: Essential | J8: =I8*F8 -> 0
A9: Cisco DNA Software | B9: Software | C9: Cisco DNA Switching | D9: E3N-C9200L2-E | E9: C9200L 48-Port DNA EA | F9: 2 | G9: Essential | J9: =I9*F9 -> 0
A10: Cisco DNA Software | B10: Software | C10: Cisco DNA Switching | D10: E3N-AS-S | E10: Cisco Support Standard for EA DNA Switching | F10: 1 | G10: NA | J10: =I10*F10 -> 0
A11: Zero Trust | B11: Software | C11: Duo | D11: SVS-E3-DUOF-B | E11: Cisco Support Standard for Duo Fed | F11: 1 | J11: =I11*F11 -> 0
A12: Zero Trust | B12: Software | C12: Duo | D12: E3S-DUO-F-ES | E12: Security EA3.0 - Duo Fed Essentials | F12: 100 | J12: =I12*F12 -> 0
A13: Zero Trust | B13: Software | C13: Identity Services Engine (ISE) | D13: E3S-ISE-PRM | E13: ISE Premier | F13: 100 | J13: =I13*F13 -> 0
A14: Zero Trust | B14: Software | C14: Identity Services Engine (ISE) | D14: SVS-E3S-ISE-B | E14: Cisco Support Standard for ISE | F14: 1 | J14: =I14*F14 -> 0
A15: Cloud and Network Security | B15: Software | C15: Secure Firewall | D15: SVS-E3S-SFW-B | E15: Cisco Support Standard for Cisco Secure Firewall | F15: 1 | J15: =I15*F15 -> 0
A16: Cloud and Network Security | B16: Software | C16: Secure Firewall | D16: E3S-SFW-FPR4125T | E16: FPR4125 Threat Defense Threat, Malware,URL | F16: 2 | J16: =I16*F16 -> 0
A17: Cloud and Network Security Services | B17: Services | C17: Services: Secure Firewall | D17: E3-CX-SFW-T1TCS | E17: SVCS Portfolio T1 Secure Firewall Solution Support - OP | F17: 0 | H17: Services Tier 1 | J17: =I17*F17 -> 0
A18: Cloud and Network Security Services | B18: Services | C18: Services: Secure Firewall | D18: E3-CX-SFW-T1NT | E18: SVCS Portfolio T1 8x5xNBD Secure Firewall Support | F18: 52 | H18: Services Tier 1 | J18: =I18*F18 -> 0
A19: Cloud and Network Security Services | B19: Services | C19: Services: Secure Firewall | D19: E3-CX-SFW-T1NC | E19: SVCS Portfolio T1 8x7xNCD Secure Firewall Support | F19: 2 | H19: Services Tier 1 | J19: =I19*F19 -> 0
A20: Cloud and Network Security Services | B20: Services | C20: Services: Secure Firewall | D20: E3-CX-EAMSC | E20: SVCS Portfolio EA Management Service Cisco | F20: 0 | H20: Services Tier 1 | J20: =I20*F20 -> 0
A21: Zero Trust Services | B21: Services | C21: Services: Identity Services Engine (ISE) | D21: E3-CX-ISE-T1TCS | E21: SVCS Portfolio T1 ISE Solution Support - OnPrem | F21: 0 | H21: Services Tier 1 | J21: =I21*F21 -> 0
A22: Zero Trust Services | B22: Services | C22: Services: Identity Services Engine (ISE) | D22: E3-CX-ISE-T1NT | E22: SVCS Portfolio T1 8x5xNBD ISE Support | F22: 2 | H22: Services Tier 1 | J22: =I22*F22 -> 0
A23: Zero Trust Services | B23: Services | C23: Services: Identity Services Engine (ISE) | D23: E3-CX-EAMSC | E23: SVCS Portfolio EA Management Service Cisco | F23: 0 | H23: Services Tier 1 | J23: =I23*F23 -> 0
A24: Networking Support & Lifecycle Services | B24: Services | C24: Services: Cisco DNA SD-WAN & Routing | D24: E3-CX-ENWAN-L1PERP | E24: Cisco Support Enhanced Perpetual for ENTWAN | F24: 4 | H24: Support Enhanced | J24: =I24*F24 -> 0
A25: Networking Support & Lifecycle Services | B25: Services | C25: Services: Cisco DNA SD-WAN & Routing | D25: E3-CX-ENTWAN-T1NBD | E25: Cisco Support Enhanced 8x5xNBD for ENTWAN | F25: 1361 | H25: Support Enhanced | J25: =I25*F25 -> 0
A26: Networking Support & Lifecycle Services | B26: Services | C26: Services: Cisco DNA SD-WAN & Routing | D26: E3-CX-ENTWAN-T1NCD | E26: Cisco Support Enhanced 8x7xNCD for ENTWAN | F26: 10 | H26: Support Enhanced | J26: =I26*F26 -> 0
A27: Networking Support & Lifecycle Services | B27: Services | C27: Services: Nexus Switching | D27: E3-CX-DCN-T1NCD | E27: Cisco Support Enhanced 8x7xNCD for Nexus Switching | F27: 1 | H27: - | J27: =I27*F27 -> 0
A28: Networking Support & Lifecycle Services | B28: Services | C28: Services: Nexus Switching | D28: E3-CX-DCN-T1NBD | E28: Cisco Support Enhanced 8x5xNBD for Nexus Switching | F28: 37 | H28: - | J28: =I28*F28 -> 0
... A33: Networking Support & Lifecycle Services | B33: Services | C33: Services: Cisco DNA Switching | D33: E3-CX-EAMSC | E33: SVCS Portfolio EA Management Service Cisco | F33: 0 | H33: Support Enhanced | J33: =I33*F33 -> 0
J34: =SUM(J2:J33) -> 0

Sheet BLM
A1: Solution Area | B1: Type | C1: Suite | D1: Part Number | E1: Description | F1: Quantity Desired | G1: License Tiers | H1: Service Tier | I1: Unit Price | J1: Total Price
A2: Cisco Networking | B2: Software | C2: Meraki FedRamp Moderate - Network Infrastructure | D2: E3N-FED-MR-E | E2: Meraki FedRamp MR Essentials Subscription EA 3 LIC | F2: 1985 | G2: NA | J2: =I2*F2 -> 0
A3: Cisco Networking | B3: Software | C3: Meraki FedRamp Moderate - Network Infrastructure | D3: E3N-FED-MX-S-E | E3: Meraki FedRamp MX Small Essentials Subscription EA 3 LIC | F3: 92 | G3: NA | J3: =I3*F3 -> 0
A4: Cisco Networking | B4: Software | C4: Meraki FedRamp Moderate - Network Infrastructure | D4: E3N-FED-MX-M-E | E4: Meraki FedRamp MX Medium Essentials Subscription EA 3 LIC | F4: 2 | G4: NA | J4: =I4*F4 -> 0
A5: Cloud Networking | B5: Software | C5: Nexus Switching | D5: E3N-N9300-XF-A | E5: Nexus 9300 XF 10G or higher (up to 3.6T) | F5: 22 | G5: Advantage | J5: =I5*F5 -> 0
A6: Cloud Networking | B6: Software | C6: Nexus Switching | D6: E3N-DCN-S | E6: Support for Cisco Data Center EA for Data Center Networking | F6: 1 | G6: NA | J6: =I6*F6 -> 0
A7: Cloud Networking | B7: Software | C7: Nexus Switching | D7: E3N-N9500-M4-A | E7: Nexus 9500 4 Slot | F7: 2 | G7: Advantage | J7: =I7*F7 -> 0
A8: Cloud Networking | B8: Software | C8: Nexus Switching | D8: E3N-N9500-M816-A | E8: Nexus 9500 8 or 16 Slot | F8: 2 | G8: Advantage | J8: =I8*F8 -> 0
A9: Cisco DNA Software | B9: Software | C9: Cisco DNA Switching | D9: E3N-C93001-A | E9: C9300 24-Port DNA EA | F9: 168 | G9: Advantage | J9: =I9*F9 -> 0
A10: Cisco DNA Software | B10: Software | C10: Cisco DNA Switching | D10: E3N-C9400-A | E10: C9400 DNA EA | F10: 1 | G10: Advantage | J10: =I10*F10 -> 0
A11: Cisco DNA Software | B11: Software | C11: Cisco DNA Switching | D11: E3N-C93002-A | E11: C9300/C9300X 48-Port DNA EA | F11: 475 | G11: Advantage | J11: =I11*F11 -> 0
A12: Cisco DNA Software | B12: Software | C12: Cisco DNA Switching | D12: E3N-C9200CX2-A | E12: C9200CX 12-Port DNA EA | F12: 24 | G12: Advantage | J12: =I12*F12 -> 0
A13: Cisco DNA Software | B13: Software | C13: Cisco DNA Switching | D13: E3N-AS-S | E13: Cisco Support Standard for EA DNA Switching | F13: 1 | G13: NA | J13: =I13*F13 -> 0
A14: Cisco DNA Software | B14: Software | C14: Cisco DNA Switching | D14: E3N-C9300X1-A | E14: C9300X 12-Port DNA EA | F14: 5 | G14: Advantage | J14: =I14*F14 -> 0
A15: Full Stack Observability | B15: Software | C15: Thousand Eyes | D15: E3A-TE-UNITS | E15: ThousandEyes - Cloud and Enterprise Agents (per unit) | F15: 3000 | J15: =I15*F15 -> 0
A16: Full Stack Observability | B16: Software | C16: Thousand Eyes | D16: E3A-TE-S | E16: Cisco Support Standard for EA Thousand Eyes | F16: 1 | J16: =I16*F16 -> 0
A17: Full Stack Observability | B17: Software | C17: Thousand Eyes | D17: E3A-TE-USERS | E17: Cisco ThousandEyes - End User Monitoring Advantage | F17: 100 | J17: =I17*F17 -> 0
A18: Zero Trust | B18: Software | C18: Duo | D18: SVS-E3-DUOF-B | E18: Cisco Support Standard for Duo Fed | F18: 1 | J18: =I18*F18 -> 0
A19: Zero Trust | B19: Software | C19: Duo | D19: E3S-DUO-F-ES | E19: Security EA3.0 - Duo Fed Essentials | F19: 210 | J19: =I19*F19 -> 0
A20: Zero Trust | B20: Software | C20: Identity Services Engine (ISE) | D20: E3S-ISE-PRM | E20: ISE Premier | F20: 100 | J20: =I20*F20 -> 0
A21: Zero Trust | B21: Software | C21: Identity Services Engine (ISE) | D21: SVS-E3S-ISE-B | E21: Cisco Support Standard for ISE | F21: 1 | J21: =I21*F21 -> 0
A22: Zero Trust | B22: Software | C22: Identity Services Engine (ISE) | D22: E3S-ISE-ADV | E22: ISE Advantage | F22: 300 | J22: =I22*F22 -> 0
A23: Zero Trust | B23: Software | C23: Identity Services Engine (ISE) | D23: E3S-ISE-ESS | E23: ISE Essentials | F23: 3200 | J23: =I23*F23 -> 0
A24: Cloud and Network Security | B24: Software | C24: Secure Firewall | D24: SVS-E3S-SFW-B | E24: Cisco Support Standard for Cisco Secure Firewall | F24: 1 | J24: =I24*F24 -> 0
A25: Cloud and Network Security | B25: Software | C25: Secure Firewall | D25: E3S-SFW-FPR1120-TM | E25: FPR1120 ThreatDefense Threat and Malware Lic | F25: 1 | J25: =I25*F25 -> 0
A26: Cloud and Network Security | B26: Software | C26: Secure Firewall | D26: E3S-SFW-FPR2130-TM | E26: FPR2130 ThreatDefense Threat and Malware Lic | F26: 3 | J26: =I26*F26 -> 0
... A49: Zero Trust Services | B49: Services | C49: Services: Identity Services Engine (ISE) | D49: E3-CX-ISE-ENBD | E49: Cisco Support Enhanced 8x5xNBD for ISE | F49: 2 | J49: =I49*F49 -> 0
A50: CON-SSSNT-BE7MM5K9 | B50: Services | D50: BE7M-M5-K9 | E50: ^Cisco Business Edition 7000M (M5) Appliance, Export Restr SW | F50: 1 | J50: =I50*F50 -> 0
A51: CON-SSSNT-BE7MM5K9 | B51: Services | D51: BE7M-M5-K9 | E51: ^Cisco Business Edition 7000M (M5) Appliance, Export Restr SW | F51: 1 | J51: =I51*F51 -> 0
A52: CON-SSSNT-BE7MM5K9 | B52: Services | D52: BE7M-M5-K9 | E52: ^Cisco Business Edition 7000M (M5) Appliance, Export Restr SW | F52: 1 | J52: =I52*F52 -> 0
A53: CON-SSSNT-BE7MM5K9 | B53: Services | D53: BE7M-M5-K9 | E53: ^Cisco Business Edition 7000M (M5) Appliance, Export Restr SW | F53: 1 | J53: =I53*F53 -> 0
A54: CON-SSSNT-BE7MM5K9 | B54: Services | D54: BE7M-M5-K9 | E54: ^Cisco Business Edition 7000M (M5) Appliance, Export Restr SW | F54: 1 | J54: =I54*F54 -> 0
A55: CON-SSSNT-BE7MM5K9 | B55: Services | D55: BE7M-M5-K9 | E55: ^Cisco Business Edition 7000M (M5) Appliance, Export Restr SW | F55: 1 | J55: =I55*F55 -> 0
A56: CON-SSSNT-BE7MM5K9 | B56: Services | D56: BE7M-M5-K9 | E56: ^Cisco Business Edition 7000M (M5) Appliance, Export Restr SW | F56: 1 | J56: =I56*F56 -> 0
A57: CON-SSSNT-BE7MM5K9 | B57: Services | D57: BE7M-M5-K9 | E57: ^Cisco Business Edition 7000M (M5) Appliance, Export Restr SW | F57: 1 | J57: =I57*F57 -> 0
A58: CON-SSSNT-BE7MM5K9 | B58: Services | D58: BE7M-M5-K9 | E58: ^Cisco Business Edition 7000M (M5) Appliance, Export Restr SW | F58: 1 | J58: =I58*F58 -> 0
A59: CON-SSSNT-BE7MM5K9 | B59: Services | D59: BE7M-M5-K9 | E59: ^Cisco Business Edition 7000M (M5) Appliance, Export Restr SW | F59: 1 | J59: =I59*F59 -> 0
A60: CON-SSSNT-BE7MM5K9 | B60: Services | D60: BE7M-M5-K9 | E60: ^Cisco Business Edition 7000M (M5) Appliance, Export Restr SW | F60: 1 | J60: =I60*F60 -> 0
A61: CON-SSSNT-BE7MM5K9 | B61: Services | D61: BE7M-M5-K9 | E61: ^Cisco Business Edition 7000M (M5) Appliance, Export Restr SW | F61: 1 | J61: =I61*F61 -> 0
J62: =SUM(J2:J61) -> 0

Sheet BOR
A1: Solution Area | B1: Type | C1: Suite | D1: Part Number | E1: Description | F1: Quantity Desired | G1: License Tiers | H1: Service Tier | I1: Unit Price | J1: Total Price
A2: Cisco Networking | B2: Software | C2: Meraki FedRamp Moderate - Network Infrastructure | D2: E3N-FED-MR-E | E2: Meraki FedRamp MR Essentials Subscription EA 3 LIC | F2: 100 | G2: NA | J2: =I2*F2 -> 0
A3: Cisco Networking | B3: Software | C3: Cisco Networking FedRamp Moderate - Switching | D3: E3N-FED-CS-AC1-L-A | E3: Cisco Switching FedRamp EA 3.0 LIC Access Tier 1 Large | F3: 1 | G3: Advantage | J3: =I3*F3 -> 0
A4: Cisco Networking | B4: Software | C4: Cisco Networking FedRamp Moderate - Switching | D4: E3N-FED-CS-AC1-M-A | E4: Cisco Switching FedRamp EA 3.0 LIC Access Tier 1 Medium | F4: 1 | G4: Advantage | J4: =I4*F4 -> 0
A5: Cisco Networking | B5: Software | C5: Cisco Networking FedRamp Moderate - Switching | D5: E3N-FED-CS-CO-MO-A | E5: Cisco Switching Advantage FedRamp EA 3.0 LIC Core Modular | F5: 1 | G5: Advantage | J5: =I5*F5 -> 0
A6: Cisco Networking | B6: Software | C6: Cisco Networking FedRamp Moderate - Switching | D6: SVS-E3S-CS-GMEAEMB | E6: Cisco Support Standard for Cisco Network Subscription | F6: 1 | G6: NA | J6: =I6*F6 -> 0
A7: Cisco Networking | B7: Software | C7: Cisco Networking FedRamp Moderate - Wireless | D7: E3N-FED-CW-A | E7: Cisco Wireless FedRamp EA 3.0 LIC | F7: 1 | G7: Advantage | J7: =I7*F7 -> 0
A8: Cisco Networking | B8: Software | C8: Cisco Networking FedRamp Moderate - Wireless | D8: SVS-E3S-CW-GMEAEMB | E8: Cisco Support Standard for Cisco Network Subscription | F8: 1 | G8: NA | J8: =I8*F8 -> 0
A9: Cloud Networking | B9: Software | C9: Nexus Switching | D9: E3N-N9300-XF-A | E9: Nexus 9300 XF 10G or higher (up to 3.6T) | F9: 11 | G9: Advantage | J9: =I9*F9 -> 0
A10: Cloud Networking | B10: Software | C10: Nexus Switching | D10: E3N-DCN-S | E10: Support for Cisco Data Center EA for Data Center Networking | F10: 1 | G10: NA | J10: =I10*F10 -> 0
A11: Cloud Networking | B11: Software | C11: Nexus Switching | D11: E3N-N9500-M4-A | E11: Nexus 9500 4 Slot | F11: 2 | G11: Advantage | J11: =I11*F11 -> 0
A12: Cisco DNA Software | B12: Software | C12: Cisco DNA Switching | D12: E3N-C93001-A | E12: C9300 24-Port DNA EA | F12: 113 | G12: Advantage | J12: =I12*F12 -> 0
A13: Cisco DNA Software | B13: Software | C13: Cisco DNA Switching | D13: E3N-C95001-A | E13: C9500 High Port (24Q/40X) DNA EA | F13: 6 | G13: Advantage | J13: =I13*F13 -> 0
... A24: Cisco DNA Software | B24: Software | C24: Cisco DNA Wireless | D24: E3N-AIR-S | E24: Cisco Support Standard for EA DNA Wireless | F24: 1 | G24: NA | J24: =I24*F24 -> 0
A25: Zero Trust | B25: Software | C25: Duo | D25: SVS-E3-DUOF-B | E25: Cisco Support Standard for Duo Fed | F25: 1 | J25: =I25*F25 -> 0
A26: Zero Trust | B26: Software | C26: Duo | D26: E3S-DUO-F-ES | E26: Security EA3.0 - Duo Fed Essentials | F26: 100 | J26: =I26*F26 -> 0
A27: Zero Trust | B27: Software | C27: Identity Services Engine (ISE) | D27: E3S-ISE-PRM | E27: ISE Premier | F27: 840 | J27: =I27*F27 -> 0
A28: Zero Trust | B28: Software | C28: Identity Services Engine (ISE) | D28: SVS-E3S-ISE-B | E28: Cisco Support Standard for ISE | F28: 1 | J28: =I28*F28 -> 0
A29: Zero Trust | B29: Software | C29: Identity Services Engine (ISE) | D29: E3S-ISE-ADV | E29: ISE Advantage | F29: 740 | J29: =I29*F29 -> 0
A30: Zero Trust | B30: Software | C30: Identity Services Engine (ISE) | D30: E3S-ISE-ESS | E30: ISE Essentials | F30: 2300 | J30: =I30*F30 -> 0
A31: Networking Support & Lifecycle Services | B31: Services | C31: Services: Cisco DNA SD-WAN & Routing | D31: E3-CX-CSWAN-T1SWP | E31: Cisco Support Enhanced Combined Svs SW On-Prem for ENTWAN | F31: 0 | H31: Combined Services Support Enhanced | J31: =I31*F31 -> 0
A32: Networking Support & Lifecycle Services | B32: Services | C32: Services: Cisco DNA SD-WAN & Routing | D32: E3-CX-CSWAN-T14OS | E32: Cisco Support Enhanced Combined Svs 24x7x4 OS for ENTWAN | F32: 11 | H32: Combined Services Support Enhanced | J32: =I32*F32 -> 0
A33: Networking Support & Lifecycle Services | B33: Services | C33: Services: Cisco DNA SD-WAN & Routing | D33: E3-CX-CSWAN-T1NBD | E33: Cisco Support Enhanced Combined Svs 8x5xNBD for ENTWAN | F33: 1322 | H33: Combined Services Support Enhanced | J33: =I33*F33 -> 0
A34: Networking Support & Lifecycle Services | B34: Services | C34: Services: Cisco DNA SD-WAN & Routing | D34: E3-CX-CSWAN-T1NCD | E34: Cisco Support Enhanced Combined Svs 8x7xNCD for ENTWAN | F34: 25 | H34: Combined Services Support Enhanced | J34: =I34*F34 -> 0
A35: Networking Support & Lifecycle Services | B35: Services | C35: Services: Cisco DNA SD-WAN & Routing | D35: E3-CX-EAMSC | E35: SVCS Portfolio EA Management Service Cisco | F35: 0 | H35: Combined Services Support Enhanced | J35: =I35*F35 -> 0
A36: Networking Support & Lifecycle Services | B36: Services | C36: Services: Cisco DNA SD-WAN & Routing | D36: E3-CX-CSWAN-L1PERP | E36: Cisco Support Enhanced Combined Svs Perpetual for ENTWAN | F36: 21 | H36: Combined Services Support Enhanced | J36: =I36*F36 -> 0
A37: Networking Support & Lifecycle Services | B37: Services | C37: Services: Nexus Switching | D37: E3-CX-CSDCN-L1PERP | E37: Cisco Support Enhanced Combined Svss Perpetual for DCN | F37: 4 | H37: - | J37: =I37*F37 -> 0
A38: Networking Support & Lifecycle Services | B38: Services | C38: Services: Nexus Switching | D38: E3-CX-CSDCN-T1NBD | E38: Cisco Support Enhanced Combined Svs 8x5xNBD for DCN | F38: 68 | H38: - | J38: =I38*F38 -> 0
A39: Networking Support & Lifecycle Services | B39: Services | C39: Services: Nexus Switching | D39: E3-CX-CSDCN-T14HR | E39: Cisco Support Enhanced Combined Svs 24x7x4 for DCN | F39: 70 | H39: - | J39: =I39*F39 -> 0
A40: Networking Support & Lifecycle Services | B40: Services | C40: Services: SAN Switching | D40: E3-CX-MDS-T1NBD | E40: Cisco Support Enhanced 8x5xNBD for SAN Switching | F40: 9 | H40: - | J40: =I40*F40 -> 0
A41: Networking Support & Lifecycle Services | B41: Services | C41: Services: Cisco DNA Wireless | D41: E3-CX-CSAIR-T1SWP | E41: Cisco Support Enhanced Combined Svs Wireless SW for Wireless | F41: 0 | H41: Combined Services Support Enhanced | J41: =I41*F41 -> 0
A42: Networking Support & Lifecycle Services | B42: Services | C42: Services: Cisco DNA Wireless | D42: E3-CX-CSAIR-L1PERP | E42: Cisco Support Enhanced Combined Svss Perpetual for Wireless | F42: 1 | H42: Combined Services Support Enhanced | J42: =I42*F42 -> 0
... A56: Zero Trust Services | B56: Services | C56: Services: Identity Services Engine (ISE) | D56: E3-CX-EAMSC | E56: SVCS Portfolio EA Management Service Cisco | F56: 0 | H56: Services Tier 2 | J56: =I56*F56 -> 0
A57: CON-SSSNT-LCTUPG | B57: Services | D57: L-LIC-CT5508-UPG | E57: Primary SKU for CT5508 upgrade licenses (Delivery via Email) | F57: 1 | J57: =I57*F57 -> 0
B58: Services | D58: L-LIC-CT5508-25A | E58: 25 AP Adder License for the 5508 Controller (eDelivery) | F58: 1 | J58: =I58*F58 -> 0
A59: CON-SSSNT-LCTUPG | B59: Services | D59: L-LIC-CT5508-UPG | E59: Primary SKU for CT5508 upgrade licenses (Delivery via Email) | F59: 1 | J59: =I59*F59 -> 0
B60: Services | D60: L-LIC-CT5508-25A | E60: 25 AP Adder License for the 5508 Controller (eDelivery) | F60: 1 | J60: =I60*F60 -> 0
A61: CON-SSSNT-LCTUPG | B61: Services | D61: L-LIC-CT5508-UPG | E61: Primary SKU for CT5508 upgrade licenses (Delivery via Email) | F61: 1 | J61: =I61*F61 -> 0
B62: Services | D62: L-LIC-CT5508-25A | E62: 25 AP Adder License for the 5508 Controller (eDelivery) | F62: 1 | J62: =I62*F62 -> 0
A63: CON-SSSNT-LCTUPG | B63: Services | D63: L-LIC-CT5508-UPG | E63: Primary SKU for CT5508 upgrade licenses (Delivery via Email) | F63: 1 | J63: =I63*F63 -> 0
...

Sheet BSEE
A1: Solution Area | B1: Type | C1: Suite | D1: Part Number | E1: Description | F1: Quantity Desired | G1: License Tiers | H1: Service Tier | I1: Unit Price | J1: Total Price
A2: Cisco Networking | B2: Software | C2: Meraki FedRamp Moderate - Network Infrastructure | D2: E3N-FED-MR-E | E2: Meraki FedRamp MR Essentials Subscription EA 3 LIC | F2: 100 | G2: NA | J2: =I2*F2 -> 0
A3: Cisco Networking | B3: Software | C3: Meraki FedRamp Moderate - Network Infrastructure | D3: E3N-FED-MX-M-A | E3: Meraki FedRamp MX Medium Advantage Subscription EA 3 LIC | F3: 1 | G3: NA | J3: =I3*F3 -> 0
A4: Cisco Networking | B4: Software | C4: Meraki FedRamp Moderate - Network Infrastructure | D4: E3N-FED-MX-S-A | E4: Meraki FedRamp MX Small Advantage Subscription EA 3 LIC | F4: 1 | G4: NA | J4: =I4*F4 -> 0
A5: Cisco DNA Software | B5: Software | C5: Cisco DNA Switching | D5: E3N-C93001-A | E5: C9300 24-Port DNA EA | F5: 10 | G5: Advantage | J5: =I5*F5 -> 0
A6: Cisco DNA Software | B6: Software | C6: Cisco DNA Switching | D6: E3N-C93002-A | E6: C9300/C9300X 48-Port DNA EA | F6: 50 | G6: Advantage | J6: =I6*F6 -> 0
A7: Cisco DNA Software | B7: Software | C7: Cisco DNA Switching | D7: E3N-C9200CX2-A | E7: C9200CX 12-Port DNA EA | F7: 8 | G7: Advantage | J7: =I7*F7 -> 0
A8: Cisco DNA Software | B8: Software | C8: Cisco DNA Switching | D8: E3N-C9200CX2-E | E8: C9200CX 12-Port DNA EA | F8: 14 | G8: Essential | J8: =I8*F8 -> 0
A9: Cisco DNA Software | B9: Software | C9: Cisco DNA Switching | D9: E3N-AS-S | E9: Cisco Support Standard for EA DNA Switching | F9: 1 | G9: NA | J9: =I9*F9 -> 0
A10: Cisco DNA Software | B10: Software | C10: Cisco DNA Switching | D10: E3N-C9300X1-A | E10: C9300X 12-Port DNA EA | F10: 10 | G10: Advantage | J10: =I10*F10 -> 0
A11: Zero Trust | B11: Software | C11: Identity Services Engine (ISE) | D11: E3S-ISE-PRM | E11: ISE Premier | F11: 3000 | J11: =I11*F11 -> 0
A12: Zero Trust | B12: Software | C12: Identity Services Engine (ISE) | D12: SVS-E3S-ISE-B | E12: Cisco Support Standard for ISE | F12: 1 | J12: =I12*F12 -> 0
A13: Cloud and Network Security | B13: Software | C13: Secure Firewall | D13: E3S-SFW-FPR1010T | E13: FPR1010T Threat Defense Threat, Malware,URL | F13: 4 | J13: =I13*F13 -> 0
A14: Cloud and Network Security | B14: Software | C14: Secure Firewall | D14: E3S-SFW-FPR1120T | E14: FPR1120T Threat Defense Threat, Malware,URL | F14: 15 | J14: =I14*F14 -> 0
A15: Cloud and Network Security | B15: Software | C15: Secure Firewall | D15: SVS-E3S-SFW-B | E15: Cisco Support Standard for Cisco Secure Firewall | F15: 1 | J15: =I15*F15 -> 0
A16: Cloud and Network Security | B16: Software | C16: Secure Firewall | D16: E3S-SFW-FPR2130T | E16: FPR2130T Threat Defense Threat, Malware,URL | F16: 1 | J16: =I16*F16 -> 0
A17: Cloud and Network Security | B17: Software | C17: Secure Firewall | D17: E3S-SFW-FPR2140T | E17: FPR2140 Threat Defense Threat, Malware,URL | F17: 4 | J17: =I17*F17 -> 0
A18: Networking Support & Lifecycle Services | B18: Services | C18: Services: Nexus Switching | D18: E3-CX-DCN-T1NBD | E18: Cisco Support Enhanced 8x5xNBD for Nexus Switching | F18: 42 | H18: - | J18: =I18*F18 -> 0
A19: Networking Support & Lifecycle Services | B19: Services | C19: Services: Cisco DNA Switching | D19: E3-CX-ST-T1NBD | E19: Cisco Support Enhanced 8x5xNBD for Switching | F19: 2489 | H19: Support Enhanced | J19: =I19*F19 -> 0
A20: Networking Support & Lifecycle Services | B20: Services | C20: Services: Cisco DNA Switching | D20: E3-CX-ST-T1SWT | E20: Cisco Support Enhanced SW for Switching | F20: 0 | H20: Support Enhanced | J20: =I20*F20 -> 0
A21: Networking Support & Lifecycle Services | B21: Services | C21: Services: Cisco DNA Switching | D21: E3-CX-EAMSC | E21: SVCS Portfolio EA Management Service Cisco | F21: 0 | H21: Support Enhanced | J21: =I21*F21 -> 0
A22: Cloud and Network Security Services | B22: Services | C22: Services: Secure Firewall | D22: E3-CX-SFW-T1TCS | E22: SVCS Portfolio T1 Secure Firewall Solution Support - OP | F22: 0 | H22: Services Tier 1 | J22: =I22*F22 -> 0
A23: Cloud and Network Security Services | B23: Services | C23: Services: Secure Firewall | D23: E3-CX-SFW-T1NT | E23: SVCS Portfolio T1 8x5xNBD Secure Firewall Support | F23: 105 | H23: Services Tier 1 | J23: =I23*F23 -> 0
A24: Cloud and Network Security Services | B24: Services | C24: Services: Secure Firewall | D24: E3-CX-EAMSC | E24: SVCS Portfolio EA Management Service Cisco | F24: 0 | H24: Services Tier 1 | J24: =I24*F24 -> 0
A25: Zero Trust Services | B25: Services | C25: Services: Identity Services Engine (ISE) | D25: E3-CX-ISE-SWPERP-1 | E25: SVCS Portfolio Solution Support Perpetual ISE | F25: 1 | H25: Services Tier 1 | J25: =I25*F25 -> 0
A26: Zero Trust Services | B26: Services | C26: Services: Identity Services Engine (ISE) | D26: E3-CX-ISE-T1TCS | E26: SVCS Portfolio T1 ISE Solution Support - OnPrem | F26: 0 | H26: Services Tier 1 | J26: =I26*F26 -> 0
A27: Zero Trust Services | B27: Services | C27: Services: Identity Services Engine (ISE) | D27: E3-CX-EAMSC | E27: SVCS Portfolio EA Management Service Cisco | F27: 0 | H27: Services Tier 1 | J27: =I27*F27 -> 0
A28: CON-L1NBD-CSPC2205 | B28: Services | D28: CAAPL-CSPC-L-V3-K9 | E28: ^BCS-CSPC-Type 2-Large-V3-Collector | F28: 1 | J28: =I28*F28 -> 0
J29: =SUM(J2:J28) -> 0

Sheet FWS
A1: Solution Area | B1: Type | C1: Suite | D1: Part Number | E1: Description | F1: Quantity Desired | G1: License Tiers | H1: Service Tier | I1: Unit Price | J1: Total Price
A2: Cisco Networking | B2: Software | C2: Meraki FedRamp Moderate - Network Infrastructure | D2: E3N-FED-MR-E | E2: Meraki FedRamp MR Essentials Subscription EA 3 LIC | F2: 100 | G2: NA | J2: =I2*F2 -> 0
A3: Cisco Networking | B3: Software | C3: Cisco Networking FedRamp Moderate - Switching | D3: E3N-FED-CS-AC1-L-A | E3: Cisco Switching FedRamp EA 3.0 LIC Access Tier 1 Large | F3: 1 | G3: Advantage | J3: =I3*F3 -> 0
A4: Cisco Networking | B4: Software | C4: Cisco Networking FedRamp Moderate - Switching | D4: E3N-FED-CS-AC1-M-A | E4: Cisco Switching FedRamp EA 3.0 LIC Access Tier 1 Medium | F4: 1 | G4: Advantage | J4: =I4*F4 -> 0
A5: Cisco Networking | B5: Software | C5: Cisco Networking FedRamp Moderate - Switching | D5: E3N-FED-CS-CO-MO-A | E5: Cisco Switching Advantage FedRamp EA 3.0 LIC Core Modular | F5: 1 | G5: Advantage | J5: =I5*F5 -> 0
A6: Cisco Networking | B6: Software | C6: Cisco Networking FedRamp Moderate - Switching | D6: SVS-E3S-CS-GMEAEMB | E6: Cisco Support Standard for Cisco Network Subscription | F6: 1 | G6: NA | J6: =I6*F6 -> 0
A7: Cisco Networking | B7: Software | C7: Cisco Networking FedRamp Moderate - Wireless | D7: E3N-FED-CW-A | E7: Cisco Wireless FedRamp EA 3.0 LIC | F7: 1 | G7: Advantage | J7: =I7*F7 -> 0
A8: Cisco Networking | B8: Software | C8: Cisco Networking FedRamp Moderate - Wireless | D8: SVS-E3S-CW-GMEAEMB | E8: Cisco Support Standard for Cisco Network Subscription | F8: 1 | G8: NA | J8: =I8*F8 -> 0
A9: Cloud Networking | B9: Software | C9: Nexus Switching | D9: E3N-N9300-XF-A | E9: Nexus 9300 XF 10G or higher (up to 3.6T) | F9: 7 | G9: Advantage | J9: =I9*F9 -> 0
A10: Cloud Networking | B10: Software | C10: Nexus Switching | D10: E3N-DCN-S | E10: Support for Cisco Data Center EA for Data Center Networking | F10: 1 | G10: NA | J10: =I10*F10 -> 0
A11: Cisco DNA Software | B11: Software | C11: Cisco DNA Switching | D11: E3N-C93001-E | E11: C9300 24-Port DNA EA | F11: 3 | G11: Essential | J11: =I11*F11 -> 0
A12: Cisco DNA Software | B12: Software | C12: Cisco DNA Switching | D12: E3N-C93001-A | E12: C9300 24-Port DNA EA | F12: 4 | G12: Advantage | J12: =I12*F12 -> 0
A13: Cisco DNA Software | B13: Software | C13: Cisco DNA Switching | D13: E3N-C9400-A | E13: C9400 DNA EA | F13: 6 | G13: Advantage | J13: =I13*F13 -> 0
... A26: Cisco DNA Software | B26: Software | C26: Cisco DNA Wireless | D26: E3N-AIR-S | E26: Cisco Support Standard for EA DNA Wireless | F26: 1 | G26: NA | J26: =I26*F26 -> 0
A27: Zero Trust | B27: Software | C27: Duo | D27: SVS-E3-DUOF-B | E27: Cisco Support Standard for Duo Fed | F27: 1 | J27: =I27*F27 -> 0
A28: Zero Trust | B28: Software | C28: Duo | D28: E3S-DUO-F-ES | E28: Security EA3.0 - Duo Fed Essentials | F28: 100 | J28: =I28*F28 -> 0
A29: Zero Trust | B29: Software | C29: Identity Services Engine (ISE) | D29: E3S-ISE-PRM | E29: ISE Premier | F29: 5500 | J29: =I29*F29 -> 0
A30: Zero Trust | B30: Software | C30: Identity Services Engine (ISE) | D30: SVS-E3S-ISE-B | E30: Cisco Support Standard for ISE | F30: 1 | J30: =I30*F30 -> 0
A31: Networking Support & Lifecycle Services | B31: Services | C31: Services: Nexus Switching | D31: E3-CX-DCN-T1NCD | E31: Cisco Support Enhanced 8x7xNCD for Nexus Switching | F31: 50 | J31: =I31*F31 -> 0
A32: Networking Support & Lifecycle Services | B32: Services | C32: Services: Nexus Switching | D32: E3-CX-DCN-L1SWPERP | E32: Cisco Support Enhanced Perpetual for Nexus Switching | F32: 24 | J32: =I32*F32 -> 0
A33: Networking Support & Lifecycle Services | B33: Services | C33: Services: Nexus Switching | D33: E3-CX-DCN-T1NBD | E33: Cisco Support Enhanced 8x5xNBD for Nexus Switching | F33: 4 | J33: =I33*F33 -> 0
A34: Networking Support & Lifecycle Services | B34: Services | C34: Services: Cisco DNA Switching | D34: E3-CX-ST-T1SWT | E34: Cisco Support Enhanced SW for Switching | F34: 0 | J34: =I34*F34 -> 0
A35: Networking Support & Lifecycle Services | B35: Services | C35: Services: Cisco DNA Switching | D35: E3-CX-ST-T1NCD | E35: Cisco Support Enhanced 8x7xNCD for Switching | F35: 40 | J35: =I35*F35 -> 0
A36: Networking Support & Lifecycle Services | B36: Services | C36: Services: Cisco DNA Switching | D36: E3-CX-ST-T1NBD | E36: Cisco Support Enhanced 8x5xNBD for Switching | F36: 1011 | J36: =I36*F36 -> 0
J37: =SUM(J2:J36) -> 0

Sheet OIG
A1: Solution Area | B1: Type | C1: Suite | D1: Part Number | E1: Description | F1: Quantity Desired | G1: License Tiers | H1: Service Tier | I1: Unit Price | J1: Total Price
A2: Cisco Networking | B2: Software | C2: Meraki FedRamp Moderate - Network Infrastructure | D2: E3N-FED-MR-E | E2: Meraki FedRamp MR Essentials Subscription EA 3 LIC | F2: 100 | G2: NA | J2: =I2*F2 -> 0
A3: Cisco Networking | B3: Software | C3: Cisco Networking FedRamp Moderate - Switching | D3: E3N-FED-CS-AC1-L-E | E3: Cisco Switching FedRamp EA 3.0 LIC Access Tier 1 Large | F3: 1 | G3: Essential | J3: =I3*F3 -> 0
A4: Cisco Networking | B4: Software | C4: Cisco Networking FedRamp Moderate - Switching | D4: E3N-FED-CS-AC1-M-E | E4: Cisco Switching FedRamp EA 3.0 LIC Access Tier 1 Medium | F4: 1 | G4: Essential | J4: =I4*F4 -> 0
A5: Cisco Networking | B5: Software | C5: Cisco Networking FedRamp Moderate - Switching | D5: E3N-FED-CS-CO-MO-A | E5: Cisco Switching Advantage FedRamp EA 3.0 LIC Core Modular | F5: 1 | G5: Advantage | J5: =I5*F5 -> 0
A6: Cisco Networking | B6: Software | C6: Cisco Networking FedRamp Moderate - Switching | D6: SVS-E3S-CS-GMEAEMB | E6: Cisco Support Standard for Cisco Network Subscription | F6: 1 | G6: NA | J6: =I6*F6 -> 0
A7: Cisco Networking | B7: Software | C7: Cisco Networking FedRamp Moderate - Wireless | D7: SVS-E3S-CW-GMEAEMB | E7: Cisco Support Standard for Cisco Network Subscription | F7: 1 | G7: NA | J7: =I7*F7 -> 0
A8: Cisco Networking | B8: Software | C8: Cisco Networking FedRamp Moderate - Wireless | D8: E3N-FED-CW-E | E8: Cisco Wireless FedRamp EA 3.0 LIC | F8: 1 | G8: Essential | J8: =I8*F8 -> 0
A9: Cisco DNA Software | B9: Software | C9: Cisco DNA Switching | D9: E3N-C9300L1-E | E9: C9300L 24-Port DNA EA | F9: 24 | G9: Essential | J9: =I9*F9 -> 0
A10: Cisco DNA Software | B10: Software | C10: Cisco DNA Switching | D10: E3N-C9300L2-E | E10: C9300L 48-Port DNA EA | F10: 26 | G10: Essential | J10: =I10*F10 -> 0
A11: Cisco DNA Software | B11: Software | C11: Cisco DNA Switching | D11: E3N-AS-S | E11: Cisco Support Standard for EA DNA Switching | F11: 1 | G11: NA | J11: =I11*F11 -> 0
A12: Cisco DNA Software | B12: Software | C12: Cisco DNA Wireless | D12: E3N-AIRWLAN-E | E12: Cisco DNA Wireless | F12: 50 | G12: Essential | J12: =I12*F12 -> 0
A13: Cisco DNA Software | B13: Software | C13: Cisco DNA Wireless | D13: E3N-AIR-S | E13: Cisco Support Standard for EA DNA Wireless | F13: 1 | G13: NA | J13: =I13*F13 -> 0
A14: Zero Trust | B14: Software | C14: Duo | D14: SVS-E3-DUOF-B | E14: Cisco Support Standard for Duo Fed | F14: 1 | J14: =I14*F14 -> 0
A15: Zero Trust | B15: Software | C15: Duo | D15: E3S-DUO-F-ES | E15: Security EA3.0 - Duo Fed Essentials | F15: 100 | J15: =I15*F15 -> 0
A16: Zero Trust | B16: Software | C16: Identity Services Engine (ISE) | D16: E3S-ISE-PRM | E16: ISE Premier | F16: 500 | J16: =I16*F16 -> 0
A17: Zero Trust | B17: Software | C17: Identity Services Engine (ISE) | D17: SVS-E3S-ISE-B | E17: Cisco Support Standard for ISE | F17: 1 | J17: =I17*F17 -> 0
A18: Cloud and Network Security | B18: Software | C18: Secure Firewall | D18: E3S-SFW-FPR1010T | E18: FPR1010T Threat Defense Threat, Malware,URL | F18: 1 | J18: =I18*F18 -> 0
A19: Cloud and Network Security | B19: Software | C19: Secure Firewall | D19: E3S-SFW-FPR1120T | E19: FPR1120T Threat Defense Threat, Malware,URL | F19: 1 | J19: =I19*F19 -> 0
A20: Cloud and Network Security | B20: Software | C20: Secure Firewall | D20: SVS-E3S-SFW-B | E20: Cisco Support Standard for Cisco Secure Firewall | F20: 1 | J20: =I20*F20 -> 0
A21: Add-on Products | B21: Software | C21: Security Add-ons | D21: E3S-AC-APEX | E21: Secure Client Premier | F21: 330 | J21: =I21*F21 -> 0
A22: Add-on Products | B22: Software | C22: Security Add-ons | D22: SVS-E3S-ADDONS-B | E22: Cisco Support Standard for Security Add-Ons | F22: 1 | J22: =I22*F22 -> 0
A23: Add-ons Services | B23: Services | C23: Services: Security Add-ons | D23: E3-CX-ADD-T2SWE | E23: SVCS Portfolio T2 Secure AddOns SWSSENHCD SW Support - OP | F23: 0 | H23: Support Enhanced | J23: =I23*F23 -> 0
A24: Add-ons Services | B24: Services | C24: Services: Security Add-ons | D24: E3-CX-EAMSC | E24: SVCS Portfolio EA Management Service Cisco | F24: 0 | H24: Support Enhanced | J24: =I24*F24 -> 0
A25: Cloud and Network Security Services | B25: Services | C25: Services: Secure Firewall | D25: E3-CX-SFW-T1TCS | E25: SVCS Portfolio T1 Secure Firewall Solution Support - OP | F25: 0 | H25: Services Tier 1 | J25: =I25*F25 -> 0
A26: Cloud and Network Security Services | B26: Services | C26: Services: Secure Firewall | D26: E3-CX-SFW-T1NT | E26: SVCS Portfolio T1 8x5xNBD Secure Firewall Support | F26: 44 | H26: Services Tier 1 | J26: =I26*F26 -> 0
A27: Cloud and Network Security Services | B27: Services | C27: Services: Secure Firewall | D27: E3-CX-SFW-T1NC | E27: SVCS Portfolio T1 8x7xNCD Secure Firewall Support | F27: 17 | H27: Services Tier 1 | J27: =I27*F27 -> 0
A28: Cloud and Network Security Services | B28: Services | C28: Services: Secure Firewall | D28: E3-CX-EAMSC | E28: SVCS Portfolio EA Management Service Cisco | F28: 0 | H28: Services Tier 1 | J28: =I28*F28 -> 0
A29: Zero Trust Services | B29: Services | C29: Services: Identity Services Engine (ISE) | D29: E3-CX-ISE-T1TCS | E29: SVCS Portfolio T1 ISE Solution Support - OnPrem | F29: 0 | H29: Services Tier 1 | J29: =I29*F29 -> 0
A30: Zero Trust Services | B30: Services | C30: Services: Identity Services Engine (ISE) | D30: E3-CX-EAMSC | E30: SVCS Portfolio EA Management Service Cisco | F30: 0 | H30: Services Tier 1 | J30: =I30*F30 -> 0
A31: Networking Support & Lifecycle Services | B31: Services | C31: Services: Cisco DNA SD-WAN & Routing | D31: E3-CX-ENTWAN-T1NBD | E31: Cisco Support Enhanced 8x5xNBD for ENTWAN | F31: 90 | H31: Support Enhanced | J31: =I31*F31 -> 0
A32: Networking Support & Lifecycle Services | B32: Services | C32: Services: Cisco DNA SD-WAN & Routing | D32: E3-CX-ENTWAN-T14OS | E32: Cisco Support Enhanced 24x7x4 OS for ENTWAN | F32: 23 | H32: Support Enhanced | J32: =I32*F32 -> 0
A33: Networking Support & Lifecycle Services | B33: Services | C33: Services: Cisco DNA Wireless | D33: E3-CX-AIR-T1NBD | E33: Cisco Support Enhanced 8x5xNBD for Wireless | F33: 1 | H33: Support Enhanced | J33: =I33*F33 -> 0
A34: Networking Support & Lifecycle Services | B34: Services | C34: Services: Cisco DNA Wireless | D34: E3-CX-AIR-L1SWPERP | E34: Cisco Support Enhanced Perpetual for Wireless | F34: 4 | H34: Support Enhanced | J34: =I34*F34 -> 0
... A41: Networking Support & Lifecycle Services | B41: Services | C41: Services: Cisco DNA Switching | D41: E3-CX-EAMSC | E41: SVCS Portfolio EA Management Service Cisco | F41: 0 | H41: Support Enhanced | J41: =I41*F41 -> 0
J42: =SUM(J2:J41) -> 0

Sheet USGS
A1: Solution Area | B1: Type | C1: Suite | D1: Part Number | E1: Description | F1: Quantity Desired | G1: License Tiers | H1: Service Tier | I1: Unit Price | J1: Total Price
A2: Cisco Networking | B2: Software | C2: Meraki FedRamp Moderate - Network Infrastructure | D2: E3N-FED-MR-E | E2: Meraki FedRamp MR Essentials Subscription EA 3 LIC | F2: 100 | G2: NA | J2: =I2*F2 -> 0
A3: Cisco Networking | B3: Software | C3: Cisco Networking FedRamp Moderate - Switching | D3: E3N-FED-CS-AC1-L-A | E3: Cisco Switching FedRamp EA 3.0 LIC Access Tier 1 Large | F3: 1 | G3: Advantage | J3: =I3*F3 -> 0
A4: Cisco Networking | B4: Software | C4: Cisco Networking FedRamp Moderate - Switching | D4: E3N-FED-CS-AC1-M-A | E4: Cisco Switching FedRamp EA 3.0 LIC Access Tier 1 Medium | F4: 1 | G4: Advantage | J4: =I4*F4 -> 0
A5: Cisco Networking | B5: Software | C5: Cisco Networking FedRamp Moderate - Switching | D5: E3N-FED-CS-CO-MO-A | E5: Cisco Switching Advantage FedRamp EA 3.0 LIC Core Modular | F5: 1 | G5: Advantage | J5: =I5*F5 -> 0
A6: Cisco Networking | B6: Software | C6: Cisco Networking FedRamp Moderate - Switching | D6: SVS-E3S-CS-GMEAEMB | E6: Cisco Support Standard for Cisco Network Subscription | F6: 1 | G6: NA | J6: =I6*F6 -> 0
A7: Cloud Networking | B7: Software | C7: Nexus Switching | D7: E3N-N9300-XF-A | E7: Nexus 9300 XF 10G or higher (up to 3.6T) | F7: 21 | G7: Advantage | J7: =I7*F7 -> 0
A8: Cloud Networking | B8: Software | C8: Nexus Switching | D8: E3N-DCN-S | E8: Support for Cisco Data Center EA for Data Center Networking | F8: 1 | G8: NA | J8: =I8*F8 -> 0
A9: Cloud Networking | B9: Software | C9: Nexus Switching | D9: E3N-N9300-XF-E | E9: Nexus 9300 XF 10G or higher (up to 3.6T) | F9: 13 | G9: Essential | J9: =I9*F9 -> 0
A10: Cisco DNA Software | B10: Software | C10: Cisco DNA Switching | D10: E3N-C93001-E | E10: C9300 24-Port DNA EA | F10: 18 | G10: Essential | J10: =I10*F10 -> 0
A11: Cisco DNA Software | B11: Software | C11: Cisco DNA Switching | D11: E3N-C95001-E | E11: C9500 High Port (24Q/40X) DNA EA | F11: 2 | G11: Essential | J11: =I11*F11 -> 0
A12: Cisco DNA Software | B12: Software | C12: Cisco DNA Switching | D12: E3N-C93002-E | E12: C9300/C9300X 48-Port DNA EA | F12: 60 | G12: Essential | J12: =I12*F12 -> 0
A13: Cisco DNA Software | B13: Software | C13: Cisco DNA Switching | D13: E3N-AS-S | E13: Cisco Support Standard for EA DNA Switching | F13: 1 | G13: NA | J13: =I13*F13 -> 0
... A16: Cisco DNA Software | B16: Software | C16: Cisco DNA SD-WAN & Routing | D16: E3N-OP-ENTWAN-S | E16: Cisco Support Standard for EA SD-WAN & Routing | F16: 1 | G16: NA | J16: =I16*F16 -> 0
A17: Zero Trust | B17: Software | C17: Duo | D17: SVS-E3-DUOF-B | E17: Cisco Support Standard for Duo Fed | F17: 1 | J17: =I17*F17 -> 0
A18: Zero Trust | B18: Software | C18: Duo | D18: E3S-DUO-F-ES | E18: Security EA3.0 - Duo Fed Essentials | F18: 100 | J18: =I18*F18 -> 0
A19: Zero Trust | B19: Software | C19: Identity Services Engine (ISE) | D19: E3S-ISE-PRM | E19: ISE Premier | F19: 150 | J19: =I19*F19 -> 0
A20: Zero Trust | B20: Software | C20: Identity Services Engine (ISE) | D20: SVS-E3S-ISE-B | E20: Cisco Support Standard for ISE | F20: 1 | J20: =I20*F20 -> 0
A21: Zero Trust | B21: Software | C21: Identity Services Engine (ISE) | D21: E3S-ISE-ADV | E21: ISE Advantage | F21: 200 | J21: =I21*F21 -> 0
A22: Zero Trust Services | B22: Services | C22: Services: Identity Services Engine (ISE) | D22: E3-CX-ISE-ESWP | E22: Cisco Support Enhanced SW Support OP for ISE | F22: 1 | G22: - | J22: =I22*F22 -> 0
A23: Networking Support & Lifecycle Services | B23: Services | C23: Services: Cisco DNA SD-WAN & Routing | D23: E3-CXST-T1SWP | E23: Cisco Support Enhanced SW On-Prem for ENTWAN | F23: 0 | H23: Support Enhanced | J23: =I23*F23 -> 0
A24: Networking Support & Lifecycle Services | B24: Services | C24: Services: Cisco DNA SD-WAN & Routing | D24: E3-CX-ENWAN-L1PERP | E24: Cisco Support Enhanced Perpetual for ENTWAN | F24: 3 | H24: Support Enhanced | J24: =I24*F24 -> 0
A25: Networking Support & Lifecycle Services | B25: Services | C25: Services: Cisco DNA SD-WAN & Routing | D25: E3-CX-ENTWAN-T1NBD | E25: Cisco Support Enhanced 8x5xNBD for ENTWAN | F25: 31 | H25: Support Enhanced | J25: =I25*F25 -> 0
A26: Networking Support & Lifecycle Services | B26: Services | C26: Services: Cisco DNA SD-WAN & Routing | D26: E3-CX-ENTWAN-T1NCD | E26: Cisco Support Enhanced 8x7xNCD for ENTWAN | F26: 82 | H26: Support Enhanced | J26: =I26*F26 -> 0
A27: Networking Support & Lifecycle Services | B27: Services | C27: Services: Cisco DNA SD-WAN & Routing | D27: E3-CX-ENTWAN-T14HR | E27: Cisco Support Enhanced 24x7x4 for ENTWAN | F27: 10 | H27: Support Enhanced | J27: =I27*F27 -> 0
A28: Networking Support & Lifecycle Services | B28: Services | C28: Services: Cisco DNA SD-WAN & Routing | D28: E3-CX-EAMSC | E28: SVCS Portfolio EA Management Service Cisco | F28: 0 | H28: Support Enhanced | J28: =I28*F28 -> 0
A29: Networking Support & Lifecycle Services | B29: Services | C29: Services: Nexus Switching | D29: E3-CX-DCN-T1NCD | E29: Cisco Support Enhanced 8x7xNCD for Nexus Switching | F29: 46 | H29: - | J29: =I29*F29 -> 0
A30: Networking Support & Lifecycle Services | B30: Services | C30: Services: Nexus Switching | D30: E3-CX-DCN-L1SWPERP | E30: Cisco Support Enhanced Perpetual for Nexus Switching | F30: 29 | H30: - | J30: =I30*F30 -> 0
A31: Networking Support & Lifecycle Services | B31: Services | C31: Services: Nexus Switching | D31: E3-CX-DCN-T1NBD | E31: Cisco Support Enhanced 8x5xNBD for Nexus Switching | F31: 707 | H31: - | J31: =I31*F31 -> 0
A32: Networking Support & Lifecycle Services | B32: Services | C32: Services: Cisco DNA Switching | D32: E3-CX-ST-T1NCD | E32: Cisco Support Enhanced 8x7xNCD for Switching | F32: 22 | H32: Support Enhanced | J32: =I32*F32 -> 0
