Workbook

Sheet Table 1 Summary (2)
A1: Contractor Name: | E1: Summary Table
A2: Solicitation Number:
A3: Task Order Number:
A4: Task Order Title:
B5: Base Period:
B6: Option 1:
B7: Option 2:
B8: Option 3:
B9: Option 4:
B10: Option 5:
A12: Contract Value
A13: Description | C13: Total Price Base | D13: Total Price Option 1 | E13: Total Price Option 2 | F13: Total Price Option 3 | G13: Total Price Option 4 | H13: 52.217-8 Extension | I13: Total Price
A14: EQUIPMENT - Multi Energy Portal (MEP)
B15: CLIN 001 MEP | C15: =+'[1]MEP FFP (2)'!F14 -> 0 | I15: =SUM(C15:H15) -> 0
B16: CLIN 101 Command Center | D16: =+'[1]MEP FFP (2)'!#REF! -> #REF!
B17: CLIN 201 Blanking Wall | E17: =+'[1]MEP FFP (2)'!#REF! -> #REF!
B18: CLIN 301 Power Conditioner | F18: =+'[1]MEP FFP (2)'!#REF! -> #REF!
B19: CLIN 401 | G19: =+'[1]MEP FFP (2)'!#REF! -> #REF!
B20: CLIN 501 | H20: =+'[1]MEP FFP (2)'!#REF! -> #REF! | I20: =SUM(C16:H20) -> #REF!
A21: STANDARD LABOR
B22: CLIN 002 Engineering | C22: =+'[1]MEP FFP (2)'!#REF! -> #REF!
B23: CLIN 102 Technical Trade | D23: =+'[1]MEP FFP (2)'!#REF! -> #REF!
B24: CLIN 202 Laborers | E24: =+'[1]MEP FFP (2)'!#REF! -> #REF!
B25: CLIN 302 MEP | F25: =+'[1]MEP FFP (2)'!#REF! -> #REF!
B26: CLIN 402 Architecture | G26: =+'[1]MEP FFP (2)'!#REF! -> #REF!
B27: CLIN 502 Systems Designer | H27: =+'[1]MEP FFP (2)'!#REF! -> #REF! | I27: =SUM(C22:H27) -> #REF!
A28: GENERAL REQUIREMENTS
B29: CLIN 003 Design | C29: =+'[1]MEP FFP (2)'!F73 -> 0
B30: CLIN 103 Civil | D30: =+'[1]MEP FFP (2)'!J73 -> 0
B31: CLIN 203 Site | E31: =+'[1]MEP FFP (2)'!N73 -> 0
B32: CLIN 303 Systems | F32: =+'[1]MEP FFP (2)'!R73 -> 0
B33: CLIN 403 Structure | G33: =+'[1]MEP FFP (2)'!V73 -> 0
B34: CLIN 503 Infrastructure | H34: =+'[1]MEP FFP (2)'!Z73 -> 0 | I34: =SUM(C29:H34) -> 0
A35: TRAINING
B36: CLIN 004 Analyst | C36: ='[1]MEP FFP (2)'!F78 -> 156481
B37: CLIN 104 Training for Trainers | D37: ='[1]MEP FFP (2)'!J78 -> 0
B38: CLIN 204 Operators | E38: ='[1]MEP FFP (2)'!N78 -> 0
B39: CLIN 304 | F39: ='[1]MEP FFP (2)'!R78 -> 0
B40: CLIN 404 | G40: ='[1]MEP FFP (2)'!V78 -> 0
B41: CLIN 504 | H41: ='[1]MEP FFP (2)'!Z78 -> 0 | I41: =SUM(C36:H41) -> 156481
...

Sheet Table 1 Summary
A1: Contractor Name: | E1: Summary Table
A2: Solicitation Number:
A3: Task Order Number:
A4: Task Order Title:
B5: Base Period:
B6: Option 1:
B7: Option 2:
B8: Option 3:
B9: Option 4:
B10: Option 5:
A12: Contract Value
A13: Description | C13: Total Price Base | D13: Total Price Option 1 | E13: Total Price Option 2 | F13: Total Price Option 3 | G13: Total Price Option 4 | H13: 52.217-8 Extension | I13: Total Price
A14: EQUIPMENT - Low Energy Portal (LEP)
B15: CLIN 101 LEP | C15: =+'[1]MEP FFP (2)'!F14 -> 0 | I15: =SUM(C15:H15) -> 0
B16: CLIN 101 Command Center | D16: =+'[1]MEP FFP (2)'!#REF! -> #REF!
B17: CLIN 201 Blanking Wall | E17: =+'[1]MEP FFP (2)'!#REF! -> #REF!
B18: CLIN 301 Power Conditioner | F18: =+'[1]MEP FFP (2)'!#REF! -> #REF!
B19: CLIN 401 | G19: =+'[1]MEP FFP (2)'!#REF! -> #REF!
B20: CLIN 501 | H20: =+'[1]MEP FFP (2)'!#REF! -> #REF! | I20: =SUM(C16:H20) -> #REF!
A21: STANDARD LABOR
B22: CLIN 002 Engineering | C22: =+'[1]MEP FFP (2)'!#REF! -> #REF!
B23: CLIN 102 Technical Trade | D23: =+'[1]MEP FFP (2)'!#REF! -> #REF!
B24: CLIN 202 Laborers | E24: =+'[1]MEP FFP (2)'!#REF! -> #REF!
B25: CLIN 302 Systems Design | F25: =+'[1]MEP FFP (2)'!#REF! -> #REF!
B26: CLIN 402 Architecture | G26: =+'[1]MEP FFP (2)'!#REF! -> #REF!
B27: CLIN 502 MEP | H27: =+'[1]MEP FFP (2)'!#REF! -> #REF! | I27: =SUM(C22:H27) -> #REF!
A28: GENERAL REQUIREMENTS
B29: CLIN 003 Design | C29: =+'[1]MEP FFP (2)'!F73 -> 0
B30: CLIN 103 Civil | D30: =+'[1]MEP FFP (2)'!J73 -> 0
B31: CLIN 203 Site | E31: =+'[1]MEP FFP (2)'!N73 -> 0
B32: CLIN 303 Systems | F32: =+'[1]MEP FFP (2)'!R73 -> 0
B33: CLIN 403 Structure | G33: =+'[1]MEP FFP (2)'!V73 -> 0
B34: CLIN 503 Infrastructure | H34: =+'[1]MEP FFP (2)'!Z73 -> 0 | I34: =SUM(C29:H34) -> 0
A35: TRAINING
B36: CLIN 004 Analyst | C36: ='[1]MEP FFP (2)'!F78 -> 156481
B37: CLIN 104 Training for Trainers | D37: ='[1]MEP FFP (2)'!J78 -> 0
B38: CLIN 204 Operators | E38: ='[1]MEP FFP (2)'!N78 -> 0
B39: CLIN 304 | F39: ='[1]MEP FFP (2)'!R78 -> 0
B40: CLIN 404 | G40: ='[1]MEP FFP (2)'!V78 -> 0
B41: CLIN 504 | H41: ='[1]MEP FFP (2)'!Z78 -> 0 | I41: =SUM(C36:H41) -> 156481
...

Sheet Instructions
A1: Attachment 8 serves as the standardized format for submitting pricing information and associated details for all required Contract Line Item Numbers (CLINs). This ensures uniformity across proposals and facilitates efficient evaluation of submissions. 1. Required Information Contractors must complete the following sections of Attachment 8: a. Pricing Table: Provide detailed pricing for all required CLINs as specified in the solicitation. Ensure that all costs are clearly itemized and align with the scope of work and technical requirements outlined in the Statement of Work (SOW). I. You will notice there are several sub-CLINs under the main CLIN structure. CBP will factor the estimates included in the sub-CLINs into the main CLIN. Vendors will not be limited due to these sub-SLINs, however, the intent is to make sure all aspect of these CLINs are being considered, estimate, and proposed to. If vendors feel some of the sub-CLINs should not be proposed to, then refrain from providing an estimate. If vendors feel like a sub-CLIN is missing from consideration, please add the additional sub-CLIN and provide an estimate. b. Justification Tab: Use this tab to provide a detailed explanation of the proposed pricing. Include any supporting rationale, such as cost breakdowns, market research, or other relevant data that substantiates the proposed costs. c. Assumptions Tab: Clearly outline any assumptions made during the development of the proposal. These may include technical, operational, or logistical considerations that impact pricing or performance. 2. Formatting Requirements All entries in Attachment 8 must be completed electronically using the provided template. Do not alter the structure or format of the pricing table or tabs. If additional information is necessary, include it as supplemental documentation and reference it in the justification tab. Ensure all calculations are accurate and formulas within the pricing table are functional. 3. Submission Guidelines Proposals must be submitted in accordance with the timeline and instructions provided in the solicitation. Ensure Attachment 8 is included as part of the proposal package. Proposals submitted without Attachment 8 completed in full may be deemed non-compliant and excluded from consideration. 5. Evaluation Considerations Proposals will be evaluated based on the accuracy, completeness, and reasonableness of the pricing provided in Attachment 8, as well as the clarity and validity of the justification and assumptions. Contractors are encouraged to provide detailed and transparent information to facilitate the evaluation process. 6. Questions and Clarifications If contractors have questions regarding the use of Attachment 8 or require clarification on any aspect of the pricing table template, they should submit inquiries in writing to the Contracting Officer prior to the proposal submission deadline.

Sheet MEP CLINs
A1: =+'Table 1 Summary'!A1 -> Contractor Name:
A2: =+'Table 1 Summary'!A2 -> Solicitation Number:
A3: =+'Table 1 Summary'!A3 -> Task Order Number:
A4: =+'Table 1 Summary'!A4 -> Task Order Title:
C10: Base Year | G10: Option Year 1 | K10: Option Year 2 | O10: Option Year 3 | S10: Option Year 4
A11: EQUIPMENT - MULTI-ENERGY PORTAL SYSTEM (FFP) | C11: CLIN 001-XX | G11: CLIN 101 | K11: CLIN 201 | O11: CLIN 301 | S11: CLIN 401
A12: Sub-CLIN | B12: Description | C12: Type | D12: Qty | E12: Rate | F12: Amount | G12: Type | H12: Qty | I12: Rate | J12: Amount | K12: Type | L12: Qty | M12: Rate | N12: Amount | O12: Type | P12: Qty | Q12: Rate | R12: Amount | S12: Type | T12: Qty | U12: Rate | V12: Amount | W12: Total
A13: X100 | B13: MEP (less than 5 units) | C13: FFUP | D13: 1 | E13: 0 | F13: =D13*E13 -> 0 | G13: =C13 -> FFUP | H13: 1 | I13: =E13*1.05 -> 0 | J13: =H13*I13 -> 0 | K13: =G13 -> FFUP | L13: 1 | M13: =I13*1.05 -> 0 | N13: =L13*M13 -> 0 | O13: =K13 -> FFUP | P13: 1 | Q13: =M13*1.05 -> 0 | R13: =P13*Q13 -> 0 | S13: =O13 -> FFUP | T13: 1 | U13: =Q13*1.05 -> 0 | V13: =T13*U13 -> 0 | W13: =SUM(V13,R13,N13,J13,F13) -> 0
A14: X101 | B14: MEP (units 5-10) | C14: FFUP | D14: 5 | E14: 0 | F14: =D14*E14 -> 0 | G14: =C14 -> FFUP | H14: 5 | I14: =E14*1.05 -> 0 | J14: =H14*I14 -> 0 | K14: =G14 -> FFUP | L14: 5 | M14: =I14*1.05 -> 0 | N14: =L14*M14 -> 0 | O14: =K14 -> FFUP | P14: 5 | Q14: =M14*1.05 -> 0 | R14: =P14*Q14 -> 0 | S14: =O14 -> FFUP | T14: 5 | U14: =Q14*1.05 -> 0 | V14: =T14*U14 -> 0 | W14: =SUM(V14,R14,N14,J14,F14) -> 0
A15: X102 | B15: MEP (units 11-20) | C15: FFUP | D15: 11 | E15: 0 | F15: =D15*E15 -> 0 | G15: =C15 -> FFUP | H15: 11 | I15: =E15*1.05 -> 0 | J15: =H15*I15 -> 0 | K15: =G15 -> FFUP | L15: 11 | M15: =I15*1.05 -> 0 | N15: =L15*M15 -> 0 | O15: =K15 -> FFUP | P15: 11 | Q15: =M15*1.05 -> 0 | R15: =P15*Q15 -> 0 | S15: =O15 -> FFUP | T15: 11 | U15: =Q15*1.05 -> 0 | V15: =T15*U15 -> 0 | W15: =SUM(V15,R15,N15,J15,F15) -> 0
A16: X103 | B16: MEP (more than 20 units) | C16: FFUP | D16: 21 | E16: 0 | F16: =D16*E16 -> 0 | G16: =C16 -> FFUP | H16: 21 | I16: =E16*1.05 -> 0 | J16: =H16*I16 -> 0 | K16: =G16 -> FFUP | L16: 21 | M16: =I16*1.05 -> 0 | N16: =L16*M16 -> 0 | O16: =K16 -> FFUP | P16: 21 | Q16: =M16*1.05 -> 0 | R16: =P16*Q16 -> 0 | S16: =O16 -> FFUP | T16: 21 | U16: =Q16*1.05 -> 0 | V16: =T16*U16 -> 0 | W16: =SUM(V16,R16,N16,J16,F16) -> 0
A17: X116 | B17: UVBx | C17: FFUP | D17: =D13 -> 1 | E17: 0 | F17: =D17*E17 -> 0 | G17: FFUP | H17: =H13 -> 1 | I17: =E17*1.05 -> 0 | J17: =H17*I17 -> 0 | K17: FFUP | L17: =L13 -> 1 | M17: =I17*1.05 -> 0 | N17: =L17*M17 -> 0 | O17: FFUP | P17: =P13 -> 1 | Q17: =M17*1.05 -> 0 | R17: =P17*Q17 -> 0 | S17: FFUP | T17: =T13 -> 1 | U17: =Q17*1.05 -> 0 | V17: =T17*U17 -> 0 | W17: =SUM(V17,R17,N17,J17,F17) -> 0
B18: Perephiral Sensors
E20: Total Equipment Management | F20: =SUM(F13:F19) -> 0 | I20: Total Equipment Management | J20: =SUM(J13:J19) -> 0 | M20: Total Equipment Management | N20: =SUM(N13:N19) -> 0 | Q20: Total Equipment Management | R20: =SUM(R13:R19) -> 0 | U20: Total Equipment Management | V20: =SUM(V13:V19) -> 0 | W20: =SUM(V20,R20,N20,J20,F20) -> 0
C22: Base Year | G22: Option Year 1 | K22: Option Year 2 | O22: Option Year 3 | S22: Option Year 4
A23: SITE DESIGN (FFP) | C23: CLIN 002 | G23: CLIN 102 | K23: CLIN 202 | O23: CLIN 302 | S23: CLIN 402
A24: Sub-CLIN | B24: Description | C24: Type | D24: Qty | E24: Rate | F24: Amount | G24: Type | H24: Qty | I24: Rate | J24: Amount | K24: Type | L24: Qty | M24: Rate | N24: Amount | O24: Type | P24: Qty | Q24: Rate | R24: Amount | S24: Type | T24: Qty | U24: Rate | V24: Amount | W24: Total
A25: X200 | B25: Program Management and Operations Labor- Fully Burdened | C25: T&M | D25: 1 | F25: =D25*E25 -> 0 | G25: =C25 -> T&M | H25: 1 | I25: =E25*1.05 -> 0 | J25: =H25*I25 -> 0 | K25: =G25 -> T&M | L25: 1 | M25: =I25*1.05 -> 0 | N25: =L25*M25 -> 0 | O25: =K25 -> T&M | P25: 1 | Q25: =M25*1.05 -> 0 | R25: =P25*Q25 -> 0 | S25: =O25 -> T&M | T25: 1 | U25: =Q25*1.05 -> 0 | V25: =T25*U25 -> 0 | W25: =SUM(V25,R25,N25,J25,F25) -> 0
A26: X201 | B26: Travel | C26: Cost reimbursable | D26: 1 | F26: =D26*E26 -> 0 | G26: =C26 -> Cost reimbursable | H26: 1 | I26: =E26*1.05 -> 0 | J26: =H26*I26 -> 0 | K26: =G26 -> Cost reimbursable | L26: 1 | M26: =I26*1.05 -> 0 | N26: =L26*M26 -> 0 | O26: =K26 -> Cost reimbursable | P26: 1 | Q26: =M26*1.05 -> 0 | R26: =P26*Q26 -> 0 | S26: =O26 -> Cost reimbursable | T26: 1 | U26: =Q26*1.05 -> 0 | V26: =T26*U26 -> 0 | W26: =SUM(V26,R26,N26,J26,F26) -> 0
A27: X202 | B27: Site Design | C27: FFP | D27: 1 | F27: =D27*E27 -> 0 | G27: =C27 -> FFP | H27: 1 | I27: =E27*1.05 -> 0 | J27: =H27*I27 -> 0 | K27: =G27 -> FFP | L27: 1 | M27: =I27*1.05 -> 0 | N27: =L27*M27 -> 0 | O27: =K27 -> FFP | P27: 1 | Q27: =M27*1.05 -> 0 | R27: =P27*Q27 -> 0 | S27: =O27 -> FFP | T27: 1 | U27: =Q27*1.05 -> 0 | V27: =T27*U27 -> 0 | W27: =SUM(V27,R27,N27,J27,F27) -> 0
A28: X203 | B28: Concept Review
A29: X204 | B29: 50% Design
A30: X205 | B30: 95% Design
A31: X206 | B31: Issued for Construction Drawings
E32: Total Site Design | F32: =SUM(F27:F31) -> 0 | I32: Total Site Design | J32: =SUM(J21:J31) -> 0 | M32: Total Site Design | N32: =SUM(N21:N31) -> 0 | Q32: Total Site Design | R32: =SUM(R21:R31) -> 0 | U32: Total Site Design | V32: =SUM(V21:V31) -> 0 | W32: =SUM(V32,R32,N32,J32,F32) -> 0
C34: Base Year | G34: Option Year 1 | K34: Option Year 2 | O34: Option Year 3 | S34: Option Year 4
A35: CIVIL WORKS (T&M) | C35: CLIN 003 | G35: CLIN 103 | K35: CLIN 203 | O35: CLIN 303 | S35: CLIN 403
A36: Sub - CLIN | B36: Description | C36: Type | D36: Qty | E36: Rate | F36: Amount | G36: Type | H36: Qty | I36: Rate | J36: Amount | K36: Type | L36: Qty | M36: Rate | N36: Amount | O36: Type | P36: Qty | Q36: Rate | R36: Amount | S36: Type | T36: Qty | U36: Rate | V36: Amount | W36: Total
A37: X300 | B37: Mobilization and Site Preparations, Securing the site, Demobilization | C37: T&M | D37: 1 | F37: =ROUND(D37*E37,2) -> 0 | G37: T&M | H37: 1 | I37: =E37*1.05 -> 0 | J37: =ROUND(H37*I37,2) -> 0 | K37: T&M | L37: 1 | M37: =I37*1.05 -> 0 | N37: =ROUND(L37*M37,2) -> 0 | O37: T&M | P37: 1 | Q37: =M37*1.05 -> 0 | R37: =ROUND(P37*Q37,2) -> 0 | S37: T&M | T37: 1 | U37: =Q37*1.05 -> 0 | V37: =ROUND(T37*U37,2) -> 0 | W37: =SUM(V37,R37,N37,J37,F37) -> 0
A38: X301 | B38: Command Center-New Construction | C38: T&M | D38: 1 | F38: =ROUND(D38*E38,2) -> 0 | G38: T&M | H38: 1 | I38: =E38*1.05 -> 0 | J38: =ROUND(H38*I38,2) -> 0 | K38: T&M | L38: 1 | M38: =I38*1.05 -> 0 | N38: =ROUND(L38*M38,2) -> 0 | O38: T&M | P38: 1 | Q38: =M38*1.05 -> 0 | R38: =ROUND(P38*Q38,2) -> 0 | S38: T&M | T38: 1 | U38: =Q38*1.05 -> 0 | V38: =ROUND(T38*U38,2) -> 0 | W38: =SUM(V38,R38,N38,J38,F38) -> 0
A39: X302 | B39: Command Center-Retrofit | C39: T&M | D39: 1 | F39: =ROUND(D39*E39,2) -> 0 | G39: T&M | H39: 1 | I39: =E39*1.05 -> 0 | J39: =ROUND(H39*I39,2) -> 0 | K39: T&M | L39: 1 | M39: =I39*1.05 -> 0 | N39: =ROUND(L39*M39,2) -> 0 | O39: T&M | P39: 1 | Q39: =M39*1.05 -> 0 | R39: =ROUND(P39*Q39,2) -> 0 | S39: T&M | T39: 1 | U39: =Q39*1.05 -> 0 | V39: =ROUND(T39*U39,2) -> 0 | W39: =SUM(V39,R39,N39,J39,F39) -> 0
A40: X303 | B40: Demolition/Excavation/Removal/Saw Cut | C40: T&M | D40: 1 | F40: =ROUND(D40*E40,2) -> 0 | G40: T&M | H40: 1 | I40: =E40*1.05 -> 0 | J40: =ROUND(H40*I40,2) -> 0 | K40: T&M | L40: 1 | M40: =I40*1.05 -> 0 | N40: =ROUND(L40*M40,2) -> 0 | O40: T&M | P40: 1 | Q40: =M40*1.05 -> 0 | R40: =ROUND(P40*Q40,2) -> 0 | S40: T&M | T40: 1 | U40: =Q40*1.05 -> 0 | V40: =ROUND(T40*U40,2) -> 0 | W40: =SUM(V40,R40,N40,J40,F40) -> 0
A41: X304 | B41: Clearing/Grubbing, Dirt Work (balancing cut/fill), Compaction, Drainage | C41: T&M | D41: 1 | F41: =ROUND(D41*E41,2) -> 0 | G41: T&M | H41: 1 | I41: =E41*1.05 -> 0 | J41: =ROUND(H41*I41,2) -> 0 | K41: T&M | L41: 1 | M41: =I41*1.05 -> 0 | N41: =ROUND(L41*M41,2) -> 0 | O41: T&M | P41: 1 | Q41: =M41*1.05 -> 0 | R41: =ROUND(P41*Q41,2) -> 0 | S41: T&M | T41: 1 | U41: =Q41*1.05 -> 0 | V41: =ROUND(T41*U41,2) -> 0 | W41: =SUM(V41,R41,N41,J41,F41) -> 0
A42: X305 | B42: Electrical/Plumbing/Mechanical | C42: T&M | D42: 1 | F42: =ROUND(D42*E42,2) -> 0 | G42: T&M | H42: 1 | I42: =E42*1.05 -> 0 | J42: =ROUND(H42*I42,2) -> 0 | K42: T&M | L42: 1 | M42: =I42*1.05 -> 0 | N42: =ROUND(L42*M42,2) -> 0 | O42: T&M | P42: 1 | Q42: =M42*1.05 -> 0 | R42: =ROUND(P42*Q42,2) -> 0 | S42: T&M | T42: 1 | U42: =Q42*1.05 -> 0 | V42: =ROUND(T42*U42,2) -> 0 | W42: =SUM(V42,R42,N42,J42,F42) -> 0
A43: X306 | B43: Concrete/Asphalt/Footers/Foundations/Lanes of Traffic | C43: T&M | D43: 1 | F43: =ROUND(D43*E43,2) -> 0 | G43: T&M | H43: 1 | I43: =E43*1.05 -> 0 | J43: =ROUND(H43*I43,2) -> 0 | K43: T&M | L43: 1 | M43: =I43*1.05 -> 0 | N43: =ROUND(L43*M43,2) -> 0 | O43: T&M | P43: 1 | Q43: =M43*1.05 -> 0 | R43: =ROUND(P43*Q43,2) -> 0 | S43: T&M | T43: 1 | U43: =Q43*1.05 -> 0 | V43: =ROUND(T43*U43,2) -> 0 | W43: =SUM(V43,R43,N43,J43,F43) -> 0
A44: X307 | B44: Steel Work | C44: T&M | D44: 1 | F44: =ROUND(D44*E44,2) -> 0 | G44: T&M | H44: 1 | I44: =E44*1.05 -> 0 | J44: =ROUND(H44*I44,2) -> 0 | K44: T&M | L44: 1 | M44: =I44*1.05 -> 0 | N44: =ROUND(L44*M44,2) -> 0 | O44: T&M | P44: 1 | Q44: =M44*1.05 -> 0 | R44: =ROUND(P44*Q44,2) -> 0 | S44: T&M | T44: 1 | U44: =Q44*1.05 -> 0 | V44: =ROUND(T44*U44,2) -> 0 | W44: =SUM(V44,R44,N44,J44,F44) -> 0
A45: X308 | B45: Traffic Control Measures, Jersey Barriers, Speed bumps, striping, signage | C45: T&M | D45: 1 | F45: =ROUND(D45*E45,2) -> 0 | G45: T&M | H45: 1 | I45: =E45*1.05 -> 0 | J45: =ROUND(H45*I45,2) -> 0 | K45: T&M | L45: 1 | M45: =I45*1.05 -> 0 | N45: =ROUND(L45*M45,2) -> 0 | O45: T&M | P45: 1 | Q45: =M45*1.05 -> 0 | R45: =ROUND(P45*Q45,2) -> 0 | S45: T&M | T45: 1 | U45: =Q45*1.05 -> 0 | V45: =ROUND(T45*U45,2) -> 0 | W45: =SUM(V45,R45,N45,J45,F45) -> 0
A46: X309 | B46: IT Trenches, Conduit, Conduit Banks, Junction Boxes, Pull Strings | C46: T&M | D46: 1 | F46: =ROUND(D46*E46,2) -> 0 | G46: T&M | H46: 1 | I46: =E46*1.05 -> 0 | J46: =ROUND(H46*I46,2) -> 0 | K46: T&M | L46: 1 | M46: =I46*1.05 -> 0 | N46: =ROUND(L46*M46,2) -> 0 | O46: T&M | P46: 1 | Q46: =M46*1.05 -> 0 | R46: =ROUND(P46*Q46,2) -> 0 | S46: T&M | T46: 1 | U46: =Q46*1.05 -> 0 | V46: =ROUND(T46*U46,2) -> 0 | W46: =SUM(V46,R46,N46,J46,F46) -> 0
A47: X310 | B47: Site Survey | C47: T&M | D47: 1 | F47: =ROUND(D47*E47,2) -> 0 | G47: T&M | H47: 1 | I47: =E47*1.05 -> 0 | J47: =ROUND(H47*I47,2) -> 0 | K47: T&M | L47: 1 | M47: =I47*1.05 -> 0 | N47: =ROUND(L47*M47,2) -> 0 | O47: T&M | P47: 1 | Q47: =M47*1.05 -> 0 | R47: =ROUND(P47*Q47,2) -> 0 | S47: T&M | T47: 1 | U47: =Q47*1.05 -> 0 | V47: =ROUND(T47*U47,2) -> 0 | W47: =SUM(V47,R47,N47,J47,F47) -> 0
A48: X311 | B48: SWPPP, Permitting | C48: T&M | D48: 1 | F48: =ROUND(D48*E48,2) -> 0 | G48: T&M | H48: 1 | I48: =E48*1.05 -> 0 | J48: =ROUND(H48*I48,2) -> 0 | K48: T&M | L48: 1 | M48: =I48*1.05 -> 0 | N48: =ROUND(L48*M48,2) -> 0 | O48: T&M | P48: 1 | Q48: =M48*1.05 -> 0 | R48: =ROUND(P48*Q48,2) -> 0 | S48: T&M | T48: 1 | U48: =Q48*1.05 -> 0 | V48: =ROUND(T48*U48,2) -> 0 | W48: =SUM(V48,R48,N48,J48,F48) -> 0
...

Sheet LEP CLINs
A1: =+'Table 1 Summary'!A1 -> Contractor Name:
A2: =+'Table 1 Summary'!A2 -> Solicitation Number:
A3: =+'Table 1 Summary'!A3 -> Task Order Number:
A4: =+'Table 1 Summary'!A4 -> Task Order Title:
C10: Base Year | G10: Option Year 1 | K10: Option Year 2 | O10: Option Year 3 | S10: Option Year 4
A11: EQUIPMENT - LOW ENERGY PORTAL SYSTEM (FFP) | C11: CLIN 001 | G11: CLIN 101 | K11: CLIN 201 | O11: CLIN 301 | S11: CLIN 401
A12: Sub-CLIN | B12: Description | C12: Type | D12: Qty | E12: Rate | F12: Amount | G12: Type | H12: Qty | I12: Rate | J12: Amount | K12: Type | L12: Qty | M12: Rate | N12: Amount | O12: Type | P12: Qty | Q12: Rate | R12: Amount | S12: Type | T12: Qty | U12: Rate | V12: Amount | W12: Total
A13: X104 | B13: LEP-Type 1 (less than 5 units) | C13: FFUP | D13: 1 | E13: 0 | F13: =D13*E13 -> 0 | G13: =C13 -> FFUP | H13: 1 | I13: =E13*1.05 -> 0 | J13: =H13*I13 -> 0 | K13: =G13 -> FFUP | L13: 1 | M13: =I13*1.05 -> 0 | N13: =L13*M13 -> 0 | O13: =K13 -> FFUP | P13: 1 | Q13: =M13*1.05 -> 0 | R13: =P13*Q13 -> 0 | S13: =O13 -> FFUP | T13: 1 | U13: =Q13*1.05 -> 0 | V13: =T13*U13 -> 0 | W13: =SUM(V13,R13,N13,J13,F13) -> 0
A14: X105 | B14: LEP-Type 1 (units 5-10) | C14: FFUP | D14: 5 | E14: 0 | F14: =D14*E14 -> 0 | G14: =C14 -> FFUP | H14: 5 | I14: =E14*1.05 -> 0 | J14: =H14*I14 -> 0 | K14: =G14 -> FFUP | L14: 5 | M14: =I14*1.05 -> 0 | N14: =L14*M14 -> 0 | O14: =K14 -> FFUP | P14: 5 | Q14: =M14*1.05 -> 0 | R14: =P14*Q14 -> 0 | S14: =O14 -> FFUP | T14: 5 | U14: =Q14*1.05 -> 0 | V14: =T14*U14 -> 0 | W14: =SUM(V14,R14,N14,J14,F14) -> 0
A15: X106 | B15: LEP-Type 1 (units 11-20) | C15: FFUP | D15: 11 | E15: 0 | F15: =D15*E15 -> 0 | G15: =C15 -> FFUP | H15: 11 | I15: =E15*1.05 -> 0 | J15: =H15*I15 -> 0 | K15: =G15 -> FFUP | L15: 11 | M15: =I15*1.05 -> 0 | N15: =L15*M15 -> 0 | O15: =K15 -> FFUP | P15: 11 | Q15: =M15*1.05 -> 0 | R15: =P15*Q15 -> 0 | S15: =O15 -> FFUP | T15: 11 | U15: =Q15*1.05 -> 0 | V15: =T15*U15 -> 0 | W15: =SUM(V15,R15,N15,J15,F15) -> 0
A16: X107 | B16: LEP-Type 1 (more than 20 units) | C16: FFUP | D16: 21 | E16: 0 | F16: =D16*E16 -> 0 | G16: =C16 -> FFUP | H16: 21 | I16: =E16*1.05 -> 0 | J16: =H16*I16 -> 0 | K16: =G16 -> FFUP | L16: 21 | M16: =I16*1.05 -> 0 | N16: =L16*M16 -> 0 | O16: =K16 -> FFUP | P16: 21 | Q16: =M16*1.05 -> 0 | R16: =P16*Q16 -> 0 | S16: =O16 -> FFUP | T16: 21 | U16: =Q16*1.05 -> 0 | V16: =T16*U16 -> 0 | W16: =SUM(V16,R16,N16,J16,F16) -> 0
A17: X108 | B17: LEP-Type 2 (less than 5 units) | C17: FFUP | D17: 1 | E17: 0 | F17: =D17*E17 -> 0 | G17: =C17 -> FFUP | H17: 1 | I17: =E17*1.05 -> 0 | J17: =H17*I17 -> 0 | K17: =G17 -> FFUP | L17: 1 | M17: =I17*1.05 -> 0 | N17: =L17*M17 -> 0 | O17: =K17 -> FFUP | P17: 1 | Q17: =M17*1.05 -> 0 | R17: =P17*Q17 -> 0 | S17: =O17 -> FFUP | T17: 1 | U17: =Q17*1.05 -> 0 | V17: =T17*U17 -> 0 | W17: =SUM(V17,R17,N17,J17,F17) -> 0
A18: X109 | B18: LEP-Type 2 (units 5-10) | C18: FFUP | D18: 5 | E18: 0 | F18: =D18*E18 -> 0 | G18: =C18 -> FFUP | H18: 5 | I18: =E18*1.05 -> 0 | J18: =H18*I18 -> 0 | K18: =G18 -> FFUP | L18: 5 | M18: =I18*1.05 -> 0 | N18: =L18*M18 -> 0 | O18: =K18 -> FFUP | P18: 5 | Q18: =M18*1.05 -> 0 | R18: =P18*Q18 -> 0 | S18: =O18 -> FFUP | T18: 5 | U18: =Q18*1.05 -> 0 | V18: =T18*U18 -> 0 | W18: =SUM(V18,R18,N18,J18,F18) -> 0
A19: X110 | B19: LEP-Type 2 (units 11-20) | C19: FFUP | D19: 11 | E19: 0 | F19: =D19*E19 -> 0 | G19: =C19 -> FFUP | H19: 11 | I19: =E19*1.05 -> 0 | J19: =H19*I19 -> 0 | K19: =G19 -> FFUP | L19: 11 | M19: =I19*1.05 -> 0 | N19: =L19*M19 -> 0 | O19: =K19 -> FFUP | P19: 11 | Q19: =M19*1.05 -> 0 | R19: =P19*Q19 -> 0 | S19: =O19 -> FFUP | T19: 11 | U19: =Q19*1.05 -> 0 | V19: =T19*U19 -> 0 | W19: =SUM(V19,R19,N19,J19,F19) -> 0
A20: X111 | B20: LEP-Type 2 (more than 20 units) | C20: FFUP | D20: 21 | E20: 0 | F20: =D20*E20 -> 0 | G20: =C20 -> FFUP | H20: 21 | I20: =E20*1.05 -> 0 | J20: =H20*I20 -> 0 | K20: =G20 -> FFUP | L20: 21 | M20: =I20*1.05 -> 0 | N20: =L20*M20 -> 0 | O20: =K20 -> FFUP | P20: 21 | Q20: =M20*1.05 -> 0 | R20: =P20*Q20 -> 0 | S20: =O20 -> FFUP | T20: 21 | U20: =Q20*1.05 -> 0 | V20: =T20*U20 -> 0 | W20: =SUM(V20,R20,N20,J20,F20) -> 0
A21: X112 | B21: LEP-Type 3 (less than 5 units) | C21: FFUP | D21: 1 | E21: 0 | F21: =D21*E21 -> 0 | G21: =C21 -> FFUP | H21: 1 | I21: =E21*1.05 -> 0 | J21: =H21*I21 -> 0 | K21: =G21 -> FFUP | L21: 1 | M21: =I21*1.05 -> 0 | N21: =L21*M21 -> 0 | O21: =K21 -> FFUP | P21: 1 | Q21: =M21*1.05 -> 0 | R21: =P21*Q21 -> 0 | S21: =O21 -> FFUP | T21: 1 | U21: =Q21*1.05 -> 0 | V21: =T21*U21 -> 0 | W21: =SUM(V21,R21,N21,J21,F21) -> 0
A22: X113 | B22: LEP-Type 3 (units 5-10) | C22: FFUP | D22: 5 | E22: 0 | F22: =D22*E22 -> 0 | G22: =C22 -> FFUP | H22: 5 | I22: =E22*1.05 -> 0 | J22: =H22*I22 -> 0 | K22: =G22 -> FFUP | L22: 5 | M22: =I22*1.05 -> 0 | N22: =L22*M22 -> 0 | O22: =K22 -> FFUP | P22: 5 | Q22: =M22*1.05 -> 0 | R22: =P22*Q22 -> 0 | S22: =O22 -> FFUP | T22: 5 | U22: =Q22*1.05 -> 0 | V22: =T22*U22 -> 0 | W22: =SUM(V22,R22,N22,J22,F22) -> 0
A23: X114 | B23: LEP-Type 3 (units 11-20) | C23: FFUP | D23: 11 | E23: 0 | F23: =D23*E23 -> 0 | G23: =C23 -> FFUP | H23: 11 | I23: =E23*1.05 -> 0 | J23: =H23*I23 -> 0 | K23: =G23 -> FFUP | L23: 11 | M23: =I23*1.05 -> 0 | N23: =L23*M23 -> 0 | O23: =K23 -> FFUP | P23: 11 | Q23: =M23*1.05 -> 0 | R23: =P23*Q23 -> 0 | S23: =O23 -> FFUP | T23: 11 | U23: =Q23*1.05 -> 0 | V23: =T23*U23 -> 0 | W23: =SUM(V23,R23,N23,J23,F23) -> 0
A24: X115 | B24: LEP-Type 3 (more than 20 units) | C24: FFUP | D24: 21 | E24: 0 | F24: =D24*E24 -> 0 | G24: =C24 -> FFUP | H24: 21 | I24: =E24*1.05 -> 0 | J24: =H24*I24 -> 0 | K24: =G24 -> FFUP | L24: 21 | M24: =I24*1.05 -> 0 | N24: =L24*M24 -> 0 | O24: =K24 -> FFUP | P24: 21 | Q24: =M24*1.05 -> 0 | R24: =P24*Q24 -> 0 | S24: =O24 -> FFUP | T24: 21 | U24: =Q24*1.05 -> 0 | V24: =T24*U24 -> 0 | W24: =SUM(V24,R24,N24,J24,F24) -> 0
A25: X116 | B25: UVBx | C25: FFUP | D25: 1 | E25: 0 | F25: =D25*E25 -> 0 | G25: =C25 -> FFUP | H25: 1 | I25: =E25*1.05 -> 0 | J25: =H25*I25 -> 0 | K25: =G25 -> FFUP | L25: 1 | M25: =I25*1.05 -> 0 | N25: =L25*M25 -> 0 | O25: =K25 -> FFUP | P25: 1 | Q25: =M25*1.05 -> 0 | R25: =P25*Q25 -> 0 | S25: =O25 -> FFUP | T25: 1 | U25: =Q25*1.05 -> 0 | V25: =T25*U25 -> 0 | W25: =SUM(V25,R25,N25,J25,F25) -> 0
E27: Total Equipment Management | F27: =SUM(F13:F26) -> 0 | I27: Total Equipment Management | J27: =SUM(J13:J26) -> 0 | M27: Total Equipment Management | N27: =SUM(N13:N26) -> 0 | Q27: Total Equipment Management | R27: =SUM(R13:R26) -> 0 | U27: Total Equipment Management | V27: =SUM(V13:V26) -> 0 | W27: =SUM(V27,R27,N27,J27,F27) -> 0
C29: Base Year | G29: Option Year 1 | K29: Option Year 2 | O29: Option Year 3 | S29: Option Year 4
A30: SITE DESIGN (FFP) | C30: CLIN 002 | G30: CLIN 102 | K30: CLIN 202 | O30: CLIN 302 | S30: CLIN 402
A31: Sub-CLIN | B31: Description | C31: Type | D31: Qty | E31: Rate | F31: Amount | G31: Type | H31: Qty | I31: Rate | J31: Amount | K31: Type | L31: Qty | M31: Rate | N31: Amount | O31: Type | P31: Qty | Q31: Rate | R31: Amount | S31: Type | T31: Qty | U31: Rate | V31: Amount | W31: Total
A32: X200 | B32: Program Management and Operations Labor- Fully Burdened | C32: T&M | D32: 1 | E32: 0 | F32: =D32*E32 -> 0 | G32: T&M | H32: 1 | I32: =E32*1.05 -> 0 | J32: =H32*I32 -> 0 | K32: T&M | L32: 1 | M32: =I32*1.05 -> 0 | N32: =L32*M32 -> 0 | O32: T&M | P32: 1 | Q32: =M32*1.05 -> 0 | R32: =P32*Q32 -> 0 | S32: T&M | T32: 1 | U32: =Q32*1.05 -> 0 | V32: =T32*U32 -> 0 | W32: =SUM(V32,R32,N32,J32,F32) -> 0
A33: X201 | B33: Travel | C33: Cost reimbursable | D33: 1 | E33: 0 | F33: =D33*E33 -> 0 | G33: Cost reimbursable | H33: 1 | I33: =E33*1.05 -> 0 | J33: =H33*I33 -> 0 | K33: Cost reimbursable | L33: 1 | M33: =I33*1.05 -> 0 | N33: =L33*M33 -> 0 | O33: Cost reimbursable | P33: 1 | Q33: =M33*1.05 -> 0 | R33: =P33*Q33 -> 0 | S33: Cost reimbursable | T33: 1 | U33: =Q33*1.05 -> 0 | V33: =T33*U33 -> 0 | W33: =SUM(V33,R33,N33,J33,F33) -> 0
A34: X202 | B34: Site Design | C34: FFP | D34: 1 | E34: 0 | F34: =D34*E34 -> 0 | G34: FFP | H34: 1 | I34: =E34*1.05 -> 0 | J34: =H34*I34 -> 0 | K34: FFP | L34: 1 | M34: =I34*1.05 -> 0 | N34: =L34*M34 -> 0 | O34: FFP | P34: 1 | Q34: =M34*1.05 -> 0 | R34: =P34*Q34 -> 0 | S34: FFP | T34: 1 | U34: =Q34*1.05 -> 0 | V34: =T34*U34 -> 0 | W34: =SUM(V34,R34,N34,J34,F34) -> 0
A35: X203 | B35: Concept Review | C35: FFP | D35: 1 | E35: 0 | F35: =D35*E35 -> 0 | G35: FFP | H35: 1 | I35: =E35*1.05 -> 0 | J35: =H35*I35 -> 0 | K35: FFP | L35: 1 | M35: =I35*1.05 -> 0 | N35: =L35*M35 -> 0 | O35: FFP | P35: 1 | Q35: =M35*1.05 -> 0 | R35: =P35*Q35 -> 0 | S35: FFP | T35: 1 | U35: =Q35*1.05 -> 0 | V35: =T35*U35 -> 0 | W35: =SUM(V35,R35,N35,J35,F35) -> 0
A36: X204 | B36: 50% Design | C36: FFP | D36: 1 | E36: 0 | F36: =D36*E36 -> 0 | G36: FFP | H36: 1 | I36: =E36*1.05 -> 0 | J36: =H36*I36 -> 0 | K36: FFP | L36: 1 | M36: =I36*1.05 -> 0 | N36: =L36*M36 -> 0 | O36: FFP | P36: 1 | Q36: =M36*1.05 -> 0 | R36: =P36*Q36 -> 0 | S36: FFP | T36: 1 | U36: =Q36*1.05 -> 0 | V36: =T36*U36 -> 0 | W36: =SUM(V36,R36,N36,J36,F36) -> 0
A37: X205 | B37: 95% Design | C37: FFP | D37: 1 | E37: 0 | F37: =D37*E37 -> 0 | G37: FFP | H37: 1 | I37: =E37*1.05 -> 0 | J37: =H37*I37 -> 0 | K37: FFP | L37: 1 | M37: =I37*1.05 -> 0 | N37: =L37*M37 -> 0 | O37: FFP | P37: 1 | Q37: =M37*1.05 -> 0 | R37: =P37*Q37 -> 0 | S37: FFP | T37: 1 | U37: =Q37*1.05 -> 0 | V37: =T37*U37 -> 0 | W37: =SUM(V37,R37,N37,J37,F37) -> 0
A38: X206 | B38: Issued for Construction Drawings | C38: FFP | D38: 1 | E38: 0 | F38: =D38*E38 -> 0 | G38: FFP | H38: 1 | I38: =E38*1.05 -> 0 | J38: =H38*I38 -> 0 | K38: FFP | L38: 1 | M38: =I38*1.05 -> 0 | N38: =L38*M38 -> 0 | O38: FFP | P38: 1 | Q38: =M38*1.05 -> 0 | R38: =P38*Q38 -> 0 | S38: FFP | T38: 1 | U38: =Q38*1.05 -> 0 | V38: =T38*U38 -> 0 | W38: =SUM(V38,R38,N38,J38,F38) -> 0
E39: Total Site Design | F39: =SUM(F34:F38) -> 0 | I39: Total Site Design | J39: =SUM(J28:J38) -> 0 | M39: Total Site Design | N39: =SUM(N28:N38) -> 0 | Q39: Total Site Design | R39: =SUM(R28:R38) -> 0 | U39: Total Site Design | V39: =SUM(V28:V38) -> 0 | W39: =SUM(V39,R39,N39,J39,F39) -> 0
C41: Base Year | G41: Option Year 1 | K41: Option Year 2 | O41: Option Year 3 | S41: Option Year 4
A42: CIVIL WORKS (T&M) | C42: CLIN 003 | G42: CLIN 103 | K42: CLIN 203 | O42: CLIN 303 | S42: CLIN 403
A43: Sub - CLIN | B43: Description | C43: Type | D43: Qty | E43: Rate | F43: Amount | G43: Type | H43: Qty | I43: Rate | J43: Amount | K43: Type | L43: Qty | M43: Rate | N43: Amount | O43: Type | P43: Qty | Q43: Rate | R43: Amount | S43: Type | T43: Qty | U43: Rate | V43: Amount | W43: Total
A44: X300 | B44: Mobilization and Site Preparations, Securing the site, Demobilization | C44: T&M | D44: 1 | E44: 0 | F44: =ROUND(D44*E44,2) -> 0 | G44: T&M | H44: 1 | I44: =E44*1.05 -> 0 | J44: =ROUND(H44*I44,2) -> 0 | K44: T&M | L44: 1 | M44: =I44*1.05 -> 0 | N44: =ROUND(L44*M44,2) -> 0 | O44: T&M | P44: 1 | Q44: =M44*1.05 -> 0 | R44: =ROUND(P44*Q44,2) -> 0 | S44: T&M | T44: 1 | U44: =Q44*1.05 -> 0 | V44: =ROUND(T44*U44,2) -> 0 | W44: =SUM(V44,R44,N44,J44,F44) -> 0
A45: X301 | B45: Command Center-New Construction | C45: T&M | D45: 1 | E45: 0 | F45: =ROUND(D45*E45,2) -> 0 | G45: T&M | H45: 1 | I45: =E45*1.05 -> 0 | J45: =ROUND(H45*I45,2) -> 0 | K45: T&M | L45: 1 | M45: =I45*1.05 -> 0 | N45: =ROUND(L45*M45,2) -> 0 | O45: T&M | P45: 1 | Q45: =M45*1.05 -> 0 | R45: =ROUND(P45*Q45,2) -> 0 | S45: T&M | T45: 1 | U45: =Q45*1.05 -> 0 | V45: =ROUND(T45*U45,2) -> 0 | W45: =SUM(V45,R45,N45,J45,F45) -> 0
A46: X302 | B46: Command Center-Retrofit | C46: T&M | D46: 1 | E46: 0 | F46: =ROUND(D46*E46,2) -> 0 | G46: T&M | H46: 1 | I46: =E46*1.05 -> 0 | J46: =ROUND(H46*I46,2) -> 0 | K46: T&M | L46: 1 | M46: =I46*1.05 -> 0 | N46: =ROUND(L46*M46,2) -> 0 | O46: T&M | P46: 1 | Q46: =M46*1.05 -> 0 | R46: =ROUND(P46*Q46,2) -> 0 | S46: T&M | T46: 1 | U46: =Q46*1.05 -> 0 | V46: =ROUND(T46*U46,2) -> 0 | W46: =SUM(V46,R46,N46,J46,F46) -> 0
A47: X303 | B47: Demolition/Excavation/Removal/Saw Cut | C47: T&M | D47: 1 | E47: 0 | F47: =ROUND(D47*E47,2) -> 0 | G47: T&M | H47: 1 | I47: =E47*1.05 -> 0 | J47: =ROUND(H47*I47,2) -> 0 | K47: T&M | L47: 1 | M47: =I47*1.05 -> 0 | N47: =ROUND(L47*M47,2) -> 0 | O47: T&M | P47: 1 | Q47: =M47*1.05 -> 0 | R47: =ROUND(P47*Q47,2) -> 0 | S47: T&M | T47: 1 | U47: =Q47*1.05 -> 0 | V47: =ROUND(T47*U47,2) -> 0 | W47: =SUM(V47,R47,N47,J47,F47) -> 0
A48: X304 | B48: Clearing/Grubing, Dirt Work (balancing cut/fill), Compaction, Drainage | C48: T&M | D48: 1 | E48: 0 | F48: =ROUND(D48*E48,2) -> 0 | G48: T&M | H48: 1 | I48: =E48*1.05 -> 0 | J48: =ROUND(H48*I48,2) -> 0 | K48: T&M | L48: 1 | M48: =I48*1.05 -> 0 | N48: =ROUND(L48*M48,2) -> 0 | O48: T&M | P48: 1 | Q48: =M48*1.05 -> 0 | R48: =ROUND(P48*Q48,2) -> 0 | S48: T&M | T48: 1 | U48: =Q48*1.05 -> 0 | V48: =ROUND(T48*U48,2) -> 0 | W48: =SUM(V48,R48,N48,J48,F48) -> 0
...

Sheet Price Justification
A1: Price Justification

Sheet Assumptions
A1: Project/Price Assumptions
A3: Allowances, Assumptions, Exclusions and Exceptions:
