Workbook
Name Area: [1]!Table7[Area]
Name Clins: [2]Overview!$T$4:$T$84
Name CONUS: [1]!Table8[CONUS]
Name Cost_Cats: [2]Overview!$Y$5:$Y$21
Name Data_Type: [2]Overview!$AA$4:$AA$6
Name Dates: #REF!
Name Destination: '[3]Travel Destinations'!$A$11:$A$38
Name ERI_Job_Title_List: [4]!ERI_List[ERI Job Title]
Name ERI_Jobs_List: [4]!ERI_Jobs_List_All[#Data]
Name labcat: '[5]Drop Down Lists'!$E$3:$E$51
Name Months: [2]Overview!$P$4:$P$150
Name OCONUS: [1]!Table9[OCONUS]
Name Periods: [2]Overview!$W$4:$W$8
Name Site: '[5]Drop Down Lists'!$F$3:$F$4
Name Time: '[5]Drop Down Lists'!$G$3:$G$4
Name Unit_Measure: '[5]Drop Down Lists'!$H$3:$H$53
Name WBS: #REF!
Name WBS_Name: [2]Tables!$G$4:$H$122

Sheet INSTRUCTIONS
A1: INSTRUCTIONS TO OFFERORS
A3: General
A4: 1 | B4: The Prime Offeror shall complete this Government Format Pricing Model (GFPM).
A5: 2 | B5: All proposed direct labor rates shall be in line with justifying data (historical/incurred costs, salary survey, BLS OES etc.) for each identified locality.
A6: 3 | B6: Subcontractor offerors shall complete the subcontractor GFPM (GFPM-Subs).
A7: 3a | B7: The Government has included a separate subcontractor GFPM attachment (GFPM-Subs) for the prime offeror to provide each subcontractor. The subcontractor GFPM shall be utilized for each subcontractor to show its compliance with providing a full labor buildup, per labor category and to ensure compliance with the Government provided floor rates.
A8: 3b | B8: All subcontractors must provide the subcontractor GFPM (GFPM-Subs) to the prime offeror for submittal to the Government as part of its prime offeror proposal OR each subcontractor must submit this file directly to the Government.
A9: 3c | B9: To promote consistency between subcontractor files and prime offeror files, the Government has provided a "Sub - FBLR Summary" tab within the GFPM-Subs for the subcontractor to be able to more easily transfer its proposed FBLRs, for its provided labor categories, to the prime offeror for the prime offeror to include in its proposal.
A10: "Minimum Qualifications" Tab
A11: 1 | B11: This tab is for offerors to certify that the provided employees meet or exceed the minimum education/experience requirements identified by the USG and to provide an offeror specific labor category name for each labor category identified in the SOW.
A12: 2 | B12: In Column E, a person legally authorized to bind the offeror shall enter their name for certification. This person is certifying that the offerors (prime & subcontractor) will provide personnel that meet the minimum qualifications in accordance with the SOW throughout the entire performance period of this effort. In Column G the same person shall enter the date of certification.
A13: "Total - Summary" Tab
A14: 1 | B14: This tab shows the total price for each Ordering Period.
A15: 2 | B15: No offeror input is necessary.
A16: "Total - Detail" Tab
A17: 1 | B17: Offerors shall input offeror name into cell C2.
A18: 2 | B18: The total proposed price is calculated in cell F50.
A19: 3 | B19: No other offeror input necessary, all totals will auto-populate from the "Ordering Period 1", "Ordering Period 2", "Ordering Period 3", "Ordering Period 4", "Ordering Period 5" tabs. The USG may utilize this tab while evaluating the Most Probable Cost to the Government.
A20: "Ordering Period 1", "Ordering Period 2", "Ordering Period 3", "Ordering Period 4", and "Ordering Period 5" Tabs
A21: 1 | B21: Offeror input is required in all applicable cells highlighted in yellow.
A22: 2 | B22: The "Ordering Period Labor Categories & Hours" (columns A - H) contain all of the performance locations and labor categories that the USG anticipates to be necessary for completion of this effort. The "Req. Hours" column (Column F) contains the total number of hours to be proposed for each of the USG identified labor categories. The hours may be allocated to the prime contractor and/or subcontractors. All Proposed (prime & subcontractor) labor hours must be equal to the total number of hours identified in the "Req. Hours" column.
A23: 2a | B23: In the "Prime Contractor CPFF Labor" table (columns J - Y in the Ordering Period 1 (OP1) tab and columns J - W in the OP2, OP3, OP4 & OP5 tabs), offerors shall input the proposed number of hours that will be completed by the prime contractor for each of the USG identified labor categories. Offerors are required to submit fully burdened labor rates for each of the USG identified labor categories (column V in the OP1 tab and column T in the OP2, OP3, OP4 & OP5 tabs). Offerors shall insert all of the cost elements (direct labor, DBA Insurance, fringe benefit cost, labor overhead costs, general & administrative cost, fee etc.) that make up all of the fully burdened labor rates proposed for each of the USG identified labor categories (columns L - U in the OP1 tab and columns K - S in the OP2, OP3, OP4 & OP5 tabs). Columns W - Y in the OP1 tab and columns U - W in the OP2, OP3, OP4 & OP5 tabs automatically calculate based on the offeror's inputs.
A24: 2b | B24: Offerors shall insert direct labor rates in the OP1 tab for the applicable labor categories in Column L (L5 - L36). Note: Per section L of the RTOP, the proposed direct labor rate must meet or exceed the USG floor rates referenced in the OP1 tab in Column K (K5 - K36).
A25: 2c | B25: Some labor categories are listed more than once as identified by the ID#. Proposed rates are only required to be input once for each labor category, as they will auto-populate in any additional locations. For example, ID 002 appears in Row 6, Row 16, and Row 17. Once proposed rates are input into the applicable yellow cells for ID 002 in Row 6, they will auto-populate for the same labor category (ID 002) in Rows 16 & 17.
A26: 2d | B26: Offerors that do not account for Defense Base Act (DBA) Insurance in its indirect rates shall utilize column N in the OP1 tab and Column L in the OP2, OP3, OP4 & OP5 tabs to input its DBA Insurance premium for all applicable OCONUS labor categories. DBA Insurance shall be proposed in the direct labor build up as it is not included in the Travel/ODC or Material costs.
A27: 3 | B27: In the event a Prime Offeror proposes a direct labor rate below the floor rate in error, the GFPM corrects this error by utilizing the floor rate (as calculated by the pre-populated formula in column M in the OP1 tab) to compute the Prime Offeror costs that contribute to the Prime Offeror proposed FBLR in column V.
A28: 4 | B28: Subcontractor offerors shall submit a detailed cost build up for each proposed fully burdened labor rate utilizing Attachment 0016 (GFPM-Subs). Subcontractors may choose to submit the cost build up data as part of the prime contractor's cost submission or as a separate submission directly to the Government. If reconciliation differences exist between the prime contractor's pricing submission and the subcontractor cost build up spreadsheets, the Government will rely on the data entered into the prime contractor's Government format spreadsheets to make any reasonableness/realism determinations.
A29: 4a | B29: In the "Subcontractor Labor" table (columns AA - AO in the OP1 tab and columns Y - AM in the OP2, OP3, OP4 & OP5 tabs), offerors shall input the proposed number of hours that will be completed by the subcontractor for each of the USG identified labor categories. Offerors are required to submit fully burdened labor rates for each of the applicable USG identified labor categories (column AI in the OP1 tab and column AG in the OP2, OP3, OP4 & OP5 tabs). Offerors shall insert all of the cost elements (FBLRs, prime overhead costs, prime general & administrative cost, prime fee etc.) that make up all of the fully burdened labor rates proposed for each of the applicable USG identified labor categories (columns AB - AH in the OP1 tab and columns Z - AF in the OP2, OP3, OP4 & OP5 tabs). Columns AJ - AL in the OP1 tab and Columns AH - AJ in the OP2, OP3, OP4 & OP5 tabs automatically calculate based on the offeror's inputs. If necessary, subcontractors may submit additional cost data in it's own format to further justify the proposed single elements of the subcontractor labor costs.
A30: 4b | B30: In column AM in the OP1 tab and AK in the OP2, OP3, OP4 & OP5 tabs, the prime offeror shall enter the name of the subcontractor(s) proposed to complete the hours associated with each labor category. If the prime offeror proposes more than one subcontractor for a single labor category a single FBLR (inclusive of prime contractor indirect adders and fee) shall be proposed. The proposed FBLR (inclusive of prime contractor indirect adders and fee) shall be a blend of each subcontractor’s proposed FBLR. In column AN in the OP1 tab and AL in the OP2, OP3, OP4 & OP5 tabs the prime offeror shall indicate if the proposed subcontractor FBLR is a "blended" FBLR. In column AO in the OP1 tab and AM in the OP2, OP3, OP4 & OP5 tabs the prime offeror shall enter the billing nomenclature for each of the subcontracted labor categories, all subcontracted labor categories shall be differentiated from prime labor categories.
A31: 5 | B31: Columns AQ - AS in the OP1 tab and Columns AO-AQ in the OP2, OP3, OP4 & OP5 tabs calculate a single composite fully burdened labor rate (prime and subcontractor) for each of the USG identified labor categories.
A32: 5a | B32: All values populate based on the offerors input in the "Prime Labor" and "Subcontractor Labor" tables. No offeror input is necessary.
A33: 6 | B33: The Travel/ODC Plug Figures in cells D51 - D54 in all OP tabs are pre-populated plug figures.
... A41: 9 | B41: The DBA, Fringe Benefit, Labor OH, Other OH, G&A, and FCCOM columns are unlocked and editable.
A42: "Escalation" Tab
A43: 1 | B43: This tab provides the data for the labor escalation rates which apply to all ordering periods of performance tabs.
A44: 2 | B44: Per section L of the RFP, for evaluation purposes only, this solicitation has set a minimum escalation for each period of performance. Offerors may choose to increase this rate in column C of the escalation tab, but shall not propose an escalation rate which is below the USG minimum.
A45: "Composite Labor Rates" Tab
A46: 1 | B46: This tab organizes all proposed composite (prime and subcontractor) costs, fees and fully burdened labor rates. All values automatically populate based on offerors input on the "Ordering Period" tabs.
A47: 2 | B47: No offeror input is necessary.
A48: "Prime Ceiling Rates" Tab:
...

Sheet Minimum Qualifications
A1: ID | B1: Labor Category | C1: Offeror Labor Category | D1: Location | E1: Offeror Certification | F1: Date of Certification
A2: 1 | B2: Project Management Specialist | D2: CONUS
A3: 2 | B3: Field Service Representative | D3: CONUS
A4: =A3+1 -> 3 | B4: Field Service Mechanic | D4: CONUS
A5: =A4+1 -> 4 | B5: Heavy Equipment Mechanic | D5: CONUS
A6: =A5+1 -> 5 | B6: Material Handling Specialist | D6: CONUS
A7: =A6+1 -> 6 | B7: Inspector | D7: CONUS
A8: =A7+1 -> 7 | B8: Supply/Procurement Specialist | D8: CONUS
A9: =A8+1 -> 8 | B9: Welder | D9: CONUS
A10: =A9+1 -> 9 | B10: Instructor | D10: CONUS
A11: =A10+1 -> 10 | B11: MWO Installer | D11: CONUS
A12: =A11+1 -> 11 | B12: Field Service Representative | D12: OCONUS
A13: =A12+1 -> 12 | B13: Field Service Mechanic | D13: OCONUS
A14: =A13+1 -> 13 | B14: Heavy Equipment Mechanic | D14: OCONUS
A15: =A14+1 -> 14 | B15: Material Handling Specialist | D15: OCONUS
... A20: =A19+1 -> 19 | B20: MWO Installer | D20: OCONUS

Sheet Total - Summary
B2: Extended Price
A3: Ordering Period 1 | B3: ='Total - Detail'!F50 -> 9834599.1
A4: Ordering Period 2 | B4: ='Total - Detail'!H50 -> 9834599.1
A5: Ordering Period 3 | B5: ='Total - Detail'!J50 -> 9834599.1
A6: Ordering Period 4 | B6: ='Total - Detail'!L50 -> 9834599.1
A7: Ordering Period 5 | B7: ='Total - Detail'!N50 -> 9834599.1
A9: TOTAL PROPOSED PRICE | B9: =SUM(B3:B7) -> 49172995
B10: ='Total - Detail'!F52-B9 -> 0

Sheet Total - Detail
A2: OFFEROR NAME:
F3: Total Proposed Price
A4: Service | B4: ID | C4: Required Labor - Labor Category | D4: Location | F4: Ordering Period 1 | H4: Ordering Period 2 | J4: Ordering Period 3 | L4: Ordering Period 4 | N4: Ordering Period 5
A5: CONUS
A6: Program Management | B6: 1 | C6: Project Management Specialist | D6: CONUS | F6: ='Ordering Period 1'!Y5+'Ordering Period 1'!AL5 -> 0 | H6: ='Ordering Period 2'!W5+'Ordering Period 2'!AJ5 -> 0 | J6: ='Ordering Period 3'!W5+'Ordering Period 3'!AJ5 -> 0 | L6: ='Ordering Period 4'!W5+'Ordering Period 4'!AJ5 -> 0 | N6: ='Ordering Period 5'!W5+'Ordering Period 5'!AJ5 -> 0
A7: Field Service Representative (FSR) | B7: 2 | C7: Field Service Representative | D7: CONUS | F7: ='Ordering Period 1'!Y6+'Ordering Period 1'!AL6 -> 0 | H7: ='Ordering Period 2'!W6+'Ordering Period 2'!AJ6 -> 0 | J7: ='Ordering Period 3'!W6+'Ordering Period 3'!AJ6 -> 0 | L7: ='Ordering Period 4'!W6+'Ordering Period 4'!AJ6 -> 0 | N7: ='Ordering Period 5'!W6+'Ordering Period 5'!AJ6 -> 0
B8: 3 | C8: Field Service Mechanic | D8: CONUS
A9: Deprocessing | B9: 4 | C9: Heavy Equipment Mechanic | D9: CONUS | F9: ='Ordering Period 1'!Y8+'Ordering Period 1'!AL8 -> 0 | H9: ='Ordering Period 2'!W8+'Ordering Period 2'!AJ8 -> 0 | J9: ='Ordering Period 3'!W8+'Ordering Period 3'!AJ8 -> 0 | L9: ='Ordering Period 4'!W8+'Ordering Period 4'!AJ8 -> 0 | N9: ='Ordering Period 5'!W8+'Ordering Period 5'!AJ8 -> 0
B10: 5 | C10: Material Handling Specialist | D10: CONUS | F10: ='Ordering Period 1'!Y9+'Ordering Period 1'!AL9 -> 0 | H10: ='Ordering Period 2'!W9+'Ordering Period 2'!AJ9 -> 0 | J10: ='Ordering Period 3'!W9+'Ordering Period 3'!AJ9 -> 0 | L10: ='Ordering Period 4'!W9+'Ordering Period 4'!AJ9 -> 0 | N10: ='Ordering Period 5'!W9+'Ordering Period 5'!AJ9 -> 0
B11: 6 | C11: Inspector | D11: CONUS | F11: ='Ordering Period 1'!Y10+'Ordering Period 1'!AL10 -> 0 | H11: ='Ordering Period 2'!W10+'Ordering Period 2'!AJ10 -> 0 | J11: ='Ordering Period 3'!W10+'Ordering Period 3'!AJ10 -> 0 | L11: ='Ordering Period 4'!W10+'Ordering Period 4'!AJ10 -> 0 | N11: ='Ordering Period 5'!W10+'Ordering Period 5'!AJ10 -> 0
B12: 7 | C12: Supply/Procurement Specialist | D12: CONUS | F12: ='Ordering Period 1'!Y11+'Ordering Period 1'!AL11 -> 0 | H12: ='Ordering Period 2'!W11+'Ordering Period 2'!AJ11 -> 0 | J12: ='Ordering Period 3'!W11+'Ordering Period 3'!AJ11 -> 0 | L12: ='Ordering Period 4'!W11+'Ordering Period 4'!AJ11 -> 0 | N12: ='Ordering Period 5'!W11+'Ordering Period 5'!AJ11 -> 0
B13: 8 | C13: Welder | D13: CONUS | F13: ='Ordering Period 1'!Y12+'Ordering Period 1'!AL12 -> 0 | H13: ='Ordering Period 2'!W12+'Ordering Period 2'!AJ12 -> 0 | J13: ='Ordering Period 3'!W12+'Ordering Period 3'!AJ12 -> 0 | L13: ='Ordering Period 4'!W12+'Ordering Period 4'!AJ12 -> 0 | N13: ='Ordering Period 5'!W12+'Ordering Period 5'!AJ12 -> 0
A14: New Equipment Training (NET) / Displaced Equipment Training (DET) | B14: 9 | C14: Instructor | D14: CONUS | F14: ='Ordering Period 1'!Y13+'Ordering Period 1'!AL13 -> 0 | H14: ='Ordering Period 2'!W13+'Ordering Period 2'!AJ13 -> 0 | J14: ='Ordering Period 3'!W13+'Ordering Period 3'!AJ13 -> 0 | L14: ='Ordering Period 4'!W13+'Ordering Period 4'!AJ13 -> 0 | N14: ='Ordering Period 5'!W13+'Ordering Period 5'!AJ13 -> 0
A15: Total Package Fielding (TPF) | B15: 4 | C15: Heavy Equipment Mechanic | D15: CONUS | F15: ='Ordering Period 1'!Y14+'Ordering Period 1'!AL14 -> 0 | H15: ='Ordering Period 2'!W14+'Ordering Period 2'!AJ14 -> 0 | J15: ='Ordering Period 3'!W14+'Ordering Period 3'!AJ14 -> 0 | L15: ='Ordering Period 4'!W14+'Ordering Period 4'!AJ14 -> 0 | N15: ='Ordering Period 5'!W14+'Ordering Period 5'!AJ14 -> 0
B16: 5 | C16: Material Handling Specialist | D16: CONUS | F16: ='Ordering Period 1'!Y15+'Ordering Period 1'!AL15 -> 0 | H16: ='Ordering Period 2'!W15+'Ordering Period 2'!AJ15 -> 0 | J16: ='Ordering Period 3'!W15+'Ordering Period 3'!AJ15 -> 0 | L16: ='Ordering Period 4'!W15+'Ordering Period 4'!AJ15 -> 0 | N16: ='Ordering Period 5'!W15+'Ordering Period 5'!AJ15 -> 0
B17: 6 | C17: Inspector | D17: CONUS | F17: ='Ordering Period 1'!Y16+'Ordering Period 1'!AL16 -> 0 | H17: ='Ordering Period 2'!W16+'Ordering Period 2'!AJ16 -> 0 | J17: ='Ordering Period 3'!W16+'Ordering Period 3'!AJ16 -> 0 | L17: ='Ordering Period 4'!W16+'Ordering Period 4'!AJ16 -> 0 | N17: ='Ordering Period 5'!W16+'Ordering Period 5'!AJ16 -> 0
B18: 2 | C18: Field Service Representative | D18: CONUS | F18: ='Ordering Period 1'!Y17+'Ordering Period 1'!AL17 -> 0 | H18: ='Ordering Period 2'!W17+'Ordering Period 2'!AJ17 -> 0 | J18: ='Ordering Period 3'!W17+'Ordering Period 3'!AJ17 -> 0 | L18: ='Ordering Period 4'!W17+'Ordering Period 4'!AJ17 -> 0 | N18: ='Ordering Period 5'!W17+'Ordering Period 5'!AJ17 -> 0
A19: Modification Work Order (MWO) Installation | B19: 2 | C19: Field Service Representative | D19: CONUS | F19: ='Ordering Period 1'!Y18+'Ordering Period 1'!AL18 -> 0 | H19: ='Ordering Period 2'!W18+'Ordering Period 2'!AJ18 -> 0 | J19: ='Ordering Period 3'!W18+'Ordering Period 3'!AJ18 -> 0 | L19: ='Ordering Period 4'!W18+'Ordering Period 4'!AJ18 -> 0 | N19: ='Ordering Period 5'!W18+'Ordering Period 5'!AJ18 -> 0
B20: 10 | C20: MWO Installer | D20: CONUS | F20: ='Ordering Period 1'!Y19+'Ordering Period 1'!AL19 -> 0 | H20: ='Ordering Period 2'!W19+'Ordering Period 2'!AJ19 -> 0 | J20: ='Ordering Period 3'!W19+'Ordering Period 3'!AJ19 -> 0 | L20: ='Ordering Period 4'!W19+'Ordering Period 4'!AJ19 -> 0 | N20: ='Ordering Period 5'!W19+'Ordering Period 5'!AJ19 -> 0
B21: 6 | C21: Inspector | D21: CONUS | F21: ='Ordering Period 1'!Y20+'Ordering Period 1'!AL20 -> 0 | H21: ='Ordering Period 2'!W20+'Ordering Period 2'!AJ20 -> 0 | J21: ='Ordering Period 3'!W20+'Ordering Period 3'!AJ20 -> 0 | L21: ='Ordering Period 4'!W20+'Ordering Period 4'!AJ20 -> 0 | N21: ='Ordering Period 5'!W20+'Ordering Period 5'!AJ20 -> 0
B22: 8 | C22: Welder | D22: CONUS | F22: ='Ordering Period 1'!Y21+'Ordering Period 1'!AL21 -> 0 | H22: ='Ordering Period 2'!W21+'Ordering Period 2'!AJ21 -> 0 | J22: ='Ordering Period 3'!W21+'Ordering Period 3'!AJ21 -> 0 | L22: ='Ordering Period 4'!W21+'Ordering Period 4'!AJ21 -> 0 | N22: ='Ordering Period 5'!W21+'Ordering Period 5'!AJ21 -> 0
A23: OCONUS
A24: Field Service Representative (FSR) | B24: 11 | C24: Field Service Representative | D24: OCONUS | F24: ='Ordering Period 1'!Y23+'Ordering Period 1'!AL23 -> 0 | H24: ='Ordering Period 2'!W23+'Ordering Period 2'!AJ23 -> 0 | J24: ='Ordering Period 3'!W23+'Ordering Period 3'!AJ23 -> 0 | L24: ='Ordering Period 4'!W23+'Ordering Period 4'!AJ23 -> 0 | N24: ='Ordering Period 5'!W23+'Ordering Period 5'!AJ23 -> 0
B25: 12 | C25: Field Service Mechanic | D25: OCONUS
A26: Deprocessing | B26: 13 | C26: Heavy Equipment Mechanic | D26: OCONUS | F26: ='Ordering Period 1'!Y25+'Ordering Period 1'!AL25 -> 0 | H26: ='Ordering Period 2'!W25+'Ordering Period 2'!AJ25 -> 0 | J26: ='Ordering Period 3'!W25+'Ordering Period 3'!AJ25 -> 0 | L26: ='Ordering Period 4'!W25+'Ordering Period 4'!AJ25 -> 0 | N26: ='Ordering Period 5'!W25+'Ordering Period 5'!AJ25 -> 0
B27: 14 | C27: Material Handling Specialist | D27: OCONUS | F27: ='Ordering Period 1'!Y26+'Ordering Period 1'!AL26 -> 0 | H27: ='Ordering Period 2'!W26+'Ordering Period 2'!AJ26 -> 0 | J27: ='Ordering Period 3'!W26+'Ordering Period 3'!AJ26 -> 0 | L27: ='Ordering Period 4'!W26+'Ordering Period 4'!AJ26 -> 0 | N27: ='Ordering Period 5'!W26+'Ordering Period 5'!AJ26 -> 0
B28: 15 | C28: Inspector | D28: OCONUS | F28: ='Ordering Period 1'!Y27+'Ordering Period 1'!AL27 -> 0 | H28: ='Ordering Period 2'!W27+'Ordering Period 2'!AJ27 -> 0 | J28: ='Ordering Period 3'!W27+'Ordering Period 3'!AJ27 -> 0 | L28: ='Ordering Period 4'!W27+'Ordering Period 4'!AJ27 -> 0 | N28: ='Ordering Period 5'!W27+'Ordering Period 5'!AJ27 -> 0
B29: 16 | C29: Supply/Procurement Specialist | D29: OCONUS | F29: ='Ordering Period 1'!Y28+'Ordering Period 1'!AL28 -> 0 | H29: ='Ordering Period 2'!W28+'Ordering Period 2'!AJ28 -> 0 | J29: ='Ordering Period 3'!W28+'Ordering Period 3'!AJ28 -> 0 | L29: ='Ordering Period 4'!W28+'Ordering Period 4'!AJ28 -> 0 | N29: ='Ordering Period 5'!W28+'Ordering Period 5'!AJ28 -> 0
B30: 17 | C30: Welder | D30: OCONUS | F30: ='Ordering Period 1'!Y29+'Ordering Period 1'!AL29 -> 0 | H30: ='Ordering Period 2'!W29+'Ordering Period 2'!AJ29 -> 0 | J30: ='Ordering Period 3'!W29+'Ordering Period 3'!AJ29 -> 0 | L30: ='Ordering Period 4'!W29+'Ordering Period 4'!AJ29 -> 0 | N30: ='Ordering Period 5'!W29+'Ordering Period 5'!AJ29 -> 0
A31: New Equipment Training (NET) / Displaced Equipment Training (DET) | B31: 18 | C31: Instructor | D31: OCONUS | F31: ='Ordering Period 1'!Y30+'Ordering Period 1'!AL30 -> 0 | H31: ='Ordering Period 2'!W30+'Ordering Period 2'!AJ30 -> 0 | J31: ='Ordering Period 3'!W30+'Ordering Period 3'!AJ30 -> 0 | L31: ='Ordering Period 4'!W30+'Ordering Period 4'!AJ30 -> 0 | N31: ='Ordering Period 5'!W30+'Ordering Period 5'!AJ30 -> 0
A32: Total Package Fielding (TPF) | B32: 13 | C32: Heavy Equipment Mechanic | D32: OCONUS | F32: ='Ordering Period 1'!Y31+'Ordering Period 1'!AL31 -> 0 | H32: ='Ordering Period 2'!W31+'Ordering Period 2'!AJ31 -> 0 | J32: ='Ordering Period 3'!W31+'Ordering Period 3'!AJ31 -> 0 | L32: ='Ordering Period 4'!W31+'Ordering Period 4'!AJ31 -> 0 | N32: ='Ordering Period 5'!W31+'Ordering Period 5'!AJ31 -> 0
B33: 14 | C33: Material Handling Specialist | D33: OCONUS | F33: ='Ordering Period 1'!Y32+'Ordering Period 1'!AL32 -> 0 | H33: ='Ordering Period 2'!W32+'Ordering Period 2'!AJ32 -> 0 | J33: ='Ordering Period 3'!W32+'Ordering Period 3'!AJ32 -> 0 | L33: ='Ordering Period 4'!W32+'Ordering Period 4'!AJ32 -> 0 | N33: ='Ordering Period 5'!W32+'Ordering Period 5'!AJ32 -> 0
B34: 15 | C34: Inspector | D34: OCONUS | F34: ='Ordering Period 1'!Y33+'Ordering Period 1'!AL33 -> 0 | H34: ='Ordering Period 2'!W33+'Ordering Period 2'!AJ33 -> 0 | J34: ='Ordering Period 3'!W33+'Ordering Period 3'!AJ33 -> 0 | L34: ='Ordering Period 4'!W33+'Ordering Period 4'!AJ33 -> 0 | N34: ='Ordering Period 5'!W33+'Ordering Period 5'!AJ33 -> 0
B35: 11 | C35: Field Service Representative | D35: OCONUS | F35: ='Ordering Period 1'!Y34+'Ordering Period 1'!AL34 -> 0 | H35: ='Ordering Period 2'!W34+'Ordering Period 2'!AJ34 -> 0 | J35: ='Ordering Period 3'!W34+'Ordering Period 3'!AJ34 -> 0 | L35: ='Ordering Period 4'!W34+'Ordering Period 4'!AJ34 -> 0 | N35: ='Ordering Period 5'!W34+'Ordering Period 5'!AJ34 -> 0
A36: Modification Work Order (MWO) Installation | B36: 11 | C36: Field Service Representative | D36: OCONUS | F36: ='Ordering Period 1'!Y35+'Ordering Period 1'!AL35 -> 0 | H36: ='Ordering Period 2'!W35+'Ordering Period 2'!AJ35 -> 0 | J36: ='Ordering Period 3'!W35+'Ordering Period 3'!AJ35 -> 0 | L36: ='Ordering Period 4'!W35+'Ordering Period 4'!AJ35 -> 0 | N36: ='Ordering Period 5'!W35+'Ordering Period 5'!AJ35 -> 0
B37: 19 | C37: MWO Installer | D37: OCONUS | F37: ='Ordering Period 1'!Y36+'Ordering Period 1'!AL36 -> 0 | H37: ='Ordering Period 2'!W36+'Ordering Period 2'!AJ36 -> 0 | J37: ='Ordering Period 3'!W36+'Ordering Period 3'!AJ36 -> 0 | L37: ='Ordering Period 4'!W36+'Ordering Period 4'!AJ36 -> 0 | N37: ='Ordering Period 5'!W36+'Ordering Period 5'!AJ36 -> 0
B38: 15 | C38: Inspector | D38: OCONUS | F38: ='Ordering Period 1'!Y37+'Ordering Period 1'!AL37 -> 0 | H38: ='Ordering Period 2'!W37+'Ordering Period 2'!AJ37 -> 0 | J38: ='Ordering Period 3'!W37+'Ordering Period 3'!AJ37 -> 0 | L38: ='Ordering Period 4'!W37+'Ordering Period 4'!AJ37 -> 0 | N38: ='Ordering Period 5'!W37+'Ordering Period 5'!AJ37 -> 0
B39: 17 | C39: Welder | D39: OCONUS | F39: ='Ordering Period 1'!Y38+'Ordering Period 1'!AL38 -> 0 | H39: ='Ordering Period 2'!W38+'Ordering Period 2'!AJ38 -> 0 | J39: ='Ordering Period 3'!W38+'Ordering Period 3'!AJ38 -> 0 | L39: ='Ordering Period 4'!W38+'Ordering Period 4'!AJ38 -> 0 | N39: ='Ordering Period 5'!W38+'Ordering Period 5'!AJ38 -> 0
C41: Description: | F41: =F4 -> Ordering Period 1 | H41: =H4 -> Ordering Period 2 | J41: =J4 -> Ordering Period 3 | L41: =L4 -> Ordering Period 4 | N41: =N4 -> Ordering Period 5
C44: Total Labor | F44: ='Ordering Period 1'!F50 -> 0 | H44: ='Ordering Period 2'!F50 -> 0 | J44: ='Ordering Period 3'!F50 -> 0 | L44: ='Ordering Period 4'!F50 -> 0 | N44: ='Ordering Period 5'!F50 -> 0
...

Sheet Ordering Period 1
A1: Ordering Period 1:
A2: Ordering Period 1 Labor Categories & Hours | J2: Prime Contractor CPFF Labor | AA2: Subcontractor Labor | AQ2: Composite FBLR (Prime & Sub)
A3: Service | B3: ID | C3: Labor Category | D3: Reference | E3: Location | F3: Req. Hours | G3: Prop Hours. | H3: Delta (Req. - Prop.) | J3: Prime Hours | K3: (Floor Rate) | L3: Direct Labor (Proposed) | M3: Direct Labor (Calculation) | N3: DBA | O3: Fringe Benefit | P3: Labor OH | Q3: Other OH | R3: G&A | S3: FCCOM | T3: Cost | U3: Fee | V3: FBLR | W3: Total Cost | X3: Total Fee | Y3: Total Price | AA3: Sub Hours | AB3: Sub FBLR | AC3: Sub FBLR (Calculation) | AD3: Prime OH | AE3: Prime G&A | AF3: Prime FCCOM | AG3: Cost | AH3: Prime Fee | AI3: FBLR (Inclusive of All Prime Adders) | AJ3: Total Cost | AK3: Total Fee | AL3: Total Price | AM3: Name of Subcontractor(s) | AN3: Blended Sub FBLR (Y/N) | AO3: Billing Nomenclature | AQ3: CPFF
A4: CONUS | AQ4: Cost | AR4: Fee | AS4: Total
A5: Program Management | B5: ='Total - Detail'!B6 -> 1 | C5: ='Total - Detail'!C6 -> Project Management Specialist | D5: H.3.11 | E5: CONUS | F5: 19114.698 | G5: =SUM(J5,AA5) -> 0 | H5: =F5-G5 -> 19114.698 | J5: 0 | K5: 48.44 | M5: =IF($J5>0,IF($L5<$K5,$K5,$L5),0) -> 0 | O5: =(M5*$O$4) -> 0 | P5: =(O5+M5)*$P$4 -> 0 | Q5: =(M5+O5)*$Q$4 -> 0 | R5: =(O5+M5+P5+Q5)*$R$4 -> 0 | S5: =(M5+O5+P5+Q5+R5)*$S$4 -> 0 | T5: =SUM(M5:S5) -> 0 | U5: =(T5-S5)*$U$4 -> 0 | V5: =SUM(T5:U5) -> 0 | W5: =T5*J5 -> 0 | X5: =U5*J5 -> 0 | Y5: =V5*J5 -> 0 | AC5: =IF($AA5>0,$AB5,0) -> 0 | AD5: =(AC5*$AD$4) -> 0 | AE5: =(AC5+AD5)*$AE$4 -> 0 | AG5: =SUM(AC5:AF5) -> 0 | AH5: =$AH$4*(AE5+AC5+AD5) -> 0 | AI5: =SUM(AG5:AH5) -> 0 | AJ5: =AG5*AA5 -> 0 | AK5: =AH5*AA5 -> 0 | AL5: =AI5*AA5 -> 0 | AQ5: =IFERROR(SUM(W5,AJ5)/G5,"") | AR5: =IFERROR(SUM(X5,AK5)/G5,"") | AS5: =SUM(AQ5:AR5) -> 0
A6: Field Service Representative (FSR) | B6: ='Total - Detail'!B7 -> 2 | C6: Field Service Representative | D6: H.3.8 | E6: CONUS | F6: 39357.391 | G6: =SUM(J6,AA6) -> 0 | H6: =F6-G6 -> 39357.391 | K6: 35.83 | M6: =IF($J6>0,IF($L6<$K6,$K6,$L6),0) -> 0 | O6: =(M6*$O$4) -> 0 | P6: =(O6+M6)*$P$4 -> 0 | Q6: =(M6+O6)*$Q$4 -> 0 | R6: =(O6+M6+P6+Q6)*$R$4 -> 0 | S6: =(M6+O6+P6+Q6+R6)*$S$4 -> 0 | T6: =SUM(M6:S6) -> 0 | U6: =(T6-S6)*$U$4 -> 0 | V6: =SUM(T6:U6) -> 0 | W6: =T6*J6 -> 0 | X6: =U6*J6 -> 0 | Y6: =V6*J6 -> 0 | AC6: =IF($AA6>0,$AB6,0) -> 0 | AD6: =(AC6*$AD$4) -> 0 | AE6: =(AC6+AD6)*$AE$4 -> 0 | AG6: =SUM(AC6:AF6) -> 0 | AH6: =$AH$4*(AE6+AC6+AD6) -> 0 | AI6: =SUM(AG6:AH6) -> 0 | AJ6: =AG6*AA6 -> 0 | AK6: =AH6*AA6 -> 0 | AL6: =AI6*AA6 -> 0 | AQ6: =IFERROR(SUM(W6,AJ6)/G6,"") | AR6: =IFERROR(SUM(X6,AK6)/G6,"") | AS6: =SUM(AQ6:AR6) -> 0
B7: ='Total - Detail'!B8 -> 3 | C7: ='Total - Detail'!C8 -> Field Service Mechanic | D7: H.3.9 | E7: CONUS | F7: 73092.298 | H7: =F7-G7 -> 73092.298 | K7: 30.76 | M7: =IF($J7>0,IF($L7<$K7,$K7,$L7),0) -> 0 | O7: =(M7*$O$4) -> 0 | P7: =(O7+M7)*$P$4 -> 0 | Q7: =(M7+O7)*$Q$4 -> 0 | R7: =(O7+M7+P7+Q7)*$R$4 -> 0 | S7: =(M7+O7+P7+Q7+R7)*$S$4 -> 0 | T7: =SUM(M7:S7) -> 0 | U7: =(T7-S7)*$U$4 -> 0 | V7: =SUM(T7:U7) -> 0 | W7: =T7*J7 -> 0 | X7: =U7*J7 -> 0 | Y7: =V7*J7 -> 0 | AC7: =IF($AA7>0,$AB7,0) -> 0 | AD7: =(AC7*$AD$4) -> 0 | AE7: =(AC7+AD7)*$AE$4 -> 0 | AG7: =SUM(AC7:AF7) -> 0 | AH7: =$AH$4*(AE7+AC7+AD7) -> 0 | AI7: =SUM(AG7:AH7) -> 0 | AJ7: =AG7*AA7 -> 0 | AK7: =AH7*AA7 -> 0 | AL7: =AI7*AA7 -> 0 | AQ7: =IFERROR(SUM(W7,AJ7)/G7,"") | AR7: =IFERROR(SUM(X7,AK7)/G7,"") | AS7: =SUM(AQ7:AR7) -> 0
A8: Deprocessing | B8: ='Total - Detail'!B9 -> 4 | C8: ='Total - Detail'!C9 -> Heavy Equipment Mechanic | D8: H.3.4 | E8: CONUS | F8: 96564.591 | G8: =SUM(J8,AA8) -> 0 | H8: =F8-G8 -> 96564.591 | K8: 30.76 | M8: =IF($J8>0,IF($L8<$K8,$K8,$L8),0) -> 0 | O8: =(M8*$O$4) -> 0 | P8: =(O8+M8)*$P$4 -> 0 | Q8: =(M8+O8)*$Q$4 -> 0 | R8: =(O8+M8+P8+Q8)*$R$4 -> 0 | S8: =(M8+O8+P8+Q8+R8)*$S$4 -> 0 | T8: =SUM(M8:S8) -> 0 | U8: =(T8-S8)*$U$4 -> 0 | V8: =SUM(T8:U8) -> 0 | W8: =T8*J8 -> 0 | X8: =U8*J8 -> 0 | Y8: =V8*J8 -> 0 | AC8: =IF($AA8>0,$AB8,0) -> 0 | AD8: =(AC8*$AD$4) -> 0 | AE8: =(AC8+AD8)*$AE$4 -> 0 | AG8: =SUM(AC8:AF8) -> 0 | AH8: =$AH$4*(AE8+AC8+AD8) -> 0 | AI8: =SUM(AG8:AH8) -> 0 | AJ8: =AG8*AA8 -> 0 | AK8: =AH8*AA8 -> 0 | AL8: =AI8*AA8 -> 0 | AQ8: =IFERROR(SUM(W8,AJ8)/G8,"") | AR8: =IFERROR(SUM(X8,AK8)/G8,"") | AS8: =SUM(AQ8:AR8) -> 0
B9: ='Total - Detail'!B10 -> 5 | C9: ='Total - Detail'!C10 -> Material Handling Specialist | D9: H.3.3 | E9: CONUS | F9: 6328.2994 | G9: =SUM(J9,AA9) -> 0 | H9: =F9-G9 -> 6328.2994 | K9: 27.78 | M9: =IF($J9>0,IF($L9<$K9,$K9,$L9),0) -> 0 | O9: =(M9*$O$4) -> 0 | P9: =(O9+M9)*$P$4 -> 0 | Q9: =(M9+O9)*$Q$4 -> 0 | R9: =(O9+M9+P9+Q9)*$R$4 -> 0 | S9: =(M9+O9+P9+Q9+R9)*$S$4 -> 0 | T9: =SUM(M9:S9) -> 0 | U9: =(T9-S9)*$U$4 -> 0 | V9: =SUM(T9:U9) -> 0 | W9: =T9*J9 -> 0 | X9: =U9*J9 -> 0 | Y9: =V9*J9 -> 0 | AC9: =IF($AA9>0,$AB9,0) -> 0 | AD9: =(AC9*$AD$4) -> 0 | AE9: =(AC9+AD9)*$AE$4 -> 0 | AG9: =SUM(AC9:AF9) -> 0 | AH9: =$AH$4*(AE9+AC9+AD9) -> 0 | AI9: =SUM(AG9:AH9) -> 0 | AJ9: =AG9*AA9 -> 0 | AK9: =AH9*AA9 -> 0 | AL9: =AI9*AA9 -> 0 | AQ9: =IFERROR(SUM(W9,AJ9)/G9,"") | AR9: =IFERROR(SUM(X9,AK9)/G9,"") | AS9: =SUM(AQ9:AR9) -> 0
B10: ='Total - Detail'!B11 -> 6 | C10: ='Total - Detail'!C11 -> Inspector | D10: H.3.10 | E10: CONUS | F10: 1981.0998 | G10: =SUM(J10,AA10) -> 0 | H10: =F10-G10 -> 1981.0998 | K10: 24.98 | M10: =IF($J10>0,IF($L10<$K10,$K10,$L10),0) -> 0 | O10: =(M10*$O$4) -> 0 | P10: =(O10+M10)*$P$4 -> 0 | Q10: =(M10+O10)*$Q$4 -> 0 | R10: =(O10+M10+P10+Q10)*$R$4 -> 0 | S10: =(M10+O10+P10+Q10+R10)*$S$4 -> 0 | T10: =SUM(M10:S10) -> 0 | U10: =(T10-S10)*$U$4 -> 0 | V10: =SUM(T10:U10) -> 0 | W10: =T10*J10 -> 0 | X10: =U10*J10 -> 0 | Y10: =V10*J10 -> 0 | AC10: =IF($AA10>0,$AB10,0) -> 0 | AD10: =(AC10*$AD$4) -> 0 | AE10: =(AC10+AD10)*$AE$4 -> 0 | AG10: =SUM(AC10:AF10) -> 0 | AH10: =$AH$4*(AE10+AC10+AD10) -> 0 | AI10: =SUM(AG10:AH10) -> 0 | AJ10: =AG10*AA10 -> 0 | AK10: =AH10*AA10 -> 0 | AL10: =AI10*AA10 -> 0 | AQ10: =IFERROR(SUM(W10,AJ10)/G10,"") | AR10: =IFERROR(SUM(X10,AK10)/G10,"") | AS10: =SUM(AQ10:AR10) -> 0
B11: ='Total - Detail'!B12 -> 7 | C11: ='Total - Detail'!C12 -> Supply/Procurement Specialist | D11: H.3.2 | E11: CONUS | F11: 3163.5997 | G11: =SUM(J11,AA11) -> 0 | H11: =F11-G11 -> 3163.5997 | K11: 35.7 | M11: =IF($J11>0,IF($L11<$K11,$K11,$L11),0) -> 0 | O11: =(M11*$O$4) -> 0 | P11: 8 | Q11: =(M11+O11)*$Q$4 -> 0 | R11: =(O11+M11+P11+Q11)*$R$4 -> 0 | S11: =(M11+O11+P11+Q11+R11)*$S$4 -> 0 | T11: =SUM(M11:S11) -> 8 | U11: =(T11-S11)*$U$4 -> 0 | V11: =SUM(T11:U11) -> 8 | W11: =T11*J11 -> 0 | X11: =U11*J11 -> 0 | Y11: =V11*J11 -> 0 | AC11: =IF($AA11>0,$AB11,0) -> 0 | AD11: =(AC11*$AD$4) -> 0 | AE11: =(AC11+AD11)*$AE$4 -> 0 | AG11: =SUM(AC11:AF11) -> 0 | AH11: =$AH$4*(AE11+AC11+AD11) -> 0 | AI11: =SUM(AG11:AH11) -> 0 | AJ11: =AG11*AA11 -> 0 | AK11: =AH11*AA11 -> 0 | AL11: =AI11*AA11 -> 0 | AQ11: =IFERROR(SUM(W11,AJ11)/G11,"") | AR11: =IFERROR(SUM(X11,AK11)/G11,"") | AS11: =SUM(AQ11:AR11) -> 0
B12: ='Total - Detail'!B13 -> 8 | C12: ='Total - Detail'!C13 -> Welder | D12: H.3.5 | E12: CONUS | F12: 3406.6997 | G12: =SUM(J12,AA12) -> 0 | H12: =F12-G12 -> 3406.6997 | K12: 24.52 | M12: =IF($J12>0,IF($L12<$K12,$K12,$L12),0) -> 0 | O12: =(M12*$O$4) -> 0 | P12: =(O12+M12)*$P$4 -> 0 | Q12: =(M12+O12)*$Q$4 -> 0 | R12: =(O12+M12+P12+Q12)*$R$4 -> 0 | S12: =(M12+O12+P12+Q12+R12)*$S$4 -> 0 | T12: =SUM(M12:S12) -> 0 | U12: =(T12-S12)*$U$4 -> 0 | V12: =SUM(T12:U12) -> 0 | W12: =T12*J12 -> 0 | X12: =U12*J12 -> 0 | Y12: =V12*J12 -> 0 | AC12: =IF($AA12>0,$AB12,0) -> 0 | AD12: =(AC12*$AD$4) -> 0 | AE12: =(AC12+AD12)*$AE$4 -> 0 | AG12: =SUM(AC12:AF12) -> 0 | AH12: =$AH$4*(AE12+AC12+AD12) -> 0 | AI12: =SUM(AG12:AH12) -> 0 | AJ12: =AG12*AA12 -> 0 | AK12: =AH12*AA12 -> 0 | AL12: =AI12*AA12 -> 0 | AQ12: =IFERROR(SUM(W12,AJ12)/G12,"") | AR12: =IFERROR(SUM(X12,AK12)/G12,"") | AS12: =SUM(AQ12:AR12) -> 0
A13: New Equipment Training (NET) / Displaced Equipment Training (DET) | B13: ='Total - Detail'!B14 -> 9 | C13: Instructor | D13: H.3.7 | E13: CONUS | F13: 47226.296 | G13: =SUM(J13,AA13) -> 0 | H13: =F13-G13 -> 47226.296 | K13: 25.89 | M13: =IF($J13>0,IF($L13<$K13,$K13,$L13),0) -> 0 | O13: =(M13*$O$4) -> 0 | P13: =(O13+M13)*$P$4 -> 0 | Q13: =(M13+O13)*$Q$4 -> 0 | R13: =(O13+M13+P13+Q13)*$R$4 -> 0 | S13: =(M13+O13+P13+Q13+R13)*$S$4 -> 0 | T13: =SUM(M13:S13) -> 0 | U13: =(T13-S13)*$U$4 -> 0 | V13: =SUM(T13:U13) -> 0 | W13: =T13*J13 -> 0 | X13: =U13*J13 -> 0 | Y13: =V13*J13 -> 0 | AC13: =IF($AA13>0,$AB13,0) -> 0 | AD13: =(AC13*$AD$4) -> 0 | AE13: =(AC13+AD13)*$AE$4 -> 0 | AG13: =SUM(AC13:AF13) -> 0 | AH13: =$AH$4*(AE13+AC13+AD13) -> 0 | AI13: =SUM(AG13:AH13) -> 0 | AJ13: =AG13*AA13 -> 0 | AK13: =AH13*AA13 -> 0 | AL13: =AI13*AA13 -> 0 | AQ13: =IFERROR(SUM(W13,AJ13)/G13,"") | AR13: =IFERROR(SUM(X13,AK13)/G13,"") | AS13: =SUM(AQ13:AR13) -> 0
A14: Total Package Fielding (TPF) | B14: ='Total - Detail'!B15 -> 4 | C14: ='Total - Detail'!C15 -> Heavy Equipment Mechanic | D14: H.3.4 | E14: CONUS | F14: 14445.199 | G14: =SUM(J14,AA14) -> 0 | H14: =F14-G14 -> 14445.199 | K14: 30.76 | L14: =L8 -> 0 | M14: =IF($J14>0,IF($L14<$K14,$K14,$L14),0) -> 0 | O14: =O8 -> 0 | P14: =P8 -> 0 | Q14: =Q8 -> 0 | R14: =R8 -> 0 | S14: =S8 -> 0 | T14: =SUM(M14:S14) -> 0 | U14: =(T14-S14)*$U$4 -> 0 | V14: =SUM(T14:U14) -> 0 | W14: =T14*J14 -> 0 | X14: =U14*J14 -> 0 | Y14: =V14*J14 -> 0 | AC14: =IF($AA14>0,$AB14,0) -> 0 | AD14: =(AC14*$AD$4) -> 0 | AE14: =(AC14+AD14)*$AE$4 -> 0 | AG14: =SUM(AC14:AF14) -> 0 | AH14: =$AH$4*(AE14+AC14+AD14) -> 0 | AI14: =SUM(AG14:AH14) -> 0 | AJ14: =AG14*AA14 -> 0 | AK14: =AH14*AA14 -> 0 | AL14: =AI14*AA14 -> 0 | AQ14: =IFERROR(SUM(W14,AJ14)/G14,"") | AR14: =IFERROR(SUM(X14,AK14)/G14,"") | AS14: =SUM(AQ14:AR14) -> 0
B15: ='Total - Detail'!B16 -> 5 | C15: ='Total - Detail'!C16 -> Material Handling Specialist | D15: H.3.3 | E15: CONUS | F15: 6328.2994 | G15: =SUM(J15,AA15) -> 0 | H15: =F15-G15 -> 6328.2994 | K15: 27.78 | L15: =L9 -> 0 | M15: =IF($J15>0,IF($L15<$K15,$K15,$L15),0) -> 0 | O15: =O9 -> 0 | P15: =P9 -> 0 | Q15: =Q9 -> 0 | R15: =R9 -> 0 | S15: =S9 -> 0 | T15: =SUM(M15:S15) -> 0 | U15: =(T15-S15)*$U$4 -> 0 | V15: =SUM(T15:U15) -> 0 | W15: =T15*J15 -> 0 | X15: =U15*J15 -> 0 | Y15: =V15*J15 -> 0 | AC15: =IF($AA15>0,$AB15,0) -> 0 | AD15: =(AC15*$AD$4) -> 0 | AE15: =(AC15+AD15)*$AE$4 -> 0 | AG15: =SUM(AC15:AF15) -> 0 | AH15: =$AH$4*(AE15+AC15+AD15) -> 0 | AI15: =SUM(AG15:AH15) -> 0 | AJ15: =AG15*AA15 -> 0 | AK15: =AH15*AA15 -> 0 | AL15: =AI15*AA15 -> 0 | AQ15: =IFERROR(SUM(W15,AJ15)/G15,"") | AR15: =IFERROR(SUM(X15,AK15)/G15,"") | AS15: =SUM(AQ15:AR15) -> 0
B16: ='Total - Detail'!B17 -> 6 | C16: ='Total - Detail'!C17 -> Inspector | D16: H.3.10 | E16: CONUS | F16: 1981.0998 | G16: =SUM(J16,AA16) -> 0 | H16: =F16-G16 -> 1981.0998 | K16: 24.98 | L16: =L10 -> 0 | M16: =IF($J16>0,IF($L16<$K16,$K16,$L16),0) -> 0 | O16: =O10 -> 0 | P16: =P10 -> 0 | Q16: =Q10 -> 0 | R16: =R10 -> 0 | S16: =S10 -> 0 | T16: =SUM(M16:S16) -> 0 | U16: =(T16-S16)*$U$4 -> 0 | V16: =SUM(T16:U16) -> 0 | W16: =T16*J16 -> 0 | X16: =U16*J16 -> 0 | Y16: =V16*J16 -> 0 | AC16: =IF($AA16>0,$AB16,0) -> 0 | AD16: =(AC16*$AD$4) -> 0 | AE16: =(AC16+AD16)*$AE$4 -> 0 | AG16: =SUM(AC16:AF16) -> 0 | AH16: =$AH$4*(AE16+AC16+AD16) -> 0 | AI16: =SUM(AG16:AH16) -> 0 | AJ16: =AG16*AA16 -> 0 | AK16: =AH16*AA16 -> 0 | AL16: =AI16*AA16 -> 0 | AQ16: =IFERROR(SUM(W16,AJ16)/G16,"") | AR16: =IFERROR(SUM(X16,AK16)/G16,"") | AS16: =SUM(AQ16:AR16) -> 0
B17: ='Total - Detail'!B18 -> 2 | C17: ='Total - Detail'!C18 -> Field Service Representative | D17: H.3.8 | E17: CONUS | F17: 3163.5997 | G17: =SUM(J17,AA17) -> 0 | H17: =F17-G17 -> 3163.5997 | K17: 35.83 | L17: =L6 -> 0 | M17: =IF($J17>0,IF($L17<$K17,$K17,$L17),0) -> 0 | O17: =O6 -> 0 | P17: =P6 -> 0 | Q17: =Q6 -> 0 | R17: =R6 -> 0 | S17: =S6 -> 0 | T17: =SUM(M17:S17) -> 0 | U17: =(T17-S17)*$U$4 -> 0 | V17: =SUM(T17:U17) -> 0 | W17: =T17*J17 -> 0 | X17: =U17*J17 -> 0 | Y17: =V17*J17 -> 0 | AC17: =IF($AA17>0,$AB17,0) -> 0 | AD17: =(AC17*$AD$4) -> 0 | AE17: =(AC17+AD17)*$AE$4 -> 0 | AG17: =SUM(AC17:AF17) -> 0 | AH17: =$AH$4*(AE17+AC17+AD17) -> 0 | AI17: =SUM(AG17:AH17) -> 0 | AJ17: =AG17*AA17 -> 0 | AK17: =AH17*AA17 -> 0 | AL17: =AI17*AA17 -> 0 | AQ17: =IFERROR(SUM(W17,AJ17)/G17,"") | AR17: =IFERROR(SUM(X17,AK17)/G17,"") | AS17: =SUM(AQ17:AR17) -> 0
A18: Modification Work Order (MWO) Installation | B18: ='Total - Detail'!B19 -> 2 | C18: ='Total - Detail'!C19 -> Field Service Representative | D18: H.3.8 | E18: CONUS | F18: 1814.9998 | G18: =SUM(J18,AA18) -> 0 | H18: =F18-G18 -> 1814.9998 | K18: 35.83 | L18: =L6 -> 0 | M18: =IF($J18>0,IF($L18<$K18,$K18,$L18),0) -> 0 | O18: =O6 -> 0 | P18: =P6 -> 0 | Q18: =Q6 -> 0 | R18: =R6 -> 0 | S18: =S6 -> 0 | T18: =SUM(M18:S18) -> 0 | U18: =(T18-S18)*$U$4 -> 0 | V18: =SUM(T18:U18) -> 0 | W18: =T18*J18 -> 0 | X18: =U18*J18 -> 0 | Y18: =V18*J18 -> 0 | AC18: =IF($AA18>0,$AB18,0) -> 0 | AD18: =(AC18*$AD$4) -> 0 | AE18: =(AC18+AD18)*$AE$4 -> 0 | AG18: =SUM(AC18:AF18) -> 0 | AH18: =$AH$4*(AE18+AC18+AD18) -> 0 | AI18: =SUM(AG18:AH18) -> 0 | AJ18: =AG18*AA18 -> 0 | AK18: =AH18*AA18 -> 0 | AL18: =AI18*AA18 -> 0 | AQ18: =IFERROR(SUM(W18,AJ18)/G18,"") | AR18: =IFERROR(SUM(X18,AK18)/G18,"") | AS18: =SUM(AQ18:AR18) -> 0
B19: ='Total - Detail'!B20 -> 10 | C19: ='Total - Detail'!C20 -> MWO Installer | D19: H.3.6 | E19: CONUS | F19: 23634.598 | G19: =SUM(J19,AA19) -> 0 | H19: =F19-G19 -> 23634.598 | K19: 30.76 | M19: =IF($J19>0,IF($L19<$K19,$K19,$L19),0) -> 0 | O19: =(M19*$O$4) -> 0 | P19: =(O19+M19)*$P$4 -> 0 | Q19: =(M19+O19)*$Q$4 -> 0 | R19: =(O19+M19+P19+Q19)*$R$4 -> 0 | S19: =(M19+O19+P19+Q19+R19)*$S$4 -> 0 | T19: =SUM(M19:S19) -> 0 | U19: =(T19-S19)*$U$4 -> 0 | V19: =SUM(T19:U19) -> 0 | W19: =T19*J19 -> 0 | X19: =U19*J19 -> 0 | Y19: =V19*J19 -> 0 | AC19: =IF($AA19>0,$AB19,0) -> 0 | AD19: =(AC19*$AD$4) -> 0 | AE19: =(AC19+AD19)*$AE$4 -> 0 | AG19: =SUM(AC19:AF19) -> 0 | AH19: =$AH$4*(AE19+AC19+AD19) -> 0 | AI19: =SUM(AG19:AH19) -> 0 | AJ19: =AG19*AA19 -> 0 | AK19: =AH19*AA19 -> 0 | AL19: =AI19*AA19 -> 0 | AQ19: =IFERROR(SUM(W19,AJ19)/G19,"") | AR19: =IFERROR(SUM(X19,AK19)/G19,"") | AS19: =SUM(AQ19:AR19) -> 0
B20: ='Total - Detail'!B21 -> 6 | C20: ='Total - Detail'!C21 -> Inspector | D20: H.3.9 | E20: CONUS | F20: 6135.7994 | G20: =SUM(J20,AA20) -> 0 | H20: =F20-G20 -> 6135.7994 | K20: 24.98 | L20: =L10 -> 0 | M20: =IF($J20>0,IF($L20<$K20,$K20,$L20),0) -> 0 | O20: =O10 -> 0 | P20: =P10 -> 0 | Q20: =Q10 -> 0 | R20: =R10 -> 0 | S20: =S10 -> 0 | T20: =SUM(M20:S20) -> 0 | U20: =(T20-S20)*$U$4 -> 0 | V20: =SUM(T20:U20) -> 0 | W20: =T20*J20 -> 0 | X20: =U20*J20 -> 0 | Y20: =V20*J20 -> 0 | AC20: =IF($AA20>0,$AB20,0) -> 0 | AD20: =(AC20*$AD$4) -> 0 | AE20: =(AC20+AD20)*$AE$4 -> 0 | AG20: =SUM(AC20:AF20) -> 0 | AH20: =$AH$4*(AE20+AC20+AD20) -> 0 | AI20: =SUM(AG20:AH20) -> 0 | AJ20: =AG20*AA20 -> 0 | AK20: =AH20*AA20 -> 0 | AL20: =AI20*AA20 -> 0 | AQ20: =IFERROR(SUM(W20,AJ20)/G20,"") | AR20: =IFERROR(SUM(X20,AK20)/G20,"") | AS20: =SUM(AQ20:AR20) -> 0
B21: ='Total - Detail'!B22 -> 8 | C21: ='Total - Detail'!C22 -> Welder | D21: H.3.5 | E21: CONUS | F21: 4718.9996 | G21: =SUM(J21,AA21) -> 0 | H21: =F21-G21 -> 4718.9996 | K21: 24.52 | L21: =L12 -> 0 | M21: =IF($J21>0,IF($L21<$K21,$K21,$L21),0) -> 0 | O21: =O12 -> 0 | P21: =P12 -> 0 | Q21: =Q12 -> 0 | R21: =R12 -> 0 | S21: =S12 -> 0 | T21: =SUM(M21:S21) -> 0 | U21: =(T21-S21)*$U$4 -> 0 | V21: =SUM(T21:U21) -> 0 | W21: =T21*J21 -> 0 | X21: =U21*J21 -> 0 | Y21: =V21*J21 -> 0 | AC21: =IF($AA21>0,$AB21,0) -> 0 | AD21: =(AC21*$AD$4) -> 0 | AE21: =(AC21+AD21)*$AE$4 -> 0 | AG21: =SUM(AC21:AF21) -> 0 | AH21: =$AH$4*(AE21+AC21+AD21) -> 0 | AI21: =SUM(AG21:AH21) -> 0 | AJ21: =AG21*AA21 -> 0 | AK21: =AH21*AA21 -> 0 | AL21: =AI21*AA21 -> 0 | AQ21: =IFERROR(SUM(W21,AJ21)/G21,"") | AR21: =IFERROR(SUM(X21,AK21)/G21,"") | AS21: =SUM(AQ21:AR21) -> 0
A22: OCONUS | R22: =(O22+M22+P22+Q22)*$R$4 -> 0 | S22: =(M22+O22+P22+Q22+R22)*$S$4 -> 0
A23: Field Service Representative (FSR) | B23: ='Total - Detail'!B24 -> 11 | C23: ='Total - Detail'!C24 -> Field Service Representative | D23: H.3.8 | E23: OCONUS | F23: 6177.7094 | G23: =SUM(J23,AA23) -> 0 | H23: =F23-G23 -> 6177.7094 | K23: 37.6215 | M23: =IF($J23>0,IF($L23<$K23,$K23,$L23),0) -> 0 | N23: =(M23*$N$4) -> 0 | O23: =(M23+N23)*$O$4 -> 0 | P23: =(O23+N23+M23)*$P$4 -> 0 | Q23: =(M23+N23+O23)*$Q$4 -> 0 | R23: =(O23+M23+P23+Q23)*$R$4 -> 0 | S23: =(M23+O23+P23+Q23+R23)*$S$4 -> 0 | T23: =SUM(M23:S23) -> 0 | U23: =(T23-S23)*$U$4 -> 0 | V23: =SUM(T23:U23) -> 0 | W23: =T23*J23 -> 0 | X23: =U23*J23 -> 0 | Y23: =V23*J23 -> 0 | AC23: =IF($AA23>0,$AB23,0) -> 0 | AD23: =(AC23*$AD$4) -> 0 | AE23: =(AC23+AD23)*$AE$4 -> 0 | AG23: =SUM(AC23:AF23) -> 0 | AH23: =$AH$4*(AE23+AC23+AD23) -> 0 | AI23: =SUM(AG23:AH23) -> 0 | AJ23: =AG23*AA23 -> 0 | AK23: =AH23*AA23 -> 0 | AL23: =AI23*AA23 -> 0 | AQ23: =IFERROR(SUM(W23,AJ23)/G23,"") | AR23: =IFERROR(SUM(X23,AK23)/G23,"") | AS23: =SUM(AQ23:AR23) -> 0
B24: ='Total - Detail'!B25 -> 12 | C24: Field Service Mechanic | D24: H.3.9 | E24: OCONUS | F24: 11472.889 | H24: =F24-G24 -> 11472.889 | K24: 32.298 | M24: =IF($J24>0,IF($L24<$K24,$K24,$L24),0) -> 0 | O24: =(M24*$O$4) -> 0 | P24: =(O24+M24)*$P$4 -> 0 | Q24: =(M24+O24)*$Q$4 -> 0 | R24: =(O24+M24+P24+Q24)*$R$4 -> 0 | S24: =(M24+O24+P24+Q24+R24)*$S$4 -> 0 | T24: =SUM(M24:S24) -> 0 | U24: =(T24-S24)*$U$4 -> 0 | V24: =SUM(T24:U24) -> 0 | W24: =T24*J24 -> 0 | X24: =U24*J24 -> 0 | Y24: =V24*J24 -> 0 | AC24: =IF($AA24>0,$AB24,0) -> 0 | AD24: =(AC24*$AD$4) -> 0 | AE24: =(AC24+AD24)*$AE$4 -> 0 | AG24: =SUM(AC24:AF24) -> 0 | AH24: =$AH$4*(AE24+AC24+AD24) -> 0 | AI24: =SUM(AG24:AH24) -> 0 | AJ24: =AG24*AA24 -> 0 | AK24: =AH24*AA24 -> 0 | AL24: =AI24*AA24 -> 0 | AQ24: =IFERROR(SUM(W24,AJ24)/G24,"") | AR24: =IFERROR(SUM(X24,AK24)/G24,"") | AS24: =SUM(AQ24:AR24) -> 0
A25: Deprocessing | B25: ='Total - Detail'!B26 -> 13 | C25: ='Total - Detail'!C26 -> Heavy Equipment Mechanic | D25: H.3.4 | E25: OCONUS | F25: 668.79994 | G25: =SUM(J25,AA25) -> 0 | H25: =F25-G25 -> 668.79994 | K25: 32.298 | M25: =IF($J25>0,IF($L25<$K25,$K25,$L25),0) -> 0 | N25: =(M25*$N$4) -> 0 | O25: =(M25+N25)*$O$4 -> 0 | P25: =(O25+N25+M25)*$P$4 -> 0 | Q25: =(M25+N25+O25)*$Q$4 -> 0 | R25: =(O25+M25+P25+Q25)*$R$4 -> 0 | S25: =(M25+O25+P25+Q25+R25)*$S$4 -> 0 | T25: =SUM(M25:S25) -> 0 | U25: =(T25-S25)*$U$4 -> 0 | V25: =SUM(T25:U25) -> 0 | W25: =T25*J25 -> 0 | X25: =U25*J25 -> 0 | Y25: =V25*J25 -> 0 | AC25: =IF($AA25>0,$AB25,0) -> 0 | AD25: =(AC25*$AD$4) -> 0 | AE25: =(AC25+AD25)*$AE$4 -> 0 | AG25: =SUM(AC25:AF25) -> 0 | AH25: =$AH$4*(AE25+AC25+AD25) -> 0 | AI25: =SUM(AG25:AH25) -> 0 | AJ25: =AG25*AA25 -> 0 | AK25: =AH25*AA25 -> 0 | AL25: =AI25*AA25 -> 0 | AQ25: =IFERROR(SUM(W25,AJ25)/G25,"") | AR25: =IFERROR(SUM(X25,AK25)/G25,"") | AS25: =SUM(AQ25:AR25) -> 0
B26: ='Total - Detail'!B27 -> 14 | C26: ='Total - Detail'!C27 -> Material Handling Specialist | D26: H.3.3 | E26: OCONUS | F26: 2899.5997 | G26: =SUM(J26,AA26) -> 0 | H26: =F26-G26 -> 2899.5997 | K26: 29.169 | M26: =IF($J26>0,IF($L26<$K26,$K26,$L26),0) -> 0 | N26: =(M26*$N$4) -> 0 | O26: =(M26+N26)*$O$4 -> 0 | P26: =(O26+N26+M26)*$P$4 -> 0 | Q26: =(M26+N26+O26)*$Q$4 -> 0 | R26: =(O26+M26+P26+Q26)*$R$4 -> 0 | S26: =(M26+O26+P26+Q26+R26)*$S$4 -> 0 | T26: =SUM(M26:S26) -> 0 | U26: =(T26-S26)*$U$4 -> 0 | V26: =SUM(T26:U26) -> 0 | W26: =T26*J26 -> 0 | X26: =U26*J26 -> 0 | Y26: =V26*J26 -> 0 | AC26: =IF($AA26>0,$AB26,0) -> 0 | AD26: =(AC26*$AD$4) -> 0 | AE26: =(AC26+AD26)*$AE$4 -> 0 | AG26: =SUM(AC26:AF26) -> 0 | AH26: =$AH$4*(AE26+AC26+AD26) -> 0 | AI26: =SUM(AG26:AH26) -> 0 | AJ26: =AG26*AA26 -> 0 | AK26: =AH26*AA26 -> 0 | AL26: =AI26*AA26 -> 0 | AQ26: =IFERROR(SUM(W26,AJ26)/G26,"") | AR26: =IFERROR(SUM(X26,AK26)/G26,"") | AS26: =SUM(AQ26:AR26) -> 0
B27: ='Total - Detail'!B28 -> 15 | C27: ='Total - Detail'!C28 -> Inspector | D27: H.3.10 | E27: OCONUS | F27: 656.69994 | G27: =SUM(J27,AA27) -> 0 | H27: =F27-G27 -> 656.69994 | K27: 26.229 | M27: =IF($J27>0,IF($L27<$K27,$K27,$L27),0) -> 0 | N27: =(M27*$N$4) -> 0 | O27: =(M27+N27)*$O$4 -> 0 | P27: =(O27+N27+M27)*$P$4 -> 0 | Q27: =(M27+N27+O27)*$Q$4 -> 0 | R27: =(O27+M27+P27+Q27)*$R$4 -> 0 | S27: =(M27+O27+P27+Q27+R27)*$S$4 -> 0 | T27: =SUM(M27:S27) -> 0 | U27: =(T27-S27)*$U$4 -> 0 | V27: =SUM(T27:U27) -> 0 | W27: =T27*J27 -> 0 | X27: =U27*J27 -> 0 | Y27: =V27*J27 -> 0 | AC27: =IF($AA27>0,$AB27,0) -> 0 | AD27: =(AC27*$AD$4) -> 0 | AE27: =(AC27+AD27)*$AE$4 -> 0 | AG27: =SUM(AC27:AF27) -> 0 | AH27: =$AH$4*(AE27+AC27+AD27) -> 0 | AI27: =SUM(AG27:AH27) -> 0 | AJ27: =AG27*AA27 -> 0 | AK27: =AH27*AA27 -> 0 | AL27: =AI27*AA27 -> 0 | AQ27: =IFERROR(SUM(W27,AJ27)/G27,"") | AR27: =IFERROR(SUM(X27,AK27)/G27,"") | AS27: =SUM(AQ27:AR27) -> 0
B28: ='Total - Detail'!B29 -> 16 | C28: ='Total - Detail'!C29 -> Supply/Procurement Specialist | D28: H.3.2 | E28: OCONUS | F28: 1449.7999 | G28: =SUM(J28,AA28) -> 0 | H28: =F28-G28 -> 1449.7999 | K28: 37.485 | M28: =IF($J28>0,IF($L28<$K28,$K28,$L28),0) -> 0 | N28: =(M28*$N$4) -> 0 | O28: =(M28+N28)*$O$4 -> 0 | P28: =(O28+N28+M28)*$P$4 -> 0 | Q28: =(M28+N28+O28)*$Q$4 -> 0 | R28: =(O28+M28+P28+Q28)*$R$4 -> 0 | S28: =(M28+O28+P28+Q28+R28)*$S$4 -> 0 | T28: =SUM(M28:S28) -> 0 | U28: =(T28-S28)*$U$4 -> 0 | V28: =SUM(T28:U28) -> 0 | W28: =T28*J28 -> 0 | X28: =U28*J28 -> 0 | Y28: =V28*J28 -> 0 | AC28: =IF($AA28>0,$AB28,0) -> 0 | AD28: =(AC28*$AD$4) -> 0 | AE28: =(AC28+AD28)*$AE$4 -> 0 | AG28: =SUM(AC28:AF28) -> 0 | AH28: =$AH$4*(AE28+AC28+AD28) -> 0 | AI28: =SUM(AG28:AH28) -> 0 | AJ28: =AG28*AA28 -> 0 | AK28: =AH28*AA28 -> 0 | AL28: =AI28*AA28 -> 0 | AQ28: =IFERROR(SUM(W28,AJ28)/G28,"") | AR28: =IFERROR(SUM(X28,AK28)/G28,"") | AS28: =SUM(AQ28:AR28) -> 0
B29: ='Total - Detail'!B30 -> 17 | C29: ='Total - Detail'!C30 -> Welder | D29: H.3.5 | E29: OCONUS | F29: 1129.6999 | G29: =SUM(J29,AA29) -> 0 | H29: =F29-G29 -> 1129.6999 | K29: 25.746 | M29: =IF($J29>0,IF($L29<$K29,$K29,$L29),0) -> 0 | N29: =(M29*$N$4) -> 0 | O29: =(M29+N29)*$O$4 -> 0 | P29: =(O29+N29+M29)*$P$4 -> 0 | Q29: =(M29+N29+O29)*$Q$4 -> 0 | R29: =(O29+M29+P29+Q29)*$R$4 -> 0 | S29: =(M29+O29+P29+Q29+R29)*$S$4 -> 0 | T29: =SUM(M29:S29) -> 0 | U29: =(T29-S29)*$U$4 -> 0 | V29: =SUM(T29:U29) -> 0 | W29: =T29*J29 -> 0 | X29: =U29*J29 -> 0 | Y29: =V29*J29 -> 0 | AC29: =IF($AA29>0,$AB29,0) -> 0 | AD29: =(AC29*$AD$4) -> 0 | AE29: =(AC29+AD29)*$AE$4 -> 0 | AG29: =SUM(AC29:AF29) -> 0 | AH29: =$AH$4*(AE29+AC29+AD29) -> 0 | AI29: =SUM(AG29:AH29) -> 0 | AJ29: =AG29*AA29 -> 0 | AK29: =AH29*AA29 -> 0 | AL29: =AI29*AA29 -> 0 | AQ29: =IFERROR(SUM(W29,AJ29)/G29,"") | AR29: =IFERROR(SUM(X29,AK29)/G29,"") | AS29: =SUM(AQ29:AR29) -> 0
A30: New Equipment Training (NET) / Displaced Equipment Training (DET) | B30: ='Total - Detail'!B31 -> 18 | C30: ='Total - Detail'!C31 -> Instructor | D30: H.3.7 | E30: OCONUS | F30: 3764.1997 | G30: =SUM(J30,AA30) -> 0 | H30: =F30-G30 -> 3764.1997 | K30: 27.1845 | M30: =IF($J30>0,IF($L30<$K30,$K30,$L30),0) -> 0 | N30: =(M30*$N$4) -> 0 | O30: =(M30+N30)*$O$4 -> 0 | P30: =(O30+N30+M30)*$P$4 -> 0 | Q30: =(M30+N30+O30)*$Q$4 -> 0 | R30: =(O30+M30+P30+Q30)*$R$4 -> 0 | S30: =(M30+O30+P30+Q30+R30)*$S$4 -> 0 | T30: =SUM(M30:S30) -> 0 | U30: =(T30-S30)*$U$4 -> 0 | V30: =SUM(T30:U30) -> 0 | W30: =T30*J30 -> 0 | X30: =U30*J30 -> 0 | Y30: =V30*J30 -> 0 | AC30: =IF($AA30>0,$AB30,0) -> 0 | AD30: =(AC30*$AD$4) -> 0 | AE30: =(AC30+AD30)*$AE$4 -> 0 | AG30: =SUM(AC30:AF30) -> 0 | AH30: =$AH$4*(AE30+AC30+AD30) -> 0 | AI30: =SUM(AG30:AH30) -> 0 | AJ30: =AG30*AA30 -> 0 | AK30: =AH30*AA30 -> 0 | AL30: =AI30*AA30 -> 0 | AQ30: =IFERROR(SUM(W30,AJ30)/G30,"") | AR30: =IFERROR(SUM(X30,AK30)/G30,"") | AS30: =SUM(AQ30:AR30) -> 0
A31: Total Package Fielding (TPF) | B31: ='Total - Detail'!B32 -> 13 | C31: ='Total - Detail'!C32 -> Heavy Equipment Mechanic | D31: H.3.4 | E31: OCONUS | F31: 668.79994 | G31: =SUM(J31,AA31) -> 0 | H31: =F31-G31 -> 668.79994 | K31: 32.298 | L31: =L25 -> 0 | M31: =IF($J31>0,IF($L31<$K31,$K31,$L31),0) -> 0 | N31: =N25 -> 0 | O31: =O25 -> 0 | P31: =P25 -> 0 | Q31: =Q25 -> 0 | R31: =R25 -> 0 | S31: =S25 -> 0 | T31: =SUM(M31:S31) -> 0 | U31: =(T31-S31)*$U$4 -> 0 | V31: =SUM(T31:U31) -> 0 | W31: =T31*J31 -> 0 | X31: =U31*J31 -> 0 | Y31: =V31*J31 -> 0 | AC31: =IF($AA31>0,$AB31,0) -> 0 | AD31: =(AC31*$AD$4) -> 0 | AE31: =(AC31+AD31)*$AE$4 -> 0 | AG31: =SUM(AC31:AF31) -> 0 | AH31: =$AH$4*(AE31+AC31+AD31) -> 0 | AI31: =SUM(AG31:AH31) -> 0 | AJ31: =AG31*AA31 -> 0 | AK31: =AH31*AA31 -> 0 | AL31: =AI31*AA31 -> 0 | AQ31: =IFERROR(SUM(W31,AJ31)/G31,"") | AR31: =IFERROR(SUM(X31,AK31)/G31,"") | AS31: =SUM(AQ31:AR31) -> 0
B32: ='Total - Detail'!B33 -> 14 | C32: ='Total - Detail'!C33 -> Material Handling Specialist | D32: H.3.3 | E32: OCONUS | F32: 2899.5997 | G32: =SUM(J32,AA32) -> 0 | H32: =F32-G32 -> 2899.5997 | K32: 29.169 | L32: =L26 -> 0 | M32: =IF($J32>0,IF($L32<$K32,$K32,$L32),0) -> 0 | N32: =N26 -> 0 | O32: =O26 -> 0 | P32: =P26 -> 0 | Q32: =Q26 -> 0 | R32: =R26 -> 0 | S32: =S26 -> 0 | T32: =SUM(M32:S32) -> 0 | U32: =(T32-S32)*$U$4 -> 0 | V32: =SUM(T32:U32) -> 0 | W32: =T32*J32 -> 0 | X32: =U32*J32 -> 0 | Y32: =V32*J32 -> 0 | AC32: =IF($AA32>0,$AB32,0) -> 0 | AD32: =(AC32*$AD$4) -> 0 | AE32: =(AC32+AD32)*$AE$4 -> 0 | AG32: =SUM(AC32:AF32) -> 0 | AH32: =$AH$4*(AE32+AC32+AD32) -> 0 | AI32: =SUM(AG32:AH32) -> 0 | AJ32: =AG32*AA32 -> 0 | AK32: =AH32*AA32 -> 0 | AL32: =AI32*AA32 -> 0 | AQ32: =IFERROR(SUM(W32,AJ32)/G32,"") | AR32: =IFERROR(SUM(X32,AK32)/G32,"") | AS32: =SUM(AQ32:AR32) -> 0
B33: ='Total - Detail'!B34 -> 15 | C33: ='Total - Detail'!C34 -> Inspector | D33: H.3.10 | E33: OCONUS | F33: 656.69994 | G33: =SUM(J33,AA33) -> 0 | H33: =F33-G33 -> 656.69994 | K33: 26.229 | L33: =L27 -> 0 | M33: =IF($J33>0,IF($L33<$K33,$K33,$L33),0) -> 0 | N33: =N27 -> 0 | O33: =O27 -> 0 | P33: =P27 -> 0 | Q33: =Q27 -> 0 | R33: =R27 -> 0 | S33: =S27 -> 0 | T33: =SUM(M33:S33) -> 0 | U33: =(T33-S33)*$U$4 -> 0 | V33: =SUM(T33:U33) -> 0 | W33: =T33*J33 -> 0 | X33: =U33*J33 -> 0 | Y33: =V33*J33 -> 0 | AC33: =IF($AA33>0,$AB33,0) -> 0 | AD33: =(AC33*$AD$4) -> 0 | AE33: =(AC33+AD33)*$AE$4 -> 0 | AG33: =SUM(AC33:AF33) -> 0 | AH33: =$AH$4*(AE33+AC33+AD33) -> 0 | AI33: =SUM(AG33:AH33) -> 0 | AJ33: =AG33*AA33 -> 0 | AK33: =AH33*AA33 -> 0 | AL33: =AI33*AA33 -> 0 | AQ33: =IFERROR(SUM(W33,AJ33)/G33,"") | AR33: =IFERROR(SUM(X33,AK33)/G33,"") | AS33: =SUM(AQ33:AR33) -> 0
B34: ='Total - Detail'!B35 -> 11 | C34: ='Total - Detail'!C35 -> Field Service Representative | D34: H.3.8 | E34: OCONUS | F34: 1449.7999 | G34: =SUM(J34,AA34) -> 0 | H34: =F34-G34 -> 1449.7999 | K34: 32.298 | L34: =L23 -> 0 | M34: =IF($J34>0,IF($L34<$K34,$K34,$L34),0) -> 0 | N34: =N23 -> 0 | O34: =O23 -> 0 | P34: =P23 -> 0 | Q34: =Q23 -> 0 | R34: =R23 -> 0 | S34: =S23 -> 0 | T34: =SUM(M34:S34) -> 0 | U34: =(T34-S34)*$U$4 -> 0 | V34: =SUM(T34:U34) -> 0 | W34: =T34*J34 -> 0 | X34: =U34*J34 -> 0 | Y34: =V34*J34 -> 0 | AC34: =IF($AA34>0,$AB34,0) -> 0 | AD34: =(AC34*$AD$4) -> 0 | AE34: =(AC34+AD34)*$AE$4 -> 0 | AG34: =SUM(AC34:AF34) -> 0 | AH34: =$AH$4*(AE34+AC34+AD34) -> 0 | AI34: =SUM(AG34:AH34) -> 0 | AJ34: =AG34*AA34 -> 0 | AK34: =AH34*AA34 -> 0 | AL34: =AI34*AA34 -> 0 | AQ34: =IFERROR(SUM(W34,AJ34)/G34,"") | AR34: =IFERROR(SUM(X34,AK34)/G34,"") | AS34: =SUM(AQ34:AR34) -> 0
A35: Modification Work Order (MWO) Installation | B35: ='Total - Detail'!B36 -> 11 | C35: ='Total - Detail'!C36 -> Field Service Representative | D35: H.3.8 | E35: OCONUS | F35: 774.39993 | G35: =SUM(J35,AA35) -> 0 | H35: =F35-G35 -> 774.39993 | K35: 32.298 | L35: =L23 -> 0 | M35: =IF($J35>0,IF($L35<$K35,$K35,$L35),0) -> 0 | N35: =N23 -> 0 | O35: =O23 -> 0 | P35: =P23 -> 0 | Q35: =Q23 -> 0 | R35: =R23 -> 0 | S35: =S23 -> 0 | T35: =SUM(M35:S35) -> 0 | U35: =(T35-S35)*$U$4 -> 0 | V35: =SUM(T35:U35) -> 0 | W35: =T35*J35 -> 0 | X35: =U35*J35 -> 0 | Y35: =V35*J35 -> 0 | AC35: =IF($AA35>0,$AB35,0) -> 0 | AD35: =(AC35*$AD$4) -> 0 | AE35: =(AC35+AD35)*$AE$4 -> 0 | AG35: =SUM(AC35:AF35) -> 0 | AH35: =$AH$4*(AE35+AC35+AD35) -> 0 | AI35: =SUM(AG35:AH35) -> 0 | AJ35: =AG35*AA35 -> 0 | AK35: =AH35*AA35 -> 0 | AL35: =AI35*AA35 -> 0 | AQ35: =IFERROR(SUM(W35,AJ35)/G35,"") | AR35: =IFERROR(SUM(X35,AK35)/G35,"") | AS35: =SUM(AQ35:AR35) -> 0
B36: ='Total - Detail'!B37 -> 19 | C36: ='Total - Detail'!C37 -> MWO Installer | D36: H.3.6 | E36: OCONUS | F36: 10084.799 | G36: =SUM(J36,AA36) -> 0 | H36: =F36-G36 -> 10084.799 | K36: 32.298 | M36: =IF($J36>0,IF($L36<$K36,$K36,$L36),0) -> 0 | N36: =(M36*$N$4) -> 0 | O36: =(M36+N36)*$O$4 -> 0 | P36: =(O36+N36+M36)*$P$4 -> 0 | Q36: =(M36+N36+O36)*$Q$4 -> 0 | R36: =(O36+M36+P36+Q36)*$R$4 -> 0 | S36: =(M36+O36+P36+Q36+R36)*$S$4 -> 0 | T36: =SUM(M36:S36) -> 0 | U36: =(T36-S36)*$U$4 -> 0 | V36: =SUM(T36:U36) -> 0 | W36: =T36*J36 -> 0 | X36: =U36*J36 -> 0 | Y36: =V36*J36 -> 0 | AC36: =IF($AA36>0,$AB36,0) -> 0 | AD36: =(AC36*$AD$4) -> 0 | AE36: =(AC36+AD36)*$AE$4 -> 0 | AG36: =SUM(AC36:AF36) -> 0 | AH36: =$AH$4*(AE36+AC36+AD36) -> 0 | AI36: =SUM(AG36:AH36) -> 0 | AJ36: =AG36*AA36 -> 0 | AK36: =AH36*AA36 -> 0 | AL36: =AI36*AA36 -> 0 | AQ36: =IFERROR(SUM(W36,AJ36)/G36,"") | AR36: =IFERROR(SUM(X36,AK36)/G36,"") | AS36: =SUM(AQ36:AR36) -> 0
B37: ='Total - Detail'!B38 -> 15 | C37: ='Total - Detail'!C38 -> Inspector | D37: H.3.10 | E37: OCONUS | F37: 2617.9998 | G37: =SUM(J37,AA37) -> 0 | H37: =F37-G37 -> 2617.9998 | K37: 26.229 | L37: =L27 -> 0 | M37: =IF($J37>0,IF($L37<$K37,$K37,$L37),0) -> 0 | N37: =N27 -> 0 | O37: =O27 -> 0 | P37: =P27 -> 0 | Q37: =Q27 -> 0 | R37: =R27 -> 0 | S37: =S27 -> 0 | T37: =SUM(M37:S37) -> 0 | U37: =(T37-S37)*$U$4 -> 0 | V37: =SUM(T37:U37) -> 0 | W37: =T37*J37 -> 0 | X37: =U37*J37 -> 0 | Y37: =V37*J37 -> 0 | AC37: =IF($AA37>0,$AB37,0) -> 0 | AD37: =(AC37*$AD$4) -> 0 | AE37: =(AC37+AD37)*$AE$4 -> 0 | AG37: =SUM(AC37:AF37) -> 0 | AH37: =$AH$4*(AE37+AC37+AD37) -> 0 | AI37: =SUM(AG37:AH37) -> 0 | AJ37: =AG37*AA37 -> 0 | AK37: =AH37*AA37 -> 0 | AL37: =AI37*AA37 -> 0 | AQ37: =IFERROR(SUM(W37,AJ37)/G37,"") | AR37: =IFERROR(SUM(X37,AK37)/G37,"") | AS37: =SUM(AQ37:AR37) -> 0
B38: ='Total - Detail'!B39 -> 17 | C38: ='Total - Detail'!C39 -> Welder | D38: H.3.5 | E38: OCONUS | F38: 2014.0998 | G38: =SUM(J38,AA38) -> 0 | H38: =F38-G38 -> 2014.0998 | K38: 25.746 | L38: =L29 -> 0 | M38: =IF($J38>0,IF($L38<$K38,$K38,$L38),0) -> 0 | N38: =N29 -> 0 | O38: =O29 -> 0 | P38: =P29 -> 0 | Q38: =Q29 -> 0 | R38: =R29 -> 0 | S38: =S29 -> 0 | T38: =SUM(M38:S38) -> 0 | U38: =(T38-S38)*$U$4 -> 0 | V38: =SUM(T38:U38) -> 0 | W38: =T38*J38 -> 0 | X38: =U38*J38 -> 0 | Y38: =V38*J38 -> 0 | AC38: =IF($AA38>0,$AB38,0) -> 0 | AD38: =(AC38*$AD$4) -> 0 | AE38: =(AC38+AD38)*$AE$4 -> 0 | AG38: =SUM(AC38:AF38) -> 0 | AH38: =$AH$4*(AE38+AC38+AD38) -> 0 | AI38: =SUM(AG38:AH38) -> 0 | AJ38: =AG38*AA38 -> 0 | AK38: =AH38*AA38 -> 0 | AL38: =AI38*AA38 -> 0 | AQ38: =IFERROR(SUM(W38,AJ38)/G38,"") | AR38: =IFERROR(SUM(X38,AK38)/G38,"") | AS38: =SUM(AQ38:AR38) -> 0
E39: CONUS HOURS | F39: =SUM(F5:F21) -> 352457.57 | G39: =SUM(G5:G21) -> 0 | H39: =F39-G39 -> 352457.57
E40: OCONUS HOURS | F40: =SUM(F23:F38) -> 49385.596 | G40: =SUM(G23:G38) -> 0 | H40: =F40-G40 -> 49385.596
...

Sheet Ordering Period 2
A1: Ordering Period 2:
A2: Ordering Period 2 Labor Categories & Hours | J2: Prime Contractor CPFF Labor | Y2: Subcontractor Labor | AO2: Composite FBLR (Prime & Sub)
A3: Service | B3: ID | C3: Labor Category | D3: Reference | E3: Location | F3: Req. Hours | G3: Prop Hours. | H3: Delta (Req. - Prop.) | J3: Prime Hours | K3: Direct Labor (Calculation) | L3: DBA | M3: Fringe Benefit | N3: Labor OH | O3: Other OH | P3: G&A | Q3: FCCOM | R3: Cost | S3: Fee | T3: FBLR | U3: Total Cost | V3: Total Fee | W3: Total Price | Y3: Sub Hours | Z3: Sub FBLR | AA3: Sub FBLR (Calculation) | AB3: Prime OH | AC3: Prime G&A | AD3: Prime FCCOM | AE3: Cost | AF3: Prime Fee | AG3: FBLR (Inclusive of All Prime Adders) | AH3: Total Cost | AI3: Total Fee | AJ3: Total Price | AK3: Name of Subcontractor(s) | AL3: Blended Sub FBLR (Y/N) | AM3: Billing Nomenclature | AO3: CPFF
A4: CONUS | AO4: Cost | AP4: Fee | AQ4: Total
A5: Program Management | B5: ='Total - Detail'!B6 -> 1 | C5: ='Total - Detail'!C6 -> Project Management Specialist | D5: H.3.11 | E5: CONUS | F5: 19114.698 | G5: =SUM(J5,Y5) -> 0 | H5: =F5-G5 -> 19114.698 | K5: ='Ordering Period 1'!M5+('Ordering Period 1'!M5*Escalation!$D$2) -> 0 | M5: =(K5*$M$4) -> 0 | N5: =(M5+K5)*$N$4 -> 0 | O5: =(K5+M5)*$O$4 -> 0 | P5: =(M5+K5+N5+O5)*$P$4 -> 0 | Q5: =(K5+M5+N5+O5+P5)*$Q$4 -> 0 | R5: =SUM(K5:Q5) -> 0 | S5: =(R5-Q5)*$S$4 -> 0 | T5: =SUM(R5:S5) -> 0 | U5: =R5*J5 -> 0 | V5: =S5*J5 -> 0 | W5: =T5*J5 -> 0 | Z5: ='Ordering Period 1'!AC5+('Ordering Period 1'!AC5*Escalation!$D$2) -> 0 | AA5: =IF($Y5>0,$Z5,0) -> 0 | AB5: =(AA5*$AB$4) -> 0 | AC5: =(AA5+AB5)*$AC$4 -> 0 | AE5: =SUM(AA5:AD5) -> 0 | AF5: =$AF$4*(AC5+AA5+AB5) -> 0 | AG5: =SUM(AE5:AF5) -> 0 | AH5: =AE5*Y5 -> 0 | AI5: =AF5*Y5 -> 0 | AJ5: =AG5*Y5 -> 0 | AO5: =IFERROR(SUM(U5,AH5)/G5,"") | AP5: =IFERROR(SUM(V5,AI5)/G5,"") | AQ5: =SUM(AO5:AP5) -> 0 | AR5: =F5/$F$41 -> 0.047567559 | AS5: =AR5*$AV$5 -> 19114.698 | AV5: 401843.16
A6: Field Service Representative (FSR) | B6: ='Total - Detail'!B7 -> 2 | C6: ='Total - Detail'!C7 -> Field Service Representative | D6: H.3.8 | E6: CONUS | F6: 39357.391 | G6: =SUM(J6,Y6) -> 0 | H6: =F6-G6 -> 39357.391 | K6: ='Ordering Period 1'!M6+('Ordering Period 1'!M6*Escalation!$D$2) -> 0 | M6: =(K6*$M$4) -> 0 | N6: =(M6+K6)*$N$4 -> 0 | O6: =(K6+M6)*$O$4 -> 0 | P6: =(M6+K6+N6+O6)*$P$4 -> 0 | Q6: =(K6+M6+N6+O6+P6)*$Q$4 -> 0 | R6: =SUM(K6:Q6) -> 0 | S6: =(R6-Q6)*$S$4 -> 0 | T6: =SUM(R6:S6) -> 0 | U6: =R6*J6 -> 0 | V6: =S6*J6 -> 0 | W6: =T6*J6 -> 0 | Z6: ='Ordering Period 1'!AC6+('Ordering Period 1'!AC6*Escalation!$D$2) -> 0 | AA6: =IF($Y6>0,$Z6,0) -> 0 | AB6: =(AA6*$AB$4) -> 0 | AC6: =(AA6+AB6)*$AC$4 -> 0 | AE6: =SUM(AA6:AD6) -> 0 | AF6: =$AF$4*(AC6+AA6+AB6) -> 0 | AG6: =SUM(AE6:AF6) -> 0 | AH6: =AE6*Y6 -> 0 | AI6: =AF6*Y6 -> 0 | AJ6: =AG6*Y6 -> 0 | AO6: =IFERROR(SUM(U6,AH6)/G6,"") | AP6: =IFERROR(SUM(V6,AI6)/G6,"") | AQ6: =SUM(AO6:AP6) -> 0 | AR6: =F6/$F$41 -> 0.09794217 | AS6: =AR6*$AV$5 -> 39357.391
B7: ='Total - Detail'!B8 -> 3 | C7: ='Total - Detail'!C8 -> Field Service Mechanic | D7: H.3.9 | E7: CONUS | F7: 73092.298 | H7: =F7-G7 -> 73092.298 | M7: =(K7*$M$4) -> 0 | N7: =(M7+K7)*$N$4 -> 0 | O7: =(K7+M7)*$O$4 -> 0 | P7: =(M7+K7+N7+O7)*$P$4 -> 0 | Q7: =(K7+M7+N7+O7+P7)*$Q$4 -> 0 | R7: =SUM(K7:Q7) -> 0 | S7: =(R7-Q7)*$S$4 -> 0 | T7: =SUM(R7:S7) -> 0 | U7: =R7*J7 -> 0 | V7: =S7*J7 -> 0 | W7: =T7*J7 -> 0 | Z7: ='Ordering Period 1'!AC7+('Ordering Period 1'!AC7*Escalation!$D$2) -> 0 | AA7: =IF($Y7>0,$Z7,0) -> 0 | AB7: =(AA7*$AB$4) -> 0 | AC7: =(AA7+AB7)*$AC$4 -> 0 | AE7: =SUM(AA7:AD7) -> 0 | AF7: =$AF$4*(AC7+AA7+AB7) -> 0 | AG7: =SUM(AE7:AF7) -> 0 | AH7: =AE7*Y7 -> 0 | AI7: =AF7*Y7 -> 0 | AJ7: =AG7*Y7 -> 0 | AO7: =IFERROR(SUM(U7,AH7)/G7,"") | AP7: =IFERROR(SUM(V7,AI7)/G7,"") | AQ7: =SUM(AO7:AP7) -> 0 | AR7: =F7/$F$41 -> 0.1818926 | AS7: =AR7*$AV$5 -> 73092.298
A8: Deprocessing | B8: ='Total - Detail'!B9 -> 4 | C8: ='Total - Detail'!C9 -> Heavy Equipment Mechanic | D8: H.3.4 | E8: CONUS | F8: 96564.591 | G8: =SUM(J8,Y8) -> 0 | H8: =F8-G8 -> 96564.591 | K8: ='Ordering Period 1'!M8+('Ordering Period 1'!M8*Escalation!$D$2) -> 0 | M8: =(K8*$M$4) -> 0 | N8: =(M8+K8)*$N$4 -> 0 | O8: =(K8+M8)*$O$4 -> 0 | P8: =(M8+K8+N8+O8)*$P$4 -> 0 | Q8: =(K8+M8+N8+O8+P8)*$Q$4 -> 0 | R8: =SUM(K8:Q8) -> 0 | S8: =(R8-Q8)*$S$4 -> 0 | T8: =SUM(R8:S8) -> 0 | U8: =R8*J8 -> 0 | V8: =S8*J8 -> 0 | W8: =T8*J8 -> 0 | Z8: ='Ordering Period 1'!AC8+('Ordering Period 1'!AC8*Escalation!$D$2) -> 0 | AA8: =IF($Y8>0,$Z8,0) -> 0 | AB8: =(AA8*$AB$4) -> 0 | AC8: =(AA8+AB8)*$AC$4 -> 0 | AE8: =SUM(AA8:AD8) -> 0 | AF8: =$AF$4*(AC8+AA8+AB8) -> 0 | AG8: =SUM(AE8:AF8) -> 0 | AH8: =AE8*Y8 -> 0 | AI8: =AF8*Y8 -> 0 | AJ8: =AG8*Y8 -> 0 | AO8: =IFERROR(SUM(U8,AH8)/G8,"") | AP8: =IFERROR(SUM(V8,AI8)/G8,"") | AQ8: =SUM(AO8:AP8) -> 0 | AR8: =F8/$F$41 -> 0.24030418 | AS8: =AR8*$AV$5 -> 96564.591
