Workbook

Sheet ALL Other SINs - Proposal
F1: Product Information | S1: MFC Information | V1: TC Information | AA1: FSS Information
A2: SIN# | B2: NDC 1 or Item # | C2: NDC2 (4 digits only - Add leading 0 if necessary) | D2: NDC3 | E2: Type "YES" if item is handled by Specialty Distrib. | F2: Generic Name / Strength | G2: Trade Name / Strength | H2: Package Size | I2: Unit of Sale | J2: Quantity in Unit of Sale | K2: Unit Pkg | L2: Quantity in Unit Pkg | M2: Unit of Measure | N2: FDA Application Number | O2: Country of Origin (See Country Codes Tab) | P2: Total (comm. & gov’t) units sold during Prior Fiscal Year (or a more recent 12-month period) | Q2: Total (comm. & gov’t) sales ($) during Prior Fiscal Year (or a more recent 12-month period) | R2: Commercial List Price ($) | S2: MFC Price ($) | T2: MFC % Off Comm. List Price | U2: MFC Name | V2: Proposed Tracking Customer (TC) Name | W2: Proposed TC Price ($) | X2: TC % Off Comm. List Price | Y2: Total sales ($) to Proposed TC during Prior Fiscal Year (or a more recent 12-month period) | Z2: Total Gov't sales (FSS & open market) ($) during Prior Fiscal Year (or a more recent 12-month period) | AA2: Proposed FSS Price ($) without IFF | AB2: Proposed FSS % Off Comm. List Price w/out IFF | AC2: Proposed FSS Price ($) with IFF | AI2: TC<=MFC Price | AJ2: Proposed TC Ratio
T3: =IF(ISBLANK(R3)," ",((ROUND(S3,2)-(ROUND(R3,2)))/(ROUND(R3,2)))) | X3: =IF(ISBLANK(R3)," ",((ROUND(W3,2))-(ROUND(R3,2)))/(ROUND(R3,2))) | AB3: =IF(ISBLANK(R3)," ",((ROUND(AA3,2))-(ROUND(R3,2)))/(ROUND(R3,2))) | AC3: =IF(ISBLANK(AA3)," ",(ROUND(AA3,2)/0.995)) | AI3: =IF(W3<=S3,"TC Better Price","MFC Better Price") -> TC Better Price | AJ3: =IF(W3=0,"",(#REF!/W3))
T4: =IF(ISBLANK(R4)," ",((ROUND(S4,2)-(ROUND(R4,2)))/(ROUND(R4,2)))) | X4: =IF(ISBLANK(R4)," ",((ROUND(W4,2))-(ROUND(R4,2)))/(ROUND(R4,2))) | AB4: =IF(ISBLANK(R4)," ",((ROUND(AA4,2))-(ROUND(R4,2)))/(ROUND(R4,2))) | AC4: =IF(ISBLANK(AA4)," ",(ROUND(AA4,2)/0.995)) | AD4: 42-1 | AI4: =IF(W4<=S4,"TC Better Price","MFC Better Price") -> TC Better Price | AJ4: =IF(W4=0,"",(#REF!/W4))
T5: =IF(ISBLANK(R5)," ",((ROUND(S5,2)-(ROUND(R5,2)))/(ROUND(R5,2)))) | X5: =IF(ISBLANK(R5)," ",((ROUND(W5,2))-(ROUND(R5,2)))/(ROUND(R5,2))) | AB5: =IF(ISBLANK(R5)," ",((ROUND(AA5,2))-(ROUND(R5,2)))/(ROUND(R5,2))) | AC5: =IF(ISBLANK(AA5)," ",(ROUND(AA5,2)/0.995)) | AD5: 42-2B | AI5: =IF(W5<=S5,"TC Better Price","MFC Better Price") -> TC Better Price | AJ5: =IF(W5=0,"",(#REF!/W5))
T6: =IF(ISBLANK(R6)," ",((ROUND(S6,2)-(ROUND(R6,2)))/(ROUND(R6,2)))) | X6: =IF(ISBLANK(R6)," ",((ROUND(W6,2))-(ROUND(R6,2)))/(ROUND(R6,2))) | AB6: =IF(ISBLANK(R6)," ",((ROUND(AA6,2))-(ROUND(R6,2)))/(ROUND(R6,2))) | AC6: =IF(ISBLANK(AA6)," ",(ROUND(AA6,2)/0.995)) | AD6: 42-3 | AI6: =IF(W6<=S6,"TC Better Price","MFC Better Price") -> TC Better Price | AJ6: =IF(W6=0,"",(#REF!/W6))
T7: =IF(ISBLANK(R7)," ",((ROUND(S7,2)-(ROUND(R7,2)))/(ROUND(R7,2)))) | X7: =IF(ISBLANK(R7)," ",((ROUND(W7,2))-(ROUND(R7,2)))/(ROUND(R7,2))) | AB7: =IF(ISBLANK(R7)," ",((ROUND(AA7,2))-(ROUND(R7,2)))/(ROUND(R7,2))) | AC7: =IF(ISBLANK(AA7)," ",(ROUND(AA7,2)/0.995)) | AD7: 42-5 | AI7: =IF(W7<=S7,"TC Better Price","MFC Better Price") -> TC Better Price | AJ7: =IF(W7=0,"",(#REF!/W7)) | AQ7: AM | AR7: EA
T8: =IF(ISBLANK(R8)," ",((ROUND(S8,2)-(ROUND(R8,2)))/(ROUND(R8,2)))) | X8: =IF(ISBLANK(R8)," ",((ROUND(W8,2))-(ROUND(R8,2)))/(ROUND(R8,2))) | AB8: =IF(ISBLANK(R8)," ",((ROUND(AA8,2))-(ROUND(R8,2)))/(ROUND(R8,2))) | AC8: =IF(ISBLANK(AA8)," ",(ROUND(AA8,2)/0.995)) | AD8: 622 | AI8: =IF(W8<=S8,"TC Better Price","MFC Better Price") -> TC Better Price | AJ8: =IF(W8=0,"",(#REF!/W8)) | AP8: 42-2B | AQ8: BG | AR8: F2
T9: =IF(ISBLANK(R9)," ",((ROUND(S9,2)-(ROUND(R9,2)))/(ROUND(R9,2)))) | X9: =IF(ISBLANK(R9)," ",((ROUND(W9,2))-(ROUND(R9,2)))/(ROUND(R9,2))) | AB9: =IF(ISBLANK(R9)," ",((ROUND(AA9,2))-(ROUND(R9,2)))/(ROUND(R9,2))) | AC9: =IF(ISBLANK(AA9)," ",(ROUND(AA9,2)/0.995)) | AD9: INP | AI9: =IF(W9<=S9,"TC Better Price","MFC Better Price") -> TC Better Price | AJ9: =IF(W9=0,"",(#REF!/W9)) | AP9: 42-1 | AQ9: BO | AR9: GM
T10: =IF(ISBLANK(R10)," ",((ROUND(S10,2)-(ROUND(R10,2)))/(ROUND(R10,2)))) | X10: =IF(ISBLANK(R10)," ",((ROUND(W10,2))-(ROUND(R10,2)))/(ROUND(R10,2))) | AB10: =IF(ISBLANK(R10)," ",((ROUND(AA10,2))-(ROUND(R10,2)))/(ROUND(R10,2))) | AC10: =IF(ISBLANK(AA10)," ",(ROUND(AA10,2)/0.995)) | AI10: =IF(W10<=S10,"TC Better Price","MFC Better Price") -> TC Better Price | AJ10: =IF(W10=0,"",(#REF!/W10)) | AP10: 42-3 | AQ10: BX | AR10: IN
T11: =IF(ISBLANK(R11)," ",((ROUND(S11,2)-(ROUND(R11,2)))/(ROUND(R11,2)))) | X11: =IF(ISBLANK(R11)," ",((ROUND(W11,2))-(ROUND(R11,2)))/(ROUND(R11,2))) | AB11: =IF(ISBLANK(R11)," ",((ROUND(AA11,2))-(ROUND(R11,2)))/(ROUND(R11,2))) | AC11: =IF(ISBLANK(AA11)," ",(ROUND(AA11,2)/0.995)) | AI11: =IF(W11<=S11,"TC Better Price","MFC Better Price") -> TC Better Price | AJ11: =IF(W11=0,"",(#REF!/W11)) | AP11: 42-5 | AQ11: CA | AR11: LT
T12: =IF(ISBLANK(R12)," ",((ROUND(S12,2)-(ROUND(R12,2)))/(ROUND(R12,2)))) | X12: =IF(ISBLANK(R12)," ",((ROUND(W12,2))-(ROUND(R12,2)))/(ROUND(R12,2))) | AB12: =IF(ISBLANK(R12)," ",((ROUND(AA12,2))-(ROUND(R12,2)))/(ROUND(R12,2))) | AC12: =IF(ISBLANK(AA12)," ",(ROUND(AA12,2)/0.995)) | AI12: =IF(W12<=S12,"TC Better Price","MFC Better Price") -> TC Better Price | AJ12: =IF(W12=0,"",(#REF!/W12)) | AP12: 622 | AQ12: CH | AR12: ML
T13: =IF(ISBLANK(R13)," ",((ROUND(S13,2)-(ROUND(R13,2)))/(ROUND(R13,2)))) | X13: =IF(ISBLANK(R13)," ",((ROUND(W13,2))-(ROUND(R13,2)))/(ROUND(R13,2))) | AB13: =IF(ISBLANK(R13)," ",((ROUND(AA13,2))-(ROUND(R13,2)))/(ROUND(R13,2))) | AC13: =IF(ISBLANK(AA13)," ",(ROUND(AA13,2)/0.995)) | AI13: =IF(W13<=S13,"TC Better Price","MFC Better Price") -> TC Better Price | AJ13: =IF(W13=0,"",(#REF!/W13)) | AP13: INP | AQ13: CL
T14: =IF(ISBLANK(R14)," ",((ROUND(S14,2)-(ROUND(R14,2)))/(ROUND(R14,2)))) | X14: =IF(ISBLANK(R14)," ",((ROUND(W14,2))-(ROUND(R14,2)))/(ROUND(R14,2))) | AB14: =IF(ISBLANK(R14)," ",((ROUND(AA14,2))-(ROUND(R14,2)))/(ROUND(R14,2))) | AC14: =IF(ISBLANK(AA14)," ",(ROUND(AA14,2)/0.995)) | AI14: =IF(W14<=S14,"TC Better Price","MFC Better Price") -> TC Better Price | AJ14: =IF(W14=0,"",(#REF!/W14)) | AQ14: CN
T15: =IF(ISBLANK(R15)," ",((ROUND(S15,2)-(ROUND(R15,2)))/(ROUND(R15,2)))) | X15: =IF(ISBLANK(R15)," ",((ROUND(W15,2))-(ROUND(R15,2)))/(ROUND(R15,2))) | AB15: =IF(ISBLANK(R15)," ",((ROUND(AA15,2))-(ROUND(R15,2)))/(ROUND(R15,2))) | AC15: =IF(ISBLANK(AA15)," ",(ROUND(AA15,2)/0.995)) | AI15: =IF(W15<=S15,"TC Better Price","MFC Better Price") -> TC Better Price | AJ15: =IF(W15=0,"",(#REF!/W15)) | AQ15: CQ
T16: =IF(ISBLANK(R16)," ",((ROUND(S16,2)-(ROUND(R16,2)))/(ROUND(R16,2)))) | X16: =IF(ISBLANK(R16)," ",((ROUND(W16,2))-(ROUND(R16,2)))/(ROUND(R16,2))) | AB16: =IF(ISBLANK(R16)," ",((ROUND(AA16,2))-(ROUND(R16,2)))/(ROUND(R16,2))) | AC16: =IF(ISBLANK(AA16)," ",(ROUND(AA16,2)/0.995)) | AI16: =IF(W16<=S16,"TC Better Price","MFC Better Price") -> TC Better Price | AJ16: =IF(W16=0,"",(#REF!/W16)) | AQ16: CT
T17: =IF(ISBLANK(R17)," ",((ROUND(S17,2)-(ROUND(R17,2)))/(ROUND(R17,2)))) | X17: =IF(ISBLANK(R17)," ",((ROUND(W17,2))-(ROUND(R17,2)))/(ROUND(R17,2))) | AB17: =IF(ISBLANK(R17)," ",((ROUND(AA17,2))-(ROUND(R17,2)))/(ROUND(R17,2))) | AC17: =IF(ISBLANK(AA17)," ",(ROUND(AA17,2)/0.995)) | AI17: =IF(W17<=S17,"TC Better Price","MFC Better Price") -> TC Better Price | AJ17: =IF(W17=0,"",(#REF!/W17)) | AQ17: DR
T18: =IF(ISBLANK(R18)," ",((ROUND(S18,2)-(ROUND(R18,2)))/(ROUND(R18,2)))) | X18: =IF(ISBLANK(R18)," ",((ROUND(W18,2))-(ROUND(R18,2)))/(ROUND(R18,2))) | AB18: =IF(ISBLANK(R18)," ",((ROUND(AA18,2))-(ROUND(R18,2)))/(ROUND(R18,2))) | AC18: =IF(ISBLANK(AA18)," ",(ROUND(AA18,2)/0.995)) | AI18: =IF(W18<=S18,"TC Better Price","MFC Better Price") -> TC Better Price | AJ18: =IF(W18=0,"",(#REF!/W18)) | AQ18: EA
T19: =IF(ISBLANK(R19)," ",((ROUND(S19,2)-(ROUND(R19,2)))/(ROUND(R19,2)))) | X19: =IF(ISBLANK(R19)," ",((ROUND(W19,2))-(ROUND(R19,2)))/(ROUND(R19,2))) | AB19: =IF(ISBLANK(R19)," ",((ROUND(AA19,2))-(ROUND(R19,2)))/(ROUND(R19,2))) | AC19: =IF(ISBLANK(AA19)," ",(ROUND(AA19,2)/0.995)) | AI19: =IF(W19<=S19,"TC Better Price","MFC Better Price") -> TC Better Price | AJ19: =IF(W19=0,"",(#REF!/W19)) | AQ19: KT
T20: =IF(ISBLANK(R20)," ",((ROUND(S20,2)-(ROUND(R20,2)))/(ROUND(R20,2)))) | X20: =IF(ISBLANK(R20)," ",((ROUND(W20,2))-(ROUND(R20,2)))/(ROUND(R20,2))) | AB20: =IF(ISBLANK(R20)," ",((ROUND(AA20,2))-(ROUND(R20,2)))/(ROUND(R20,2))) | AC20: =IF(ISBLANK(AA20)," ",(ROUND(AA20,2)/0.995)) | AI20: =IF(W20<=S20,"TC Better Price","MFC Better Price") -> TC Better Price | AJ20: =IF(W20=0,"",(#REF!/W20)) | AQ20: PC
T21: =IF(ISBLANK(R21)," ",((ROUND(S21,2)-(ROUND(R21,2)))/(ROUND(R21,2)))) | X21: =IF(ISBLANK(R21)," ",((ROUND(W21,2))-(ROUND(R21,2)))/(ROUND(R21,2))) | AB21: =IF(ISBLANK(R21)," ",((ROUND(AA21,2))-(ROUND(R21,2)))/(ROUND(R21,2))) | AC21: =IF(ISBLANK(AA21)," ",(ROUND(AA21,2)/0.995)) | AI21: =IF(W21<=S21,"TC Better Price","MFC Better Price") -> TC Better Price | AJ21: =IF(W21=0,"",(#REF!/W21)) | AQ21: PK
T22: =IF(ISBLANK(R22)," ",((ROUND(S22,2)-(ROUND(R22,2)))/(ROUND(R22,2)))) | X22: =IF(ISBLANK(R22)," ",((ROUND(W22,2))-(ROUND(R22,2)))/(ROUND(R22,2))) | AB22: =IF(ISBLANK(R22)," ",((ROUND(AA22,2))-(ROUND(R22,2)))/(ROUND(R22,2))) | AC22: =IF(ISBLANK(AA22)," ",(ROUND(AA22,2)/0.995)) | AI22: =IF(W22<=S22,"TC Better Price","MFC Better Price") -> TC Better Price | AJ22: =IF(W22=0,"",(#REF!/W22)) | AQ22: RL
T23: =IF(ISBLANK(R23)," ",((ROUND(S23,2)-(ROUND(R23,2)))/(ROUND(R23,2)))) | X23: =IF(ISBLANK(R23)," ",((ROUND(W23,2))-(ROUND(R23,2)))/(ROUND(R23,2))) | AB23: =IF(ISBLANK(R23)," ",((ROUND(AA23,2))-(ROUND(R23,2)))/(ROUND(R23,2))) | AC23: =IF(ISBLANK(AA23)," ",(ROUND(AA23,2)/0.995)) | AI23: =IF(W23<=S23,"TC Better Price","MFC Better Price") -> TC Better Price | AJ23: =IF(W23=0,"",(#REF!/W23)) | AQ23: TB
T24: =IF(ISBLANK(R24)," ",((ROUND(S24,2)-(ROUND(R24,2)))/(ROUND(R24,2)))) | X24: =IF(ISBLANK(R24)," ",((ROUND(W24,2))-(ROUND(R24,2)))/(ROUND(R24,2))) | AB24: =IF(ISBLANK(R24)," ",((ROUND(AA24,2))-(ROUND(R24,2)))/(ROUND(R24,2))) | AC24: =IF(ISBLANK(AA24)," ",(ROUND(AA24,2)/0.995)) | AI24: =IF(W24<=S24,"TC Better Price","MFC Better Price") -> TC Better Price | AJ24: =IF(W24=0,"",(#REF!/W24)) | AQ24: VI
T25: =IF(ISBLANK(R25)," ",((ROUND(S25,2)-(ROUND(R25,2)))/(ROUND(R25,2)))) | X25: =IF(ISBLANK(R25)," ",((ROUND(W25,2))-(ROUND(R25,2)))/(ROUND(R25,2))) | AB25: =IF(ISBLANK(R25)," ",((ROUND(AA25,2))-(ROUND(R25,2)))/(ROUND(R25,2))) | AC25: =IF(ISBLANK(AA25)," ",(ROUND(AA25,2)/0.995)) | AI25: =IF(W25<=S25,"TC Better Price","MFC Better Price") -> TC Better Price | AJ25: =IF(W25=0,"",(#REF!/W25))
T26: =IF(ISBLANK(R26)," ",((ROUND(S26,2)-(ROUND(R26,2)))/(ROUND(R26,2)))) | X26: =IF(ISBLANK(R26)," ",((ROUND(W26,2))-(ROUND(R26,2)))/(ROUND(R26,2))) | AB26: =IF(ISBLANK(R26)," ",((ROUND(AA26,2))-(ROUND(R26,2)))/(ROUND(R26,2))) | AC26: =IF(ISBLANK(AA26)," ",(ROUND(AA26,2)/0.995)) | AI26: =IF(W26<=S26,"TC Better Price","MFC Better Price") -> TC Better Price | AJ26: =IF(W26=0,"",(#REF!/W26))
T27: =IF(ISBLANK(R27)," ",((ROUND(S27,2)-(ROUND(R27,2)))/(ROUND(R27,2)))) | X27: =IF(ISBLANK(R27)," ",((ROUND(W27,2))-(ROUND(R27,2)))/(ROUND(R27,2))) | AB27: =IF(ISBLANK(R27)," ",((ROUND(AA27,2))-(ROUND(R27,2)))/(ROUND(R27,2))) | AC27: =IF(ISBLANK(AA27)," ",(ROUND(AA27,2)/0.995)) | AI27: =IF(W27<=S27,"TC Better Price","MFC Better Price") -> TC Better Price | AJ27: =IF(W27=0,"",(#REF!/W27))
T28: =IF(ISBLANK(R28)," ",((ROUND(S28,2)-(ROUND(R28,2)))/(ROUND(R28,2)))) | X28: =IF(ISBLANK(R28)," ",((ROUND(W28,2))-(ROUND(R28,2)))/(ROUND(R28,2))) | AB28: =IF(ISBLANK(R28)," ",((ROUND(AA28,2))-(ROUND(R28,2)))/(ROUND(R28,2))) | AC28: =IF(ISBLANK(AA28)," ",(ROUND(AA28,2)/0.995)) | AI28: =IF(W28<=S28,"TC Better Price","MFC Better Price") -> TC Better Price | AJ28: =IF(W28=0,"",(#REF!/W28))
T29: =IF(ISBLANK(R29)," ",((ROUND(S29,2)-(ROUND(R29,2)))/(ROUND(R29,2)))) | X29: =IF(ISBLANK(R29)," ",((ROUND(W29,2))-(ROUND(R29,2)))/(ROUND(R29,2))) | AB29: =IF(ISBLANK(R29)," ",((ROUND(AA29,2))-(ROUND(R29,2)))/(ROUND(R29,2))) | AC29: =IF(ISBLANK(AA29)," ",(ROUND(AA29,2)/0.995)) | AI29: =IF(W29<=S29,"TC Better Price","MFC Better Price") -> TC Better Price | AJ29: =IF(W29=0,"",(#REF!/W29))
T30: =IF(ISBLANK(R30)," ",((ROUND(S30,2)-(ROUND(R30,2)))/(ROUND(R30,2)))) | X30: =IF(ISBLANK(R30)," ",((ROUND(W30,2))-(ROUND(R30,2)))/(ROUND(R30,2))) | AB30: =IF(ISBLANK(R30)," ",((ROUND(AA30,2))-(ROUND(R30,2)))/(ROUND(R30,2))) | AC30: =IF(ISBLANK(AA30)," ",(ROUND(AA30,2)/0.995)) | AI30: =IF(W30<=S30,"TC Better Price","MFC Better Price") -> TC Better Price | AJ30: =IF(W30=0,"",(#REF!/W30))
T31: =IF(ISBLANK(R31)," ",((ROUND(S31,2)-(ROUND(R31,2)))/(ROUND(R31,2)))) | X31: =IF(ISBLANK(R31)," ",((ROUND(W31,2))-(ROUND(R31,2)))/(ROUND(R31,2))) | AB31: =IF(ISBLANK(R31)," ",((ROUND(AA31,2))-(ROUND(R31,2)))/(ROUND(R31,2))) | AC31: =IF(ISBLANK(AA31)," ",(ROUND(AA31,2)/0.995)) | AI31: =IF(W31<=S31,"TC Better Price","MFC Better Price") -> TC Better Price | AJ31: =IF(W31=0,"",(#REF!/W31))
T32: =IF(ISBLANK(R32)," ",((ROUND(S32,2)-(ROUND(R32,2)))/(ROUND(R32,2)))) | X32: =IF(ISBLANK(R32)," ",((ROUND(W32,2))-(ROUND(R32,2)))/(ROUND(R32,2))) | AB32: =IF(ISBLANK(R32)," ",((ROUND(AA32,2))-(ROUND(R32,2)))/(ROUND(R32,2))) | AC32: =IF(ISBLANK(AA32)," ",(ROUND(AA32,2)/0.995)) | AI32: =IF(W32<=S32,"TC Better Price","MFC Better Price") -> TC Better Price | AJ32: =IF(W32=0,"",(#REF!/W32))
T33: =IF(ISBLANK(R33)," ",((ROUND(S33,2)-(ROUND(R33,2)))/(ROUND(R33,2)))) | X33: =IF(ISBLANK(R33)," ",((ROUND(W33,2))-(ROUND(R33,2)))/(ROUND(R33,2))) | AB33: =IF(ISBLANK(R33)," ",((ROUND(AA33,2))-(ROUND(R33,2)))/(ROUND(R33,2))) | AC33: =IF(ISBLANK(AA33)," ",(ROUND(AA33,2)/0.995)) | AI33: =IF(W33<=S33,"TC Better Price","MFC Better Price") -> TC Better Price | AJ33: =IF(W33=0,"",(#REF!/W33))
T34: =IF(ISBLANK(R34)," ",((ROUND(S34,2)-(ROUND(R34,2)))/(ROUND(R34,2)))) | X34: =IF(ISBLANK(R34)," ",((ROUND(W34,2))-(ROUND(R34,2)))/(ROUND(R34,2))) | AB34: =IF(ISBLANK(R34)," ",((ROUND(AA34,2))-(ROUND(R34,2)))/(ROUND(R34,2))) | AC34: =IF(ISBLANK(AA34)," ",(ROUND(AA34,2)/0.995)) | AI34: =IF(W34<=S34,"TC Better Price","MFC Better Price") -> TC Better Price | AJ34: =IF(W34=0,"",(#REF!/W34))
T35: =IF(ISBLANK(R35)," ",((ROUND(S35,2)-(ROUND(R35,2)))/(ROUND(R35,2)))) | X35: =IF(ISBLANK(R35)," ",((ROUND(W35,2))-(ROUND(R35,2)))/(ROUND(R35,2))) | AB35: =IF(ISBLANK(R35)," ",((ROUND(AA35,2))-(ROUND(R35,2)))/(ROUND(R35,2))) | AC35: =IF(ISBLANK(AA35)," ",(ROUND(AA35,2)/0.995)) | AI35: =IF(W35<=S35,"TC Better Price","MFC Better Price") -> TC Better Price | AJ35: =IF(W35=0,"",(#REF!/W35))
T36: =IF(ISBLANK(R36)," ",((ROUND(S36,2)-(ROUND(R36,2)))/(ROUND(R36,2)))) | X36: =IF(ISBLANK(R36)," ",((ROUND(W36,2))-(ROUND(R36,2)))/(ROUND(R36,2))) | AB36: =IF(ISBLANK(R36)," ",((ROUND(AA36,2))-(ROUND(R36,2)))/(ROUND(R36,2))) | AC36: =IF(ISBLANK(AA36)," ",(ROUND(AA36,2)/0.995)) | AI36: =IF(W36<=S36,"TC Better Price","MFC Better Price") -> TC Better Price | AJ36: =IF(W36=0,"",(#REF!/W36))
... T300: =IF(ISBLANK(R300)," ",((ROUND(S300,2)-(ROUND(R300,2)))/(ROUND(R300,2)))) | X300: =IF(ISBLANK(R300)," ",((ROUND(W300,2))-(ROUND(R300,2)))/(ROUND(R300,2))) | AB300: =IF(ISBLANK(R300)," ",((ROUND(AA300,2))-(ROUND(R300,2)))/(ROUND(R300,2))) | AC300: =IF(ISBLANK(AA300)," ",(ROUND(AA300,2)/0.995)) | AI300: =IF(W300<=S300,"TC Better Price","MFC Better Price") -> TC Better Price | AJ300: =IF(W300=0,"",(#REF!/W300))
T301: =IF(ISBLANK(R301)," ",((ROUND(S301,2)-(ROUND(R301,2)))/(ROUND(R301,2)))) | X301: =IF(ISBLANK(R301)," ",((ROUND(W301,2))-(ROUND(R301,2)))/(ROUND(R301,2))) | AB301: =IF(ISBLANK(R301)," ",((ROUND(AA301,2))-(ROUND(R301,2)))/(ROUND(R301,2))) | AC301: =IF(ISBLANK(AA301)," ",(ROUND(AA301,2)/0.995))
T302: =IF(ISBLANK(R302)," ",((ROUND(S302,2)-(ROUND(R302,2)))/(ROUND(R302,2)))) | X302: =IF(ISBLANK(R302)," ",((ROUND(W302,2))-(ROUND(R302,2)))/(ROUND(R302,2))) | AB302: =IF(ISBLANK(R302)," ",((ROUND(AA302,2))-(ROUND(R302,2)))/(ROUND(R302,2))) | AC302: =IF(ISBLANK(AA302)," ",(ROUND(AA302,2)/0.995))
T303: =IF(ISBLANK(R303)," ",((ROUND(S303,2)-(ROUND(R303,2)))/(ROUND(R303,2)))) | X303: =IF(ISBLANK(R303)," ",((ROUND(W303,2))-(ROUND(R303,2)))/(ROUND(R303,2))) | AB303: =IF(ISBLANK(R303)," ",((ROUND(AA303,2))-(ROUND(R303,2)))/(ROUND(R303,2))) | AC303: =IF(ISBLANK(AA303)," ",(ROUND(AA303,2)/0.995))
...

Sheet Definitions & Examples
A2: Column G - Package Size: Quantity in Unit of Sale x Quantity in Unit of Package
A4: Columns H & J - Unit of Sale & Unit Package | D4: Column L - Unit of Measure
A5: AM | B5: Ampule | D5: EA | E5: Each
A6: BG | B6: Bag | D6: F2 | E6: Square Feet
A7: BO | B7: Bottle | D7: GM | E7: Gram
A8: BX | B8: Box | D8: IN | E8: Inch
A9: CA | B9: Case | D9: LT | E9: Liter
A10: CH | B10: Container | D10: ML | E10: Milliliter
A11: CL | B11: Cylinder
A12: CN | B12: Can
A13: CQ | B13: Cartridge
A14: CT | B14: Carton
A15: DR | B15: Drum
A16: EA | B16: Each
A17: KT | B17: Kit
A18: PC | B18: Piece
A19: PK | B19: Package
A20: RL | B20: Roll
A21: TB | B21: Tube
A22: VI | B22: Vial
A24: EXAMPLES:
A25: Note: There is no column for strength. It is to be included with the generic and trade names.
A26: Generic Name / Strength | B26: Trade Name / Strength | C26: Package Size | D26: Unit of Sale | E26: Unit of Pkg | F26: Unit of Measure
A28: XXXXXX / 30mg | B28: XXXXXX / 30mg | C28: 1 x 100 | D28: BO | E28: BO | F28: EA
A29: FSS Price is for one bottle containing 100 tablets of 30 mg each.
A32: XXXXXX / 25mg | B32: XXXXXX / 25mg | C32: 10 x 100 | D32: CA | E32: BO | F32: EA
A33: FSS Price is for one case containing 10 boxes of bottles which contain 100 capsules of 25 mg each.
A36: XXXXXX / 0.3% | B36: XXXXXX / 0.3% | C36: 1 x 6 | D36: VI | E36: VI | F36: ML
A37: FSS Price is for one vial containing 6 ml of 0.3% solution.
A40: XXXXXX / 0.3% | B40: XXXXXX / 0.3% | C40: 5 x 6 | D40: BX | E40: VI | F40: ML
A41: FSS Price is for one box containing 5 vials, 6 ml each, of 0.3% solution.
A44: XXXXXX / 0.2% | B44: XXXXXX / 0.2% | C44: 1 x 150 | D44: BO | E44: BO | F44: ML
A45: FSS Price is for one bottle containing 150 ml of 2% suspension.
A48: XXXXXX / 0.1% | B48: XXXXXX / 0.1% | C48: 50 x 150 | D48: CA | E48: BO | F48: ML
A49: FSS Price is for one case of 50 bottles containing 150ml each of 1% strength.
A52: XXXXXX / 0.1% | B52: XXXXXX / 0.1% | C52: 1 x 5 | D52: TB | E52: TB | F52: GM
A53: FSS Price is for one, 5 gram tube containing 1% strength.

Sheet Country Codes
A1: Country | B1: Code
A2: Afghanistan | B2: AF
A3: Albania | B3: AL
A4: Alberta | B4: XA
A5: Algeria | B5: DZ
A6: American Samoa | B6: AS
A7: Andorra | B7: AD
A8: Angola | B8: AO
A9: Anguilla | B9: AI
A10: Antigua & Barbuda | B10: AG
A11: APO Customs Mail Entry Only | B11: AP
A12: Argentina | B12: AR
... A264: Zimbabwe | B264: ZW

Sheet Figure 515.4-2 CSP-1
C1: FIGURE 515.4-2
A2: The Government expects you to provide information required by the format in accordance with the solicitation instructions for Figure 515.4-2 that is, to the best of your knowledge and belief, current, accurate, and complete as of 60 calendar days prior to its submission. The data provided in the price proposal tab and Figure 515.4-2 is current, accurate, and complete as of (enter date in cell to the right). | D2: Enter date in this cell based on instructions to the left.
A3: Provide the date range which represents the start and end date of the transactional data and commercial agreements used to populate the MFC and TC columns on the Price Proposal tab as well as Figure 515.4-2 below (enter date in cell to the right). | D3: Enter date range (start and end date) in this cell based on instructions to the left.
A4: Column 1 - Customer | B4: Column 2 - Discount | C4: Column 3 - Quantity/Volume | D4: Column 4 - FOB Terms | E4: Column 5 - Additional Discounts or Concessions
K5: F.O.B. Origin
K6: F.O.B. Destination
A18: Please reference the instructions for this Figure in the CSP-1 section of the solicitation and in the "Contractor Guide to CSP"
A19: found on our Training web page under the "Prospective Contractors - Solicitation Assistance" section at:
A20: https://www.va.gov/opal/nac/fss/training.asp

Sheet ManufPlaceOfPerf
E1: Manufacturing Facilities / Place of Performance
A2: Please complete the table below with information regarding each place of performance for the offered products.
A3: Provide the Field Establishment Identifier (FEI) Number and the Facility Owner Name, Address, City, County, State and Zip Code)
A4: You should provide information for the following (choose from the drop-down menu in column B):
A5: 1. Measured/Compounded: Location where ingredients are measured, weighed, mixed and compounded.
A6: 2. Sterilization: Location where product is sterilized.
A7: 3. Vaccines: Location where vaccine is produced.
A8: 4. Packaging: Location where intermediate containers will be fixed and labeled.
A9: 5. Packing: Location where products will be packed and prepared for shipment.
A11: NDC 1 or Item # | B11: NDC2 (4 digits only - Add leading 0 if necessary) | C11: NDC3 | D11: Generic Name | E11: Trade Name | F11: Facility Location Type | G11: (FEI) Number | H11: Facility Information Facility Owner Name, Address, City, County, State and Zip Code | I11: Point of Contact Including Phone Number & Email Address
H12: Facility Owner Name & Address: | AD12: Measured/ Compounded
H13: Facility Owner Name & Address: | AD13: Sterilization
H14: Facility Owner Name & Address: | AD14: Vaccines
H15: Facility Owner Name & Address: | AD15: Packaging
H16: Facility Owner Name & Address: | AD16: Packing
H17: Facility Owner Name & Address:
H18: Facility Owner Name & Address:
H19: Facility Owner Name & Address:
H20: Facility Owner Name & Address:

Sheet NonManufacturers
A2: SIN# | B2: Manufacturer Name | C2: Manuf. NDC 1 or Item # | D2: Manuf. NDC2 (4 digits only - Add leading 0 if necessary) | E2: Manuf. NDC3 | F2: Dealer/ Reseller NDC 1 or Item # | G2: Dealer/ Reseller NDC2 (4 digits only - Add leading 0 if necessary) | H2: Dealer/ Reseller NDC3 | I2: Product Description | J2: Mfr List Price | K2: Dealer/ Reseller % discount off Mfr. List Price
S3: 42-1
S4: 42-2A
S5: 42-2B
S6: 42-3
S7: 42-5
S8: 622
S9: INP

Sheet Price Analysis
M1: MFC & TC Analysis
A2: SIN# | B2: Item # / NDC1 | C2: NDC2 | D2: NDC3 | E2: Commercial List Price ($) | F2: MFC Price ($) | G2: MFC Discount off Comm. List Price (%) | H2: Proposed TC Name | I2: Proposed TC Price ($) | J2: TC Discount off Comm. List Price (%) | K2: Proposed FSS Price ($) without IFF | L2: Proposed FSS Discount off Comm. Price w/out IFF (%) | M2: Is Proposed Gov't Price (w/out IFF) Less Than or Equal to MFC Price? | N2: Proposed TC Ratio
A3: =IF(ISBLANK('ALL Other SINs - Proposal'!A3)," ",'ALL Other SINs - Proposal'!A3) | B3: =IF(ISBLANK('ALL Other SINs - Proposal'!B3)," ",'ALL Other SINs - Proposal'!B3) | C3: =IF(ISBLANK('ALL Other SINs - Proposal'!C3)," ",'ALL Other SINs - Proposal'!C3) | D3: =IF(ISBLANK('ALL Other SINs - Proposal'!D3)," ",'ALL Other SINs - Proposal'!D3) | E3: =IF(ISBLANK('ALL Other SINs - Proposal'!R3)," ",'ALL Other SINs - Proposal'!R3) | F3: =IF(ISBLANK('ALL Other SINs - Proposal'!S3)," ",'ALL Other SINs - Proposal'!S3) | G3: =IF(ISBLANK('ALL Other SINs - Proposal'!T3)," ",'ALL Other SINs - Proposal'!T3) | H3: =IF(ISBLANK('ALL Other SINs - Proposal'!V3)," ",'ALL Other SINs - Proposal'!V3) | I3: =IF(ISBLANK('ALL Other SINs - Proposal'!W3)," ",'ALL Other SINs - Proposal'!W3) | J3: =IF(ISBLANK('ALL Other SINs - Proposal'!X3)," ",'ALL Other SINs - Proposal'!X3) | K3: =IF(ISBLANK('ALL Other SINs - Proposal'!AA3)," ",'ALL Other SINs - Proposal'!AA3) | L3: =IF(ISBLANK('ALL Other SINs - Proposal'!AB3)," ",'ALL Other SINs - Proposal'!AB3) | M3: =IFERROR(IF((ROUND(K3,2))<=(ROUND(F3,2)),"YES","NO")," ") | N3: =IFERROR(IF(ISBLANK(K3)," ",(ROUND(K3,2))/(ROUND(I3,2)))," ")
A4: =IF(ISBLANK('ALL Other SINs - Proposal'!A4)," ",'ALL Other SINs - Proposal'!A4) | B4: =IF(ISBLANK('ALL Other SINs - Proposal'!B4)," ",'ALL Other SINs - Proposal'!B4) | C4: =IF(ISBLANK('ALL Other SINs - Proposal'!C4)," ",'ALL Other SINs - Proposal'!C4) | D4: =IF(ISBLANK('ALL Other SINs - Proposal'!D4)," ",'ALL Other SINs - Proposal'!D4) | E4: =IF(ISBLANK('ALL Other SINs - Proposal'!R4)," ",'ALL Other SINs - Proposal'!R4) | F4: =IF(ISBLANK('ALL Other SINs - Proposal'!S4)," ",'ALL Other SINs - Proposal'!S4) | G4: =IF(ISBLANK('ALL Other SINs - Proposal'!T4)," ",'ALL Other SINs - Proposal'!T4) | H4: =IF(ISBLANK('ALL Other SINs - Proposal'!V4)," ",'ALL Other SINs - Proposal'!V4) | I4: =IF(ISBLANK('ALL Other SINs - Proposal'!W4)," ",'ALL Other SINs - Proposal'!W4) | J4: =IF(ISBLANK('ALL Other SINs - Proposal'!X4)," ",'ALL Other SINs - Proposal'!X4) | K4: =IF(ISBLANK('ALL Other SINs - Proposal'!AA4)," ",'ALL Other SINs - Proposal'!AA4) | L4: =IF(ISBLANK('ALL Other SINs - Proposal'!AB4)," ",'ALL Other SINs - Proposal'!AB4) | M4: =IFERROR(IF((ROUND(K4,2))<=(ROUND(F4,2)),"YES","NO")," ") | N4: =IFERROR(IF(ISBLANK(K4)," ",(ROUND(K4,2))/(ROUND(I4,2)))," ")
A5: =IF(ISBLANK('ALL Other SINs - Proposal'!A5)," ",'ALL Other SINs - Proposal'!A5) | B5: =IF(ISBLANK('ALL Other SINs - Proposal'!B5)," ",'ALL Other SINs - Proposal'!B5) | C5: =IF(ISBLANK('ALL Other SINs - Proposal'!C5)," ",'ALL Other SINs - Proposal'!C5) | D5: =IF(ISBLANK('ALL Other SINs - Proposal'!D5)," ",'ALL Other SINs - Proposal'!D5) | E5: =IF(ISBLANK('ALL Other SINs - Proposal'!R5)," ",'ALL Other SINs - Proposal'!R5) | F5: =IF(ISBLANK('ALL Other SINs - Proposal'!S5)," ",'ALL Other SINs - Proposal'!S5) | G5: =IF(ISBLANK('ALL Other SINs - Proposal'!T5)," ",'ALL Other SINs - Proposal'!T5) | H5: =IF(ISBLANK('ALL Other SINs - Proposal'!V5)," ",'ALL Other SINs - Proposal'!V5) | I5: =IF(ISBLANK('ALL Other SINs - Proposal'!W5)," ",'ALL Other SINs - Proposal'!W5) | J5: =IF(ISBLANK('ALL Other SINs - Proposal'!X5)," ",'ALL Other SINs - Proposal'!X5) | K5: =IF(ISBLANK('ALL Other SINs - Proposal'!AA5)," ",'ALL Other SINs - Proposal'!AA5) | L5: =IF(ISBLANK('ALL Other SINs - Proposal'!AB5)," ",'ALL Other SINs - Proposal'!AB5) | M5: =IFERROR(IF((ROUND(K5,2))<=(ROUND(F5,2)),"YES","NO")," ") | N5: =IFERROR(IF(ISBLANK(K5)," ",(ROUND(K5,2))/(ROUND(I5,2)))," ")
A6: =IF(ISBLANK('ALL Other SINs - Proposal'!A6)," ",'ALL Other SINs - Proposal'!A6) | B6: =IF(ISBLANK('ALL Other SINs - Proposal'!B6)," ",'ALL Other SINs - Proposal'!B6) | C6: =IF(ISBLANK('ALL Other SINs - Proposal'!C6)," ",'ALL Other SINs - Proposal'!C6) | D6: =IF(ISBLANK('ALL Other SINs - Proposal'!D6)," ",'ALL Other SINs - Proposal'!D6) | E6: =IF(ISBLANK('ALL Other SINs - Proposal'!R6)," ",'ALL Other SINs - Proposal'!R6) | F6: =IF(ISBLANK('ALL Other SINs - Proposal'!S6)," ",'ALL Other SINs - Proposal'!S6) | G6: =IF(ISBLANK('ALL Other SINs - Proposal'!T6)," ",'ALL Other SINs - Proposal'!T6) | H6: =IF(ISBLANK('ALL Other SINs - Proposal'!V6)," ",'ALL Other SINs - Proposal'!V6) | I6: =IF(ISBLANK('ALL Other SINs - Proposal'!W6)," ",'ALL Other SINs - Proposal'!W6) | J6: =IF(ISBLANK('ALL Other SINs - Proposal'!X6)," ",'ALL Other SINs - Proposal'!X6) | K6: =IF(ISBLANK('ALL Other SINs - Proposal'!AA6)," ",'ALL Other SINs - Proposal'!AA6) | L6: =IF(ISBLANK('ALL Other SINs - Proposal'!AB6)," ",'ALL Other SINs - Proposal'!AB6) | M6: =IFERROR(IF((ROUND(K6,2))<=(ROUND(F6,2)),"YES","NO")," ") | N6: =IFERROR(IF(ISBLANK(K6)," ",(ROUND(K6,2))/(ROUND(I6,2)))," ")
A7: =IF(ISBLANK('ALL Other SINs - Proposal'!A7)," ",'ALL Other SINs - Proposal'!A7) | B7: =IF(ISBLANK('ALL Other SINs - Proposal'!B7)," ",'ALL Other SINs - Proposal'!B7) | C7: =IF(ISBLANK('ALL Other SINs - Proposal'!C7)," ",'ALL Other SINs - Proposal'!C7) | D7: =IF(ISBLANK('ALL Other SINs - Proposal'!D7)," ",'ALL Other SINs - Proposal'!D7) | E7: =IF(ISBLANK('ALL Other SINs - Proposal'!R7)," ",'ALL Other SINs - Proposal'!R7) | F7: =IF(ISBLANK('ALL Other SINs - Proposal'!S7)," ",'ALL Other SINs - Proposal'!S7) | G7: =IF(ISBLANK('ALL Other SINs - Proposal'!T7)," ",'ALL Other SINs - Proposal'!T7) | H7: =IF(ISBLANK('ALL Other SINs - Proposal'!V7)," ",'ALL Other SINs - Proposal'!V7) | I7: =IF(ISBLANK('ALL Other SINs - Proposal'!W7)," ",'ALL Other SINs - Proposal'!W7) | J7: =IF(ISBLANK('ALL Other SINs - Proposal'!X7)," ",'ALL Other SINs - Proposal'!X7) | K7: =IF(ISBLANK('ALL Other SINs - Proposal'!AA7)," ",'ALL Other SINs - Proposal'!AA7) | L7: =IF(ISBLANK('ALL Other SINs - Proposal'!AB7)," ",'ALL Other SINs - Proposal'!AB7) | M7: =IFERROR(IF((ROUND(K7,2))<=(ROUND(F7,2)),"YES","NO")," ") | N7: =IFERROR(IF(ISBLANK(K7)," ",(ROUND(K7,2))/(ROUND(I7,2)))," ")
A8: =IF(ISBLANK('ALL Other SINs - Proposal'!A8)," ",'ALL Other SINs - Proposal'!A8) | B8: =IF(ISBLANK('ALL Other SINs - Proposal'!B8)," ",'ALL Other SINs - Proposal'!B8) | C8: =IF(ISBLANK('ALL Other SINs - Proposal'!C8)," ",'ALL Other SINs - Proposal'!C8) | D8: =IF(ISBLANK('ALL Other SINs - Proposal'!D8)," ",'ALL Other SINs - Proposal'!D8) | E8: =IF(ISBLANK('ALL Other SINs - Proposal'!R8)," ",'ALL Other SINs - Proposal'!R8) | F8: =IF(ISBLANK('ALL Other SINs - Proposal'!S8)," ",'ALL Other SINs - Proposal'!S8) | G8: =IF(ISBLANK('ALL Other SINs - Proposal'!T8)," ",'ALL Other SINs - Proposal'!T8) | H8: =IF(ISBLANK('ALL Other SINs - Proposal'!V8)," ",'ALL Other SINs - Proposal'!V8) | I8: =IF(ISBLANK('ALL Other SINs - Proposal'!W8)," ",'ALL Other SINs - Proposal'!W8) | J8: =IF(ISBLANK('ALL Other SINs - Proposal'!X8)," ",'ALL Other SINs - Proposal'!X8) | K8: =IF(ISBLANK('ALL Other SINs - Proposal'!AA8)," ",'ALL Other SINs - Proposal'!AA8) | L8: =IF(ISBLANK('ALL Other SINs - Proposal'!AB8)," ",'ALL Other SINs - Proposal'!AB8) | M8: =IFERROR(IF((ROUND(K8,2))<=(ROUND(F8,2)),"YES","NO")," ") | N8: =IFERROR(IF(ISBLANK(K8)," ",(ROUND(K8,2))/(ROUND(I8,2)))," ")
A9: =IF(ISBLANK('ALL Other SINs - Proposal'!A9)," ",'ALL Other SINs - Proposal'!A9) | B9: =IF(ISBLANK('ALL Other SINs - Proposal'!B9)," ",'ALL Other SINs - Proposal'!B9) | C9: =IF(ISBLANK('ALL Other SINs - Proposal'!C9)," ",'ALL Other SINs - Proposal'!C9) | D9: =IF(ISBLANK('ALL Other SINs - Proposal'!D9)," ",'ALL Other SINs - Proposal'!D9) | E9: =IF(ISBLANK('ALL Other SINs - Proposal'!R9)," ",'ALL Other SINs - Proposal'!R9) | F9: =IF(ISBLANK('ALL Other SINs - Proposal'!S9)," ",'ALL Other SINs - Proposal'!S9) | G9: =IF(ISBLANK('ALL Other SINs - Proposal'!T9)," ",'ALL Other SINs - Proposal'!T9) | H9: =IF(ISBLANK('ALL Other SINs - Proposal'!V9)," ",'ALL Other SINs - Proposal'!V9) | I9: =IF(ISBLANK('ALL Other SINs - Proposal'!W9)," ",'ALL Other SINs - Proposal'!W9) | J9: =IF(ISBLANK('ALL Other SINs - Proposal'!X9)," ",'ALL Other SINs - Proposal'!X9) | K9: =IF(ISBLANK('ALL Other SINs - Proposal'!AA9)," ",'ALL Other SINs - Proposal'!AA9) | L9: =IF(ISBLANK('ALL Other SINs - Proposal'!AB9)," ",'ALL Other SINs - Proposal'!AB9) | M9: =IFERROR(IF((ROUND(K9,2))<=(ROUND(F9,2)),"YES","NO")," ") | N9: =IFERROR(IF(ISBLANK(K9)," ",(ROUND(K9,2))/(ROUND(I9,2)))," ")
A10: =IF(ISBLANK('ALL Other SINs - Proposal'!A10)," ",'ALL Other SINs - Proposal'!A10) | B10: =IF(ISBLANK('ALL Other SINs - Proposal'!B10)," ",'ALL Other SINs - Proposal'!B10) | C10: =IF(ISBLANK('ALL Other SINs - Proposal'!C10)," ",'ALL Other SINs - Proposal'!C10) | D10: =IF(ISBLANK('ALL Other SINs - Proposal'!D10)," ",'ALL Other SINs - Proposal'!D10) | E10: =IF(ISBLANK('ALL Other SINs - Proposal'!R10)," ",'ALL Other SINs - Proposal'!R10) | F10: =IF(ISBLANK('ALL Other SINs - Proposal'!S10)," ",'ALL Other SINs - Proposal'!S10) | G10: =IF(ISBLANK('ALL Other SINs - Proposal'!T10)," ",'ALL Other SINs - Proposal'!T10) | H10: =IF(ISBLANK('ALL Other SINs - Proposal'!V10)," ",'ALL Other SINs - Proposal'!V10) | I10: =IF(ISBLANK('ALL Other SINs - Proposal'!W10)," ",'ALL Other SINs - Proposal'!W10) | J10: =IF(ISBLANK('ALL Other SINs - Proposal'!X10)," ",'ALL Other SINs - Proposal'!X10) | K10: =IF(ISBLANK('ALL Other SINs - Proposal'!AA10)," ",'ALL Other SINs - Proposal'!AA10) | L10: =IF(ISBLANK('ALL Other SINs - Proposal'!AB10)," ",'ALL Other SINs - Proposal'!AB10) | M10: =IFERROR(IF((ROUND(K10,2))<=(ROUND(F10,2)),"YES","NO")," ") | N10: =IFERROR(IF(ISBLANK(K10)," ",(ROUND(K10,2))/(ROUND(I10,2)))," ")
A11: =IF(ISBLANK('ALL Other SINs - Proposal'!A11)," ",'ALL Other SINs - Proposal'!A11) | B11: =IF(ISBLANK('ALL Other SINs - Proposal'!B11)," ",'ALL Other SINs - Proposal'!B11) | C11: =IF(ISBLANK('ALL Other SINs - Proposal'!C11)," ",'ALL Other SINs - Proposal'!C11) | D11: =IF(ISBLANK('ALL Other SINs - Proposal'!D11)," ",'ALL Other SINs - Proposal'!D11) | E11: =IF(ISBLANK('ALL Other SINs - Proposal'!R11)," ",'ALL Other SINs - Proposal'!R11) | F11: =IF(ISBLANK('ALL Other SINs - Proposal'!S11)," ",'ALL Other SINs - Proposal'!S11) | G11: =IF(ISBLANK('ALL Other SINs - Proposal'!T11)," ",'ALL Other SINs - Proposal'!T11) | H11: =IF(ISBLANK('ALL Other SINs - Proposal'!V11)," ",'ALL Other SINs - Proposal'!V11) | I11: =IF(ISBLANK('ALL Other SINs - Proposal'!W11)," ",'ALL Other SINs - Proposal'!W11) | J11: =IF(ISBLANK('ALL Other SINs - Proposal'!X11)," ",'ALL Other SINs - Proposal'!X11) | K11: =IF(ISBLANK('ALL Other SINs - Proposal'!AA11)," ",'ALL Other SINs - Proposal'!AA11) | L11: =IF(ISBLANK('ALL Other SINs - Proposal'!AB11)," ",'ALL Other SINs - Proposal'!AB11) | M11: =IFERROR(IF((ROUND(K11,2))<=(ROUND(F11,2)),"YES","NO")," ") | N11: =IFERROR(IF(ISBLANK(K11)," ",(ROUND(K11,2))/(ROUND(I11,2)))," ")
A12: =IF(ISBLANK('ALL Other SINs - Proposal'!A12)," ",'ALL Other SINs - Proposal'!A12) | B12: =IF(ISBLANK('ALL Other SINs - Proposal'!B12)," ",'ALL Other SINs - Proposal'!B12) | C12: =IF(ISBLANK('ALL Other SINs - Proposal'!C12)," ",'ALL Other SINs - Proposal'!C12) | D12: =IF(ISBLANK('ALL Other SINs - Proposal'!D12)," ",'ALL Other SINs - Proposal'!D12) | E12: =IF(ISBLANK('ALL Other SINs - Proposal'!R12)," ",'ALL Other SINs - Proposal'!R12) | F12: =IF(ISBLANK('ALL Other SINs - Proposal'!S12)," ",'ALL Other SINs - Proposal'!S12) | G12: =IF(ISBLANK('ALL Other SINs - Proposal'!T12)," ",'ALL Other SINs - Proposal'!T12) | H12: =IF(ISBLANK('ALL Other SINs - Proposal'!V12)," ",'ALL Other SINs - Proposal'!V12) | I12: =IF(ISBLANK('ALL Other SINs - Proposal'!W12)," ",'ALL Other SINs - Proposal'!W12) | J12: =IF(ISBLANK('ALL Other SINs - Proposal'!X12)," ",'ALL Other SINs - Proposal'!X12) | K12: =IF(ISBLANK('ALL Other SINs - Proposal'!AA12)," ",'ALL Other SINs - Proposal'!AA12) | L12: =IF(ISBLANK('ALL Other SINs - Proposal'!AB12)," ",'ALL Other SINs - Proposal'!AB12) | M12: =IFERROR(IF((ROUND(K12,2))<=(ROUND(F12,2)),"YES","NO")," ") | N12: =IFERROR(IF(ISBLANK(K12)," ",(ROUND(K12,2))/(ROUND(I12,2)))," ")
A13: =IF(ISBLANK('ALL Other SINs - Proposal'!A13)," ",'ALL Other SINs - Proposal'!A13) | B13: =IF(ISBLANK('ALL Other SINs - Proposal'!B13)," ",'ALL Other SINs - Proposal'!B13) | C13: =IF(ISBLANK('ALL Other SINs - Proposal'!C13)," ",'ALL Other SINs - Proposal'!C13) | D13: =IF(ISBLANK('ALL Other SINs - Proposal'!D13)," ",'ALL Other SINs - Proposal'!D13) | E13: =IF(ISBLANK('ALL Other SINs - Proposal'!R13)," ",'ALL Other SINs - Proposal'!R13) | F13: =IF(ISBLANK('ALL Other SINs - Proposal'!S13)," ",'ALL Other SINs - Proposal'!S13) | G13: =IF(ISBLANK('ALL Other SINs - Proposal'!T13)," ",'ALL Other SINs - Proposal'!T13) | H13: =IF(ISBLANK('ALL Other SINs - Proposal'!V13)," ",'ALL Other SINs - Proposal'!V13) | I13: =IF(ISBLANK('ALL Other SINs - Proposal'!W13)," ",'ALL Other SINs - Proposal'!W13) | J13: =IF(ISBLANK('ALL Other SINs - Proposal'!X13)," ",'ALL Other SINs - Proposal'!X13) | K13: =IF(ISBLANK('ALL Other SINs - Proposal'!AA13)," ",'ALL Other SINs - Proposal'!AA13) | L13: =IF(ISBLANK('ALL Other SINs - Proposal'!AB13)," ",'ALL Other SINs - Proposal'!AB13) | M13: =IFERROR(IF((ROUND(K13,2))<=(ROUND(F13,2)),"YES","NO")," ") | N13: =IFERROR(IF(ISBLANK(K13)," ",(ROUND(K13,2))/(ROUND(I13,2)))," ")
A14: =IF(ISBLANK('ALL Other SINs - Proposal'!A14)," ",'ALL Other SINs - Proposal'!A14) | B14: =IF(ISBLANK('ALL Other SINs - Proposal'!B14)," ",'ALL Other SINs - Proposal'!B14) | C14: =IF(ISBLANK('ALL Other SINs - Proposal'!C14)," ",'ALL Other SINs - Proposal'!C14) | D14: =IF(ISBLANK('ALL Other SINs - Proposal'!D14)," ",'ALL Other SINs - Proposal'!D14) | E14: =IF(ISBLANK('ALL Other SINs - Proposal'!R14)," ",'ALL Other SINs - Proposal'!R14) | F14: =IF(ISBLANK('ALL Other SINs - Proposal'!S14)," ",'ALL Other SINs - Proposal'!S14) | G14: =IF(ISBLANK('ALL Other SINs - Proposal'!T14)," ",'ALL Other SINs - Proposal'!T14) | H14: =IF(ISBLANK('ALL Other SINs - Proposal'!V14)," ",'ALL Other SINs - Proposal'!V14) | I14: =IF(ISBLANK('ALL Other SINs - Proposal'!W14)," ",'ALL Other SINs - Proposal'!W14) | J14: =IF(ISBLANK('ALL Other SINs - Proposal'!X14)," ",'ALL Other SINs - Proposal'!X14) | K14: =IF(ISBLANK('ALL Other SINs - Proposal'!AA14)," ",'ALL Other SINs - Proposal'!AA14) | L14: =IF(ISBLANK('ALL Other SINs - Proposal'!AB14)," ",'ALL Other SINs - Proposal'!AB14) | M14: =IFERROR(IF((ROUND(K14,2))<=(ROUND(F14,2)),"YES","NO")," ") | N14: =IFERROR(IF(ISBLANK(K14)," ",(ROUND(K14,2))/(ROUND(I14,2)))," ")
... A1002: =IF(ISBLANK('ALL Other SINs - Proposal'!A1002)," ",'ALL Other SINs - Proposal'!A1002) | B1002: =IF(ISBLANK('ALL Other SINs - Proposal'!B1002)," ",'ALL Other SINs - Proposal'!B1002) | C1002: =IF(ISBLANK('ALL Other SINs - Proposal'!C1002)," ",'ALL Other SINs - Proposal'!C1002) | D1002: =IF(ISBLANK('ALL Other SINs - Proposal'!D1002)," ",'ALL Other SINs - Proposal'!D1002) | E1002: =IF(ISBLANK('ALL Other SINs - Proposal'!R1002)," ",'ALL Other SINs - Proposal'!R1002) | F1002: =IF(ISBLANK('ALL Other SINs - Proposal'!S1002)," ",'ALL Other SINs - Proposal'!S1002) | G1002: =IF(ISBLANK('ALL Other SINs - Proposal'!T1002)," ",'ALL Other SINs - Proposal'!T1002) | H1002: =IF(ISBLANK('ALL Other SINs - Proposal'!V1002)," ",'ALL Other SINs - Proposal'!V1002) | I1002: =IF(ISBLANK('ALL Other SINs - Proposal'!W1002)," ",'ALL Other SINs - Proposal'!W1002) | J1002: =IF(ISBLANK('ALL Other SINs - Proposal'!X1002)," ",'ALL Other SINs - Proposal'!X1002) | K1002: =IF(ISBLANK('ALL Other SINs - Proposal'!AA1002)," ",'ALL Other SINs - Proposal'!AA1002) | L1002: =IF(ISBLANK('ALL Other SINs - Proposal'!AB1002)," ",'ALL Other SINs - Proposal'!AB1002) | M1002: =IFERROR(IF((ROUND(K1002,2))<=(ROUND(F1002,2)),"YES","NO")," ") | N1002: =IFERROR(IF(ISBLANK(K1002)," ",(ROUND(K1002,2))/(ROUND(I1002,2)))," ")

Sheet Award
A2: SIN# | B2: NDC1 or Item # | C2: NDC2 | D2: NDC3 | E2: Specialty Distrib. Item? | F2: Generic Name / Strength | G2: Trade Name / Description | H2: Pkg Size | I2: Unit of Sale | J2: Qnty in Unit of Sale | K2: Unit Pkg | L2: Qnty in Unit Pkg | M2: Unit of Meas | N2: Tracking Customer Name | O2: Tracking Ratio | P2: Gov't Price without IFF | Q2: (Copy FSS w/ IFF from PP Tab) | R2: Gov't Price with IFF | S2: Red "A" = Awarded
A3: ='ALL Other SINs - Proposal'!A3 -> 0 | B3: ='ALL Other SINs - Proposal'!B3 -> 0 | C3: ='ALL Other SINs - Proposal'!C3 -> 0 | D3: ='ALL Other SINs - Proposal'!D3 -> 0 | E3: ='ALL Other SINs - Proposal'!E3 -> 0 | F3: ='ALL Other SINs - Proposal'!F3 -> 0 | G3: ='ALL Other SINs - Proposal'!G3 -> 0 | H3: ='ALL Other SINs - Proposal'!H3 -> 0 | ... M3: ='ALL Other SINs - Proposal'!M3 -> 0 | N3: ='ALL Other SINs - Proposal'!V3 -> 0 | O3: ='Price Analysis'!N3 | P3: =IF(ISBLANK('ALL Other SINs - Proposal'!AA3)," ",'ALL Other SINs - Proposal'!AA3) | Q3: ='ALL Other SINs - Proposal'!AC3 | R3: =IF(ISBLANK('ALL Other SINs - Proposal'!AA3)," ",ROUND(Q3,2)) | S3: A
A4: ='ALL Other SINs - Proposal'!A4 -> 0 | B4: ='ALL Other SINs - Proposal'!B4 -> 0 | C4: ='ALL Other SINs - Proposal'!C4 -> 0 | D4: ='ALL Other SINs - Proposal'!D4 -> 0 | E4: ='ALL Other SINs - Proposal'!E4 -> 0 | F4: ='ALL Other SINs - Proposal'!F4 -> 0 | G4: ='ALL Other SINs - Proposal'!G4 -> 0 | H4: ='ALL Other SINs - Proposal'!H4 -> 0 | ... M4: ='ALL Other SINs - Proposal'!M4 -> 0 | N4: ='ALL Other SINs - Proposal'!V4 -> 0 | O4: ='Price Analysis'!N4 | P4: =IF(ISBLANK('ALL Other SINs - Proposal'!AA4)," ",'ALL Other SINs - Proposal'!AA4) | Q4: ='ALL Other SINs - Proposal'!AC4 | R4: =IF(ISBLANK('ALL Other SINs - Proposal'!AA4)," ",ROUND(Q4,2))
A5: ='ALL Other SINs - Proposal'!A5 -> 0 | B5: ='ALL Other SINs - Proposal'!B5 -> 0 | C5: ='ALL Other SINs - Proposal'!C5 -> 0 | D5: ='ALL Other SINs - Proposal'!D5 -> 0 | E5: ='ALL Other SINs - Proposal'!E5 -> 0 | F5: ='ALL Other SINs - Proposal'!F5 -> 0 | G5: ='ALL Other SINs - Proposal'!G5 -> 0 | H5: ='ALL Other SINs - Proposal'!H5 -> 0 | ... M5: ='ALL Other SINs - Proposal'!M5 -> 0 | N5: ='ALL Other SINs - Proposal'!V5 -> 0 | O5: ='Price Analysis'!N5 | P5: =IF(ISBLANK('ALL Other SINs - Proposal'!AA5)," ",'ALL Other SINs - Proposal'!AA5) | Q5: ='ALL Other SINs - Proposal'!AC5 | R5: =IF(ISBLANK('ALL Other SINs - Proposal'!AA5)," ",ROUND(Q5,2))
A6: ='ALL Other SINs - Proposal'!A6 -> 0 | B6: ='ALL Other SINs - Proposal'!B6 -> 0 | C6: ='ALL Other SINs - Proposal'!C6 -> 0 | D6: ='ALL Other SINs - Proposal'!D6 -> 0 | E6: ='ALL Other SINs - Proposal'!E6 -> 0 | F6: ='ALL Other SINs - Proposal'!F6 -> 0 | G6: ='ALL Other SINs - Proposal'!G6 -> 0 | H6: ='ALL Other SINs - Proposal'!H6 -> 0 | ... M6: ='ALL Other SINs - Proposal'!M6 -> 0 | N6: ='ALL Other SINs - Proposal'!V6 -> 0 | O6: ='Price Analysis'!N6 | P6: =IF(ISBLANK('ALL Other SINs - Proposal'!AA6)," ",'ALL Other SINs - Proposal'!AA6) | Q6: ='ALL Other SINs - Proposal'!AC6 | R6: =IF(ISBLANK('ALL Other SINs - Proposal'!AA6)," ",ROUND(Q6,2))
A7: ='ALL Other SINs - Proposal'!A7 -> 0 | B7: ='ALL Other SINs - Proposal'!B7 -> 0 | C7: ='ALL Other SINs - Proposal'!C7 -> 0 | D7: ='ALL Other SINs - Proposal'!D7 -> 0 | E7: ='ALL Other SINs - Proposal'!E7 -> 0 | F7: ='ALL Other SINs - Proposal'!F7 -> 0 | G7: ='ALL Other SINs - Proposal'!G7 -> 0 | H7: ='ALL Other SINs - Proposal'!H7 -> 0 | ... M7: ='ALL Other SINs - Proposal'!M7 -> 0 | N7: ='ALL Other SINs - Proposal'!V7 -> 0 | O7: ='Price Analysis'!N7 | P7: =IF(ISBLANK('ALL Other SINs - Proposal'!AA7)," ",'ALL Other SINs - Proposal'!AA7) | Q7: ='ALL Other SINs - Proposal'!AC7 | R7: =IF(ISBLANK('ALL Other SINs - Proposal'!AA7)," ",ROUND(Q7,2))
A8: ='ALL Other SINs - Proposal'!A8 -> 0 | B8: ='ALL Other SINs - Proposal'!B8 -> 0 | C8: ='ALL Other SINs - Proposal'!C8 -> 0 | D8: ='ALL Other SINs - Proposal'!D8 -> 0 | E8: ='ALL Other SINs - Proposal'!E8 -> 0 | F8: ='ALL Other SINs - Proposal'!F8 -> 0 | G8: ='ALL Other SINs - Proposal'!G8 -> 0 | H8: ='ALL Other SINs - Proposal'!H8 -> 0 | ... M8: ='ALL Other SINs - Proposal'!M8 -> 0 | N8: ='ALL Other SINs - Proposal'!V8 -> 0 | O8: ='Price Analysis'!N8 | P8: =IF(ISBLANK('ALL Other SINs - Proposal'!AA8)," ",'ALL Other SINs - Proposal'!AA8) | Q8: ='ALL Other SINs - Proposal'!AC8 | R8: =IF(ISBLANK('ALL Other SINs - Proposal'!AA8)," ",ROUND(Q8,2))
A9: ='ALL Other SINs - Proposal'!A9 -> 0 | B9: ='ALL Other SINs - Proposal'!B9 -> 0 | C9: ='ALL Other SINs - Proposal'!C9 -> 0 | D9: ='ALL Other SINs - Proposal'!D9 -> 0 | E9: ='ALL Other SINs - Proposal'!E9 -> 0 | F9: ='ALL Other SINs - Proposal'!F9 -> 0 | G9: ='ALL Other SINs - Proposal'!G9 -> 0 | H9: ='ALL Other SINs - Proposal'!H9 -> 0 | ... M9: ='ALL Other SINs - Proposal'!M9 -> 0 | N9: ='ALL Other SINs - Proposal'!V9 -> 0 | O9: ='Price Analysis'!N9 | P9: =IF(ISBLANK('ALL Other SINs - Proposal'!AA9)," ",'ALL Other SINs - Proposal'!AA9) | Q9: ='ALL Other SINs - Proposal'!AC9 | R9: =IF(ISBLANK('ALL Other SINs - Proposal'!AA9)," ",ROUND(Q9,2))
A10: ='ALL Other SINs - Proposal'!A10 -> 0 | B10: ='ALL Other SINs - Proposal'!B10 -> 0 | C10: ='ALL Other SINs - Proposal'!C10 -> 0 | D10: ='ALL Other SINs - Proposal'!D10 -> 0 | E10: ='ALL Other SINs - Proposal'!E10 -> 0 | F10: ='ALL Other SINs - Proposal'!F10 -> 0 | G10: ='ALL Other SINs - Proposal'!G10 -> 0 | H10: ='ALL Other SINs - Proposal'!H10 -> 0 | ... M10: ='ALL Other SINs - Proposal'!M10 -> 0 | N10: ='ALL Other SINs - Proposal'!V10 -> 0 | O10: ='Price Analysis'!N10 | P10: =IF(ISBLANK('ALL Other SINs - Proposal'!AA10)," ",'ALL Other SINs - Proposal'!AA10) | Q10: ='ALL Other SINs - Proposal'!AC10 | R10: =IF(ISBLANK('ALL Other SINs - Proposal'!AA10)," ",ROUND(Q10,2))
A11: ='ALL Other SINs - Proposal'!A11 -> 0 | B11: ='ALL Other SINs - Proposal'!B11 -> 0 | C11: ='ALL Other SINs - Proposal'!C11 -> 0 | D11: ='ALL Other SINs - Proposal'!D11 -> 0 | E11: ='ALL Other SINs - Proposal'!E11 -> 0 | F11: ='ALL Other SINs - Proposal'!F11 -> 0 | G11: ='ALL Other SINs - Proposal'!G11 -> 0 | H11: ='ALL Other SINs - Proposal'!H11 -> 0 | ... M11: ='ALL Other SINs - Proposal'!M11 -> 0 | N11: ='ALL Other SINs - Proposal'!V11 -> 0 | O11: ='Price Analysis'!N11 | P11: =IF(ISBLANK('ALL Other SINs - Proposal'!AA11)," ",'ALL Other SINs - Proposal'!AA11) | Q11: ='ALL Other SINs - Proposal'!AC11 | R11: =IF(ISBLANK('ALL Other SINs - Proposal'!AA11)," ",ROUND(Q11,2))
A12: ='ALL Other SINs - Proposal'!A12 -> 0 | B12: ='ALL Other SINs - Proposal'!B12 -> 0 | C12: ='ALL Other SINs - Proposal'!C12 -> 0 | D12: ='ALL Other SINs - Proposal'!D12 -> 0 | E12: ='ALL Other SINs - Proposal'!E12 -> 0 | F12: ='ALL Other SINs - Proposal'!F12 -> 0 | G12: ='ALL Other SINs - Proposal'!G12 -> 0 | H12: ='ALL Other SINs - Proposal'!H12 -> 0 | ... M12: ='ALL Other SINs - Proposal'!M12 -> 0 | N12: ='ALL Other SINs - Proposal'!V12 -> 0 | O12: ='Price Analysis'!N12 | P12: =IF(ISBLANK('ALL Other SINs - Proposal'!AA12)," ",'ALL Other SINs - Proposal'!AA12) | Q12: ='ALL Other SINs - Proposal'!AC12 | R12: =IF(ISBLANK('ALL Other SINs - Proposal'!AA12)," ",ROUND(Q12,2))
A13: ='ALL Other SINs - Proposal'!A13 -> 0 | B13: ='ALL Other SINs - Proposal'!B13 -> 0 | C13: ='ALL Other SINs - Proposal'!C13 -> 0 | D13: ='ALL Other SINs - Proposal'!D13 -> 0 | E13: ='ALL Other SINs - Proposal'!E13 -> 0 | F13: ='ALL Other SINs - Proposal'!F13 -> 0 | G13: ='ALL Other SINs - Proposal'!G13 -> 0 | H13: ='ALL Other SINs - Proposal'!H13 -> 0 | ... M13: ='ALL Other SINs - Proposal'!M13 -> 0 | N13: ='ALL Other SINs - Proposal'!V13 -> 0 | O13: ='Price Analysis'!N13 | P13: =IF(ISBLANK('ALL Other SINs - Proposal'!AA13)," ",'ALL Other SINs - Proposal'!AA13) | Q13: ='ALL Other SINs - Proposal'!AC13 | R13: =IF(ISBLANK('ALL Other SINs - Proposal'!AA13)," ",ROUND(Q13,2))
A14: ='ALL Other SINs - Proposal'!A14 -> 0 | B14: ='ALL Other SINs - Proposal'!B14 -> 0 | C14: ='ALL Other SINs - Proposal'!C14 -> 0 | D14: ='ALL Other SINs - Proposal'!D14 -> 0 | E14: ='ALL Other SINs - Proposal'!E14 -> 0 | F14: ='ALL Other SINs - Proposal'!F14 -> 0 | G14: ='ALL Other SINs - Proposal'!G14 -> 0 | H14: ='ALL Other SINs - Proposal'!H14 -> 0 | ... M14: ='ALL Other SINs - Proposal'!M14 -> 0 | N14: ='ALL Other SINs - Proposal'!V14 -> 0 | O14: ='Price Analysis'!N14 | P14: =IF(ISBLANK('ALL Other SINs - Proposal'!AA14)," ",'ALL Other SINs - Proposal'!AA14) | Q14: ='ALL Other SINs - Proposal'!AC14 | R14: =IF(ISBLANK('ALL Other SINs - Proposal'!AA14)," ",ROUND(Q14,2))
A15: ='ALL Other SINs - Proposal'!A15 -> 0 | B15: ='ALL Other SINs - Proposal'!B15 -> 0 | C15: ='ALL Other SINs - Proposal'!C15 -> 0 | D15: ='ALL Other SINs - Proposal'!D15 -> 0 | E15: ='ALL Other SINs - Proposal'!E15 -> 0 | F15: ='ALL Other SINs - Proposal'!F15 -> 0 | G15: ='ALL Other SINs - Proposal'!G15 -> 0 | H15: ='ALL Other SINs - Proposal'!H15 -> 0 | ... M15: ='ALL Other SINs - Proposal'!M15 -> 0 | N15: ='ALL Other SINs - Proposal'!V15 -> 0 | O15: ='Price Analysis'!N15 | P15: =IF(ISBLANK('ALL Other SINs - Proposal'!AA15)," ",'ALL Other SINs - Proposal'!AA15) | Q15: ='ALL Other SINs - Proposal'!AC15 | R15: =IF(ISBLANK('ALL Other SINs - Proposal'!AA15)," ",ROUND(Q15,2))
... A1002: ='ALL Other SINs - Proposal'!A1002 -> 0 | B1002: ='ALL Other SINs - Proposal'!B1002 -> 0 | C1002: ='ALL Other SINs - Proposal'!C1002 -> 0 | D1002: ='ALL Other SINs - Proposal'!D1002 -> 0 | E1002: ='ALL Other SINs - Proposal'!E1002 -> 0 | F1002: ='ALL Other SINs - Proposal'!F1002 -> 0 | G1002: ='ALL Other SINs - Proposal'!G1002 -> 0 | H1002: ='ALL Other SINs - Proposal'!H1002 -> 0 | ... M1002: ='ALL Other SINs - Proposal'!M1002 -> 0 | N1002: ='ALL Other SINs - Proposal'!V1002 -> 0 | O1002: ='Price Analysis'!N1002 | P1002: =IF(ISBLANK('ALL Other SINs - Proposal'!AA1002)," ",'ALL Other SINs - Proposal'!AA1002) | Q1002: ='ALL Other SINs - Proposal'!AC1002 | R1002: =IF(ISBLANK('ALL Other SINs - Proposal'!AA1002)," ",ROUND(Q1002,2))
