Workbook
Name Common: #REF!
Name Consum: #REF!
Name EngRate: #REF!
Name GARate: #REF!
Name GrossProfit: #REF!
Name MatHandle: #REF!
Name Risk: #REF!
Name ShopRate: #REF!

Sheet INSTRUCTIONS
B1: Source Selection Information - See FAR 2.101 and 3.104
B2: KC-135 Center Console Refresh (CCR) Source Selection
B3: Attachment 3B, EPW - SUB
B4: Notes:
B5: 1. The worksheet tabs highlighted in yellow within Attachment 3B require Offeror input; the cells within each worksheet requiring input are highlighted in yellow
B6: 2. All proposed dollar amounts and labor rates shall be rounded to two decimal places. All proposed rates in percentages shall be rounded to four decimal places (ex. .0755 = 7.55%)
B7: 3. The total proposed price is calculated in the "SUMMARY" worksheet
B9: Instructions for completing this Cost Model:
B11: Cost Model - CPIF CLINs 0001 - 0003:
B12: 1 | C12: Refer to the "Notes" on each CPIF worksheet for specific information/instructions
B13: 2 | C13: The format of the Cost Model worksheets entitled "SUB CPIF RATES (ALL)", "SUB CPIF RATE DESC (ALL)", "SUB CPIF LABOR by TASK", "SUB CPIF LABOR INPUTS", "SUB CPIF TOTAL MATERIAL", "SUB CPIF TOTAL SUB", "SUB CPIF TOTAL ODC" and "CPIF CLIN 000X-TASK 1.XX INPUTS" may be revised by the Offeror as necessary; if revisions are made, Offerors shall ensure properly linking to corresponding worksheets
B14: 3 | C14: The "CPIF CLIN 000X-TASK 1.XX INPUTS" worksheets are linked to the "SUB CPIF RATES (ALL)", "SUB CPIF LABOR INPUTS", "SUB CPIF TOTAL MATERIAL", "SUB CPIF TOTAL SUB", and "SUB CPIF TOTAL ODC" worksheets. Inputs in the "CPIF CLIN 000X-TASK 1.XX INPUTS" worksheets are not required, but the format of these worksheets may be revised, if necessary
B15: 4 | C15: The "CPIF CLIN 000X TOTAL" worksheets are linked to the "CPIF CLIN 000X-TASK 1.XX INPUTS" worksheets; no inputs are required, but the format of these worksheets should be revised to align with "CPIF 000X-TASK 1.XX INPUTS" worksheets, if necessary
B16: 5 | C16: The "CPIF CLIN 000X SUMMARY" worksheets includes links to the "CPIF CLIN 000X-TASK 1.XX INPUTS" worksheets; no inputs required
B17: 6 | C17: The total proposed amounts for the CPIF CLINs will automatically populate the "SUMMARY" worksheet; no inputs required

Sheet SUMMARY
A1: MAJOR SUBCONTRACTOR | B1: ='SUB CPIF RATES (ALL)'!C1 -> NAME
A2: PRIME OFFEROR | B2: ='SUB CPIF RATES (ALL)'!C2 -> NAME
A4: Notes: Proposed CLIN amounts are linked to the "CPIF CLIN 000X TOTAL" worksheets; no input required
A7: KC-135 Center Console Refresh (CCR) Competitive Pricing Matrix SUMMARY | E7: Basic Period (48 months)
A8: CLIN Description | B8: Contract Type | C8: Unit of Issue | D8: Basic Period CLIN | E8: Qty | F8: Unit Price | G8: Extended Price | I8: TOTAL EVALUATED PRICE
A9: EMD | E9: EMD
A10: Development | B10: Cost Plus Incentive Fee (CPIF) | C10: Lot | D10: 0001 | E10: 1 | F10: ='CPIF CLIN 0001 TOTAL'!Q74 -> 0 | G10: =ROUND(E10*F10,0) -> 0 | I10: =G10 -> 0
A11: Simulator Kit | B11: CPIF | C11: Lot | D11: 0002 | E11: 1 | F11: ='CPIF CLIN 0002 TOTAL'!Q73 -> 0 | G11: =ROUND(E11*F11,0) -> 0 | I11: =G11 -> 0
A12: Systems Integration Laboratory (SIL) | B12: CPIF | C12: Lot | D12: 0003 | E12: 1 | F12: ='CPIF CLIN 0003 TOTAL'!Q74 -> 0 | G12: =ROUND(E12*F12,0) -> 0 | I12: =G12 -> 0
A13: Data - EMD | B13: Not Separately Priced (NSP) | C13: N/A | D13: 0004
A14: Travel - EMD | B14: Cost Reimbursable - No Fee (CR-NF) | C14: N/A | D14: 0005
A15: Intellectual Property | B15: NSP | C15: N/A | D15: 0006
F16: TOTAL | G16: =G10+G11+G12 -> 0 | I16: =I10+I11+I12 -> 0 | J16: TOTAL EVALUATED PRICE

Sheet SUB CPIF RATES (ALL)
B1: MAJOR SUBCONTRACTOR | C1: NAME
B2: PRIME OFFEROR | C2: NAME
B4: KC-135 Center Console Refresh (CCR) Major Subontractor Direct Labor and Indirect Rates
B6: Notes:
B7: 1. The format of this worksheet may be revised as required to be consistent with the Major Subcontractor's approved Accounting System to include, but not limited to, inserting additional labor categories and revising the indirect rate structure
B8: 2. The Major Subcontractor shall propose labor rates and indirect rates in the yellow-highlighted cells below. All proposed labor rates shall be rounded to two (2) decimal places. All rates in percentages shall be rounded to four decimal places (ex. .0755 = 7.55%)
B9: 3. The Major Subcontractor shall input the proposed rates and indirect rates below and ensure these cells are linked correctly to the relevant CPIF rate cells on the "CPIF CLIN 0001 - TASK 1.0X" INPUTS", "CPIF CLIN 0002 - TASK 1.0X INPUTS", and "CPIF CLIN 0003 - TASK 1.0X INPUTS" worksheets
B10: 4. The Major Subcontractor shall provide descriptions of the labor categories and indirect rates in the "SUB CPIF RATE DESC (ALL)" worksheet, in addition to base costs upon which indirect rates apply
B11: 5. The Major Subcontractor shall ensure that all labor and indirect rate categories included in the proposal for EMD CLINs 0001, 0002, and 0003 are included in this worksheet
C13: Proposed Direct Labor Rates
C14: Basic (Year 1) | D14: Basic (Year 2) | E14: Basic (Year 3) | F14: Basic (Year 4)
B15: Labor Category | C15: Hourly Rate | D15: Hourly Rate | E15: Hourly Rate | F15: Hourly Rate
B16: Insert all direct labor categories that apply (add more rows if necessary); make changes to below categories accordingly and ensure cells properly link to the 'CPIF CLIN 000X - TASK 1.XX INPUTS' worksheets for CLINs 0001,0002, and 0003
C33: Proposed Indirect Rates/Factors
B34: Indirect Rate Category (Labor) | C34: Basic (Year 1) | D34: Basic (Year 2) | E34: Basic (Year 3) | F34: Basic (Year 4)
B35: Insert all indirect categories that apply to labor costs; make changes to below categories accordingly and ensure cells properly link to the 'CPIF CLIN 000X - TASK 1.XX INPUTS' worksheets (Columns E, I, and M for CLINs 0001,0002, and 0003) and align with the rates reflected in the 'SUB CPIF RATE DESC (ALL)' work sheet
B36: Indirect Labor Category: [Labor Fringe]
B37: Indirect Labor Category: [Labor Overhead]
B38: Indirect Labor Category: [G&A]
B39: Indirect Labor Category: [FCCOM]
B40: Indirect Labor Category: [Target Fee]
C42: Proposed Subcontractor Rates/Factors (Burdens added by Prime to Subcontractor Costs)
B43: Indirect Rate Category (Subcontractor) | C43: Basic (Year 1) | D43: Basic (Year 2) | E43: Basic (Year 3) | F43: Basic (Year 4)
B44: Insert all indirect categories that the Major Subcontractor will apply to subcontractor costs; make changes to below categories accordingly and ensure cells link properly to the 'CPIF CLIN 000X - TASK 1.XX INPUTS' worksheets (Columns E, I, and M for CLINs 0001, 0002, and 0003) and align with the rates reflected in the 'PRIME CPIF RATE DESC (ALL)' work sheet
B45: Indirect Category: [Overhead] | I45: `
B46: Indirect Category: [G&A]
B47: Indirect Category: [FCCOM]
B48: Indirect Category: [Target Fee]
C50: Proposed Material Rates/Factors
B51: Indirect Rate Category (Material) | C51: Basic (Year 1) | D51: Basic (Year 2) | E51: Basic (Year 3) | F51: Basic (Year 4)
B52: Insert all indirect categories that apply to material costs; make changes to below categories accordingly and ensure cells link properly to the 'CPIF CLIN 000X - TASK 1.XX INPUTS' worksheets (Columns, E, I, and M for CLINs 0001, 0002, and 0003) and align with the rates reflected in the 'PRIME CPIF Rate Desc (All)' work sheet
B53: Indirect Category: [Material Overhead]
B54: Indirect Category: [G&A]
B55: Indirect Category: [FCCOM]
B56: Indirect Category: [Target Fee]
C58: Proposed Other Direct Cost (ODC) Rates/Factors
B59: Indirect ODC Category (Other) | C59: Basic (Year 1) | D59: Basic (Year 2) | E59: Basic (Year 3) | F59: Basic (Year 4)
B60: Insert all indirect categories that apply to ODC; make changes to below categories accordingly and ensure cells link properly to the 'CPIF CLIN 000X - TASK 1.XX INPUTS' worksheets (Columns, E, I, and M for CLINs 0001, 0002, and 0003) and align with the rates reflected in the 'PRIME CPIF Rate Desc (All)' work sheet
B61: Indirect Category: [Overhead]
B62: Indirect Category: [G&A]
...

Sheet SUB CPIF RATE DESC (ALL)
B1: MAJOR SUBCONTRACTOR | C1: ='SUB CPIF RATES (ALL)'!C1 -> NAME
B2: PRIME OFFEROR | C2: ='SUB CPIF RATES (ALL)'!C2 -> NAME
B4: KC-135 Center Console Refresh (CCR) Major Subcontractor Direct Labor and Indirect Rates
B6: Notes:
B7: 1. The format of this worksheet may be revised as required to be consistent with the Major Subcontractor's approved Accounting System to include, but not limited to, inserting additional labor categories and revising the indirect rate structure
B8: 2. The Major Subcontractor shall list all proposed labor categories and provide a summary description for each labor category
B9: 3. The Major Subcontractor shall list all proposed indirect rate categories, and provide a summary description of each indirect rate category along with the base cost upon which the indirect rate is applied
B10: 4. The Major Subcontractor shall ensure that all labor and indirect rate categories included in the proposal for EMD CLINs 0001, 0002, and 0003 are included in this worksheet
B12: Labor Category and Indirect Rate Descriptions
B14: Labor Category | C14: Description
B15: Example Labor Category: Systems Engineer/Integrator | C15: Conducts comprehensive system-wide review and analysis of all aspects of the development life cycle. Provides expertise in the transition of legacy systems to modernized systems.
B16: ='SUB CPIF RATES (ALL)'!B17 -> 0
B17: ='SUB CPIF RATES (ALL)'!B18 -> 0
B18: ='SUB CPIF RATES (ALL)'!B19 -> 0
B19: ='SUB CPIF RATES (ALL)'!B20 -> 0
B20: ='SUB CPIF RATES (ALL)'!B21 -> 0
B21: ='SUB CPIF RATES (ALL)'!B22 -> 0
B22: ='SUB CPIF RATES (ALL)'!B23 -> 0
B23: ='SUB CPIF RATES (ALL)'!B24 -> 0
B24: ='SUB CPIF RATES (ALL)'!B25 -> 0
B25: ='SUB CPIF RATES (ALL)'!B26 -> 0
B26: ='SUB CPIF RATES (ALL)'!B27 -> 0
B27: ='SUB CPIF RATES (ALL)'!B28 -> 0
... B30: ='SUB CPIF RATES (ALL)'!B31 -> 0
B32: Indirect Rate Category | C32: Description | D32: Allocation Base (Provide the base upon which the Indirect Rate is applied)
B33: Example: Labor Fringe | C33: Includes employee retirement plans, health insurance, and paid time off for sick leave and vacation | D33: The base for Labor Fringe is total direct labor costs
B34: Labor Fringe
B35: Overhead (Labor)
B36: Overhead (Material)
B37: Overhead (Subcontractor)
B38: Overhead (ODC)
B39: General & Administrative (G&A)
B40: Facilities Capital Cost of Money (FCCOM)
B41: Target Fee

Sheet SUB CPIF LABOR by TASK
B1: MAJOR SUBCONTRACTOR | C1: ='SUB CPIF RATES (ALL)'!C1 -> NAME
B2: PRIME OFFEROR | C2: ='SUB CPIF RATES (ALL)'!C2 -> NAME
B4: KC-135 Center Console Refresh (CCR) Major Subcontractor Labor by Task
B6: Notes:
B7: 1. The format of this worksheet shall be revised to include every WBS (at the sub-task level) with proposed labor (if a WBS does not include proposed labor, do not include below)
B8: 2. At the sub-WBS level, the Prime Offeror shall provide the task to be performed, the labor category proposed to perform this task, the number of Full-Time Equivalents (FTEs) and corresponding labor hours to be utilized, and rationale to support the proposed labor
B9: 3. An example input has been provided in the template below (for illustrative purposes only); offerors shall delete the example in their proposal submission
A11: Task Number | B11: Task | C11: Labor Category | D11: # FTEs/Hours | E11: Rationale
A12: Example - For Illustrative Purposes Only
A13: 1.01 | B13: Development Thru PDR
A14: 1.01.01 | B14: ADD TITLE HERE | C14: ENGINEER I | D14: 2 FTEs x 1,784 hours | E14: To develop engineering plans
C15: ENGINEER II | E15: To evaluate engineering plans
C16: QUALITY SPECIALIST | E16: To evaluate quality of the engineering plans

Sheet SUB CPIF LABOR INPUTS
B1: MAJOR SUBCONTRACTOR | C1: ='SUB CPIF RATES (ALL)'!C1 -> NAME
B2: PRIME OFFEROR | C2: ='SUB CPIF RATES (ALL)'!C2 -> NAME
B4: Notes:
B5: 1. The format of this worksheet should be revised as required to include all proposed labor by task
B6: 2. The Major Subcontractor shall input the proposed labor categories and corresponding labor hours by task (at the sub-task level) in the yellow-highlighted cells below; ensure consistency with the "PRIME LABOR by TASK" worksheet
B7: 3. The Major Subcontractor shall ensure that the proposed labor rates properly link to the corresponding labor rates reflected in the "SUB-CPIF RATES (ALL)" worksheet
B8: 4. The Major Subcontractor shall ensure that all labor categories included in the proposal for EMD CLINs 0001, 0002, and 0003 are included in this worksheet
B10: CLIN 0001 DEVELOPMENT, TASK 1.01 DEVELOPMENT THROUGH PDR | D10: PROPOSED COSTS/PRICES - LABOR | H10: PROPOSED COSTS/PRICES - LABOR | L10: PROPOSED COSTS/PRICES - LABOR | P10: PROPOSED COSTS/PRICES - LABOR
D11: Basic Period (Year 1) | H11: Basic Period (Year 2) | L11: Basic Period (Year 3) | P11: Basic Period (Year 4)
B12: Labor Category | C12: Task | D12: Labor Hours | E12: Labor Rates | F12: Direct Labor Cost | H12: Labor Hours | I12: Labor Rates | J12: Direct Labor Cost | L12: Labor Hours | M12: Labor Rates | N12: Direct Labor Cost | P12: Labor Hours | Q12: Labor Rates | R12: Direct Labor Cost
B13: Insert all labor categories that apply; add/delete rows as necessary and ensure cells in Columns E, I, and M are properly linked to the rates in the 'SUB-CPIF RATES (ALL)' worksheet | C13: Insert applicable task by labor category at sub-task level (ex. 1.01.01, 1.01.02, and so forth); ensure consistency with the 'SUB LABOR by TASK' worksheet | D13: Insert proposed labor hours by labor category and sub-task | E13: Link corresponding proposed labor rate; ensure the labor rate aligns with 'SUB CPIF RATES (ALL)' worksheet | H13: Insert proposed labor hours by labor category and sub-task | I13: Link corresponding proposed labor rate; ensure the labor rate aligns with 'SUB CPIF RATES (ALL)' worksheet | L13: Insert proposed labor hours by labor category and sub-task | M13: Link corresponding proposed labor rate; ensure the labor rate aligns with 'SUB CPIF RATES (ALL)' worksheet | P13: Insert proposed labor hours by labor category and sub-task | Q13: Link corresponding proposed labor rate; ensure the labor rate aligns with 'SUB CPIF RATES (ALL)' worksheet
B14: Labor Category : [INSERT LABOR CATEGORY NAME HERE] | C14: 1.01.01 | D14: 0 | E14: 0 | F14: =ROUND(D14*E14,0) -> 0 | H14: 0 | I14: 0 | J14: =ROUND(H14*I14,0) -> 0 | L14: 0 | M14: 0 | N14: =ROUND(L14*M14,0) -> 0 | P14: 0 | Q14: 0 | R14: =ROUND(P14*Q14,0) -> 0
B15: Labor Category : [INSERT LABOR CATEGORY NAME HERE] | D15: 0 | E15: 0 | F15: =ROUND(D15*E15,0) -> 0 | H15: 0 | I15: 0 | J15: =ROUND(H15*I15,0) -> 0 | L15: 0 | M15: 0 | N15: =ROUND(L15*M15,0) -> 0 | P15: 0 | Q15: 0 | R15: =ROUND(P15*Q15,0) -> 0
B16: Labor Category : [INSERT LABOR CATEGORY NAME HERE] | D16: 0 | E16: 0 | F16: =ROUND(D16*E16,0) -> 0 | H16: 0 | I16: 0 | J16: =ROUND(H16*I16,0) -> 0 | L16: 0 | M16: 0 | N16: =ROUND(L16*M16,0) -> 0 | P16: 0 | Q16: 0 | R16: =ROUND(P16*Q16,0) -> 0
B17: Labor Category : [INSERT LABOR CATEGORY NAME HERE] | D17: 0 | E17: 0 | F17: =ROUND(D17*E17,0) -> 0 | H17: 0 | I17: 0 | J17: =ROUND(H17*I17,0) -> 0 | L17: 0 | M17: 0 | N17: =ROUND(L17*M17,0) -> 0 | P17: 0 | Q17: 0 | R17: =ROUND(P17*Q17,0) -> 0
B18: Labor Category : [INSERT LABOR CATEGORY NAME HERE] | D18: 0 | E18: 0 | F18: =ROUND(D18*E18,0) -> 0 | H18: 0 | I18: 0 | J18: =ROUND(H18*I18,0) -> 0 | L18: 0 | M18: 0 | N18: =ROUND(L18*M18,0) -> 0 | P18: 0 | Q18: 0 | R18: =ROUND(P18*Q18,0) -> 0
B19: Labor Category : [INSERT LABOR CATEGORY NAME HERE] | C19: 1.01.02 | D19: 0 | E19: 0 | F19: =ROUND(D19*E19,0) -> 0 | H19: 0 | I19: 0 | J19: =ROUND(H19*I19,0) -> 0 | L19: 0 | M19: 0 | N19: =ROUND(L19*M19,0) -> 0 | P19: 0 | Q19: 0 | R19: =ROUND(P19*Q19,0) -> 0
B20: Labor Category : [INSERT LABOR CATEGORY NAME HERE] | D20: 0 | E20: 0 | F20: =ROUND(D20*E20,0) -> 0 | H20: 0 | I20: 0 | J20: =ROUND(H20*I20,0) -> 0 | L20: 0 | M20: 0 | N20: =ROUND(L20*M20,0) -> 0 | P20: 0 | Q20: 0 | R20: =ROUND(P20*Q20,0) -> 0
B21: Labor Category : [INSERT LABOR CATEGORY NAME HERE] | D21: 0 | E21: 0 | F21: =ROUND(D21*E21,0) -> 0 | H21: 0 | I21: 0 | J21: =ROUND(H21*I21,0) -> 0 | L21: 0 | M21: 0 | N21: =ROUND(L21*M21,0) -> 0 | P21: 0 | Q21: 0 | R21: =ROUND(P21*Q21,0) -> 0
B22: Labor Category : [INSERT LABOR CATEGORY NAME HERE] | D22: 0 | E22: 0 | F22: =ROUND(D22*E22,0) -> 0 | H22: 0 | I22: 0 | J22: =ROUND(H22*I22,0) -> 0 | L22: 0 | M22: 0 | N22: =ROUND(L22*M22,0) -> 0 | P22: 0 | Q22: 0 | R22: =ROUND(P22*Q22,0) -> 0
B23: Labor Category : [INSERT LABOR CATEGORY NAME HERE] | D23: 0 | E23: 0 | F23: =ROUND(D23*E23,0) -> 0 | H23: 0 | I23: 0 | J23: =ROUND(H23*I23,0) -> 0 | L23: 0 | M23: 0 | N23: =ROUND(L23*M23,0) -> 0 | P23: 0 | Q23: 0 | R23: =ROUND(P23*Q23,0) -> 0
B24: Labor Category : [INSERT LABOR CATEGORY NAME HERE] | C24: 1.01.03 | D24: 0 | E24: 0 | F24: =ROUND(D24*E24,0) -> 0 | H24: 0 | I24: 0 | J24: =ROUND(H24*I24,0) -> 0 | L24: 0 | M24: 0 | N24: =ROUND(L24*M24,0) -> 0 | P24: 0 | Q24: 0 | R24: =ROUND(P24*Q24,0) -> 0
B25: Labor Category : [INSERT LABOR CATEGORY NAME HERE] | D25: 0 | E25: 0 | F25: =ROUND(D25*E25,0) -> 0 | H25: 0 | I25: 0 | J25: =ROUND(H25*I25,0) -> 0 | L25: 0 | M25: 0 | N25: =ROUND(L25*M25,0) -> 0 | P25: 0 | Q25: 0 | R25: =ROUND(P25*Q25,0) -> 0
B26: Labor Category : [INSERT LABOR CATEGORY NAME HERE] | D26: 0 | E26: 0 | F26: =ROUND(D26*E26,0) -> 0 | H26: 0 | I26: 0 | J26: =ROUND(H26*I26,0) -> 0 | L26: 0 | M26: 0 | N26: =ROUND(L26*M26,0) -> 0 | P26: 0 | Q26: 0 | R26: =ROUND(P26*Q26,0) -> 0
B27: Labor Category : [INSERT LABOR CATEGORY NAME HERE] | D27: 0 | E27: 0 | F27: =ROUND(D27*E27,0) -> 0 | H27: 0 | I27: 0 | J27: =ROUND(H27*I27,0) -> 0 | L27: 0 | M27: 0 | N27: =ROUND(L27*M27,0) -> 0 | P27: 0 | Q27: 0 | R27: =ROUND(P27*Q27,0) -> 0
B28: Labor Category : [INSERT LABOR CATEGORY NAME HERE] | D28: 0 | E28: 0 | F28: =ROUND(D28*E28,0) -> 0 | H28: 0 | I28: 0 | J28: =ROUND(H28*I28,0) -> 0 | L28: 0 | M28: 0 | N28: =ROUND(L28*M28,0) -> 0 | P28: 0 | Q28: 0 | R28: =ROUND(P28*Q28,0) -> 0
B29: TOTAL DIRECT LABOR HOURS/COST | D29: =SUM(D14:D28) -> 0 | F29: =ROUND(SUM(F14:F28),0) -> 0 | H29: =SUM(H14:H28) -> 0 | J29: =ROUND(SUM(J14:J28),0) -> 0 | L29: =SUM(L14:L28) -> 0 | N29: =ROUND(SUM(N14:N28),0) -> 0 | P29: =SUM(P14:P28) -> 0 | R29: =ROUND(SUM(R14:R28),0) -> 0
B31: CLIN 0001 DEVELOPMENT, TASK 1.02 DEVELOPMENT FROM PDR TO CDR | D31: PROPOSED COSTS/PRICES - LABOR | H31: PROPOSED COSTS/PRICES - LABOR | L31: PROPOSED COSTS/PRICES - LABOR | P31: PROPOSED COSTS/PRICES - LABOR
D32: =D11 -> Basic Period (Year 1) | H32: =H11 -> Basic Period (Year 2) | L32: =L11 -> Basic Period (Year 3) | P32: =P11 -> Basic Period (Year 4)
B33: Labor Category | C33: Task | D33: Labor Hours | E33: Labor Rates | F33: Direct Labor Cost | H33: Labor Hours | I33: Labor Rates | J33: Direct Labor Cost | L33: Labor Hours | M33: Labor Rates | N33: Direct Labor Cost | P33: Labor Hours | Q33: Labor Rates | R33: Direct Labor Cost
B34: Insert all labor categories that apply; add/delete rows as necessary and ensure cells in Columns E, I, and M are properly linked to the rates in the 'SUB-CPIF RATES (ALL)' worksheet | C34: Insert applicable task by labor category at sub-task level (ex. 1.01.01, 1.01.02, and so forth); ensure consistency with the 'SUB LABOR by TASK' worksheet | D34: Insert proposed labor hours by labor category and sub-task | E34: Link corresponding proposed labor rate; ensure the labor rate aligns with 'SUB CPIF RATES (ALL)' worksheet | H34: Insert proposed labor hours by labor category and sub-task | I34: Link corresponding proposed labor rate; ensure the labor rate aligns with 'SUB CPIF RATES (ALL)' worksheet | L34: Insert proposed labor hours by labor category and sub-task | M34: Link corresponding proposed labor rate; ensure the labor rate aligns with 'SUB CPIF RATES (ALL)' worksheet | P34: Insert proposed labor hours by labor category and sub-task | Q34: Link corresponding proposed labor rate; ensure the labor rate aligns with 'SUB CPIF RATES (ALL)' worksheet
B35: Labor Category : [INSERT LABOR CATEGORY NAME HERE] | C35: 1.02.01 | D35: 0 | E35: 0 | F35: =ROUND(D35*E35,0) -> 0 | H35: 0 | I35: 0 | J35: =ROUND(H35*I35,0) -> 0 | L35: 0 | M35: 0 | N35: =ROUND(L35*M35,0) -> 0 | P35: 0 | Q35: 0 | R35: =ROUND(P35*Q35,0) -> 0
B36: Labor Category : [INSERT LABOR CATEGORY NAME HERE] | D36: 0 | E36: 0 | F36: =ROUND(D36*E36,0) -> 0 | H36: 0 | I36: 0 | J36: =ROUND(H36*I36,0) -> 0 | L36: 0 | M36: 0 | N36: =ROUND(L36*M36,0) -> 0 | P36: 0 | Q36: 0 | R36: =ROUND(P36*Q36,0) -> 0
B37: Labor Category : [INSERT LABOR CATEGORY NAME HERE] | D37: 0 | E37: 0 | F37: =ROUND(D37*E37,0) -> 0 | H37: 0 | I37: 0 | J37: =ROUND(H37*I37,0) -> 0 | L37: 0 | M37: 0 | N37: =ROUND(L37*M37,0) -> 0 | P37: 0 | Q37: 0 | R37: =ROUND(P37*Q37,0) -> 0
B38: Labor Category : [INSERT LABOR CATEGORY NAME HERE] | D38: 0 | E38: 0 | F38: =ROUND(D38*E38,0) -> 0 | H38: 0 | I38: 0 | J38: =ROUND(H38*I38,0) -> 0 | L38: 0 | M38: 0 | N38: =ROUND(L38*M38,0) -> 0 | P38: 0 | Q38: 0 | R38: =ROUND(P38*Q38,0) -> 0
B39: Labor Category : [INSERT LABOR CATEGORY NAME HERE] | D39: 0 | E39: 0 | F39: =ROUND(D39*E39,0) -> 0 | H39: 0 | I39: 0 | J39: =ROUND(H39*I39,0) -> 0 | L39: 0 | M39: 0 | N39: =ROUND(L39*M39,0) -> 0 | P39: 0 | Q39: 0 | R39: =ROUND(P39*Q39,0) -> 0
B40: Labor Category : [INSERT LABOR CATEGORY NAME HERE] | C40: 1.02.02 | D40: 0 | E40: 0 | F40: =ROUND(D40*E40,0) -> 0 | H40: 0 | I40: 0 | J40: =ROUND(H40*I40,0) -> 0 | L40: 0 | M40: 0 | N40: =ROUND(L40*M40,0) -> 0 | P40: 0 | Q40: 0 | R40: =ROUND(P40*Q40,0) -> 0
B41: Labor Category : [INSERT LABOR CATEGORY NAME HERE] | D41: 0 | E41: 0 | F41: =ROUND(D41*E41,0) -> 0 | H41: 0 | I41: 0 | J41: =ROUND(H41*I41,0) -> 0 | L41: 0 | M41: 0 | N41: =ROUND(L41*M41,0) -> 0 | P41: 0 | Q41: 0 | R41: =ROUND(P41*Q41,0) -> 0
B42: Labor Category : [INSERT LABOR CATEGORY NAME HERE] | D42: 0 | E42: 0 | F42: =ROUND(D42*E42,0) -> 0 | H42: 0 | I42: 0 | J42: =ROUND(H42*I42,0) -> 0 | L42: 0 | M42: 0 | N42: =ROUND(L42*M42,0) -> 0 | P42: 0 | Q42: 0 | R42: =ROUND(P42*Q42,0) -> 0
B43: Labor Category : [INSERT LABOR CATEGORY NAME HERE] | D43: 0 | E43: 0 | F43: =ROUND(D43*E43,0) -> 0 | H43: 0 | I43: 0 | J43: =ROUND(H43*I43,0) -> 0 | L43: 0 | M43: 0 | N43: =ROUND(L43*M43,0) -> 0 | P43: 0 | Q43: 0 | R43: =ROUND(P43*Q43,0) -> 0
...

Sheet SUB CPIF TOTAL MATERIAL
B1: MAJOR SUBCONTRACTOR | C1: ='SUB CPIF RATES (ALL)'!C1 -> NAME
B2: PRIME OFFEROR | C2: ='SUB CPIF RATES (ALL)'!C2 -> NAME
B4: Notes:
B5: 1. In Contractor format, the Major Subcontractor shall provide data other than cost or pricing data in a Consolidated Bill of Material (CBOM) for all Material costs associated with EMD CLINs 0001, 0002, and 0003 (at the subtask level), in accordance with RFP Section L, Paragraph 7.3.2.
B6: 2. Populate the yellow-highlighted cells below to summarize the proposed material costs by CLIN/Task (the totals by CLIN/Task shall match the other than cost and pricing data provided in the CBOM)
B7: 3. Total Material costs by Task provided below are linked to each applicable worksheet (ex. "CPIF CLIN 0001 - TASK 1.01 INPUTS", "CPIF CLIN 0001 - TASK 1.02 INPUTS" and so forth); the Offeror shall ensure the cells are properly linked.
A9: KC-135 Center Console Refresh (CCR) - Proposed Material Summary CLINs 0001, 0002, and 0003 (CPIF) | E9: Basic Period - Year 1 | G9: Basic Period - Year 2 | I9: Basic Period - Year 3 | K9: Basic Period - Year 4
A10: Task | E10: Total Proposed Material Costs (CPIF) | G10: Total Proposed Material Costs (CPIF) | I10: Total Proposed Material Costs (CPIF) | K10: Total Proposed Material Costs (CPIF) | M10: Total Material Costs (CPIF)
A11: 1.0 | B11: Development
A12: 1.01 | C12: Development through PDR | D12: 0001 | M12: =E12+G12+I12+K12 -> 0
A13: 1.02 | C13: Development from PDR to CDR | D13: 0001 | M13: =E13+G13+I13+K13 -> 0
A14: 1.03 | C14: System Test and Evaluation | D14: 0001 | M14: =E14+G14+I14+K14 -> 0
A15: 1.04 | C15: Material - Development Kits (COTS and Developmental) | D15: 0001 | M15: =E15+G15+I15+K15 -> 0
A16: 1.05 | C16: Prototype Support, Installation, and Checkout | D16: 0001 | M16: =E16+G16+I16+K16 -> 0
A17: 1.06 | C17: Qualification, Developmental, and Operational Testing | D17: 0001 | M17: =E17+G17+I17+K17 -> 0
A18: 1.07 | C18: Material - Development Spares | D18: 0001 | M18: =E18+G18+I18+K18 -> 0
A19: 1.08 | C19: Black Label HW & SW Certification | D19: 0001 | M19: =E19+G19+I19+K19 -> 0
A20: 1.09 | C20: Systems Engineering and Program Management | D20: 0001 | M20: =E20+G20+I20+K20 -> 0
A21: 1.1 | C21: Aircrew and maintenance training | D21: 0001 | M21: =E21+G21+I21+K21 -> 0
A22: 1.11 | C22: Support Equipment | D22: 0001 | M22: =E22+G22+I22+K22 -> 0
C23: Total CPIF CLIN 0001 | E23: =SUM(E12:E22) -> 0 | G23: =SUM(G12:G22) -> 0 | I23: =SUM(I12:I22) -> 0 | K23: =SUM(K12:K22) -> 0 | M23: =E23+G23+I23+K23 -> 0
A24: 1.0 | B24: Simulator Kit
A25: 1.01 | C25: Support required to determine elements of Simulator Kit | D25: 0002 | M25: =E25+G25+I25+K25 -> 0
A26: 1.02 | C26: Material - 1 Simulator kit (Ref Section L) | D26: 0002 | M26: =E26+G26+I26+K26 -> 0
A27: 1.03 | C27: Delivery of material to Simulator SPO | D27: 0002 | M27: =E27+G27+I27+K27 -> 0
C28: Total CPIF CLIN 0002 | E28: =E25+E26+E27 -> 0 | G28: =G25+G26+G27 -> 0 | I28: =I25+I26+I27 -> 0 | K28: =K25+K26+K27 -> 0 | M28: =E28+G28+I28+K28 -> 0
A29: 1.0 | B29: Systems Integration Laboratory
A30: 1.01 | C30: Development Labor to Have an Operational SIL | D30: 0003 | M30: =E30+G30+I30+K30 -> 0
A31: 1.02 | C31: Material - Contractor Procured Material for SIL | D31: 0003 | M31: =E31+G31+I31+K31 -> 0
A32: 1.03 | C32: Material - Anticipated Required GFE | D32: 0003 | M32: =E32+G32+I32+K32 -> 0
A33: 1.04 | C33: Delivery of SIL to Government | D33: 0003 | M33: =E33+G33+I33+K33 -> 0
C34: Total CPIF CLIN 0003 | E34: =E30+E31+E32+E33 -> 0 | G34: =G30+G31+G32+G33 -> 0 | I34: =I30+I31+I32+I33 -> 0 | K34: =K30+K31+K32+K33 -> 0 | M34: =E34+G34+I34+K34 -> 0
E36: =E23+E28+E34 -> 0 | G36: =G23+G28+G34 -> 0 | I36: =I23+I28+I34 -> 0 | K36: =K23+K28+K34 -> 0 | M36: =M23+M28+M34 -> 0 | N36: Total Material Costs (CPIF)
M38: =E36+G36+I36+K36 -> 0 | N38: Double Check
M39: =M36-M38 -> 0 | N39: Difference should be $0

Sheet SUB CPIF TOTAL SUB
B1: MAJOR SUBCONTRACTOR | C1: ='SUB CPIF RATES (ALL)'!C1 -> NAME
B2: PRIME OFFEROR | C2: ='SUB CPIF RATES (ALL)'!C2 -> NAME
B4: Notes:
B5: 1. The Major Subcontractor Offeror shall provide data other than cost and pricing data for all proposed subcontractor costs associated with EMD CLINs 0001, 0002, and 0003; for each Major Subcontractor (valued at $2.5M+), a separate cost model (Attachment 3B) shall be submitted
B6: 2. Populate the yellow-highlighted cells below to summarize the proposed subcontractor costs by CLIN/Task
B7: 3. Total subcontractor costs by Task provided below are linked to each applicable worksheet (ex. "CPIF CLIN 0001 - TASK 1.01 INPUTS", "CPIF CLIN 0001 - TASK 1.02 INPUTS" and so forth); the Offeror shall ensure the cells are properly linked.
A9: KC-135 Center Console Refresh (CCR) - Proposed Subcontractor Summary CLINs 0001, 0002, and 0003 (CPIF) | E9: Basic Period - Year 1 | G9: Basic Period - Year 2 | I9: Basic Period - Year 3 | K9: Basic Period - Year 4
A10: TASK | E10: Total Proposed Subcontractor Costs (CPIF) | G10: Total Proposed Subcontractor Costs (CPIF) | I10: Total Proposed Subcontractor Costs (CPIF) | K10: Total Proposed Subcontractor Costs (CPIF) | M10: Total Subcontractor Costs (CPIF)
A11: 1.0 | B11: Development
A12: 1.01 | C12: Development through PDR | D12: 0001 | M12: =E12+G12+I12+K12 -> 0
A13: 1.02 | C13: Development from PDR to CDR | D13: 0001 | M13: =E13+G13+I13+K13 -> 0
A14: 1.03 | C14: System Test and Evaluation | D14: 0001 | M14: =E14+G14+I14+K14 -> 0
A15: 1.04 | C15: Material - Development Kits (COTS and Developmental) | D15: 0001 | M15: =E15+G15+I15+K15 -> 0
A16: 1.05 | C16: Prototype Support, Installation, and Checkout | D16: 0001 | M16: =E16+G16+I16+K16 -> 0
A17: 1.06 | C17: Qualification, Developmental, and Operational Testing | D17: 0001 | M17: =E17+G17+I17+K17 -> 0
A18: 1.07 | C18: Material - Development Spares | D18: 0001 | M18: =E18+G18+I18+K18 -> 0
A19: 1.08 | C19: Black Label HW & SW Certification | D19: 0001 | M19: =E19+G19+I19+K19 -> 0
A20: 1.09 | C20: Systems Engineering and Program Management | D20: 0001 | M20: =E20+G20+I20+K20 -> 0
A21: 1.1 | C21: Aircrew and maintenance training | D21: 0001 | M21: =E21+G21+I21+K21 -> 0
A22: 1.11 | C22: Support Equipment | D22: 0001 | M22: =E22+G22+I22+K22 -> 0
C23: Total CPIF CLIN 0001 | E23: =SUM(E12:E22) -> 0 | G23: =SUM(G12:G22) -> 0 | I23: =SUM(I12:I22) -> 0 | K23: =SUM(K12:K22) -> 0 | M23: =E23+G23+I23+K23 -> 0
A24: 1.0 | B24: Simulator Kit
A25: 1.01 | C25: Support required to determine elements of Simulator Kit | D25: 0002 | M25: =E25+G25+I25+K25 -> 0
A26: 1.02 | C26: Material - 1 Simulator kit (Ref Section L) | D26: 0002 | M26: =E26+G26+I26+K26 -> 0
A27: 1.03 | C27: Delivery of material to Simulator SPO | D27: 0002 | M27: =E27+G27+I27+K27 -> 0
C28: Total CPIF CLIN 0002 | E28: =E25+E26+E27 -> 0 | G28: =G25+G26+G27 -> 0 | I28: =I25+I26+I27 -> 0 | K28: =K25+K26+K27 -> 0 | M28: =E28+G28+I28+K28 -> 0
A29: 1.0 | B29: Systems Integration Laboratory
A30: 1.01 | C30: Development Labor to Have an Operational SIL | D30: 0003 | M30: =E30+G30+I30+K30 -> 0
A31: 1.02 | C31: Material - Contractor Procured Material for SIL | D31: 0003 | M31: =E31+G31+I31+K31 -> 0
A32: 1.03 | C32: Material - Anticipated Required GFE | D32: 0003 | M32: =E32+G32+I32+K32 -> 0
A33: 1.04 | C33: Delivery of SIL to Government | D33: 0003 | M33: =E33+G33+I33+K33 -> 0
C34: Total CPIF CLIN 0003 | E34: =E30+E31+E32+E33 -> 0 | G34: =G30+G31+G32+G33 -> 0 | I34: =I30+I31+I32+I33 -> 0 | K34: =K30+K31+K32+K33 -> 0 | M34: =E34+G34+I34+K34 -> 0
E36: =E23+E28+E34 -> 0 | G36: =G23+G28+G34 -> 0 | I36: =I23+I28+I34 -> 0 | K36: =K23+K28+K34 -> 0 | M36: =M23+M28+M34 -> 0 | N36: Total Subcontractor Costs (CPIF)
M38: =E36+G36+I36+K36 -> 0 | N38: Double Check
M39: =M36-M38 -> 0 | N39: Difference should be $0

Sheet SUB CPIF TOTAL ODC
B1: MAJOR SUBCONTRACTOR | C1: ='SUB CPIF RATES (ALL)'!C1 -> NAME
B2: PRIME OFFEROR | C2: ='SUB CPIF RATES (ALL)'!C2 -> NAME
B4: Notes:
B5: 1. In Contractor format, the Major Subcontractor shall provide data other than cost or pricing data (at the sub-Task level) for all Other Direct Costs associated with EMD CLINs 0001, 0002, and 0003, if applicable. Data may be provided as an additional worksheet in this EPW or as an attachment
B6: 2. Populate the yellow-highlighted cells below to summarize the proposed ODC by CLIN/Task (the totals by CLIN/Task shall match the other than cost and pricing data provided in Contractor format)
B7: 3. Total ODC by Task provided below are linked to each applicable worksheet (ex. "CPIF CLIN 0001 - TASK 1.01 INPUTS", "CPIF CLIN 0001 - TASK 1.02 INPUTS" and so forth); the Offeror shall ensure the cells are properly linked.
A10: KC-135 Center Console Refresh (CCR) - Proposed Subcontractor Summary CLINs 0001, 0002, and 0003 (CPIF) | E10: Basic Period - Year 1 | G10: Basic Period - Year 2 | I10: Basic Period - Year 3 | K10: Basic Period - Year 4
A11: TASK | E11: Total Proposed Other Direct Costs (CPIF) | G11: Total Proposed Other Direct Costs (CPIF) | I11: Total Proposed Other Direct Costs (CPIF) | K11: Total Proposed Other Direct Costs (CPIF) | M11: Total Other Direct Costs (CPIF)
A12: 1.0 | B12: Development
A13: 1.01 | C13: Development through PDR | D13: 0001 | M13: =E13+G13+I13+K13 -> 0
A14: 1.02 | C14: Development from PDR to CDR | D14: 0001 | M14: =E14+G14+I14+K14 -> 0
A15: 1.03 | C15: System Test and Evaluation | D15: 0001 | M15: =E15+G15+I15+K15 -> 0
A16: 1.04 | C16: Material - Development Kits (COTS and Developmental) | D16: 0001 | M16: =E16+G16+I16+K16 -> 0
A17: 1.05 | C17: Prototype Support, Installation, and Checkout | D17: 0001 | M17: =E17+G17+I17+K17 -> 0
A18: 1.06 | C18: Qualification, Developmental, and Operational Testing | D18: 0001 | M18: =E18+G18+I18+K18 -> 0
A19: 1.07 | C19: Material - Development Spares | D19: 0001 | M19: =E19+G19+I19+K19 -> 0
A20: 1.08 | C20: Black Label HW & SW Certification | D20: 0001 | M20: =E20+G20+I20+K20 -> 0
A21: 1.09 | C21: Systems Engineering and Program Management | D21: 0001 | M21: =E21+G21+I21+K21 -> 0
A22: 1.1 | C22: Aircrew and maintenance training | D22: 0001 | M22: =E22+G22+I22+K22 -> 0
A23: 1.11 | C23: Support Equipment | D23: 0001 | M23: =E23+G23+I23+K23 -> 0
C24: Total CPIF CLIN 0001 | E24: =E13+E14+E15+E16+E17+E18+E19+E20+E21+E22+E23 -> 0 | G24: =G13+G14+G15+G16+G17+G18+G19+G20+G21+G22+G23 -> 0 | I24: =I13+I14+I15+I16+I17+I18+I19+I20+I21+I22+I23 -> 0 | K24: =K13+K14+K15+K16+K17+K18+K19+K20+K21+K22+K23 -> 0 | M24: =E24+G24+I24+K24 -> 0
A25: 1.0 | B25: Simulator Kit
A26: 1.01 | C26: Support required to determine elements of Simulator Kit | D26: 0002 | M26: =E26+G26+I26+K26 -> 0
A27: 1.02 | C27: Material - 1 Simulator kit (Ref Section L) | D27: 0002 | M27: =E27+G27+I27+K27 -> 0
A28: 1.03 | C28: Delivery of material to Simulator SPO | D28: 0002 | M28: =E28+G28+I28+K28 -> 0
C29: Total CPIF CLIN 0002 | E29: =E26+E27+E28 -> 0 | G29: =G26+G27+G28 -> 0 | I29: =I26+I27+I28 -> 0 | K29: =K26+K27+K28 -> 0 | M29: =E29+G29+I29+K29 -> 0
A30: 1.0 | B30: Systems Integration Laboratory
A31: 1.01 | C31: Development Labor to Have an Operational SIL | D31: 0003 | M31: =E31+G31+I31+K31 -> 0
A32: 1.02 | C32: Material - Contractor Procured Material for SIL | D32: 0003 | M32: =E32+G32+I32+K32 -> 0
A33: 1.03 | C33: Material - Anticipated Required GFE | D33: 0003 | M33: =E33+G33+I33+K33 -> 0
A34: 1.04 | C34: Delivery of SIL to Government | D34: 0003 | M34: =E34+G34+I34+K34 -> 0
C35: Total CPIF CLIN 0003 | E35: =E32+E33+E34 -> 0 | G35: =G32+G33+G34 -> 0 | I35: =I32+I33+I34 -> 0 | K35: =K32+K33+K34 -> 0 | M35: =E35+G35+I35+K35 -> 0
E37: =E24+E29+E35 -> 0 | G37: =G24+G29+G35 -> 0 | I37: =I24+I29+I35 -> 0 | K37: =K24+K29+K35 -> 0 | M37: =M24+M29+M35 -> 0 | N37: Total Other Direct Costs (CPIF)
M39: =E37+G37+I37+K37 -> 0 | N39: Double Check
M40: =M37-M39 -> 0 | N40: Difference should be $0

Sheet CPIF CLIN 0001 SUMMARY
B1: MAJOR SUBCONTRACTOR | C1: ='SUB CPIF RATES (ALL)'!C1 -> NAME
B2: PRIME OFFEROR | C2: ='SUB CPIF RATES (ALL)'!C2 -> NAME
A4: Note: Offerors shall ensure the proposed unit prices are properly linked to the corresponding "CPIF CLIN 0001-TASK 1.XX INPUTS" worksheets
A6: KC-135 Center Console Refresh (CCR) Competitive Pricing Matrix CLIN 0001: Development (CPIF) | E6: Basic Period (Year 1) | I6: Basic Period (Year 2) | M6: Basic Period (Year 3) | Q6: Basic Period (Year 4)
A7: Development Tasks | D7: Basic Period CLIN | E7: By Event | F7: Unit Price | G7: Extended Target Price | I7: By Event | J7: Unit Price | K7: Extended Target Price | M7: By Event | N7: Unit Price | O7: Extended Target Price | Q7: By Event | R7: Unit Price | S7: Extended Target Price | U7: TOTAL CPIF CLIN 0001
A8: 1.0 | B8: Development | C8: Task
A9: 1.01 | C9: Development through PDR | D9: 0001 | E9: 1 | F9: ='CPIF CLIN 0001-TASK 1.01 INPUTS'!E80 -> 0 | G9: =ROUND(E9*F9,2) -> 0 | I9: 1 | J9: ='CPIF CLIN 0001-TASK 1.01 INPUTS'!I80 -> 0 | K9: =ROUND(I9*J9,2) -> 0 | M9: 1 | N9: ='CPIF CLIN 0001-TASK 1.01 INPUTS'!M80 -> 0 | O9: =ROUND(M9*N9,2) -> 0 | Q9: 1 | R9: ='CPIF CLIN 0001-TASK 1.01 INPUTS'!Q80 -> 0 | S9: =ROUND(Q9*R9,2) -> 0 | U9: =G9+K9+O9+S9 -> 0
A10: 1.02 | C10: Development from PDR to CDR | D10: 0001 | E10: 1 | F10: ='CPIF CLIN 0001-TASK 1.02 INPUTS'!E78 -> 0 | G10: =ROUND(E10*F10,2) -> 0 | I10: 1 | J10: ='CPIF CLIN 0001-TASK 1.02 INPUTS'!I78 -> 0 | K10: =ROUND(I10*J10,2) -> 0 | M10: 1 | N10: ='CPIF CLIN 0001-TASK 1.02 INPUTS'!M78 -> 0 | O10: =ROUND(M10*N10,2) -> 0 | Q10: 1 | R10: ='CPIF CLIN 0001-TASK 1.02 INPUTS'!Q78 -> 0 | S10: =ROUND(Q10*R10,2) -> 0 | U10: =G10+K10+O10+S10 -> 0
A11: 1.03 | C11: System Test and Evaluation | D11: 0001 | E11: 1 | F11: ='CPIF CLIN 0001-TASK 1.03 INPUTS'!E78 -> 0 | G11: =ROUND(E11*F11,2) -> 0 | I11: 1 | J11: ='CPIF CLIN 0001-TASK 1.03 INPUTS'!I78 -> 0 | K11: =ROUND(I11*J11,2) -> 0 | M11: 1 | N11: ='CPIF CLIN 0001-TASK 1.03 INPUTS'!M78 -> 0 | O11: =ROUND(M11*N11,2) -> 0 | Q11: 1 | R11: ='CPIF CLIN 0001-TASK 1.03 INPUTS'!Q78 -> 0 | S11: =ROUND(Q11*R11,2) -> 0 | U11: =G11+K11+O11+S11 -> 0
A12: 1.04 | C12: Material - Development Kits (COTS and Developmental) | D12: 0001 | E12: 1 | F12: ='CPIF CLIN 0001 TASK 1.04 INPUTS'!E78 -> 0 | G12: =ROUND(E12*F12,2) -> 0 | I12: 1 | J12: ='CPIF CLIN 0001 TASK 1.04 INPUTS'!I78 -> 0 | K12: =ROUND(I12*J12,2) -> 0 | M12: 1 | N12: ='CPIF CLIN 0001 TASK 1.04 INPUTS'!M78 -> 0 | O12: =ROUND(M12*N12,2) -> 0 | Q12: 1 | R12: ='CPIF CLIN 0001 TASK 1.04 INPUTS'!Q78 -> 0 | S12: =ROUND(Q12*R12,2) -> 0 | U12: =G12+K12+O12+S12 -> 0
A13: 1.05 | C13: Prototype Support, Installation, and Checkout | D13: 0001 | E13: 1 | F13: ='CPIF CLIN 0001-TASK 1.05 INPUTS'!E78 -> 0 | G13: =ROUND(E13*F13,2) -> 0 | I13: 1 | J13: ='CPIF CLIN 0001-TASK 1.05 INPUTS'!I78 -> 0 | K13: =ROUND(I13*J13,2) -> 0 | M13: 1 | N13: ='CPIF CLIN 0001-TASK 1.05 INPUTS'!M78 -> 0 | O13: =ROUND(M13*N13,2) -> 0 | Q13: 1 | R13: ='CPIF CLIN 0001-TASK 1.05 INPUTS'!Q78 -> 0 | S13: =ROUND(Q13*R13,2) -> 0 | U13: =G13+K13+O13+S13 -> 0
A14: 1.06 | C14: Qualification, Developmental, and Operational Testing | D14: 0001 | E14: 1 | F14: ='CPIF CLIN 0001-TASK 1.06 INPUTS'!E78 -> 0 | G14: =ROUND(E14*F14,2) -> 0 | I14: 1 | J14: ='CPIF CLIN 0001-TASK 1.06 INPUTS'!I78 -> 0 | K14: =ROUND(I14*J14,2) -> 0 | M14: 1 | N14: ='CPIF CLIN 0001-TASK 1.06 INPUTS'!M78 -> 0 | O14: =ROUND(M14*N14,2) -> 0 | Q14: 1 | R14: ='CPIF CLIN 0001-TASK 1.06 INPUTS'!Q78 -> 0 | S14: =ROUND(Q14*R14,2) -> 0 | U14: =G14+K14+O14+S14 -> 0
A15: 1.07 | C15: Material - Development Spares | D15: 0001 | E15: 1 | F15: ='CPIF CLIN 0001-TASK 1.07 INPUTS'!E78 -> 0 | G15: =ROUND(E15*F15,2) -> 0 | I15: 1 | J15: ='CPIF CLIN 0001-TASK 1.07 INPUTS'!I78 -> 0 | K15: =ROUND(I15*J15,2) -> 0 | M15: 1 | N15: ='CPIF CLIN 0001-TASK 1.07 INPUTS'!M78 -> 0 | O15: =ROUND(M15*N15,2) -> 0 | Q15: 1 | R15: ='CPIF CLIN 0001-TASK 1.07 INPUTS'!Q78 -> 0 | S15: =ROUND(Q15*R15,2) -> 0 | U15: =G15+K15+O15+S15 -> 0
A16: 1.08 | C16: Black Label HW & SW Certification | D16: 0001 | E16: 1 | F16: ='CPIF CLIN 0001-TASK 1.08 INPUTS'!E78 -> 0 | G16: =ROUND(E16*F16,2) -> 0 | I16: 1 | J16: ='CPIF CLIN 0001-TASK 1.08 INPUTS'!I78 -> 0 | K16: =ROUND(I16*J16,2) -> 0 | M16: 1 | N16: ='CPIF CLIN 0001-TASK 1.08 INPUTS'!M78 -> 0 | O16: =ROUND(M16*N16,2) -> 0 | Q16: 1 | R16: ='CPIF CLIN 0001-TASK 1.08 INPUTS'!Q78 -> 0 | S16: =ROUND(Q16*R16,2) -> 0 | U16: =G16+K16+O16+S16 -> 0
A17: 1.09 | C17: Systems Engineering and Program Management | D17: 0001 | E17: 1 | F17: ='CPIF CLIN 0001-TASK 1.09 INPUTS'!E78 -> 0 | G17: =ROUND(E17*F17,2) -> 0 | I17: 1 | J17: ='CPIF CLIN 0001-TASK 1.09 INPUTS'!I78 -> 0 | K17: =ROUND(I17*J17,2) -> 0 | M17: 1 | N17: ='CPIF CLIN 0001-TASK 1.09 INPUTS'!M78 -> 0 | O17: =ROUND(M17*N17,2) -> 0 | Q17: 1 | R17: ='CPIF CLIN 0001-TASK 1.09 INPUTS'!Q78 -> 0 | S17: =ROUND(Q17*R17,2) -> 0 | U17: =G17+K17+O17+S17 -> 0
A18: 1.1 | C18: Aircrew and Maintenance Training | D18: 0001 | E18: 1 | F18: ='CPIF CLIN 0001-TASK 1.10 INPUTS'!E78 -> 0 | G18: =ROUND(E18*F18,2) -> 0 | I18: 1 | J18: ='CPIF CLIN 0001-TASK 1.10 INPUTS'!I78 -> 0 | K18: =ROUND(I18*J18,2) -> 0 | M18: 1 | N18: ='CPIF CLIN 0001-TASK 1.10 INPUTS'!M78 -> 0 | O18: =ROUND(M18*N18,2) -> 0 | Q18: 1 | R18: ='CPIF CLIN 0001-TASK 1.10 INPUTS'!Q78 -> 0 | S18: =ROUND(Q18*R18,2) -> 0 | U18: =G18+K18+O18+S18 -> 0
A19: 1.11 | C19: Support Equipment | D19: 0001 | E19: 1 | F19: ='CPIF CLIN 0001-TASK 1.11 INPUTS'!E78 -> 0 | G19: =ROUND(E19*F19,2) -> 0 | I19: 1 | J19: ='CPIF CLIN 0001-TASK 1.11 INPUTS'!I78 -> 0 | K19: =ROUND(I19*J19,2) -> 0 | M19: 1 | N19: ='CPIF CLIN 0001-TASK 1.11 INPUTS'!M78 -> 0 | O19: =ROUND(M19*N19,2) -> 0 | Q19: 1 | R19: ='CPIF CLIN 0001-TASK 1.11 INPUTS'!Q78 -> 0 | S19: =ROUND(Q19*R19,2) -> 0 | U19: =G19+K19+O19+S19 -> 0
F20: TOTAL CPIF CLIN 0001 (Year 1) | G20: =SUM(G9:G19) -> 0 | J20: TOTAL CPIF CLIN 0001 (Year 2) | K20: =SUM(K9:K19) -> 0 | N20: TOTAL CPIF CLIN 0001 (Year 3) | O20: =SUM(O9:O19) -> 0 | R20: TOTAL CPIF CLIN 0001 (Year 4) | S20: =SUM(S9:S19) -> 0 | U20: =SUM(U9:U19) -> 0 | V20: TOTAL CPIF CLIN 0001
U22: =G20+K20+O20+S20 -> 0 | V22: Double Check
U23: =U20-U22 -> 0 | V23: Difference should be $0

Sheet CPIF CLIN 0001-TASK 1.01 INPUTS
B1: Offeror: | C1: =#REF! -> #REF!
B3: MAJOR SUBCONTRACTOR | C3: ='SUB CPIF RATES (ALL)'!C1 -> NAME
B4: PRIME OFFEROR | C4: ='SUB CPIF RATES (ALL)'!C2 -> NAME
A6: KC-135 Center Console Refresh (CCR) Competitive Pricing Matrix CLIN 0001: Development (CPIF)
B8: Notes:
B9: 1. The format of this worksheet may be revised as required to be consistent with the Major Subcontractor's approved accounting system; amend base costs and direct/indirect rates as necessary
B10: 2. Proposed costs for Labor, Material, Subcontractor, and Other Direct Costs (ODCs) are linked to corresponding worksheets as specified below - no input required
B11: 3. The proposed indirect rates are linked to the "SUB CPIF RATES (ALL)" worksheet and will automatically be applied to the proposed amounts for labor, material, ODC, and subcontractor costs (CPIF Target Cost, Target FCCOM, Target Fee, and Total Price will automatically calculate)
B12: 4. The Major Subcontractor shall amend the indirect categories as needed, and ensure the proposed indirect rates are properly linked to the "SUB CPIF RATES (ALL)" worksheet
B13: 5. Definitions of the labor categories and indirect rates are included in the "SUB CPIF RATE (ALL)" worksheet; the Offeror shall amend as necessary
B14: 6. The total target price for CLIN 0001, TASK 1.01 will automatically calculate for the Basic Period
B16: CLIN 0001 (CPIF) TASK 1.01 DEVELOPMENT THROUGH PDR | C16: PROPOSED COSTS/PRICES - LABOR | G16: PROPOSED COSTS/PRICES - LABOR | K16: PROPOSED COSTS/PRICES - LABOR | O16: PROPOSED COSTS/PRICES - LABOR
C17: CLIN 0001 - Basic Period (Year 1) | G17: CLIN 0001 - Basic Period (Year 2) | K17: CLIN 0001 - Basic Period (Year 3) | O17: CLIN 0001 - Basic Period (Year 4)
B18: Labor Category | C18: Labor Hours | E18: Direct Labor Cost | G18: Labor Hours | I18: Direct Labor Cost | K18: Labor Hours | M18: Direct Labor Cost | O18: Labor Hours | Q18: Direct Labor Cost
B19: No input - total labor (labor hours and total labor costs) linked to the 'SUB CPIF LABOR INPUTS' worksheet
B20: TOTAL DIRECT LABOR HOURS/COST | C20: ='SUB CPIF LABOR INPUTS'!D29 -> 0 | E20: ='SUB CPIF LABOR INPUTS'!F29 -> 0 | G20: ='SUB CPIF LABOR INPUTS'!H29 -> 0 | I20: ='SUB CPIF LABOR INPUTS'!J29 -> 0 | K20: ='SUB CPIF LABOR INPUTS'!L29 -> 0 | M20: ='SUB CPIF LABOR INPUTS'!N29 -> 0 | O20: ='SUB CPIF LABOR INPUTS'!P29 -> 0 | Q20: ='SUB CPIF LABOR INPUTS'!R29 -> 0
C21: Base Cost | D21: Rate | E21: Labor Cost | G21: Base Cost | H21: Rate | I21: Labor Cost | K21: Base Cost | L21: Rate | M21: Labor Cost | O21: Base Cost | P21: Rate | Q21: Labor Cost
B22: Insert all indirect categories that apply to labor; make changes to indirect categories in Column B accordingly and amend links in Columns C, G, K, and O as needed. Also ensure rates in Columns D, H, L and P are properly linked to 'PRIME-CPIF Rates (All)' worksheet
B23: ='SUB CPIF RATES (ALL)'!B36 -> Indirect Labor Category: [Labor Fringe] | C23: =E20 -> 0 | D23: ='SUB CPIF RATES (ALL)'!C36 -> 0 | E23: =ROUND(C23*D23,2) -> 0 | G23: =I20 -> 0 | H23: ='SUB CPIF RATES (ALL)'!D36 -> 0 | I23: =ROUND(G23*H23,2) -> 0 | K23: =+M20 -> 0 | L23: ='SUB CPIF RATES (ALL)'!E36 -> 0 | M23: =ROUND(K23*L23,2) -> 0 | O23: =+Q20 -> 0 | P23: ='SUB CPIF RATES (ALL)'!F36 -> 0 | Q23: =ROUND(O23*P23,2) -> 0
B24: ='SUB CPIF RATES (ALL)'!B37 -> Indirect Labor Category: [Labor Overhead] | C24: =C23+E23 -> 0 | D24: ='SUB CPIF RATES (ALL)'!C37 -> 0 | E24: =ROUND(C24*D24,2) -> 0 | G24: =G23+I23 -> 0 | H24: ='SUB CPIF RATES (ALL)'!D37 -> 0 | I24: =ROUND(G24*H24,2) -> 0 | K24: =+K23+M23 -> 0 | L24: ='SUB CPIF RATES (ALL)'!E37 -> 0 | M24: =ROUND(K24*L24,2) -> 0 | O24: =+O23+Q23 -> 0 | P24: ='SUB CPIF RATES (ALL)'!F37 -> 0 | Q24: =ROUND(O24*P24,2) -> 0
B25: ='SUB CPIF RATES (ALL)'!B38 -> Indirect Labor Category: [G&A] | C25: =C24+E24 -> 0 | D25: ='SUB CPIF RATES (ALL)'!C38 -> 0 | E25: =ROUND(C25*D25,2) -> 0 | G25: =G24+I24 -> 0 | H25: ='SUB CPIF RATES (ALL)'!D38 -> 0 | I25: =ROUND(G25*H25,2) -> 0 | K25: =+K24+M24 -> 0 | L25: ='SUB CPIF RATES (ALL)'!E38 -> 0 | M25: =ROUND(K25*L25,2) -> 0 | O25: =+O24+Q24 -> 0 | P25: ='SUB CPIF RATES (ALL)'!F38 -> 0 | Q25: =ROUND(O25*P25,2) -> 0
B26: ='SUB CPIF RATES (ALL)'!B39 -> Indirect Labor Category: [FCCOM] | C26: =C25+E25 -> 0 | D26: ='SUB CPIF RATES (ALL)'!C39 -> 0 | E26: =ROUND(C26*D26,2) -> 0 | G26: =I20 -> 0 | H26: ='SUB CPIF RATES (ALL)'!D39 -> 0 | I26: =ROUND(G26*H26,2) -> 0 | K26: =K25+M25 -> 0 | L26: ='SUB CPIF RATES (ALL)'!E39 -> 0 | M26: =ROUND(K26*L26,2) -> 0 | O26: =O25+Q25 -> 0 | P26: ='SUB CPIF RATES (ALL)'!F39 -> 0 | Q26: =ROUND(O26*P26,2) -> 0
B27: ='SUB CPIF RATES (ALL)'!B40 -> Indirect Labor Category: [Target Fee] | C27: =C25+E25 -> 0 | D27: ='SUB CPIF RATES (ALL)'!C40 -> 0 | E27: =ROUND(C27*D27,2) -> 0 | G27: =G25+I25 -> 0 | H27: ='SUB CPIF RATES (ALL)'!D40 -> 0 | I27: =ROUND(G27*H27,2) -> 0 | K27: =+K25+M25 -> 0 | L27: ='SUB CPIF RATES (ALL)'!E40 -> 0 | M27: =ROUND(K27*L27,2) -> 0 | O27: =+O25+Q25 -> 0 | P27: ='SUB CPIF RATES (ALL)'!F40 -> 0 | Q27: =ROUND(O27*P27,2) -> 0
B28: Total Proposed Target Labor Cost | E28: =ROUND(SUM(E20,E23,E24,E25),2) -> 0 | I28: =ROUND(SUM(I20,I23,I24,I25),2) -> 0 | M28: =ROUND(SUM(M20,M23,M24,M25),2) -> 0 | Q28: =ROUND(SUM(Q20,Q23,Q24,Q25),2) -> 0
B29: Total Proposed Target FCCOM | E29: =ROUND(E26,2) -> 0 | I29: =ROUND(I26,2) -> 0 | M29: =ROUND(M26,2) -> 0 | Q29: =ROUND(Q26,2) -> 0
B30: Total Proposed Target Fee | E30: =ROUND(E27,2) -> 0 | I30: =ROUND(I27,2) -> 0 | M30: =ROUND(M27,2) -> 0 | Q30: =ROUND(Q27,2) -> 0
B31: Total Proposed Labor Price (Target) | E31: =ROUND(SUM(E28:E30),2) -> 0 | I31: =ROUND(SUM(I28:I30),2) -> 0 | M31: =ROUND(SUM(M28:M30),2) -> 0 | Q31: =ROUND(SUM(Q28:Q30),2) -> 0
B33: CLIN 0001 (CPIF) TASK 1.01 DEVELOPMENT THROUGH PDR | C33: PROPOSED COSTS/PRICES - MATERIAL | G33: PROPOSED COSTS/PRICES - MATERIAL | K33: PROPOSED COSTS/PRICES - MATERIAL | O33: PROPOSED COSTS/PRICES - MATERIAL
C34: =C17 -> CLIN 0001 - Basic Period (Year 1) | G34: =G17 -> CLIN 0001 - Basic Period (Year 2) | K34: =K17 -> CLIN 0001 - Basic Period (Year 3) | O34: =O17 -> CLIN 0001 - Basic Period (Year 4)
C35: =C21 -> Base Cost | D35: =D21 -> Rate | E35: Material Cost | G35: =G21 -> Base Cost | H35: =H21 -> Rate | I35: Material Cost | K35: =K21 -> Base Cost | L35: =L21 -> Rate | M35: Material Cost | O35: =O21 -> Base Cost | P35: =P21 -> Rate | Q35: Material Cost
B36: No input - material costs linked to the 'SUB CPIF TOTAL MATERIAL' worksheet (amounts shall also match total material in Consolidated Bill of Materials (CBOM) in RFP Section L, Paragraph 7.3.2 | E36: ='SUB CPIF TOTAL MATERIAL'!E12 -> 0 | I36: ='SUB CPIF TOTAL MATERIAL'!G12 -> 0 | M36: ='SUB CPIF TOTAL MATERIAL'!I12 -> 0 | Q36: ='SUB CPIF TOTAL MATERIAL'!K12 -> 0
B37: Insert all indirect categories that apply to material; make changes to indirect categories in Column B accordingly and amend links in Columns C, G, K, and O as needed. Also ensure rates in Columns D, H, L and P are properly linked to 'SUB-CPIF RATES (ALL)' worksheet
B38: ='SUB CPIF RATES (ALL)'!B53 -> Indirect Category: [Material Overhead] | C38: =E36 -> 0 | D38: ='SUB CPIF RATES (ALL)'!C53 -> 0 | E38: =ROUND(C38*D38,2) -> 0 | G38: =I36 -> 0 | H38: ='SUB CPIF RATES (ALL)'!D53 -> 0 | I38: =ROUND(G38*H38,2) -> 0 | K38: =M36 -> 0 | L38: ='SUB CPIF RATES (ALL)'!E53 -> 0 | M38: =ROUND(K38*L38,2) -> 0 | O38: =Q36 -> 0 | P38: ='SUB CPIF RATES (ALL)'!F53 -> 0 | Q38: =ROUND(O38*P38,2) -> 0
B39: ='SUB CPIF RATES (ALL)'!B54 -> Indirect Category: [G&A] | C39: =E36+E38 -> 0 | D39: ='SUB CPIF RATES (ALL)'!C54 -> 0 | E39: =ROUND(C39*D39,2) -> 0 | G39: =I36+I38 -> 0 | H39: ='SUB CPIF RATES (ALL)'!D54 -> 0 | I39: =ROUND(G39*H39,2) -> 0 | K39: =M36+M38 -> 0 | L39: ='SUB CPIF RATES (ALL)'!E54 -> 0 | M39: =ROUND(K39*L39,2) -> 0 | O39: =Q36+Q38 -> 0 | P39: ='SUB CPIF RATES (ALL)'!F54 -> 0 | Q39: =ROUND(O39*P39,2) -> 0
B40: ='SUB CPIF RATES (ALL)'!B55 -> Indirect Category: [FCCOM] | C40: =C39+E39 -> 0 | D40: ='SUB CPIF RATES (ALL)'!C55 -> 0 | E40: =ROUND(C40*D40,2) -> 0 | G40: =G39+I39 -> 0 | H40: ='SUB CPIF RATES (ALL)'!D55 -> 0 | I40: =ROUND(G40*H40,2) -> 0 | K40: =K39+M39 -> 0 | L40: ='SUB CPIF RATES (ALL)'!E55 -> 0 | M40: =ROUND(K40*L40,2) -> 0 | O40: =O39+Q39 -> 0 | P40: ='SUB CPIF RATES (ALL)'!F55 -> 0 | Q40: =ROUND(O40*P40,2) -> 0
B41: ='SUB CPIF RATES (ALL)'!B56 -> Indirect Category: [Target Fee] | C41: =C39+E39 -> 0 | D41: ='SUB CPIF RATES (ALL)'!C56 -> 0 | E41: =ROUND(C41*D41,2) -> 0 | G41: =G39+I39 -> 0 | H41: ='SUB CPIF RATES (ALL)'!D56 -> 0 | I41: =ROUND(G41*H41,2) -> 0 | K41: =K39+M39 -> 0 | L41: ='SUB CPIF RATES (ALL)'!E56 -> 0 | M41: =ROUND(K41*L41,2) -> 0 | O41: =O39+Q39 -> 0 | P41: ='SUB CPIF RATES (ALL)'!F56 -> 0 | Q41: =ROUND(O41*P41,2) -> 0
B42: Total Proposed Target Material Cost | E42: =ROUND(SUM(E36:E39),2) -> 0 | I42: =ROUND(SUM(I36:I39),2) -> 0 | M42: =ROUND(SUM(M36:M39),2) -> 0 | Q42: =ROUND(SUM(Q36:Q39),2) -> 0
B43: Total Proposed Target FCCOM | E43: =ROUND(E40,2) -> 0 | I43: =ROUND(I40,2) -> 0 | M43: =ROUND(M40,2) -> 0 | Q43: =ROUND(Q40,2) -> 0
B44: Total Proposed Target Fee | E44: =ROUND(E41,2) -> 0 | I44: =ROUND(I41,2) -> 0 | M44: =ROUND(M41,2) -> 0 | Q44: =ROUND(Q41,2) -> 0
B45: Total Proposed Material Price (Target) | E45: =SUM(E42:E44) -> 0 | I45: =SUM(I42:I44) -> 0 | M45: =SUM(M42:M44) -> 0 | Q45: =SUM(Q42:Q44) -> 0
...

Sheet CPIF CLIN 0001-TASK 1.02 INPUTS
B1: MAJOR SUBCONTRACTOR | C1: ='SUB CPIF RATES (ALL)'!C1 -> NAME
B2: PRIME OFFEROR | C2: ='SUB CPIF RATES (ALL)'!C2 -> NAME
A4: KC-135 Center Console Refresh (CCR) Competitive Pricing Matrix CLIN 0001: Development (CPIF)
B6: Notes:
B7: 1. The format of this worksheet may be revised as required to be consistent with the Major Subcontractor's approved accounting system; amend base costs and direct/indirect rates as necessary
B8: 2. Proposed costs for Labor, Material, Subcontractor, and Other Direct Costs (ODCs) are linked to corresponding worksheets as specified below - no input required
B9: 3. The proposed indirect rates are linked to the "SUB CPIF RATES (ALL)" worksheet and will automatically be applied to the proposed amounts for labor, material, ODC, and subcontractor costs (CPIF Target Cost, Target FCCOM, Target Fee, and Total Price will automatically calculate)
B10: 4. The Major Subcontractor shall amend the indirect categories as needed, and ensure the proposed indirect rates are properly linked to the "SUB CPIF RATES (ALL)" worksheet
B11: 5. Definitions of the labor categories and indirect rates are included in the "SUB CPIF RATE (ALL)" worksheet; the Offeror shall amend as necessary
B12: 6. The total target price for CLIN 0001, TASK 1.02 will automatically calculate for the Basic Period
B14: CLIN 0001 (CPIF) TASK 1.02 DEVELOPMENT FROM PDR TO CDR | C14: PROPOSED COSTS/PRICES - LABOR | G14: PROPOSED COSTS/PRICES - LABOR | K14: PROPOSED COSTS/PRICES - LABOR | O14: PROPOSED COSTS/PRICES - LABOR
C15: CLIN 0001 - Basic Period (Year 1) | G15: CLIN 0001 - Basic Period (Year 2) | K15: CLIN 0001 - Basic Period (Year 3) | O15: CLIN 0001 - Basic Period (Year 4)
B16: Labor Category | C16: Labor Hours | E16: Direct Labor Cost | G16: Labor Hours | I16: Direct Labor Cost | K16: Labor Hours | M16: Direct Labor Cost | O16: Labor Hours | Q16: Direct Labor Cost
B17: No input - total labor (labor hours and total labor costs) linked to the 'SUB CPIF LABOR INPUTS' worksheet
B18: TOTAL DIRECT LABOR HOURS/COST | C18: ='SUB CPIF LABOR INPUTS'!D50 -> 0 | E18: ='SUB CPIF LABOR INPUTS'!F50 -> 0 | G18: ='SUB CPIF LABOR INPUTS'!H50 -> 0 | I18: ='SUB CPIF LABOR INPUTS'!J50 -> 0 | K18: ='SUB CPIF LABOR INPUTS'!L50 -> 0 | M18: ='SUB CPIF LABOR INPUTS'!N50 -> 0 | O18: ='SUB CPIF LABOR INPUTS'!P50 -> 0 | Q18: ='SUB CPIF LABOR INPUTS'!R50 -> 0
C19: Base Cost | D19: Rate | E19: Labor Cost | G19: Base Cost | H19: Rate | I19: Labor Cost | K19: Base Cost | L19: Rate | M19: Labor Cost | O19: Base Cost | P19: Rate | Q19: Labor Cost
B20: Insert all indirect categories that apply to labor; make changes to indirect categories in Column B accordingly and amend links in Columns C, G, K, and O as needed. Also ensure rates in Columns D, H, L and P are properly linked to 'PRIME-CPIF Rates (All)' worksheet
B21: ='SUB CPIF RATES (ALL)'!B36 -> Indirect Labor Category: [Labor Fringe] | C21: =+E18 -> 0 | D21: ='SUB CPIF RATES (ALL)'!C36 -> 0 | E21: =ROUND(C21*D21,2) -> 0 | G21: =+I18 -> 0 | H21: ='SUB CPIF RATES (ALL)'!D36 -> 0 | I21: =ROUND(G21*H21,2) -> 0 | K21: =+M18 -> 0 | L21: ='SUB CPIF RATES (ALL)'!E36 -> 0 | M21: =ROUND(K21*L21,2) -> 0 | O21: =+Q18 -> 0 | P21: ='SUB CPIF RATES (ALL)'!F36 -> 0 | Q21: =ROUND(O21*P21,2) -> 0
B22: ='SUB CPIF RATES (ALL)'!B37 -> Indirect Labor Category: [Labor Overhead] | C22: =+C21+E21 -> 0 | D22: ='SUB CPIF RATES (ALL)'!C37 -> 0 | E22: =ROUND(C22*D22,2) -> 0 | G22: =+G21+I21 -> 0 | H22: ='SUB CPIF RATES (ALL)'!D37 -> 0 | I22: =ROUND(G22*H22,2) -> 0 | K22: =+K21+M21 -> 0 | L22: ='SUB CPIF RATES (ALL)'!E37 -> 0 | M22: =ROUND(K22*L22,2) -> 0 | O22: =+O21+Q21 -> 0 | P22: ='SUB CPIF RATES (ALL)'!F37 -> 0 | Q22: =ROUND(O22*P22,2) -> 0
B23: ='SUB CPIF RATES (ALL)'!B38 -> Indirect Labor Category: [G&A] | C23: =+C22+E22 -> 0 | D23: ='SUB CPIF RATES (ALL)'!C38 -> 0 | E23: =ROUND(C23*D23,2) -> 0 | G23: =+G22+I22 -> 0 | H23: ='SUB CPIF RATES (ALL)'!D38 -> 0 | I23: =ROUND(G23*H23,2) -> 0 | K23: =+K22+M22 -> 0 | L23: ='SUB CPIF RATES (ALL)'!E38 -> 0 | M23: =ROUND(K23*L23,2) -> 0 | O23: =+O22+Q22 -> 0 | P23: ='SUB CPIF RATES (ALL)'!F38 -> 0 | Q23: =ROUND(O23*P23,2) -> 0
B24: ='SUB CPIF RATES (ALL)'!B39 -> Indirect Labor Category: [FCCOM] | C24: =C23+E23 -> 0 | D24: ='SUB CPIF RATES (ALL)'!C39 -> 0 | E24: =ROUND(C24*D24,2) -> 0 | G24: =G23+I23 -> 0 | H24: ='SUB CPIF RATES (ALL)'!D39 -> 0 | I24: =ROUND(G24*H24,2) -> 0 | K24: =K23+M23 -> 0 | L24: ='SUB CPIF RATES (ALL)'!E39 -> 0 | M24: =ROUND(K24*L24,2) -> 0 | O24: =O23+Q23 -> 0 | P24: ='SUB CPIF RATES (ALL)'!F39 -> 0 | Q24: =ROUND(O24*P24,2) -> 0
B25: ='SUB CPIF RATES (ALL)'!B40 -> Indirect Labor Category: [Target Fee] | C25: =+C23+E23 -> 0 | D25: ='SUB CPIF RATES (ALL)'!C40 -> 0 | E25: =ROUND(C25*D25,2) -> 0 | G25: =+G23+I23 -> 0 | H25: ='SUB CPIF RATES (ALL)'!D40 -> 0 | I25: =ROUND(G25*H25,2) -> 0 | K25: =+K23+M23 -> 0 | L25: ='SUB CPIF RATES (ALL)'!E40 -> 0 | M25: =ROUND(K25*L25,2) -> 0 | O25: =+O23+Q23 -> 0 | P25: ='SUB CPIF RATES (ALL)'!F40 -> 0 | Q25: =ROUND(O25*P25,2) -> 0
B26: Total Proposed Target Labor Cost | E26: =ROUND(SUM(E18,E21,E22,E23),2) -> 0 | I26: =ROUND(SUM(I18,I21,I22,I23),2) -> 0 | M26: =ROUND(SUM(M18,M21,M22,M23),2) -> 0 | Q26: =ROUND(SUM(Q18,Q21,Q22,Q23),2) -> 0
B27: Total Proposed FCCOM | E27: =ROUND(E24,2) -> 0 | I27: =ROUND(I24,2) -> 0 | M27: =ROUND(M24,2) -> 0 | Q27: =ROUND(Q24,2) -> 0
B28: Total Proposed Target Fee | E28: =ROUND(E25,2) -> 0 | I28: =ROUND(I25,2) -> 0 | M28: =ROUND(M25,2) -> 0 | Q28: =ROUND(Q25,2) -> 0
B29: Total Proposed Labor Price (Target) | E29: =ROUND(SUM(E26:E28),2) -> 0 | I29: =ROUND(SUM(I26:I28),2) -> 0 | M29: =ROUND(SUM(M26:M28),2) -> 0 | Q29: =ROUND(SUM(Q26:Q28),2) -> 0
B31: =B14 -> CLIN 0001 (CPIF) TASK 1.02 DEVELOPMENT FROM PDR TO CDR | C31: PROPOSED COSTS/PRICES - MATERIAL | G31: PROPOSED COSTS/PRICES - MATERIAL | K31: PROPOSED COSTS/PRICES - MATERIAL | O31: PROPOSED COSTS/PRICES - MATERIAL
C32: =C15 -> CLIN 0001 - Basic Period (Year 1) | G32: =G15 -> CLIN 0001 - Basic Period (Year 2) | K32: =K15 -> CLIN 0001 - Basic Period (Year 3) | O32: =O15 -> CLIN 0001 - Basic Period (Year 4)
C33: =C19 -> Base Cost | D33: =D19 -> Rate | E33: Material Cost | G33: =G19 -> Base Cost | H33: =H19 -> Rate | I33: Material Cost | K33: =K19 -> Base Cost | L33: =L19 -> Rate | M33: Material Cost | O33: =O19 -> Base Cost | P33: =P19 -> Rate | Q33: Material Cost
B34: No input - material costs linked to the 'SUB CPIF TOTAL MATERIAL' worksheet (amounts shall also match total material in Consolidated Bill of Materials (CBOM) in RFP Section L, Paragraph 7.3.2 | E34: ='SUB CPIF TOTAL MATERIAL'!E13 -> 0 | I34: ='SUB CPIF TOTAL MATERIAL'!G13 -> 0 | M34: ='SUB CPIF TOTAL MATERIAL'!I13 -> 0 | Q34: ='SUB CPIF TOTAL MATERIAL'!K13 -> 0
B35: Insert all indirect categories that apply to material; make changes to indirect categories in Column B accordingly and amend links in Columns C, G, K, and O as needed. Also ensure rates in Columns D, H, L and P are properly linked to 'SUB-CPIF RATES (ALL)' worksheet
B36: ='SUB CPIF RATES (ALL)'!B53 -> Indirect Category: [Material Overhead] | C36: =+E34 -> 0 | D36: ='SUB CPIF RATES (ALL)'!C53 -> 0 | E36: =ROUND(C36*D36,2) -> 0 | G36: =+I34 -> 0 | H36: ='SUB CPIF RATES (ALL)'!D53 -> 0 | I36: =ROUND(G36*H36,2) -> 0 | K36: =+M34 -> 0 | L36: ='SUB CPIF RATES (ALL)'!E53 -> 0 | M36: =ROUND(K36*L36,2) -> 0 | O36: =+Q34 -> 0 | P36: ='SUB CPIF RATES (ALL)'!F53 -> 0 | Q36: =ROUND(O36*P36,2) -> 0
B37: ='SUB CPIF RATES (ALL)'!B54 -> Indirect Category: [G&A] | C37: =+C36+E36 -> 0 | D37: ='SUB CPIF RATES (ALL)'!C54 -> 0 | E37: =ROUND(C37*D37,2) -> 0 | G37: =+G36+I36 -> 0 | H37: ='SUB CPIF RATES (ALL)'!D54 -> 0 | I37: =ROUND(G37*H37,2) -> 0 | K37: =+K36+M36 -> 0 | L37: ='SUB CPIF RATES (ALL)'!E54 -> 0 | M37: =ROUND(K37*L37,2) -> 0 | O37: =+O36+Q36 -> 0 | P37: ='SUB CPIF RATES (ALL)'!F54 -> 0 | Q37: =ROUND(O37*P37,2) -> 0
B38: ='SUB CPIF RATES (ALL)'!B55 -> Indirect Category: [FCCOM] | C38: =C37+E37 -> 0 | D38: ='SUB CPIF RATES (ALL)'!C55 -> 0 | E38: =ROUND(C38*D38,2) -> 0 | G38: =G37+I37 -> 0 | H38: ='SUB CPIF RATES (ALL)'!D55 -> 0 | I38: =ROUND(G38*H38,2) -> 0 | K38: =K37+M37 -> 0 | L38: ='SUB CPIF RATES (ALL)'!E55 -> 0 | M38: =ROUND(K38*L38,2) -> 0 | O38: =O37+Q37 -> 0 | P38: ='SUB CPIF RATES (ALL)'!F55 -> 0 | Q38: =ROUND(O38*P38,2) -> 0
B39: ='SUB CPIF RATES (ALL)'!B56 -> Indirect Category: [Target Fee] | C39: =+C37+E37 -> 0 | D39: ='SUB CPIF RATES (ALL)'!C56 -> 0 | E39: =ROUND(C39*D39,2) -> 0 | G39: =+G37+I37 -> 0 | H39: ='SUB CPIF RATES (ALL)'!D56 -> 0 | I39: =ROUND(G39*H39,2) -> 0 | K39: =+K37+M37 -> 0 | L39: ='SUB CPIF RATES (ALL)'!E56 -> 0 | M39: =ROUND(K39*L39,2) -> 0 | O39: =+O37+Q37 -> 0 | P39: ='SUB CPIF RATES (ALL)'!F56 -> 0 | Q39: =ROUND(O39*P39,2) -> 0
B40: Total Proposed Target Material Cost | E40: =ROUND(SUM(E34:E37),2) -> 0 | I40: =ROUND(SUM(I34:I37),2) -> 0 | M40: =ROUND(SUM(M34:M37),2) -> 0 | Q40: =ROUND(SUM(Q34:Q37),2) -> 0
B41: Total Proposed FCCOM | E41: =ROUND(E38,2) -> 0 | I41: =ROUND(I38,2) -> 0 | M41: =ROUND(M38,2) -> 0 | Q41: =ROUND(Q38,2) -> 0
B42: Total Proposed Target Fee | E42: =ROUND(E39,2) -> 0 | I42: =ROUND(I39,2) -> 0 | M42: =ROUND(M39,2) -> 0 | Q42: =ROUND(Q39,2) -> 0
B43: Total Proposed Material Price (Target) | E43: =SUM(E40:E42) -> 0 | I43: =SUM(I40:I42) -> 0 | M43: =SUM(M40:M42) -> 0 | Q43: =SUM(Q40:Q42) -> 0
B45: =B14 -> CLIN 0001 (CPIF) TASK 1.02 DEVELOPMENT FROM PDR TO CDR | C45: PROPOSED COSTS/PRICES - SUBCONTRACTOR | G45: PROPOSED COSTS/PRICES - SUBCONTRACTOR | K45: PROPOSED COSTS/PRICES - SUBCONTRACTOR | O45: PROPOSED COSTS/PRICES - SUBCONTRACTOR
...

Sheet CPIF CLIN 0001-TASK 1.03 INPUTS
B1: MAJOR SUBCONTRACTOR | C1: ='SUB CPIF RATES (ALL)'!C1 -> NAME
B2: PRIME OFFEROR | C2: ='SUB CPIF RATES (ALL)'!C2 -> NAME
A4: KC-135 Center Console Refresh (CCR) Competitive Pricing Matrix CLIN 0001: Development (CPIF)
B6: Notes:
B7: 1. The format of this worksheet may be revised as required to be consistent with the Major Subcontractor's approved accounting system; amend base costs and direct/indirect rates as necessary
B8: 2. Proposed costs for Labor, Material, Subcontractor, and Other Direct Costs (ODCs) are linked to corresponding worksheets as specified below - no input required
