Workbook

Sheet Instructions
A1: Requirement Name: | B1: Marine Corps Prepositioning Program
A2: RFP Number: | B2: M67004-26-R-0007 | F2: Attachment J-7: Cost Model Workbook
A3: Company Name (Prime):
A6: This Cost Model Workbook reflects the Contract Line Item Number (CLIN) Structure and shall be used when submitting the Cost/Price Proposal Volume VI.
A8: * Fillable cells are highlighted in Yellow.
A9: * Enter the Contractor Name in Cell B3. This entry will auto-populate the other Tabs.
A10: * Each tab includes its own Instructions.
A11: * The Total Proposed Price Tab pulls values from all of the other Tabs and calculates the Total Proposed Price.

Sheet Total Proposed Price
A1: M67004-26-R-0007 Attachment J-7: Cost Model Workbook
A2: Contractor Name: | D2: =IF(Instructions!B3="","",Instructions!B3)
A4: *CLINX002 and CLIN X003 in below table Order Year 1 has a dollar value calculated already based on example line items in the CLINX002 and CLINX003 tabs.
A5: *CLINX002 and X003 for each Year is a summation of straight time and overtime. CLINX002 and X003 have their own overtime tab.
A6: *CLINX004 is a Government provided plug number. The Offeror shall proposed fixed fee (ceiling) that will apply to future task orders under this CLIN.
A7: *CLINX005 is a Government provided plug number and no action is required by the Offeror.
A8: *CLINX006 allows indirect rates to be applied but cannot apply fee.
A9: *CLINX007 is Not Seperately Priced (NSP) and no action is required by the Offeror.
E12: Base Ordering Period | J12: Optional Ordering Period
B13: CLIN | D13: Description | E13: Order Year 1 | F13: Order Year 2 | G13: Order Year 3 | H13: Order Year 4 | I13: Order Year 5 | J13: Option Year 1 | K13: Option Year 2 | L13: Option Year 3 | M13: Option Year 4 | N13: Option Year 5 | O13: Total Price
B14: X001 | C14: FFP | D14: Program Management Labor | E14: =CLINX001!F11 -> 0 | F14: =CLINX001!F12 -> 0 | G14: =CLINX001!F13 -> 0 | H14: =CLINX001!F14 -> 0 | I14: =CLINX001!F15 -> 0 | J14: =CLINX001!F20 -> 0 | K14: =CLINX001!F21 -> 0 | L14: =CLINX001!F22 -> 0 | M14: =CLINX001!F23 -> 0 | N14: =CLINX001!F24 -> 0 | O14: =SUM(E14:N14) -> 0
B15: X002 | C15: CPFF | D15: MCPP Labor (CONUS) | E15: =CLINX002!Z138+'CLINX002 OT'!W135 -> 1259053.7 | F15: =CLINX002!Z263+'CLINX002 OT'!W260 -> 0 | G15: =CLINX002!Z387+'CLINX002 OT'!W384 -> 0 | H15: =CLINX002!Z511+'CLINX002 OT'!W508 -> 0 | I15: =CLINX002!Z635+'CLINX002 OT'!W632 -> 0 | J15: =CLINX002!Z759+'CLINX002 OT'!W756 -> 0 | K15: =CLINX002!Z883+'CLINX002 OT'!W880 -> 0 | L15: =CLINX002!Z1007+'CLINX002 OT'!W1004 -> 0 | M15: =CLINX002!Z1131+'CLINX002 OT'!W1128 -> 0 | N15: =CLINX002!Z1255+'CLINX002 OT'!W1252 -> 0 | O15: =SUM(E15:N15) -> 1259053.7
B16: X003 | C16: CPFF | D16: MCPP Labor (OCONUS) | E16: =CLINX003!Z57+'CLINX003 OT'!W55 -> 1524108.1 | F16: =CLINX003!Z100+'CLINX003 OT'!W99 -> 0 | G16: =CLINX003!Z143+'CLINX003 OT'!W143 -> 0 | H16: =CLINX003!Z186+'CLINX003 OT'!W187 -> 0 | I16: =CLINX003!Z229+'CLINX003 OT'!W231 -> 0 | J16: =CLINX003!Z272+'CLINX003 OT'!W275 -> 0 | K16: =CLINX003!Z315+'CLINX003 OT'!W319 -> 0 | L16: =CLINX003!Z358+'CLINX003 OT'!W363 -> 0 | M16: =CLINX003!Z401+'CLINX003 OT'!W407 -> 0 | N16: =CLINX003!Z444+'CLINX003 OT'!W451 -> 0 | O16: =SUM(E16:N16) -> 1524108.1
B17: X004 | C17: CPFF | D17: Other Logistics Support | E17: =CLINX004!F11 -> 1850000 | F17: =CLINX004!F12 -> 1903650 | G17: =CLINX004!F13 -> 1958855.8 | H17: =CLINX004!F14 -> 2015662.7 | I17: =CLINX004!F15 -> 2074116.9 | J17: =CLINX004!F20 -> 2134266.3 | K17: =CLINX004!F21 -> 2196160 | L17: =CLINX004!F22 -> 2259848.6 | M17: =CLINX004!F23 -> 2325384.2 | N17: =CLINX004!F24 -> 2392820.4 | O17: =SUM(E17:N17) -> 21110765
B18: X005 | C18: CNF | D18: Travel | E18: 3827666 | F18: 4438668.3 | G18: 5552889.7 | H18: 6170423.5 | I18: 7291365.8 | J18: 7502815.4 | K18: 7720397.1 | L18: 7944288.6 | M18: 8174672.9 | N18: 8411738.5 | O18: =SUM(E18:N18) -> 67034926
B19: X006 | C19: CNF | D19: Other Direct Costs | E19: =CLINX006!H11 -> 64414905 | F19: =CLINX006!H12 -> 66282937 | G19: =CLINX006!H13 -> 68205142 | H19: =CLINX006!H14 -> 70183091 | I19: =CLINX006!H15 -> 72218401 | J19: =CLINX006!H20 -> 74312734 | K19: =CLINX006!H21 -> 76467804 | L19: =CLINX006!H22 -> 78685370 | M19: =CLINX006!H23 -> 80967246 | N19: =CLINX006!H24 -> 83315296 | O19: =SUM(E19:N19) -> 7.3505293e+08
B20: X007 | C20: NSP | D20: Data Requirements/CDRLs | E20: NSP | F20: NSP | G20: NSP | H20: NSP | I20: NSP | J20: NSP | K20: NSP | L20: NSP | M20: NSP | N20: NSP | O20: NSP
B21: 0008 | C21: FFP | D21: Transition (first task order only) | E21: =CLIN0008!G12 -> 0 | O21: =E21 -> 0
D22: Total Price | E22: =SUM(E14:E21) -> 72875733 | F22: =SUM(F14:F21) -> 72625255 | G22: =SUM(G14:G21) -> 75716888 | H22: =SUM(H14:H21) -> 78369177 | I22: =SUM(I14:I21) -> 81583884 | J22: =SUM(J14:J21) -> 83949816 | K22: =SUM(K14:K21) -> 86384361 | L22: =SUM(L14:L21) -> 88889507 | ... O22: =SUM(O14:O21) -> 8.2598178e+08
N25: =O16-E16+F16 -> 0

Sheet CLINX001
A1: M67004-26-R-0007 Attachment J-7: Cost Model Workbook
A2: Contractor Name: | C2: =IF(Instructions!B3="","",Instructions!B3)
A3: * Offerors shall fill in the yellow cells below for the Monthly FFP amount proposed to perform Program and Risk Management support in accordance with Sections C.1 and C.2 of the Statement of Work.
A4: * FFP monthly amount shall be inclusive of all costs necessary to perform this work (e.g., direct labor, indirect rates, profit, and any other costs necessary to accomplish this work other than those defined in the other CLINs or RFP Section H-4).
A9: CLIN 0001 Base Ordering Period
A10: Year # | B10: Description | C10: Qty | D10: Unit Price | E10: Unit of Issue | F10: Total Price
A11: Year 1 | B11: Program Management | C11: 12 | E11: Months | F11: =C11*D11 -> 0
A12: Year 2 | B12: Program Management | C12: 12 | E12: Months | F12: =C12*D12 -> 0
A13: Year 3 | B13: Program Management | C13: 12 | E13: Months | F13: =C13*D13 -> 0
A14: Year 4 | B14: Program Management | C14: 12 | E14: Months | F14: =C14*D14 -> 0
A15: Year 5 | B15: Program Management | C15: 12 | E15: Months | F15: =C15*D15 -> 0
B16: CLIN 0001 SUBTOTAL | C16: 60 | E16: Months | F16: =SUM(F11:F15) -> 0
A18: CLIN 1001 Optional Ordering Period
A19: Year # | B19: Description | C19: Qty | D19: Unit Price | E19: Unit of Issue | F19: Total Price
A20: Year 1 | B20: Program Management | C20: 12 | E20: Months | F20: =C20*D20 -> 0
A21: Year 2 | B21: Program Management | C21: 12 | E21: Months | F21: =C21*D21 -> 0
A22: Year 3 | B22: Program Management | C22: 12 | E22: Months | F22: =C22*D22 -> 0
A23: Year 4 | B23: Program Management | C23: 12 | E23: Months | F23: =C23*D23 -> 0
A24: Year 5 | B24: Program Management | C24: 12 | E24: Months | F24: =C24*D24 -> 0
B25: CLIN 1001 SUBTOTAL | C25: 60 | E25: Months | F25: =SUM(F20:F24) -> 0
D27: TOTAL | F27: =F25+F16 -> 0

Sheet CLINX002
A1: M67004-26-R-0007 Attachment J-7: Cost Model Workbook
A2: Contractor Name: | C2: =IF(Instructions!B3="","",Instructions!B3)
A3: * Rows 17–21 (blue) are examples only. Delete or modify these rows as needed. Ensure the Total cell at the bottom of each Ordering Period (Column Z) remains linked to the Total Proposed Price tab.
A4: * Input cells are highlighted in yellow. Non‑yellow cells contain formulas used to calculate the Total Price in Column Z.
A5: * Rows may be added or deleted as needed to reflect your manning solution. Use “N/A” in cells that do not apply.
A6: * Drop‑down selections are provided for Labor Type, Labor Category, Fringe Pool, and Job Location.
A7: * Column D: Identify where each position fits within your manning solution. This should align with the Organization Structure required in Section L.6, Volume II – Management Proposal.
A8: * Productive Hours (Column H): Calculate as total available hours per year minus weekends, holidays, and PTO for the proposed location.
A9: * Labor Hours (Column I): Calculate as Productive Hours multiplied by Proposed Manning.
A10: * Subcontractors (Cost‑type): Must provide labor rates and labor categories (LCATs). If submitting directly to the Government, the prime shall ensure the total subcontract price is entered in Column Z and annotate that detailed costs were submitted separately.
A11: * Subcontractors (Fixed Price or T&M): The prime must complete Columns B–I for each proposed Subcontract Labor Category. Instead of completing the cost build‑up (Columns J–Y), enter the total subcontract price directly in Column Z.
A12: * Column AB will auto‑calculate based on the value entered in Column Z.
A15: Ordering Period 1 Year 1
A16: CLIN | B16: Labor Type | C16: Labor Category | D16: Organizational Structure Location | E16: Proposed Manning | F16: Work Location | G16: Fringe Pool | H16: Productive Hours | I16: Regular Labor Hours | J16: Direct Labor Rate | K16: Regular Labor Cost | L16: Fringe rate | M16: Fringe Cost | N16: Fringe + Labor Cost | O16: Labor OH rate | P16: Labor Overhead | Q16: Labor+Fringe+OH | R16: G&A Rate | S16: G&A | T16: Cost less FCCM | U16: FCCM Rate | V16: FCCM | W16: Total Cost | X16: Profit/Fee Rate | Y16: Profit/Fee | Z16: Total Price | AB16: Straight TimeWrap Rate
A17: 0002 | B17: EX | C17: MANAGER MAINTENANCE DEPARTMENT | D17: Maintenance Department | E17: 1 | F17: Jacksonville | G17: Full Time Benefits | H17: 1848 | I17: =H17*E17 -> 1848 | J17: 52 | K17: =I17*J17 -> 96096 | L17: 0.35 | M17: =K17*L17 -> 33633.6 | N17: =M17+K17 -> 129729.6 | O17: 0.08 | P17: =N17*O17 -> 10378.368 | Q17: =P17+N17 -> 140107.97 | R17: 0.1 | S17: =Q17*R17 -> 14010.797 | T17: =S17+Q17 -> 154118.76 | U17: 0.0005 | V17: =U17*T17 -> 77.059382 | W17: =T17+V17 -> 154195.82 | X17: 0.08 | Y17: =X17*T17 -> 12329.501 | Z17: =W17+Y17 -> 166525.33 | AB17: =Z17/I17 -> 90.111107
A18: 0002 | B18: CBA | C18: Auto Diesel Mech | D18: Maintenance Department Motor T Section | E18: 5 | F18: Jacksonville | G18: SCA Fringe | H18: 1848 | I18: =H18*E18 -> 9240 | J18: 33.29 | K18: =I18*J18 -> 307599.6 | L18: 0.35 | M18: =K18*L18 -> 107659.86 | N18: =M18+K18 -> 415259.46 | O18: 0.08 | P18: =N18*O18 -> 33220.757 | Q18: =P18+N18 -> 448480.22 | R18: 0.1 | S18: =Q18*R18 -> 44848.022 | T18: =S18+Q18 -> 493328.24 | U18: 0.0005 | V18: =U18*T18 -> 246.66412 | W18: =T18+V18 -> 493574.9 | X18: 0.08 | Y18: =X18*W18 -> 39485.992 | Z18: =W18+Y18 -> 533060.89 | AB18: =Z18/I18 -> 57.690573
A19: 0002 | B19: CBA | C19: Auto Diesel Mech SR Lead | D19: Maintenance Department Motor T Section | E19: 1 | F19: Jacksonville | G19: SCA Fringe | H19: 1848 | I19: =H19*E19 -> 1848 | J19: 39.94 | K19: =I19*J19 -> 73809.12 | L19: 0.35 | M19: =K19*L19 -> 25833.192 | N19: =M19+K19 -> 99642.312 | O19: 0.08 | P19: =N19*O19 -> 7971.385 | Q19: =P19+N19 -> 107613.7 | R19: 0.1 | S19: =Q19*R19 -> 10761.37 | T19: =S19+Q19 -> 118375.07 | U19: 0.0005 | V19: =U19*T19 -> 59.187533 | W19: =T19+V19 -> 118434.25 | X19: 0.08 | Y19: =X19*W19 -> 9474.7403 | Z19: =W19+Y19 -> 127908.99 | AB19: =Z19/I19 -> 69.214824
A20: 0002 | B20: EX | C20: MGR Supply Chain | D20: Supply Department | E20: 1 | F20: Jacksonville | G20: Full Time Benefits | H20: 1848 | I20: =H20*E20 -> 1848 | J20: 52 | K20: =I20*J20 -> 96096 | L20: 0.35 | M20: =K20*L20 -> 33633.6 | N20: =M20+K20 -> 129729.6 | O20: 0.08 | P20: =N20*O20 -> 10378.368 | Q20: =P20+N20 -> 140107.97 | R20: 0.1 | S20: =Q20*R20 -> 14010.797 | T20: =S20+Q20 -> 154118.76 | U20: 0.0005 | V20: =U20*T20 -> 77.059382 | W20: =T20+V20 -> 154195.82 | X20: 0.08 | Y20: =X20*W20 -> 12335.666 | Z20: =W20+Y20 -> 166531.49 | AB20: =Z20/I20 -> 90.114443
A21: 0002 | B21: SCA | C21: Material Spec II | D21: Supply Department Container Management | E21: 3 | F21: Jacksonville | G21: SCA Fringe | H21: 1848 | I21: =H21*E21 -> 5544 | J21: 28 | K21: =I21*J21 -> 155232 | L21: 0.33 | M21: =K21*L21 -> 51226.56 | N21: =M21+K21 -> 206458.56 | O21: 0.08 | P21: =N21*O21 -> 16516.685 | Q21: =P21+N21 -> 222975.24 | R21: 0.1 | S21: =Q21*R21 -> 22297.524 | T21: =S21+Q21 -> 245272.77 | U21: 0.0005 | V21: =U21*T21 -> 122.63638 | W21: =T21+V21 -> 245395.41 | X21: 0.08 | Y21: =X21*W21 -> 19631.632 | Z21: =W21+Y21 -> 265027.04 | AB21: =Z21/I21 -> 47.8043
A22: 0002 | F22: Jacksonville | I22: =H22*E22 -> 0 | K22: =I22*J22 -> 0 | M22: =K22*L22 -> 0 | N22: =M22+K22 -> 0 | P22: =N22*O22 -> 0 | Q22: =P22+N22 -> 0 | S22: =Q22*R22 -> 0 | T22: =S22+Q22 -> 0 | V22: =U22*T22 -> 0 | W22: =T22+V22 -> 0 | Y22: =X22*W22 -> 0 | Z22: =W22+Y22 -> 0 | AB22: =IFERROR(Z22/I22,0) -> 0
A23: 0002 | F23: Jacksonville | I23: =H23*E23 -> 0 | K23: =I23*J23 -> 0 | M23: =K23*L23 -> 0 | N23: =M23+K23 -> 0 | P23: =N23*O23 -> 0 | Q23: =P23+N23 -> 0 | S23: =Q23*R23 -> 0 | T23: =S23+Q23 -> 0 | V23: =U23*T23 -> 0 | W23: =T23+V23 -> 0 | Y23: =X23*W23 -> 0 | Z23: =W23+Y23 -> 0 | AB23: =IFERROR(Z23/I23,0) -> 0
A24: 0002 | F24: Jacksonville | I24: =H24*E24 -> 0 | K24: =I24*J24 -> 0 | M24: =K24*L24 -> 0 | N24: =M24+K24 -> 0 | P24: =N24*O24 -> 0 | Q24: =P24+N24 -> 0 | S24: =Q24*R24 -> 0 | T24: =S24+Q24 -> 0 | V24: =U24*T24 -> 0 | W24: =T24+V24 -> 0 | Y24: =X24*W24 -> 0 | Z24: =W24+Y24 -> 0 | AB24: =IFERROR(Z24/I24,0) -> 0
A25: 0002 | F25: Jacksonville | I25: =H25*E25 -> 0 | K25: =I25*J25 -> 0 | M25: =K25*L25 -> 0 | N25: =M25+K25 -> 0 | P25: =N25*O25 -> 0 | Q25: =P25+N25 -> 0 | S25: =Q25*R25 -> 0 | T25: =S25+Q25 -> 0 | V25: =U25*T25 -> 0 | W25: =T25+V25 -> 0 | Y25: =X25*W25 -> 0 | Z25: =W25+Y25 -> 0 | AB25: =IFERROR(Z25/I25,0) -> 0
A26: 0002 | F26: Jacksonville | I26: =H26*E26 -> 0 | K26: =I26*J26 -> 0 | M26: =K26*L26 -> 0 | N26: =M26+K26 -> 0 | P26: =N26*O26 -> 0 | Q26: =P26+N26 -> 0 | S26: =Q26*R26 -> 0 | T26: =S26+Q26 -> 0 | V26: =U26*T26 -> 0 | W26: =T26+V26 -> 0 | Y26: =X26*W26 -> 0 | Z26: =W26+Y26 -> 0 | AB26: =IFERROR(Z26/I26,0) -> 0
A27: 0002 | F27: Jacksonville | I27: =H27*E27 -> 0 | K27: =I27*J27 -> 0 | M27: =K27*L27 -> 0 | N27: =M27+K27 -> 0 | P27: =N27*O27 -> 0 | Q27: =P27+N27 -> 0 | S27: =Q27*R27 -> 0 | T27: =S27+Q27 -> 0 | V27: =U27*T27 -> 0 | W27: =T27+V27 -> 0 | Y27: =X27*W27 -> 0 | Z27: =W27+Y27 -> 0 | AB27: =IFERROR(Z27/I27,0) -> 0
A28: 0002 | F28: Jacksonville | I28: =H28*E28 -> 0 | K28: =I28*J28 -> 0 | M28: =K28*L28 -> 0 | N28: =M28+K28 -> 0 | P28: =N28*O28 -> 0 | Q28: =P28+N28 -> 0 | S28: =Q28*R28 -> 0 | T28: =S28+Q28 -> 0 | V28: =U28*T28 -> 0 | W28: =T28+V28 -> 0 | Y28: =X28*W28 -> 0 | Z28: =W28+Y28 -> 0 | AB28: =IFERROR(Z28/I28,0) -> 0
A29: 0002 | F29: Jacksonville | I29: =H29*E29 -> 0 | K29: =I29*J29 -> 0 | M29: =K29*L29 -> 0 | N29: =M29+K29 -> 0 | P29: =N29*O29 -> 0 | Q29: =P29+N29 -> 0 | S29: =Q29*R29 -> 0 | T29: =S29+Q29 -> 0 | V29: =U29*T29 -> 0 | W29: =T29+V29 -> 0 | Y29: =X29*W29 -> 0 | Z29: =W29+Y29 -> 0 | AB29: =IFERROR(Z29/I29,0) -> 0
A30: 0002 | F30: Jacksonville | I30: =H30*E30 -> 0 | K30: =I30*J30 -> 0 | M30: =K30*L30 -> 0 | N30: =M30+K30 -> 0 | P30: =N30*O30 -> 0 | Q30: =P30+N30 -> 0 | S30: =Q30*R30 -> 0 | T30: =S30+Q30 -> 0 | V30: =U30*T30 -> 0 | W30: =T30+V30 -> 0 | Y30: =X30*W30 -> 0 | Z30: =W30+Y30 -> 0 | AB30: =IFERROR(Z30/I30,0) -> 0
A31: 0002 | F31: Jacksonville | I31: =H31*E31 -> 0 | K31: =I31*J31 -> 0 | M31: =K31*L31 -> 0 | N31: =M31+K31 -> 0 | P31: =N31*O31 -> 0 | Q31: =P31+N31 -> 0 | S31: =Q31*R31 -> 0 | T31: =S31+Q31 -> 0 | V31: =U31*T31 -> 0 | W31: =T31+V31 -> 0 | Y31: =X31*W31 -> 0 | Z31: =W31+Y31 -> 0 | AB31: =IFERROR(Z31/I31,0) -> 0
A32: 0002 | F32: Jacksonville | I32: =H32*E32 -> 0 | K32: =I32*J32 -> 0 | M32: =K32*L32 -> 0 | N32: =M32+K32 -> 0 | P32: =N32*O32 -> 0 | Q32: =P32+N32 -> 0 | S32: =Q32*R32 -> 0 | T32: =S32+Q32 -> 0 | V32: =U32*T32 -> 0 | W32: =T32+V32 -> 0 | Y32: =X32*W32 -> 0 | Z32: =W32+Y32 -> 0 | AB32: =IFERROR(Z32/I32,0) -> 0
A33: 0002 | F33: Jacksonville | I33: =H33*E33 -> 0 | K33: =I33*J33 -> 0 | M33: =K33*L33 -> 0 | N33: =M33+K33 -> 0 | P33: =N33*O33 -> 0 | Q33: =P33+N33 -> 0 | S33: =Q33*R33 -> 0 | T33: =S33+Q33 -> 0 | V33: =U33*T33 -> 0 | W33: =T33+V33 -> 0 | Y33: =X33*W33 -> 0 | Z33: =W33+Y33 -> 0 | AB33: =IFERROR(Z33/I33,0) -> 0
... A137: 0002 | F137: Jacksonville | I137: =H137*E137 -> 0 | K137: =I137*J137 -> 0 | M137: =K137*L137 -> 0 | N137: =M137+K137 -> 0 | P137: =N137*O137 -> 0 | Q137: =P137+N137 -> 0 | S137: =Q137*R137 -> 0 | T137: =S137+Q137 -> 0 | V137: =U137*T137 -> 0 | W137: =T137+V137 -> 0 | Y137: =X137*W137 -> 0 | Z137: =W137+Y137 -> 0 | AB137: =IFERROR(Z137/I137,0) -> 0
W138: =SUM(W17:W137) -> 1165796.2 | Y138: =SUM(Y17:Y137) -> 93257.532 | Z138: =SUM(Z17:Z137) -> 1259053.7
A140: Ordering Period 1 Year 2
A141: CLIN | B141: Labor Type | C141: Labor Category | D141: Organizational Structure Location | E141: Proposed Manning | F141: Work Location | G141: Fringe Pool | H141: Productive Hours | I141: Regular Labor Hours | J141: Direct Labor Rate | K141: Regular Labor Cost | L141: Fringe rate | M141: Fringe Cost | N141: Fringe + Labor Cost | O141: Labor OH rate | P141: Labor Overhead | Q141: Labor+Fringe+OH | R141: G&A Rate | S141: G&A | T141: Cost less FCCM | U141: FCCM Rate | V141: FCCM | W141: Total Cost | X141: Profit/Fee Rate | Y141: Profit/Fee | Z141: Total Price | AB141: Straight TimeWrap Rate
A142: 0002 | F142: Jacksonville | I142: =H142*E142 -> 0 | K142: =I142*J142 -> 0 | M142: =K142*L142 -> 0 | N142: =M142+K142 -> 0 | P142: =N142*O142 -> 0 | Q142: =P142+N142 -> 0 | S142: =Q142*R142 -> 0 | T142: =S142+Q142 -> 0 | V142: =U142*T142 -> 0 | W142: =T142+V142 -> 0 | Y142: =X142*T142 -> 0 | Z142: =W142+Y142 -> 0 | AB142: =IFERROR(Z142/I142,0) -> 0
A143: 0002 | F143: Jacksonville | I143: =H143*E143 -> 0 | K143: =I143*J143 -> 0 | M143: =K143*L143 -> 0 | N143: =M143+K143 -> 0 | P143: =N143*O143 -> 0 | Q143: =P143+N143 -> 0 | S143: =Q143*R143 -> 0 | T143: =S143+Q143 -> 0 | V143: =U143*T143 -> 0 | W143: =T143+V143 -> 0 | Y143: =X143*W143 -> 0 | Z143: =W143+Y143 -> 0 | AB143: =IFERROR(Z143/I143,0) -> 0
A144: 0002 | F144: Jacksonville | I144: =H144*E144 -> 0 | K144: =I144*J144 -> 0 | M144: =K144*L144 -> 0 | N144: =M144+K144 -> 0 | P144: =N144*O144 -> 0 | Q144: =P144+N144 -> 0 | S144: =Q144*R144 -> 0 | T144: =S144+Q144 -> 0 | V144: =U144*T144 -> 0 | W144: =T144+V144 -> 0 | Y144: =X144*W144 -> 0 | Z144: =W144+Y144 -> 0 | AB144: =IFERROR(Z144/I144,0) -> 0
A145: 0002 | F145: Jacksonville | I145: =H145*E145 -> 0 | K145: =I145*J145 -> 0 | M145: =K145*L145 -> 0 | N145: =M145+K145 -> 0 | P145: =N145*O145 -> 0 | Q145: =P145+N145 -> 0 | S145: =Q145*R145 -> 0 | T145: =S145+Q145 -> 0 | V145: =U145*T145 -> 0 | W145: =T145+V145 -> 0 | Y145: =X145*W145 -> 0 | Z145: =W145+Y145 -> 0 | AB145: =IFERROR(Z145/I145,0) -> 0
A146: 0002 | F146: Jacksonville | I146: =H146*E146 -> 0 | K146: =I146*J146 -> 0 | M146: =K146*L146 -> 0 | N146: =M146+K146 -> 0 | P146: =N146*O146 -> 0 | Q146: =P146+N146 -> 0 | S146: =Q146*R146 -> 0 | T146: =S146+Q146 -> 0 | V146: =U146*T146 -> 0 | W146: =T146+V146 -> 0 | Y146: =X146*W146 -> 0 | Z146: =W146+Y146 -> 0 | AB146: =IFERROR(Z146/I146,0) -> 0
...

Sheet CLINX002 OT
A1: M67004-26-R-0007 Attachment J-7: Cost Model Workbook
A2: Contractor Name: | C2: =IF(Instructions!B3="","",Instructions!B3)
A3: * This tab captures proposed overtime (OT) hours minus applied fee.
A4: * Enter the OT rate by Labor Category. You may enter ZERO in Column E if not applicable.
A5: * Rows 14–18 (blue) are examples. Delete or edit as needed. Ensure the Ordering Period Total (Column W) remains linked to the Total Proposed Price tab.
A6: * Subcontractors may be proposed under OT CLINs.
A7: * If the Prime proposes subcontractor LCATs for OT, enter their fully burdened OT rates on this tab.
A8: * No fee is allowed on Prime or subcontractor overtime.
A12: Ordering Period 1 Year 1
A13: CLIN | B13: Labor Type | C13: Labor Category | D13: Organizational Structure Location | E13: Proposed Manning | F13: Work Location | G13: Fringe Pool | H13: Overtime hours/person | I13: Total Overtime Hours | J13: Direct OT Rate | K13: Overtime Cost | L13: Fringe rate | M13: Fringe Cost | N13: Fringe + Labor Cost | O13: Labor OH rate | P13: Labor Overhead | Q13: Labor+Fringe+OH | R13: G&A Rate | S13: G&A | T13: Cost less FCCM | U13: FCCM Rate | V13: FCCM | W13: Total Cost | Y13: Overtime Wrap Rate
A14: 0002 | B14: EX | C14: MANAGER MAINTENANCE DEPARTMENT | D14: Maintenance Department | E14: 1 | F14: Jacksonville | G14: Full Time Benefits | I14: =H14*E14 -> 0 | J14: 52 | K14: =I14*J14 -> 0 | L14: 0.35 | M14: =K14*L14 -> 0 | N14: =M14+K14 -> 0 | O14: 0.08 | P14: =N14*O14 -> 0 | Q14: =P14+N14 -> 0 | R14: 0.1 | S14: =Q14*R14 -> 0 | T14: =S14+Q14 -> 0 | U14: 0.0005 | V14: =U14*T14 -> 0 | W14: =T14+V14 -> 0 | Y14: =IFERROR(W14/I14,0) -> 0
A15: 0002 | B15: CBA | C15: Auto Diesel Mech | D15: Maintenance Department Motor T Section | E15: 5 | F15: Jacksonville | G15: SCA Fringe | I15: =H15*E15 -> 0 | J15: 33.29 | K15: =I15*J15 -> 0 | L15: 0.35 | M15: =K15*L15 -> 0 | N15: =M15+K15 -> 0 | O15: 0.08 | P15: =N15*O15 -> 0 | Q15: =P15+N15 -> 0 | R15: 0.1 | S15: =Q15*R15 -> 0 | T15: =S15+Q15 -> 0 | U15: 0.0005 | V15: =U15*T15 -> 0 | W15: =T15+V15 -> 0 | Y15: =IFERROR(W15/I15,0) -> 0
A16: 0002 | B16: CBA | C16: Auto Diesel Mech SR Lead | D16: Maintenance Department Motor T Section | E16: 1 | F16: Jacksonville | G16: SCA Fringe | I16: =H16*E16 -> 0 | J16: 39.94 | K16: =I16*J16 -> 0 | L16: 0.35 | M16: =K16*L16 -> 0 | N16: =M16+K16 -> 0 | O16: 0.08 | P16: =N16*O16 -> 0 | Q16: =P16+N16 -> 0 | R16: 0.1 | S16: =Q16*R16 -> 0 | T16: =S16+Q16 -> 0 | U16: 0.0005 | V16: =U16*T16 -> 0 | W16: =T16+V16 -> 0 | Y16: =IFERROR(W16/I16,0) -> 0
A17: 0002 | B17: EX | C17: MGR Supply Chain | D17: Supply Department | E17: 1 | F17: Jacksonville | G17: Full Time Benefits | I17: =H17*E17 -> 0 | J17: 52 | K17: =I17*J17 -> 0 | L17: 0.35 | M17: =K17*L17 -> 0 | N17: =M17+K17 -> 0 | O17: 0.08 | P17: =N17*O17 -> 0 | Q17: =P17+N17 -> 0 | R17: 0.1 | S17: =Q17*R17 -> 0 | T17: =S17+Q17 -> 0 | U17: 0.0005 | V17: =U17*T17 -> 0 | W17: =T17+V17 -> 0 | Y17: =IFERROR(W17/I17,0) -> 0
A18: 0002 | B18: CBA | C18: Material Spec II | D18: Supply Department Container Management | E18: 3 | F18: Jacksonville | G18: SCA Fringe | I18: =H18*E18 -> 0 | J18: 28 | K18: =I18*J18 -> 0 | L18: 0.33 | M18: =K18*L18 -> 0 | N18: =M18+K18 -> 0 | O18: 0.08 | P18: =N18*O18 -> 0 | Q18: =P18+N18 -> 0 | R18: 0.1 | S18: =Q18*R18 -> 0 | T18: =S18+Q18 -> 0 | U18: 0.0005 | V18: =U18*T18 -> 0 | W18: =T18+V18 -> 0 | Y18: =IFERROR(W18/I18,0) -> 0
A19: 0002 | F19: Jacksonville | I19: =H19*E19 -> 0 | K19: =I19*J19 -> 0 | M19: =K19*L19 -> 0 | N19: =M19+K19 -> 0 | P19: =N19*O19 -> 0 | Q19: =P19+N19 -> 0 | S19: =Q19*R19 -> 0 | T19: =S19+Q19 -> 0 | V19: =U19*T19 -> 0 | W19: =T19+V19 -> 0 | Y19: =IFERROR(W19/I19,0) -> 0
A20: 0002 | F20: Jacksonville | I20: =H20*E20 -> 0 | K20: =I20*J20 -> 0 | M20: =K20*L20 -> 0 | N20: =M20+K20 -> 0 | P20: =N20*O20 -> 0 | Q20: =P20+N20 -> 0 | S20: =Q20*R20 -> 0 | T20: =S20+Q20 -> 0 | V20: =U20*T20 -> 0 | W20: =T20+V20 -> 0 | Y20: =IFERROR(W20/I20,0) -> 0
A21: 0002 | F21: Jacksonville | I21: =H21*E21 -> 0 | K21: =I21*J21 -> 0 | M21: =K21*L21 -> 0 | N21: =M21+K21 -> 0 | P21: =N21*O21 -> 0 | Q21: =P21+N21 -> 0 | S21: =Q21*R21 -> 0 | T21: =S21+Q21 -> 0 | V21: =U21*T21 -> 0 | W21: =T21+V21 -> 0 | Y21: =IFERROR(W21/I21,0) -> 0
A22: 0002 | F22: Jacksonville | I22: =H22*E22 -> 0 | K22: =I22*J22 -> 0 | M22: =K22*L22 -> 0 | N22: =M22+K22 -> 0 | P22: =N22*O22 -> 0 | Q22: =P22+N22 -> 0 | S22: =Q22*R22 -> 0 | T22: =S22+Q22 -> 0 | V22: =U22*T22 -> 0 | W22: =T22+V22 -> 0 | Y22: =IFERROR(W22/I22,0) -> 0
A23: 0002 | F23: Jacksonville | I23: =H23*E23 -> 0 | K23: =I23*J23 -> 0 | M23: =K23*L23 -> 0 | N23: =M23+K23 -> 0 | P23: =N23*O23 -> 0 | Q23: =P23+N23 -> 0 | S23: =Q23*R23 -> 0 | T23: =S23+Q23 -> 0 | V23: =U23*T23 -> 0 | W23: =T23+V23 -> 0 | Y23: =IFERROR(W23/I23,0) -> 0
A24: 0002 | F24: Jacksonville | I24: =H24*E24 -> 0 | K24: =I24*J24 -> 0 | M24: =K24*L24 -> 0 | N24: =M24+K24 -> 0 | P24: =N24*O24 -> 0 | Q24: =P24+N24 -> 0 | S24: =Q24*R24 -> 0 | T24: =S24+Q24 -> 0 | V24: =U24*T24 -> 0 | W24: =T24+V24 -> 0 | Y24: =IFERROR(W24/I24,0) -> 0
A25: 0002 | F25: Jacksonville | I25: =H25*E25 -> 0 | K25: =I25*J25 -> 0 | M25: =K25*L25 -> 0 | N25: =M25+K25 -> 0 | P25: =N25*O25 -> 0 | Q25: =P25+N25 -> 0 | S25: =Q25*R25 -> 0 | T25: =S25+Q25 -> 0 | V25: =U25*T25 -> 0 | W25: =T25+V25 -> 0 | Y25: =IFERROR(W25/I25,0) -> 0
A26: 0002 | F26: Jacksonville | I26: =H26*E26 -> 0 | K26: =I26*J26 -> 0 | M26: =K26*L26 -> 0 | N26: =M26+K26 -> 0 | P26: =N26*O26 -> 0 | Q26: =P26+N26 -> 0 | S26: =Q26*R26 -> 0 | T26: =S26+Q26 -> 0 | V26: =U26*T26 -> 0 | W26: =T26+V26 -> 0 | Y26: =IFERROR(W26/I26,0) -> 0
A27: 0002 | F27: Jacksonville | I27: =H27*E27 -> 0 | K27: =I27*J27 -> 0 | M27: =K27*L27 -> 0 | N27: =M27+K27 -> 0 | P27: =N27*O27 -> 0 | Q27: =P27+N27 -> 0 | S27: =Q27*R27 -> 0 | T27: =S27+Q27 -> 0 | V27: =U27*T27 -> 0 | W27: =T27+V27 -> 0 | Y27: =IFERROR(W27/I27,0) -> 0
A28: 0002 | F28: Jacksonville | I28: =H28*E28 -> 0 | K28: =I28*J28 -> 0 | M28: =K28*L28 -> 0 | N28: =M28+K28 -> 0 | P28: =N28*O28 -> 0 | Q28: =P28+N28 -> 0 | S28: =Q28*R28 -> 0 | T28: =S28+Q28 -> 0 | V28: =U28*T28 -> 0 | W28: =T28+V28 -> 0 | Y28: =IFERROR(W28/I28,0) -> 0
A29: 0002 | F29: Jacksonville | I29: =H29*E29 -> 0 | K29: =I29*J29 -> 0 | M29: =K29*L29 -> 0 | N29: =M29+K29 -> 0 | P29: =N29*O29 -> 0 | Q29: =P29+N29 -> 0 | S29: =Q29*R29 -> 0 | T29: =S29+Q29 -> 0 | V29: =U29*T29 -> 0 | W29: =T29+V29 -> 0 | Y29: =IFERROR(W29/I29,0) -> 0
A30: 0002 | F30: Jacksonville | I30: =H30*E30 -> 0 | K30: =I30*J30 -> 0 | M30: =K30*L30 -> 0 | N30: =M30+K30 -> 0 | P30: =N30*O30 -> 0 | Q30: =P30+N30 -> 0 | S30: =Q30*R30 -> 0 | T30: =S30+Q30 -> 0 | V30: =U30*T30 -> 0 | W30: =T30+V30 -> 0 | Y30: =IFERROR(W30/I30,0) -> 0
... A134: 0002 | F134: Jacksonville | I134: =H134*E134 -> 0 | K134: =I134*J134 -> 0 | M134: =K134*L134 -> 0 | N134: =M134+K134 -> 0 | P134: =N134*O134 -> 0 | Q134: =P134+N134 -> 0 | S134: =Q134*R134 -> 0 | T134: =S134+Q134 -> 0 | V134: =U134*T134 -> 0 | W134: =T134+V134 -> 0 | Y134: =IFERROR(W134/I134,0) -> 0
V135: Total | W135: =SUM(W14:W134) -> 0
A137: Ordering Period 1 Year 2
A138: CLIN | B138: Labor Type | C138: Labor Category | D138: Organizational Structure Location | E138: Proposed Manning | F138: Work Location | G138: Fringe Pool | H138: Overtime hours/person | I138: Total Overtime Hours | J138: Direct OT Rate | K138: Overtime Cost | L138: Fringe rate | M138: Fringe Cost | N138: Fringe + Labor Cost | O138: Labor OH rate | P138: Labor Overhead | Q138: Labor+Fringe+OH | R138: G&A Rate | S138: G&A | T138: Cost less FCCM | U138: FCCM Rate | V138: FCCM | W138: Total Cost | Y138: Overtime Wrap Rate
A139: 0002 | F139: Jacksonville | I139: =H139*E139 -> 0 | K139: =I139*J139 -> 0 | M139: =K139*L139 -> 0 | N139: =M139+K139 -> 0 | P139: =N139*O139 -> 0 | Q139: =P139+N139 -> 0 | S139: =Q139*R139 -> 0 | T139: =S139+Q139 -> 0 | V139: =U139*T139 -> 0 | W139: =T139+V139 -> 0 | Y139: =IFERROR(W139/I139,0) -> 0
A140: 0002 | F140: Jacksonville | I140: =H140*E140 -> 0 | K140: =I140*J140 -> 0 | M140: =K140*L140 -> 0 | N140: =M140+K140 -> 0 | P140: =N140*O140 -> 0 | Q140: =P140+N140 -> 0 | S140: =Q140*R140 -> 0 | T140: =S140+Q140 -> 0 | V140: =U140*T140 -> 0 | W140: =T140+V140 -> 0 | Y140: =IFERROR(W140/I140,0) -> 0
A141: 0002 | F141: Jacksonville | I141: =H141*E141 -> 0 | K141: =I141*J141 -> 0 | M141: =K141*L141 -> 0 | N141: =M141+K141 -> 0 | P141: =N141*O141 -> 0 | Q141: =P141+N141 -> 0 | S141: =Q141*R141 -> 0 | T141: =S141+Q141 -> 0 | V141: =U141*T141 -> 0 | W141: =T141+V141 -> 0 | Y141: =IFERROR(W141/I141,0) -> 0
A142: 0002 | F142: Jacksonville | I142: =H142*E142 -> 0 | K142: =I142*J142 -> 0 | M142: =K142*L142 -> 0 | N142: =M142+K142 -> 0 | P142: =N142*O142 -> 0 | Q142: =P142+N142 -> 0 | S142: =Q142*R142 -> 0 | T142: =S142+Q142 -> 0 | V142: =U142*T142 -> 0 | W142: =T142+V142 -> 0 | Y142: =IFERROR(W142/I142,0) -> 0
A143: 0002 | F143: Jacksonville | I143: =H143*E143 -> 0 | K143: =I143*J143 -> 0 | M143: =K143*L143 -> 0 | N143: =M143+K143 -> 0 | P143: =N143*O143 -> 0 | Q143: =P143+N143 -> 0 | S143: =Q143*R143 -> 0 | T143: =S143+Q143 -> 0 | V143: =U143*T143 -> 0 | W143: =T143+V143 -> 0 | Y143: =IFERROR(W143/I143,0) -> 0
A144: 0002 | F144: Jacksonville | I144: =H144*E144 -> 0 | K144: =I144*J144 -> 0 | M144: =K144*L144 -> 0 | N144: =M144+K144 -> 0 | P144: =N144*O144 -> 0 | Q144: =P144+N144 -> 0 | S144: =Q144*R144 -> 0 | T144: =S144+Q144 -> 0 | V144: =U144*T144 -> 0 | W144: =T144+V144 -> 0 | Y144: =IFERROR(W144/I144,0) -> 0
A145: 0002 | F145: Jacksonville | I145: =H145*E145 -> 0 | K145: =I145*J145 -> 0 | M145: =K145*L145 -> 0 | N145: =M145+K145 -> 0 | P145: =N145*O145 -> 0 | Q145: =P145+N145 -> 0 | S145: =Q145*R145 -> 0 | T145: =S145+Q145 -> 0 | V145: =U145*T145 -> 0 | W145: =T145+V145 -> 0 | Y145: =IFERROR(W145/I145,0) -> 0
A146: 0002 | F146: Jacksonville | I146: =H146*E146 -> 0 | K146: =I146*J146 -> 0 | M146: =K146*L146 -> 0 | N146: =M146+K146 -> 0 | P146: =N146*O146 -> 0 | Q146: =P146+N146 -> 0 | S146: =Q146*R146 -> 0 | T146: =S146+Q146 -> 0 | V146: =U146*T146 -> 0 | W146: =T146+V146 -> 0 | Y146: =IFERROR(W146/I146,0) -> 0
A147: 0002 | F147: Jacksonville | I147: =H147*E147 -> 0 | K147: =I147*J147 -> 0 | M147: =K147*L147 -> 0 | N147: =M147+K147 -> 0 | P147: =N147*O147 -> 0 | Q147: =P147+N147 -> 0 | S147: =Q147*R147 -> 0 | T147: =S147+Q147 -> 0 | V147: =U147*T147 -> 0 | W147: =T147+V147 -> 0 | Y147: =IFERROR(W147/I147,0) -> 0
...

Sheet CLINX003
A1: M67004-26-R-0007 Attachment J-7: Cost Model Workbook
A2: Contractor Name: | C2: =IF(Instructions!B3="","",Instructions!B3)
A3: * Rows 17-20 (blue) are examples only. Delete or modify these rows as needed. Ensure the Total cell at the bottom of each Ordering Period (Column Z) remains linked to the Total Proposed Price tab.
A4: * Input cells are highlighted in yellow. Non‑yellow cells contain formulas used to calculate the Total Price in Column Z.
A5: * Rows may be added or deleted as needed to reflect your manning solution. Use “N/A” in cells that do not apply.
A6: * Drop‑down selections are provided for Labor Type, Labor Category, Fringe Pool, and Job Location.
A7: * Column D: Identify where each position fits within your manning solution. This should align with the Organization Structure required in Section L.6, Volume II – Management Proposal.
A8: * Productive Hours (Column H): Calculate as total available hours per year minus weekends, holidays, and PTO for the proposed location.
A9: * Labor Hours (Column I): Calculate as Productive Hours multiplied by Proposed Manning.
A10: * Subcontractors (Cost‑type): Must provide labor rates and labor categories (LCATs). If submitting directly to the Government, the prime shall ensure the total subcontract price is entered in Column Z and annotate that detailed costs were submitted separately.
A11: * Subcontractors (Fixed Price or T&M): The prime must complete Columns B–I for each proposed Subcontract Labor Category. Instead of completing the cost build‑up (Columns J–Y), enter the total subcontract price directly in Column Z.
A12: * Column AB will auto‑calculate based on the value entered in Column Z.
A15: Ordering Period 1 Year1
A16: CLIN | B16: Labor Type | C16: Labor Category | D16: Organizational Structure Location | E16: Proposed Manning | F16: Work Location | G16: Fringe Pool | H16: Productive Hours | I16: Regular Labor Hours | J16: Direct Labor Rate | K16: Regular Labor Cost | L16: Fringe rate | M16: Fringe Cost | N16: Fringe + Labor Cost | O16: Labor OH rate | P16: Labor Overhead | Q16: Labor+Fringe+OH | R16: G&A Rate | S16: G&A | T16: Cost less FCCM | U16: FCCM | V16: FCCM | W16: Total Cost | X16: Profit/Fee Rate | Y16: Profit/Fee | Z16: Total Price | AB16: Straight TimeWrap Rate
A17: 0003 | B17: EX | C17: Land Based Program Manager | D17: Program Management | E17: 1 | F17: Palau | G17: Full Time Benefits | H17: 1830 | I17: =E17*H17 -> 1830 | J17: 50 | K17: =I17*J17 -> 91500 | L17: 0.35 | M17: =K17*L17 -> 32025 | N17: =M17+K17 -> 123525 | O17: 0.08 | P17: =N17*O17 -> 9882 | Q17: =P17+N17 -> 133407 | R17: 0.1 | S17: =Q17*R17 -> 13340.7 | T17: =S17+Q17 -> 146747.7 | U17: 0.0005 | V17: =U17*T17 -> 73.37385 | W17: =T17+V17 -> 146821.07 | X17: 0.08 | Y17: =X17*T17 -> 11739.816 | Z17: =W17+Y17 -> 158560.89 | AB17: =IFERROR(Z17/I17,0) -> 86.645295
A18: 0003 | B18: EX | C18: Carpenter | D18: Supply Section | E18: 1 | F18: Philippines | G18: Full Time Benefits | H18: 1830 | I18: =E18*H18 -> 1830 | J18: 30 | K18: =I18*J18 -> 54900 | L18: 0.35 | M18: =K18*L18 -> 19215 | N18: =M18+K18 -> 74115 | O18: 0.08 | P18: =N18*O18 -> 5929.2 | Q18: =P18+N18 -> 80044.2 | R18: 0.1 | S18: =Q18*R18 -> 8004.42 | T18: =S18+Q18 -> 88048.62 | U18: 0.0005 | V18: =U18*T18 -> 44.02431 | W18: =T18+V18 -> 88092.644 | X18: 0.08 | Y18: =X18*T18 -> 7043.8896 | Z18: =W18+Y18 -> 95136.534 | AB18: =IFERROR(Z18/I18,0) -> 51.987177
A19: 0003 | B19: EX | C19: Shipboard Supervisor | D19: Ship | E19: 8 | F19: Shipboard | G19: Full Time Benefits | H19: 1848 | I19: =E19*H19 -> 14784 | J19: 40 | K19: =I19*J19 -> 591360 | L19: 0.35 | M19: =K19*L19 -> 206976 | N19: =M19+K19 -> 798336 | O19: 0.08 | P19: =N19*O19 -> 63866.88 | Q19: =P19+N19 -> 862202.88 | R19: 0.1 | S19: =Q19*R19 -> 86220.288 | T19: =S19+Q19 -> 948423.17 | U19: 0.0005 | V19: =U19*T19 -> 474.21158 | W19: =T19+V19 -> 948897.38 | X19: 0.08 | Y19: =X19*T19 -> 75873.853 | Z19: =W19+Y19 -> 1024771.2 | AB19: =IFERROR(Z19/I19,0) -> 69.316236
A20: 0003 | B20: EX | C20: COMSEC Tech | D20: Communications | E20: 3 | F20: Norway | G20: OCONUS Fringe | H20: 1750 | I20: =E20*H20 -> 5250 | J20: 27 | K20: =I20*J20 -> 141750 | L20: 0.35 | M20: =K20*L20 -> 49612.5 | N20: =M20+K20 -> 191362.5 | O20: 0.08 | P20: =N20*O20 -> 15309 | Q20: =P20+N20 -> 206671.5 | R20: 0.1 | S20: =Q20*R20 -> 20667.15 | T20: =S20+Q20 -> 227338.65 | U20: 0.0005 | V20: =U20*T20 -> 113.66933 | W20: =T20+V20 -> 227452.32 | X20: 0.08 | Y20: =X20*T20 -> 18187.092 | Z20: =W20+Y20 -> 245639.41 | AB20: =IFERROR(Z20/I20,0) -> 46.788459
A21: 0003 | I21: =H21*E21 -> 0 | K21: =I21*J21 -> 0 | M21: =K21*L21 -> 0 | N21: =M21+K21 -> 0 | P21: =N21*O21 -> 0 | Q21: =P21+N21 -> 0 | S21: =Q21*R21 -> 0 | T21: =S21+Q21 -> 0 | V21: =U21*T21 -> 0 | W21: =T21+V21 -> 0 | Y21: =X21*T21 -> 0 | Z21: =W21+Y21 -> 0 | AB21: =IFERROR(Z21/I21,0) -> 0
A22: 0003 | I22: =H22*E22 -> 0 | K22: =I22*J22 -> 0 | M22: =K22*L22 -> 0 | N22: =M22+K22 -> 0 | P22: =N22*O22 -> 0 | Q22: =P22+N22 -> 0 | S22: =Q22*R22 -> 0 | T22: =S22+Q22 -> 0 | V22: =U22*T22 -> 0 | W22: =T22+V22 -> 0 | Y22: =X22*T22 -> 0 | Z22: =W22+Y22 -> 0 | AB22: =IFERROR(Z22/I22,0) -> 0
A23: 0003 | I23: =H23*E23 -> 0 | K23: =I23*J23 -> 0 | M23: =K23*L23 -> 0 | N23: =M23+K23 -> 0 | P23: =N23*O23 -> 0 | Q23: =P23+N23 -> 0 | S23: =Q23*R23 -> 0 | T23: =S23+Q23 -> 0 | V23: =U23*T23 -> 0 | W23: =T23+V23 -> 0 | Y23: =X23*T23 -> 0 | Z23: =W23+Y23 -> 0 | AB23: =IFERROR(Z23/I23,0) -> 0
A24: 0003 | I24: =H24*E24 -> 0 | K24: =I24*J24 -> 0 | M24: =K24*L24 -> 0 | N24: =M24+K24 -> 0 | P24: =N24*O24 -> 0 | Q24: =P24+N24 -> 0 | S24: =Q24*R24 -> 0 | T24: =S24+Q24 -> 0 | V24: =U24*T24 -> 0 | W24: =T24+V24 -> 0 | Y24: =X24*T24 -> 0 | Z24: =W24+Y24 -> 0 | AB24: =IFERROR(Z24/I24,0) -> 0
A25: 0003 | I25: =H25*E25 -> 0 | K25: =I25*J25 -> 0 | M25: =K25*L25 -> 0 | N25: =M25+K25 -> 0 | P25: =N25*O25 -> 0 | Q25: =P25+N25 -> 0 | S25: =Q25*R25 -> 0 | T25: =S25+Q25 -> 0 | V25: =U25*T25 -> 0 | W25: =T25+V25 -> 0 | Y25: =X25*T25 -> 0 | Z25: =W25+Y25 -> 0 | AB25: =IFERROR(Z25/I25,0) -> 0
A26: 0003 | I26: =H26*E26 -> 0 | K26: =I26*J26 -> 0 | M26: =K26*L26 -> 0 | N26: =M26+K26 -> 0 | P26: =N26*O26 -> 0 | Q26: =P26+N26 -> 0 | S26: =Q26*R26 -> 0 | T26: =S26+Q26 -> 0 | V26: =U26*T26 -> 0 | W26: =T26+V26 -> 0 | Y26: =X26*T26 -> 0 | Z26: =W26+Y26 -> 0 | AB26: =IFERROR(Z26/I26,0) -> 0
A27: 0003 | I27: =H27*E27 -> 0 | K27: =I27*J27 -> 0 | M27: =K27*L27 -> 0 | N27: =M27+K27 -> 0 | P27: =N27*O27 -> 0 | Q27: =P27+N27 -> 0 | S27: =Q27*R27 -> 0 | T27: =S27+Q27 -> 0 | V27: =U27*T27 -> 0 | W27: =T27+V27 -> 0 | Y27: =X27*T27 -> 0 | Z27: =W27+Y27 -> 0 | AB27: =IFERROR(Z27/I27,0) -> 0
A28: 0003 | I28: =H28*E28 -> 0 | K28: =I28*J28 -> 0 | M28: =K28*L28 -> 0 | N28: =M28+K28 -> 0 | P28: =N28*O28 -> 0 | Q28: =P28+N28 -> 0 | S28: =Q28*R28 -> 0 | T28: =S28+Q28 -> 0 | V28: =U28*T28 -> 0 | W28: =T28+V28 -> 0 | Y28: =X28*T28 -> 0 | Z28: =W28+Y28 -> 0 | AB28: =IFERROR(Z28/I28,0) -> 0
A29: 0003 | I29: =H29*E29 -> 0 | K29: =I29*J29 -> 0 | M29: =K29*L29 -> 0 | N29: =M29+K29 -> 0 | P29: =N29*O29 -> 0 | Q29: =P29+N29 -> 0 | S29: =Q29*R29 -> 0 | T29: =S29+Q29 -> 0 | V29: =U29*T29 -> 0 | W29: =T29+V29 -> 0 | Y29: =X29*T29 -> 0 | Z29: =W29+Y29 -> 0 | AB29: =IFERROR(Z29/I29,0) -> 0
A30: 0003 | I30: =H30*E30 -> 0 | K30: =I30*J30 -> 0 | M30: =K30*L30 -> 0 | N30: =M30+K30 -> 0 | P30: =N30*O30 -> 0 | Q30: =P30+N30 -> 0 | S30: =Q30*R30 -> 0 | T30: =S30+Q30 -> 0 | V30: =U30*T30 -> 0 | W30: =T30+V30 -> 0 | Y30: =X30*T30 -> 0 | Z30: =W30+Y30 -> 0 | AB30: =IFERROR(Z30/I30,0) -> 0
A31: 0003 | I31: =H31*E31 -> 0 | K31: =I31*J31 -> 0 | M31: =K31*L31 -> 0 | N31: =M31+K31 -> 0 | P31: =N31*O31 -> 0 | Q31: =P31+N31 -> 0 | S31: =Q31*R31 -> 0 | T31: =S31+Q31 -> 0 | V31: =U31*T31 -> 0 | W31: =T31+V31 -> 0 | Y31: =X31*T31 -> 0 | Z31: =W31+Y31 -> 0 | AB31: =IFERROR(Z31/I31,0) -> 0
A32: 0003 | I32: =H32*E32 -> 0 | K32: =I32*J32 -> 0 | M32: =K32*L32 -> 0 | N32: =M32+K32 -> 0 | P32: =N32*O32 -> 0 | Q32: =P32+N32 -> 0 | S32: =Q32*R32 -> 0 | T32: =S32+Q32 -> 0 | V32: =U32*T32 -> 0 | W32: =T32+V32 -> 0 | Y32: =X32*T32 -> 0 | Z32: =W32+Y32 -> 0 | AB32: =IFERROR(Z32/I32,0) -> 0
... A56: 0003 | I56: =H56*E56 -> 0 | K56: =I56*J56 -> 0 | M56: =K56*L56 -> 0 | N56: =M56+K56 -> 0 | P56: =N56*O56 -> 0 | Q56: =P56+N56 -> 0 | S56: =Q56*R56 -> 0 | T56: =S56+Q56 -> 0 | V56: =U56*T56 -> 0 | W56: =T56+V56 -> 0 | Y56: =X56*T56 -> 0 | Z56: =W56+Y56 -> 0 | AB56: =IFERROR(Z56/I56,0) -> 0
W57: =SUM(W17:W56) -> 1411263.4 | Y57: =SUM(Y17:Y56) -> 112844.65 | Z57: =SUM(Z17:Z56) -> 1524108.1
A58: Ordering Period 1 Year 2
A59: CLIN | B59: Labor Type | C59: Labor Category | D59: Organizational Structure Location | E59: Positions Required | F59: Work Location | G59: Fringe Pool | H59: Productive Hours | I59: Regular Labor Hours | J59: Direct Labor Rate | K59: Regular Labor Cost | L59: Fringe rate | M59: Fringe Cost | N59: Fringe + Labor Cost | O59: Labor OH rate | P59: Labor Overhead | Q59: Labor+Fringe+OH | R59: G&A Rate | S59: G&A | T59: Cost less FCCM | U59: FCCM | V59: FCCM | W59: Total Cost | X59: Profit/Fee Rate | Y59: Profit/Fee | Z59: Total Price | AB59: Straight TimeWrap Rate
A60: 0003 | K60: =I60*J60 -> 0 | M60: =K60*L60 -> 0 | N60: =M60+K60 -> 0 | P60: =N60*O60 -> 0 | Q60: =P60+N60 -> 0 | S60: =Q60*R60 -> 0 | T60: =S60+Q60 -> 0 | V60: =U60*T60 -> 0 | W60: =T60+V60 -> 0 | Y60: =X60*T60 -> 0 | Z60: =W60+Y60 -> 0 | AB60: =IFERROR(Z60/I60,0) -> 0
A61: 0003 | K61: =I61*J61 -> 0 | M61: =K61*L61 -> 0 | N61: =M61+K61 -> 0 | P61: =N61*O61 -> 0 | Q61: =P61+N61 -> 0 | S61: =Q61*R61 -> 0 | T61: =S61+Q61 -> 0 | V61: =U61*T61 -> 0 | W61: =T61+V61 -> 0 | Y61: =X61*T61 -> 0 | Z61: =W61+Y61 -> 0 | AB61: =IFERROR(Z61/I61,0) -> 0
A62: 0003 | K62: =I62*J62 -> 0 | M62: =K62*L62 -> 0 | N62: =M62+K62 -> 0 | P62: =N62*O62 -> 0 | Q62: =P62+N62 -> 0 | S62: =Q62*R62 -> 0 | T62: =S62+Q62 -> 0 | V62: =U62*T62 -> 0 | W62: =T62+V62 -> 0 | Y62: =X62*T62 -> 0 | Z62: =W62+Y62 -> 0 | AB62: =IFERROR(Z62/I62,0) -> 0
A63: 0003 | K63: =I63*J63 -> 0 | M63: =K63*L63 -> 0 | N63: =M63+K63 -> 0 | P63: =N63*O63 -> 0 | Q63: =P63+N63 -> 0 | S63: =Q63*R63 -> 0 | T63: =S63+Q63 -> 0 | V63: =U63*T63 -> 0 | W63: =T63+V63 -> 0 | Y63: =X63*T63 -> 0 | Z63: =W63+Y63 -> 0 | AB63: =IFERROR(Z63/I63,0) -> 0
A64: 0003 | I64: =H64*E64 -> 0 | K64: =I64*J64 -> 0 | M64: =K64*L64 -> 0 | N64: =M64+K64 -> 0 | P64: =N64*O64 -> 0 | Q64: =P64+N64 -> 0 | S64: =Q64*R64 -> 0 | T64: =S64+Q64 -> 0 | V64: =U64*T64 -> 0 | W64: =T64+V64 -> 0 | Y64: =X64*T64 -> 0 | Z64: =W64+Y64 -> 0 | AB64: =IFERROR(Z64/I64,0) -> 0
A65: 0003 | I65: =H65*E65 -> 0 | K65: =I65*J65 -> 0 | M65: =K65*L65 -> 0 | N65: =M65+K65 -> 0 | P65: =N65*O65 -> 0 | Q65: =P65+N65 -> 0 | S65: =Q65*R65 -> 0 | T65: =S65+Q65 -> 0 | V65: =U65*T65 -> 0 | W65: =T65+V65 -> 0 | Y65: =X65*T65 -> 0 | Z65: =W65+Y65 -> 0 | AB65: =IFERROR(Z65/I65,0) -> 0
...

Sheet CLINX003 OT
A1: M67004-26-R-0007 Attachment J-7: Cost Model Workbook
A2: Contractor Name: | C2: =IF(Instructions!B3="","",Instructions!B3)
A3: * This tab captures proposed overtime (OT) hours minus applied fee.
A4: * Enter the OT rate by Labor Category. You may enter ZERO in Column E if not applicable.
A5: * Ensure the Ordering Period Total (Column W) remains linked to the Total Proposed Price tab.
A6: * Subcontractors may be proposed under OT CLINs.
A7: * If the Prime proposes subcontractor LCATs for OT, enter their fully burdened OT rates on this tab.
A8: * No fee is allowed on Prime or subcontractor overtime.
A12: Ordering Period 1 Year1
A13: CLIN | B13: Labor Type | C13: Labor Category | D13: Organizational Structure Location | E13: Positions Required | F13: Work Location | G13: Fringe Pool | H13: Overtime hours/person | I13: Total Overtime Hours | J13: Direct OT Rate | K13: Overtime Cost | L13: Fringe rate | M13: Fringe Cost | N13: Fringe + Labor Cost | O13: Labor OH rate | P13: Labor Overhead | Q13: Labor+Fringe+OH | R13: G&A Rate | S13: G&A | T13: Cost less FCCM | U13: FCCM | V13: FCCM | W13: Total Cost | Y13: Overtime Wrap Rate
A14: 0003 | I14: =E14*H14 -> 0 | K14: =I14*J14 -> 0 | M14: =K14*L14 -> 0 | N14: =M14+K14 -> 0 | P14: =N14*O14 -> 0 | Q14: =P14+N14 -> 0 | S14: =Q14*R14 -> 0 | T14: =S14+Q14 -> 0 | V14: =U14*T14 -> 0 | W14: =T14+V14 -> 0 | Y14: =IFERROR(W14/I14,0) -> 0
A15: 0003 | I15: =E15*H15 -> 0 | K15: =I15*J15 -> 0 | M15: =K15*L15 -> 0 | N15: =M15+K15 -> 0 | P15: =N15*O15 -> 0 | Q15: =P15+N15 -> 0 | S15: =Q15*R15 -> 0 | T15: =S15+Q15 -> 0 | V15: =U15*T15 -> 0 | W15: =T15+V15 -> 0 | Y15: =IFERROR(W15/I15,0) -> 0
A16: 0003 | I16: =E16*H16 -> 0 | K16: =I16*J16 -> 0 | M16: =K16*L16 -> 0 | N16: =M16+K16 -> 0 | P16: =N16*O16 -> 0 | Q16: =P16+N16 -> 0 | S16: =Q16*R16 -> 0 | T16: =S16+Q16 -> 0 | V16: =U16*T16 -> 0 | W16: =T16+V16 -> 0 | Y16: =IFERROR(W16/I16,0) -> 0
A17: 0003 | I17: =E17*H17 -> 0 | K17: =I17*J17 -> 0 | M17: =K17*L17 -> 0 | N17: =M17+K17 -> 0 | P17: =N17*O17 -> 0 | Q17: =P17+N17 -> 0 | S17: =Q17*R17 -> 0 | T17: =S17+Q17 -> 0 | V17: =U17*T17 -> 0 | W17: =T17+V17 -> 0 | Y17: =IFERROR(W17/I17,0) -> 0
A18: 0003 | I18: =H18*E18 -> 0 | K18: =I18*J18 -> 0 | M18: =K18*L18 -> 0 | N18: =M18+K18 -> 0 | P18: =N18*O18 -> 0 | Q18: =P18+N18 -> 0 | S18: =Q18*R18 -> 0 | T18: =S18+Q18 -> 0 | V18: =U18*T18 -> 0 | W18: =T18+V18 -> 0 | Y18: =IFERROR(W18/I18,0) -> 0
A19: 0003 | I19: =H19*E19 -> 0 | K19: =I19*J19 -> 0 | M19: =K19*L19 -> 0 | N19: =M19+K19 -> 0 | P19: =N19*O19 -> 0 | Q19: =P19+N19 -> 0 | S19: =Q19*R19 -> 0 | T19: =S19+Q19 -> 0 | V19: =U19*T19 -> 0 | W19: =T19+V19 -> 0 | Y19: =IFERROR(W19/I19,0) -> 0
A20: 0003 | I20: =H20*E20 -> 0 | K20: =I20*J20 -> 0 | M20: =K20*L20 -> 0 | N20: =M20+K20 -> 0 | P20: =N20*O20 -> 0 | Q20: =P20+N20 -> 0 | S20: =Q20*R20 -> 0 | T20: =S20+Q20 -> 0 | V20: =U20*T20 -> 0 | W20: =T20+V20 -> 0 | Y20: =IFERROR(W20/I20,0) -> 0
A21: 0003 | I21: =H21*E21 -> 0 | K21: =I21*J21 -> 0 | M21: =K21*L21 -> 0 | N21: =M21+K21 -> 0 | P21: =N21*O21 -> 0 | Q21: =P21+N21 -> 0 | S21: =Q21*R21 -> 0 | T21: =S21+Q21 -> 0 | V21: =U21*T21 -> 0 | W21: =T21+V21 -> 0 | Y21: =IFERROR(W21/I21,0) -> 0
A22: 0003 | I22: =H22*E22 -> 0 | K22: =I22*J22 -> 0 | M22: =K22*L22 -> 0 | N22: =M22+K22 -> 0 | P22: =N22*O22 -> 0 | Q22: =P22+N22 -> 0 | S22: =Q22*R22 -> 0 | T22: =S22+Q22 -> 0 | V22: =U22*T22 -> 0 | W22: =T22+V22 -> 0 | Y22: =IFERROR(W22/I22,0) -> 0
A23: 0003 | I23: =H23*E23 -> 0 | K23: =I23*J23 -> 0 | M23: =K23*L23 -> 0 | N23: =M23+K23 -> 0 | P23: =N23*O23 -> 0 | Q23: =P23+N23 -> 0 | S23: =Q23*R23 -> 0 | T23: =S23+Q23 -> 0 | V23: =U23*T23 -> 0 | W23: =T23+V23 -> 0 | Y23: =IFERROR(W23/I23,0) -> 0
A24: 0003 | I24: =H24*E24 -> 0 | K24: =I24*J24 -> 0 | M24: =K24*L24 -> 0 | N24: =M24+K24 -> 0 | P24: =N24*O24 -> 0 | Q24: =P24+N24 -> 0 | S24: =Q24*R24 -> 0 | T24: =S24+Q24 -> 0 | V24: =U24*T24 -> 0 | W24: =T24+V24 -> 0 | Y24: =IFERROR(W24/I24,0) -> 0
A25: 0003 | I25: =H25*E25 -> 0 | K25: =I25*J25 -> 0 | M25: =K25*L25 -> 0 | N25: =M25+K25 -> 0 | P25: =N25*O25 -> 0 | Q25: =P25+N25 -> 0 | S25: =Q25*R25 -> 0 | T25: =S25+Q25 -> 0 | V25: =U25*T25 -> 0 | W25: =T25+V25 -> 0 | Y25: =IFERROR(W25/I25,0) -> 0
A26: 0003 | I26: =H26*E26 -> 0 | K26: =I26*J26 -> 0 | M26: =K26*L26 -> 0 | N26: =M26+K26 -> 0 | P26: =N26*O26 -> 0 | Q26: =P26+N26 -> 0 | S26: =Q26*R26 -> 0 | T26: =S26+Q26 -> 0 | V26: =U26*T26 -> 0 | W26: =T26+V26 -> 0 | Y26: =IFERROR(W26/I26,0) -> 0
A27: 0003 | I27: =H27*E27 -> 0 | K27: =I27*J27 -> 0 | M27: =K27*L27 -> 0 | N27: =M27+K27 -> 0 | P27: =N27*O27 -> 0 | Q27: =P27+N27 -> 0 | S27: =Q27*R27 -> 0 | T27: =S27+Q27 -> 0 | V27: =U27*T27 -> 0 | W27: =T27+V27 -> 0 | Y27: =IFERROR(W27/I27,0) -> 0
A28: 0003 | I28: =H28*E28 -> 0 | K28: =I28*J28 -> 0 | M28: =K28*L28 -> 0 | N28: =M28+K28 -> 0 | P28: =N28*O28 -> 0 | Q28: =P28+N28 -> 0 | S28: =Q28*R28 -> 0 | T28: =S28+Q28 -> 0 | V28: =U28*T28 -> 0 | W28: =T28+V28 -> 0 | Y28: =IFERROR(W28/I28,0) -> 0
A29: 0003 | I29: =H29*E29 -> 0 | K29: =I29*J29 -> 0 | M29: =K29*L29 -> 0 | N29: =M29+K29 -> 0 | P29: =N29*O29 -> 0 | Q29: =P29+N29 -> 0 | S29: =Q29*R29 -> 0 | T29: =S29+Q29 -> 0 | V29: =U29*T29 -> 0 | W29: =T29+V29 -> 0 | Y29: =IFERROR(W29/I29,0) -> 0
... A54: 0003 | I54: =H54*E54 -> 0 | K54: =I54*J54 -> 0 | M54: =K54*L54 -> 0 | N54: =M54+K54 -> 0 | P54: =N54*O54 -> 0 | Q54: =P54+N54 -> 0 | S54: =Q54*R54 -> 0 | T54: =S54+Q54 -> 0 | V54: =U54*T54 -> 0 | W54: =T54+V54 -> 0 | Y54: =IFERROR(W54/I54,0) -> 0
V55: Total | W55: =SUM(W14:W54) -> 0
A56: Ordering Period 1 Year 2
A57: CLIN | B57: Labor Type | C57: Labor Category | D57: Organizational Structure Location | E57: Positions Required | F57: Work Location | G57: Fringe Pool | H57: Overtime hours/person | I57: Total Overtime Hours | J57: Direct OT Rate | K57: Overtime Cost | L57: Fringe rate | M57: Fringe Cost | N57: Fringe + Labor Cost | O57: Labor OH rate | P57: Labor Overhead | Q57: Labor+Fringe+OH | R57: G&A Rate | S57: G&A | T57: Cost less FCCM | U57: FCCM | V57: FCCM | W57: Total Cost | Y57: Overtime Wrap Rate
A58: 0003 | I58: =E58*H58 -> 0 | K58: =I58*J58 -> 0 | M58: =K58*L58 -> 0 | N58: =M58+K58 -> 0 | P58: =N58*O58 -> 0 | Q58: =P58+N58 -> 0 | S58: =Q58*R58 -> 0 | T58: =S58+Q58 -> 0 | V58: =U58*T58 -> 0 | W58: =T58+V58 -> 0 | Y58: =IFERROR(W58/I58,0) -> 0
A59: 0003 | I59: =E59*H59 -> 0 | K59: =I59*J59 -> 0 | M59: =K59*L59 -> 0 | N59: =M59+K59 -> 0 | P59: =N59*O59 -> 0 | Q59: =P59+N59 -> 0 | S59: =Q59*R59 -> 0 | T59: =S59+Q59 -> 0 | V59: =U59*T59 -> 0 | W59: =T59+V59 -> 0 | Y59: =IFERROR(W59/I59,0) -> 0
A60: 0003 | I60: =E60*H60 -> 0 | K60: =I60*J60 -> 0 | M60: =K60*L60 -> 0 | N60: =M60+K60 -> 0 | P60: =N60*O60 -> 0 | Q60: =P60+N60 -> 0 | S60: =Q60*R60 -> 0 | T60: =S60+Q60 -> 0 | V60: =U60*T60 -> 0 | W60: =T60+V60 -> 0 | Y60: =IFERROR(W60/I60,0) -> 0
A61: 0003 | I61: =E61*H61 -> 0 | K61: =I61*J61 -> 0 | M61: =K61*L61 -> 0 | N61: =M61+K61 -> 0 | P61: =N61*O61 -> 0 | Q61: =P61+N61 -> 0 | S61: =Q61*R61 -> 0 | T61: =S61+Q61 -> 0 | V61: =U61*T61 -> 0 | W61: =T61+V61 -> 0 | Y61: =IFERROR(W61/I61,0) -> 0
A62: 0003 | I62: =H62*E62 -> 0 | K62: =I62*J62 -> 0 | M62: =K62*L62 -> 0 | N62: =M62+K62 -> 0 | P62: =N62*O62 -> 0 | Q62: =P62+N62 -> 0 | S62: =Q62*R62 -> 0 | T62: =S62+Q62 -> 0 | V62: =U62*T62 -> 0 | W62: =T62+V62 -> 0 | Y62: =IFERROR(W62/I62,0) -> 0
A63: 0003 | I63: =H63*E63 -> 0 | K63: =I63*J63 -> 0 | M63: =K63*L63 -> 0 | N63: =M63+K63 -> 0 | P63: =N63*O63 -> 0 | Q63: =P63+N63 -> 0 | S63: =Q63*R63 -> 0 | T63: =S63+Q63 -> 0 | V63: =U63*T63 -> 0 | W63: =T63+V63 -> 0 | Y63: =IFERROR(W63/I63,0) -> 0
A64: 0003 | I64: =H64*E64 -> 0 | K64: =I64*J64 -> 0 | M64: =K64*L64 -> 0 | N64: =M64+K64 -> 0 | P64: =N64*O64 -> 0 | Q64: =P64+N64 -> 0 | S64: =Q64*R64 -> 0 | T64: =S64+Q64 -> 0 | V64: =U64*T64 -> 0 | W64: =T64+V64 -> 0 | Y64: =IFERROR(W64/I64,0) -> 0
A65: 0003 | I65: =H65*E65 -> 0 | K65: =I65*J65 -> 0 | M65: =K65*L65 -> 0 | N65: =M65+K65 -> 0 | P65: =N65*O65 -> 0 | Q65: =P65+N65 -> 0 | S65: =Q65*R65 -> 0 | T65: =S65+Q65 -> 0 | V65: =U65*T65 -> 0 | W65: =T65+V65 -> 0 | Y65: =IFERROR(W65/I65,0) -> 0
A66: 0003 | I66: =H66*E66 -> 0 | K66: =I66*J66 -> 0 | M66: =K66*L66 -> 0 | N66: =M66+K66 -> 0 | P66: =N66*O66 -> 0 | Q66: =P66+N66 -> 0 | S66: =Q66*R66 -> 0 | T66: =S66+Q66 -> 0 | V66: =U66*T66 -> 0 | W66: =T66+V66 -> 0 | Y66: =IFERROR(W66/I66,0) -> 0
A67: 0003 | I67: =H67*E67 -> 0 | K67: =I67*J67 -> 0 | M67: =K67*L67 -> 0 | N67: =M67+K67 -> 0 | P67: =N67*O67 -> 0 | Q67: =P67+N67 -> 0 | S67: =Q67*R67 -> 0 | T67: =S67+Q67 -> 0 | V67: =U67*T67 -> 0 | W67: =T67+V67 -> 0 | Y67: =IFERROR(W67/I67,0) -> 0
...

Sheet CLINX004
A1: M67004-26-R-0007 Attachment J-7: Cost Model Workbook
A2: Contractor Name: | C2: =IF(Instructions!B3="","",Instructions!B3)
A3: * Use the Government‑provided plug number for “Other Logistics Support” under CLINs 0004 and 1004. Do not change Column C. Government‑provided costs must remain unchanged.
A4: * Enter the proposed fixed fee (ceiling) that will apply to future task orders under this CLIN.
A5: * Fee Amount and Total CPFF will calculate automatically.
A9: CLIN 0004 Base Ordering Period
A10: Year # | B10: Description | C10: Government Provided Cost | D10: Fee % | E10: Fee Amount | F10: Total Cost + Fixed Fee
A11: Year 1 | B11: Other Logistics Support | C11: 1850000 | E11: =C11*D11 -> 0 | F11: =E11+C11 -> 1850000
A12: Year 2 | B12: Other Logistics Support | C12: 1903650 | E12: =C12*D12 -> 0 | F12: =E12+C12 -> 1903650
A13: Year 3 | B13: Other Logistics Support | C13: 1958855.8 | E13: =C13*D13 -> 0 | F13: =E13+C13 -> 1958855.8
A14: Year 4 | B14: Other Logistics Support | C14: 2015662.7 | E14: =C14*D14 -> 0 | F14: =E14+C14 -> 2015662.7
A15: Year 5 | B15: Other Logistics Support | C15: 2074116.9 | E15: =C15*D15 -> 0 | F15: =E15+C15 -> 2074116.9
B16: CLIN 0004 SUBTOTAL | C16: =SUM(C11:C15) -> 9802285.4 | E16: =SUM(E11:E15) -> 0 | F16: =SUM(F11:F15) -> 9802285.4
A18: CLIN 1004 Optional Ordering Period
A19: Year # | B19: Description | C19: Government Provided Cost | D19: Fee % | E19: Fee Amount | F19: Total Cost + Fixed Fee
A20: Year 1 | B20: Other Logistics Support | C20: 2134266.3 | E20: =C20*D20 -> 0 | F20: =E20+C20 -> 2134266.3
A21: Year 2 | B21: Other Logistics Support | C21: 2196160 | E21: =C21*D21 -> 0 | F21: =E21+C21 -> 2196160
A22: Year 3 | B22: Other Logistics Support | C22: 2259848.6 | E22: =C22*D22 -> 0 | F22: =E22+C22 -> 2259848.6
A23: Year 4 | B23: Other Logistics Support | C23: 2325384.2 | E23: =C23*D23 -> 0 | F23: =E23+C23 -> 2325384.2
A24: Year 5 | B24: Other Logistics Support | C24: 2392820.4 | E24: =C24*D24 -> 0 | F24: =E24+C24 -> 2392820.4
B25: CLIN 1004 SUBTOTAL | C25: =SUM(C20:C24) -> 11308480 | E25: =SUM(E20:E24) -> 0 | F25: =SUM(F20:F24) -> 11308480
B27: TOTAL (BOTH CLINS) | C27: =C25+C16 -> 21110765 | E27: =E25+E16 -> 0 | F27: =F25+F16 -> 21110765

Sheet CLINX006
A1: M67004-26-R-0007 Attachment J-7: Cost Model Workbook
A2: Contractor Name: | C2: =IF(Instructions!B3="","",Instructions!B3)
A3: * Use the Government‑provided plug number for ODCs under CLINs 0006 and 1006. Do not adjust Column C.
A4: * Enter any proposed indirect rate(s) that apply to ODCs.
A5: * The Government has assumed G&A and/or Material Handling (MH) will apply; if your company uses different indirect rates for ODCs, update this sheet accordingly.
A6: * Be aware: Adjusting this sheet may break links to the Total Proposed Price tab. Offerors must correct any links or formulas to ensure ODCs + indirect rates total correctly on this tab and on the Total Proposed Price tab.
A7: * Fee is not allowed on this CLIN.
A9: CLIN 0006 Base Ordering Period
A10: Year # | B10: Description | C10: Government Provided Cost | D10: Material Handling Rate | E10: Material Handling Costs | F10: G&A Rate | G10: G&A Costs | H10: Total Cost (inclusive of all Indirects)
A11: Year 1 | B11: Other Direct Costs (ODCs) | C11: 64414905 | E11: =D11*C11 -> 0 | G11: =F11*(C11+E11) -> 0 | H11: =E11+C11+G11 -> 64414905
A12: Year 2 | B12: Other Direct Costs (ODCs) | C12: 66282937 | E12: =D12*C12 -> 0 | G12: =F12*(C12+E12) -> 0 | H12: =E12+C12+G12 -> 66282937
A13: Year 3 | B13: Other Direct Costs (ODCs) | C13: 68205142 | E13: =D13*C13 -> 0 | G13: =F13*(C13+E13) -> 0 | H13: =E13+C13+G13 -> 68205142
A14: Year 4 | B14: Other Direct Costs (ODCs) | C14: 70183091 | E14: =D14*C14 -> 0 | G14: =F14*(C14+E14) -> 0 | H14: =E14+C14+G14 -> 70183091
A15: Year 5 | B15: Other Direct Costs (ODCs) | C15: 72218401 | E15: =D15*C15 -> 0 | G15: =F15*(C15+E15) -> 0 | H15: =E15+C15+G15 -> 72218401
B16: CLIN 0006 SUBTOTAL | C16: =SUM(C11:C15) -> 3.4130448e+08 | E16: =SUM(E11:E15) -> 0 | G16: =SUM(G11:G15) -> 0 | H16: =SUM(H11:H15) -> 3.4130448e+08
A18: CLIN 1006 Optional Ordering Period
A19: Year # | B19: Description | C19: Government Provided Cost | D19: Material Handling Rate | E19: Material Handling Costs | F19: G&A Rate | G19: G&A Costs | H19: Total Cost (inclusive of all Indirects)
A20: Year 1 | B20: Other Direct Costs (ODCs) | C20: 74312734 | E20: =D20*C20 -> 0 | G20: =F20*(C20+E20) -> 0 | H20: =E20+C20+G20 -> 74312734
A21: Year 2 | B21: Other Direct Costs (ODCs) | C21: 76467804 | E21: =D21*C21 -> 0 | G21: =F21*(C21+E21) -> 0 | H21: =E21+C21+G21 -> 76467804
A22: Year 3 | B22: Other Direct Costs (ODCs) | C22: 78685370 | E22: =D22*C22 -> 0 | G22: =F22*(C22+E22) -> 0 | H22: =E22+C22+G22 -> 78685370
A23: Year 4 | B23: Other Direct Costs (ODCs) | C23: 80967246 | E23: =D23*C23 -> 0 | G23: =F23*(C23+E23) -> 0 | H23: =E23+C23+G23 -> 80967246
A24: Year 5 | B24: Other Direct Costs (ODCs) | C24: 83315296 | E24: =D24*C24 -> 0 | G24: =F24*(C24+E24) -> 0 | H24: =E24+C24+G24 -> 83315296
B25: CLIN 1006 SUBTOTAL | C25: =SUM(C20:C24) -> 3.9374845e+08 | E25: =SUM(E20:E24) -> 0 | G25: =SUM(G20:G24) -> 0 | H25: =SUM(H20:H24) -> 3.9374845e+08
B27: TOTAL (BOTH CLINS) | C27: =C25+C16 -> 7.3505293e+08 | E27: =E25+E16 -> 0 | G27: =G25+G16 -> 0 | H27: =H25+H16 -> 7.3505293e+08

Sheet CLIN0008
A1: M67004-26-R-0007 Attachment J-7: Cost Model Workbook
A2: Contractor Name: | C2: =IF(Instructions!B3="","",Instructions!B3)
A3: * Offerors shall fill in the firm-fixed-price (FFP) amount in the yellow cell they are proposing to accomplish the Transition-In IAW RFP Section H-21.
B11: CLIN | C11: Description | D11: Qty | E11: Unit Price | F11: Unit of Issue | G11: Total Price
B12: CLIN 0008 | C12: Transition-In | D12: 1 | F12: EA | G12: =D12*E12 -> 0

Sheet Labor Category
A1: LABOR CATEGORY
A2: 3M DATA ANALYST
A3: AAV MECHANIC
A4: AAV MECHANIC SR
A5: AAV MECHANIC SR LEAD
A6: ACCOUNT ANALYST
A7: ACV MECHANIC
A8: ACV MECHANIC LEAD
A9: ADMIN ASSISTANT
A10: ADMIN COORD
A11: AMMUNITION TECHNICIAN
A12: ARTILLERY MECHANIC
... A180: WOODWORKER
