Workbook

Sheet Summary
B1: US Naval Community College Consortium of Integrated Academic Services Pricing Template
C9: POP | D9: FY | E9: Est. Cost (USD)
B10: BASE | C10: 10/01/2026* to 09/30/2027 | D10: 2027 | E10: ='CLIN 0001 (Base)'!M89 -> 0
B11: OY1 | C11: 10/01/2027 to 09/30/2028 | D11: 2028 | E11: ='CLIN 0002 (OY1)'!M89 -> 0
B12: OY2 | C12: 10/01/2028 to 09/30/2029 | D12: 2029 | E12: ='CLIN 0003 (OY2)'!M95 -> 0
B13: OY3 | C13: 10/01/2029 to 09/30/2030 | D13: 2030 | E13: ='CLIN 0004 (OY3)'!M97 -> 0
B14: OY4 | C14: 10/01/2030 to 09/30/2031 | D14: 2031 | E14: ='CLIN 0005 (OY4)'!M98 -> 0
B15: 6-Month | C15: 10/01/2031 to 03/31/2032 | D15: 2032 | E15: ='6-Month Add'!M98 -> 0
E17: =SUM(E10:E15) -> 0
A18: *Tentative contract start and contract end date
A20: Institution:
A21: POC:
A22: Phone:
A23: Email:

Sheet CLIN 0001 (Base)
A1: IDIQ | B1: Partner Institution | C1: Program | D1: CLIN | E1: Course Seats | F1: Tuition | G1: Instruction Materials | H1: Term Fees | I1: Annual Fees | J1: Graduation Fees | L1: Credits/Course | M1: Total
A2: N0018925DZXX1 | B2: A | D2: 0001 | E2: =SUM(E3:E6) -> 5875 | M2: =SUM(M3:M8) -> 0
C3: Military Studies | E3: 1250 | F3: 0 | G3: 0 | H3: 0 | I3: 0 | J3: 0 | K3: 0 | L3: 3.5 | M3: =(E3*F3*L3)+(G3*E3)+((H3+I3+J3)*E3) -> 0
C4: Orginazational Leadership | E4: 3000 | F4: 0 | G4: 0 | H4: 0 | I4: 0 | J4: 0 | K4: 0 | L4: 3.5 | M4: =(E4*F4*L4)+(G4*E4)+((H4+I4+J4)*E4) -> 0
C5: Maritime Logistics | E5: 1250 | F5: 0 | G5: 0 | H5: 0 | I5: 0 | J5: 0 | K5: 0 | L5: 3.5 | M5: =(E5*F5*L5)+(G5*E5)+((H5+I5+J5)*E5) -> 0
C6: Emergency Management | E6: 375 | F6: 0 | G6: 0 | H6: 0 | I6: 0 | J6: 0 | K6: 0 | L6: 3.5 | M6: =(E6*F6*L6)+(G6*E6)+((H6+I6+J6)*E6) -> 0
C7: Program Management | D7: 1001 | M7: 0
C8: IT/Data Support | D8: 1002 | M8: 0
A10: N0018925DZXX2 | B10: B | D10: 0001 | E10: =SUM(E11:E14) -> 2750 | M10: =SUM(M11:M16) -> 0
C11: Nuclear Technology | E11: 750 | F11: 0 | G11: 0 | H11: 0 | I11: 0 | J11: 0 | K11: =(F11+G11+H11) -> 0 | L11: 3.5 | M11: =(E11*F11*L11)+(G11*E11)+((H11+I11+J11)*E11) -> 0
C12: Engineering Fundamentals | E12: 1500 | F12: 0 | G12: 0 | H12: 0 | I12: 0 | J12: 0 | K12: =(F12+G12+H12) -> 0 | L12: 3.5 | M12: =(E12*F12*L12)+(G12*E12)+((H12+I12+J12)*E12) -> 0
C13: FY27 (Mechatronics) | E13: 500 | F13: 0 | G13: 0 | H13: 0 | I13: 0 | J13: 0 | K13: 0 | L13: 3.5 | M13: =(E13*F13*L13)+(G13*E13)+((H13+I13+J13)*E13) -> 0
M14: =(E14*F14*L14)+(G14*E14)+((H14+I14+J14)*E14) -> 0
C15: Program Management | D15: 1001 | M15: 0
C16: IT/Data Support | D16: 1002 | M16: 0
A18: N0018925DZXX3 | B18: C | D18: 0001 | E18: =SUM(E19:E22) -> 3275 | M18: =SUM(M19:M24) -> 0
C19: GS w/ Computer Studies | E19: 2750 | F19: 0 | G19: 0 | H19: 0 | I19: 0 | J19: 0 | K19: =(F19+G19+H19) -> 0 | L19: 3.5 | M19: =(E19*F19*L19)+(G19*E19)+((H19+I19+J19)*E19) -> 0
C20: FY27 (Additive/Advance Manufacturing) | E20: 525 | F20: 0 | G20: 0 | H20: 0 | I20: 0 | J20: 0 | K20: =(F20+G20+H20) -> 0 | L20: 3.5 | M20: =(E20*F20*L20)+(G20*E20)+((H20+I20+J20)*E20) -> 0
M21: =(E21*F21*L21)+(G21*E21)+((H21+I21+J21)*E21) -> 0
M22: =(E22*F22*L22)+(G22*E22)+((H22+I22+J22)*E22) -> 0
C23: Program Management | D23: 1001 | M23: 0
C24: IT/Data Support | D24: 1002 | M24: 0
A26: N0018925DZXX4 | B26: D | D26: 0001 | E26: =SUM(E27:E30) -> 2625 | M26: =SUM(M27:M32) -> 0
C27: Cyber Security | E27: 2250 | F27: 0 | G27: 0 | H27: 0 | I27: 0 | J27: 0 | K27: =(F27+G27+H27) -> 0 | L27: 3.5 | M27: =(E27*F27*L27)+(G27*E27)+((H27+I27+J27)*E27) -> 0
C28: FY27 (Electronics/ Electronics Technology) | E28: 375 | F28: 0 | G28: 0 | H28: 0 | I28: 0 | J28: 0 | K28: =(F28+G28+H28) -> 0 | L28: 3.5 | M28: =(E28*F28*L28)+(G28*E28)+((H28+I28+J28)*E28) -> 0
M29: =(E29*F29*L29)+(G29*E29)+((H29+I29+J29)*E29) -> 0
M30: =(E30*F30*L30)+(G30*E30)+((H30+I30+J30)*E30) -> 0
C31: Program Management | D31: 1001 | M31: 0
C32: IT/Data Support | D32: 1002 | M32: 0
A34: N0018925DZXX5 | B34: E | D34: 0001 | E34: =SUM(E35:E38) -> 4450 | M34: =SUM(M35:M40) -> 0
C35: Aviation Maintenance and Uncrewed Systems | E35: 2500 | F35: 0 | G35: 0 | H35: 0 | I35: 0 | J35: 0 | K35: =(F35+G35+H35) -> 0 | L35: 3.5 | M35: =(E35*F35*L35)+(G35*E35)+((H35+I35+J35)*E35) -> 0
C36: Engineering Fundamentals | E36: 1000 | F36: 0 | G36: 0 | H36: 0 | I36: 0 | J36: 0 | K36: =(F36+G36+H36) -> 0 | L36: 3.5 | M36: =(E36*F36*L36)+(G36*E36)+((H36+I36+J36)*E36) -> 0
C37: Emergency Management | E37: 500 | F37: 0 | G37: 0 | H37: 0 | I37: 0 | J37: 0 | K37: =(F37+G37+H37) -> 0 | L37: 3.5 | M37: =(E37*F37*L37)+(G37*E37)+((H37+I37+J37)*E37) -> 0
C38: FY27 (Communications/ Electronic Warfare Technology) | E38: 450 | F38: 0 | G38: 0 | H38: 0 | I38: 0 | J38: 0 | K38: =(F38+G38+H38) -> 0 | L38: 3.5 | M38: =(E38*F38*L38)+(G38*E38)+((H38+I38+J38)*E38) -> 0
C39: Program Management | D39: 1001 | M39: 0
C40: IT/Data Support | D40: 1002 | M40: 0
A42: N0018925DZXX6 | B42: F | D42: 0001 | E42: =SUM(E43:E45) -> 1375 | M42: =SUM(M43:M47) -> 0
C43: Maritime Logistics | E43: 1000 | F43: 0 | G43: 0 | H43: 0 | I43: 0 | J43: 0 | K43: =(F43+G43+H43) -> 0 | L43: 3.5 | M43: =(E43*F43*L43)+(G43*E43)+((H43+I43+J43)*E43) -> 0
C44: FY27 (Industrial Maintenance/ AUS Technology) | E44: 375 | F44: 0 | G44: 0 | H44: 0 | I44: 0 | J44: 0 | K44: =(F44+G44+H44) -> 0 | L44: 3.5 | M44: =(E44*F44*L44)+(G44*E44)+((H44+I44+J44)*E44) -> 0
M45: =(E45*F45*L45)+(G45*E45)+((H45+I45+J45)*E45) -> 0
...

Sheet CLIN 0002 (OY1)
A1: IDIQ | B1: Partner Institution | C1: Program | D1: CLIN | E1: Course Seats | F1: Tuition | G1: Instruction Materials | H1: Term Fees | I1: Annual Fees | J1: Graduation Fees | L1: Credits/Course | M1: Total
A2: N0018900026DZXX1 | B2: A | D2: 0002 | E2: =SUM(E3:E6) -> 6500 | M2: =SUM(M3:M8) -> 0
C3: Military Studies | E3: 1500 | F3: 0 | G3: 0 | H3: 0 | I3: 0 | J3: 0 | K3: 0 | L3: 3.5 | M3: =(E3*F3*L3)+(G3*E3)+((H3+I3+J3)*E3) -> 0
C4: Orginazational Leadership | E4: 3250 | F4: 0 | G4: 0 | H4: 0 | I4: 0 | J4: 0 | K4: 0 | L4: 3.5 | M4: =(E4*F4*L4)+(G4*E4)+((H4+I4+J4)*E4) -> 0
C5: Maritime Logistics | E5: 1250 | F5: 0 | G5: 0 | H5: 0 | I5: 0 | J5: 0 | K5: 0 | L5: 3.5 | M5: =(E5*F5*L5)+(G5*E5)+((H5+I5+J5)*E5) -> 0
C6: Emergency Management | E6: 500 | F6: 0 | G6: 0 | H6: 0 | I6: 0 | J6: 0 | K6: 0 | L6: 3.5 | M6: =(E6*F6*L6)+(G6*E6)+((H6+I6+J6)*E6) -> 0
C7: Program Management | D7: 2001 | M7: 0
C8: IT/Data Support | D8: 2002 | M8: 0
A10: N0018900026DZXX0002 | B10: B | D10: 0002 | E10: =SUM(E11:E14) -> 3725 | M10: =SUM(M11:M16) -> 0
C11: Nuclear Technology | E11: 1000 | F11: 0 | G11: 0 | H11: 0 | I11: 0 | J11: 0 | K11: =(F11+G11+H11) -> 0 | L11: 3.5 | M11: =(E11*F11*L11)+(G11*E11)+((H11+I11+J11)*E11) -> 0
C12: Engineering Fundamentals | E12: 1750 | F12: 0 | G12: 0 | H12: 0 | I12: 0 | J12: 0 | K12: =(F10003+G10003+H10003) -> 0 | L12: 3.5 | M12: =(E12*F12*L12)+(G12*E12)+((H12+I12+J12)*E12) -> 0
C13: FY28 (Mechatronics) | E13: 750 | F13: 0 | G13: 0 | H13: 0 | I13: 0 | J13: 0 | K13: =(F13+G13+H13) -> 0 | L13: 3.5 | M13: =(E13*F13*L13)+(G13*E13)+((H13+I13+J13)*E13) -> 0
C14: FY28 (Marine Technology) | E14: 225 | F14: 0 | G14: 0 | H14: 0 | I14: 0 | J14: 0 | K14: =(F14+G14+H14) -> 0 | L14: 3.5 | M14: =(E14*F14*L14)+(G14*E14)+((H14+I14+J14)*E14) -> 0
C15: Program Management | D15: 2001 | M15: 0
C16: IT/Data Support | D16: 2002 | M16: 0
A18: N0018900026DZXX3 | B18: C | D18: 0002 | E18: =SUM(E19:E21) -> 4225 | M18: =SUM(M19:M23) -> 0
C19: GS w/ Computer Studies | E19: 3000 | F19: 0 | G19: 0 | H19: 0 | I19: 0 | J19: 0 | K19: =(F19+G19+H19) -> 0 | L19: 3.5 | M19: =(E19*F19*L19)+(G19*E19)+((H19+I19+J19)*E19) -> 0
C20: FY28 (Additive/Advance Manufacturing) | E20: 1000 | F20: 0 | G20: 0 | H20: 0 | I20: 0 | J20: 0 | K20: =(F20+G20+H20) -> 0 | L20: 3.5 | M20: =(E20*F20*L20)+(G20*E20)+((H20+I20+J20)*E20) -> 0
C21: [Insert Program] - FY28 | E21: 225 | F21: 0 | G21: 0 | H21: 0 | I21: 0 | J21: 0 | K21: =(F21+G21+H21) -> 0 | L21: 3.5 | M21: =(E21*F21*L21)+(G21*E21)+((H21+I21+J21)*E21) -> 0
C22: Program Management | D22: 2001 | M22: 0
C23: IT/Data Support | D23: 2002 | M23: 0
A25: N0018900026DZXX4 | B25: D | D25: 0002 | E25: =SUM(E26:E28) -> 3550 | M25: =SUM(M26:M30) -> 0
C26: Cyber Security | E26: 2500 | F26: 0 | G26: 0 | H26: 0 | I26: 0 | J26: 0 | K26: =(F26+G26+H26) -> 0 | L26: 3.5 | M26: =(E26*F26*L26)+(G26*E26)+((H26+I26+J26)*E26) -> 0
C27: FY28 (Electronics/ Electronics Technology) | E27: 750 | F27: 0 | G27: 0 | H27: 0 | I27: 0 | J27: 0 | K27: =(F27+G27+H27) -> 0 | L27: 3.5 | M27: =(E27*F27*L27)+(G27*E27)+((H27+I27+J27)*E27) -> 0
C28: [Insert Program] - FY28 | E28: 300 | F28: 0 | G28: 0 | H28: 0 | I28: 0 | J28: 0 | K28: =(F28+G28+H28) -> 0 | L28: 3.5 | M28: =(E28*F28*L28)+(G28*E28)+((H28+I28+J28)*E28) -> 0
C29: Program Management | D29: 2001 | M29: 0
C30: IT/Data Support | D30: 2002 | M30: 0
A32: N0018900026DZXX5 | B32: E | D32: 0002 | E32: =SUM(E33:E36) -> 5500 | M32: =SUM(M33:M38) -> 0
C33: Aviation Maintenance and Uncrewed Systems | E33: 2750 | F33: 0 | G33: 0 | H33: 0 | I33: 0 | J33: 0 | K33: =(F33+G33+H33) -> 0 | L33: 3.5 | M33: =(E33*F33*L33)+(G33*E33)+((H33+I33+J33)*E33) -> 0
C34: Engineering Fundamentals | E34: 1125 | F34: 0 | G34: 0 | H34: 0 | I34: 0 | J34: 0 | K34: =(F34+G34+H34) -> 0 | L34: 3.5 | M34: =(E34*F34*L34)+(G34*E34)+((H34+I34+J34)*E34) -> 0
C35: Emergency Management | E35: 625 | F35: 0 | G35: 0 | H35: 0 | I35: 0 | J35: 0 | K35: =(F35+G35+H35) -> 0 | L35: 3.5 | M35: =(E35*F35*L35)+(G35*E35)+((H35+I35+J35)*E35) -> 0
C36: FY28 (Communications/ Electronic Warfare Technology) | E36: 1000 | F36: 0 | G36: 0 | H36: 0 | I36: 0 | J36: 0 | K36: =(F36+G36+H36) -> 0 | L36: 3.5 | M36: =(E36*F36*L36)+(G36*E36)+((H36+I36+J36)*E36) -> 0
C37: Program Management | D37: 2001 | M37: 0
C38: IT/Data Support | D38: 2002 | M38: 0
A40: N0018900026DZXX6 | B40: F | D40: 0002 | E40: =SUM(E41:E43) -> 1900 | M40: =SUM(M41:M45) -> 0
C41: Maritime Logistics | E41: 1000 | F41: 0 | G41: 0 | H41: 0 | I41: 0 | J41: 0 | K41: =(F41+G41+H41) -> 0 | L41: 3.5 | M41: =(E41*F41*L41)+(G41*E41)+((H41+I41+J41)*E41) -> 0
C42: FY27 (Industrial Maintenance/ AUS Technology) | E42: 750 | F42: 0 | G42: 0 | H42: 0 | I42: 0 | J42: 0 | K42: =(F40003+G40003+H40003) -> 0 | L42: 3.5 | M42: =(E42*F42*L42)+(G42*E42)+((H42+I42+J42)*E42) -> 0
C43: [Insert Program] - FY28 | E43: 150 | F43: 0 | G43: 0 | H43: 0 | I43: 0 | J43: 0 | K43: =(F43+G43+H43) -> 0 | L43: 3.5 | M43: =(E43*F43*L43)+(G43*E43)+((H43+I43+J43)*E43) -> 0
C44: Program Management | D44: 2001 | M44: 0
C45: IT/Data Support | D45: 2002 | M45: 0
...

Sheet CLIN 0003 (OY2)
A1: IDIQ | B1: Partner Institution | C1: Program | D1: CLIN | E1: Course Seats | F1: Tuition | G1: Instruction Materials | H1: Term Fees | I1: Annual Fees | J1: Graduation Fees | L1: Credits/Course | M1: Total
A2: N0018925DZXX1 | B2: A | D2: 0003 | E2: =SUM(E3:E6) -> 8250 | M2: =SUM(M3:M8) -> 0
C3: Military Studies | E3: 1875 | F3: 0 | G3: 0 | H3: 0 | I3: 0 | J3: 0 | K3: 0 | L3: 3.5 | M3: =(E3*F3*L3)+(G3*E3)+((H3+I3+J3)*E3) -> 0
C4: Orginazational Leadership | E4: 3750 | F4: 0 | G4: 0 | H4: 0 | I4: 0 | J4: 0 | K4: 0 | L4: 3.5 | M4: =(E4*F4*L4)+(G4*E4)+((H4+I4+J4)*E4) -> 0
C5: Maritime Logistics | E5: 1875 | F5: 0 | G5: 0 | H5: 0 | I5: 0 | J5: 0 | K5: 0 | L5: 3.5 | M5: =(E5*F5*L5)+(G5*E5)+((H5+I5+J5)*E5) -> 0
C6: Emergency Management | E6: 750 | F6: 0 | G6: 0 | H6: 0 | I6: 0 | J6: 0 | K6: 0 | L6: 3.5 | M6: =(E6*F6*L6)+(G6*E6)+((H6+I6+J6)*E6) -> 0
C7: Program Management | D7: 3001 | M7: 0
C8: IT/Data Support | D8: 3002 | M8: 0
A10: N0018925DZXX2 | B10: B | D10: 0003 | E10: =SUM(E11:E14) -> 4750 | M10: =SUM(M11:M16) -> 0
C11: Nuclear Technology | E11: 1125 | F11: 0 | G11: 0 | H11: 0 | I11: 0 | J11: 0 | K11: =(F11+G11+H11) -> 0 | L11: 3.5 | M11: =(E11*F11*L11)+(G11*E11)+((H11+I11+J11)*E11) -> 0
C12: Engineering Fundamentals | E12: 1875 | F12: 0 | G12: 0 | H12: 0 | I12: 0 | J12: 0 | K12: =(F12+G12+H12) -> 0 | L12: 3.5 | M12: =(E12*F12*L12)+(G12*E12)+((H12+I12+J12)*E12) -> 0
C13: FY28 (Mechatronics) | E13: 1125 | F13: 0 | G13: 0 | H13: 0 | I13: 0 | J13: 0 | K13: =(F13+G13+H13) -> 0 | L13: 3.5 | M13: =(E13*F13*L13)+(G13*E13)+((H13+I13+J13)*E13) -> 0
C14: FY28 (Marine Technology) | E14: 625 | F14: 0 | G14: 0 | H14: 0 | I14: 0 | J14: 0 | K14: =(F14+G14+H14) -> 0 | L14: 3.5 | M14: =(E14*F14*L14)+(G14*E14)+((H14+I14+J14)*E14) -> 0
C15: Program Management | D15: 3001 | M15: 0
C16: IT/Data Support | D16: 3002 | M16: 0
A18: N0018925DZXX3 | B18: C | D18: 0003 | E18: =SUM(E19:E22) -> 5625 | M18: =SUM(M19:M24) -> 0
C19: GS w/ Computer Studies | E19: 3250 | F19: 0 | G19: 0 | H19: 0 | I19: 0 | J19: 0 | K19: =(F19+G19+H19) -> 0 | L19: 3.5 | M19: =(E19*F19*L19)+(G19*E19)+((H19+I19+J19)*E19) -> 0
C20: FY27 (Additive/Advance Manufacturing) | E20: 1250 | F20: 0 | G20: 0 | H20: 0 | I20: 0 | J20: 0 | K20: =(F20+G20+H20) -> 0 | L20: 3.5 | M20: =(E20*F20*L20)+(G20*E20)+((H20+I20+J20)*E20) -> 0
C21: [Insert Program] - FY28 | E21: 750 | F21: 0 | G21: 0 | H21: 0 | I21: 0 | J21: 0 | K21: =(F21+G21+H21) -> 0 | L21: 3.5 | M21: =(E21*F21*L21)+(G21*E21)+((H21+I21+J21)*E21) -> 0
C22: [Insert Program] - FY29 | E22: 375 | F22: 0 | G22: 0 | H22: 0 | I22: 0 | J22: 0 | K22: =(F22+G22+H22) -> 0 | L22: 3.5 | M22: =(E22*F22*L22)+(G22*E22)+((H22+I22+J22)*E22) -> 0
C23: Program Management | D23: 3001 | M23: 0
C24: IT/Data Support | D24: 3002 | M24: 0
A26: N0018925DZXX4 | B26: D | D26: 0003 | E26: =SUM(E27:E30) -> 5300 | M26: =SUM(M27:M32) -> 0
C27: Cyber Security | E27: 3125 | F27: 0 | G27: 0 | H27: 0 | I27: 0 | J27: 0 | K27: =(F27+G27+H27) -> 0 | L27: 3.5 | M27: =(E27*F27*L27)+(G27*E27)+((H27+I27+J27)*E27) -> 0
C28: FY27 (Electronics/ Electronics Technology) | E28: 1125 | F28: 0 | G28: 0 | H28: 0 | I28: 0 | J28: 0 | K28: =(F28+G28+H28) -> 0 | L28: 3.5 | M28: =(E28*F28*L28)+(G28*E28)+((H28+I28+J28)*E28) -> 0
C29: [Insert Program] - FY28 | E29: 750 | F29: 0 | G29: 0 | H29: 0 | I29: 0 | J29: 0 | K29: =(F29+G29+H29) -> 0 | L29: 3.5 | M29: =(E29*F29*L29)+(G29*E29)+((H29+I29+J29)*E29) -> 0
C30: [Insert Program] - FY29 | E30: 300 | F30: 0 | G30: 0 | H30: 0 | I30: 0 | J30: 0 | K30: =(F30+G30+H30) -> 0 | L30: 3.5 | M30: =(E30*F30*L30)+(G30*E30)+((H30+I30+J30)*E30) -> 0
C31: Program Management | D31: 3001 | M31: 0
C32: IT/Data Support | D32: 3002 | M32: 0
A34: N0018925DZXX5 | B34: E | D34: 0003 | E34: =SUM(E35:E38) -> 7250 | M34: =SUM(M35:M40) -> 0
C35: Aviation Maintenance and Uncrewed Systems | E35: 3750 | F35: 0 | G35: 0 | H35: 0 | I35: 0 | J35: 0 | K35: =(F35+G35+H35) -> 0 | L35: 3.5 | M35: =(E35*F35*L35)+(G35*E35)+((H35+I35+J35)*E35) -> 0
C36: Engineering Fundamentals | E36: 1500 | F36: 0 | G36: 0 | H36: 0 | I36: 0 | J36: 0 | K36: =(F36+G36+H36) -> 0 | L36: 3.5 | M36: =(E36*F36*L36)+(G36*E36)+((H36+I36+J36)*E36) -> 0
C37: Emergency Management | E37: 750 | F37: 0 | G37: 0 | H37: 0 | I37: 0 | J37: 0 | K37: =(F37+G37+H37) -> 0 | L37: 3.5 | M37: =(E37*F37*L37)+(G37*E37)+((H37+I37+J37)*E37) -> 0
C38: FY28 (Communications/ Electronic Warfare Technology) | E38: 1250 | F38: 0 | G38: 0 | H38: 0 | I38: 0 | J38: 0 | K38: =(F38+G38+H38) -> 0 | L38: 3.5 | M38: =(E38*F38*L38)+(G38*E38)+((H38+I38+J38)*E38) -> 0
C39: Program Management | D39: 3001 | M39: 0
C40: IT/Data Support | D40: 3002 | M40: 0
A42: N0018925DZXX6 | B42: F | D42: 0003 | E42: =SUM(E43:E45) -> 3250 | M42: =SUM(M43:M47) -> 0
C43: Maritime Logistics | E43: 1500 | F43: 0 | G43: 0 | H43: 0 | I43: 0 | J43: 0 | K43: =(F43+G43+H43) -> 0 | L43: 3.5 | M43: =(E43*F43*L43)+(G43*E43)+((H43+I43+J43)*E43) -> 0
C44: FY27 (Industrial Maintenance/ AUS Technology) | E44: 1125 | F44: 0 | G44: 0 | H44: 0 | I44: 0 | J44: 0 | K44: =(F44+G44+H44) -> 0 | L44: 3.5 | M44: =(E44*F44*L44)+(G44*E44)+((H44+I44+J44)*E44) -> 0
C45: [Insert Program] - FY28 | E45: 625 | F45: 0 | G45: 0 | H45: 0 | I45: 0 | J45: 0 | K45: =(F45+G45+H45) -> 0 | L45: 3.5 | M45: =(E45*F45*L45)+(G45*E45)+((H45+I45+J45)*E45) -> 0
...

Sheet CLIN 0004 (OY3)
A1: IDIQ | B1: Partner Institution | C1: Program | D1: CLIN | E1: Course Seats | F1: Tuition | G1: Instruction Materials | H1: Term Fees | I1: Annual Fees | J1: Graduation Fees | L1: Credits/Course | M1: Total
A2: N0018925DZXX1 | B2: A | D2: 0004 | E2: =SUM(E3:E6) -> 9000 | M2: =SUM(M3:M8) -> 0
C3: Military Studies | E3: 2000 | F3: 0 | G3: 0 | H3: 0 | I3: 0 | J3: 0 | K3: 0 | L3: 3.5 | M3: =(E3*F3*L3)+(G3*E3)+((H3+I3+J3)*E3) -> 0
C4: Orginazational Leadership | E4: 4000 | F4: 0 | G4: 0 | H4: 0 | I4: 0 | J4: 0 | K4: 0 | L4: 3.5 | M4: =(E4*F4*L4)+(G4*E4)+((H4+I4+J4)*E4) -> 0
C5: Maritime Logistics | E5: 2125 | F5: 0 | G5: 0 | H5: 0 | I5: 0 | J5: 0 | K5: 0 | L5: 3.5 | M5: =(E5*F5*L5)+(G5*E5)+((H5+I5+J5)*E5) -> 0
C6: Emergency Management | E6: 875 | F6: 0 | G6: 0 | H6: 0 | I6: 0 | J6: 0 | K6: 0 | L6: 3.5 | M6: =(E6*F6*L6)+(G6*E6)+((H6+I6+J6)*E6) -> 0
C7: Program Management | D7: 4001 | M7: 0
C8: IT/Data Support | D8: 4002 | M8: 0
A10: N0018925DZXX2 | B10: B | D10: 0004 | E10: =SUM(E11:E14) -> 5250 | M10: =SUM(M11:M16) -> 0
C11: Nuclear Technology | E11: 1125 | F11: 0 | G11: 0 | H11: 0 | I11: 0 | J11: 0 | K11: =(F11+G11+H11) -> 0 | L11: 3.5 | M11: =(E11*F11*L11)+(G11*E11)+((H11+I11+J11)*E11) -> 0
C12: Engineering Fundamentals | E12: 2125 | F12: 0 | G12: 0 | H12: 0 | I12: 0 | J12: 0 | K12: =(F12+G12+H12) -> 0 | L12: 3.5 | M12: =(E12*F12*L12)+(G12*E12)+((H12+I12+J12)*E12) -> 0
C13: FY28 (Mechatronics) | E13: 1250 | F13: 0 | G13: 0 | H13: 0 | I13: 0 | J13: 0 | K13: =(F13+G13+H13) -> 0 | L13: 3.5 | M13: =(E13*F13*L13)+(G13*E13)+((H13+I13+J13)*E13) -> 0
C14: FY28 (Marine Technology) | E14: 750 | F14: 0 | G14: 0 | H14: 0 | I14: 0 | J14: 0 | K14: =(F14+G14+H14) -> 0 | L14: 3.5 | M14: =(E14*F14*L14)+(G14*E14)+((H14+I14+J14)*E14) -> 0
C15: Program Management | D15: 4001 | M15: 0
C16: IT/Data Support | D16: 4002 | M16: 0
A18: N0018925DZXX3 | B18: C | D18: 0004 | E18: =SUM(E19:E22) -> 6750 | M18: =SUM(M19:M24) -> 0
C19: GS w/ Computer Studies | E19: 3500 | F19: 0 | G19: 0 | H19: 0 | I19: 0 | J19: 0 | K19: =(F19+G19+H19) -> 0 | L19: 3.5 | M19: =(E19*F19*L19)+(G19*E19)+((H19+I19+J19)*E19) -> 0
C20: FY27 (Additive/Advance Manufacturing) | E20: 1500 | F20: 0 | G20: 0 | H20: 0 | I20: 0 | J20: 0 | K20: =(F20+G20+H20) -> 0 | L20: 3.5 | M20: =(E20*F20*L20)+(G20*E20)+((H20+I20+J20)*E20) -> 0
C21: [Insert Program] - FY28 | E21: 875 | F21: 0 | G21: 0 | H21: 0 | I21: 0 | J21: 0 | K21: =(F21+G21+H21) -> 0 | L21: 3.5 | M21: =(E21*F21*L21)+(G21*E21)+((H21+I21+J21)*E21) -> 0
C22: [Insert Program] - FY29 | E22: 875 | F22: 0 | G22: 0 | H22: 0 | I22: 0 | J22: 0 | K22: =(F22+G22+H22) -> 0 | L22: 3.5 | M22: =(E22*F22*L22)+(G22*E22)+((H22+I22+J22)*E22) -> 0
C23: Program Management | D23: 4001 | M23: 0
C24: IT/Data Support | D24: 4002 | M24: 0
A26: N0018925DZXX4 | B26: D | D26: 0004 | E26: =SUM(E27:E30) -> 6750 | M26: =SUM(M27:M32) -> 0
C27: Cyber Security | E27: 3750 | F27: 0 | G27: 0 | H27: 0 | I27: 0 | J27: 0 | K27: =(F27+G27+H27) -> 0 | L27: 3.5 | M27: =(E27*F27*L27)+(G27*E27)+((H27+I27+J27)*E27) -> 0
C28: FY27 (Electronics/ Electronics Technology) | E28: 1250 | F28: 0 | G28: 0 | H28: 0 | I28: 0 | J28: 0 | K28: =(F28+G28+H28) -> 0 | L28: 3.5 | M28: =(E28*F28*L28)+(G28*E28)+((H28+I28+J28)*E28) -> 0
C29: [Insert Program] - FY28 | E29: 1000 | F29: 0 | G29: 0 | H29: 0 | I29: 0 | J29: 0 | K29: =(F29+G29+H29) -> 0 | L29: 3.5 | M29: =(E29*F29*L29)+(G29*E29)+((H29+I29+J29)*E29) -> 0
C30: [Insert Program] - FY29 | E30: 750 | F30: 0 | G30: 0 | H30: 0 | I30: 0 | J30: 0 | K30: =(F30+G30+H30) -> 0 | L30: 3.5 | M30: =(E30*F30*L30)+(G30*E30)+((H30+I30+J30)*E30) -> 0
C31: Program Management | D31: 4001 | M31: 0
C32: IT/Data Support | D32: 4002 | M32: 0
A34: N0018925DZXX5 | B34: E | D34: 0004 | E34: =SUM(E35:E38) -> 8250 | M34: =SUM(M35:M40) -> 0
C35: Aviation Maintenance and Uncrewed Systems | E35: 4250 | F35: 0 | G35: 0 | H35: 0 | I35: 0 | J35: 0 | K35: =(F35+G35+H35) -> 0 | L35: 3.5 | M35: =(E35*F35*L35)+(G35*E35)+((H35+I35+J35)*E35) -> 0
C36: Engineering Fundamentals | E36: 1750 | F36: 0 | G36: 0 | H36: 0 | I36: 0 | J36: 0 | K36: =(F36+G36+H36) -> 0 | L36: 3.5 | M36: =(E36*F36*L36)+(G36*E36)+((H36+I36+J36)*E36) -> 0
C37: Emergency Management | E37: 750 | F37: 0 | G37: 0 | H37: 0 | I37: 0 | J37: 0 | K37: =(F37+G37+H37) -> 0 | L37: 3.5 | M37: =(E37*F37*L37)+(G37*E37)+((H37+I37+J37)*E37) -> 0
C38: FY28 (Communications/ Electronic Warfare Technology) | E38: 1500 | F38: 0 | G38: 0 | H38: 0 | I38: 0 | J38: 0 | K38: =(F38+G38+H38) -> 0 | L38: 3.5 | M38: =(E38*F38*L38)+(G38*E38)+((H38+I38+J38)*E38) -> 0
C39: Program Management | D39: 4001 | M39: 0
C40: IT/Data Support | D40: 4002 | M40: 0
A42: N0018925DZXX6 | B42: F | D42: 0004 | E42: =SUM(E43:E45) -> 3750 | M42: =SUM(M43:M47) -> 0
C43: Maritime Logistics | E43: 1625 | F43: 0 | G43: 0 | H43: 0 | I43: 0 | J43: 0 | K43: =(F43+G43+H43) -> 0 | L43: 3.5 | M43: =(E43*F43*L43)+(G43*E43)+((H43+I43+J43)*E43) -> 0
C44: FY27 (Industrial Maintenance/ AUS Technology) | E44: 1250 | F44: 0 | G44: 0 | H44: 0 | I44: 0 | J44: 0 | K44: =(F44+G44+H44) -> 0 | L44: 3.5 | M44: =(E44*F44*L44)+(G44*E44)+((H44+I44+J44)*E44) -> 0
C45: [Insert Program] - FY28 | E45: 875 | F45: 0 | G45: 0 | H45: 0 | I45: 0 | J45: 0 | K45: =(F45+G45+H45) -> 0 | L45: 3.5 | M45: =(E45*F45*L45)+(G45*E45)+((H45+I45+J45)*E45) -> 0
...

Sheet CLIN 0005 (OY4)
A1: IDIQ | B1: Partner Institution | C1: Program | D1: CLIN | E1: Course Seats | F1: Tuition | G1: Instruction Materials | H1: Term Fees | I1: Annual Fees | J1: Graduation Fees | L1: Credits/Course | M1: Total
A2: N0018925DZXX1 | B2: A | D2: 0005 | E2: =SUM(E3:E6) -> 9000 | M2: =SUM(M3:M8) -> 0
C3: Military Studies | E3: 2000 | F3: 0 | G3: 0 | H3: 0 | I3: 0 | J3: 0 | K3: 0 | L3: 3.5 | M3: =(E3*F3*L3)+(G3*E3)+((H3+I3+J3)*E3) -> 0
C4: Orginazational Leadership | E4: 4000 | F4: 0 | G4: 0 | H4: 0 | I4: 0 | J4: 0 | K4: 0 | L4: 3.5 | M4: =(E4*F4*L4)+(G4*E4)+((H4+I4+J4)*E4) -> 0
C5: Maritime Logistics | E5: 2125 | F5: 0 | G5: 0 | H5: 0 | I5: 0 | J5: 0 | K5: 0 | L5: 3.5 | M5: =(E5*F5*L5)+(G5*E5)+((H5+I5+J5)*E5) -> 0
C6: Emergency Management | E6: 875 | F6: 0 | G6: 0 | H6: 0 | I6: 0 | J6: 0 | K6: 0 | L6: 3.5 | M6: =(E6*F6*L6)+(G6*E6)+((H6+I6+J6)*E6) -> 0
C7: Program Management | D7: 5001 | M7: 0
C8: IT/Data Support | D8: 5002 | M8: 0
A10: N0018925DZXX2 | B10: B | D10: 0005 | E10: =SUM(E11:E14) -> 5250 | M10: =SUM(M11:M16) -> 0
C11: Nuclear Technology | E11: 1125 | F11: 0 | G11: 0 | H11: 0 | I11: 0 | J11: 0 | K11: =(F11+G11+H11) -> 0 | L11: 3.5 | M11: =(E11*F11*L11)+(G11*E11)+((H11+I11+J11)*E11) -> 0
C12: Engineering Fundamentals | E12: 2125 | F12: 0 | G12: 0 | H12: 0 | I12: 0 | J12: 0 | K12: =(F12+G12+H12) -> 0 | L12: 3.5 | M12: =(E12*F12*L12)+(G12*E12)+((H12+I12+J12)*E12) -> 0
C13: FY28 (Mechatronics) | E13: 1250 | F13: 0 | G13: 0 | H13: 0 | I13: 0 | J13: 0 | K13: =(F13+G13+H13) -> 0 | L13: 3.5 | M13: =(E13*F13*L13)+(G13*E13)+((H13+I13+J13)*E13) -> 0
C14: FY28 (Marine Technology) | E14: 750 | F14: 0 | G14: 0 | H14: 0 | I14: 0 | J14: 0 | K14: =(F14+G14+H14) -> 0 | L14: 3.5 | M14: =(E14*F14*L14)+(G14*E14)+((H14+I14+J14)*E14) -> 0
C15: Program Management | D15: 5001 | M15: 0
C16: IT/Data Support | D16: 5002 | M16: 0
A18: N0018925DZXX3 | B18: C | D18: 0005 | E18: =SUM(E19:E22) -> 6750 | M18: =SUM(M19:M24) -> 0
C19: GS w/ Computer Studies | E19: 3500 | F19: 0 | G19: 0 | H19: 0 | I19: 0 | J19: 0 | K19: =(F19+G19+H19) -> 0 | L19: 3.5 | M19: =(E19*F19*L19)+(G19*E19)+((H19+I19+J19)*E19) -> 0
C20: FY27 (Additive/Advance Manufacturing) | E20: 1500 | F20: 0 | G20: 0 | H20: 0 | I20: 0 | J20: 0 | K20: =(F20+G20+H20) -> 0 | L20: 3.5 | M20: =(E20*F20*L20)+(G20*E20)+((H20+I20+J20)*E20) -> 0
C21: [Insert Program] - FY28 | E21: 875 | F21: 0 | G21: 0 | H21: 0 | I21: 0 | J21: 0 | K21: =(F21+G21+H21) -> 0 | L21: 3.5 | M21: =(E21*F21*L21)+(G21*E21)+((H21+I21+J21)*E21) -> 0
C22: [Insert Program] - FY29 | E22: 875 | F22: 0 | G22: 0 | H22: 0 | I22: 0 | J22: 0 | K22: =(F22+G22+H22) -> 0 | L22: 3.5 | M22: =(E22*F22*L22)+(G22*E22)+((H22+I22+J22)*E22) -> 0
C23: Program Management | D23: 5001 | M23: 0
C24: IT/Data Support | D24: 5002 | M24: 0
A26: N0018925DZXX4 | B26: D | D26: 0005 | E26: =SUM(E27:E30) -> 6750 | M26: =SUM(M27:M32) -> 0
C27: Cyber Security | E27: 3750 | F27: 0 | G27: 0 | H27: 0 | I27: 0 | J27: 0 | K27: =(F27+G27+H27) -> 0 | L27: 3.5 | M27: =(E27*F27*L27)+(G27*E27)+((H27+I27+J27)*E27) -> 0
C28: FY27 (Electronics/ Electronics Technology) | E28: 1250 | F28: 0 | G28: 0 | H28: 0 | I28: 0 | J28: 0 | K28: =(F28+G28+H28) -> 0 | L28: 3.5 | M28: =(E28*F28*L28)+(G28*E28)+((H28+I28+J28)*E28) -> 0
C29: [Insert Program] - FY28 | E29: 1000 | F29: 0 | G29: 0 | H29: 0 | I29: 0 | J29: 0 | K29: =(F29+G29+H29) -> 0 | L29: 3.5 | M29: =(E29*F29*L29)+(G29*E29)+((H29+I29+J29)*E29) -> 0
C30: [Insert Program] - FY29 | E30: 750 | F30: 0 | G30: 0 | H30: 0 | I30: 0 | J30: 0 | K30: =(F30+G30+H30) -> 0 | L30: 3.5 | M30: =(E30*F30*L30)+(G30*E30)+((H30+I30+J30)*E30) -> 0
C31: Program Management | D31: 1001 | M31: 0
C32: IT/Data Support | D32: 1002 | M32: 0
A34: N0018925DZXX5 | B34: E | D34: 0005 | E34: =SUM(E35:E38) -> 8250 | M34: =SUM(M35:M40) -> 0
C35: Aviation Maintenance and Uncrewed Systems | E35: 4250 | F35: 0 | G35: 0 | H35: 0 | I35: 0 | J35: 0 | K35: =(F35+G35+H35) -> 0 | L35: 3.5 | M35: =(E35*F35*L35)+(G35*E35)+((H35+I35+J35)*E35) -> 0
C36: Engineering Fundamentals | E36: 1750 | F36: 0 | G36: 0 | H36: 0 | I36: 0 | J36: 0 | K36: =(F36+G36+H36) -> 0 | L36: 3.5 | M36: =(E36*F36*L36)+(G36*E36)+((H36+I36+J36)*E36) -> 0
C37: Emergency Management | E37: 750 | F37: 0 | G37: 0 | H37: 0 | I37: 0 | J37: 0 | K37: =(F37+G37+H37) -> 0 | L37: 3.5 | M37: =(E37*F37*L37)+(G37*E37)+((H37+I37+J37)*E37) -> 0
C38: FY28 (Communications/ Electronic Warfare Technology) | E38: 1500 | F38: 0 | G38: 0 | H38: 0 | I38: 0 | J38: 0 | K38: =(F38+G38+H38) -> 0 | L38: 3.5 | M38: =(E38*F38*L38)+(G38*E38)+((H38+I38+J38)*E38) -> 0
C39: Program Management | D39: 5001 | M39: 0
C40: IT/Data Support | D40: 5002 | M40: 0
A42: N0018925DZXX6 | B42: F | D42: 0005 | E42: =SUM(E43:E45) -> 3750 | M42: =SUM(M43:M47) -> 0
C43: Maritime Logistics | E43: 1625 | F43: 0 | G43: 0 | H43: 0 | I43: 0 | J43: 0 | K43: =(F43+G43+H43) -> 0 | L43: 3.5 | M43: =(E43*F43*L43)+(G43*E43)+((H43+I43+J43)*E43) -> 0
C44: FY27 (Industrial Maintenance/ AUS Technology) | E44: 1250 | F44: 0 | G44: 0 | H44: 0 | I44: 0 | J44: 0 | K44: =(F44+G44+H44) -> 0 | L44: 3.5 | M44: =(E44*F44*L44)+(G44*E44)+((H44+I44+J44)*E44) -> 0
C45: [Insert Program] - FY28 | E45: 875 | M45: =(E45*K45*L45)+(E45*(I45+J45)) -> 0
...

Sheet 6-Month Add
A1: IDIQ | B1: Partner Institution | C1: Program | D1: CLIN | E1: Course Seats | F1: Tuition | G1: Instruction Materials | H1: Term Fees | I1: Annual Fees | J1: Graduation Fees | L1: Credits/Course | M1: Total
A2: N0018925DZXX1 | B2: A | D2: 0006 | E2: =SUM(E3:E6) -> 4500 | M2: =SUM(M3:M8) -> 0
C3: Military Studies | E3: ='CLIN 0005 (OY4)'!E3/2 -> 1000 | F3: 0 | G3: 0 | H3: 0 | I3: 0 | J3: 0 | K3: 0 | L3: 3.5 | M3: =(E3*F3*L3)+(G3*E3)+((H3+I3+J3)*E3) -> 0
C4: Orginazational Leadership | E4: ='CLIN 0005 (OY4)'!E4/2 -> 2000 | F4: 0 | G4: 0 | H4: 0 | I4: 0 | J4: 0 | K4: 0 | L4: 3.5 | M4: =(E4*F4*L4)+(G4*E4)+((H4+I4+J4)*E4) -> 0
C5: Maritime Logistics | E5: ='CLIN 0005 (OY4)'!E5/2 -> 1062.5 | F5: 0 | G5: 0 | H5: 0 | I5: 0 | J5: 0 | K5: 0 | L5: 3.5 | M5: =(E5*F5*L5)+(G5*E5)+((H5+I5+J5)*E5) -> 0
C6: Emergency Management | E6: ='CLIN 0005 (OY4)'!E6/2 -> 437.5 | F6: 0 | G6: 0 | H6: 0 | I6: 0 | J6: 0 | K6: 0 | L6: 3.5 | M6: =(E6*F6*L6)+(G6*E6)+((H6+I6+J6)*E6) -> 0
C7: Program Management | D7: 6001 | M7: 0
C8: IT/Data Support | D8: 6002 | M8: 0
A10: N0018925DZXX2 | B10: B | D10: 0006 | E10: =SUM(E11:E14) -> 2625 | M10: =SUM(M11:M16) -> 0
C11: Nuclear Technology | E11: ='CLIN 0005 (OY4)'!E11/2 -> 562.5 | F11: 0 | G11: 0 | H11: 0 | I11: 0 | J11: 0 | K11: =(F11+G11+H11) -> 0 | L11: 3.5 | M11: =(E11*F11*L11)+(G11*E11)+((H11+I11+J11)*E11) -> 0
C12: Engineering Fundamentals | E12: ='CLIN 0005 (OY4)'!E12/2 -> 1062.5 | F12: 0 | G12: 0 | H12: 0 | I12: 0 | J12: 0 | K12: =(F12+G12+H12) -> 0 | L12: 3.5 | M12: =(E12*F12*L12)+(G12*E12)+((H12+I12+J12)*E12) -> 0
C13: FY28 (Mechatronics) | E13: ='CLIN 0005 (OY4)'!E13/2 -> 625 | F13: 0 | G13: 0 | H13: 0 | I13: 0 | J13: 0 | K13: =(F13+G13+H13) -> 0 | L13: 3.5 | M13: =(E13*F13*L13)+(G13*E13)+((H13+I13+J13)*E13) -> 0
C14: FY28 (Marine Technology) | E14: ='CLIN 0005 (OY4)'!E14/2 -> 375 | F14: 0 | G14: 0 | H14: 0 | I14: 0 | J14: 0 | K14: =(F14+G14+H14) -> 0 | L14: 3.5 | M14: =(E14*F14*L14)+(G14*E14)+((H14+I14+J14)*E14) -> 0
C15: Program Management | D15: 6001 | M15: 0
C16: IT/Data Support | D16: 6002 | M16: 0
A18: N0018925DZXX3 | B18: C | D18: 0006 | E18: =SUM(E19:E22) -> 3375 | M18: =SUM(M19:M24) -> 0
C19: GS w/ Computer Studies | E19: ='CLIN 0005 (OY4)'!E19/2 -> 1750 | F19: 0 | G19: 0 | H19: 0 | I19: 0 | J19: 0 | K19: =(F19+G19+H19) -> 0 | L19: 3.5 | M19: =(E19*F19*L19)+(G19*E19)+((H19+I19+J19)*E19) -> 0
C20: FY27 (Additive/Advance Manufacturing) | E20: ='CLIN 0005 (OY4)'!E20/2 -> 750 | F20: 0 | G20: 0 | H20: 0 | I20: 0 | J20: 0 | K20: =(F20+G20+H20) -> 0 | L20: 3.5 | M20: =(E20*F20*L20)+(G20*E20)+((H20+I20+J20)*E20) -> 0
C21: [Insert Program] - FY28 | E21: ='CLIN 0005 (OY4)'!E21/2 -> 437.5 | F21: 0 | G21: 0 | H21: 0 | I21: 0 | J21: 0 | K21: =(F21+G21+H21) -> 0 | L21: 3.5 | M21: =(E21*F21*L21)+(G21*E21)+((H21+I21+J21)*E21) -> 0
C22: [Insert Program] - FY29 | E22: ='CLIN 0005 (OY4)'!E22/2 -> 437.5 | F22: 0 | G22: 0 | H22: 0 | I22: 0 | J22: 0 | K22: =(F22+G22+H22) -> 0 | L22: 3.5 | M22: =(E22*F22*L22)+(G22*E22)+((H22+I22+J22)*E22) -> 0
C23: Program Management | D23: 6001 | M23: 0
C24: IT/Data Support | D24: 6002 | M24: 0
A26: N0018925DZXX4 | B26: D | D26: 0006 | E26: =SUM(E27:E30) -> 3375 | M26: =SUM(M27:M32) -> 0
C27: Cyber Security | E27: ='CLIN 0005 (OY4)'!E27/2 -> 1875 | F27: 0 | G27: 0 | H27: 0 | I27: 0 | J27: 0 | K27: =(F27+G27+H27) -> 0 | L27: 3.5 | M27: =(E27*F27*L27)+(G27*E27)+((H27+I27+J27)*E27) -> 0
C28: FY27 (Electronics/ Electronics Technology) | E28: ='CLIN 0005 (OY4)'!E28/2 -> 625 | F28: 0 | G28: 0 | H28: 0 | I28: 0 | J28: 0 | K28: =(F28+G28+H28) -> 0 | L28: 3.5 | M28: =(E28*F28*L28)+(G28*E28)+((H28+I28+J28)*E28) -> 0
C29: [Insert Program] - FY28 | E29: ='CLIN 0005 (OY4)'!E29/2 -> 500 | F29: 0 | G29: 0 | H29: 0 | I29: 0 | J29: 0 | K29: =(F29+G29+H29) -> 0 | L29: 3.5 | M29: =(E29*F29*L29)+(G29*E29)+((H29+I29+J29)*E29) -> 0
C30: [Insert Program] - FY29 | E30: ='CLIN 0005 (OY4)'!E30/2 -> 375 | F30: 0 | G30: 0 | H30: 0 | I30: 0 | J30: 0 | K30: =(F30+G30+H30) -> 0 | L30: 3.5 | M30: =(E30*F30*L30)+(G30*E30)+((H30+I30+J30)*E30) -> 0
C31: Program Management | D31: 6001 | M31: 0
C32: IT/Data Support | D32: 6002 | M32: 0
A34: N0018925DZXX5 | B34: E | D34: 0006 | E34: =SUM(E35:E38) -> 4125 | M34: =SUM(M35:M40) -> 0
C35: Aviation Maintenance and Uncrewed Systems | E35: ='CLIN 0005 (OY4)'!E35/2 -> 2125 | F35: 0 | G35: 0 | H35: 0 | I35: 0 | J35: 0 | K35: =(F35+G35+H35) -> 0 | L35: 3.5 | M35: =(E35*F35*L35)+(G35*E35)+((H35+I35+J35)*E35) -> 0
C36: Engineering Fundamentals | E36: ='CLIN 0005 (OY4)'!E36/2 -> 875 | F36: 0 | G36: 0 | H36: 0 | I36: 0 | J36: 0 | K36: =(F36+G36+H36) -> 0 | L36: 3.5 | M36: =(E36*F36*L36)+(G36*E36)+((H36+I36+J36)*E36) -> 0
C37: Emergency Management | E37: ='CLIN 0005 (OY4)'!E37/2 -> 375 | F37: 0 | G37: 0 | H37: 0 | I37: 0 | J37: 0 | K37: =(F37+G37+H37) -> 0 | L37: 3.5 | M37: =(E37*F37*L37)+(G37*E37)+((H37+I37+J37)*E37) -> 0
C38: FY28 (Communications/ Electronic Warfare Technology) | E38: ='CLIN 0005 (OY4)'!E38/2 -> 750 | F38: 0 | G38: 0 | H38: 0 | I38: 0 | J38: 0 | K38: =(F38+G38+H38) -> 0 | L38: 3.5 | M38: =(E38*F38*L38)+(G38*E38)+((H38+I38+J38)*E38) -> 0
C39: Program Management | D39: 6001 | M39: 0
C40: IT/Data Support | D40: 6002 | M40: 0
A42: N0018925DZXX6 | B42: F | D42: 0006 | E42: =SUM(E43:E45) -> 1875 | M42: =SUM(M43:M47) -> 0
C43: Maritime Logistics | E43: ='CLIN 0005 (OY4)'!E43/2 -> 812.5 | F43: 0 | G43: 0 | H43: 0 | I43: 0 | J43: 0 | K43: =(F43+G43+H43) -> 0 | L43: 3.5 | M43: =(E43*F43*L43)+(G43*E43)+((H43+I43+J43)*E43) -> 0
C44: FY27 (Industrial Maintenance/ AUS Technology) | E44: ='CLIN 0005 (OY4)'!E44/2 -> 625 | F44: 0 | G44: 0 | H44: 0 | I44: 0 | J44: 0 | K44: =(F44+G44+H44) -> 0 | L44: 3.5 | M44: =(E44*F44*L44)+(G44*E44)+((H44+I44+J44)*E44) -> 0
C45: [Insert Program] - FY28 | E45: ='CLIN 0005 (OY4)'!E45/2 -> 437.5 | F45: 0 | G45: 0 | H45: 0 | I45: 0 | J45: 0 | K45: =(F45+G45+H45) -> 0 | L45: 3.5 | M45: =(E45*F45*L45)+(G45*E45)+((H45+I45+J45)*E45) -> 0
...
