Workbook

Sheet Instructions
A3: Instructions
A4: 1. Only input data into the yellow cells of the Self Score Sheet tab.
A5: 2. Please insert Offeror's name on Row 4.
A6: 3. Offeror shall fill in Column D "Offeror Self-Score Points: Work performed by Prime" and Column E "Offeror Self-Score Points: Work performed by Teaming Subcontractor" for the first 5 Categories, 3.2.2.1-3.2.2.5.
A7: 4. Sum of Work Samples submitted for each Subcategory cannot break the max allowable points (Column F must be less than or equal to Column C for each subcategory).
A8: 5. An Offeror may account for a sum of 20 points across the first three Categories: 3.2.2.1 Mechanical Systems, 3.2.2.2 Electrical Systems, and 3.2.2.3 Facility Renovations. Please note that points are referencing the value placed by the Offeror in columns D&E, not the score calculated from those entries.
A9: 6. The total number of Work Samples submitted on behalf of a Teaming Subcontractor must be less than or equal to the number of Work Samples submitted for work performed by the Prime (Cell E31 must be less than or equal to Cell D31).
A10: 7. All Offerors are to fill in the Project Management, Development, and Design Category (3.2.2.4 and 3.2.2.5) based off the projects/work samples submitted for sections 3.2.2.1-3.2.2.3.
A11: 8. All Offerors are encouraged to fill out the CPARS/CPARS Equivalent Data Submission Category (3.2.2.6), columns A-I, based off the projects/work samples submitted from Categories 3.2.2.1-3.2.2.3.
A12: 9. Offerors are allotted a maximum of five CPARS/CPARS Equivalent submissions (3.2.2.6). It is up to the Offeror to determine best score feasible with the available five submissions. Note that the number of subcontractor CPAR submissions must be less than or equal to the number of CPARs submitted for the Prime.
A13: 10. Points allotted from CPARS/CPARS Equivalent data are considered a bonus score; each entry will produce a calculated percentage bonus based off of the specific Subcategory it is associated with and the Offeror's ratings.
A14: 11. If an Offeror is able to submit at least one CPARS/CPARS Equivalent response for each of the first three Categories (3.2.2.1 Mechanical Systems, 3.2.2.2 Electrical Systems, 3.2.2.3 Facility Renovations), then the Offeror will receive a double bonus, doubling the points received for all CPAR submissions.

Sheet Self Score Sheet
A1: FARM III
A2: FA9101-26-R-B011
A3: Draft Attachment L-4 HTRO Scoring Matrix
A4: OFFEROR NAME: [FILL IN OFFEROR NAME HERE]
A5: Section L Paragraph | B5: Category | C5: Maximum Self-Score Points | D5: Offeror Self-Score Points: Work performed by Prime (1-4, 1-5) | E5: Offeror Self-Score Points: Work performed by Teaming Subcontractor (1-4, 1-5) | F5: Offeror Proposed Total Self-Score Points | G5: Self-Score Point Multiplication Factor | H5: Offeror's Initial Unweighted Score | I5: Weight Factor | J5: Single Project Weighted Score | K5: Max Weighted Score | L5: Offeror's Weighted Score before Bonus
B6: Mechanical Systems
A7: 3.2.2.1 | B7: Number of Work Samples that include all labor, materials, equipment, transportation, supervision, and quality control to repair, repair by replace, or installation of the following systems:
A8: M1 | B8: Air Duct, expansion joints and control/process valves (≥ 36" Ø and 150psig) | C8: 4 | F8: =IF(SUM(D8:E8)>C8,"See Instructions", SUM(D8:E8)) -> 0 | G8: =1000/C8 -> 250 | H8: =F8*G8 -> 0 | I8: 4 | J8: =G8*I8 -> 1000 | K8: =I8*1000 -> 4000 | L8: =$H8*$I8 -> 0
A9: M2 | B9: High pressure duct/piping and valves (≥ 4" Ø, ≥ 4,000psig) | C9: 4 | F9: =IF(SUM(D9:E9)>C9,"See Instructions", SUM(D9:E9)) -> 0 | G9: =1000/C9 -> 250 | H9: =F9*G9 -> 0 | I9: 7 | J9: =G9*I9 -> 1750 | K9: =I9*1000 -> 7000 | L9: =$H9*$I9 -> 0
A10: M3 | B10: Large pressure vessels (≥ 2000psig; ≥ 10K gallons) | C10: 4 | F10: =IF(SUM(D10:E10)>C10,"See Instructions", SUM(D10:E10)) -> 0 | G10: =1000/C10 -> 250 | H10: =F10*G10 -> 0 | I10: 9 | J10: =G10*I10 -> 2250 | K10: =I10*1000 -> 9000 | L10: =$H10*$I10 -> 0
A11: M4 | B11: Desiccant bed air dryers (≤ 300psia and ≥ 200lb/s) | C11: 4 | F11: =IF(SUM(D11:E11)>C11,"See Instructions", SUM(D11:E11)) -> 0 | G11: =1000/C11 -> 250 | H11: =F11*G11 -> 0 | I11: 3 | J11: =G11*I11 -> 750 | K11: =I11*1000 -> 3000 | L11: =$H11*$I11 -> 0
A12: M5 | B12: Turning vanes for large air ducting (≥ 30ft Ø, 0.5-160psia) | C12: 4 | F12: =IF(SUM(D12:E12)>C12,"See Instructions", SUM(D12:E12)) -> 0 | G12: =1000/C12 -> 250 | H12: =F12*G12 -> 0 | I12: 5 | J12: =G12*I12 -> 1250 | K12: =I12*1000 -> 5000 | L12: =$H12*$I12 -> 0
A13: M6 | B13: Cooling water/raw water pumps (10,000-50,000gpm) | C13: 4 | F13: =IF(SUM(D13:E13)>C13,"See Instructions", SUM(D13:E13)) -> 0 | G13: =1000/C13 -> 250 | H13: =F13*G13 -> 0 | I13: 8 | J13: =G13*I13 -> 2000 | K13: =I13*1000 -> 8000 | L13: =$H13*$I13 -> 0
A14: M7 | B14: Cooling water/raw water filters/strainers, valves (control/process) and distribution lines (≥ 36” Ø) | C14: 4 | F14: =IF(SUM(D14:E14)>C14,"See Instructions", SUM(D14:E14)) -> 0 | G14: =1000/C14 -> 250 | H14: =F14*G14 -> 0 | I14: 7 | J14: =G14*I14 -> 1750 | K14: =I14*1000 -> 7000 | L14: =$H14*$I14 -> 0
A15: M8 | B15: Hydraulic Systems with high flow and pressure requirements (≥ 100gpm, ≥2000psig) | C15: 4 | F15: =IF(SUM(D15:E15)>C15,"See Instructions", SUM(D15:E15)) -> 0 | G15: =1000/C15 -> 250 | H15: =F15*G15 -> 0 | I15: 4 | J15: =G15*I15 -> 1000 | K15: =I15*1000 -> 4000 | L15: =$H15*$I15 -> 0
A16: M9 | B16: Large Steam Boilers (≥50kpph) | C16: 4 | F16: =IF(SUM(D16:E16)>C16,"See Instructions", SUM(D16:E16)) -> 0 | G16: =1000/C16 -> 250 | H16: =F16*G16 -> 0 | I16: 5 | J16: =G16*I16 -> 1250 | K16: =I16*1000 -> 5000 | L16: =$H16*$I16 -> 0
A17: M10 | B17: Chillers and Refrigeration equipment, project sum (≥1,000 refrigeration tons) | C17: 4 | F17: =IF(SUM(D17:E17)>C17,"See Instructions", SUM(D17:E17)) -> 0 | G17: =1000/C17 -> 250 | H17: =F17*G17 -> 0 | I17: 6 | J17: =G17*I17 -> 1500 | K17: =I17*1000 -> 6000 | L17: =$H17*$I17 -> 0
B18: Electrical Systems
A19: 3.2.2.2 | B19: Number of Work Samples that include all labor, materials, equipment, transportation, supervision, and quality control to repair, repair by replace, or installation of the following systems:
A20: E1 | B20: Medium Voltage gas insulated switchgear (≥ 1kV and ≤ 35kV) | C20: 4 | F20: =IF(SUM(D20:E20)>C20,"See Instructions", SUM(D20:E20)) -> 0 | G20: =1000/C20 -> 250 | H20: =F20*G20 -> 0 | I20: 6 | J20: =G20*I20 -> 1500 | K20: =I20*1000 -> 6000 | L20: =$H20*$I20 -> 0
A21: E2 | B21: Medium Voltage unit substations (≥ 1kV and ≤ 35kV) | C21: 4 | F21: =IF(SUM(D21:E21)>C21,"See Instructions", SUM(D21:E21)) -> 0 | G21: =1000/C21 -> 250 | H21: =F21*G21 -> 0 | I21: 6 | J21: =G21*I21 -> 1500 | K21: =I21*1000 -> 6000 | L21: =$H21*$I21 -> 0
A22: E3 | B22: Medium Voltage ducting/vaults/cables (≥ 1kV and ≤ 35kV), more than 500 linear feet | C22: 4 | F22: =IF(SUM(D22:E22)>C22,"See Instructions", SUM(D22:E22)) -> 0 | G22: =1000/C22 -> 250 | H22: =F22*G22 -> 0 | I22: 6 | J22: =G22*I22 -> 1500 | K22: =I22*1000 -> 6000 | L22: =$H22*$I22 -> 0
A23: E4 | B23: High Voltage ducting/vaults/cables (>35kV), more than 500 linear feet | C23: 4 | F23: =IF(SUM(D23:E23)>C23,"See Instructions", SUM(D23:E23)) -> 0 | G23: 250 | H23: =F23*G23 -> 0 | I23: 8 | J23: =G23*I23 -> 2000 | K23: =I23*1000 -> 8000 | L23: =$H23*$I23 -> 0
A24: E5 | B24: High Voltage transformers (> 35kV) | C24: 4 | F24: =IF(SUM(D24:E24)>C24,"See Instructions", SUM(D24:E24)) -> 0 | G24: =1000/C24 -> 250 | H24: =F24*G24 -> 0 | I24: 8 | J24: =G24*I24 -> 2000 | K24: =I24*1000 -> 8000 | L24: =$H24*$I24 -> 0
A25: E6 | B25: Oil or gas circuit breakers (≥ 1000 amp and ≥ 500kV) | C25: 4 | F25: =IF(SUM(D25:E25)>C25,"See Instructions", SUM(D25:E25)) -> 0 | G25: =1000/C25 -> 250 | H25: =F25*G25 -> 0 | I25: 8 | J25: =G25*I25 -> 2000 | K25: =I25*1000 -> 8000 | L25: =$H25*$I25 -> 0
A26: E7 | B26: Variable frequency drives for motors (≥ 1000V) | C26: 4 | F26: =IF(SUM(D26:E26)>C26,"See Instructions", SUM(D26:E26)) -> 0 | G26: =1000/C26 -> 250 | H26: =F26*G26 -> 0 | I26: 5 | J26: =G26*I26 -> 1250 | K26: =I26*1000 -> 5000 | L26: =$H26*$I26 -> 0
A27: E8 | B27: Facility Wide Lightning Protection Systems (Facility ≥ 5,000SF) | C27: 4 | F27: =IF(SUM(D27:E27)>C27,"See Instructions", SUM(D27:E27)) -> 0 | G27: =1000/C27 -> 250 | H27: =F27*G27 -> 0 | I27: 4 | J27: =G27*I27 -> 1000 | K27: =I27*1000 -> 4000 | L27: =$H27*$I27 -> 0
B28: Facility Renovations
A29: 3.2.2.3 | B29: Number of Work Samples that include all labor, materials, equipment, transportation, supervision, and quality control to execute a construction service contract by repairing, repair by replacing, or installing at least 5 of 7 Elements listed below: -Facility HVAC will include at least 4 of the following items: chillers, Air Handler Units, ducting, boilers, refrigerant/refrigerant lines, condensers, and compressors -Facility Fire protection will include at least 3 of the following items: sprinkler systems, heat/smoke detectors, pull stations, fire alarm control panels, notification systems -Facility Electrical systems will include at least 4 of the following items: facility transformers, power panels, bus bars, circuit breakers/fuses, conduit/conductors, lights/wall plugs, and grounding systems -Facility Exterior components will include at least 2 of the following items: roofing systems, exterior cladding, windows/doors, and insulation -Facility Plumbing systems will include at least 2 of the following items: potable water piping/fittings, sewage piping/fittings, venting, and fixtures -Facility Communications Systems will include at least 2 of the following items: hardware replacement withing telecommunication rooms/closets, cabling within the facility, wireless network systems, public address systems, and uninterruptible power supplies (UPS) -Interior Finishes will include at least 3 of the following items: finished flooring, drywall (or other typical wall material) installation/repair, painting, wall paper/coverings, suspended ceiling systems, and systems furniture | C29: 5 | F29: =IF(SUM(D29:E29)>C29,"See Instructions", SUM(D29:E29)) -> 0 | G29: =1250/C29 -> 250 | H29: =F29*G29 -> 0 | I29: 7 | J29: =G29*I29 -> 1750 | K29: =I29*1250 -> 8750 | L29: =$H29*$I29 -> 0
B31: Total Sum of Self-Score Points Selected for Mechanical Systems, Electrical Systems, and Facility Renovation cannot be greater than 20. Total Sum of Teaming Subcontractor Points (Cell E31) cannot be greater than Total Sum of the Prime's Points (Cell D31). | C31: Total Self-Score Points | D31: =SUM(D8:D17,D20:D27,D29) -> 0 | E31: =SUM(E8:E17,E20:E27,E29) -> 0 | F31: =SUM(F8:F17,F20:F27,F29) -> 0
B33: Project Management, Development, and Design | D33: Acceptable Input (1-60/1-20)
A34: 3.2.2.4 | B34: Total dollar value of construction services projects supporting DoD Installations. | C34: 60 | F34: =IF(SUM(D34:E34)>C34,"See Instructions", SUM(D34:E34)) -> 0 | G34: =1000/C34 -> 16.666667 | H34: =F34*G34 -> 0 | I34: 3 | J34: =G34*I34 -> 50 | K34: =I34*1000 -> 3000 | L34: =$H34*$I34 -> 0
A35: 3.2.2.5 | B35: Total number of design and construction services on a single contract/TO. | C35: 20 | F35: =IF(SUM(D35:E35)>C35,"See Instructions", SUM(D35:E35)) -> 0 | G35: =1000/C35 -> 50 | H35: =F35*G35 -> 0 | I35: 3 | J35: =G35*I35 -> 150 | K35: =I35*1000 -> 3000 | L35: =$H35*$I35 -> 0
B38: Offeror is only to input data into the yellow cells.
B40: Offeror's Weighted Score Before CPARS Bonus (Column J Sum) | D40: =IF(F31>20,"Contractor has provided too many work samples.", IF(E31>D31, "Contractor has submitted more Work Samples for Teaming Subcontractors than allowable.", SUM(L8:L17,L20:L27,L29,L34:L35))) -> 0
B41: Offeror's Bonus Score based off CPARS Data (CPARS Sections Below) | D41: =IF(OR($F$31>20, $E$31>$D$31), "Error, see note in Cell D31", SUM(J55,J66,J77,J88,J99)) -> 0
B42: Did Offeror Receive "CPAR For All Categories" Bonus, Points Awarded | C42: =_xlfn.IFNA(IF(AND(MATCH("M",Sheet1!G2:G6,0),MATCH("E",Sheet1!G2:G6,0),MATCH("3",Sheet1!G2:G6,0)),"Yes","No"),"No") -> No | D42: =IF(OR($F$31>20, $E$31>$D$31), "Error, see note in Cell D31", IF(C42="Yes", D41, )) -> 0
B43: Offeror's Final Self Score | D43: =IF(OR($F$31>20, $E$31>$D$31), "Error, see note in Cell D31", SUM(D40:D42)) -> 0
B44: Government-Validated Score
A46: 3.2.2.6 | B46: CPARS/CPARS Equivalent Data Submission
...

Sheet Sheet1
A1: CPAR Ratings | B1: Associated Score | D1: Subsections | F1: CPARS Criteria Selected | I1: CPARS Potential Criteria | L1: Check
A2: Exceptional | B2: 50 | D2: M1 | F2: ='Self Score Sheet'!C54 -> 0 | G2: =LEFT(F2,1) -> 0 | I2: M1 | J2: ='Self Score Sheet'!F8 -> 0 | K2: =COUNTIF($F$2:$F$6,I2) -> 0 | L2: =J2-K2 -> 0
A3: Very Good | B3: 40 | D3: M2 | F3: ='Self Score Sheet'!C65 -> 0 | G3: =LEFT(F3,1) -> 0 | I3: M2 | J3: ='Self Score Sheet'!F9 -> 0 | K3: =COUNTIF($F$2:$F$6,I3) -> 0 | L3: =J3-K3 -> 0
A4: Satisfactory | B4: 20 | D4: M3 | F4: ='Self Score Sheet'!C76 -> 0 | G4: =LEFT(F4,1) -> 0 | I4: M3 | J4: ='Self Score Sheet'!F10 -> 0 | K4: =COUNTIF($F$2:$F$6,I4) -> 0 | L4: =J4-K4 -> 0
A5: Marginal | B5: 0 | D5: M4 | F5: ='Self Score Sheet'!C87 -> 0 | G5: =LEFT(F5,1) -> 0 | I5: M4 | J5: ='Self Score Sheet'!F11 -> 0 | K5: =COUNTIF($F$2:$F$6,I5) -> 0 | L5: =J5-K5 -> 0
A6: Unsatisfactory | B6: -5 | D6: M5 | F6: ='Self Score Sheet'!C98 -> 0 | G6: =LEFT(F6,1) -> 0 | I6: M5 | J6: ='Self Score Sheet'!F12 -> 0 | K6: =COUNTIF($F$2:$F$6,I6) -> 0 | L6: =J6-K6 -> 0
A7: N/A | B7: 0 | D7: M6 | I7: M6 | J7: ='Self Score Sheet'!F13 -> 0 | K7: =COUNTIF($F$2:$F$6,I7) -> 0 | L7: =J7-K7 -> 0
A8: "" | B8: 0 | D8: M7 | I8: M7 | J8: ='Self Score Sheet'!F14 -> 0 | K8: =COUNTIF($F$2:$F$6,I8) -> 0 | L8: =J8-K8 -> 0
D9: M8 | I9: M8 | J9: ='Self Score Sheet'!F15 -> 0 | K9: =COUNTIF($F$2:$F$6,I9) -> 0 | L9: =J9-K9 -> 0
D10: M9 | I10: M9 | J10: ='Self Score Sheet'!F16 -> 0 | K10: =COUNTIF($F$2:$F$6,I10) -> 0 | L10: =J10-K10 -> 0
D11: M10 | I11: M10 | J11: ='Self Score Sheet'!F17 -> 0 | K11: =COUNTIF($F$2:$F$6,I11) -> 0 | L11: =J11-K11 -> 0
D12: E1 | I12: E1 | J12: ='Self Score Sheet'!F20 -> 0 | K12: =COUNTIF($F$2:$F$6,I12) -> 0 | L12: =J12-K12 -> 0
D13: E2 | I13: E2 | J13: ='Self Score Sheet'!F21 -> 0 | K13: =COUNTIF($F$2:$F$6,I13) -> 0 | L13: =J13-K13 -> 0
D14: E3 | I14: E3 | J14: ='Self Score Sheet'!F22 -> 0 | K14: =COUNTIF($F$2:$F$6,I14) -> 0 | L14: =J14-K14 -> 0
D15: E4 | I15: E4 | J15: ='Self Score Sheet'!F23 -> 0 | K15: =COUNTIF($F$2:$F$6,I15) -> 0 | L15: =J15-K15 -> 0
D16: E5 | I16: E5 | J16: ='Self Score Sheet'!F24 -> 0 | K16: =COUNTIF($F$2:$F$6,I16) -> 0 | L16: =J16-K16 -> 0
D17: E6 | I17: E6 | J17: ='Self Score Sheet'!F25 -> 0 | K17: =COUNTIF($F$2:$F$6,I17) -> 0 | L17: =J17-K17 -> 0
D18: E7 | I18: E7 | J18: ='Self Score Sheet'!F26 -> 0 | K18: =COUNTIF($F$2:$F$6,I18) -> 0 | L18: =J18-K18 -> 0
D19: E8 | I19: E8 | J19: ='Self Score Sheet'!F27 -> 0 | K19: =COUNTIF($F$2:$F$6,I19) -> 0 | L19: =J19-K19 -> 0
D20: 3.2.2.3 | I20: 3.2.2.3 | J20: ='Self Score Sheet'!F29 -> 0 | K20: =COUNTIF($F$2:$F$6,I20) -> 0 | L20: =J20-K20 -> 0
