Workbook
Name _Hlk8638798: SUMMARY!#REF!

Sheet SUMMARY
A1: Vendor Pricing: DOTS VIPR Procurement (IDIQ)
A4: Vendor:
A5: Title: | B5: Disaster Overseas Transportation Support (DOTS) - Virgin Islands/Puerto Rico (VIPR)
A6: FEMA Component: | B6: Logistics Management Directorate
A7: Contract Type: | B7: IDIQ - Firm Fixed Unit Prices
A8: Date Submitted:
A9: PoP: | B9: 2026 - 2029
A10: Total Contract Value: | B10: =D18 -> 0
A14: Contract Year | B14: Period of Performance | C14: CLIN (s) | D14: Total Cost
A15: Base | B15: 7/1/2026 - 6/30/2027 | C15: 0001 - 0036 | D15: =Base!G173 -> 0
A16: Option Year 1 | B16: 7/1/2027 - 6/30/2028 | C16: 1001 - 1035 | D16: ='OY1'!G173 -> 0
A17: Option Year 2 | B17: 7/1/2028 - 6/30/2029 | C17: 2001 - 2035 | D17: ='OY2'!G173 -> 0
A18: Total | D18: =SUM(D15:D17) -> 0

Sheet Base
A1: CLIN | B1: Description | C1: Quantities | D1: Unit | E1: Unit Price | F1: Days | G1: Total Price | H1: PWS REF
A2: Inclusive of container handling (CHE)/material handling (MHE) equipment usage, fees, taxes, diversions.
A3: GROUND TRANSPORTATION:
A4: 0001 | B4: Surface line haul/Drayage services of containerized commodities from Origin to Port of Embarkation. | H4: 2.2-2.2.1
A5: 0001AA | B5: Ground Transportation: Point of Origin to Port of Embarkation (Mid Atlantic Region) | C5: 250 | D5: EA Container/Trailer | F5: N/A | G5: =IF(ISNUMBER(E5),C5*E5,0) -> 0
A6: 0001AB | B6: Ground Transportation: Point of Origin to Port of Embarkation (South Atlantic Region) | C6: 500 | D6: EA Container/Trailer | F6: N/A | G6: =IF(ISNUMBER(E6),C6*E6,0) -> 0
A7: 0001AC | B7: Ground Transportation: Point of Origin to Port of Embarkation (Gulf Coast) | C7: 200 | D7: EA Container/Trailer | F7: N/A | G7: =IF(ISNUMBER(E7),C7*E7,0) -> 0
A8: 0001AD | B8: Ground Transportation: Point of Origin to Port of Embarkation (FEMA Distribution Center Caribbean, San Juan PR) | C8: 500 | D8: EA Container/Trailer | F8: N/A | G8: =IF(ISNUMBER(E8),C8*E8,0) -> 0
A9: 0002 | B9: Surface line haul services of containerized commodities from Port of Debarkation to FEMA designated Point of Need. | H9: 2.2.4-2.2.5
A10: 0002AA | B10: Ground Transportation: Destination - USVI locations | C10: 1000 | D10: EA Container/Trailer | F10: N/A | G10: =IF(ISNUMBER(E10),C10*E10,0) -> 0
A11: 0002AB | B11: Ground Transportation: Destination - Puerto Rico locations | C11: 2500 | D11: EA Container/Trailer | F11: N/A | G11: =IF(ISNUMBER(E11),C11*E11,0) -> 0
A12: 0003 | B12: Shuttle service of resources Intra-Island (containers/dry van trailers/box trucks/flat beds) | H12: 2.2.4-2.2.5
A13: 0003AA | B13: Ground Transportation: USVI locations | C13: 1000 | D13: EA Container/Trailer | F13: N/A | G13: =IF(ISNUMBER(E13),C13*E13,0) -> 0
A14: 0003AB | B14: Ground Transportation: Puerto Rico locations | C14: 2500 | D14: EA Container/Trailer | F14: N/A | G14: =IF(ISNUMBER(E14),C14*E14,0) -> 0
A15: 0004 | B15: Surface line haul services of containerized retrograde commodities from FEMA designated Point of Need to Port of embarkation. | H15: 2.2-2.2.6
A16: 0004AA | B16: Ground Transportation: Port of Embarkation - USVI | C16: 1000 | D16: EA Container/Trailer | F16: N/A | G16: =IF(ISNUMBER(E16),C16*E16,0) -> 0
A17: 0004AB | B17: Ground Transportation: Port of Embarkation - Puerto Rico | C17: 2500 | D17: EA Container/Trailer | F17: N/A | G17: =IF(ISNUMBER(E17),C17*E17,0) -> 0
A18: 0005 | B18: Surface line haul/Drayage services of Breakbulk Cargo. (Per Chassis) | H18: 2.2-2.2.1
A19: 0005AA | B19: Ground Transportation: Point of Origin to Port of Embarkation (Mid Atlantic Region) | C19: 100 | D19: EA Container/Trailer | F19: N/A | G19: =IF(ISNUMBER(E19),C19*E19,0) -> 0
A20: 0005AB | B20: Ground Transportation: Point of Origin to Port of Embarkation (South Atlantic Region) | C20: 100 | D20: EA Container/Trailer | F20: N/A | G20: =IF(ISNUMBER(E20),C20*E20,0) -> 0
A21: 0005AC | B21: Ground Transportation: Point of Origin to Port of Embarkation (Gulf Coast) | C21: 100 | D21: EA Container/Trailer | F21: N/A | G21: =IF(ISNUMBER(E21),C21*E21,0) -> 0
A22: 0005AD | B22: Ground Transportation: Point of Origin to Port of Embarkation (FEMA Distribution Center Caribbean, San Juan PR) | C22: 100 | D22: EA Container/Trailer | F22: N/A | G22: =IF(ISNUMBER(E22),C22*E22,0) -> 0
A23: 0006 | B23: Surface line haul services of Breakbulk Cargo. (Per Chassis) | H23: 2.2.4-2.2.5
A24: 0006AA | B24: Ground Transportation: Destination - USVI locations | C24: 10 | D24: EA Container/Trailer | F24: N/A | G24: =IF(ISNUMBER(E24),C24*E24,0) -> 0
A25: 0006AB | B25: Ground Transportation: Destination - Puerto Rico locations | C25: 10 | D25: EA Container/Trailer | F25: N/A | G25: =IF(ISNUMBER(E25),C25*E25,0) -> 0
A26: 0007 | B26: Surface line haul services of retrograde Breakbulk Cargo from FEMA designated Point of Need to port of embarkation. (Per Chassis) | H26: 2.2-2.2.6
A27: 0007AA | B27: Ground Transportation: Port of Embarkation - USVI | C27: 10 | D27: EA Container/Trailer | F27: N/A | G27: =IF(ISNUMBER(E27),C27*E27,0) -> 0
A28: 0007AB | B28: Ground Transportation: Port of Embarkation - Puerto Rico | C28: 10 | D28: EA Container/Trailer | F28: N/A | G28: =IF(ISNUMBER(E28),C28*E28,0) -> 0
G29: =SUM(G5:G28) -> 0
A30: OCEAN TRANSPORTATION
A31: 0008 | B31: Transport loaded containers, via ocean vessel from Port of Embarkation to assigned port in the USVI, FOB Destination. | H31: 2.2.2-2.2.6
A32: 0008AA | B32: Ocean Transportation: Mid Atlantic Region to assigned port in the USVI | C32: 250 | D32: EA Container/Trailer | F32: N/A | G32: =IF(ISNUMBER(E32),C32*E32,0) -> 0
A33: 0008AB | B33: Ocean Transportation: South Atlantic Region to assigned port in the USVI | C33: 1000 | D33: EA Container/Trailer | F33: N/A | G33: =IF(ISNUMBER(E33),C33*E33,0) -> 0
A34: 0008AC | B34: Ocean Transportation: Gulf Coast to assigned port in the USVI | C34: 200 | D34: EA Container/Trailer | F34: N/A | G34: =IF(ISNUMBER(E34),C34*E34,0) -> 0
A35: 0008AD | B35: Ocean Transportation: FEMA Distribution Center Caribbean, San Juan PR to assigned port in the USVI | C35: 50 | D35: EA Container/Trailer | F35: N/A | G35: =IF(ISNUMBER(E35),C35*E35,0) -> 0
A36: 0009 | B36: Transport loaded containers, via ocean vessel from Port of Embarkation to assigned port in Puerto Rico, FOB Destination. | H36: 2.2.2-2.2.6
A37: 0009AA | B37: Ocean Transportation: Mid Atlantic Region to assigned port in Puerto Rico | C37: 250 | D37: EA Container/Trailer | F37: N/A | G37: =IF(ISNUMBER(E37),C37*E37,0) -> 0
A38: 0009AB | B38: Ocean Transportation: South Atlantic Region to assigned port in Puerto Rico | C38: 1000 | D38: EA Container/Trailer | F38: N/A | G38: =IF(ISNUMBER(E38),C38*E38,0) -> 0
A39: 0009AC | B39: Ocean Transportation: Gulf Coast to assigned port in Puerto Rico | C39: 200 | D39: EA Container/Trailer | F39: N/A | G39: =IF(ISNUMBER(E39),C39*E39,0) -> 0
A40: 0009AD | B40: Ocean Transportation: FEMA Distribution Center Caribbean, San Juan PR to assigned port in Puerto Rico (i.e. Ponce, Vieques) | C40: 50 | D40: EA Container/Trailer | F40: N/A | G40: =IF(ISNUMBER(E40),C40*E40,0) -> 0
...

Sheet OY1
A1: CLIN | B1: Description | C1: Quantities | D1: Unit | E1: Unit Price | F1: Days | G1: Total Price | H1: PWS REF
A2: Inclusive of container handling (CHE)/material handling (MHE) equipment usage, fees, taxes, diversions.
A3: GROUND TRANSPORTATION:
A4: 1001 | B4: Surface line haul/Drayage services of containerized commodities from Origin to Port of Embarkation. | H4: 2.2-2.2.1
A5: 1001AA | B5: Ground Transportation: Point of Origin to Port of Embarkation (Mid Atlantic Region) | C5: 250 | D5: EA Container/Trailer | F5: N/A | G5: =IF(ISNUMBER(E5),C5*E5,0) -> 0
A6: 1001AB | B6: Ground Transportation: Point of Origin to Port of Embarkation (South Atlantic Region) | C6: 500 | D6: EA Container/Trailer | F6: N/A | G6: =IF(ISNUMBER(E6),C6*E6,0) -> 0
A7: 1001AC | B7: Ground Transportation: Point of Origin to Port of Embarkation (Gulf Coast) | C7: 200 | D7: EA Container/Trailer | F7: N/A | G7: =IF(ISNUMBER(E7),C7*E7,0) -> 0
A8: 1001AD | B8: Ground Transportation: Point of Origin to Port of Embarkation (FEMA Distribution Center Caribbean, San Juan PR) | C8: 500 | D8: EA Container/Trailer | F8: N/A | G8: =IF(ISNUMBER(E8),C8*E8,0) -> 0
A9: 1002 | B9: Surface line haul services of containerized commodities from Port of Debarkation to FEMA designated Point of Need. | H9: 2.2.4-2.2.5
A10: 1002AA | B10: Ground Transportation: Destination - USVI locations | C10: 1000 | D10: EA Container/Trailer | F10: N/A | G10: =IF(ISNUMBER(E10),C10*E10,0) -> 0
A11: 1002AB | B11: Ground Transportation: Destination - Puerto Rico locations | C11: 2500 | D11: EA Container/Trailer | F11: N/A | G11: =IF(ISNUMBER(E11),C11*E11,0) -> 0
A12: 1003 | B12: Shuttle service of resources Intra-Island (containers/dry van trailers/box trucks/flat beds) | H12: 2.2.4-2.2.5
A13: 1003AA | B13: Ground Transportation: USVI locations | C13: 1000 | D13: EA Container/Trailer | F13: N/A | G13: =IF(ISNUMBER(E13),C13*E13,0) -> 0
A14: 1003AB | B14: Ground Transportation: Puerto Rico locations | C14: 2500 | D14: EA Container/Trailer | F14: N/A | G14: =IF(ISNUMBER(E14),C14*E14,0) -> 0
A15: 1004 | B15: Surface line haul services of containerized retrograde commodities from FEMA designated Point of Need to Port of embarkation. | H15: 2.2-2.2.6
A16: 1004AA | B16: Ground Transportation: Port of Embarkation - USVI | C16: 1000 | D16: EA Container/Trailer | F16: N/A | G16: =IF(ISNUMBER(E16),C16*E16,0) -> 0
A17: 1004AB | B17: Ground Transportation: Port of Embarkation - Puerto Rico | C17: 2500 | D17: EA Container/Trailer | F17: N/A | G17: =IF(ISNUMBER(E17),C17*E17,0) -> 0
A18: 1005 | B18: Surface line haul/Drayage services of Breakbulk Cargo. (Per Chassis) | H18: 2.2-2.2.1
A19: 1005AA | B19: Ground Transportation: Point of Origin to Port of Embarkation (Mid Atlantic Region) | C19: 100 | D19: EA Container/Trailer | F19: N/A | G19: =IF(ISNUMBER(E19),C19*E19,0) -> 0
A20: 1005AB | B20: Ground Transportation: Point of Origin to Port of Embarkation (South Atlantic Region) | C20: 100 | D20: EA Container/Trailer | F20: N/A | G20: =IF(ISNUMBER(E20),C20*E20,0) -> 0
A21: 1005AC | B21: Ground Transportation: Point of Origin to Port of Embarkation (Gulf Coast) | C21: 100 | D21: EA Container/Trailer | F21: N/A | G21: =IF(ISNUMBER(E21),C21*E21,0) -> 0
A22: 1005AD | B22: Ground Transportation: Point of Origin to Port of Embarkation (FEMA Distribution Center Caribbean, San Juan PR) | C22: 100 | D22: EA Container/Trailer | F22: N/A | G22: =IF(ISNUMBER(E22),C22*E22,0) -> 0
A23: 1006 | B23: Surface line haul services of Breakbulk Cargo. (Per Chassis) | H23: 2.2.4-2.2.5
A24: 1006AA | B24: Ground Transportation: Destination - USVI locations | C24: 10 | D24: EA Container/Trailer | F24: N/A | G24: =IF(ISNUMBER(E24),C24*E24,0) -> 0
A25: 1006AB | B25: Ground Transportation: Destination - Puerto Rico locations | C25: 10 | D25: EA Container/Trailer | F25: N/A | G25: =IF(ISNUMBER(E25),C25*E25,0) -> 0
A26: 1007 | B26: Surface line haul services of retrograde Breakbulk Cargo from FEMA designated Point of Need to port of embarkation. (Per Chassis) | H26: 2.2-2.2.6
A27: 1007AA | B27: Ground Transportation: Port of Embarkation - USVI | C27: 10 | D27: EA Container/Trailer | F27: N/A | G27: =IF(ISNUMBER(E27),C27*E27,0) -> 0
A28: 1007AB | B28: Ground Transportation: Port of Embarkation - Puerto Rico | C28: 10 | D28: EA Container/Trailer | F28: N/A | G28: =IF(ISNUMBER(E28),C28*E28,0) -> 0
G29: =SUM(G5:G28) -> 0
A30: OCEAN TRANSPORTATION
A31: 1008 | B31: Transport loaded containers, via ocean vessel from Port of Embarkation to assigned port in the USVI, FOB Destination. | H31: 2.2.2-2.2.6
A32: 1008AA | B32: Ocean Transportation: Mid Atlantic Region to assigned port in the USVI | C32: 250 | D32: EA Container/Trailer | F32: N/A | G32: =IF(ISNUMBER(E32),C32*E32,0) -> 0
A33: 1008AB | B33: Ocean Transportation: South Atlantic Region to assigned port in the USVI | C33: 1000 | D33: EA Container/Trailer | F33: N/A | G33: =IF(ISNUMBER(E33),C33*E33,0) -> 0
A34: 1008AC | B34: Ocean Transportation: Gulf Coast to assigned port in the USVI | C34: 200 | D34: EA Container/Trailer | F34: N/A | G34: =IF(ISNUMBER(E34),C34*E34,0) -> 0
A35: 1008AD | B35: Ocean Transportation: FEMA Distribution Center Caribbean, San Juan PR to assigned port in the USVI | C35: 50 | D35: EA Container/Trailer | F35: N/A | G35: =IF(ISNUMBER(E35),C35*E35,0) -> 0
A36: 1009 | B36: Transport loaded containers, via ocean vessel from Port of Embarkation to assigned port in Puerto Rico, FOB Destination. | H36: 2.2.2-2.2.6
A37: 1009AA | B37: Ocean Transportation: Mid Atlantic Region to assigned port in Puerto Rico | C37: 250 | D37: EA Container/Trailer | F37: N/A | G37: =IF(ISNUMBER(E37),C37*E37,0) -> 0
A38: 1009AB | B38: Ocean Transportation: South Atlantic Region to assigned port in Puerto Rico | C38: 1000 | D38: EA Container/Trailer | F38: N/A | G38: =IF(ISNUMBER(E38),C38*E38,0) -> 0
A39: 1009AC | B39: Ocean Transportation: Gulf Coast to assigned port in Puerto Rico | C39: 200 | D39: EA Container/Trailer | F39: N/A | G39: =IF(ISNUMBER(E39),C39*E39,0) -> 0
A40: 1009AD | B40: Ocean Transportation: FEMA Distribution Center Caribbean, San Juan PR to assigned port in Puerto Rico (i.e. Ponce, Vieques) | C40: 50 | D40: EA Container/Trailer | F40: N/A | G40: =IF(ISNUMBER(E40),C40*E40,0) -> 0
...

Sheet OY2
A1: CLIN | B1: Description | C1: Quantities | D1: Unit | E1: Unit Price | F1: Days | G1: Total Price | H1: PWS REF
A2: Inclusive of container handling (CHE)/material handling (MHE) equipment usage, fees, taxes, diversions.
A3: GROUND TRANSPORTATION:
A4: 2001 | B4: Surface line haul/Drayage services of containerized commodities from Origin to Port of Embarkation. | H4: 2.2-2.2.1
A5: 2001AA | B5: Ground Transportation: Point of Origin to Port of Embarkation (Mid Atlantic Region) | C5: 250 | D5: EA Container/Trailer | F5: N/A | G5: =IF(ISNUMBER(E5),C5*E5,0) -> 0
A6: 2001AB | B6: Ground Transportation: Point of Origin to Port of Embarkation (South Atlantic Region) | C6: 500 | D6: EA Container/Trailer | F6: N/A | G6: =IF(ISNUMBER(E6),C6*E6,0) -> 0
A7: 2001AC | B7: Ground Transportation: Point of Origin to Port of Embarkation (Gulf Coast) | C7: 200 | D7: EA Container/Trailer | F7: N/A | G7: =IF(ISNUMBER(E7),C7*E7,0) -> 0
A8: 2001AD | B8: Ground Transportation: Point of Origin to Port of Embarkation (FEMA Distribution Center Caribbean, San Juan PR) | C8: 500 | D8: EA Container/Trailer | F8: N/A | G8: =IF(ISNUMBER(E8),C8*E8,0) -> 0
A9: 2002 | B9: Surface line haul services of containerized commodities from Port of Debarkation to FEMA designated Point of Need. | H9: 2.2.4-2.2.5
A10: 2002AA | B10: Ground Transportation: Destination - USVI locations | C10: 1000 | D10: EA Container/Trailer | F10: N/A | G10: =IF(ISNUMBER(E10),C10*E10,0) -> 0
A11: 2002AB | B11: Ground Transportation: Destination - Puerto Rico locations | C11: 2500 | D11: EA Container/Trailer | F11: N/A | G11: =IF(ISNUMBER(E11),C11*E11,0) -> 0
A12: 2003 | B12: Shuttle service of resources Intra-Island (containers/dry van trailers/box trucks/flat beds) | H12: 2.2.4-2.2.5
A13: 2003AA | B13: Ground Transportation: USVI locations | C13: 1000 | D13: EA Container/Trailer | F13: N/A | G13: =IF(ISNUMBER(E13),C13*E13,0) -> 0
A14: 2003AB | B14: Ground Transportation: Puerto Rico locations | C14: 2500 | D14: EA Container/Trailer | F14: N/A | G14: =IF(ISNUMBER(E14),C14*E14,0) -> 0
A15: 2004 | B15: Surface line haul services of containerized retrograde commodities from FEMA designated Point of Need to Port of embarkation. | H15: 2.2-2.2.6
A16: 2004AA | B16: Ground Transportation: Port of Embarkation - USVI | C16: 1000 | D16: EA Container/Trailer | F16: N/A | G16: =IF(ISNUMBER(E16),C16*E16,0) -> 0
A17: 2004AB | B17: Ground Transportation: Port of Embarkation - Puerto Rico | C17: 2500 | D17: EA Container/Trailer | F17: N/A | G17: =IF(ISNUMBER(E17),C17*E17,0) -> 0
A18: 2005 | B18: Surface line haul/Drayage services of Breakbulk Cargo. (Per Chassis) | H18: 2.2-2.2.1
A19: 2005AA | B19: Ground Transportation: Point of Origin to Port of Embarkation (Mid Atlantic Region) | C19: 100 | D19: EA Container/Trailer | F19: N/A | G19: =IF(ISNUMBER(E19),C19*E19,0) -> 0
A20: 2005AB | B20: Ground Transportation: Point of Origin to Port of Embarkation (South Atlantic Region) | C20: 100 | D20: EA Container/Trailer | F20: N/A | G20: =IF(ISNUMBER(E20),C20*E20,0) -> 0
A21: 2005AC | B21: Ground Transportation: Point of Origin to Port of Embarkation (Gulf Coast) | C21: 100 | D21: EA Container/Trailer | F21: N/A | G21: =IF(ISNUMBER(E21),C21*E21,0) -> 0
A22: 2005AD | B22: Ground Transportation: Point of Origin to Port of Embarkation (FEMA Distribution Center Caribbean, San Juan PR) | C22: 100 | D22: EA Container/Trailer | F22: N/A | G22: =IF(ISNUMBER(E22),C22*E22,0) -> 0
A23: 2006 | B23: Surface line haul services of Breakbulk Cargo. (Per Chassis) | H23: 2.2.4-2.2.5
A24: 2006AA | B24: Ground Transportation: Destination - USVI locations | C24: 10 | D24: EA Container/Trailer | F24: N/A | G24: =IF(ISNUMBER(E24),C24*E24,0) -> 0
A25: 2006AB | B25: Ground Transportation: Destination - Puerto Rico locations | C25: 10 | D25: EA Container/Trailer | F25: N/A | G25: =IF(ISNUMBER(E25),C25*E25,0) -> 0
A26: 2007 | B26: Surface line haul services of retrograde Breakbulk Cargo from FEMA designated Point of Need to port of embarkation. (Per Chassis) | H26: 2.2-2.2.6
A27: 2007AA | B27: Ground Transportation: Port of Embarkation - USVI | C27: 10 | D27: EA Container/Trailer | F27: N/A | G27: =IF(ISNUMBER(E27),C27*E27,0) -> 0
A28: 2007AB | B28: Ground Transportation: Port of Embarkation - Puerto Rico | C28: 10 | D28: EA Container/Trailer | F28: N/A | G28: =IF(ISNUMBER(E28),C28*E28,0) -> 0
G29: =SUM(G5:G28) -> 0
A30: OCEAN TRANSPORTATION
A31: 2008 | B31: Transport loaded containers, via ocean vessel from Port of Embarkation to assigned port in the USVI, FOB Destination. | H31: 2.2.2-2.2.6
A32: 2008AA | B32: Ocean Transportation: Mid Atlantic Region to assigned port in the USVI | C32: 250 | D32: EA Container/Trailer | F32: N/A | G32: =IF(ISNUMBER(E32),C32*E32,0) -> 0
A33: 2008AB | B33: Ocean Transportation: South Atlantic Region to assigned port in the USVI | C33: 1000 | D33: EA Container/Trailer | F33: N/A | G33: =IF(ISNUMBER(E33),C33*E33,0) -> 0
A34: 2008AC | B34: Ocean Transportation: Gulf Coast to assigned port in the USVI | C34: 200 | D34: EA Container/Trailer | F34: N/A | G34: =IF(ISNUMBER(E34),C34*E34,0) -> 0
A35: 2008AD | B35: Ocean Transportation: FEMA Distribution Center Caribbean, San Juan PR to assigned port in the USVI | C35: 50 | D35: EA Container/Trailer | F35: N/A | G35: =IF(ISNUMBER(E35),C35*E35,0) -> 0
A36: 2009 | B36: Transport loaded containers, via ocean vessel from Port of Embarkation to assigned port in Puerto Rico, FOB Destination. | H36: 2.2.2-2.2.6
A37: 2009AA | B37: Ocean Transportation: Mid Atlantic Region to assigned port in Puerto Rico | C37: 250 | D37: EA Container/Trailer | F37: N/A | G37: =IF(ISNUMBER(E37),C37*E37,0) -> 0
A38: 2009AB | B38: Ocean Transportation: South Atlantic Region to assigned port in Puerto Rico | C38: 1000 | D38: EA Container/Trailer | F38: N/A | G38: =IF(ISNUMBER(E38),C38*E38,0) -> 0
A39: 2009AC | B39: Ocean Transportation: Gulf Coast to assigned port in Puerto Rico | C39: 200 | D39: EA Container/Trailer | F39: N/A | G39: =IF(ISNUMBER(E39),C39*E39,0) -> 0
A40: 2009AD | B40: Ocean Transportation: FEMA Distribution Center Caribbean, San Juan PR to assigned port in Puerto Rico (i.e. Ponce, Vieques) | C40: 50 | D40: EA Container/Trailer | F40: N/A | G40: =IF(ISNUMBER(E40),C40*E40,0) -> 0
...

Sheet Opt YR 1
A1: RCTSD - Opt YR 1
A2: INSTRUCTIONS: Please note the quantites listed below are for evaluation purposes only. Quoters are not expected to have a minimum of the units used to evaluate. Unit Price will be fixed at time of award.
A3: CLIN | B3: Description | C3: Quantities | D3: Unit | E3: Unit Price | F3: Total Price
A4: 1001 | B4: Commodity Pre-Positioning. Task: Deliver Empty Shipping Containers to FEMA loading/discharging (receiving) locations. (Inclusive of container handling (CHE)/material handling (MHE) equipment) | C4: - | D4: - | E4: - | F4: -
A5: 1001AA | B5: Destination: Mid Atlantic Region | C5: =Base!C115 -> 250 | D5: EA | E5: =Base!E115*1.02 -> 0 | F5: =IF(ISNUMBER(E5),C5*E5,0) -> 0
A6: 1001AB | B6: Destination: South Atlantic Region | C6: =Base!C116 -> 500 | D6: EA | E6: =Base!E116*1.02 -> 0 | F6: =IF(ISNUMBER(E6),C6*E6,0) -> 0
A7: 1001AC | B7: Destination: Gulf Coast | C7: =Base!C117 -> 200 | D7: EA | E7: =Base!E117*1.02 -> 0 | F7: =IF(ISNUMBER(E7),C7*E7,0) -> 0
A8: 1001AD | B8: Destination: FEMA Distribution Center Caribbean, San Juan PR | C8: =Base!C118 -> 500 | D8: EA | E8: =Base!E118*1.02 -> 0 | F8: =IF(ISNUMBER(E8),C8*E8,0) -> 0
A9: 1002 | B9: Task: Surface line haul/Drayage services of containerized commodities from Origin to Port of Embarkation. (Inclusive of container handling (CHE)/material handling (MHE) equipment) | C9: =Base!C4 -> 0 | D9: - | E9: =Base!E4*1.02 -> 0
A10: 1002AA | B10: Ground Transportation: Point of Origin to Port of Embarkation (Mid Atlantic Region) | C10: =Base!C5 -> 250 | D10: EA | E10: =Base!E5*1.02 -> 0 | F10: =IF(ISNUMBER(E10),C10*E10,0) -> 0
A11: 1002AB | B11: Ground Transportation: Point of Origin to Port of Embarkation (South Atlantic Region) | C11: =Base!C6 -> 500 | D11: EA | E11: =Base!E6*1.02 -> 0 | F11: =IF(ISNUMBER(E11),C11*E11,0) -> 0
A12: 1002AC | B12: Ground Transportation: Point of Origin to Port of Embarkation (Gulf Coast) | C12: =Base!C7 -> 200 | D12: EA | E12: =Base!E7*1.02 -> 0 | F12: =IF(ISNUMBER(E12),C12*E12,0) -> 0
A13: 1002AD | B13: Ground Transportation: Point of Origin to Port of Embarkation (FEMA Distribution Center Caribbean, San Juan PR) | C13: =Base!C8 -> 500 | D13: EA | E13: =Base!E8*1.02 -> 0 | F13: =IF(ISNUMBER(E13),C13*E13,0) -> 0
A14: 1003 | B14: Task: Surface line haul/Drayage services of Breakbulk Cargo. (Per Chassis) (Inclusive of container handling (CHE)/material handling (MHE) equipment) | C14: =Base!C18 -> 0 | D14: - | E14: 0
A15: 1003AA | B15: Ground Transportation: Point of Origin to Port of Embarkation (Mid Atlantic Region) | C15: =Base!C19 -> 100 | D15: EA | E15: =Base!E19*1.02 -> 0 | F15: =IF(ISNUMBER(E15),C15*E15,0) -> 0
A16: 1003AB | B16: Ground Transportation: Point of Origin to Port of Embarkation (South Atlantic Region) | C16: =Base!C20 -> 100 | D16: EA | E16: =Base!E20*1.02 -> 0 | F16: =IF(ISNUMBER(E16),C16*E16,0) -> 0
A17: 1003AC | B17: Ground Transportation: Point of Origin to Port of Embarkation (Gulf Coast) | C17: =Base!C21 -> 100 | D17: EA | E17: =Base!E21*1.02 -> 0 | F17: =IF(ISNUMBER(E17),C17*E17,0) -> 0
A18: 1003AD | B18: Ground Transportation: Point of Origin to Port of Embarkation (FEMA Distribution Center Caribbean, San Juan PR) | C18: =Base!C22 -> 100 | D18: EA | E18: =Base!E22*1.02 -> 0 | F18: =IF(ISNUMBER(E18),C18*E18,0) -> 0
A19: 1004 | B19: Task: Transport loaded containers, via ocean vessel from Port of Embarkation to assigned port in the USVI, FOB Destination. (Inclusive of container handling (CHE)/material handling (MHE) equipment) | C19: =Base!C31 -> 0 | D19: - | E19: 0
A20: 1004AA | B20: Ocean Transportation: Mid Atlantic Region to assigned port in the USVI | C20: =Base!C32 -> 250 | D20: EA | E20: =Base!E32*1.02 -> 0 | F20: =IF(ISNUMBER(E20),C20*E20,0) -> 0
A21: 1004AB | B21: Ocean Transportation: South Atlantic Region to assigned port in the USVI | C21: =Base!C33 -> 1000 | D21: EA | E21: =Base!E33*1.02 -> 0 | F21: =IF(ISNUMBER(E21),C21*E21,0) -> 0
A22: 1004AC | B22: Ocean Transportation: Gulf Coast to assigned port in the USVI | C22: =Base!C34 -> 200 | D22: EA | E22: =Base!E34*1.02 -> 0 | F22: =IF(ISNUMBER(E22),C22*E22,0) -> 0
A23: 1004AD | B23: Ocean Transportation: FEMA Distribution Center Caribbean, San Juan PR to assigned port in the USVI | C23: =Base!C35 -> 50 | D23: EA | E23: =Base!E35*1.02 -> 0 | F23: =IF(ISNUMBER(E23),C23*E23,0) -> 0
A24: 1005 | B24: Task: Transport loaded containers, via ocean vessel from Port of Embarkation to assigned port in Puerto Rico, FOB Destination. (Inclusive of container handling (CHE)/material handling (MHE) equipment) | C24: =Base!C36 -> 0 | D24: - | E24: 0 | F24: 0
A25: 1005AA | B25: Ocean Transportation: Mid Atlantic Region to assigned port in Puerto Rico | C25: =Base!C37 -> 250 | D25: EA | E25: =Base!E37*1.02 -> 0 | F25: =IF(ISNUMBER(E25),C25*E25,0) -> 0
A26: 1005AB | B26: Ocean Transportation: South Atlantic Region to assigned port in Puerto Rico | C26: =Base!C38 -> 1000 | D26: EA | E26: =Base!E38*1.02 -> 0 | F26: =IF(ISNUMBER(E26),C26*E26,0) -> 0
A27: 1005AC | B27: Ocean Transportation: Gulf Coast to assigned port in Puerto Rico | C27: =Base!C39 -> 200 | D27: EA | E27: =Base!E39*1.02 -> 0 | F27: =IF(ISNUMBER(E27),C27*E27,0) -> 0
A28: 1005AD | B28: Ocean Transportation: FEMA Distribution Center Caribbean, San Juan PR to assigned port in Puerto Rico | C28: =Base!C40 -> 50 | D28: EA | E28: =Base!E40*1.02 -> 0 | F28: =IF(ISNUMBER(E28),C28*E28,0) -> 0
A29: 1006 | B29: Task: Dedicated Vessel Voyage from Port of Embarkation to assigned port in USVI, FOB Destination (Inclusive of container handling (CHE)/material handling (MHE) equipment and services) (30 day minimum length of dedicated vessel) | C29: =Base!C41 -> 0 | D29: - | E29: 0
A30: 1006AA | B30: Ocean Transportation: Mid Atlantic Region to assigned port in the USVI | C30: =Base!C42 -> 1 | D30: Vessel/Barge per Day | E30: =Base!E42*1.02 -> 0 | F30: =IF(ISNUMBER(E30),C30*E30,0) -> 0
A31: 1006AB | B31: Ocean Transportation: South Atlantic Region to assigned port in the USVI | C31: =Base!C43 -> 1 | D31: Vessel/Barge per Day | E31: =Base!E43*1.02 -> 0 | F31: =IF(ISNUMBER(E31),C31*E31,0) -> 0
A32: 1006AC | B32: Ocean Transportation: Gulf Coast to assigned port in the USVI | C32: =Base!C44 -> 1 | D32: Vessel/Barge per Day | E32: =Base!E44*1.02 -> 0 | F32: =IF(ISNUMBER(E32),C32*E32,0) -> 0
A33: 1006AD | B33: Ocean Transportation: FEMA Distribution Center Caribbean, San Juan PR to assigned port in the USVI | C33: =Base!C45 -> 1 | D33: Vessel/Barge per Day | E33: =Base!E45*1.02 -> 0 | F33: =IF(ISNUMBER(E33),C33*E33,0) -> 0
A34: 1007 | B34: Task: Dedicated Vessel Voyage from Port of Embarkation to assigned port in Puerto Rico, FOB Destination (Inclusive of container handling (CHE)/material handling (MHE) equipment and services) (30 day minimum length of dedicated vessel) | C34: =Base!C46 -> 0 | D34: - | E34: 0
A35: 1007AA | B35: Ocean Transportation: Mid Atlantic Region to assigned port in Puerto Rico | C35: =Base!C47 -> 1 | D35: Vessel/Barge per Day | E35: =Base!E47*1.02 -> 0 | F35: =IF(ISNUMBER(E35),C35*E35,0) -> 0
A36: 1007AB | B36: Ocean Transportation: South Atlantic Region to assigned port in Puerto Rico | C36: =Base!C48 -> 1 | D36: Vessel/Barge per Day | E36: =Base!E48*1.02 -> 0 | F36: =IF(ISNUMBER(E36),C36*E36,0) -> 0
A37: 1007AC | B37: Ocean Transportation: Gulf Coast to assigned port in Puerto Rico | C37: =Base!C49 -> 1 | D37: Vessel/Barge per Day | E37: =Base!E49*1.02 -> 0 | F37: =IF(ISNUMBER(E37),C37*E37,0) -> 0
A38: 1007AD | B38: Ocean Transportation: FEMA Distribution Center Caribbean, San Juan PR to assigned port in Puerto Rico | C38: =Base!C50 -> 1 | D38: Vessel/Barge per Day | E38: =Base!E50*1.02 -> 0 | F38: =IF(ISNUMBER(E38),C38*E38,0) -> 0
A39: 1008 | B39: Task: Expedited Air Transportation Services. USVI, FOB Destination. (Inclusive of container handling (CHE)/material handling (MHE) equipment). Standard Pallet Size (48"L x 40"W x 48"H). Weight: Up to 1650lbs. | C39: =Base!C94 -> 0 | D39: - | E39: 0
A40: 1008AA | B40: Air Transportation: Mid Atlantic Region to Destination USVI | C40: =Base!C95 -> 200 | D40: Warehouse Pallets | E40: =Base!E95*1.02 -> 0 | F40: =IF(ISNUMBER(E40),C40*E40,0) -> 0
...

Sheet Opt YR 2
A1: RCTSD - Opt YR 2
A2: INSTRUCTIONS: Please note the quantites listed below are for evaluation purposes only. Quoters are not expected to have a minimum of the units used to evaluate. Unit Price will be fixed at time of award.
A3: CLIN | B3: Description | C3: Quantities | D3: Unit | E3: Unit Price | F3: Total Price
A4: 2001 | B4: Commodity Pre-Positioning. Task: Deliver Empty Shipping Containers to FEMA loading/discharging (receiving) locations. (Inclusive of container handling (CHE)/material handling (MHE) equipment) | C4: - | D4: - | E4: - | F4: -
A5: 2001AA | B5: Destination: Mid Atlantic Region | C5: =Base!C115 -> 250 | D5: EA | E5: =Base!E115*1.04 -> 0 | F5: =IF(ISNUMBER(E5),C5*E5,0) -> 0
A6: 2001AB | B6: Destination: South Atlantic Region | C6: =Base!C116 -> 500 | D6: EA | E6: =Base!E116*1.04 -> 0 | F6: =IF(ISNUMBER(E6),C6*E6,0) -> 0
A7: 2001AC | B7: Destination: Gulf Coast | C7: =Base!C117 -> 200 | D7: EA | E7: =Base!E117*1.04 -> 0 | F7: =IF(ISNUMBER(E7),C7*E7,0) -> 0
A8: 2001AD | B8: Destination: FEMA Distribution Center Caribbean, San Juan PR | C8: =Base!C118 -> 500 | D8: EA | E8: =Base!E118*1.04 -> 0 | F8: =IF(ISNUMBER(E8),C8*E8,0) -> 0
A9: 2002 | B9: Task: Surface line haul/Drayage services of containerized commodities from Origin to Port of Embarkation. (Inclusive of container handling (CHE)/material handling (MHE) equipment) | C9: =Base!C4 -> 0 | D9: - | E9: =Base!E4*1.04 -> 0
A10: 2002AA | B10: Ground Transportation: Point of Origin to Port of Embarkation (Mid Atlantic Region) | C10: =Base!C5 -> 250 | D10: EA | E10: =Base!E5*1.04 -> 0 | F10: =IF(ISNUMBER(E10),C10*E10,0) -> 0
A11: 2002AB | B11: Ground Transportation: Point of Origin to Port of Embarkation (South Atlantic Region) | C11: =Base!C6 -> 500 | D11: EA | E11: =Base!E6*1.04 -> 0 | F11: =IF(ISNUMBER(E11),C11*E11,0) -> 0
A12: 2002AC | B12: Ground Transportation: Point of Origin to Port of Embarkation (Gulf Coast) | C12: =Base!C7 -> 200 | D12: EA | E12: =Base!E7*1.04 -> 0 | F12: =IF(ISNUMBER(E12),C12*E12,0) -> 0
A13: 2002AD | B13: Ground Transportation: Point of Origin to Port of Embarkation (FEMA Distribution Center Caribbean, San Juan PR) | C13: =Base!C8 -> 500 | D13: EA | E13: =Base!E8*1.04 -> 0 | F13: =IF(ISNUMBER(E13),C13*E13,0) -> 0
A14: 2003 | B14: Task: Surface line haul/Drayage services of Breakbulk Cargo. (Per Chassis) (Inclusive of container handling (CHE)/material handling (MHE) equipment) | C14: =Base!C18 -> 0 | D14: - | E14: 0
A15: 2003AA | B15: Ground Transportation: Point of Origin to Port of Embarkation (Mid Atlantic Region) | C15: =Base!C19 -> 100 | D15: EA | E15: =Base!E19*1.04 -> 0 | F15: =IF(ISNUMBER(E15),C15*E15,0) -> 0
A16: 2003AB | B16: Ground Transportation: Point of Origin to Port of Embarkation (South Atlantic Region) | C16: =Base!C20 -> 100 | D16: EA | E16: =Base!E20*1.04 -> 0 | F16: =IF(ISNUMBER(E16),C16*E16,0) -> 0
A17: 2003AC | B17: Ground Transportation: Point of Origin to Port of Embarkation (Gulf Coast) | C17: =Base!C21 -> 100 | D17: EA | E17: =Base!E21*1.04 -> 0 | F17: =IF(ISNUMBER(E17),C17*E17,0) -> 0
A18: 2003AD | B18: Ground Transportation: Point of Origin to Port of Embarkation (FEMA Distribution Center Caribbean, San Juan PR) | C18: =Base!C22 -> 100 | D18: EA | E18: =Base!E22*1.04 -> 0 | F18: =IF(ISNUMBER(E18),C18*E18,0) -> 0
A19: 2004 | B19: Task: Transport loaded containers, via ocean vessel from Port of Embarkation to assigned port in the USVI, FOB Destination. (Inclusive of container handling (CHE)/material handling (MHE) equipment) | C19: =Base!C31 -> 0 | D19: - | E19: 0
A20: 2004AA | B20: Ocean Transportation: Mid Atlantic Region to assigned port in the USVI | C20: =Base!C32 -> 250 | D20: EA | E20: =Base!E32*1.04 -> 0 | F20: =IF(ISNUMBER(E20),C20*E20,0) -> 0
A21: 2004AB | B21: Ocean Transportation: South Atlantic Region to assigned port in the USVI | C21: =Base!C33 -> 1000 | D21: EA | E21: =Base!E33*1.04 -> 0 | F21: =IF(ISNUMBER(E21),C21*E21,0) -> 0
A22: 2004AC | B22: Ocean Transportation: Gulf Coast to assigned port in the USVI | C22: =Base!C34 -> 200 | D22: EA | E22: =Base!E34*1.04 -> 0 | F22: =IF(ISNUMBER(E22),C22*E22,0) -> 0
A23: 2004AD | B23: Ocean Transportation: FEMA Distribution Center Caribbean, San Juan PR to assigned port in the USVI | C23: =Base!C35 -> 50 | D23: EA | E23: =Base!E35*1.04 -> 0 | F23: =IF(ISNUMBER(E23),C23*E23,0) -> 0
A24: 2005 | B24: Task: Transport loaded containers, via ocean vessel from Port of Embarkation to assigned port in Puerto Rico, FOB Destination. (Inclusive of container handling (CHE)/material handling (MHE) equipment) | C24: =Base!C36 -> 0 | D24: - | E24: 0 | F24: 0
A25: 2005AA | B25: Ocean Transportation: Mid Atlantic Region to assigned port in Puerto Rico | C25: =Base!C37 -> 250 | D25: EA | E25: =Base!E37*1.04 -> 0 | F25: =IF(ISNUMBER(E25),C25*E25,0) -> 0
A26: 2005AB | B26: Ocean Transportation: South Atlantic Region to assigned port in Puerto Rico | C26: =Base!C38 -> 1000 | D26: EA | E26: =Base!E38*1.04 -> 0 | F26: =IF(ISNUMBER(E26),C26*E26,0) -> 0
A27: 2005AC | B27: Ocean Transportation: Gulf Coast to assigned port in Puerto Rico | C27: =Base!C39 -> 200 | D27: EA | E27: =Base!E39*1.04 -> 0 | F27: =IF(ISNUMBER(E27),C27*E27,0) -> 0
A28: 2005AD | B28: Ocean Transportation: FEMA Distribution Center Caribbean, San Juan PR to assigned port in Puerto Rico | C28: =Base!C40 -> 50 | D28: EA | E28: =Base!E40*1.04 -> 0 | F28: =IF(ISNUMBER(E28),C28*E28,0) -> 0
A29: 2006 | B29: Task: Dedicated Vessel Voyage from Port of Embarkation to assigned port in USVI, FOB Destination (Inclusive of container handling (CHE)/material handling (MHE) equipment and services) (30 day minimum length of dedicated vessel) | C29: =Base!C41 -> 0 | D29: - | E29: 0
A30: 2006AA | B30: Ocean Transportation: Mid Atlantic Region to assigned port in the USVI | C30: =Base!C42 -> 1 | D30: Vessel/Barge per Day | E30: =Base!E42*1.04 -> 0 | F30: =IF(ISNUMBER(E30),C30*E30,0) -> 0
A31: 2006AB | B31: Ocean Transportation: South Atlantic Region to assigned port in the USVI | C31: =Base!C43 -> 1 | D31: Vessel/Barge per Day | E31: =Base!E43*1.04 -> 0 | F31: =IF(ISNUMBER(E31),C31*E31,0) -> 0
A32: 2006AC | B32: Ocean Transportation: Gulf Coast to assigned port in the USVI | C32: =Base!C44 -> 1 | D32: Vessel/Barge per Day | E32: =Base!E44*1.04 -> 0 | F32: =IF(ISNUMBER(E32),C32*E32,0) -> 0
A33: 2006AD | B33: Ocean Transportation: FEMA Distribution Center Caribbean, San Juan PR to assigned port in the USVI | C33: =Base!C45 -> 1 | D33: Vessel/Barge per Day | E33: =Base!E45*1.04 -> 0 | F33: =IF(ISNUMBER(E33),C33*E33,0) -> 0
A34: 2007 | B34: Task: Dedicated Vessel Voyage from Port of Embarkation to assigned port in Puerto Rico, FOB Destination (Inclusive of container handling (CHE)/material handling (MHE) equipment and services) (30 day minimum length of dedicated vessel) | C34: =Base!C46 -> 0 | D34: - | E34: 0
A35: 2007AA | B35: Ocean Transportation: Mid Atlantic Region to assigned port in Puerto Rico | C35: =Base!C47 -> 1 | D35: Vessel/Barge per Day | E35: =Base!E47*1.04 -> 0 | F35: =IF(ISNUMBER(E35),C35*E35,0) -> 0
A36: 2007AB | B36: Ocean Transportation: South Atlantic Region to assigned port in Puerto Rico | C36: =Base!C48 -> 1 | D36: Vessel/Barge per Day | E36: =Base!E48*1.04 -> 0 | F36: =IF(ISNUMBER(E36),C36*E36,0) -> 0
A37: 2007AC | B37: Ocean Transportation: Gulf Coast to assigned port in Puerto Rico | C37: =Base!C49 -> 1 | D37: Vessel/Barge per Day | E37: =Base!E49*1.04 -> 0 | F37: =IF(ISNUMBER(E37),C37*E37,0) -> 0
A38: 2007AD | B38: Ocean Transportation: FEMA Distribution Center Caribbean, San Juan PR to assigned port in Puerto Rico | C38: =Base!C50 -> 1 | D38: Vessel/Barge per Day | E38: =Base!E50*1.04 -> 0 | F38: =IF(ISNUMBER(E38),C38*E38,0) -> 0
A39: 2008 | B39: Task: Expedited Air Transportation Services. USVI, FOB Destination. (Inclusive of container handling (CHE)/material handling (MHE) equipment). Standard Pallet Size (48"L x 40"W x 48"H). Weight: Up to 1650lbs. | C39: =Base!C94 -> 0 | D39: - | E39: 0
A40: 2008AA | B40: Air Transportation: Mid Atlantic Region to Destination USVI | C40: =Base!C95 -> 200 | D40: Warehouse Pallets | E40: =Base!E95*1.04 -> 0 | F40: =IF(ISNUMBER(E40),C40*E40,0) -> 0
...

Sheet Opt YR 3
A1: RCTSD - Opt YR 3
A2: INSTRUCTIONS: Please note the quantites listed below are for evaluation purposes only. Quoters are not expected to have a minimum of the units used to evaluate. Unit Price will be fixed at time of award.
A3: CLIN | B3: Description | C3: Quantities | D3: Unit | E3: Unit Price | F3: Total Price
A4: 3001 | B4: Commodity Pre-Positioning. Task: Deliver Empty Shipping Containers to FEMA loading/discharging (receiving) locations. (Inclusive of container handling (CHE)/material handling (MHE) equipment) | C4: - | D4: - | E4: - | F4: -
A5: 3001AA | B5: Destination: Mid Atlantic Region | C5: =Base!C115 -> 250 | D5: EA | E5: =Base!E115*1.06 -> 0 | F5: =IF(ISNUMBER(E5),C5*E5,0) -> 0
A6: 3001AB | B6: Destination: South Atlantic Region | C6: =Base!C116 -> 500 | D6: EA | E6: =Base!E116*1.06 -> 0 | F6: =IF(ISNUMBER(E6),C6*E6,0) -> 0
A7: 3001AC | B7: Destination: Gulf Coast | C7: =Base!C117 -> 200 | D7: EA | E7: =Base!E117*1.06 -> 0 | F7: =IF(ISNUMBER(E7),C7*E7,0) -> 0
A8: 3001AD | B8: Destination: FEMA Distribution Center Caribbean, San Juan PR | C8: =Base!C118 -> 500 | D8: EA | E8: =Base!E118*1.06 -> 0 | F8: =IF(ISNUMBER(E8),C8*E8,0) -> 0
A9: 3002 | B9: Task: Surface line haul/Drayage services of containerized commodities from Origin to Port of Embarkation. (Inclusive of container handling (CHE)/material handling (MHE) equipment) | C9: =Base!C4 -> 0 | D9: - | E9: =Base!E4*1.06 -> 0
A10: 3002AA | B10: Ground Transportation: Point of Origin to Port of Embarkation (Mid Atlantic Region) | C10: =Base!C5 -> 250 | D10: EA | E10: =Base!E5*1.06 -> 0 | F10: =IF(ISNUMBER(E10),C10*E10,0) -> 0
A11: 3002AB | B11: Ground Transportation: Point of Origin to Port of Embarkation (South Atlantic Region) | C11: =Base!C6 -> 500 | D11: EA | E11: =Base!E6*1.06 -> 0 | F11: =IF(ISNUMBER(E11),C11*E11,0) -> 0
A12: 3002AC | B12: Ground Transportation: Point of Origin to Port of Embarkation (Gulf Coast) | C12: =Base!C7 -> 200 | D12: EA | E12: =Base!E7*1.06 -> 0 | F12: =IF(ISNUMBER(E12),C12*E12,0) -> 0
A13: 3002AD | B13: Ground Transportation: Point of Origin to Port of Embarkation (FEMA Distribution Center Caribbean, San Juan PR) | C13: =Base!C8 -> 500 | D13: EA | E13: =Base!E8*1.06 -> 0 | F13: =IF(ISNUMBER(E13),C13*E13,0) -> 0
A14: 3003 | B14: Task: Surface line haul/Drayage services of Breakbulk Cargo. (Per Chassis) (Inclusive of container handling (CHE)/material handling (MHE) equipment) | C14: =Base!C18 -> 0 | D14: - | E14: 0
A15: 3003AA | B15: Ground Transportation: Point of Origin to Port of Embarkation (Mid Atlantic Region) | C15: =Base!C19 -> 100 | D15: EA | E15: =Base!E19*1.06 -> 0 | F15: =IF(ISNUMBER(E15),C15*E15,0) -> 0
A16: 3003AB | B16: Ground Transportation: Point of Origin to Port of Embarkation (South Atlantic Region) | C16: =Base!C20 -> 100 | D16: EA | E16: =Base!E20*1.06 -> 0 | F16: =IF(ISNUMBER(E16),C16*E16,0) -> 0
A17: 3003AC | B17: Ground Transportation: Point of Origin to Port of Embarkation (Gulf Coast) | C17: =Base!C21 -> 100 | D17: EA | E17: =Base!E21*1.06 -> 0 | F17: =IF(ISNUMBER(E17),C17*E17,0) -> 0
A18: 3003AD | B18: Ground Transportation: Point of Origin to Port of Embarkation (FEMA Distribution Center Caribbean, San Juan PR) | C18: =Base!C22 -> 100 | D18: EA | E18: =Base!E22*1.06 -> 0 | F18: =IF(ISNUMBER(E18),C18*E18,0) -> 0
A19: 3004 | B19: Task: Transport loaded containers, via ocean vessel from Port of Embarkation to assigned port in the USVI, FOB Destination. (Inclusive of container handling (CHE)/material handling (MHE) equipment) | C19: =Base!C31 -> 0 | D19: - | E19: 0
A20: 3004AA | B20: Ocean Transportation: Mid Atlantic Region to assigned port in the USVI | C20: =Base!C32 -> 250 | D20: EA | E20: =Base!E32*1.06 -> 0 | F20: =IF(ISNUMBER(E20),C20*E20,0) -> 0
A21: 3004AB | B21: Ocean Transportation: South Atlantic Region to assigned port in the USVI | C21: =Base!C33 -> 1000 | D21: EA | E21: =Base!E33*1.06 -> 0 | F21: =IF(ISNUMBER(E21),C21*E21,0) -> 0
A22: 3004AC | B22: Ocean Transportation: Gulf Coast to assigned port in the USVI | C22: =Base!C34 -> 200 | D22: EA | E22: =Base!E34*1.06 -> 0 | F22: =IF(ISNUMBER(E22),C22*E22,0) -> 0
A23: 3004AD | B23: Ocean Transportation: FEMA Distribution Center Caribbean, San Juan PR to assigned port in the USVI | C23: =Base!C35 -> 50 | D23: EA | E23: =Base!E35*1.06 -> 0 | F23: =IF(ISNUMBER(E23),C23*E23,0) -> 0
A24: 3005 | B24: Task: Transport loaded containers, via ocean vessel from Port of Embarkation to assigned port in Puerto Rico, FOB Destination. (Inclusive of container handling (CHE)/material handling (MHE) equipment) | C24: =Base!C36 -> 0 | D24: - | E24: 0 | F24: 0
A25: 3005AA | B25: Ocean Transportation: Mid Atlantic Region to assigned port in Puerto Rico | C25: =Base!C37 -> 250 | D25: EA | E25: =Base!E37*1.06 -> 0 | F25: =IF(ISNUMBER(E25),C25*E25,0) -> 0
A26: 3005AB | B26: Ocean Transportation: South Atlantic Region to assigned port in Puerto Rico | C26: =Base!C38 -> 1000 | D26: EA | E26: =Base!E38*1.06 -> 0 | F26: =IF(ISNUMBER(E26),C26*E26,0) -> 0
A27: 3005AC | B27: Ocean Transportation: Gulf Coast to assigned port in Puerto Rico | C27: =Base!C39 -> 200 | D27: EA | E27: =Base!E39*1.06 -> 0 | F27: =IF(ISNUMBER(E27),C27*E27,0) -> 0
A28: 3005AD | B28: Ocean Transportation: FEMA Distribution Center Caribbean, San Juan PR to assigned port in Puerto Rico | C28: =Base!C40 -> 50 | D28: EA | E28: =Base!E40*1.06 -> 0 | F28: =IF(ISNUMBER(E28),C28*E28,0) -> 0
A29: 3006 | B29: Task: Dedicated Vessel Voyage from Port of Embarkation to assigned port in USVI, FOB Destination (Inclusive of container handling (CHE)/material handling (MHE) equipment and services) (30 day minimum length of dedicated vessel) | C29: =Base!C41 -> 0 | D29: - | E29: 0
A30: 3006AA | B30: Ocean Transportation: Mid Atlantic Region to assigned port in the USVI | C30: =Base!C42 -> 1 | D30: Vessel/Barge per Day | E30: =Base!E42*1.06 -> 0 | F30: =IF(ISNUMBER(E30),C30*E30,0) -> 0
A31: 3006AB | B31: Ocean Transportation: South Atlantic Region to assigned port in the USVI | C31: =Base!C43 -> 1 | D31: Vessel/Barge per Day | E31: =Base!E43*1.06 -> 0 | F31: =IF(ISNUMBER(E31),C31*E31,0) -> 0
A32: 3006AC | B32: Ocean Transportation: Gulf Coast to assigned port in the USVI | C32: =Base!C44 -> 1 | D32: Vessel/Barge per Day | E32: =Base!E44*1.06 -> 0 | F32: =IF(ISNUMBER(E32),C32*E32,0) -> 0
A33: 3006AD | B33: Ocean Transportation: FEMA Distribution Center Caribbean, San Juan PR to assigned port in the USVI | C33: =Base!C45 -> 1 | D33: Vessel/Barge per Day | E33: =Base!E45*1.06 -> 0 | F33: =IF(ISNUMBER(E33),C33*E33,0) -> 0
A34: 3007 | B34: Task: Dedicated Vessel Voyage from Port of Embarkation to assigned port in Puerto Rico, FOB Destination (Inclusive of container handling (CHE)/material handling (MHE) equipment and services) (30 day minimum length of dedicated vessel) | C34: =Base!C46 -> 0 | D34: - | E34: 0
A35: 3007AA | B35: Ocean Transportation: Mid Atlantic Region to assigned port in Puerto Rico | C35: =Base!C47 -> 1 | D35: Vessel/Barge per Day | E35: =Base!E47*1.06 -> 0 | F35: =IF(ISNUMBER(E35),C35*E35,0) -> 0
A36: 3007AB | B36: Ocean Transportation: South Atlantic Region to assigned port in Puerto Rico | C36: =Base!C48 -> 1 | D36: Vessel/Barge per Day | E36: =Base!E48*1.06 -> 0 | F36: =IF(ISNUMBER(E36),C36*E36,0) -> 0
A37: 3007AC | B37: Ocean Transportation: Gulf Coast to assigned port in Puerto Rico | C37: =Base!C49 -> 1 | D37: Vessel/Barge per Day | E37: =Base!E49*1.06 -> 0 | F37: =IF(ISNUMBER(E37),C37*E37,0) -> 0
A38: 3007AD | B38: Ocean Transportation: FEMA Distribution Center Caribbean, San Juan PR to assigned port in Puerto Rico | C38: =Base!C50 -> 1 | D38: Vessel/Barge per Day | E38: =Base!E50*1.06 -> 0 | F38: =IF(ISNUMBER(E38),C38*E38,0) -> 0
A39: 3008 | B39: Task: Expedited Air Transportation Services. USVI, FOB Destination. (Inclusive of container handling (CHE)/material handling (MHE) equipment). Standard Pallet Size (48"L x 40"W x 48"H). Weight: Up to 1650lbs. | C39: =Base!C94 -> 0 | D39: - | E39: 0
A40: 3008AA | B40: Air Transportation: Mid Atlantic Region to Destination USVI | C40: =Base!C95 -> 200 | D40: Warehouse Pallets | E40: =Base!E95*1.06 -> 0 | F40: =IF(ISNUMBER(E40),C40*E40,0) -> 0
...

Sheet Opt YR 4
A1: RCTSD - Opt YR 4
A2: INSTRUCTIONS: Please note the quantites listed below are for evaluation purposes only. Quoters are not expected to have a minimum of the units used to evaluate. Unit Price will be fixed at time of award.
A3: CLIN | B3: Description | C3: Quantities | D3: Unit | E3: Unit Price | F3: Total Price
A4: 4001 | B4: Commodity Pre-Positioning. Task: Deliver Empty Shipping Containers to FEMA loading/discharging (receiving) locations. (Inclusive of container handling (CHE)/material handling (MHE) equipment) | C4: - | D4: - | E4: - | F4: -
A5: 4001AA | B5: Destination: Mid Atlantic Region | C5: =Base!C115 -> 250 | D5: EA | E5: =Base!E115*1.08 -> 0 | F5: =IF(ISNUMBER(E5),C5*E5,0) -> 0
A6: 4001AB | B6: Destination: South Atlantic Region | C6: =Base!C116 -> 500 | D6: EA | E6: =Base!E116*1.08 -> 0 | F6: =IF(ISNUMBER(E6),C6*E6,0) -> 0
A7: 4001AC | B7: Destination: Gulf Coast | C7: =Base!C117 -> 200 | D7: EA | E7: =Base!E117*1.08 -> 0 | F7: =IF(ISNUMBER(E7),C7*E7,0) -> 0
A8: 4001AD | B8: Destination: FEMA Distribution Center Caribbean, San Juan PR | C8: =Base!C118 -> 500 | D8: EA | E8: =Base!E118*1.08 -> 0 | F8: =IF(ISNUMBER(E8),C8*E8,0) -> 0
A9: 4002 | B9: Task: Surface line haul/Drayage services of containerized commodities from Origin to Port of Embarkation. (Inclusive of container handling (CHE)/material handling (MHE) equipment) | C9: =Base!C4 -> 0 | D9: - | E9: =Base!E4*1.08 -> 0
A10: 4002AA | B10: Ground Transportation: Point of Origin to Port of Embarkation (Mid Atlantic Region) | C10: =Base!C5 -> 250 | D10: EA | E10: =Base!E5*1.08 -> 0 | F10: =IF(ISNUMBER(E10),C10*E10,0) -> 0
A11: 4002AB | B11: Ground Transportation: Point of Origin to Port of Embarkation (South Atlantic Region) | C11: =Base!C6 -> 500 | D11: EA | E11: =Base!E6*1.08 -> 0 | F11: =IF(ISNUMBER(E11),C11*E11,0) -> 0
A12: 4002AC | B12: Ground Transportation: Point of Origin to Port of Embarkation (Gulf Coast) | C12: =Base!C7 -> 200 | D12: EA | E12: =Base!E7*1.08 -> 0 | F12: =IF(ISNUMBER(E12),C12*E12,0) -> 0
A13: 4002AD | B13: Ground Transportation: Point of Origin to Port of Embarkation (FEMA Distribution Center Caribbean, San Juan PR) | C13: =Base!C8 -> 500 | D13: EA | E13: =Base!E8*1.08 -> 0 | F13: =IF(ISNUMBER(E13),C13*E13,0) -> 0
A14: 4003 | B14: Task: Surface line haul/Drayage services of Breakbulk Cargo. (Per Chassis) (Inclusive of container handling (CHE)/material handling (MHE) equipment) | C14: =Base!C18 -> 0 | D14: - | E14: 0
A15: 4003AA | B15: Ground Transportation: Point of Origin to Port of Embarkation (Mid Atlantic Region) | C15: =Base!C19 -> 100 | D15: EA | E15: =Base!E19*1.08 -> 0 | F15: =IF(ISNUMBER(E15),C15*E15,0) -> 0
A16: 4003AB | B16: Ground Transportation: Point of Origin to Port of Embarkation (South Atlantic Region) | C16: =Base!C20 -> 100 | D16: EA | E16: =Base!E20*1.08 -> 0 | F16: =IF(ISNUMBER(E16),C16*E16,0) -> 0
A17: 4003AC | B17: Ground Transportation: Point of Origin to Port of Embarkation (Gulf Coast) | C17: =Base!C21 -> 100 | D17: EA | E17: =Base!E21*1.08 -> 0 | F17: =IF(ISNUMBER(E17),C17*E17,0) -> 0
A18: 4003AD | B18: Ground Transportation: Point of Origin to Port of Embarkation (FEMA Distribution Center Caribbean, San Juan PR) | C18: =Base!C22 -> 100 | D18: EA | E18: =Base!E22*1.08 -> 0 | F18: =IF(ISNUMBER(E18),C18*E18,0) -> 0
A19: 4004 | B19: Task: Transport loaded containers, via ocean vessel from Port of Embarkation to assigned port in the USVI, FOB Destination. (Inclusive of container handling (CHE)/material handling (MHE) equipment) | C19: =Base!C31 -> 0 | D19: - | E19: 0
A20: 4004AA | B20: Ocean Transportation: Mid Atlantic Region to assigned port in the USVI | C20: =Base!C32 -> 250 | D20: EA | E20: =Base!E32*1.08 -> 0 | F20: =IF(ISNUMBER(E20),C20*E20,0) -> 0
A21: 4004AB | B21: Ocean Transportation: South Atlantic Region to assigned port in the USVI | C21: =Base!C33 -> 1000 | D21: EA | E21: =Base!E33*1.08 -> 0 | F21: =IF(ISNUMBER(E21),C21*E21,0) -> 0
A22: 4004AC | B22: Ocean Transportation: Gulf Coast to assigned port in the USVI | C22: =Base!C34 -> 200 | D22: EA | E22: =Base!E34*1.08 -> 0 | F22: =IF(ISNUMBER(E22),C22*E22,0) -> 0
A23: 4004AD | B23: Ocean Transportation: FEMA Distribution Center Caribbean, San Juan PR to assigned port in the USVI | C23: =Base!C35 -> 50 | D23: EA | E23: =Base!E35*1.08 -> 0 | F23: =IF(ISNUMBER(E23),C23*E23,0) -> 0
A24: 4005 | B24: Task: Transport loaded containers, via ocean vessel from Port of Embarkation to assigned port in Puerto Rico, FOB Destination. (Inclusive of container handling (CHE)/material handling (MHE) equipment) | C24: =Base!C36 -> 0 | D24: - | E24: 0 | F24: 0
A25: 4005AA | B25: Ocean Transportation: Mid Atlantic Region to assigned port in Puerto Rico | C25: =Base!C37 -> 250 | D25: EA | E25: =Base!E37*1.08 -> 0 | F25: =IF(ISNUMBER(E25),C25*E25,0) -> 0
A26: 4005AB | B26: Ocean Transportation: South Atlantic Region to assigned port in Puerto Rico | C26: =Base!C38 -> 1000 | D26: EA | E26: =Base!E38*1.08 -> 0 | F26: =IF(ISNUMBER(E26),C26*E26,0) -> 0
A27: 4005AC | B27: Ocean Transportation: Gulf Coast to assigned port in Puerto Rico | C27: =Base!C39 -> 200 | D27: EA | E27: =Base!E39*1.08 -> 0 | F27: =IF(ISNUMBER(E27),C27*E27,0) -> 0
A28: 4005AD | B28: Ocean Transportation: FEMA Distribution Center Caribbean, San Juan PR to assigned port in Puerto Rico | C28: =Base!C40 -> 50 | D28: EA | E28: =Base!E40*1.08 -> 0 | F28: =IF(ISNUMBER(E28),C28*E28,0) -> 0
A29: 4006 | B29: Task: Dedicated Vessel Voyage from Port of Embarkation to assigned port in USVI, FOB Destination (Inclusive of container handling (CHE)/material handling (MHE) equipment and services) (30 day minimum length of dedicated vessel) | C29: =Base!C41 -> 0 | D29: - | E29: 0
A30: 4006AA | B30: Ocean Transportation: Mid Atlantic Region to assigned port in the USVI | C30: =Base!C42 -> 1 | D30: Vessel/Barge per Day | E30: =Base!E42*1.08 -> 0 | F30: =IF(ISNUMBER(E30),C30*E30,0) -> 0
A31: 4006AB | B31: Ocean Transportation: South Atlantic Region to assigned port in the USVI | C31: =Base!C43 -> 1 | D31: Vessel/Barge per Day | E31: =Base!E43*1.08 -> 0 | F31: =IF(ISNUMBER(E31),C31*E31,0) -> 0
A32: 4006AC | B32: Ocean Transportation: Gulf Coast to assigned port in the USVI | C32: =Base!C44 -> 1 | D32: Vessel/Barge per Day | E32: =Base!E44*1.08 -> 0 | F32: =IF(ISNUMBER(E32),C32*E32,0) -> 0
A33: 4006AD | B33: Ocean Transportation: FEMA Distribution Center Caribbean, San Juan PR to assigned port in the USVI | C33: =Base!C45 -> 1 | D33: Vessel/Barge per Day | E33: =Base!E45*1.08 -> 0 | F33: =IF(ISNUMBER(E33),C33*E33,0) -> 0
A34: 4007 | B34: Task: Dedicated Vessel Voyage from Port of Embarkation to assigned port in Puerto Rico, FOB Destination (Inclusive of container handling (CHE)/material handling (MHE) equipment and services) (30 day minimum length of dedicated vessel) | C34: =Base!C46 -> 0 | D34: - | E34: 0
A35: 4007AA | B35: Ocean Transportation: Mid Atlantic Region to assigned port in Puerto Rico | C35: =Base!C47 -> 1 | D35: Vessel/Barge per Day | E35: =Base!E47*1.08 -> 0 | F35: =IF(ISNUMBER(E35),C35*E35,0) -> 0
A36: 4007AB | B36: Ocean Transportation: South Atlantic Region to assigned port in Puerto Rico | C36: =Base!C48 -> 1 | D36: Vessel/Barge per Day | E36: =Base!E48*1.08 -> 0 | F36: =IF(ISNUMBER(E36),C36*E36,0) -> 0
A37: 4007AC | B37: Ocean Transportation: Gulf Coast to assigned port in Puerto Rico | C37: =Base!C49 -> 1 | D37: Vessel/Barge per Day | E37: =Base!E49*1.08 -> 0 | F37: =IF(ISNUMBER(E37),C37*E37,0) -> 0
A38: 4007AD | B38: Ocean Transportation: FEMA Distribution Center Caribbean, San Juan PR to assigned port in Puerto Rico | C38: =Base!C50 -> 1 | D38: Vessel/Barge per Day | E38: =Base!E50*1.08 -> 0 | F38: =IF(ISNUMBER(E38),C38*E38,0) -> 0
A39: 4008 | B39: Task: Expedited Air Transportation Services. USVI, FOB Destination. (Inclusive of container handling (CHE)/material handling (MHE) equipment). Standard Pallet Size (48"L x 40"W x 48"H). Weight: Up to 1650lbs. | C39: =Base!C94 -> 0 | D39: - | E39: 0
A40: 4008AA | B40: Air Transportation: Mid Atlantic Region to Destination USVI | C40: =Base!C95 -> 200 | D40: Warehouse Pallets | E40: =Base!E95*1.08 -> 0 | F40: =IF(ISNUMBER(E40),C40*E40,0) -> 0
...
