Workbook
Name _FTE1: 988
Name _FTE2: 1012
Name TableName: "Dummy"

Sheet Instructions
B1: Attachment C1 Instructions
B2: Green Cells are Formula Based
B3: Yellow Cells require an Input
B4: Only one workbook shall be prepared for the entire period of performance (one workbook for each Prime and one for each Subcontractor)
B6: The worksheets of the workbook should all be formatted for printing on letter-size paper, without requiring "adjustments." It may be formatted for either landscape or portrait. DO NOT FORMAT FOR LEGAL SIZE PAPER.
B7: All cells shall be unprotected and unlocked, with formulae intact to show mathematical operations.
B8: All dollar figures shall be carried out no further than two decimal places. (ex $25.50)
A10: Instructions for Prime Contractor:
C11: Base Year Column | D11: Subsequent Year Columns
B12: Indirect Rates and Fee Worksheet Instructions
A13: 1 | B13: Enter Prime Contractor's name into cell A3.
A14: 2 | B14: Fill in all Indirect Rates in the Indirect Rates and Fee Worksheet. These rates will be pulled into the Cost Summary Spreadsheet. Ensure formulas are still intact. | C14: D | D14: E, F, G, H, I
B15: Cost Summary Worksheet Instructions
A16: 3 | B16: Enter Prime Contractor's name into cell A3. | C16: A | D16: N/A
A17: 4 | B17: Enter all Prime current or contingent employee names (or the word "Prospective") in Column A on the Cost Summary Worksheet (starting at row 10). If necessary, insert additional rows--but ensure integrity of formulas. Labor categories with more than one person being proposed shall be listed multiple times (one row per employee). For example, if the Contractor proposes four Computer Systems Analysts, then the labor category Computer Systems Analysts shall be listed four times along with their applicable rates and information. | C17: A | D17: N/A
A18: 5 | B18: Use the dropdown in Column B to enter the Labor Category from the RFO that you will be utilizing. By utilizing this drop-down, the minimum realistic rate, as stated in the Minimum Direct Labor Rates worksheet will fill in, in Column H. Please see the RFO for additional guidance regarding the minimum realistic rate. Note - DO NOT use the drag feature to pull down a labor category to a subsequent row. This will not allow the formulas to work properly. | C18: B | D18: N/A
A19: 6 | B19: Enter all Prime labor categories in Column C (starting at row 10). In Column C, the Contractor should insert the title of the labor category it will be utilizing. The Contractor is not required to utilize the Government's labor categories; however, each proposed labor category should appear in the column beside the Government labor category it is comparable to. Please note, in the evaluation the Contractor's proposal will be compared to the RFO with respect to labor categories. | C19: C | D19: N/A
A20: 7 | B20: In Column D, the Contractor shall select "BLS" if Column B is a BLS or CSWF labor category. The Contractor shall select "SCA" if Column B is an SCLS, formally known as SCA of 1965, labor category. This dropdown will allow the escalation formulas in Columns O, T, Y, and AD to calculate properly. | C20: D | D20: Formula Driven - O, T, Y, AD
A21: 8 | B21: In Column E, the Contractor shall insert a "K" if the employee will be performing at the Contractor's facility or a "G" if they will be performing in Government spaces, or a "T" if there is a differing OH rate that will be utilized for that specific person. NOTE - If this procurement has various Govt Site locations (example, WOLF and Pax River), utilize "G" for both locations. A distinction does not need to be made between these sites for evaluation purposes. | C21: E | D21: N/A
A22: 9 | B22: In Column F, identify the geograpical location of the position for each row. This input shall match the geograpic location for which the Government Labor Category is associated. | C22: F | D22: N/A
A23: 10 | B23: In Column G, identify for the specific individual whether their fully burdened rate is calculated using the full-time or part-time fringe rate. Enter "F" for full-time or "P" for part-time. | C23: G | D23: N/A
A24: 11 | B24: In Column I, insert the direct labor rate for each row. If the rate proposed is less than the minimum direct labor rate as included in the Minimun Direct Labor Rates worksheet, the cell will turn red. If this happens for a prospective employee, an explanation should be included in the cost narrative. Note, subsequent rate Columns (N, S, X, and AC) are formula-based and are calculated using the escalation for that year. Ensure formulas are intact. | C24: I | D24: Formula Driven - N, S, X, AC
A25: 12 | B25: In Column J, enter the labor hours for each row. Enter hours for each subsequent year (Columns O, T, Y, and AD). | C25: J | D25: O, T, Y, AD
A26: 13 | B26: This workbook includes hidden columns to assist with the correct application of indirect rates (two columns after each Amount column for each year). If, per accounting practices, you DO NOT apply overhead to your fringe rate, you can delete the calculations included in the hidden columns that assist with adding overhead to Fringe. | C26: Formula Driven - L, M | D26: Formula Driven - Q, R, V, W, AA, AB, AF
A27: 14 | B27: Escalation has been auto-populated based on the RFO. If, in accordance with the RFO, you are utilizing a rate that differs from that which has already been filled in, you may change the value in the cell and provide an explanation in your cost narrative. | C27: N/A | D27: O, T, Y, AD
... A29: 16 | B29: The minimum rate is blacked out in Column H for the subcontractors within the Prime's section. The minimum rate is analyzed at the direct labor rate; however, the rates included for Subcontractors in the Prime's submission will be fully burdened labor rates. | C29: H | D29: N/A
A30: 17 | B30: Please note, if more space for Subcontractors is needed, the Contractor may add additional rows to accommodate them; however, please be sure to maintain integrity of formulas. If fewer Subcontractors are needed, hide the rows instead of deleting them.
A31: 18 | B31: Under Other Direct Costs, the Prime Contractor should enter the proposed ODC costs in Columns K, P, U, Z, AE. | C31: K | D31: P, U, Z, AE
A32: 19 | B32: Check to ensure the indirects are applied appropriately to ODCs. If the formulas that are utilized do not match your accounting practices, either adjust in the Indirects Rates and Fee tab or adjust the formula and note why changes were made and what specific changes were made in the Attachment C2 - Cost/Price Narrative. | C32: K | D32: P, U, Z, AE
B33: In accordance with HTXT.232-9510 PAYMENT OF FIXED FEE, the resultant contract payment of fixed fee will be dollars per hour (based on the total fixed fee divided by the total level of effort in hours). Cell B324, calculates the fee per hour as required to only two decimal places. The value stated in cell B324 will be used to populate the fee per hour value within HTXT.232-9510. There shall be one fee per hour for the entire TO, meaning all PoPs will earn the same fee per hour. The resultant TO award will include the total fixed fee calculated within the Cost Summary worksheet (cells K287, P287, U287, and AE287) which uses the fee per hour. This ensures that the Contractor is able to earn the full fee if all level of effort (hours) is executed during contract performance and ensures the fee ceiling for CLINs on the resultant TO can be calculated correctly with no errors due to rounding. | C33: K | D33: P, U, Z, AE
B34: Fully Burdened Labor Rates Worksheet Instructions
A35: 20 | B35: Enter Prime Contractors's name into cell A3. | C35: A | D35: N/A
A36: 21 | B36: Enter employee names (starting at row 10). For Prospective hires, enter the cell reference from Column A of the Cost Summary Worksheet under applicable Prime Contractor or Subcontractor header. If necessary, insert additional rows--but ensure integrity of formulas. | C36: A | D36: N/A
A37: 22 | B37: Use the dropdown in Column B to enter the Labor Category which matches the Cost Summary Worksheet. Note - the Labor Category used in B10 of the Cost Summary worksheet should match the Labor Category used in B10 of the Fully Burdened Labor Rates worksheet. | C37: B | D37: N/A
A38: 22 | B38: Enter the Fully Burdened Labor Rate rounded to two decimal places for each year for every employee. Fully Burdened Labor Rates shall include indirect rates, fee, and subcontractor pass-through costs where applicable. For Subcontractor labor, the fully burdened labor rates shall be inclusive of any pass-through charges (e.g., subcontractor handling, fixed fee on subcontractor labor, etc.) applied by the Prime Contractor. They should not include Fully Burdened Other Direct Costs (ODCs) such as Materials, Travel, and Cost of Money costs. | C38: C | D38: F, I, L, O
A39: 23 | B39: Enter the labor hours for each year for every employee, ensuring the values match the Cost Summary Worksheet. | C39: D | D39: G, J, M, P
A40: 24 | B40: The Annual Fully Burdened amount by employee is calculated by multiplying the Fully Burdened Labor Rate by the number of hours proposed by year. This should auto calculate. However, if additional rows are added, please ensure the formulas are intact. | C40: E | D40: H, K, N, Q
A43: Instructions for Subcontractors:
B44: Green Cells are Formula Based
B45: Yellow Cells require an Input
...

Sheet Indirect Rates and Fee
A1: INDIRECT COST SUMMARY
A3: Prime Contractor Name:
A4: Subcontractor Name (if applicable):
D6: Indirect Rates (%)
C7: Indirect Cost Category | D7: Year 1 | E7: Year 2 | F7: Year 3 | G7: Year 4 | H7: Year 5 | I7: Year 6
B8: Fringe
B9: F | C9: Fringe: Full Time
B10: P | C10: Fringe: Part Time
B12: Overhead*
B13: KTR | C13: KTR Site OH
B14: G | C14: Gov Site OH
B15: T | C15: Other Site OH
B16: G&A
C17: G&A
C18: G&A on ODCs
B20: Subcontractor Handling
C21: Material Handling (on ODC)
C22: Material Handling (on sub)
C23: SubcontractsHandling
B25: Fee
C26: Fee on Prime labor
C27: Fee on Sub labor
B30: *Note, this procurement does not designate any other sites than Government and KTR site. The "Other Site" Overhead option is included in case the Contractor has multiple OH rates beyond Government and KTR site.

Sheet Cost Summary
A1: COST REIMBURSABLE SUMMARY SPREADSHEET
A3: Prime Contractor Name:
A4: Subcontractor Name (if applicable): | N4: BLS Escalation | O4: 0.033 | S4: BLS Escalation | T4: 0.033 | X4: BLS Escalation | Y4: 0.033 | AC4: BLS Escalation | AD4: 0.033 | AH4: BLS Escalation | AI4: 0.033
N5: SCLS Escalation | O5: 0.0261 | S5: SCLS Escalation | T5: 0.0261 | X5: SCLS Escalation | Y5: 0.0261 | AC5: SCLS Escalation | AD5: 0.0261 | AH5: SCLS Escalation | AI5: 0.0261
I6: Year 1 | L6: Extra columns to apply overhead to Fringe | N6: Year 2 | Q6: Extra columns to apply overhead to Fringe | S6: Year 3 | V6: Extra columns to apply overhead to Fringe | X6: Year 4 | AA6: Extra columns to apply overhead to Fringe | AC6: Year 5 | AF6: Extra columns to apply overhead to Fringe | AH6: Year 6 | AM6: Extra columns to apply overhead to Fringe | AO6: Total for All Years
A7: Cost Elements | B7: Government Labor Category | C7: Proposed Labor Category | D7: BLS or SCLS | E7: Site (K, G, T) | F7: Location | G7: F/P | H7: Minimum Direct Labor Rate | I7: Rate | 1 | J7: Hours | 1 | K7: Amount | 1 | L7: Overhead on Fringe Calc. | 1 | M7: Fringe Amount | 1 | N7: Rate | 2 | O7: Hours | 2 | P7: Amount | 2 | Q7: Overhead on Fringe Calc. | 2 | R7: Fringe Amount | 2 | S7: Rate | 3 | T7: Hours | 3 | U7: Amount | 3 | V7: Overhead on Fringe Calc. | 3 | W7: Fringe Amount | 3 | X7: Rate | 4 | Y7: Hours | 4 | Z7: Amount | 4 | AA7: Overhead on Fringe Calc. | 4 | AB7: Fringe Amount | 4 | AC7: Rate | 5 | AD7: Hours | 5 | AE7: Amount | 5 | AF7: Overhead on Fringe Calc. | 5 | AG7: Fringe Amount | 5 | AH7: Rate | 6 | AI7: Hours | 6 | AJ7: Hours | 62 | AK7: Hours | 7 | AL7: Amount | 6 | AM7: Overhead on Fringe Calc. | 6 | AN7: Fringe Amount | 6 | AO7: Hours | Total | AP7: Amount | Total | AQ7: Row | AR7: Column1 | AS7: Column2 | AT7: Column3 | AU7: Column4 | AV7: Column5 | AW7: Column6 | AX7: Column7
A8: Prime Contractor Labor Cost | H8: =IFERROR(INDEX(Labor_Categories[Minimum Direct Labor Rates],MATCH(Cost_Elements[[#This Row],[Government Labor Category]],Labor_Categories[Labor Categories],0)),"") | AQ8: =ROW(Cost_Elements[[#This Row],[Amount | Total]]) -> 8
A9: Prime Contractor Direct Labor | H9: =IFERROR(INDEX(Labor_Categories[Minimum Direct Labor Rates],MATCH(Cost_Elements[[#This Row],[Government Labor Category]],Labor_Categories[Labor Categories],0)),"") | AQ9: =ROW(Cost_Elements[[#This Row],[Amount | Total]]) -> 9
A10: Employee Name or Prospective | H10: =IFERROR(INDEX(Labor_Categories[Minimum Direct Labor Rates],MATCH(Cost_Elements[[#This Row],[Government Labor Category]],Labor_Categories[Labor Categories],0)),"") | K10: =IFERROR(IF(Cost_Elements[[#This Row],[Row]]>='Do Not Use or Delete'!$L$2, IF(Cost_Elements[[#This Row],[Row]]<='Do Not Use or Delete'!$M$2,I10*J10,0),0)+IF(Cost_Elements[[#This Row],[Cost Elements]]=$A$113,SUM(INDIRECT("I"&'Do Not Use or Delete'!$L$2& ":" & "I" & 'Do Not Use or Delete'!$M$2)),0)+IF(Cost_Elements[[#This Row],[Cost Elements]]=$A$127, SUM($K$123:$K$126),0)+IF(Cost_Elements[[#This Row],[Cost Elements]]=$A$131, SUM($K$129,$K$130))+IF(Cost_Elements[[#This Row],[Cost Elements]]=$A$119,SUMIFS(Cost_Elements[Amount | 1],Cost_Elements[Cost Elements],"Overhead"),0)+IF(Cost_Elements[[#This Row],[Cost Elements]]=$A$122,SUMIFS(Cost_Elements[Amount | 1],Cost_Elements[Cost Elements],"Fringe Benefits"),0)+IF(Cost_Elements[[#This Row],[Cost Elements]]=$A$123,SUMIFS(Cost_Elements[Amount | 1],Cost_Elements[Cost Elements],"Fringe Benefits")+SUMIFS(Cost_Elements[Amount | 1],Cost_Elements[Cost Elements],"Overhead"),IF(Cost_Elements[[#This Row],[Row]]>'Do Not Use or Delete'!$M$2,ROUND(Cost_Elements[[#This Row],[Rate | 1]]*Cost_Elements[[#This Row],[Hours | 1]],2),0))+IF(Cost_Elements[[#This Row],[Cost Elements]]=$A$128,$K$127+$K$113,0)+IF(Cost_Elements[[#This Row],[Cost Elements]]=$A$131,$K$130+$K$128,0)+IF(Cost_Elements[[#This Row],[Cost Elements]]=$A$272,SUM($K$137:$K$270),0)+IF(Cost_Elements[[#This Row],[Cost Elements]]=$A$278,SUM($K$274:$K$277),0)+IF(Cost_Elements[[#This Row],[Cost Elements]]=$A$279,$K$272+$K$278,0)+IF(Cost_Elements[[#This Row],[Cost Elements]]=$A$281,$K$131+$K$279,0)+IF(Cost_Elements[[#This Row],[Cost Elements]]=$A$286,SUM($K$284:$K$285),0)+IF(Cost_Elements[[#This Row],[Cost Elements]]=$A$288,$K$286+$K$281,0)+IF(Cost_Elements[[#This Row],[Cost Elements]]=$A$300,SUM($K$291:$K$299),0)+IF(Cost_Elements[[#This Row],[Cost Elements]]=$A$303,$K$288+$K$300,0),"") -> 0 | N10: =IF(PRODUCT(Cost_Elements[[#This Row],[BLS or SCLS]]="BLS"),(Cost_Elements[[#This Row],[Rate | 1]]*$O$4)+Cost_Elements[[#This Row],[Rate | 1]],(Cost_Elements[[#This Row],[Rate | 1]]*$O$5)+Cost_Elements[[#This Row],[Rate | 1]]) -> 0 | P10: =IFERROR(IF(Cost_Elements[[#This Row],[Row]]>='Do Not Use or Delete'!$L$2, IF(Cost_Elements[[#This Row],[Row]]<='Do Not Use or Delete'!$M$2,N10*O10,0),0)+IF(Cost_Elements[[#This Row],[Cost Elements]]=$A$113,SUM(INDIRECT("N"&'Do Not Use or Delete'!$L$2 & ":" & "N" & 'Do Not Use or Delete'!$M$2)),0)+IF(Cost_Elements[[#This Row],[Cost Elements]]=$A$127, SUM($P$123:$P$126),0)+IF(Cost_Elements[[#This Row],[Cost Elements]]=$A$131, SUM($P$129,$P$130))+IF(Cost_Elements[[#This Row],[Cost Elements]]=$A$119,SUMIFS(Cost_Elements[Amount | 2],Cost_Elements[Cost Elements],"Overhead"),0)+IF(Cost_Elements[[#This Row],[Cost Elements]]=$A$122,SUMIFS(Cost_Elements[Amount | 2],Cost_Elements[Cost Elements],"Fringe Benefits"),0)+IF(Cost_Elements[[#This Row],[Cost Elements]]=$A$123,SUMIFS(Cost_Elements[Amount | 2],Cost_Elements[Cost Elements],"Fringe Benefits")+SUMIFS(Cost_Elements[Amount | 2],Cost_Elements[Cost Elements],"Overhead"),IF(Cost_Elements[[#This Row],[Row]]>'Do Not Use or Delete'!$M$2,ROUND(Cost_Elements[[#This Row],[Rate | 2]]*Cost_Elements[[#This Row],[Hours | 2]],2),0))+IF(Cost_Elements[[#This Row],[Cost Elements]]=$A$128,$P$127+$P$113,0)+IF(Cost_Elements[[#This Row],[Cost Elements]]=$A$131,$P$130+$P$128,0)+IF(Cost_Elements[[#This Row],[Cost Elements]]=$A$272,SUM($P$137:$P$270),0)+IF(Cost_Elements[[#This Row],[Cost Elements]]=$A$278,SUM($P$274:$P$277),0)+IF(Cost_Elements[[#This Row],[Cost Elements]]=$A$279,$P$272+$P$278,0)+IF(Cost_Elements[[#This Row],[Cost Elements]]=$A$281,$P$131+$P$279,0)+IF(Cost_Elements[[#This Row],[Cost Elements]]=$A$286,SUM($P$284:$P$285),0)+IF(Cost_Elements[[#This Row],[Cost Elements]]=$A$288,$P$286+$P$281,0)+IF(Cost_Elements[[#This Row],[Cost Elements]]=$A$300,SUM($P$291:$P$299),0)+IF(Cost_Elements[[#This Row],[Cost Elements]]=$A$303,$P$288+$P$300,0),"") -> 0 | S10: =IF(PRODUCT(Cost_Elements[[#This Row],[BLS or SCLS]]="BLS"),(Cost_Elements[[#This Row],[Rate | 2]]*$T$4)+Cost_Elements[[#This Row],[Rate | 2]],(Cost_Elements[[#This Row],[Rate | 2]]*$T$5)+Cost_Elements[[#This Row],[Rate | 2]]) -> 0 | U10: =IFERROR(IF(Cost_Elements[[#This Row],[Row]]>='Do Not Use or Delete'!$L$2, IF(Cost_Elements[[#This Row],[Row]]<='Do Not Use or Delete'!$M$2,S10*T10,0),0)+IF(Cost_Elements[[#This Row],[Cost Elements]]=$A$113,SUM(INDIRECT("S"&'Do Not Use or Delete'!$L$2 & ":" & "S" & 'Do Not Use or Delete'!$M$2)),0)+IF(Cost_Elements[[#This Row],[Cost Elements]]=$A$127, SUM($U$123:$U$126),0)+IF(Cost_Elements[[#This Row],[Cost Elements]]=$A$131, SUM($U$129,$U$130))+IF(Cost_Elements[[#This Row],[Cost Elements]]=$A$119,SUMIFS(Cost_Elements[Amount | 3],Cost_Elements[Cost Elements],"Overhead"),0)+IF(Cost_Elements[[#This Row],[Cost Elements]]=$A$122,SUMIFS(Cost_Elements[Amount | 3],Cost_Elements[Cost Elements],"Fringe Benefits"),0)+IF(Cost_Elements[[#This Row],[Cost Elements]]=$A$123,SUMIFS(Cost_Elements[Amount | 3],Cost_Elements[Cost Elements],"Fringe Benefits")+SUMIFS(Cost_Elements[Amount | 3],Cost_Elements[Cost Elements],"Overhead"),IF(Cost_Elements[[#This Row],[Row]]>'Do Not Use or Delete'!$M$2,ROUND(Cost_Elements[[#This Row],[Rate | 3]]*Cost_Elements[[#This Row],[Hours | 3]],2),0))+IF(Cost_Elements[[#This Row],[Cost Elements]]=$A$128,$U$127+$U$113,0)+IF(Cost_Elements[[#This Row],[Cost Elements]]=$A$131,$U$130+$U$128,0)+IF(Cost_Elements[[#This Row],[Cost Elements]]=$A$272,SUM($U$137:$U$270),0)+IF(Cost_Elements[[#This Row],[Cost Elements]]=$A$278,SUM($U$274:$U$277),0)+IF(Cost_Elements[[#This Row],[Cost Elements]]=$A$279,$U$272+$U$278,0)+IF(Cost_Elements[[#This Row],[Cost Elements]]=$A$281,$U$131+$U$279,0)+IF(Cost_Elements[[#This Row],[Cost Elements]]=$A$286,SUM($U$284:$U$285),0)+IF(Cost_Elements[[#This Row],[Cost Elements]]=$A$288,$U$286+$U$281,0)+IF(Cost_Elements[[#This Row],[Cost Elements]]=$A$300,SUM($U$291:$U$299),0)+IF(Cost_Elements[[#This Row],[Cost Elements]]=$A$303,$U$288+$U$300,0),"") -> 0 | X10: =IF(PRODUCT(Cost_Elements[[#This Row],[BLS or SCLS]]="BLS"),(Cost_Elements[[#This Row],[Rate | 3]]*$Y$4)+Cost_Elements[[#This Row],[Rate | 3]],(Cost_Elements[[#This Row],[Rate | 3]]*$Y$5)+Cost_Elements[[#This Row],[Rate | 3]]) -> 0 | Z10: =IFERROR(IF(Cost_Elements[[#This Row],[Row]]>='Do Not Use or Delete'!$L$2, IF(Cost_Elements[[#This Row],[Row]]<='Do Not Use or Delete'!$M$2,X10*Y10,0),0)+IF(Cost_Elements[[#This Row],[Cost Elements]]=$A$113,SUM(INDIRECT("X"&'Do Not Use or Delete'!$L$2 & ":" & "X" & 'Do Not Use or Delete'!$M$2)),0)+IF(Cost_Elements[[#This Row],[Cost Elements]]=$A$127, SUM($Z$123:$Z$126),0)+IF(Cost_Elements[[#This Row],[Cost Elements]]=$A$131, SUM($Z$129,$Z$130))+IF(Cost_Elements[[#This Row],[Cost Elements]]=$A$119,SUMIFS(Cost_Elements[Amount | 4],Cost_Elements[Cost Elements],"Overhead"),0)+IF(Cost_Elements[[#This Row],[Cost Elements]]=$A$122,SUMIFS(Cost_Elements[Amount | 4],Cost_Elements[Cost Elements],"Fringe Benefits"),0)+IF(Cost_Elements[[#This Row],[Cost Elements]]=$A$123,SUMIFS(Cost_Elements[Amount | 4],Cost_Elements[Cost Elements],"Fringe Benefits")+SUMIFS(Cost_Elements[Amount | 4],Cost_Elements[Cost Elements],"Overhead"),IF(Cost_Elements[[#This Row],[Row]]>'Do Not Use or Delete'!$M$2,ROUND(Cost_Elements[[#This Row],[Rate | 4]]*Cost_Elements[[#This Row],[Hours | 4]],2),0))+IF(Cost_Elements[[#This Row],[Cost Elements]]=$A$128,$Z$127+$Z$113,0)+IF(Cost_Elements[[#This Row],[Cost Elements]]=$A$131,$Z$130+$Z$128,0)+IF(Cost_Elements[[#This Row],[Cost Elements]]=$A$272,SUM($Z$137:$Z$270),0)+IF(Cost_Elements[[#This Row],[Cost Elements]]=$A$278,SUM($Z$274:$Z$277),0)+IF(Cost_Elements[[#This Row],[Cost Elements]]=$A$279,$Z$272+$Z$278,0)+IF(Cost_Elements[[#This Row],[Cost Elements]]=$A$281,$Z$131+$Z$279,0)+IF(Cost_Elements[[#This Row],[Cost Elements]]=$A$286,SUM($Z$284:$Z$285),0)+IF(Cost_Elements[[#This Row],[Cost Elements]]=$A$288,$Z$286+$Z$281,0)+IF(Cost_Elements[[#This Row],[Cost Elements]]=$A$300,SUM($Z$291:$Z$299),0)+IF(Cost_Elements[[#This Row],[Cost Elements]]=$A$303,$Z$288+$Z$300,0),"") -> 0 | AC10: =IF(PRODUCT(Cost_Elements[[#This Row],[BLS or SCLS]]="BLS"),(Cost_Elements[[#This Row],[Rate | 4]]*$AD$4)+Cost_Elements[[#This Row],[Rate | 4]],(Cost_Elements[[#This Row],[Rate | 4]]*$AD$5)+Cost_Elements[[#This Row],[Rate | 4]]) -> 0 | AE10: =IFERROR(IF(Cost_Elements[[#This Row],[Row]]>='Do Not Use or Delete'!$L$2, IF(Cost_Elements[[#This Row],[Row]]<='Do Not Use or Delete'!$M$2,AC10*AD10,0),0)+IF(Cost_Elements[[#This Row],[Cost Elements]]=$A$113,SUM(INDIRECT("AC"&'Do Not Use or Delete'!$L$2 & ":" & "AC" & 'Do Not Use or Delete'!$M$2)),0)+IF(Cost_Elements[[#This Row],[Cost Elements]]=$A$127, SUM($AE$123:$AE$126),0)+IF(Cost_Elements[[#This Row],[Cost Elements]]=$A$131, SUM($AE$129,$AE$130))+IF(Cost_Elements[[#This Row],[Cost Elements]]=$A$119,SUMIFS(Cost_Elements[Amount | 5],Cost_Elements[Cost Elements],"Overhead"),0)+IF(Cost_Elements[[#This Row],[Cost Elements]]=$A$122,SUMIFS(Cost_Elements[Amount | 5],Cost_Elements[Cost Elements],"Fringe Benefits"),0)+IF(Cost_Elements[[#This Row],[Cost Elements]]=$A$123,SUMIFS(Cost_Elements[Amount | 5],Cost_Elements[Cost Elements],"Fringe Benefits")+SUMIFS(Cost_Elements[Amount | 5],Cost_Elements[Cost Elements],"Overhead"),IF(Cost_Elements[[#This Row],[Row]]>'Do Not Use or Delete'!$M$2,ROUND(Cost_Elements[[#This Row],[Rate | 5]]*Cost_Elements[[#This Row],[Hours | 5]],2),0))+IF(Cost_Elements[[#This Row],[Cost Elements]]=$A$128,$AE$127+$AE$113,0)+IF(Cost_Elements[[#This Row],[Cost Elements]]=$A$131,$AE$130+$AE$128,0)+IF(Cost_Elements[[#This Row],[Cost Elements]]=$A$272,SUM($AE$137:$AE$270),0)+IF(Cost_Elements[[#This Row],[Cost Elements]]=$A$278,SUM($AE$274:$AE$277),0)+IF(Cost_Elements[[#This Row],[Cost Elements]]=$A$279,$AE$272+$AE$278,0)+IF(Cost_Elements[[#This Row],[Cost Elements]]=$A$281,$AE$131+$AE$279,0)+IF(Cost_Elements[[#This Row],[Cost Elements]]=$A$286,SUM($AE$284:$AE$285),0)+IF(Cost_Elements[[#This Row],[Cost Elements]]=$A$288,$AE$286+$AE$281,0)+IF(Cost_Elements[[#This Row],[Cost Elements]]=$A$300,SUM($AE$291:$AE$299),0)+IF(Cost_Elements[[#This Row],[Cost Elements]]=$A$303,$AE$288+$AE$300,0),"") -> 0 | AH10: =IF(PRODUCT(Cost_Elements[[#This Row],[BLS or SCLS]]="BLS"),(Cost_Elements[[#This Row],[Rate | 5]]*$AI$4)+Cost_Elements[[#This Row],[Rate | 5]],(Cost_Elements[[#This Row],[Rate | 5]]*$AI$5)+Cost_Elements[[#This Row],[Rate | 5]]) -> 0 | AL10: =IFERROR(IF(Cost_Elements[[#This Row],[Row]]>='Do Not Use or Delete'!$L$2, IF(Cost_Elements[[#This Row],[Row]]<='Do Not Use or Delete'!$M$2,AH10*AI10,0),0)+IF(Cost_Elements[[#This Row],[Cost Elements]]=$A$113,SUM(INDIRECT("AC"&'Do Not Use or Delete'!$L$2 & ":" & "AC" & 'Do Not Use or Delete'!$M$2)),0)+IF(Cost_Elements[[#This Row],[Cost Elements]]=$A$127, SUM($AL$123:$AL$126),0)+IF(Cost_Elements[[#This Row],[Cost Elements]]=$A$131, SUM($AL$129,$AL$130))+IF(Cost_Elements[[#This Row],[Cost Elements]]=$A$119,SUMIFS(Cost_Elements[Amount | 6],Cost_Elements[Cost Elements],"Overhead"),0)+IF(Cost_Elements[[#This Row],[Cost Elements]]=$A$122,SUMIFS(Cost_Elements[Amount | 6],Cost_Elements[Cost Elements],"Fringe Benefits"),0)+IF(Cost_Elements[[#This Row],[Cost Elements]]=$A$123,SUMIFS(Cost_Elements[Amount | 6],Cost_Elements[Cost Elements],"Fringe Benefits")+SUMIFS(Cost_Elements[Amount | 6],Cost_Elements[Cost Elements],"Overhead"),IF(Cost_Elements[[#This Row],[Row]]>'Do Not Use or Delete'!$M$2,ROUND(Cost_Elements[[#This Row],[Rate | 6]]*Cost_Elements[[#This Row],[Hours | 6]],2),0))+IF(Cost_Elements[[#This Row],[Cost Elements]]=$A$128,$AL$127+$AL$113,0)+IF(Cost_Elements[[#This Row],[Cost Elements]]=$A$131,$AL$130+$AL$128,0)+IF(Cost_Elements[[#This Row],[Cost Elements]]=$A$272,SUM($AL$137:$AL$270),0)+IF(Cost_Elements[[#This Row],[Cost Elements]]=$A$278,SUM($AL$274:$AL$277),0)+IF(Cost_Elements[[#This Row],[Cost Elements]]=$A$279,$AL$272+$AL$278,0)+IF(Cost_Elements[[#This Row],[Cost Elements]]=$A$281,$AL$131+$AL$279,0)+IF(Cost_Elements[[#This Row],[Cost Elements]]=$A$286,SUM($AL$284:$AL$285),0)+IF(Cost_Elements[[#This Row],[Cost Elements]]=$A$288,$AL$286+$AL$281,0)+IF(Cost_Elements[[#This Row],[Cost Elements]]=$A$300,SUM($AL$291:$AL$299),0)+IF(Cost_Elements[[#This Row],[Cost Elements]]=$A$303,$AL$288+$AL$300,0),"") -> 0 | AO10: =J10+O10+T10+Y10+AD10+AI10 -> 0 | AP10: =K10+P10+U10+Z10+AE10+AL10 -> 0 | AQ10: =ROW(Cost_Elements[[#This Row],[Amount | Total]]) -> 10
A11: Employee Name or Prospective | H11: =IFERROR(INDEX(Labor_Categories[Minimum Direct Labor Rates],MATCH(Cost_Elements[[#This Row],[Government Labor Category]],Labor_Categories[Labor Categories],0)),"") | K11: =IFERROR(IF(Cost_Elements[[#This Row],[Row]]>='Do Not Use or Delete'!$L$2, IF(Cost_Elements[[#This Row],[Row]]<='Do Not Use or Delete'!$M$2,I11*J11,0),0)+IF(Cost_Elements[[#This Row],[Cost Elements]]=$A$113,SUM(INDIRECT("I"&'Do Not Use or Delete'!$L$2& ":" & "I" & 'Do Not Use or Delete'!$M$2)),0)+IF(Cost_Elements[[#This Row],[Cost Elements]]=$A$127, SUM($K$123:$K$126),0)+IF(Cost_Elements[[#This Row],[Cost Elements]]=$A$131, SUM($K$129,$K$130))+IF(Cost_Elements[[#This Row],[Cost Elements]]=$A$119,SUMIFS(Cost_Elements[Amount | 1],Cost_Elements[Cost Elements],"Overhead"),0)+IF(Cost_Elements[[#This Row],[Cost Elements]]=$A$122,SUMIFS(Cost_Elements[Amount | 1],Cost_Elements[Cost Elements],"Fringe Benefits"),0)+IF(Cost_Elements[[#This Row],[Cost Elements]]=$A$123,SUMIFS(Cost_Elements[Amount | 1],Cost_Elements[Cost Elements],"Fringe Benefits")+SUMIFS(Cost_Elements[Amount | 1],Cost_Elements[Cost Elements],"Overhead"),IF(Cost_Elements[[#This Row],[Row]]>'Do Not Use or Delete'!$M$2,ROUND(Cost_Elements[[#This Row],[Rate | 1]]*Cost_Elements[[#This Row],[Hours | 1]],2),0))+IF(Cost_Elements[[#This Row],[Cost Elements]]=$A$128,$K$127+$K$113,0)+IF(Cost_Elements[[#This Row],[Cost Elements]]=$A$131,$K$130+$K$128,0)+IF(Cost_Elements[[#This Row],[Cost Elements]]=$A$272,SUM($K$137:$K$270),0)+IF(Cost_Elements[[#This Row],[Cost Elements]]=$A$278,SUM($K$274:$K$277),0)+IF(Cost_Elements[[#This Row],[Cost Elements]]=$A$279,$K$272+$K$278,0)+IF(Cost_Elements[[#This Row],[Cost Elements]]=$A$281,$K$131+$K$279,0)+IF(Cost_Elements[[#This Row],[Cost Elements]]=$A$286,SUM($K$284:$K$285),0)+IF(Cost_Elements[[#This Row],[Cost Elements]]=$A$288,$K$286+$K$281,0)+IF(Cost_Elements[[#This Row],[Cost Elements]]=$A$300,SUM($K$291:$K$299),0)+IF(Cost_Elements[[#This Row],[Cost Elements]]=$A$303,$K$288+$K$300,0),"") -> 0 | N11: =IF(PRODUCT(Cost_Elements[[#This Row],[BLS or SCLS]]="BLS"),(Cost_Elements[[#This Row],[Rate | 1]]*$O$4)+Cost_Elements[[#This Row],[Rate | 1]],(Cost_Elements[[#This Row],[Rate | 1]]*$O$5)+Cost_Elements[[#This Row],[Rate | 1]]) -> 0 | P11: =IFERROR(IF(Cost_Elements[[#This Row],[Row]]>='Do Not Use or Delete'!$L$2, IF(Cost_Elements[[#This Row],[Row]]<='Do Not Use or Delete'!$M$2,N11*O11,0),0)+IF(Cost_Elements[[#This Row],[Cost Elements]]=$A$113,SUM(INDIRECT("N"&'Do Not Use or Delete'!$L$2 & ":" & "N" & 'Do Not Use or Delete'!$M$2)),0)+IF(Cost_Elements[[#This Row],[Cost Elements]]=$A$127, SUM($P$123:$P$126),0)+IF(Cost_Elements[[#This Row],[Cost Elements]]=$A$131, SUM($P$129,$P$130))+IF(Cost_Elements[[#This Row],[Cost Elements]]=$A$119,SUMIFS(Cost_Elements[Amount | 2],Cost_Elements[Cost Elements],"Overhead"),0)+IF(Cost_Elements[[#This Row],[Cost Elements]]=$A$122,SUMIFS(Cost_Elements[Amount | 2],Cost_Elements[Cost Elements],"Fringe Benefits"),0)+IF(Cost_Elements[[#This Row],[Cost Elements]]=$A$123,SUMIFS(Cost_Elements[Amount | 2],Cost_Elements[Cost Elements],"Fringe Benefits")+SUMIFS(Cost_Elements[Amount | 2],Cost_Elements[Cost Elements],"Overhead"),IF(Cost_Elements[[#This Row],[Row]]>'Do Not Use or Delete'!$M$2,ROUND(Cost_Elements[[#This Row],[Rate | 2]]*Cost_Elements[[#This Row],[Hours | 2]],2),0))+IF(Cost_Elements[[#This Row],[Cost Elements]]=$A$128,$P$127+$P$113,0)+IF(Cost_Elements[[#This Row],[Cost Elements]]=$A$131,$P$130+$P$128,0)+IF(Cost_Elements[[#This Row],[Cost Elements]]=$A$272,SUM($P$137:$P$270),0)+IF(Cost_Elements[[#This Row],[Cost Elements]]=$A$278,SUM($P$274:$P$277),0)+IF(Cost_Elements[[#This Row],[Cost Elements]]=$A$279,$P$272+$P$278,0)+IF(Cost_Elements[[#This Row],[Cost Elements]]=$A$281,$P$131+$P$279,0)+IF(Cost_Elements[[#This Row],[Cost Elements]]=$A$286,SUM($P$284:$P$285),0)+IF(Cost_Elements[[#This Row],[Cost Elements]]=$A$288,$P$286+$P$281,0)+IF(Cost_Elements[[#This Row],[Cost Elements]]=$A$300,SUM($P$291:$P$299),0)+IF(Cost_Elements[[#This Row],[Cost Elements]]=$A$303,$P$288+$P$300,0),"") -> 0 | S11: =IF(PRODUCT(Cost_Elements[[#This Row],[BLS or SCLS]]="BLS"),(Cost_Elements[[#This Row],[Rate | 2]]*$T$4)+Cost_Elements[[#This Row],[Rate | 2]],(Cost_Elements[[#This Row],[Rate | 2]]*$T$5)+Cost_Elements[[#This Row],[Rate | 2]]) -> 0 | U11: =IFERROR(IF(Cost_Elements[[#This Row],[Row]]>='Do Not Use or Delete'!$L$2, IF(Cost_Elements[[#This Row],[Row]]<='Do Not Use or Delete'!$M$2,S11*T11,0),0)+IF(Cost_Elements[[#This Row],[Cost Elements]]=$A$113,SUM(INDIRECT("S"&'Do Not Use or Delete'!$L$2 & ":" & "S" & 'Do Not Use or Delete'!$M$2)),0)+IF(Cost_Elements[[#This Row],[Cost Elements]]=$A$127, SUM($U$123:$U$126),0)+IF(Cost_Elements[[#This Row],[Cost Elements]]=$A$131, SUM($U$129,$U$130))+IF(Cost_Elements[[#This Row],[Cost Elements]]=$A$119,SUMIFS(Cost_Elements[Amount | 3],Cost_Elements[Cost Elements],"Overhead"),0)+IF(Cost_Elements[[#This Row],[Cost Elements]]=$A$122,SUMIFS(Cost_Elements[Amount | 3],Cost_Elements[Cost Elements],"Fringe Benefits"),0)+IF(Cost_Elements[[#This Row],[Cost Elements]]=$A$123,SUMIFS(Cost_Elements[Amount | 3],Cost_Elements[Cost Elements],"Fringe Benefits")+SUMIFS(Cost_Elements[Amount | 3],Cost_Elements[Cost Elements],"Overhead"),IF(Cost_Elements[[#This Row],[Row]]>'Do Not Use or Delete'!$M$2,ROUND(Cost_Elements[[#This Row],[Rate | 3]]*Cost_Elements[[#This Row],[Hours | 3]],2),0))+IF(Cost_Elements[[#This Row],[Cost Elements]]=$A$128,$U$127+$U$113,0)+IF(Cost_Elements[[#This Row],[Cost Elements]]=$A$131,$U$130+$U$128,0)+IF(Cost_Elements[[#This Row],[Cost Elements]]=$A$272,SUM($U$137:$U$270),0)+IF(Cost_Elements[[#This Row],[Cost Elements]]=$A$278,SUM($U$274:$U$277),0)+IF(Cost_Elements[[#This Row],[Cost Elements]]=$A$279,$U$272+$U$278,0)+IF(Cost_Elements[[#This Row],[Cost Elements]]=$A$281,$U$131+$U$279,0)+IF(Cost_Elements[[#This Row],[Cost Elements]]=$A$286,SUM($U$284:$U$285),0)+IF(Cost_Elements[[#This Row],[Cost Elements]]=$A$288,$U$286+$U$281,0)+IF(Cost_Elements[[#This Row],[Cost Elements]]=$A$300,SUM($U$291:$U$299),0)+IF(Cost_Elements[[#This Row],[Cost Elements]]=$A$303,$U$288+$U$300,0),"") -> 0 | X11: =IF(PRODUCT(Cost_Elements[[#This Row],[BLS or SCLS]]="BLS"),(Cost_Elements[[#This Row],[Rate | 3]]*$Y$4)+Cost_Elements[[#This Row],[Rate | 3]],(Cost_Elements[[#This Row],[Rate | 3]]*$Y$5)+Cost_Elements[[#This Row],[Rate | 3]]) -> 0 | Z11: =IFERROR(IF(Cost_Elements[[#This Row],[Row]]>='Do Not Use or Delete'!$L$2, IF(Cost_Elements[[#This Row],[Row]]<='Do Not Use or Delete'!$M$2,X11*Y11,0),0)+IF(Cost_Elements[[#This Row],[Cost Elements]]=$A$113,SUM(INDIRECT("X"&'Do Not Use or Delete'!$L$2 & ":" & "X" & 'Do Not Use or Delete'!$M$2)),0)+IF(Cost_Elements[[#This Row],[Cost Elements]]=$A$127, SUM($Z$123:$Z$126),0)+IF(Cost_Elements[[#This Row],[Cost Elements]]=$A$131, SUM($Z$129,$Z$130))+IF(Cost_Elements[[#This Row],[Cost Elements]]=$A$119,SUMIFS(Cost_Elements[Amount | 4],Cost_Elements[Cost Elements],"Overhead"),0)+IF(Cost_Elements[[#This Row],[Cost Elements]]=$A$122,SUMIFS(Cost_Elements[Amount | 4],Cost_Elements[Cost Elements],"Fringe Benefits"),0)+IF(Cost_Elements[[#This Row],[Cost Elements]]=$A$123,SUMIFS(Cost_Elements[Amount | 4],Cost_Elements[Cost Elements],"Fringe Benefits")+SUMIFS(Cost_Elements[Amount | 4],Cost_Elements[Cost Elements],"Overhead"),IF(Cost_Elements[[#This Row],[Row]]>'Do Not Use or Delete'!$M$2,ROUND(Cost_Elements[[#This Row],[Rate | 4]]*Cost_Elements[[#This Row],[Hours | 4]],2),0))+IF(Cost_Elements[[#This Row],[Cost Elements]]=$A$128,$Z$127+$Z$113,0)+IF(Cost_Elements[[#This Row],[Cost Elements]]=$A$131,$Z$130+$Z$128,0)+IF(Cost_Elements[[#This Row],[Cost Elements]]=$A$272,SUM($Z$137:$Z$270),0)+IF(Cost_Elements[[#This Row],[Cost Elements]]=$A$278,SUM($Z$274:$Z$277),0)+IF(Cost_Elements[[#This Row],[Cost Elements]]=$A$279,$Z$272+$Z$278,0)+IF(Cost_Elements[[#This Row],[Cost Elements]]=$A$281,$Z$131+$Z$279,0)+IF(Cost_Elements[[#This Row],[Cost Elements]]=$A$286,SUM($Z$284:$Z$285),0)+IF(Cost_Elements[[#This Row],[Cost Elements]]=$A$288,$Z$286+$Z$281,0)+IF(Cost_Elements[[#This Row],[Cost Elements]]=$A$300,SUM($Z$291:$Z$299),0)+IF(Cost_Elements[[#This Row],[Cost Elements]]=$A$303,$Z$288+$Z$300,0),"") -> 0 | AC11: =IF(PRODUCT(Cost_Elements[[#This Row],[BLS or SCLS]]="BLS"),(Cost_Elements[[#This Row],[Rate | 4]]*$AD$4)+Cost_Elements[[#This Row],[Rate | 4]],(Cost_Elements[[#This Row],[Rate | 4]]*$AD$5)+Cost_Elements[[#This Row],[Rate | 4]]) -> 0 | AE11: =IFERROR(IF(Cost_Elements[[#This Row],[Row]]>='Do Not Use or Delete'!$L$2, IF(Cost_Elements[[#This Row],[Row]]<='Do Not Use or Delete'!$M$2,AC11*AD11,0),0)+IF(Cost_Elements[[#This Row],[Cost Elements]]=$A$113,SUM(INDIRECT("AC"&'Do Not Use or Delete'!$L$2 & ":" & "AC" & 'Do Not Use or Delete'!$M$2)),0)+IF(Cost_Elements[[#This Row],[Cost Elements]]=$A$127, SUM($AE$123:$AE$126),0)+IF(Cost_Elements[[#This Row],[Cost Elements]]=$A$131, SUM($AE$129,$AE$130))+IF(Cost_Elements[[#This Row],[Cost Elements]]=$A$119,SUMIFS(Cost_Elements[Amount | 5],Cost_Elements[Cost Elements],"Overhead"),0)+IF(Cost_Elements[[#This Row],[Cost Elements]]=$A$122,SUMIFS(Cost_Elements[Amount | 5],Cost_Elements[Cost Elements],"Fringe Benefits"),0)+IF(Cost_Elements[[#This Row],[Cost Elements]]=$A$123,SUMIFS(Cost_Elements[Amount | 5],Cost_Elements[Cost Elements],"Fringe Benefits")+SUMIFS(Cost_Elements[Amount | 5],Cost_Elements[Cost Elements],"Overhead"),IF(Cost_Elements[[#This Row],[Row]]>'Do Not Use or Delete'!$M$2,ROUND(Cost_Elements[[#This Row],[Rate | 5]]*Cost_Elements[[#This Row],[Hours | 5]],2),0))+IF(Cost_Elements[[#This Row],[Cost Elements]]=$A$128,$AE$127+$AE$113,0)+IF(Cost_Elements[[#This Row],[Cost Elements]]=$A$131,$AE$130+$AE$128,0)+IF(Cost_Elements[[#This Row],[Cost Elements]]=$A$272,SUM($AE$137:$AE$270),0)+IF(Cost_Elements[[#This Row],[Cost Elements]]=$A$278,SUM($AE$274:$AE$277),0)+IF(Cost_Elements[[#This Row],[Cost Elements]]=$A$279,$AE$272+$AE$278,0)+IF(Cost_Elements[[#This Row],[Cost Elements]]=$A$281,$AE$131+$AE$279,0)+IF(Cost_Elements[[#This Row],[Cost Elements]]=$A$286,SUM($AE$284:$AE$285),0)+IF(Cost_Elements[[#This Row],[Cost Elements]]=$A$288,$AE$286+$AE$281,0)+IF(Cost_Elements[[#This Row],[Cost Elements]]=$A$300,SUM($AE$291:$AE$299),0)+IF(Cost_Elements[[#This Row],[Cost Elements]]=$A$303,$AE$288+$AE$300,0),"") -> 0 | AH11: =IF(PRODUCT(Cost_Elements[[#This Row],[BLS or SCLS]]="BLS"),(Cost_Elements[[#This Row],[Rate | 5]]*$AI$4)+Cost_Elements[[#This Row],[Rate | 5]],(Cost_Elements[[#This Row],[Rate | 5]]*$AI$5)+Cost_Elements[[#This Row],[Rate | 5]]) -> 0 | AL11: =IFERROR(IF(Cost_Elements[[#This Row],[Row]]>='Do Not Use or Delete'!$L$2, IF(Cost_Elements[[#This Row],[Row]]<='Do Not Use or Delete'!$M$2,AH11*AI11,0),0)+IF(Cost_Elements[[#This Row],[Cost Elements]]=$A$113,SUM(INDIRECT("AC"&'Do Not Use or Delete'!$L$2 & ":" & "AC" & 'Do Not Use or Delete'!$M$2)),0)+IF(Cost_Elements[[#This Row],[Cost Elements]]=$A$127, SUM($AL$123:$AL$126),0)+IF(Cost_Elements[[#This Row],[Cost Elements]]=$A$131, SUM($AL$129,$AL$130))+IF(Cost_Elements[[#This Row],[Cost Elements]]=$A$119,SUMIFS(Cost_Elements[Amount | 6],Cost_Elements[Cost Elements],"Overhead"),0)+IF(Cost_Elements[[#This Row],[Cost Elements]]=$A$122,SUMIFS(Cost_Elements[Amount | 6],Cost_Elements[Cost Elements],"Fringe Benefits"),0)+IF(Cost_Elements[[#This Row],[Cost Elements]]=$A$123,SUMIFS(Cost_Elements[Amount | 6],Cost_Elements[Cost Elements],"Fringe Benefits")+SUMIFS(Cost_Elements[Amount | 6],Cost_Elements[Cost Elements],"Overhead"),IF(Cost_Elements[[#This Row],[Row]]>'Do Not Use or Delete'!$M$2,ROUND(Cost_Elements[[#This Row],[Rate | 6]]*Cost_Elements[[#This Row],[Hours | 6]],2),0))+IF(Cost_Elements[[#This Row],[Cost Elements]]=$A$128,$AL$127+$AL$113,0)+IF(Cost_Elements[[#This Row],[Cost Elements]]=$A$131,$AL$130+$AL$128,0)+IF(Cost_Elements[[#This Row],[Cost Elements]]=$A$272,SUM($AL$137:$AL$270),0)+IF(Cost_Elements[[#This Row],[Cost Elements]]=$A$278,SUM($AL$274:$AL$277),0)+IF(Cost_Elements[[#This Row],[Cost Elements]]=$A$279,$AL$272+$AL$278,0)+IF(Cost_Elements[[#This Row],[Cost Elements]]=$A$281,$AL$131+$AL$279,0)+IF(Cost_Elements[[#This Row],[Cost Elements]]=$A$286,SUM($AL$284:$AL$285),0)+IF(Cost_Elements[[#This Row],[Cost Elements]]=$A$288,$AL$286+$AL$281,0)+IF(Cost_Elements[[#This Row],[Cost Elements]]=$A$300,SUM($AL$291:$AL$299),0)+IF(Cost_Elements[[#This Row],[Cost Elements]]=$A$303,$AL$288+$AL$300,0),"") -> 0 | AO11: =J11+O11+T11+Y11+AD11+AI11 -> 0 | AP11: =K11+P11+U11+Z11+AE11+AL11 -> 0 | AQ11: =ROW(Cost_Elements[[#This Row],[Amount | Total]]) -> 11
A12: Employee Name or Prospective | H12: =IFERROR(INDEX(Labor_Categories[Minimum Direct Labor Rates],MATCH(Cost_Elements[[#This Row],[Government Labor Category]],Labor_Categories[Labor Categories],0)),"") | K12: =IFERROR(IF(Cost_Elements[[#This Row],[Row]]>='Do Not Use or Delete'!$L$2, IF(Cost_Elements[[#This Row],[Row]]<='Do Not Use or Delete'!$M$2,I12*J12,0),0)+IF(Cost_Elements[[#This Row],[Cost Elements]]=$A$113,SUM(INDIRECT("I"&'Do Not Use or Delete'!$L$2& ":" & "I" & 'Do Not Use or Delete'!$M$2)),0)+IF(Cost_Elements[[#This Row],[Cost Elements]]=$A$127, SUM($K$123:$K$126),0)+IF(Cost_Elements[[#This Row],[Cost Elements]]=$A$131, SUM($K$129,$K$130))+IF(Cost_Elements[[#This Row],[Cost Elements]]=$A$119,SUMIFS(Cost_Elements[Amount | 1],Cost_Elements[Cost Elements],"Overhead"),0)+IF(Cost_Elements[[#This Row],[Cost Elements]]=$A$122,SUMIFS(Cost_Elements[Amount | 1],Cost_Elements[Cost Elements],"Fringe Benefits"),0)+IF(Cost_Elements[[#This Row],[Cost Elements]]=$A$123,SUMIFS(Cost_Elements[Amount | 1],Cost_Elements[Cost Elements],"Fringe Benefits")+SUMIFS(Cost_Elements[Amount | 1],Cost_Elements[Cost Elements],"Overhead"),IF(Cost_Elements[[#This Row],[Row]]>'Do Not Use or Delete'!$M$2,ROUND(Cost_Elements[[#This Row],[Rate | 1]]*Cost_Elements[[#This Row],[Hours | 1]],2),0))+IF(Cost_Elements[[#This Row],[Cost Elements]]=$A$128,$K$127+$K$113,0)+IF(Cost_Elements[[#This Row],[Cost Elements]]=$A$131,$K$130+$K$128,0)+IF(Cost_Elements[[#This Row],[Cost Elements]]=$A$272,SUM($K$137:$K$270),0)+IF(Cost_Elements[[#This Row],[Cost Elements]]=$A$278,SUM($K$274:$K$277),0)+IF(Cost_Elements[[#This Row],[Cost Elements]]=$A$279,$K$272+$K$278,0)+IF(Cost_Elements[[#This Row],[Cost Elements]]=$A$281,$K$131+$K$279,0)+IF(Cost_Elements[[#This Row],[Cost Elements]]=$A$286,SUM($K$284:$K$285),0)+IF(Cost_Elements[[#This Row],[Cost Elements]]=$A$288,$K$286+$K$281,0)+IF(Cost_Elements[[#This Row],[Cost Elements]]=$A$300,SUM($K$291:$K$299),0)+IF(Cost_Elements[[#This Row],[Cost Elements]]=$A$303,$K$288+$K$300,0),"") -> 0 | N12: =IF(PRODUCT(Cost_Elements[[#This Row],[BLS or SCLS]]="BLS"),(Cost_Elements[[#This Row],[Rate | 1]]*$O$4)+Cost_Elements[[#This Row],[Rate | 1]],(Cost_Elements[[#This Row],[Rate | 1]]*$O$5)+Cost_Elements[[#This Row],[Rate | 1]]) -> 0 | P12: =IFERROR(IF(Cost_Elements[[#This Row],[Row]]>='Do Not Use or Delete'!$L$2, IF(Cost_Elements[[#This Row],[Row]]<='Do Not Use or Delete'!$M$2,N12*O12,0),0)+IF(Cost_Elements[[#This Row],[Cost Elements]]=$A$113,SUM(INDIRECT("N"&'Do Not Use or Delete'!$L$2 & ":" & "N" & 'Do Not Use or Delete'!$M$2)),0)+IF(Cost_Elements[[#This Row],[Cost Elements]]=$A$127, SUM($P$123:$P$126),0)+IF(Cost_Elements[[#This Row],[Cost Elements]]=$A$131, SUM($P$129,$P$130))+IF(Cost_Elements[[#This Row],[Cost Elements]]=$A$119,SUMIFS(Cost_Elements[Amount | 2],Cost_Elements[Cost Elements],"Overhead"),0)+IF(Cost_Elements[[#This Row],[Cost Elements]]=$A$122,SUMIFS(Cost_Elements[Amount | 2],Cost_Elements[Cost Elements],"Fringe Benefits"),0)+IF(Cost_Elements[[#This Row],[Cost Elements]]=$A$123,SUMIFS(Cost_Elements[Amount | 2],Cost_Elements[Cost Elements],"Fringe Benefits")+SUMIFS(Cost_Elements[Amount | 2],Cost_Elements[Cost Elements],"Overhead"),IF(Cost_Elements[[#This Row],[Row]]>'Do Not Use or Delete'!$M$2,ROUND(Cost_Elements[[#This Row],[Rate | 2]]*Cost_Elements[[#This Row],[Hours | 2]],2),0))+IF(Cost_Elements[[#This Row],[Cost Elements]]=$A$128,$P$127+$P$113,0)+IF(Cost_Elements[[#This Row],[Cost Elements]]=$A$131,$P$130+$P$128,0)+IF(Cost_Elements[[#This Row],[Cost Elements]]=$A$272,SUM($P$137:$P$270),0)+IF(Cost_Elements[[#This Row],[Cost Elements]]=$A$278,SUM($P$274:$P$277),0)+IF(Cost_Elements[[#This Row],[Cost Elements]]=$A$279,$P$272+$P$278,0)+IF(Cost_Elements[[#This Row],[Cost Elements]]=$A$281,$P$131+$P$279,0)+IF(Cost_Elements[[#This Row],[Cost Elements]]=$A$286,SUM($P$284:$P$285),0)+IF(Cost_Elements[[#This Row],[Cost Elements]]=$A$288,$P$286+$P$281,0)+IF(Cost_Elements[[#This Row],[Cost Elements]]=$A$300,SUM($P$291:$P$299),0)+IF(Cost_Elements[[#This Row],[Cost Elements]]=$A$303,$P$288+$P$300,0),"") -> 0 | S12: =IF(PRODUCT(Cost_Elements[[#This Row],[BLS or SCLS]]="BLS"),(Cost_Elements[[#This Row],[Rate | 2]]*$T$4)+Cost_Elements[[#This Row],[Rate | 2]],(Cost_Elements[[#This Row],[Rate | 2]]*$T$5)+Cost_Elements[[#This Row],[Rate | 2]]) -> 0 | U12: =IFERROR(IF(Cost_Elements[[#This Row],[Row]]>='Do Not Use or Delete'!$L$2, IF(Cost_Elements[[#This Row],[Row]]<='Do Not Use or Delete'!$M$2,S12*T12,0),0)+IF(Cost_Elements[[#This Row],[Cost Elements]]=$A$113,SUM(INDIRECT("S"&'Do Not Use or Delete'!$L$2 & ":" & "S" & 'Do Not Use or Delete'!$M$2)),0)+IF(Cost_Elements[[#This Row],[Cost Elements]]=$A$127, SUM($U$123:$U$126),0)+IF(Cost_Elements[[#This Row],[Cost Elements]]=$A$131, SUM($U$129,$U$130))+IF(Cost_Elements[[#This Row],[Cost Elements]]=$A$119,SUMIFS(Cost_Elements[Amount | 3],Cost_Elements[Cost Elements],"Overhead"),0)+IF(Cost_Elements[[#This Row],[Cost Elements]]=$A$122,SUMIFS(Cost_Elements[Amount | 3],Cost_Elements[Cost Elements],"Fringe Benefits"),0)+IF(Cost_Elements[[#This Row],[Cost Elements]]=$A$123,SUMIFS(Cost_Elements[Amount | 3],Cost_Elements[Cost Elements],"Fringe Benefits")+SUMIFS(Cost_Elements[Amount | 3],Cost_Elements[Cost Elements],"Overhead"),IF(Cost_Elements[[#This Row],[Row]]>'Do Not Use or Delete'!$M$2,ROUND(Cost_Elements[[#This Row],[Rate | 3]]*Cost_Elements[[#This Row],[Hours | 3]],2),0))+IF(Cost_Elements[[#This Row],[Cost Elements]]=$A$128,$U$127+$U$113,0)+IF(Cost_Elements[[#This Row],[Cost Elements]]=$A$131,$U$130+$U$128,0)+IF(Cost_Elements[[#This Row],[Cost Elements]]=$A$272,SUM($U$137:$U$270),0)+IF(Cost_Elements[[#This Row],[Cost Elements]]=$A$278,SUM($U$274:$U$277),0)+IF(Cost_Elements[[#This Row],[Cost Elements]]=$A$279,$U$272+$U$278,0)+IF(Cost_Elements[[#This Row],[Cost Elements]]=$A$281,$U$131+$U$279,0)+IF(Cost_Elements[[#This Row],[Cost Elements]]=$A$286,SUM($U$284:$U$285),0)+IF(Cost_Elements[[#This Row],[Cost Elements]]=$A$288,$U$286+$U$281,0)+IF(Cost_Elements[[#This Row],[Cost Elements]]=$A$300,SUM($U$291:$U$299),0)+IF(Cost_Elements[[#This Row],[Cost Elements]]=$A$303,$U$288+$U$300,0),"") -> 0 | X12: =IF(PRODUCT(Cost_Elements[[#This Row],[BLS or SCLS]]="BLS"),(Cost_Elements[[#This Row],[Rate | 3]]*$Y$4)+Cost_Elements[[#This Row],[Rate | 3]],(Cost_Elements[[#This Row],[Rate | 3]]*$Y$5)+Cost_Elements[[#This Row],[Rate | 3]]) -> 0 | Z12: =IFERROR(IF(Cost_Elements[[#This Row],[Row]]>='Do Not Use or Delete'!$L$2, IF(Cost_Elements[[#This Row],[Row]]<='Do Not Use or Delete'!$M$2,X12*Y12,0),0)+IF(Cost_Elements[[#This Row],[Cost Elements]]=$A$113,SUM(INDIRECT("X"&'Do Not Use or Delete'!$L$2 & ":" & "X" & 'Do Not Use or Delete'!$M$2)),0)+IF(Cost_Elements[[#This Row],[Cost Elements]]=$A$127, SUM($Z$123:$Z$126),0)+IF(Cost_Elements[[#This Row],[Cost Elements]]=$A$131, SUM($Z$129,$Z$130))+IF(Cost_Elements[[#This Row],[Cost Elements]]=$A$119,SUMIFS(Cost_Elements[Amount | 4],Cost_Elements[Cost Elements],"Overhead"),0)+IF(Cost_Elements[[#This Row],[Cost Elements]]=$A$122,SUMIFS(Cost_Elements[Amount | 4],Cost_Elements[Cost Elements],"Fringe Benefits"),0)+IF(Cost_Elements[[#This Row],[Cost Elements]]=$A$123,SUMIFS(Cost_Elements[Amount | 4],Cost_Elements[Cost Elements],"Fringe Benefits")+SUMIFS(Cost_Elements[Amount | 4],Cost_Elements[Cost Elements],"Overhead"),IF(Cost_Elements[[#This Row],[Row]]>'Do Not Use or Delete'!$M$2,ROUND(Cost_Elements[[#This Row],[Rate | 4]]*Cost_Elements[[#This Row],[Hours | 4]],2),0))+IF(Cost_Elements[[#This Row],[Cost Elements]]=$A$128,$Z$127+$Z$113,0)+IF(Cost_Elements[[#This Row],[Cost Elements]]=$A$131,$Z$130+$Z$128,0)+IF(Cost_Elements[[#This Row],[Cost Elements]]=$A$272,SUM($Z$137:$Z$270),0)+IF(Cost_Elements[[#This Row],[Cost Elements]]=$A$278,SUM($Z$274:$Z$277),0)+IF(Cost_Elements[[#This Row],[Cost Elements]]=$A$279,$Z$272+$Z$278,0)+IF(Cost_Elements[[#This Row],[Cost Elements]]=$A$281,$Z$131+$Z$279,0)+IF(Cost_Elements[[#This Row],[Cost Elements]]=$A$286,SUM($Z$284:$Z$285),0)+IF(Cost_Elements[[#This Row],[Cost Elements]]=$A$288,$Z$286+$Z$281,0)+IF(Cost_Elements[[#This Row],[Cost Elements]]=$A$300,SUM($Z$291:$Z$299),0)+IF(Cost_Elements[[#This Row],[Cost Elements]]=$A$303,$Z$288+$Z$300,0),"") -> 0 | AC12: =IF(PRODUCT(Cost_Elements[[#This Row],[BLS or SCLS]]="BLS"),(Cost_Elements[[#This Row],[Rate | 4]]*$AD$4)+Cost_Elements[[#This Row],[Rate | 4]],(Cost_Elements[[#This Row],[Rate | 4]]*$AD$5)+Cost_Elements[[#This Row],[Rate | 4]]) -> 0 | AE12: =IFERROR(IF(Cost_Elements[[#This Row],[Row]]>='Do Not Use or Delete'!$L$2, IF(Cost_Elements[[#This Row],[Row]]<='Do Not Use or Delete'!$M$2,AC12*AD12,0),0)+IF(Cost_Elements[[#This Row],[Cost Elements]]=$A$113,SUM(INDIRECT("AC"&'Do Not Use or Delete'!$L$2 & ":" & "AC" & 'Do Not Use or Delete'!$M$2)),0)+IF(Cost_Elements[[#This Row],[Cost Elements]]=$A$127, SUM($AE$123:$AE$126),0)+IF(Cost_Elements[[#This Row],[Cost Elements]]=$A$131, SUM($AE$129,$AE$130))+IF(Cost_Elements[[#This Row],[Cost Elements]]=$A$119,SUMIFS(Cost_Elements[Amount | 5],Cost_Elements[Cost Elements],"Overhead"),0)+IF(Cost_Elements[[#This Row],[Cost Elements]]=$A$122,SUMIFS(Cost_Elements[Amount | 5],Cost_Elements[Cost Elements],"Fringe Benefits"),0)+IF(Cost_Elements[[#This Row],[Cost Elements]]=$A$123,SUMIFS(Cost_Elements[Amount | 5],Cost_Elements[Cost Elements],"Fringe Benefits")+SUMIFS(Cost_Elements[Amount | 5],Cost_Elements[Cost Elements],"Overhead"),IF(Cost_Elements[[#This Row],[Row]]>'Do Not Use or Delete'!$M$2,ROUND(Cost_Elements[[#This Row],[Rate | 5]]*Cost_Elements[[#This Row],[Hours | 5]],2),0))+IF(Cost_Elements[[#This Row],[Cost Elements]]=$A$128,$AE$127+$AE$113,0)+IF(Cost_Elements[[#This Row],[Cost Elements]]=$A$131,$AE$130+$AE$128,0)+IF(Cost_Elements[[#This Row],[Cost Elements]]=$A$272,SUM($AE$137:$AE$270),0)+IF(Cost_Elements[[#This Row],[Cost Elements]]=$A$278,SUM($AE$274:$AE$277),0)+IF(Cost_Elements[[#This Row],[Cost Elements]]=$A$279,$AE$272+$AE$278,0)+IF(Cost_Elements[[#This Row],[Cost Elements]]=$A$281,$AE$131+$AE$279,0)+IF(Cost_Elements[[#This Row],[Cost Elements]]=$A$286,SUM($AE$284:$AE$285),0)+IF(Cost_Elements[[#This Row],[Cost Elements]]=$A$288,$AE$286+$AE$281,0)+IF(Cost_Elements[[#This Row],[Cost Elements]]=$A$300,SUM($AE$291:$AE$299),0)+IF(Cost_Elements[[#This Row],[Cost Elements]]=$A$303,$AE$288+$AE$300,0),"") -> 0 | AH12: =IF(PRODUCT(Cost_Elements[[#This Row],[BLS or SCLS]]="BLS"),(Cost_Elements[[#This Row],[Rate | 5]]*$AI$4)+Cost_Elements[[#This Row],[Rate | 5]],(Cost_Elements[[#This Row],[Rate | 5]]*$AI$5)+Cost_Elements[[#This Row],[Rate | 5]]) -> 0 | AL12: =IFERROR(IF(Cost_Elements[[#This Row],[Row]]>='Do Not Use or Delete'!$L$2, IF(Cost_Elements[[#This Row],[Row]]<='Do Not Use or Delete'!$M$2,AH12*AI12,0),0)+IF(Cost_Elements[[#This Row],[Cost Elements]]=$A$113,SUM(INDIRECT("AC"&'Do Not Use or Delete'!$L$2 & ":" & "AC" & 'Do Not Use or Delete'!$M$2)),0)+IF(Cost_Elements[[#This Row],[Cost Elements]]=$A$127, SUM($AL$123:$AL$126),0)+IF(Cost_Elements[[#This Row],[Cost Elements]]=$A$131, SUM($AL$129,$AL$130))+IF(Cost_Elements[[#This Row],[Cost Elements]]=$A$119,SUMIFS(Cost_Elements[Amount | 6],Cost_Elements[Cost Elements],"Overhead"),0)+IF(Cost_Elements[[#This Row],[Cost Elements]]=$A$122,SUMIFS(Cost_Elements[Amount | 6],Cost_Elements[Cost Elements],"Fringe Benefits"),0)+IF(Cost_Elements[[#This Row],[Cost Elements]]=$A$123,SUMIFS(Cost_Elements[Amount | 6],Cost_Elements[Cost Elements],"Fringe Benefits")+SUMIFS(Cost_Elements[Amount | 6],Cost_Elements[Cost Elements],"Overhead"),IF(Cost_Elements[[#This Row],[Row]]>'Do Not Use or Delete'!$M$2,ROUND(Cost_Elements[[#This Row],[Rate | 6]]*Cost_Elements[[#This Row],[Hours | 6]],2),0))+IF(Cost_Elements[[#This Row],[Cost Elements]]=$A$128,$AL$127+$AL$113,0)+IF(Cost_Elements[[#This Row],[Cost Elements]]=$A$131,$AL$130+$AL$128,0)+IF(Cost_Elements[[#This Row],[Cost Elements]]=$A$272,SUM($AL$137:$AL$270),0)+IF(Cost_Elements[[#This Row],[Cost Elements]]=$A$278,SUM($AL$274:$AL$277),0)+IF(Cost_Elements[[#This Row],[Cost Elements]]=$A$279,$AL$272+$AL$278,0)+IF(Cost_Elements[[#This Row],[Cost Elements]]=$A$281,$AL$131+$AL$279,0)+IF(Cost_Elements[[#This Row],[Cost Elements]]=$A$286,SUM($AL$284:$AL$285),0)+IF(Cost_Elements[[#This Row],[Cost Elements]]=$A$288,$AL$286+$AL$281,0)+IF(Cost_Elements[[#This Row],[Cost Elements]]=$A$300,SUM($AL$291:$AL$299),0)+IF(Cost_Elements[[#This Row],[Cost Elements]]=$A$303,$AL$288+$AL$300,0),"") -> 0 | AO12: =J12+O12+T12+Y12+AD12+AI12 -> 0 | AP12: =K12+P12+U12+Z12+AE12+AL12 -> 0 | AQ12: =ROW(Cost_Elements[[#This Row],[Amount | Total]]) -> 12
