Workbook
Name Activity: 'PickList Tables'!$L$22:$L$24
Name Category: Table208[Equipment Category]
Name Contract_Type: 'PickList Tables'!$B$22:$B$41
Name COTS_GOTS: 'PickList Tables'!$F$22:$F$24
Name Data_Description: 'PickList Tables'!$AB$22:$AB$28
Name Data_Management: 'PickList Tables'!$P$22:$P$23
Name Development_Strategy: 'PickList Tables'!$J$22:$J$29
Name Domain_Level: 'PickList Tables'!$T$22:$T$25
Name ECP: 'PickList Tables'!$N$22:$N$26
Name Functions: 'PickList Tables'!$D$22:$D$28
Name Information_Assurance: 'PickList Tables'!$AD$22:$AD$27
Name Networking: 'PickList Tables'!$AP$22:$AP$23
Name NoT: 'PickList Tables'!$V$22:$V$25
Name Performance_Attributes: 'PickList Tables'!$X$22:$X$25
Name Pricing_Strategy: 'PickList Tables'!$H$22:$H$29
Name Protection_Level: 'PickList Tables'!$AH$22:$AH$27
Name Security: 'PickList Tables'!$Z$22:$Z$26
Name Servers: 'PickList Tables'!$AL$22:$AL$23
Name Services: 'PickList Tables'!$AT$22:$AT$28
Name Storage: 'PickList Tables'!$AR$22:$AR$26
Name SW_Code_Type: 'PickList Tables'!$AF$22:$AF$26
Name Workstations: 'PickList Tables'!$AN$22:$AN$23
Name YN_Option: 'PickList Tables'!$R$22:$R$24

Sheet 1 Introduction
J2: CLASSIFICATION: UNCLASSIFIED

Sheet 2 Program Info
D2: CLASSIFICATION: UNCLASSIFIED
G7: Contact Information:
G8: Name:
G9: Phone Number (Secure):
G10: Phone Number (Non-Secure):
G11: Email (Secure and Non-Secure):
G12: Organization:
G13: Date of Information Provided:
G14: Date of Information Accuracy:
B17: Program Description
B18: a. Program | C18: b. Primary Program Function | D18: c. Secondary Program Function | E18: d. Protection Level
B21: e. Domain Level | C21: f. # of Users | D21: g. # of Accounts | E21: h. Retention Requirements
B27: Program Milestones
B28: i. Schedule Milestone | C28: j. Current Schedule | D28: k. Comments/Notes
B34: Architecture Description | I34: DoDAF SV-6 Content
B35: l. Program Name | C35: m. Contract # | D35: n. Release / Delivery | E35: o. Subsystem | F35: p. Total Users | G35: q. Number of Interfaces | H35: r. Number of Legacy Systems Replaced | I35: s1. Nature of Transaction (L1) | J35: s2. Nature of Transaction (L2) | K35: t1. Performance Attributes (L1) | L35: t2. Performance Attributes (L2) | M35: u1. Security (L1) | N35: u2. Security (L2) | O35: v1. Data Description (L1) | P35: v2. Data Description (L2) | Q35: w1. Information Assurance (L1) | R35: w2. Information Assurance (L2) | S35: x. Reference Document Name(s) if applicable | T35: y. Comments/Notes
B36: {=Table40[a. Program]} -> 0 | C36: =' 3 Contract Info'!$B$22 -> 0
B37: {=Table40[a. Program]} -> 0 | C37: =' 3 Contract Info'!$B$22 -> 0
B38: {=Table40[a. Program]} -> 0 | C38: =' 3 Contract Info'!$B$22 -> 0
B39: {=Table40[a. Program]} -> 0 | C39: =' 3 Contract Info'!$B$22 -> 0
B40: {=Table40[a. Program]} -> 0 | C40: =' 3 Contract Info'!$B$22 -> 0
B41: {=Table40[a. Program]} -> 0 | C41: =' 3 Contract Info'!$B$22 -> 0
B42: {=Table40[a. Program]} -> 0 | C42: =' 3 Contract Info'!$B$22 -> 0
B43: {=Table40[a. Program]} -> 0 | C43: =' 3 Contract Info'!$B$22 -> 0
B44: {=Table40[a. Program]} -> 0 | C44: =' 3 Contract Info'!$B$22 -> 0
B45: {=Table40[a. Program]} -> 0 | C45: =' 3 Contract Info'!$B$22 -> 0
B46: {=Table40[a. Program]} -> 0 | C46: =' 3 Contract Info'!$B$22 -> 0
B47: {=Table40[a. Program]} -> 0 | C47: =' 3 Contract Info'!$B$22 -> 0
... B69: {=Table40[a. Program]} -> 0 | C69: =' 3 Contract Info'!$B$22 -> 0

Sheet  3 Contract Info
D2: CLASSIFICATION: UNCLASSIFIED
F6: Contact Information:
F7: Name:
F8: Phone Number (Secure):
F9: Phone Number (Non-Secure):
F10: Email (Secure and Non-Secure):
F11: Organization:
F12: Date of Information Provided:
F13: Date of Information Accuracy:
B16: Prime Contractor
B17: a. Company Name | C17: b. Location of Contractor | D17: c. Contract Type | E17: d. Contract Start Date | F17: e. Contract End Date | G17: f. Total Contract Value | H17: g. % Subcontracted | I17: h. Comments/Notes
B20: Prime Contractor Option Year Contract
B21: i. Contract # | C21: j. Base/Option Year Number | D21: k. Contract Start Date | E21: l. Contract End Date | F21: m. Option Executed | G21: n. Hours/FTE | H21: o. Comments/Notes
B28: Sub-Contractors
B29: p. Company Name | C29: q. Location of Contractor | D29: r. Contract Type | E29: s. Contract # | F29: t. Contract Start Date | G29: u. Contract End Date | H29: v. Total Sub-Contract Value | I29: w. Comments/Notes
B36: Sub-Contractor Option Year Contract
B37: x. Contract # | C37: y. Base/Option Year Number | D37: z. Contract Start Date | E37: aa. Contract End Date | F37: bb. Option Executed | G37: cc. Hours/FTE | H37: dd. Comments/Notes
B44: Contract Line Identification Number Description
B45: ee. Contract # | C45: ff. Contract Line Number | D45: gg. Contract Line Number Value | E45: hh. Descriptions | F45: ii. Comments/Notes
B56: Engineering Change Proposals
B57: jj. Program Name | C57: kk. Contract # | D57: ll. ECP Number | E57: mm. ECP Description | F57: nn. ECP Type | G57: oo. ATP Date | H57: pp. Negotiated Duration of ECP | I57: qq. Negotiated ECP Value
B58: {=Table40[a. Program]} -> 0 | C58: =$B$22 -> 0
B59: {=Table40[a. Program]} -> 0 | C59: =$B$22 -> 0
B60: {=Table40[a. Program]} -> 0 | C60: =$B$22 -> 0
B61: {=Table40[a. Program]} -> 0 | C61: =$B$22 -> 0
B62: {=Table40[a. Program]} -> 0 | C62: =$B$22 -> 0
B63: {=Table40[a. Program]} -> 0 | C63: =$B$22 -> 0
B64: {=Table40[a. Program]} -> 0 | C64: =$B$22 -> 0
B65: {=Table40[a. Program]} -> 0 | C65: =$B$22 -> 0
B66: {=Table40[a. Program]} -> 0 | C66: =$B$22 -> 0
B67: {=Table40[a. Program]} -> 0 | C67: =$B$22 -> 0
B68: {=Table40[a. Program]} -> 0 | C68: =$B$22 -> 0
B69: {=Table40[a. Program]} -> 0 | C69: =$B$22 -> 0

Sheet  4 WBS
C2: CLASSIFICATION: UNCLASSIFIED
G7: Contact Information:
G8: Name:
G9: Phone Number (Secure):
G10: Phone Number (Non-Secure):
G11: Email (Secure and Non-Secure):
G12: Organization:
G13: Date of Information Provided:
G14: Date of Information Accuracy:
B23: Function Represented:
A24: WBS # | B24: Term | C24: Definition | D24: Hours - Total | E24: Hours - % Prime Contractor | F24: Hours - % Subcontractor | G24: Cost - Total | H24: Cost - % Prime Contractor | I24: Cost - % Subcontractor
A25: 1 | B25: Total
A26: 1.1 | B26: SEITPM | C26: Management, system engineering, and integration efforts of day-to-day activities, through all phases of the program (Development, Production, O&M, etc.…). Includes, for example: a. Program Office SEITPM & Risk Management b. Integration and coordination with other programs c. Planning and implementation of technical integration efforts, as well as the testing and evaluation of required software and hardware
A27: 1.1.1 | B27: Program Management | C27: Management of day-to-day activities, through all phases of the program (Development, Production, O&M, etc.…). Includes, for example: a. Management direction (planning and direction of contract activities) b. Planning, schedule management, and control (preparing and maintaining integrated contract master schedule) c. Cost and performance management (analysis and control for cost expenditures, cost performance, cost estimation, budget planning, budget execution, report generation, EVM performance, etc.) d. Contract, subcontract, and procurement administration (subcontract management and tracking) e. Configuration management (efforts and procedures for control of program baseline to include proper tracking of GFE/GFI items) f. Quality assurance (provide adequate confidence that a product or service will satisfy given requirements for quality) g. Business process engineering program management (review, analyze, and develop business management processes) h. Security management (security management efforts consistent with approved policies, procedures, and facilities) i. Data management (control, tracking, documentation, distribution [as in the form of an integrated development environment or IDE], and disposition) j. ROM/ECP management and preparation k. Source selection support l. Development, implementation, and operation of a proactive risk management program to include risk identification, quantification, and management Excluded costs include: a. Actual mitigation or risk avoidance costs b. Costs tied to specific risks c. Travel costs d. Training costs
A28: 1.1.2 | B28: System Engineering | C28: The application of engineering in the context of the lifetime use of the system. Includes, for example: System engineering activities performed to evaluate and or investigate options and alternative system designs.
A29: 1.1.2.1 | B29: System Design and Architecture | C29: Technical effort required to transform user requirements into a system solution. Includes, for example: a. Systems engineering management (manage engineering design and development) b. Systems requirements analysis and allocation c. Systems architecture analysis and design (design and evaluate architecture alternatives) d. Systems analysis and control (systems verification and validation, document requirements verification traceability matrix) e. Data architecture and engineering (develop overall data architecture, data migration planning, data synchronization) f. Systems migration and transition planning (develop transition and migration plan) g. Systems security engineering (design systems security consistent with approved policies, procedures, and facilities) h. Technology insertion and pre-production environment (engineer inclusion of advanced technologies) i. Facility planning and engineering (design and develop all facilities) j. Integrated logistics support (design and develop logistics support)
A30: 1.1.2.2 | B30: Special Studies | C30: System engineering activities performed to evaluate or investigate alternative options for future execution. Includes, for example: a. Assessment of advanced technologies for future incorporation into the system b. Evaluation of alternatives to solve a capability shortfall or system deficiency Excludes, for example: a. Development and incorporation of advanced technologies into the system
A31: 1.1.3 | B31: Integration and Test | C31: Planning and implementation of technical integration efforts, as well as the testing and evaluation of required software and hardware.
A32: 1.1.3.1 | B32: Test and Evaluation | C32: Planning and performing Test and Evaluation functions for prototype, new, or modified systems. T&E emphasis areas include interoperability, information and system assurance, reliability and maintainability. Includes, for example: a. Developmental Test and Evaluation associated with the system b. Operational Test and Evaluation associated with the system c. System Wide Testing performed with all relevant program and system components. c. If IV&V cannot be captured separately, please capture it here
A33: 1.1.3.2 | B33: Independent Verification and Validation (IV&V) | C33: Independent planning, support, and testing of a system to ensure that it meets all stated performance requirements, processes and procedures. This work is performed by an independent team not involved in the development effort. Includes, for example: a. Program level support and personnel doing the IV&V work
A34: 1.1.3.4 | B34: System Integration | C34: Development and implementation of an integration plan, includes the integration and assembly of the system with emphasis on risk management and continuing verification of all external and internal interfaces (physical, functional and logical).
A35: 1.1.4 | B35: Site Surveys/Activation Sites 1…n (Specify) | C35: Site survey, preparation, and activation of sites for the acceptance and operation of equipment.
A36: 1.1.5 | B36: Travel | C36: Personnel travel required during the lifecycle of the system. Includes, for example: Travel associated with the following activities: a. Program Management b. Deployment c. Engineering d. Operations and Maintenance e. Training travel for trainees (applicable to program) Excludes, for example: a. Trainer travel (captured in section related to Training)
A37: 1.2 | B37: Training | C37: Development, execution and maintenance of training to provide instruction to support the prime mission product.
A38: 1.2.1 | B38: Training Development | C38: Procuring or developing the appropriate training programs and materials to provide instruction to program personnel. Includes, for example: a. The cost of developing and/or procuring the appropriate tutorial programs, training tapes, aids, services, and equipment that trainers use to facilitate instruction to program personnel b. The resources and services expended to structure and develop the training class Excludes, for example: a. Any effort associated with actually executing training
A39: 1.2.2 | B39: Training Execution | C39: Training for managers, operators, maintainers, and support personnel. Includes, for example: a. Student materials (binders, handouts, etc.…) b. Training equipment and devices c. Instructors d. Instructor travel e. Training time f: Train the Trainer g: Training site fees
A40: 1.3 | B40: Custom Software | C40: Development and maintenance of source code
A41: 1.3.1 | B41: SW SEITPM | C41: Any systems engineering, integration and test, and program management activities that are specifically associated with the developed SW for the system. Includes, for example: a. The integration of multiple custom software configuration items
A42: 1.3.2 | B42: Custom SW Development Source Code | C42: Development of source code for a specific block/spiral/release. Includes, for example: a. Writing the actual source code and conducting unit level testing of that code as part of the programming process b. Software components, consisting of the source code/applications that satisfy an end use function
A43: 1.3.2.1 | B43: Custom SW Source Code SEIT | C43: Analysis of preliminary software requirements for source code. Derive and map out software design specifications for source code. Analysis of preliminary interface design specifications for source code. Integration and test verification and validation of the source code. Includes for example: a. generating input to software test plans, descriptions, and procedures b. defining software test cases c. performing software build and test Excludes, for example: a. System level IV&V
A44: 1.3.2.2 | B44: Custom SW Source Code Development (CSCI 1...n; Specify) and Unit Test | C44: Development through unit testing of source code by CSCI 1…n. Note: A Computer Software Configuration Item (CSCI) is an aggregation of software that satisfies a function and is designated for separate configuration management by the acquirer.
A45: 1.3.3 | B45: Custom SW Development Glue/Wrapper Code | C45: Development of glue/wrapper code for a specific block/spiral/release. Glue/wrapper code is defined as any code that ensures proper interface and operation of COTS, GOTS and Custom SW applications. Includes, for example: a. Writing the actual glue/wrapper code and conducting unit testing of that glue/wrapper code
A46: 1.3.3.1 | B46: Custom SW Glue/Wrapper Code SEIT | C46: Analysis of preliminary software requirements for glue/wrapper code. Derive and map out software/database design specifications for glue/wrapper code. Analysis of preliminary interface design specifications for glue/wrapper code. Integration and test verification and validation of the glue/wrapper code. Includes for example: a. generating input to software test plans, descriptions, and procedures b. defining software test cases c. performing software build and test Excludes, for example: a. System level IV&V
A47: 1.3.3.2 | B47: Custom SW Glue Code Development (CSCI 1...n; Specify) and Unit Test | C47: Development of glue code through unit test by CSCI 1…n.
A48: 1.3.4 | B48: Database Development Code and Unit Test | C48: Development of all the database code for a specific block/spiral/release. Includes, for example: a. Creation and modification of database tables and queries
A49: 1.3.4.1 | B49: Custom SW Database Development Code SEIT | C49: Analysis of preliminary software/database requirements for Database Development code. Derive and map out software/database design specifications for Database Development code. Analysis of preliminary interface design specifications for Database Development code. Integration and test verification and validation of the Database Development code. Includes for example: a. generating input to software test plans, descriptions, and procedures b. defining software test cases c. performing software build and test Excludes, for example: a. System level IV&V
A50: 1.3.4.2 | B50: Custom SW Database Development Code Development (CSCI 1...n) and database test | C50: Development of Database Development code by CSCI 1…n. through unit/database test.
A51: 1.3.5 | B51: Custom Software and Database Maintenance | C51: Maintenance of existing software custom code, glue/wrapper code and database administrative activities. Includes for example: a. Software and Database code maintenance activities b. Database administrative activities c. DR work off post deployment to Ops
A52: 1.3.5.1 | B52: Custom Software Maintenance | C52: Maintenance of existing software code. Effort shall include support of custom and glue/wrapper code. Includes for example: a. DR work off post deployment to Ops
A53: 1.3.5.2 | B53: Custom Database Maintenance and Administration | C53: Maintenance of existing database manipulation and administrative activities. Includes, for example: a. Maintenance of software code specifically for querying records from a database b. Maintenance of software code specifically for putting records into a database c. Database administrative activities d. DR work off post deployment to Ops Excludes, for example: a. Maintenance of existing software code that does not involve database manipulation
...

Sheet  5 COTS-GOTS 
D2: CLASSIFICATION: UNCLASSIFIED
I7: Contact Information:
I8: Name:
I9: Phone Number (Secure):
I10: Phone Number (Non-Secure):
I11: Email (Secure and Non-Secure):
I12: Organization:
I13: Date of Information Provided:
I14: Date of Information Accuracy:
L24: k. Environment
B25: a. Program Name | C25: b. Contract # | D25: c. Location | E25: d. HW/SW | F25: e. Name of Application | G25: f. Description | H25: g. Original Equipment Manufacturer | I25: h. Category | J25: i. Sub-Category | K25: j. COTS/GOTS/FOSS | L25: D | M25: T | N25: O | O25: Tr | P25: l. Domain Level | Q25: m. Pricing Strategy | R25: n. Unit Cost / Rate for Usage | S25: o. Quantity | T25: p. Life Expectancy | U25: q. Warranty Period | V25: r. Annual Maint. Cost | W25: s. Comments/Notes
B26: {=Table40[a. Program]} -> 0 | C26: =' 3 Contract Info'!$B$22 -> 0
B27: {=Table40[a. Program]} -> 0 | C27: =' 3 Contract Info'!$B$22 -> 0
B28: {=Table40[a. Program]} -> 0 | C28: =' 3 Contract Info'!$B$22 -> 0
B29: {=Table40[a. Program]} -> 0 | C29: =' 3 Contract Info'!$B$22 -> 0
B30: {=Table40[a. Program]} -> 0 | C30: =' 3 Contract Info'!$B$22 -> 0
B31: {=Table40[a. Program]} -> 0 | C31: =' 3 Contract Info'!$B$22 -> 0
B32: {=Table40[a. Program]} -> 0 | C32: =' 3 Contract Info'!$B$22 -> 0
B33: {=Table40[a. Program]} -> 0 | C33: =' 3 Contract Info'!$B$22 -> 0
B34: {=Table40[a. Program]} -> 0 | C34: =' 3 Contract Info'!$B$22 -> 0
B35: {=Table40[a. Program]} -> 0 | C35: =' 3 Contract Info'!$B$22 -> 0
B36: {=Table40[a. Program]} -> 0 | C36: =' 3 Contract Info'!$B$22 -> 0
B37: {=Table40[a. Program]} -> 0 | C37: =' 3 Contract Info'!$B$22 -> 0
... B47: {=Table40[a. Program]} -> 0 | C47: =' 3 Contract Info'!$B$22 -> 0

Sheet 6 Agile Measures
D2: CLASSIFICATION: UNCLASSIFIED
G4: Contact Information:
G5: Name:
G6: Phone Number (Secure):
G7: Phone Number (Non-Secure):
G8: Email (Secure and Non-Secure):
G9: Organization:
G10: Date of Information Provided:
G11: Date of Information Accuracy:
B15: SUMMARY TOTALS
F16: a. Planned | G16: b. Actual
D17: Total Epics / Capabilities
D18: Total Features
D19: Total Stories
D20: Total Story Points | F20: =H152 -> 0 | G20: =J152 -> 0
D21: Total Feature Hours | F21: =I152 -> 0 | G21: =K152 -> 0
D22: Total Sprints
F25: Planned | H25: Actual
B26: c. Epic ID | C26: d. Epic Description | D26: e. Feature ID | E26: f. Feature Description | F26: g. Story Points | G26: h. Feature Hours | H26: i. Story Points | I26: j. Feature Hours
B27: Epic 1 | C27: Text of what the Epic is to do is here | D27: FT-00001 | E27: Feature Description here
D28: FT-00001 | E28: Feature Description here
D29: FT-00001 | E29: Feature Description here
D30: FT-00001 | E30: Feature Description here
D31: FT-00001 | E31: Feature Description here
D32: FT-00002 | E32: Feature Description here
D33: FT-00002 | E33: Feature Description here
D34: FT-00002 | E34: Feature Description here
D35: FT-00002 | E35: Feature Description here
D36: FT-00002 | E36: Feature Description here
D37: FT-00003 | E37: Feature Description here
D38: FT-00003 | E38: Feature Description here
D39: FT-00003 | E39: Feature Description here
... D51: FT-00005 | E51: Feature Description here
B52: Epic 2 | C52: Text of what the Epic is to do is here | D52: FT-00001 | E52: Feature Description here
D53: FT-00001 | E53: Feature Description here
D54: FT-00001 | E54: Feature Description here
D55: FT-00001 | E55: Feature Description here
D56: FT-00001 | E56: Feature Description here
D57: FT-00002 | E57: Feature Description here
D58: FT-00002 | E58: Feature Description here
...

Sheet  7 Agile Detail
D2: CLASSIFICATION: UNCLASSIFIED
H6: Contact Information:
H7: Name:
H8: Phone Number (Secure):
H9: Phone Number (Non-Secure):
H10: Email (Secure and Non-Secure):
H11: Organization:
H12: Date of Information Provided:
H13: Date of Information Accuracy:
B22: a. Program Name | C22: b. Contract # | D22: c. Developer | E22: d. Location of Developer | F22: e. Description | G22: f. Function | H22: g. SW Development Level 1 | I22: h. SW Development Level 2 | J22: i. SW Development Level 3 | K22: j. SW Development Level 4 | L22: k. Start Date | M22: l. End Date | N22: m. Activity | O22: n. Baseline Deployment | P22: o. Date Deployed to Operations | Q22: p. DR UID | R22: q. Actual Hours for SW Development | S22: r. Complexity | T22: s. Comments/Notes
B23: {=Table40[a. Program]} -> 0 | C23: =' 3 Contract Info'!$B$22 -> 0 | G23: =' 4 WBS'!$C$23 -> 0
B24: {=Table40[a. Program]} -> 0 | C24: =' 3 Contract Info'!$B$22 -> 0 | G24: =' 4 WBS'!$C$23 -> 0
B25: {=Table40[a. Program]} -> 0 | C25: =' 3 Contract Info'!$B$22 -> 0 | G25: =' 4 WBS'!$C$23 -> 0
B26: {=Table40[a. Program]} -> 0 | C26: =' 3 Contract Info'!$B$22 -> 0 | G26: =' 4 WBS'!$C$23 -> 0
B27: {=Table40[a. Program]} -> 0 | C27: =' 3 Contract Info'!$B$22 -> 0 | G27: =' 4 WBS'!$C$23 -> 0
B28: {=Table40[a. Program]} -> 0 | C28: =' 3 Contract Info'!$B$22 -> 0 | G28: =' 4 WBS'!$C$23 -> 0
B29: {=Table40[a. Program]} -> 0 | C29: =' 3 Contract Info'!$B$22 -> 0 | G29: =' 4 WBS'!$C$23 -> 0
B30: {=Table40[a. Program]} -> 0 | C30: =' 3 Contract Info'!$B$22 -> 0 | G30: =' 4 WBS'!$C$23 -> 0
B31: {=Table40[a. Program]} -> 0 | C31: =' 3 Contract Info'!$B$22 -> 0 | G31: =' 4 WBS'!$C$23 -> 0
B32: {=Table40[a. Program]} -> 0 | C32: =' 3 Contract Info'!$B$22 -> 0 | G32: =' 4 WBS'!$C$23 -> 0
B33: {=Table40[a. Program]} -> 0 | C33: =' 3 Contract Info'!$B$22 -> 0 | G33: =' 4 WBS'!$C$23 -> 0
B34: {=Table40[a. Program]} -> 0 | C34: =' 3 Contract Info'!$B$22 -> 0 | G34: =' 4 WBS'!$C$23 -> 0
... B50: {=Table40[a. Program]} -> 0 | C50: =' 3 Contract Info'!$B$22 -> 0 | G50: =' 4 WBS'!$C$23 -> 0

Sheet 8 Code Counts
D2: CLASSIFICATION:
G4: Contact Information:
G5: Name:
G6: Phone Number (Secure):
G7: Phone Number (Non-Secure):
G8: Email (Secure and Non-Secure):
G9: Organization:
G10: Date of Information Provided:
G11: Date of Information Accuracy:
N27: UCC-G Provided Fields
N28: Please provide the version of the UCC used for counting code.
M30: l. New Code
M31: New Code | O31: Open Source / Reuse Code | Q31: Autogenerated Code | S31: m. Unmodified Code | U31: n. Modified Code
B32: a. Program Name | C32: b. Contract # | D32: c. Developer | E32: d. Location of Developer | F32: e. SW Code Type | G32: f. Function | H32: g. SW Programming Language | I32: h. CSCI Name | J32: i. Description | K32: j. Baseline Deployment | L32: k. Development Strategy | M32: la. Total New Code | N32: lb. % Newly Developed Code | O32: lc. % of Total New Code | P32: ld. % Adaptation Adjustment Factor (AAF) | Q32: le. % of Total New Code | R32: lf. % Adaptation Adjustment Factor (AAF) | S32: ma. Total Unmodified Code | T32: mb. % Adaptation Adjustment Factor (AAF) | U32: na. Total Modified Code | V32: nb. % Adaptation Adjustment Factor (AAF) | W32: o. Total Deleted Code | X32: p. Comments/Notes
B33: {=Table40[a. Program]} -> 0 | C33: =' 3 Contract Info'!$B$22 -> 0 | D33: =' 7 Agile Detail'!$D$23 -> 0 | E33: =' 7 Agile Detail'!$E$23 -> 0 | Q33: =1-SUM(Table34[[#This Row],[lb. % Newly Developed Code]:[lc. % of Total New Code]]) -> 1
B34: {=Table40[a. Program]} -> 0 | C34: =' 3 Contract Info'!$B$22 -> 0 | D34: =' 7 Agile Detail'!$D$23 -> 0 | E34: =' 7 Agile Detail'!$E$23 -> 0 | Q34: =1-SUM(Table34[[#This Row],[lb. % Newly Developed Code]:[lc. % of Total New Code]]) -> 1
B35: {=Table40[a. Program]} -> 0 | C35: =' 3 Contract Info'!$B$22 -> 0 | D35: =' 7 Agile Detail'!$D$23 -> 0 | E35: =' 7 Agile Detail'!$E$23 -> 0 | Q35: =1-SUM(Table34[[#This Row],[lb. % Newly Developed Code]:[lc. % of Total New Code]]) -> 1
B36: {=Table40[a. Program]} -> 0 | C36: =' 3 Contract Info'!$B$22 -> 0 | D36: =' 7 Agile Detail'!$D$23 -> 0 | E36: =' 7 Agile Detail'!$E$23 -> 0 | Q36: =1-SUM(Table34[[#This Row],[lb. % Newly Developed Code]:[lc. % of Total New Code]]) -> 1
B37: {=Table40[a. Program]} -> 0 | C37: =' 3 Contract Info'!$B$22 -> 0 | D37: =' 7 Agile Detail'!$D$23 -> 0 | E37: =' 7 Agile Detail'!$E$23 -> 0 | Q37: =1-SUM(Table34[[#This Row],[lb. % Newly Developed Code]:[lc. % of Total New Code]]) -> 1
B38: {=Table40[a. Program]} -> 0 | C38: =' 3 Contract Info'!$B$22 -> 0 | D38: =' 7 Agile Detail'!$D$23 -> 0 | E38: =' 7 Agile Detail'!$E$23 -> 0 | Q38: =1-SUM(Table34[[#This Row],[lb. % Newly Developed Code]:[lc. % of Total New Code]]) -> 1
B39: {=Table40[a. Program]} -> 0 | C39: =' 3 Contract Info'!$B$22 -> 0 | D39: =' 7 Agile Detail'!$D$23 -> 0 | E39: =' 7 Agile Detail'!$E$23 -> 0 | Q39: =1-SUM(Table34[[#This Row],[lb. % Newly Developed Code]:[lc. % of Total New Code]]) -> 1
B40: {=Table40[a. Program]} -> 0 | C40: =' 3 Contract Info'!$B$22 -> 0 | D40: =' 7 Agile Detail'!$D$23 -> 0 | E40: =' 7 Agile Detail'!$E$23 -> 0 | Q40: =1-SUM(Table34[[#This Row],[lb. % Newly Developed Code]:[lc. % of Total New Code]]) -> 1
B41: {=Table40[a. Program]} -> 0 | C41: =' 3 Contract Info'!$B$22 -> 0 | D41: =' 7 Agile Detail'!$D$23 -> 0 | E41: =' 7 Agile Detail'!$E$23 -> 0 | Q41: =1-SUM(Table34[[#This Row],[lb. % Newly Developed Code]:[lc. % of Total New Code]]) -> 1
B42: {=Table40[a. Program]} -> 0 | C42: =' 3 Contract Info'!$B$22 -> 0 | D42: =' 7 Agile Detail'!$D$23 -> 0 | E42: =' 7 Agile Detail'!$E$23 -> 0 | Q42: =1-SUM(Table34[[#This Row],[lb. % Newly Developed Code]:[lc. % of Total New Code]]) -> 1
B43: {=Table40[a. Program]} -> 0 | C43: =' 3 Contract Info'!$B$22 -> 0 | D43: =' 7 Agile Detail'!$D$23 -> 0 | E43: =' 7 Agile Detail'!$E$23 -> 0 | Q43: =1-SUM(Table34[[#This Row],[lb. % Newly Developed Code]:[lc. % of Total New Code]]) -> 1
B44: {=Table40[a. Program]} -> 0 | C44: =' 3 Contract Info'!$B$22 -> 0 | D44: =' 7 Agile Detail'!$D$23 -> 0 | E44: =' 7 Agile Detail'!$E$23 -> 0 | Q44: =1-SUM(Table34[[#This Row],[lb. % Newly Developed Code]:[lc. % of Total New Code]]) -> 1
... B59: {=Table40[a. Program]} -> 0 | C59: =' 3 Contract Info'!$B$22 -> 0 | D59: =' 7 Agile Detail'!$D$23 -> 0 | E59: =' 7 Agile Detail'!$E$23 -> 0 | Q59: =1-SUM(Table34[[#This Row],[lb. % Newly Developed Code]:[lc. % of Total New Code]]) -> 1

Sheet  9 Data Management
D2: CLASSIFICATION: UNCLASSIFIED
G7: Contact Information:
G8: Name:
G9: Phone Number (Secure):
G10: Phone Number (Non-Secure):
G11: Email (Secure and Non-Secure):
G12: Organization:
G13: Date of Information Provided:
G14: Date of Information Accuracy:
M18: Data Conditioning Only | O18: Data Migration Only
B19: a. Program Name | C19: b. Contract # | D19: c. Developer | E19: d. Location of Developer | F19: e. Task (Short Description) | G19: f. Scope (Long Description) | H19: g. Data Management Effort | I19: h. Start Date | J19: i. End Date | K19: j. # of Hours Total | L19: k. Size | M19: l. % Manually Conditioned Data | N19: m. % Automatically Conditioned Data | O19: n. Migration From X | P19: o. Migration To Y | Q19: p. Database Name(s) if applicable | R19: q. Comments/Notes
B20: {=Table40[a. Program]} -> 0 | C20: =' 3 Contract Info'!$B$22 -> 0 | D20: =' 7 Agile Detail'!$D$23 -> 0 | E20: =' 7 Agile Detail'!$E$23 -> 0
B21: {=Table40[a. Program]} -> 0 | C21: =' 3 Contract Info'!$B$22 -> 0 | D21: =' 7 Agile Detail'!$D$23 -> 0 | E21: =' 7 Agile Detail'!$E$23 -> 0
B22: {=Table40[a. Program]} -> 0 | C22: =' 3 Contract Info'!$B$22 -> 0 | D22: =' 7 Agile Detail'!$D$23 -> 0 | E22: =' 7 Agile Detail'!$E$23 -> 0
B23: {=Table40[a. Program]} -> 0 | C23: =' 3 Contract Info'!$B$22 -> 0 | D23: =' 7 Agile Detail'!$D$23 -> 0 | E23: =' 7 Agile Detail'!$E$23 -> 0
B24: {=Table40[a. Program]} -> 0 | C24: =' 3 Contract Info'!$B$22 -> 0 | D24: =' 7 Agile Detail'!$D$23 -> 0 | E24: =' 7 Agile Detail'!$E$23 -> 0
B25: {=Table40[a. Program]} -> 0 | C25: =' 3 Contract Info'!$B$22 -> 0 | D25: =' 7 Agile Detail'!$D$23 -> 0 | E25: =' 7 Agile Detail'!$E$23 -> 0
B26: {=Table40[a. Program]} -> 0 | C26: =' 3 Contract Info'!$B$22 -> 0 | D26: =' 7 Agile Detail'!$D$23 -> 0 | E26: =' 7 Agile Detail'!$E$23 -> 0
B27: {=Table40[a. Program]} -> 0 | C27: =' 3 Contract Info'!$B$22 -> 0 | D27: =' 7 Agile Detail'!$D$23 -> 0 | E27: =' 7 Agile Detail'!$E$23 -> 0
B28: {=Table40[a. Program]} -> 0 | C28: =' 3 Contract Info'!$B$22 -> 0 | D28: =' 7 Agile Detail'!$D$23 -> 0 | E28: =' 7 Agile Detail'!$E$23 -> 0
B29: {=Table40[a. Program]} -> 0 | C29: =' 3 Contract Info'!$B$22 -> 0 | D29: =' 7 Agile Detail'!$D$23 -> 0 | E29: =' 7 Agile Detail'!$E$23 -> 0
B30: {=Table40[a. Program]} -> 0 | C30: =' 3 Contract Info'!$B$22 -> 0 | D30: =' 7 Agile Detail'!$D$23 -> 0 | E30: =' 7 Agile Detail'!$E$23 -> 0
B31: {=Table40[a. Program]} -> 0 | C31: =' 3 Contract Info'!$B$22 -> 0 | D31: =' 7 Agile Detail'!$D$23 -> 0 | E31: =' 7 Agile Detail'!$E$23 -> 0
... B53: {=Table40[a. Program]} -> 0 | C53: =' 3 Contract Info'!$B$22 -> 0 | D53: =' 7 Agile Detail'!$D$23 -> 0 | E53: =' 7 Agile Detail'!$E$23 -> 0

Sheet 10 Database
D2: CLASSIFICATION: UNCLASSIFIED
G7: Contact Information:
G8: Name:
G9: Phone Number (Secure):
G10: Phone Number (Non-Secure):
G11: Email (Secure and Non-Secure):
G12: Organization:
G13: Date of Information Provided:
G14: Date of Information Accuracy:
B17: a. Program Name | C17: b. Contract # | D17: c. Database Name | E17: d. Description | F17: e. Size | G17: f. # of DB Instances | H17: g. Platform for Database | I17: h. Table List | J17: i. # of Different Types of Constraints on each Attribute | K17: j. # of Fields/Tables | L17: k. # of Triggers used in Database | M17: l. # of Data Entry Forms | N17: m. # of Views to be Created | O17: n. Track Historical Records | P17: o. Comments/Notes
B18: {=Table40[a. Program]} -> 0 | C18: =' 3 Contract Info'!$B$22 -> 0
B19: {=Table40[a. Program]} -> 0 | C19: =' 3 Contract Info'!$B$22 -> 0
B20: {=Table40[a. Program]} -> 0 | C20: =' 3 Contract Info'!$B$22 -> 0
B21: {=Table40[a. Program]} -> 0 | C21: =' 3 Contract Info'!$B$22 -> 0
B22: {=Table40[a. Program]} -> 0 | C22: =' 3 Contract Info'!$B$22 -> 0
B23: {=Table40[a. Program]} -> 0 | C23: =' 3 Contract Info'!$B$22 -> 0
B24: {=Table40[a. Program]} -> 0 | C24: =' 3 Contract Info'!$B$22 -> 0
B25: {=Table40[a. Program]} -> 0 | C25: =' 3 Contract Info'!$B$22 -> 0
B26: {=Table40[a. Program]} -> 0 | C26: =' 3 Contract Info'!$B$22 -> 0
B27: {=Table40[a. Program]} -> 0 | C27: =' 3 Contract Info'!$B$22 -> 0
B28: {=Table40[a. Program]} -> 0 | C28: =' 3 Contract Info'!$B$22 -> 0
B29: {=Table40[a. Program]} -> 0 | C29: =' 3 Contract Info'!$B$22 -> 0
... B38: {=Table40[a. Program]} -> 0 | C38: =' 3 Contract Info'!$B$22 -> 0

Sheet 11 Discrepancy Reports
D2: CLASSIFICATION: UNCLASSIFIED
G7: Contact Information:
G8: Name:
G9: Phone Number (Secure):
G10: Phone Number (Non-Secure):
G11: Email (Secure and Non-Secure):
G12: Organization:
G13: Date of Information Provided:
G14: Date of Information Accuracy:
B18: SW Baseline Information
B19: a. Program Name | C19: b. Baseline | D19: c. Release / Delivery | E19: d. Subsystem | F19: e. Average Age of Code | G19: f. Total Maintained Logical SLOC | H19: g. Autogenerated SLOC | I19: h. List of Languages | J19: i. Maintenance Start Date | K19: j. Maintenance End Date | L19: k. Original Maintenance Start Date | M19: l. Total Maintenance Hours | N19: m. Annual Change Rate (%)
B20: {=Table40[a. Program]} -> 0
B21: {=Table40[a. Program]} -> 0
B22: {=Table40[a. Program]} -> 0
B23: {=Table40[a. Program]} -> 0
B25: Discrepancy Report Information
B26: n. Program Name | C26: o. Contract # | D26: p. Developer | E26: q. Location of Developer | F26: r. DR Number | G26: s. Description | H26: t. Priority / Severity | I26: u. Status | J26: v. Function | K26: w. Baseline Deployment | L26: x. Defect Origin | M26: y. Date Opened | N26: z. Date Closed | O26: aa. Comments/Notes
B27: {=Table40[a. Program]} -> 0 | C27: =' 3 Contract Info'!$B$22 -> 0 | D27: =' 7 Agile Detail'!$D$23 -> 0 | E27: =' 7 Agile Detail'!$E$23 -> 0
B28: {=Table40[a. Program]} -> 0 | C28: =' 3 Contract Info'!$B$22 -> 0 | D28: =' 7 Agile Detail'!$D$23 -> 0 | E28: =' 7 Agile Detail'!$E$23 -> 0
B29: {=Table40[a. Program]} -> 0 | C29: =' 3 Contract Info'!$B$22 -> 0 | D29: =' 7 Agile Detail'!$D$23 -> 0 | E29: =' 7 Agile Detail'!$E$23 -> 0
B30: {=Table40[a. Program]} -> 0 | C30: =' 3 Contract Info'!$B$22 -> 0 | D30: =' 7 Agile Detail'!$D$23 -> 0 | E30: =' 7 Agile Detail'!$E$23 -> 0
B31: {=Table40[a. Program]} -> 0 | C31: =' 3 Contract Info'!$B$22 -> 0 | D31: =' 7 Agile Detail'!$D$23 -> 0 | E31: =' 7 Agile Detail'!$E$23 -> 0
B32: {=Table40[a. Program]} -> 0 | C32: =' 3 Contract Info'!$B$22 -> 0 | D32: =' 7 Agile Detail'!$D$23 -> 0 | E32: =' 7 Agile Detail'!$E$23 -> 0
B33: {=Table40[a. Program]} -> 0 | C33: =' 3 Contract Info'!$B$22 -> 0 | D33: =' 7 Agile Detail'!$D$23 -> 0 | E33: =' 7 Agile Detail'!$E$23 -> 0
B34: {=Table40[a. Program]} -> 0 | C34: =' 3 Contract Info'!$B$22 -> 0 | D34: =' 7 Agile Detail'!$D$23 -> 0 | E34: =' 7 Agile Detail'!$E$23 -> 0
B35: {=Table40[a. Program]} -> 0 | C35: =' 3 Contract Info'!$B$22 -> 0 | D35: =' 7 Agile Detail'!$D$23 -> 0 | E35: =' 7 Agile Detail'!$E$23 -> 0
B36: {=Table40[a. Program]} -> 0 | C36: =' 3 Contract Info'!$B$22 -> 0 | D36: =' 7 Agile Detail'!$D$23 -> 0 | E36: =' 7 Agile Detail'!$E$23 -> 0
B37: {=Table40[a. Program]} -> 0 | C37: =' 3 Contract Info'!$B$22 -> 0 | D37: =' 7 Agile Detail'!$D$23 -> 0 | E37: =' 7 Agile Detail'!$E$23 -> 0
B38: {=Table40[a. Program]} -> 0 | C38: =' 3 Contract Info'!$B$22 -> 0 | D38: =' 7 Agile Detail'!$D$23 -> 0 | E38: =' 7 Agile Detail'!$E$23 -> 0
... B52: {=Table40[a. Program]} -> 0 | C52: =' 3 Contract Info'!$B$22 -> 0 | D52: =' 7 Agile Detail'!$D$23 -> 0 | E52: =' 7 Agile Detail'!$E$23 -> 0

Sheet PickList Tables
B2: CLASSIFICATION: UNCLASSIFIED
A4: Instructions
A6: This worksheet contains the tables used by various picklists throughout the workbook.
A8: Each "blue table" below contains the list of values for the picklist, and is a Named Range that the Data Validation function refers to
A11: To add items to the picklist, click on the cell just below the blue table and add your new value.
A13: To remove a items from the picklist, select the cell(s), do RIGHT click -->select "Delete"-->select "Table Rows"
A14: NOTE: If you remove an item from the picklist, and that particular item has already been picked on another worksheet, the other worksheet is NOT updated automatically - - it could still be using the value you just removed
A16: Use the orange cells to test each picklist. You can also use these throughout the workbook (via copy/paste) to quickly add picklists that are known to work properly
A19: Test the Picklist -->>
A21: Picklist Tables & Named Range Names--> | B21: ContractType | D21: Functions | F21: COTS/GOTS/FOSS | H21: Pricing Strategy | J21: DevelopmentStrategy | L21: Activity | N21: ECP | P21: Data Management | R21: Y/N Option | T21: Domain Level | V21: Nature of Transaction | X21: Performance Attributes | Z21: Security | AB21: Data Description | AD21: Information Assurance | AF21: SW Code Type | AH21: Protection Level | AJ21: Equipment Category | AL21: Servers | AN21: Workstations | AP21: Networking | AR21: Storage | AT21: Services
B22: CPAF | D22: Data Analysis & Exploitation | F22: COTS | H22: Price per # of Users | J22: Agile | L22: Development | N22: Cost | P22: Data Conditioning | R22: Yes | T22: UNCLASSIFIED | V22: Type | X22: Periodicity | Z22: Protection | AB22: Name/ID | AD22: Access Control | AF22: Database Dev | AH22: PL1 | AJ22: Networking | AL22: Physical | AN22: Thick Client | AP22: Routers | AR22: Solid State | AT22: Commercial Cloud Enterprise (C2E)
B23: CPFF | D23: Command & Control/Mission Management | F23: GOTS | H23: Price per # of Named Users | J23: Incremental | L23: DR Workoffs | N23: Technical | P23: Data Migration | R23: No | T23: SECRET | V23: Event | X23: Timeliness | Z23: Classification | AB23: Content | AD23: Availability | AF23: Glue/Wrapper Code | AH23: PL2 | AJ23: Security | AL23: Virtual | AN23: Thin Client | AP23: Switches | AR23: Spinning Disk | AT23: Commercial Cloud Services (C2S)
B24: CPIF | D24: Dissemination | F24: FOSS | H24: Price per # of Nodes | J24: Iterative | L24: Combination | N24: Schedule | R24: Unknown | T24: TOP SECRET | V24: Interoperability Level | X24: Throughput | Z24: Caveat | AB24: Format Type | AD24: Confidentiality | AF24: Refactoring/Migration Code | AH24: PL3 | AJ24: Servers | AR24: Tape | AT24: IC GovCloud (ICGC)
B25: CPIF (PI) | D25: Ground Terminals | H25: Price per # of Seats | J25: Multiple | N25: Other | T25: CAP/SAP | V25: Criticality | X25: Size | Z25: Releasability | AB25: Media Type | AD25: Dissemination Control | AF25: Source Code | AH25: PL4 | AJ25: Storage | AR25: RAID Array | AT25: Unclassified GovCloud (UGC)
B26: CS | D26: Infrastructure & Framework | H26: Price per # of Processors | J26: Spiral | Z26: Security Standard | AB26: Accuracy | AD26: Integrity | AH26: PL5 | AJ26: Services | AR26: Other (Clarify in Comments) | AT26: IC Desktop Environment (DTE)
B27: FFP | D27: Mission Data Processing | H27: Price per Enterprise License | J27: Waterfall | AB27: Units of Measurement | AD27: Non-Repudiation | AH27: UNKNOWN | AJ27: Workstations | AT27: Agency Infrastructure Service Provider (AISP)
B28: FPIF | D28: Tasking & Management | H28: Other | J28: Other | AB28: Data Standard | AJ28: Other | AT28: Other (Clarify in Comments)
B29: FPIST
B30: FPIST (PI)
B31: FPIFT (PI)
B32: FPAF
B33: FP/EPA
B34: FP/PPR
B35: FFP/LOET
B36: FPIC
B37: IDIQ
B38: LC
B39: T&M
B40: OT (Other Transactions)
B41: Other (Explain in Comments)
