Workbook

Sheet Teamsters Template
A1: Labor Category and CBA Required Wage | C1: Fringe | L1: Hours | S1: Total Cost | X1: New FAR 52.222-43 Wage Rates | AB1: FAR 52.222-43 Adjustment
A2: Classification | B2: Wage Rate | C2: Social Security | D2: Medicare | E2: FUTA | F2: SUTA | G2: Workman's Comp | H2: MANDATORY FRINGE BENEFITS Columns C Through G | I2: Wage Rate & MANDATORY FRINGE BENEFITS (Columns C Through G) but not Other Mandatory Benefits | J2: VOLUNTARY BENEFITS Fringe Excluded from FAR 52.222-43 (Additional Company Fringe Excluded from CBA) | K2: MANDATORY AND VOLUNTARY- Total Wage and Fringe (Excluding Other Mandatory) | L2: Productive Hours | M2: Nonproductive Hours | N2: Total Compensable Hours | O2: FTE's | P2: Productive Hours Based on FTES | Q2: Nonproductive Hours Based on FTE | R2: Total Compensable Hours Based on FTE's | S2: MANDATORY | T2: Other Mandatory | U2: TOTAL MANDATORY | V2: VOLUNTARY Total Wages and Fringe Not Subject to FAR 52.222-43 | W2: Mandatory and Voluntary Total Wages and Fringe | X2: Wage Rate | Y2: MANDATORY FRINGE BENEFITS | Z2: Other Mandatory | AA2: TOTAL | AB2: TOTAL
A3: Shift Lead | B3: 69.84 | C3: =$B3*C$25 -> 4.33008 | D3: =$B3*D$25 -> 1.01268 | E3: =$B3*E$25 -> 4.1904 | F3: =$B3*F$25 -> 0.6984 | G3: =$B3*G$25 -> 0.356184 | H3: =SUM(C3:G3) -> 10.587744 | I3: =SUM(B3,H3) -> 80.427744 | K3: =SUM(I3:J3) -> 80.427744 | L3: =$B$32 -> 1932 | M3: =$C$32 -> 264 | N3: =SUM(L3:M3) -> 2196 | O3: 2 | P3: =L3*O3 -> 3864 | Q3: =M3*O3 -> 528 | R3: =N3*O3 -> 4392 | S3: =I3*R3 -> 353238.65 | T3: =(R3*$D$17)+(P3*$D$19)+($F$13*R3/$R$9) -> 42791.904 | U3: =SUM(S3:T3) -> 396030.56 | V3: =J3*N3 -> 0 | W3: =SUM(U3:V3) -> 396030.56 | X3: =B3*1.05 -> 73.332 | Y3: =X3*$H$25 -> 11.117131 | Z3: =($G$17*R3)+($G$19*P3)+($H$13*P3/R3) -> 51925.737 | AA3: =SUM(X3:Y3)*R3+Z3 -> 422826.32 | AB3: =AA3-U3 -> 26795.766
A4: Shift/Day Float | B4: 65.19 | C4: =$B4*C$25 -> 4.04178 | D4: =$B4*D$25 -> 0.945255 | E4: =$B4*E$25 -> 3.9114 | F4: =$B4*F$25 -> 0.6519 | G4: =$B4*G$25 -> 0.332469 | H4: =SUM(C4:G4) -> 9.882804 | I4: =SUM(B4,H4) -> 75.072804 | K4: =SUM(I4:J4) -> 75.072804 | L4: =$B$32 -> 1932 | M4: =$C$32 -> 264 | N4: =SUM(L4:M4) -> 2196 | O4: 2 | P4: =L4*O4 -> 3864 | Q4: =M4*O4 -> 528 | R4: =N4*O4 -> 4392 | S4: =I4*R4 -> 329719.76 | T4: =(R4*$D$17)+(P4*$D$19)+($F$13*R4/$R$9) -> 42791.904 | U4: =SUM(S4:T4) -> 372511.66 | V4: =J4*N4 -> 0 | W4: =SUM(U4:V4) -> 372511.66 | X4: =B4*1.05 -> 68.4495 | Y4: =X4*$H$25 -> 10.376944 | Z4: =($G$17*R4)+($G$19*P4)+($H$13*P4/R4) -> 51925.737 | AA4: =SUM(X4:Y4)*R4+Z4 -> 398131.48 | AB4: =AA4-U4 -> 25619.821
A5: O&M | B5: 63.65 | C5: =$B5*C$25 -> 3.9463 | D5: =$B5*D$25 -> 0.922925 | E5: =$B5*E$25 -> 3.819 | F5: =$B5*F$25 -> 0.6365 | G5: =$B5*G$25 -> 0.324615 | H5: =SUM(C5:G5) -> 9.64934 | I5: =SUM(B5,H5) -> 73.29934 | K5: =SUM(I5:J5) -> 73.29934 | L5: =$B$32 -> 1932 | M5: =$C$32 -> 264 | N5: =SUM(L5:M5) -> 2196 | O5: 2 | P5: =L5*O5 -> 3864 | Q5: =M5*O5 -> 528 | R5: =N5*O5 -> 4392 | S5: =I5*R5 -> 321930.7 | T5: =(R5*$D$17)+(P5*$D$19)+($F$13*R5/$R$9) -> 42791.904 | U5: =SUM(S5:T5) -> 364722.61 | V5: =J5*N5 -> 0 | W5: =SUM(U5:V5) -> 364722.61 | X5: =B5*1.05 -> 66.8325 | Y5: =X5*$H$25 -> 10.131807 | Z5: =($G$17*R5)+($G$19*P5)+($H$13*P5/R5) -> 51925.737 | AA5: =SUM(X5:Y5)*R5+Z5 -> 389952.97 | AB5: =AA5-U5 -> 25230.368
A6: Antenna Tech | B6: 69.84 | C6: =$B6*C$25 -> 4.33008 | D6: =$B6*D$25 -> 1.01268 | E6: =$B6*E$25 -> 4.1904 | F6: =$B6*F$25 -> 0.6984 | G6: =$B6*G$25 -> 0.356184 | H6: =SUM(C6:G6) -> 10.587744 | I6: =SUM(B6,H6) -> 80.427744 | K6: =SUM(I6:J6) -> 80.427744 | L6: =$F$32 -> 1836 | M6: =$G$32 -> 244 | N6: =SUM(L6:M6) -> 2080 | O6: 2 | P6: =L6*O6 -> 3672 | Q6: =M6*O6 -> 488 | R6: =N6*O6 -> 4160 | S6: =I6*R6 -> 334579.42 | T6: =(R6*$D$17)+(P6*$D$19)+($F$13*R6/$R$9) -> 40549.053 | U6: =SUM(S6:T6) -> 375128.47 | V6: =J6*N6 -> 0 | W6: =SUM(U6:V6) -> 375128.47 | X6: =B6*1.05 -> 73.332 | Y6: =X6*$H$25 -> 11.117131 | Z6: =($G$17*R6)+($G$19*P6)+($H$13*P6/R6) -> 49689.006 | AA6: =SUM(X6:Y6)*R6+Z6 -> 400997.39 | AB6: =AA6-U6 -> 25868.924
A7: IT | B7: 63.65 | C7: =$B7*C$25 -> 3.9463 | D7: =$B7*D$25 -> 0.922925 | E7: =$B7*E$25 -> 3.819 | F7: =$B7*F$25 -> 0.6365 | G7: =$B7*G$25 -> 0.324615 | H7: =SUM(C7:G7) -> 9.64934 | I7: =SUM(B7,H7) -> 73.29934 | K7: =SUM(I7:J7) -> 73.29934 | L7: =$F$32 -> 1836 | M7: =$G$32 -> 244 | N7: =SUM(L7:M7) -> 2080 | O7: 2 | P7: =L7*O7 -> 3672 | Q7: =M7*O7 -> 488 | R7: =N7*O7 -> 4160 | S7: =I7*R7 -> 304925.25 | T7: =(R7*$D$17)+(P7*$D$19)+($F$13*R7/$R$9) -> 40549.053 | U7: =SUM(S7:T7) -> 345474.31 | V7: =J7*N7 -> 0 | W7: =SUM(U7:V7) -> 345474.31 | X7: =B7*1.05 -> 66.8325 | Y7: =X7*$H$25 -> 10.131807 | Z7: =($G$17*R7)+($G$19*P7)+($H$13*P7/R7) -> 49689.006 | AA7: =SUM(X7:Y7)*R7+Z7 -> 369860.52 | AB7: =AA7-U7 -> 24386.216
A8: Logistics | B8: 59.74 | C8: =$B8*C$25 -> 3.70388 | D8: =$B8*D$25 -> 0.86623 | E8: =$B8*E$25 -> 3.5844 | F8: =$B8*F$25 -> 0.5974 | G8: =$B8*G$25 -> 0.304674 | H8: =SUM(C8:G8) -> 9.056584 | I8: =SUM(B8,H8) -> 68.796584 | K8: =SUM(I8:J8) -> 68.796584 | L8: =$F$32 -> 1836 | M8: =$G$32 -> 244 | N8: =SUM(L8:M8) -> 2080 | O8: 2 | P8: =L8*O8 -> 3672 | Q8: =M8*O8 -> 488 | R8: =N8*O8 -> 4160 | S8: =I8*R8 -> 286193.79 | T8: =(R8*$D$17)+(P8*$D$19)+($F$13*R8/$R$9) -> 40549.053 | U8: =SUM(S8:T8) -> 326742.84 | V8: =J8*N8 -> 0 | W8: =SUM(U8:V8) -> 326742.84 | X8: =B8*1.05 -> 62.727 | Y8: =X8*$H$25 -> 9.5094132 | Z8: =($G$17*R8)+($G$19*P8)+($H$13*P8/R8) -> 49689.006 | AA8: =SUM(X8:Y8)*R8+Z8 -> 350192.48 | AB8: =AA8-U8 -> 23449.643
A9: Subtotal | L9: =SUM(L3:L8) -> 11304 | M9: =SUM(M3:M8) -> 1524 | N9: =SUM(N3:N8) -> 12828 | O9: =SUM(O3:O8) -> 12 | P9: =SUM(P3:P8) -> 22608 | Q9: =SUM(Q3:Q8) -> 3048 | R9: =SUM(R3:R8) -> 25656 | S9: =SUM(S3:S8) -> 1930587.6 | ... U9: =SUM(U3:U8) -> 2180610.4 | V9: =J9*N9 -> 0 | W9: =SUM(U9:V9) -> 2180610.4 | Z9: =SUM(Z3:Z8) -> 304844.23 | AA9: =SUM(AA3:AA8) -> 2331961.2 | AB9: =AA9-U9 -> 151350.74
H10: =H3/B3 -> 0.1516
A11: Other Mandatory Benefits | J11: Other Voluntary Benefits - Fringe Excluded from FAR 52.222-43 (Additional Company Fringe Excluded from CBA)
B12: Basis (Writeup) | C12: Applicable | D12: Rate | E12: Unit | F12: Calculation | G12: New CBA Rate | H12: Calculation | J12: Basis (Writeup) | K12: Rate | L12: Unit | M12: Calculation
A13: Leave not included in total compensable hours above | B13: Assuming 144 hours X Taxes | C13: Yes | D13: =AVERAGE(B3:B8)+(1*H25) -> 65.469933 | E13: 144 | F13: =D13*E13 -> 9427.6704 | G13: =AVERAGE(X3:X8)+(1*K25) -> 68.58425 | H13: =G13*E13 -> 9876.132 | J13: Please see RFI Request
A14: Benefit Administration Allocation | C14: No | F14: 0
A15: Employee Assistance Program | C15: No | F15: 0
A16: Health & Welfare | C16: No
A17: Pension | B17: Total Compensable Hours X $8.10 per Hours | C17: Yes | D17: 8.1 | E17: =N9 -> 12828 | F17: =D17*E17 -> 103906.8 | G17: =D17*1.05 -> 8.505 | H17: =G17*E17 -> 109102.14
A18: Supplemental Pension | C18: No | F18: 0
A19: Teamsters 401K Employer Expense | B19: Total Productive Hours X $1.45 per hour | C19: Yes | D19: 1.45 | E19: =L9 -> 11304 | F19: =D19*E19 -> 16390.8 | G19: =D19*1.05 -> 1.5225 | H19: =G19*E19 -> 17210.34
A20: Training | C20: No
B23: Assumptions
C24: Social Security | D24: Medicare | E24: FUTA | F24: SUTA | G24: Workman's Comp | H24: Total
B25: Rate | C25: 0.062 | D25: 0.0145 | E25: 0.06 | F25: 0.01 | G25: 0.0051 | H25: =SUM(C25:G25) -> 0.1516
B26: Narrative | C26: Up to $184,500 | D26: Additional 0.9% > $200,000 | E26: 0.6% X for 1st $7,000 | F26: 0.054 | G26: =G25 -> 0.0051 | H26: Sum of Columns
B29: FTE Basis
B30: Shift | F30: Non-Shift
B31: Productive | C31: NonProductive | D31: Total | E31: Hours Cap | F31: Productive | G31: NonProductive | H31: Total
B32: 1932 | C32: =D32-B32 -> 264 | D32: 2196 | E32: 2232 | F32: 1836 | G32: =H32-F32 -> 244 | H32: 2080

Sheet FJCC Template
A1: Labor Category and CBA Required Wage | C1: Fringe | L1: Hours | S1: Total Cost | X1: New FAR 52.222-43 Wage Rates | AB1: FAR 52.222-43 Adjustment
A2: Classification | B2: Total Package Rate | C2: Social Security | D2: Medicare | E2: FUTA | F2: SUTA | G2: Workman's Comp | H2: MANDATORY FRINGE BENEFITS Columns C Through G | I2: Wage Rate & MANDATORY FRINGE BENEFITS (Columns C Through G) but not Other Mandatory Benefits | J2: VOLUNTARY BENEFITS Fringe Excluded from FAR 52.222-43 (Additional Company Fringe Excluded from CBA) | K2: MANDATORY AND VOLUNTARY- Total Wage and Fringe (Excluding Other Mandatory) | L2: Productive Hours | M2: Nonproductive Hours | N2: Total Compensable Hours | O2: FTE's | P2: Productive Hours Based on FTES | Q2: Nonproductive Hours Based on FTE | R2: Total Compensable Hours Based on FTE's | S2: MANDATORY | T2: Other Mandatory | U2: TOTAL MANDATORY | V2: VOLUNTARY Total Wages and Fringe Not Subject to FAR 52.222-43 | W2: Mandatory and Voluntary Total Wages and Fringe | X2: New Package Rate | Y2: MANDATORY FRINGE BENEFITS | Z2: Other Mandatory | AA2: TOTAL | AB2: TOTAL
A3: M&O LABORER | B3: 80.26 | C3: =$B3*C$24 -> 4.97612 | D3: =$B3*D$24 -> 1.16377 | E3: =$B3*E$24 -> 4.8156 | F3: =$B3*F$24 -> 0.8026 | G3: =$B3*G$24 -> 0.409326 | H3: =SUM(C3:G3) -> 12.167416 | I3: =SUM(B3,H3) -> 92.427416 | K3: =I3+J3 -> 92.427416 | L3: =$B$31 -> 1836 | M3: =$C$31 -> 244 | N3: =SUM(K3:M3) -> 2172.4274 | O3: 2 | P3: =$O3*L3 -> 3672 | Q3: =O3*M3 -> 488 | R3: =SUM(P3:Q3) -> 4160 | S3: =R3*I3 -> 384498.05 | W3: =SUM(S3,V3) -> 384498.05 | X3: =B3*1.05 -> 84.273 | Y3: =$H$24*X3 -> 12.775787 | AA3: =SUM(X3:Y3)*R3 -> 403722.95 | AB3: =AA3-W3 -> 19224.903
A4: PLUMBER | B4: 82.99 | C4: =$B4*C$24 -> 5.14538 | D4: =$B4*D$24 -> 1.203355 | E4: =$B4*E$24 -> 4.9794 | F4: =$B4*F$24 -> 0.8299 | G4: =$B4*G$24 -> 0.423249 | H4: =SUM(C4:G4) -> 12.581284 | I4: =SUM(B4,H4) -> 95.571284 | K4: =I4+J4 -> 95.571284 | L4: =$B$31 -> 1836 | M4: =$C$31 -> 244 | N4: =SUM(K4:M4) -> 2175.5713 | O4: 2 | P4: =$O4*L4 -> 3672 | Q4: =O4*M4 -> 488 | R4: =SUM(P4:Q4) -> 4160 | S4: =R4*I4 -> 397576.54 | W4: =SUM(S4,V4) -> 397576.54 | X4: =B4*1.05 -> 87.1395 | Y4: =$H$24*X4 -> 13.210348 | AA4: =SUM(X4:Y4)*R4 -> 417455.37 | AB4: =AA4-W4 -> 19878.827
A5: POWERHOUSE ELECTRICIAN | B5: 84.57 | C5: =$B5*C$24 -> 5.24334 | D5: =$B5*D$24 -> 1.226265 | E5: =$B5*E$24 -> 5.0742 | F5: =$B5*F$24 -> 0.8457 | G5: =$B5*G$24 -> 0.431307 | H5: =SUM(C5:G5) -> 12.820812 | I5: =SUM(B5,H5) -> 97.390812 | K5: =I5+J5 -> 97.390812 | L5: =$B$31 -> 1836 | M5: =$C$31 -> 244 | N5: =SUM(K5:M5) -> 2177.3908 | O5: 2 | P5: =$O5*L5 -> 3672 | Q5: =O5*M5 -> 488 | R5: =SUM(P5:Q5) -> 4160 | S5: =R5*I5 -> 405145.78 | W5: =SUM(S5,V5) -> 405145.78 | X5: =B5*1.05 -> 88.7985 | Y5: =$H$24*X5 -> 13.461853 | AA5: =SUM(X5:Y5)*R5 -> 425403.07 | AB5: =AA5-W5 -> 20257.289
A6: POWERHOUSE OPERATING ENGINEER | B6: 84.57 | C6: =$B6*C$24 -> 5.24334 | D6: =$B6*D$24 -> 1.226265 | E6: =$B6*E$24 -> 5.0742 | F6: =$B6*F$24 -> 0.8457 | G6: =$B6*G$24 -> 0.431307 | H6: =SUM(C6:G6) -> 12.820812 | I6: =SUM(B6,H6) -> 97.390812 | K6: =I6+J6 -> 97.390812 | L6: =$B$31 -> 1836 | M6: =$C$31 -> 244 | N6: =SUM(K6:M6) -> 2177.3908 | O6: 2 | P6: =$O6*L6 -> 3672 | Q6: =O6*M6 -> 488 | R6: =SUM(P6:Q6) -> 4160 | S6: =R6*I6 -> 405145.78 | W6: =SUM(S6,V6) -> 405145.78 | X6: =B6*1.05 -> 88.7985 | Y6: =$H$24*X6 -> 13.461853 | AA6: =SUM(X6:Y6)*R6 -> 425403.07 | AB6: =AA6-W6 -> 20257.289
A7: POWERHOUSE OPERATING ENGINEER Lead | B7: 93.027 | C7: =$B7*C$24 -> 5.767674 | D7: =$B7*D$24 -> 1.3488915 | E7: =$B7*E$24 -> 5.58162 | F7: =$B7*F$24 -> 0.93027 | G7: =$B7*G$24 -> 0.4744377 | H7: =SUM(C7:G7) -> 14.102893 | I7: =SUM(B7,H7) -> 107.12989 | K7: =I7+J7 -> 107.12989 | L7: =$B$31 -> 1836 | M7: =$C$31 -> 244 | N7: =SUM(K7:M7) -> 2187.1299 | O7: 2 | P7: =$O7*L7 -> 3672 | Q7: =O7*M7 -> 488 | R7: =SUM(P7:Q7) -> 4160 | S7: =R7*I7 -> 445660.36 | W7: =SUM(S7,V7) -> 445660.36 | X7: =B7*1.05 -> 97.67835 | Y7: =$H$24*X7 -> 14.808038 | AA7: =SUM(X7:Y7)*R7 -> 467943.37 | AB7: =AA7-W7 -> 22283.018
A8: Subtotal | O8: =SUM(O3:O7) -> 10 | P8: =SUM(P3:P7) -> 18360 | Q8: =SUM(Q3:Q7) -> 2440 | R8: =SUM(P8:Q8) -> 20800 | S8: =SUM(S3:S7) -> 2038026.5 | W8: =SUM(W3:W7) -> 2038026.5 | AA8: =SUM(AA3:AA7) -> 2139927.8 | AB8: =SUM(AB3:AB7) -> 101901.33
A10: Other Mandatory Benefits (Not Applicable for FJCC) | J10: Other Voluntary Benefits - Fringe Excluded from FAR 52.222-43 (Additional Company Fringe Excluded from CBA)
B11: Basis (Writeup) | C11: Applicable | D11: Rate | E11: Unit | F11: Calculation | G11: New CBA Rate | H11: Calculation | J11: Basis (Writeup) | K11: Rate | L11: Unit | M11: Calculation
A12: Leave not included in total compensable hours above | J12: Please see RFI Request
A13: Benefit Administration Allocation | C13: No | F13: 0
A14: Employee Assistance Program | C14: No | F14: 0
A15: Health & Welfare | C15: No
A16: Pension | B16: Total Compensable Hours X $8.10 per Hours | C16: Yes | D16: 8.1 | E16: =N7 -> 2187.1299 | F16: =D16*E16 -> 17715.752 | G16: =D16*1.05 -> 8.505 | H16: =G16*E16 -> 18601.54
A17: Supplemental Pension | C17: No | F17: 0
A18: Teamsters 401K Employer Expense | B18: Total Productive Hours X $1.45 per hour | C18: Yes | D18: 1.45 | E18: =L7 -> 1836 | F18: =D18*E18 -> 2662.2 | G18: =D18*1.05 -> 1.5225 | H18: =G18*E18 -> 2795.31
A19: Training | C19: No
B22: Assumptions
C23: Social Security | D23: Medicare | E23: FUTA | F23: SUTA | G23: Workman's Comp | H23: Total
B24: Rate | C24: 0.062 | D24: 0.0145 | E24: 0.06 | F24: 0.01 | G24: 0.0051 | H24: =SUM(C24:G24) -> 0.1516
B25: Narrative | C25: Up to $184,500 | D25: Additional 0.9% > $200,000 | E25: 0.6% X for 1st $7,000 | F25: 0.054 | G25: =G24 -> 0.0051 | H25: Sum of Columns
B28: FTE Basis
B29: Non-Shift
B30: Productive | C30: NonProductive | D30: Total
B31: 1836 | C31: =D31-B31 -> 244 | D31: 2080

Sheet SCA Template
A1: Labor Category and SCA Required Wage | C1: Fringe | F1: Hours | M1: Total Cost | P1: New FAR 52.222-43 Wage Rates | S1: FAR 52.222-43 Adjustment
A2: Classification | B2: SCA Rate | C2: H&W | D2: VOLUNTARY BENEFITS Fringe Excluded from FAR 52.222-43 (Additional Company Fringe Excluded from CBA) | E2: MANDATORY AND VOLUNTARY- Total Wage and Fringe (Excluding Other Mandatory) | F2: Productive Hours | G2: Nonproductive Hours | H2: Total Compensable Hours | I2: FTE's | J2: Productive Hours Based on FTES | K2: Nonproductive Hours Based on FTE | L2: Total Compensable Hours Based on FTE's | M2: MANDATORY | N2: VOLUNTARY Total Wages and Fringe Not Subject to FAR 52.222-43 | O2: Mandatory and Voluntary Total Wages and Fringe | P2: New DL and H&W Rate | Q2: Other Mandatory | R2: TOTAL | S2: TOTAL
A3: Administrative Assistant (01020) | B3: 30.25 | C3: 5.55 | E3: =SUM(C3:D3) -> 5.55 | F3: =$B$29 -> 1872 | G3: =$C$29 -> 208 | H3: =SUM(E3:G3) -> 2085.55 | I3: 2 | J3: =$I3*F3 -> 3744 | K3: =I3*G3 -> 416 | L3: =SUM(J3:K3) -> 4160 | M3: =J3*SUM(B3:C3) -> 134035.2 | O3: =SUM(M3,N3) -> 134035.2 | P3: =(B3+C3)*1.05 -> 37.59 | R3: =SUM(P3:P3)*J3 -> 140736.96 | S3: =R3-O3 -> 6701.76
A4: Guard I (27101) | B4: 22.72 | C4: 5.55 | E4: =SUM(C4:D4) -> 5.55 | F4: =$B$29 -> 1872 | G4: =$C$29 -> 208 | H4: =SUM(E4:G4) -> 2085.55 | I4: 2 | J4: =$I4*F4 -> 3744 | K4: =I4*G4 -> 416 | L4: =SUM(J4:K4) -> 4160 | M4: =J4*SUM(B4:C4) -> 105842.88 | O4: =SUM(M4,N4) -> 105842.88 | P4: =(B4+C4)*1.05 -> 29.6835 | R4: =SUM(P4:P4)*J4 -> 111135.02 | S4: =R4-O4 -> 5292.144
A5: Guard II (27102 | B5: 25.41 | C5: 5.55 | E5: =SUM(C5:D5) -> 5.55 | F5: =$B$29 -> 1872 | G5: =$C$29 -> 208 | H5: =SUM(E5:G5) -> 2085.55 | I5: 2 | J5: =$I5*F5 -> 3744 | K5: =I5*G5 -> 416 | L5: =SUM(J5:K5) -> 4160 | M5: =J5*SUM(B5:C5) -> 115914.24 | O5: =SUM(M5,N5) -> 115914.24 | P5: =(B5+C5)*1.05 -> 32.508 | R5: =SUM(P5:P5)*J5 -> 121709.95 | S5: =R5-O5 -> 5795.712
A6: Subtotal | I6: =SUM(I3:I5) -> 6 | J6: =SUM(J3:J5) -> 11232 | K6: =SUM(K3:K5) -> 1248 | L6: =SUM(J6:K6) -> 12480 | M6: =SUM(M3:M5) -> 355792.32 | O6: =SUM(O3:O5) -> 355792.32 | R6: =SUM(R3:R5) -> 373581.94 | S6: =SUM(S3:S5) -> 17789.616
A8: Other Voluntary Benefits - Fringe Excluded from FAR 52.222-43 (Additional Company Fringe Excluded from CBA)
A9: Basis (Writeup) | B9: Rate | C9: Unit | D9: Calculation
A10: Please see RFI Request
B26: FTE Basis
B27: Non-Shift
B28: Productive | C28: NonProductive | D28: Total
B29: 1872 | C29: =D29-B29 -> 208 | D29: 2080

Sheet Exempt Employee Template
A1: Labor Category | C1: Fringe | E1: Hours | L1: Total Cost
A2: Classification | B2: Wage Rate | C2: Fringe | D2: Total Rate | E2: Productive Hours | F2: Nonproductive Hours | G2: Total Compensable Hours | H2: FTE's | I2: Productive Hours Based on FTES | J2: Nonproductive Hours Based on FTE | K2: Total Compensable Hours Based on FTE's
A3: FACILITIES MANAGER | B3: 63.97 | C3: =B3*0.2 -> 12.794 | D3: =SUM(B3:C3) -> 76.764 | E3: =$A$14 -> 1872 | F3: =$B$14 -> 208 | G3: =SUM(E3:F3) -> 2080 | H3: 1 | I3: =E3*$H3 -> 1872 | J3: =F3*$H3 -> 208 | K3: =G3*$H3 -> 2080 | L3: =K3*D3 -> 159669.12
A4: IT MANAGER | B4: 60.47 | C4: =B4*0.2 -> 12.094 | D4: =SUM(B4:C4) -> 72.564 | E4: =$A$14 -> 1872 | F4: =$B$14 -> 208 | G4: =SUM(E4:F4) -> 2080 | H4: 1 | I4: =E4*$H4 -> 1872 | J4: =F4*$H4 -> 208 | K4: =G4*$H4 -> 2080 | L4: =K4*D4 -> 150933.12
A5: OPERATIONS MANAGER | B5: 68.03 | C5: =B5*0.2 -> 13.606 | D5: =SUM(B5:C5) -> 81.636 | E5: =$A$14 -> 1872 | F5: =$B$14 -> 208 | G5: =SUM(E5:F5) -> 2080 | H5: 1 | I5: =E5*$H5 -> 1872 | J5: =F5*$H5 -> 208 | K5: =G5*$H5 -> 2080 | L5: =K5*D5 -> 169802.88
A6: PROJECT MANAGER | B6: 88.08 | C6: =B6*0.2 -> 17.616 | D6: =SUM(B6:C6) -> 105.696 | E6: =$A$14 -> 1872 | F6: =$B$14 -> 208 | G6: =SUM(E6:F6) -> 2080 | H6: 1 | I6: =E6*$H6 -> 1872 | J6: =F6*$H6 -> 208 | K6: =G6*$H6 -> 2080 | L6: =K6*D6 -> 219847.68
A7: SAFETY MANAGER | B7: 64.5 | C7: =B7*0.2 -> 12.9 | D7: =SUM(B7:C7) -> 77.4 | E7: =$A$14 -> 1872 | F7: =$B$14 -> 208 | G7: =SUM(E7:F7) -> 2080 | H7: 1 | I7: =E7*$H7 -> 1872 | J7: =F7*$H7 -> 208 | K7: =G7*$H7 -> 2080 | L7: =K7*D7 -> 160992
A8: SECURITY GUARD MANAGER | B8: 42.44 | C8: =B8*0.2 -> 8.488 | D8: =SUM(B8:C8) -> 50.928 | E8: =$A$14 -> 1872 | F8: =$B$14 -> 208 | G8: =SUM(E8:F8) -> 2080 | H8: 1 | I8: =E8*$H8 -> 1872 | J8: =F8*$H8 -> 208 | K8: =G8*$H8 -> 2080 | L8: =K8*D8 -> 105930.24
A9: TOTAL | E9: =SUM(E3:E8) -> 11232 | F9: =SUM(F3:F8) -> 1248 | G9: =SUM(G3:G8) -> 12480 | H9: =SUM(H3:H8) -> 6 | I9: =SUM(I3:I8) -> 11232 | J9: =SUM(J3:J8) -> 1248 | K9: =SUM(K3:K8) -> 12480 | L9: =SUM(L3:L8) -> 967175.04
A11: FTE Basis
A12: Non-Shift
A13: Productive | B13: NonProductive | C13: Total
A14: 1872 | B14: =C14-A14 -> 208 | C14: 2080

Sheet Buildup
A1: Labor Category | B1: FTE's | C1: Productive Hours Based on FTES | D1: Nonproductive Hours Based on FTE | E1: Total Compensable Hours Based on FTE's | F1: Total Cost | K1: New FAR 52.222-43 Wage Rates | O1: FAR 52.222-43 Adjustment | P1: Validate
A2: Teamsters | F2: MANDATORY | G2: Other Mandatory | H2: TOTAL MANDATORY | I2: VOLUNTARY Total Wages and Fringe Not Subject to FAR 52.222-43 | J2: Mandatory and Voluntary Total Wages and Fringe | K2: Wage Rate | L2: MANDATORY FRINGE BENEFITS | M2: Other Mandatory | N2: Total | O2: TOTAL
A3: ='Teamsters Template'!A3 -> Shift Lead | B3: ='Teamsters Template'!O3 -> 2 | C3: ='Teamsters Template'!P3 -> 3864 | D3: ='Teamsters Template'!Q3 -> 528 | E3: ='Teamsters Template'!R3 -> 4392 | F3: ='Teamsters Template'!S3 -> 353238.65 | G3: ='Teamsters Template'!T3 -> 42791.904 | H3: ='Teamsters Template'!U3 -> 396030.56 | I3: ='Teamsters Template'!V3 -> 0 | ... O3: ='Teamsters Template'!AB3 -> 26795.766 | P3: =N3-J3-O3 -> 0
A4: ='Teamsters Template'!A4 -> Shift/Day Float | B4: ='Teamsters Template'!O4 -> 2 | C4: ='Teamsters Template'!P4 -> 3864 | D4: ='Teamsters Template'!Q4 -> 528 | E4: ='Teamsters Template'!R4 -> 4392 | F4: ='Teamsters Template'!S4 -> 329719.76 | G4: ='Teamsters Template'!T4 -> 42791.904 | H4: ='Teamsters Template'!U4 -> 372511.66 | I4: ='Teamsters Template'!V4 -> 0 | ... O4: ='Teamsters Template'!AB4 -> 25619.821 | P4: =N4-J4-O4 -> 0
A5: ='Teamsters Template'!A5 -> O&M | B5: ='Teamsters Template'!O5 -> 2 | C5: ='Teamsters Template'!P5 -> 3864 | D5: ='Teamsters Template'!Q5 -> 528 | E5: ='Teamsters Template'!R5 -> 4392 | F5: ='Teamsters Template'!S5 -> 321930.7 | G5: ='Teamsters Template'!T5 -> 42791.904 | H5: ='Teamsters Template'!U5 -> 364722.61 | I5: ='Teamsters Template'!V5 -> 0 | ... O5: ='Teamsters Template'!AB5 -> 25230.368 | P5: =N5-J5-O5 -> 0
A6: ='Teamsters Template'!A6 -> Antenna Tech | B6: ='Teamsters Template'!O6 -> 2 | C6: ='Teamsters Template'!P6 -> 3672 | D6: ='Teamsters Template'!Q6 -> 488 | E6: ='Teamsters Template'!R6 -> 4160 | F6: ='Teamsters Template'!S6 -> 334579.42 | G6: ='Teamsters Template'!T6 -> 40549.053 | H6: ='Teamsters Template'!U6 -> 375128.47 | I6: ='Teamsters Template'!V6 -> 0 | ... O6: ='Teamsters Template'!AB6 -> 25868.924 | P6: =N6-J6-O6 -> 0
A7: ='Teamsters Template'!A7 -> IT | B7: ='Teamsters Template'!O7 -> 2 | C7: ='Teamsters Template'!P7 -> 3672 | D7: ='Teamsters Template'!Q7 -> 488 | E7: ='Teamsters Template'!R7 -> 4160 | F7: ='Teamsters Template'!S7 -> 304925.25 | G7: ='Teamsters Template'!T7 -> 40549.053 | H7: ='Teamsters Template'!U7 -> 345474.31 | I7: ='Teamsters Template'!V7 -> 0 | ... O7: ='Teamsters Template'!AB7 -> 24386.216 | P7: =N7-J7-O7 -> 0
A8: ='Teamsters Template'!A8 -> Logistics | B8: ='Teamsters Template'!O8 -> 2 | C8: ='Teamsters Template'!P8 -> 3672 | D8: ='Teamsters Template'!Q8 -> 488 | E8: ='Teamsters Template'!R8 -> 4160 | F8: ='Teamsters Template'!S8 -> 286193.79 | G8: ='Teamsters Template'!T8 -> 40549.053 | H8: ='Teamsters Template'!U8 -> 326742.84 | I8: ='Teamsters Template'!V8 -> 0 | ... O8: ='Teamsters Template'!AB8 -> 23449.643 | P8: =N8-J8-O8 -> 0
A9: ='Teamsters Template'!A9 -> Subtotal | B9: ='Teamsters Template'!O9 -> 12 | C9: ='Teamsters Template'!P9 -> 22608 | D9: ='Teamsters Template'!Q9 -> 3048 | E9: ='Teamsters Template'!R9 -> 25656 | F9: ='Teamsters Template'!S9 -> 1930587.6 | G9: ='Teamsters Template'!T9 -> 250022.87 | H9: ='Teamsters Template'!U9 -> 2180610.4 | I9: ='Teamsters Template'!V9 -> 0 | ... O9: ='Teamsters Template'!AB9 -> 151350.74 | P9: =N9-J9-O9 -> 0
A10: FJCC | F10: MANDATORY | G10: Other Mandatory | H10: TOTAL MANDATORY | I10: VOLUNTARY Total Wages and Fringe Not Subject to FAR 52.222-43 | J10: Mandatory and Voluntary Total Wages and Fringe | K10: New Package Rate | L10: MANDATORY FRINGE BENEFITS | M10: Other Mandatory | N10: Total | O10: TOTAL
A11: ='FJCC Template'!A3 -> M&O LABORER | B11: ='FJCC Template'!O3 -> 2 | C11: ='FJCC Template'!P3 -> 3672 | D11: ='FJCC Template'!Q3 -> 488 | E11: ='FJCC Template'!R3 -> 4160 | F11: ='FJCC Template'!S3 -> 384498.05 | G11: ='FJCC Template'!T3 -> 0 | H11: ='FJCC Template'!U3 -> 0 | I11: ='FJCC Template'!V3 -> 0 | ... O11: ='FJCC Template'!AB3 -> 19224.903 | P11: =N11-J11-O11 -> 0
A12: ='FJCC Template'!A4 -> PLUMBER | B12: ='FJCC Template'!O4 -> 2 | C12: ='FJCC Template'!P4 -> 3672 | D12: ='FJCC Template'!Q4 -> 488 | E12: ='FJCC Template'!R4 -> 4160 | F12: ='FJCC Template'!S4 -> 397576.54 | G12: ='FJCC Template'!T4 -> 0 | H12: ='FJCC Template'!U4 -> 0 | I12: ='FJCC Template'!V4 -> 0 | ... O12: ='FJCC Template'!AB4 -> 19878.827 | P12: =N12-J12-O12 -> 0
A13: ='FJCC Template'!A5 -> POWERHOUSE ELECTRICIAN | B13: ='FJCC Template'!O5 -> 2 | C13: ='FJCC Template'!P5 -> 3672 | D13: ='FJCC Template'!Q5 -> 488 | E13: ='FJCC Template'!R5 -> 4160 | F13: ='FJCC Template'!S5 -> 405145.78 | G13: ='FJCC Template'!T5 -> 0 | H13: ='FJCC Template'!U5 -> 0 | I13: ='FJCC Template'!V5 -> 0 | ... O13: ='FJCC Template'!AB5 -> 20257.289 | P13: =N13-J13-O13 -> 0
A14: ='FJCC Template'!A6 -> POWERHOUSE OPERATING ENGINEER | B14: ='FJCC Template'!O6 -> 2 | C14: ='FJCC Template'!P6 -> 3672 | D14: ='FJCC Template'!Q6 -> 488 | E14: ='FJCC Template'!R6 -> 4160 | F14: ='FJCC Template'!S6 -> 405145.78 | G14: ='FJCC Template'!T6 -> 0 | H14: ='FJCC Template'!U6 -> 0 | I14: ='FJCC Template'!V6 -> 0 | ... O14: ='FJCC Template'!AB6 -> 20257.289 | P14: =N14-J14-O14 -> 0
A15: ='FJCC Template'!A7 -> POWERHOUSE OPERATING ENGINEER Lead | B15: ='FJCC Template'!O7 -> 2 | C15: ='FJCC Template'!P7 -> 3672 | D15: ='FJCC Template'!Q7 -> 488 | E15: ='FJCC Template'!R7 -> 4160 | F15: ='FJCC Template'!S7 -> 445660.36 | G15: ='FJCC Template'!T7 -> 0 | H15: ='FJCC Template'!U7 -> 0 | I15: ='FJCC Template'!V7 -> 0 | ... O15: ='FJCC Template'!AB7 -> 22283.018 | P15: =N15-J15-O15 -> 0
A16: ='FJCC Template'!A8 -> Subtotal | B16: ='FJCC Template'!O8 -> 10 | C16: ='FJCC Template'!P8 -> 18360 | D16: ='FJCC Template'!Q8 -> 2440 | E16: ='FJCC Template'!R8 -> 20800 | F16: ='FJCC Template'!S8 -> 2038026.5 | G16: ='FJCC Template'!T8 -> 0 | H16: ='FJCC Template'!U8 -> 0 | I16: ='FJCC Template'!V8 -> 0 | ... O16: ='FJCC Template'!AB8 -> 101901.33 | P16: =N16-J16-O16 -> 0
A17: SCA | F17: MANDATORY | G17: VOLUNTARY Total Wages and Fringe Not Subject to FAR 52.222-43 | H17: Mandatory and Voluntary Total Wages and Fringe | K17: New DL and H&W Rate | L17: Other Mandatory | M17: TOTAL | O17: TOTAL
A18: ='SCA Template'!A3 -> Administrative Assistant (01020) | B18: ='SCA Template'!I3 -> 2 | C18: ='SCA Template'!J3 -> 3744 | D18: ='SCA Template'!K3 -> 416 | E18: ='SCA Template'!L3 -> 4160 | F18: ='SCA Template'!M3 -> 134035.2 | G18: ='SCA Template'!N3 -> 0 | H18: ='SCA Template'!O3 -> 134035.2 | K18: ='SCA Template'!P3 -> 37.59 | L18: ='SCA Template'!Q3 -> 0 | M18: ='SCA Template'!R3 -> 140736.96 | O18: ='SCA Template'!S3 -> 6701.76 | P18: =M18-H18-O18 -> 0
A19: ='SCA Template'!A4 -> Guard I (27101) | B19: ='SCA Template'!I4 -> 2 | C19: ='SCA Template'!J4 -> 3744 | D19: ='SCA Template'!K4 -> 416 | E19: ='SCA Template'!L4 -> 4160 | F19: ='SCA Template'!M4 -> 105842.88 | G19: ='SCA Template'!N4 -> 0 | H19: ='SCA Template'!O4 -> 105842.88 | K19: ='SCA Template'!P4 -> 29.6835 | L19: ='SCA Template'!Q4 -> 0 | M19: ='SCA Template'!R4 -> 111135.02 | O19: ='SCA Template'!S4 -> 5292.144 | P19: =M19-H19-O19 -> 0
A20: ='SCA Template'!A5 -> Guard II (27102 | B20: ='SCA Template'!I5 -> 2 | C20: ='SCA Template'!J5 -> 3744 | D20: ='SCA Template'!K5 -> 416 | E20: ='SCA Template'!L5 -> 4160 | F20: ='SCA Template'!M5 -> 115914.24 | G20: ='SCA Template'!N5 -> 0 | H20: ='SCA Template'!O5 -> 115914.24 | K20: ='SCA Template'!P5 -> 32.508 | L20: ='SCA Template'!Q5 -> 0 | M20: ='SCA Template'!R5 -> 121709.95 | O20: ='SCA Template'!S5 -> 5795.712 | P20: =M20-H20-O20 -> 0
A21: ='SCA Template'!A6 -> Subtotal | B21: ='SCA Template'!I6 -> 6 | C21: ='SCA Template'!J6 -> 11232 | D21: ='SCA Template'!K6 -> 1248 | E21: ='SCA Template'!L6 -> 12480 | F21: ='SCA Template'!M6 -> 355792.32 | G21: ='SCA Template'!N6 -> 0 | H21: ='SCA Template'!O6 -> 355792.32 | K21: ='SCA Template'!P6 -> 0 | L21: ='SCA Template'!Q6 -> 0 | M21: ='SCA Template'!R6 -> 373581.94 | O21: ='SCA Template'!S6 -> 17789.616 | P21: =M21-H21-O21 -> -2.910383e-11
A22: Exempt | F22: Total Cost
A23: ='Exempt Employee Template'!A3 -> FACILITIES MANAGER | B23: ='Exempt Employee Template'!H3 -> 1 | C23: ='Exempt Employee Template'!I3 -> 1872 | D23: ='Exempt Employee Template'!J3 -> 208 | E23: ='Exempt Employee Template'!K3 -> 2080 | F23: ='Exempt Employee Template'!L3 -> 159669.12
A24: ='Exempt Employee Template'!A4 -> IT MANAGER | B24: ='Exempt Employee Template'!H4 -> 1 | C24: ='Exempt Employee Template'!I4 -> 1872 | D24: ='Exempt Employee Template'!J4 -> 208 | E24: ='Exempt Employee Template'!K4 -> 2080 | F24: ='Exempt Employee Template'!L4 -> 150933.12
A25: ='Exempt Employee Template'!A5 -> OPERATIONS MANAGER | B25: ='Exempt Employee Template'!H5 -> 1 | C25: ='Exempt Employee Template'!I5 -> 1872 | D25: ='Exempt Employee Template'!J5 -> 208 | E25: ='Exempt Employee Template'!K5 -> 2080 | F25: ='Exempt Employee Template'!L5 -> 169802.88
A26: ='Exempt Employee Template'!A6 -> PROJECT MANAGER | B26: ='Exempt Employee Template'!H6 -> 1 | C26: ='Exempt Employee Template'!I6 -> 1872 | D26: ='Exempt Employee Template'!J6 -> 208 | E26: ='Exempt Employee Template'!K6 -> 2080 | F26: ='Exempt Employee Template'!L6 -> 219847.68
A27: ='Exempt Employee Template'!A7 -> SAFETY MANAGER | B27: ='Exempt Employee Template'!H7 -> 1 | C27: ='Exempt Employee Template'!I7 -> 1872 | D27: ='Exempt Employee Template'!J7 -> 208 | E27: ='Exempt Employee Template'!K7 -> 2080 | F27: ='Exempt Employee Template'!L7 -> 160992
A28: ='Exempt Employee Template'!A8 -> SECURITY GUARD MANAGER | B28: ='Exempt Employee Template'!H8 -> 1 | C28: ='Exempt Employee Template'!I8 -> 1872 | D28: ='Exempt Employee Template'!J8 -> 208 | E28: ='Exempt Employee Template'!K8 -> 2080 | F28: ='Exempt Employee Template'!L8 -> 105930.24
A29: ='Exempt Employee Template'!A9 -> TOTAL | B29: ='Exempt Employee Template'!H9 -> 6 | C29: ='Exempt Employee Template'!I9 -> 11232 | D29: ='Exempt Employee Template'!J9 -> 1248 | E29: ='Exempt Employee Template'!K9 -> 12480 | F29: =SUM(F23:F28) -> 967175.04
F30: Total Labor Cost | G30: =SUM(J9,J16,H21,F29) -> 5541604.3 | K30: =SUM(N9,N16,M21,F29) -> 5812646 | O30: =SUM(O9,O16,O21) -> 271041.68 | P30: =K30-G30-O30 -> -4.6566129e-10

Sheet ProTech LCats & Base Rates
C2: Level | D2: Experience (yrs) | E2: Lower Range | F2: Average | G2: Upper Range | H2: Lower Range | I2: Average | J2: Upper Range | K2: ProTech Ceiling | L2: OASIS Ceiling
B3: Scientific Services | E3: Average-centered range -/+ two standard deviations | H3: Average-centered range -/+ one standard deviation
B4: Examples: Astronomy, Atmospheric Sciences, Chemistry, Climatology, Earth Science, Environmental Science, Geodesy, Geology, Materials Science, Meteorology, Oceanography, Physics, Space Science | C4: Scientific Services - Level 1 | D4: 0 < yrs < 5 | E4: 46 | F4: 56 | G4: 66 | H4: =I4-_xlfn.STDEV.S(E4:G4) -> 46 | I4: =AVERAGE(E4:G4) -> 56 | J4: =I4+_xlfn.STDEV.S(E4:G4) -> 66 | K4: 122 | L4: 155.65
C5: Scientific Services - Level 2 | D5: 5 < yrs < 10 | E5: 45 | F5: 75 | G5: 105 | H5: =I5-_xlfn.STDEV.S(E5:G5) -> 45 | I5: =AVERAGE(E5:G5) -> 75 | J5: =I5+_xlfn.STDEV.S(E5:G5) -> 105 | K5: 160 | L5: 204.782
C6: Scientific Services - Level 3 | D6: 10 < yrs < 15 | E6: 60 | F6: 94 | G6: 128 | H6: =I6-_xlfn.STDEV.S(E6:G6) -> 60 | I6: =AVERAGE(E6:G6) -> 94 | J6: =I6+_xlfn.STDEV.S(E6:G6) -> 128 | K6: 198 | L6: 222.282
C7: Scientific Services - Level 4 | D7: 15 < yrs < 20 | E7: 67 | F7: 119 | G7: 171 | H7: =I7-_xlfn.STDEV.S(E7:G7) -> 67 | I7: =AVERAGE(E7:G7) -> 119 | J7: =I7+_xlfn.STDEV.S(E7:G7) -> 171 | K7: 250 | L7: 278.592
C8: Scientific Services - Level 5 | D8: > 20 | E8: 83 | F8: 141 | G8: 199
B9: Engineering Services
B10: Examples: Electrical, Electronic, Chemical, Electronics, Equipment, General, Materials, Mechanical, Systems | C10: Engineering Services - Level 1 | D10: 0 < yrs < 5 | E10: 55 | F10: 61 | G10: 67 | H10: =I10-_xlfn.STDEV.S(E10:G10) -> 55 | I10: =AVERAGE(E10:G10) -> 61 | J10: =I10+_xlfn.STDEV.S(E10:G10) -> 67 | K10: 126 | L10: 150.974
C11: Engineering Services - Level 2 | D11: 5 < yrs < 10 | E11: 59 | F11: 77 | G11: 95 | H11: =I11-_xlfn.STDEV.S(E11:G11) -> 59 | I11: =AVERAGE(E11:G11) -> 77 | J11: =I11+_xlfn.STDEV.S(E11:G11) -> 95 | K11: 160 | L11: 187.454
C12: Engineering Services - Level 3 | D12: 10 < yrs < 15 | E12: 58 | F12: 92 | G12: 126 | H12: =I12-_xlfn.STDEV.S(E12:G12) -> 58 | I12: =AVERAGE(E12:G12) -> 92 | J12: =I12+_xlfn.STDEV.S(E12:G12) -> 126 | K12: 198 | L12: 224.64
C13: Engineering Services - Level 4 | D13: 15 < yrs < 20 | E13: 63 | F13: 117 | G13: 171 | H13: =I13-_xlfn.STDEV.S(E13:G13) -> 63 | I13: =AVERAGE(E13:G13) -> 117 | J13: =I13+_xlfn.STDEV.S(E13:G13) -> 171 | K13: 245 | L13: 278.906
C14: Engineering Services - Level 5 | D14: > 20 | E14: 75 | F14: 139 | G14: 203
B15: Analytical Services
B16: Examples: Computer Science, Mathematics, Operations Research, Statistics | C16: Analytical Services -Level 1 | D16: 0 < yrs < 5 | E16: 24 | F16: 48 | G16: 72 | H16: =I16-_xlfn.STDEV.S(E16:G16) -> 24 | I16: =AVERAGE(E16:G16) -> 48 | J16: =I16+_xlfn.STDEV.S(E16:G16) -> 72 | K16: 118 | L16: 136.96
C17: Analytical Services -Level 2 | D17: 5 < yrs < 10 | E17: 40 | F17: 66 | G17: 92 | H17: =I17-_xlfn.STDEV.S(E17:G17) -> 40 | I17: =AVERAGE(E17:G17) -> 66 | J17: =I17+_xlfn.STDEV.S(E17:G17) -> 92 | K17: 150 | L17: 168.12667
C18: Analytical Services -Level 3 | D18: 10 < yrs < 15 | E18: 42 | F18: 82 | G18: 122 | H18: =I18-_xlfn.STDEV.S(E18:G18) -> 42 | I18: =AVERAGE(E18:G18) -> 82 | J18: =I18+_xlfn.STDEV.S(E18:G18) -> 122 | K18: 186 | L18: 203.74667
C19: Analytical Services -Level 4 | D19: 15 < yrs < 20 | E19: 54 | F19: 104 | G19: 154 | H19: =I19-_xlfn.STDEV.S(E19:G19) -> 54 | I19: =AVERAGE(E19:G19) -> 104 | J19: =I19+_xlfn.STDEV.S(E19:G19) -> 154 | K19: 239 | L19: 246.01
C20: Analytical Services -Level 5 | D20: > 20 | E20: 70 | F20: 126 | G20: 182
B21: Program Operation Services
B22: Examples: Budget Analysis, Education and Training, Financial Management, International Cooperation, Management and Program Analysis, Program Management, Technical Writing and Editing | C22: Program Operations Services - Level 1 | D22: 0 < yrs < 5 | E22: 46 | F22: 58 | G22: 70 | H22: =I22-_xlfn.STDEV.S(E22:G22) -> 46 | I22: =AVERAGE(E22:G22) -> 58 | J22: =I22+_xlfn.STDEV.S(E22:G22) -> 70 | K22: 120 | L22: 123.53333
C23: Program Operations Services - Level 2 | D23: 5 < yrs < 10 | E23: 53 | F23: 77 | G23: 101 | H23: =I23-_xlfn.STDEV.S(E23:G23) -> 53 | I23: =AVERAGE(E23:G23) -> 77 | J23: =I23+_xlfn.STDEV.S(E23:G23) -> 101 | K23: 149 | L23: 150.195
C24: Program Operations Services - Level 3 | D24: 10 < yrs < 15 | E24: 69 | F24: 101 | G24: 133 | H24: =I24-_xlfn.STDEV.S(E24:G24) -> 69 | I24: =AVERAGE(E24:G24) -> 101 | J24: =I24+_xlfn.STDEV.S(E24:G24) -> 133 | K24: 187 | L24: 183.32333
C25: Program Operations Services - Level 4 | D25: 15 < yrs < 20 | E25: 88 | F25: 124 | G25: 160 | H25: =I25-_xlfn.STDEV.S(E25:G25) -> 88 | I25: =AVERAGE(E25:G25) -> 124 | J25: =I25+_xlfn.STDEV.S(E25:G25) -> 160 | K25: 235 | L25: 225.00667
C26: Program Operations Services - Level 5 | D26: > 20 | E26: 110 | F26: 152 | G26: 194
B27: Scientific Information Services
B28: Examples: Data Collection, Data Processing, Image Analysis, Information Systems, Quality Control Inspection, Scientific Applications Programming, Scientific Systems Analysis, Web Designing | C28: Scientific Information Services - Level 1 | D28: 0 < yrs < 5 | E28: 44 | F28: 54 | G28: 64 | H28: =I28-_xlfn.STDEV.S(E28:G28) -> 44 | I28: =AVERAGE(E28:G28) -> 54 | J28: =I28+_xlfn.STDEV.S(E28:G28) -> 64 | K28: 119 | L28: 79.314
C29: Scientific Information Services - Level 2 | D29: 5 < yrs < 10 | E29: 58 | F29: 72 | G29: 86 | H29: =I29-_xlfn.STDEV.S(E29:G29) -> 58 | I29: =AVERAGE(E29:G29) -> 72 | J29: =I29+_xlfn.STDEV.S(E29:G29) -> 86 | K29: 151 | L29: 102.98
C30: Scientific Information Services - Level 3 | D30: 10 < yrs < 15 | E30: 71 | F30: 89 | G30: 107 | H30: =I30-_xlfn.STDEV.S(E30:G30) -> 71 | I30: =AVERAGE(E30:G30) -> 89 | J30: =I30+_xlfn.STDEV.S(E30:G30) -> 107 | K30: 184 | L30: 130.53
C31: Scientific Information Services - Level 4 | D31: 15 < yrs < 20 | E31: 81 | F31: 113 | G31: 145 | H31: =0.93*I31 -> 105.09 | I31: =AVERAGE(E31:G31) -> 113 | J31: =I31*1.07 -> 120.91 | K31: 233 | L31: 158.156
C32: Scientific Information Services - Level 5 | D32: > 20 | E32: 93 | F32: 139 | G32: 185
B33: To Add Custom Labor Categories
B34: Add custom labor categories to the tool by | C34: Custom Labor Category 1
B35: over-writing any of the 12 "Custom Labor Category" | C35: Custom Labor Category 2
B36: instances in Column C. | C36: Custom Labor Category 3
B37: If a range of rates for the labor category is available, | C37: Custom Labor Category 4
B38: place the low, average, and high rates in Columns E, F, G | C38: Custom Labor Category 5
B39: respectively. | C39: Custom Labor Category 6
B40: If a single rate for the labor category is available, | C40: Custom Labor Category 7
B41: place it in Colums E, F, and G. | C41: Custom Labor Category 8
...

Sheet Source 1, SciTech Blended
C1: ss1 | D1: ss2 | E1: ss3 | F1: ss4 | G1: es1 | H1: es2 | I1: es3 | J1: es4 | K1: as1 | L1: as2 | M1: as3 | N1: as4 | O1: pos1 | P1: pos2 | Q1: pos3 | R1: pos4 | S1: sis1 | T1: sis2 | U1: sis3 | V1: sis4
A2: Project Manager | B2: 179.21588 | Q2: x | R2: x | W2: =COUNTIF(C2:V2,"x") -> 2
A3: Sr. Support Scientist IV | B3: 142.2327 | F3: x | N3: x | V3: x | W3: =COUNTIF(C3:V3,"x") -> 3
A4: Support Scientist III | B4: 118.4912 | E4: x | M4: x | U4: x | W4: =COUNTIF(C4:V4,"x") -> 3
A5: Support Scientist II | B5: 98.79142 | D5: x | L5: x | T5: x | W5: =COUNTIF(C5:V5,"x") -> 3
A6: Support Scientist I | B6: 76.54754 | C6: x | W6: =COUNTIF(C6:V6,"x") -> 1
A7: Scientific Analyst IV | B7: 123.48464 | F7: x | N7: x | V7: x | W7: =COUNTIF(C7:V7,"x") -> 3
A8: Scientific Analyst III | B8: 103.92288 | E8: x | M8: x | U8: x | W8: =COUNTIF(C8:V8,"x") -> 3
A9: Scientific Analyst II | B9: 82.18164 | D9: x | L9: x | T9: x | W9: =COUNTIF(C9:V9,"x") -> 3
A10: Scientific Analyst I | B10: 69.51058 | C10: x | K10: x | S10: x | W10: =COUNTIF(C10:V10,"x") -> 3
A11: Scientific/Engineering Tech. | B11: 52.75454 | C11: x | K11: x | S11: x | W11: =COUNTIF(C11:V11,"x") -> 3
A12: Engineer V | B12: 194.63498 | J12: x | W12: =COUNTIF(C12:V12,"x") -> 1
A13: Engineer IV | B13: 155.95436 | I13: x | J13: x | W13: =COUNTIF(C13:V13,"x") -> 2
A14: Engineer III | B14: 126.56022 | H14: x | I14: x | W14: =COUNTIF(C14:V14,"x") -> 2
A15: Engineer II | B15: 94.09874 | G15: x | H15: x | W15: =COUNTIF(C15:V15,"x") -> 2
A16: Engineer I | B16: 70.8537 | G16: x | W16: =COUNTIF(C16:V16,"x") -> 1
A17: Principal Engineer | B17: 188.5106 | I17: x | J17: x | W17: =COUNTIF(C17:V17,"x") -> 2
A18: Engineering Mgr./Sr. Engineering Consultant | B18: 179.31682 | I18: x | J18: x | Q18: x | R18: x | U18: x | V18: x | W18: =COUNTIF(C18:V18,"x") -> 6
A19: Engineering Consultant/Tech. Consultant | B19: 175.84778 | H19: x | I19: x | J19: x | U19: x | V19: x | W19: =COUNTIF(C19:V19,"x") -> 5
A20: Sr. Proj. Engineer/ Consultant | B20: 135.07626 | I20: x | J20: x | U20: x | V20: x | W20: =COUNTIF(C20:V20,"x") -> 4
A21: Proj. Engineer/Proj. Manager | B21: 140.7804 | H21: x | I21: x | J21: x | P21: x | Q21: x | R21: x | W21: =COUNTIF(C21:V21,"x") -> 6
A22: Sr. Engineer/Sr. Scientist | B22: 107.10764 | E22: x | F22: x | I22: x | J22: x | U22: x | V22: x | W22: =COUNTIF(C22:V22,"x") -> 6
A23: Lead Engineer/Scientist | B23: 98.01892 | E23: x | F23: x | I23: x | J23: x | U23: x | V23: x | W23: =COUNTIF(C23:V23,"x") -> 6
A24: Engineer/Sr. Tech. Asst. | B24: 56.87866 | D24: x | G24: x | H24: x | S24: x | T24: x | W24: =COUNTIF(C24:V24,"x") -> 5
A25: Asst. Engineer/Designer/Lab Tech. | B25: 47.86822 | C25: x | G25: x | K25: x | S25: x | W25: =COUNTIF(C25:V25,"x") -> 4
A26: Director/Chief Eng. or Scientist | B26: 194.8863 | E26: x | F26: x | I26: x | J26: x | Q26: x | R26: x | W26: =COUNTIF(C26:V26,"x") -> 6
A27: Sr. Prog. Mgr./Sr. Rsch. Eng. III or Principal Scientist | B27: 182.61694 | E27: x | F27: x | I27: x | J27: x | M27: x | N27: x | Q27: x | R27: x | W27: =COUNTIF(C27:V27,"x") -> 8
A28: Prog. Mgr./Sr. Rsch. Engr. II or Sr. Rsch. Scientist II | B28: 154.28988 | D28: x | E28: x | H28: x | I28: x | L28: x | M28: x | P28: x | Q28: x | W28: =COUNTIF(C28:V28,"x") -> 8
A29: Sr. Proj. Leader/Sr. Rsch. Engr. I or Sr. Rsch. Scientist I | B29: 132.5919 | C29: x | D29: x | G29: x | H29: x | K29: x | L29: x | W29: =COUNTIF(C29:V29,"x") -> 6
A30: Proj. Leader/Rsch. Engr. III or Rsch. Scientist III | B30: 120.8602 | D30: x | E30: x | H30: x | I30: x | W30: =COUNTIF(C30:V30,"x") -> 4
A31: Rsc. Engr. II or Rsch. Scientist II | B31: 107.16326 | D31: x | H31: x | W31: =COUNTIF(C31:V31,"x") -> 2
A32: Rsch. Eng. I or Rsch. Scientist I | B32: 93.49722 | C32: x | G32: x | W32: =COUNTIF(C32:V32,"x") -> 2
A33: Eng. III or Scientist III | B33: 91.5979 | E33: x | F33: x | I33: x | J33: x | M33: x | N33: x | U33: x | V33: x | W33: =COUNTIF(C33:V33,"x") -> 8
A34: Eng. II or Scientist II | B34: 77.09344 | D34: x | E34: x | H34: x | I34: x | L34: x | M34: x | T34: x | U34: x | W34: =COUNTIF(C34:V34,"x") -> 8
A35: Eng. I or Scientist I | B35: 63.60044 | C35: x | D35: x | G35: x | H35: x | K35: x | L35: x | S35: x | T35: x | W35: =COUNTIF(C35:V35,"x") -> 8
A36: Rsch. Asst. III/Admin. Asst. III | B36: 63.63958 | Q36: x | R36: x | W36: =COUNTIF(C36:V36,"x") -> 2
A37: Rsch. Asst. II/Admin. Asst. II | B37: 52.95436 | P37: x | Q37: x | W37: =COUNTIF(C37:V37,"x") -> 2
A38: Rsch. Asst. I/Admin. Asst. I | B38: 44.0325 | O38: x | P38: x | W38: =COUNTIF(C38:V38,"x") -> 2
A39: Technician III | B39: 66.42676 | U39: x | V39: x | W39: =COUNTIF(C39:V39,"x") -> 2
A40: Technician II | B40: 56.85188 | T40: x | U40: x | W40: =COUNTIF(C40:V40,"x") -> 2
...

Sheet Source 2, GSA CALC Blended
A1: Scientific Services
A2: Examples: Astronomy, Atmospheric Sciences, Chemistry, Climatology, Earth Science, Environmental Science, Geodesy, Geology, Materials Science, Meteorology, Oceanography, Physics, Space Science | B2: 1 | C2: 4 < yrs < 8 | D2: 109
B3: 2 | C3: 8 < yrs < 16 | D3: 146
B4: 3 | C4: 16 < yrs < 25 | D4: 188
B5: 4 | C5: yrs > 25 | D5: 257
A7: Engineering Services
A8: Examples: Electrical, Electronic, Chemical, Electronics, Equipment, General, Materials, Mechanical, Systems | B8: 1 | C8: 4 < yrs < 8 | D8: 111
B9: 2 | C9: 8 < yrs < 16 | D9: 138
B10: 3 | C10: 16 < yrs < 25 | D10: 177
B11: 4 | C11: yrs > 25 | D11: 189
A13: Analytical Services | D13: Computer Science | E13: Operations Res | F13: Statistics | G13: Average
A14: Examples: Computer Science, Mathematics, Operations Research, Statistics | B14: 1 | C14: 4 < yrs < 8 | D14: 108 | E14: 111 | F14: 117 | G14: =AVERAGE(D14:F14) -> 112
B15: 2 | C15: 8 < yrs < 16 | D15: 129 | E15: 117 | F15: 152 | G15: =AVERAGE(D15:F15) -> 132.66667
B16: 3 | C16: 16 < yrs < 25 | D16: 108 | E16: 192 | F16: 132 | G16: =AVERAGE(D16:F16) -> 144
B17: 4 | C17: yrs > 25 | D17: 145 | E17: 217 | G17: =AVERAGE(D17:F17) -> 181
A19: Program Operation Services | D19: Budget | E19: Training | F19: Account | G19: Prog Analysis | H19: Prog Mgmt | I19: Tech Writer | J19: Average
A20: Examples: Budget Analysis, Education and Training, Financial Management, International Cooperation, Management and Program Analysis, Program Management, Technical Writing and Editing | B20: 1 | C20: 4 < yrs < 8 | D20: 92 | E20: 89 | F20: 119 | G20: 85 | H20: 129 | I20: 75 | J20: =AVERAGE(D20:I20) -> 98.166667
B21: 2 | C21: 8 < yrs < 16 | D21: 97 | E21: 112 | F21: 171 | G21: 118 | H21: 164 | I21: 97 | J21: =AVERAGE(D21:I21) -> 126.5
B22: 3 | C22: 16 < yrs < 25 | D22: 137 | E22: 112 | F22: 193 | G22: 152 | H22: 201 | I22: 113 | J22: =AVERAGE(D22:I22) -> 151.33333
B23: 4 | C23: yrs > 25 | G23: 152 | H23: 216 | I23: 156 | J23: =AVERAGE(D23:I23) -> 174.66667
A25: Scientific Information Services | D25: Data Proc | E25: Image Analysis | F25: Qual Control | G25: Application Pgmr | H25: Scientific Analysis | I25: Web Designer | J25: Average
A26: Examples: Data Collection, Data Processing, Image Analysis, Information Systems, Quality Control Inspection, Scientific Applications Programming, Scientific Systems Analysis, Web Designing | B26: 1 | C26: 4 < yrs < 8 | D26: 90 | E26: 101 | F26: 84 | G26: 109 | I26: 93 | J26: =AVERAGE(D26:I26) -> 95.4
B27: 2 | C27: 8 < yrs < 16 | F27: 103 | G27: 126 | I27: 104 | J27: =AVERAGE(D27:I27) -> 111
B28: 3 | C28: 16 < yrs < 25 | F28: 117 | G28: 146 | J28: =AVERAGE(D28:I28) -> 131.5
B29: 4 | C29: yrs > 25
A31: Note: Advanced degrees from an accredited institution and/or professional credentials from a recognized entity may be cumulatively tallied and substituted for experience. Masters and associates degrees are equivalent to two years of experience; bachelors and doctoral degrees are equivalent to four years of experience. Requirements for specialized degrees, credentials, and experience will be specified at the task order level.

Sheet Source 3, OASIS Blended
A1: Scientific Services | D1: Astronomy | E1: Geoscience | F1: Chemist | G1: Physics Materials | J1: Average | K1: StdDev | L1: SD/Ave
A2: Examples: Astronomy, Atmospheric Sciences, Chemistry, Climatology, Earth Science, Environmental Science, Geodesy, Geology, Materials Science, Meteorology, Oceanography, Physics, Space Science | B2: 1 | C2: 4 < yrs < 8 | D2: 148.34 | E2: 174.99 | F2: 155.76 | G2: 151.54 | H2: 147.62 | J2: =AVERAGE(D2:H2) -> 155.65 | K2: =_xlfn.STDEV.S(D2:H2) -> 11.278927 | L2: =K2/J2 -> 0.072463394
B3: 2 | C3: 8 < yrs < 16 | D3: 210.63 | E3: 213.93 | F3: 188.06 | G3: 215.56 | H3: 195.73 | J3: =AVERAGE(D3:H3) -> 204.782 | K3: =_xlfn.STDEV.S(D3:H3) -> 12.202605 | L3: =K3/J3 -> 0.05958827
B4: 3 | C4: 16 < yrs < 25 | D4: 220.54 | E4: 225 | F4: 220.51 | G4: 232.55 | H4: 212.81 | J4: =AVERAGE(D4:H4) -> 222.282 | K4: =_xlfn.STDEV.S(D4:H4) -> 7.2234459 | L4: =K4/J4 -> 0.032496765
B5: 4 | C5: yrs > 25 | D5: 279.6 | E5: 284.97 | F5: 272.61 | G5: 294.68 | H5: 261.1 | J5: =AVERAGE(D5:H5) -> 278.592 | K5: =_xlfn.STDEV.S(D5:H5) -> 12.671554 | L5: =K5/J5 -> 0.045484269
A7: Engineering Services | D7: Electrical | E7: Chemical | F7: Aerospace | G7: Mechanical | H7: Material
A8: Examples: Electrical, Electronic, Chemical, Electronics, Equipment, General, Materials, Mechanical, Systems | B8: 1 | C8: 4 < yrs < 8 | D8: 140.86 | E8: 146.91 | F8: 188.98 | G8: 133.22 | H8: 144.9 | J8: =AVERAGE(D8:H8) -> 150.974 | K8: =_xlfn.STDEV.S(D8:H8) -> 21.882431 | L8: =K8/J8 -> 0.14494172
B9: 2 | C9: 8 < yrs < 16 | D9: 186.85 | E9: 169.24 | F9: 218.24 | G9: 167.21 | H9: 195.73 | J9: =AVERAGE(D9:H9) -> 187.454 | K9: =_xlfn.STDEV.S(D9:H9) -> 20.965472 | L9: =K9/J9 -> 0.11184329
B10: 3 | C10: 16 < yrs < 25 | D10: 225.14 | E10: 196.85 | F10: 250.1 | G10: 227.15 | H10: 223.96 | J10: =AVERAGE(D10:H10) -> 224.64 | K10: =_xlfn.STDEV.S(D10:H10) -> 18.89119 | L10: =K10/J10 -> 0.084095396
B11: 4 | C11: yrs > 25 | D11: 280.43 | E11: 237.74 | F11: 305.74 | G11: 283.08 | H11: 287.54 | J11: =AVERAGE(D11:H11) -> 278.906 | K11: =_xlfn.STDEV.S(D11:H11) -> 25.044929 | L11: =K11/J11 -> 0.089797026
A13: Analytical Services | D13: Computer Science | E13: Operations Res | F13: Statistics
A14: Examples: Computer Science, Mathematics, Operations Research, Statistics | B14: 1 | C14: 4 < yrs < 8 | D14: 138.56 | E14: 137.65 | F14: 134.67 | J14: =AVERAGE(D14:H14) -> 136.96 | K14: =_xlfn.STDEV.S(D14:H14) -> 2.0347236 | L14: =K14/J14 -> 0.014856334
B15: 2 | C15: 8 < yrs < 16 | D15: 167.35 | E15: 180.95 | F15: 156.08 | J15: =AVERAGE(D15:H15) -> 168.12667 | K15: =_xlfn.STDEV.S(D15:H15) -> 12.453178 | L15: =K15/J15 -> 0.074070211
B16: 3 | C16: 16 < yrs < 25 | D16: 211.69 | E16: 220.51 | F16: 179.04 | J16: =AVERAGE(D16:H16) -> 203.74667 | K16: =_xlfn.STDEV.S(D16:H16) -> 21.846341 | L16: =K16/J16 -> 0.10722306
B17: 4 | C17: yrs > 25 | D17: 242.84 | E17: 280.22 | F17: 214.97 | J17: =AVERAGE(D17:H17) -> 246.01 | K17: =_xlfn.STDEV.S(D17:H17) -> 32.740301 | L17: =K17/J17 -> 0.13308524
A19: Program Operation Services | D19: Budget | E19: Training | F19: Finan Mgr | G19: Mgmt Analysis | H19: Prog Mgmt | I19: Tech Writer
A20: Examples: Budget Analysis, Education and Training, Financial Management, International Cooperation, Management and Program Analysis, Program Management, Technical Writing and Editing | B20: 1 | C20: 4 < yrs < 8 | D20: 126.26 | E20: 40.83 | F20: 187.24 | G20: 130.51 | H20: 179.04 | I20: 77.32 | J20: =AVERAGE(D20:I20) -> 123.53333 | K20: =_xlfn.STDEV.S(D20:I20) -> 56.870294 | L20: =K20/J20 -> 0.46036395
B21: 2 | C21: 8 < yrs < 16 | D21: 146.32 | E21: 62.69 | F21: 220.54 | G21: 162.31 | H21: 204.76 | I21: 104.55 | J21: =AVERAGE(D21:I21) -> 150.195 | K21: =_xlfn.STDEV.S(D21:I21) -> 59.712877 | L21: =K21/J21 -> 0.397569
B22: 3 | C22: 16 < yrs < 25 | D22: 164.17 | E22: 95.31 | F22: 281.37 | G22: 206.77 | H22: 220.54 | I22: 131.78 | J22: =AVERAGE(D22:I22) -> 183.32333 | K22: =_xlfn.STDEV.S(D22:I22) -> 66.810011 | L22: =K22/J22 -> 0.36443812
B23: 4 | C23: yrs > 25 | D23: 197.89 | E23: 132.01 | F23: 344.88 | G23: 258.21 | H23: 257.51 | I23: 159.54 | J23: =AVERAGE(D23:I23) -> 225.00667 | K23: =_xlfn.STDEV.S(D23:I23) -> 77.715021 | L23: =K23/J23 -> 0.34538986
A25: Scientific Information Services | D25: Computer Oper | E25: Cart & Photo | F25: Inspector | G25: Software Dev | H25: Scientific Analysis | I25: Web Designer
A26: Examples: Data Collection, Data Processing, Image Analysis, Information Systems, Quality Control Inspection, Scientific Applications Programming, Scientific Systems Analysis, Web Designing | B26: 1 | C26: 4 < yrs < 8 | D26: 52.42 | E26: 109.74 | F26: 32.95 | G26: 116.29 | I26: 85.17 | J26: =AVERAGE(D26:I26) -> 79.314 | K26: =_xlfn.STDEV.S(D26:I26) -> 36.05609 | L26: =K26/J26 -> 0.45459931
B27: 2 | C27: 8 < yrs < 16 | D27: 66.08 | E27: 138.89 | F27: 48.62 | G27: 150.8 | I27: 110.51 | J27: =AVERAGE(D27:I27) -> 102.98 | K27: =_xlfn.STDEV.S(D27:I27) -> 44.580267 | L27: =K27/J27 -> 0.43290219
B28: 3 | C28: 16 < yrs < 25 | D28: 81.77 | E28: 174.34 | F28: 72.6 | G28: 185.47 | I28: 138.47 | J28: =AVERAGE(D28:I28) -> 130.53 | K28: =_xlfn.STDEV.S(D28:I28) -> 51.802958 | L28: =K28/J28 -> 0.3968663
B29: 4 | C29: yrs > 25 | D29: 98.29 | E29: 215.38 | F29: 101.45 | G29: 210.28 | I29: 165.38 | J29: =AVERAGE(D29:I29) -> 158.156 | K29: =_xlfn.STDEV.S(D29:I29) -> 56.663904 | L29: =K29/J29 -> 0.35827856

Sheet Source 4, ProTech Awarded (tbd)
B2: Level | C2: Experience (yrs) | D2: SciTech | E2: GSA Calc | F2: OASIS | G2: Lower Range | H2: Average | I2: Upper Range | J2: ProTech Ceiling | K2: OASIS Ceiling
A3: Scientific Services | G3: Average-centered range -/+ one standard deviation
A4: Examples: Astronomy, Atmospheric Sciences, Chemistry, Climatology, Earth Science, Environmental Science, Geodesy, Geology, Materials Science, Meteorology, Oceanography, Physics, Space Science | B4: 1 | C4: 4 < yrs < 8 | D4: 74.156137 | E4: 109 | G4: =H4-_xlfn.STDEV.S(D4:F4) -> 66.939737 | H4: =AVERAGE(D4:F4) -> 91.578069 | I4: =H4+_xlfn.STDEV.S(D4:F4) -> 116.2164 | J4: 111 | K4: 155.65
B5: 2 | C5: 8 < yrs < 16 | D5: 103.7313 | E5: 146 | G5: =H5-_xlfn.STDEV.S(D5:F5) -> 94.977166 | H5: =AVERAGE(D5:F5) -> 124.86565 | I5: =H5+_xlfn.STDEV.S(D5:F5) -> 154.75413 | J5: 145 | K5: 204.782
B6: 3 | C6: 16 < yrs < 25 | D6: 130.1991 | E6: 188 | G6: =H6-_xlfn.STDEV.S(D6:F6) -> 118.22814 | H6: =AVERAGE(D6:F6) -> 159.09955 | I6: =H6+_xlfn.STDEV.S(D6:F6) -> 199.97096 | J6: 181 | K6: 222.282
B7: 4 | C7: yrs > 25 | D7: 141.39119 | E7: 257 | G7: =H7-_xlfn.STDEV.S(D7:F7) -> 117.44782 | H7: =AVERAGE(D7:F7) -> 199.19559 | I7: =H7+_xlfn.STDEV.S(D7:F7) -> 280.94337 | J7: 228 | K7: 278.592
A9: Engineering Services
A10: Examples: Electrical, Electronic, Chemical, Electronics, Equipment, General, Materials, Mechanical, Systems | B10: 1 | C10: 4 < yrs < 8 | D10: 79.912697 | E10: 111 | G10: =H10-_xlfn.STDEV.S(D10:F10) -> 73.474306 | H10: =AVERAGE(D10:F10) -> 95.456349 | I10: =H10+_xlfn.STDEV.S(D10:F10) -> 117.43839 | J10: 114 | K10: 150.974
B11: 2 | C11: 8 < yrs < 16 | D11: 118.61645 | E11: 138 | G11: =H11-_xlfn.STDEV.S(D11:F11) -> 114.60198 | H11: =AVERAGE(D11:F11) -> 128.30822 | I11: =H11+_xlfn.STDEV.S(D11:F11) -> 142.01447 | J11: 145 | K11: 187.454 | M11: Rates
B12: 3 | C12: 16 < yrs < 25 | D12: 146.5303 | E12: 177 | G12: =H12-_xlfn.STDEV.S(D12:F12) -> 140.21982 | H12: =AVERAGE(D12:F12) -> 161.76515 | I12: =H12+_xlfn.STDEV.S(D12:F12) -> 183.31048 | J12: 181 | K12: 224.64
B13: 4 | C13: yrs > 25 | D13: 159.341 | E13: 189 | G13: =H13-_xlfn.STDEV.S(D13:F13) -> 153.19842 | H13: =AVERAGE(D13:F13) -> 174.1705 | I13: =H13+_xlfn.STDEV.S(D13:F13) -> 195.14258 | J13: 228 | K13: 278.906
A15: Analytical Services
A16: Examples: Computer Science, Mathematics, Operations Research, Statistics | B16: 1 | C16: 4 < yrs < 8 | D16: 73.265136 | E16: 112 | G16: =H16-_xlfn.STDEV.S(D16:F16) -> 65.242883 | H16: =AVERAGE(D16:F16) -> 92.632568 | I16: =H16+_xlfn.STDEV.S(D16:F16) -> 120.02225 | J16: 108 | K16: 136.96
B17: 2 | C17: 8 < yrs < 16 | D17: 108.98966 | E17: 132.66667 | G17: =H17-_xlfn.STDEV.S(D17:F17) -> 104.08599 | H17: =AVERAGE(D17:F17) -> 120.82816 | I17: =H17+_xlfn.STDEV.S(D17:F17) -> 137.57034 | J17: 136 | K17: 168.12667
B18: 3 | C18: 16 < yrs < 25 | D18: 130.18376 | E18: 144 | G18: =H18-_xlfn.STDEV.S(D18:F18) -> 127.32232 | H18: =AVERAGE(D18:F18) -> 137.09188 | I18: =H18+_xlfn.STDEV.S(D18:F18) -> 146.86144 | J18: 169 | K18: 203.74667
B19: 4 | C19: yrs > 25 | D19: 149.44476 | E19: 181 | G19: =H19-_xlfn.STDEV.S(D19:F19) -> 142.90946 | H19: =AVERAGE(D19:F19) -> 165.22238 | I19: =H19+_xlfn.STDEV.S(D19:F19) -> 187.5353 | J19: 218 | K19: 246.01
A21: Program Operation Services
A22: Examples: Budget Analysis, Education and Training, Financial Management, International Cooperation, Management and Program Analysis, Program Management, Technical Writing and Editing | B22: 1 | C22: 4 < yrs < 8 | D22: 44.0325 | E22: 98.166667 | G22: =H22-_xlfn.STDEV.S(D22:F22) -> 32.820947 | H22: =AVERAGE(D22:F22) -> 71.099583 | I22: =H22+_xlfn.STDEV.S(D22:F22) -> 109.37822 | J22: 109 | K22: 123.53333
B23: 2 | C23: 8 < yrs < 16 | D23: 98.014285 | E23: 126.5 | G23: =H23-_xlfn.STDEV.S(D23:F23) -> 92.1147 | H23: =AVERAGE(D23:F23) -> 112.25714 | I23: =H23+_xlfn.STDEV.S(D23:F23) -> 132.39958 | J23: 136 | K23: 150.195
B24: 3 | C24: 16 < yrs < 25 | D24: 143.46252 | E24: 151.33333 | G24: =H24-_xlfn.STDEV.S(D24:F24) -> 141.83242 | H24: =AVERAGE(D24:F24) -> 147.39793 | I24: =H24+_xlfn.STDEV.S(D24:F24) -> 152.96343 | J24: 171 | K24: 183.32333
B25: 4 | C25: yrs > 25 | D25: 156.74265 | E25: 174.66667 | G25: =H25-_xlfn.STDEV.S(D25:F25) -> 153.03047 | H25: =AVERAGE(D25:F25) -> 165.70466 | I25: =H25+_xlfn.STDEV.S(D25:F25) -> 178.37885 | J25: 214 | K25: 225.00667
A27: Scientific Information Services
A28: Examples: Data Collection, Data Processing, Image Analysis, Information Systems, Quality Control Inspection, Scientific Applications Programming, Scientific Systems Analysis, Web Designing | B28: 1 | C28: 4 < yrs < 8 | D28: 55.42018 | E28: 95.4 | G28: =H28-_xlfn.STDEV.S(D28:F28) -> 47.140088 | H28: =AVERAGE(D28:F28) -> 75.41009 | I28: =H28+_xlfn.STDEV.S(D28:F28) -> 103.68009 | J28: 108 | K28: 79.314
B29: 2 | C29: 8 < yrs < 16 | D29: 68.9585 | E29: 111 | G29: =H29-_xlfn.STDEV.S(D29:F29) -> 60.25142 | H29: =AVERAGE(D29:F29) -> 89.97925 | I29: =H29+_xlfn.STDEV.S(D29:F29) -> 119.70708 | J29: 137 | K29: 102.98
B30: 3 | C30: 16 < yrs < 25 | D30: 115.67335 | E30: 131.5 | G30: =H30-_xlfn.STDEV.S(D30:F30) -> 112.39554 | H30: =AVERAGE(D30:F30) -> 123.58667 | I30: =H30+_xlfn.STDEV.S(D30:F30) -> 134.77781 | J30: 167 | K30: 130.53
B31: 4 | C31: yrs > 25 | D31: 128.43894 | G31: =0.93*H31 -> 119.44821 | H31: =AVERAGE(D31:F31) -> 128.43894 | I31: =H31*1.07 -> 137.42967 | J31: 212 | K31: 158.156
A33: Note: Advanced degrees from an accredited institution and/or professional credentials from a recognized entity may be cumulatively tallied and substituted for experience. Masters and associates degrees are equivalent to two years of experience; bachelors and doctoral degrees are equivalent to four years of experience. Requirements for specialized degrees, credentials, and experience will be specified at the task order level.

Sheet Rate Development
E3: Satellite Domain
E5: Labor Categories and Rates
E6: Rev 1.0 - September 2017
B9: Recommended ProTech Satellite Domain labor rates appear on tab "ProTech LCats & Rates", in Column H "Average". Since the rates were averaged from several sources, it is possible to also identify a range of rates, bounded by one sample standard deviation below (Column G) and above (Column I) the average rate. Rates below the Lower Range bounds should be judged unrealistic: Programs are likely to have difficulty filling and/or retaining quality staff at such rates. Rates above the Upper Range bound may in fact be realistic and reasonable. The "ProTech Ceiling" guidance of Column J is an average of awarded ceiling rates. Assessment will need to be conducted on a company-by-company basis. "OASIS Ceiling" rates are generally higher than ProTech ceiling rates and are based on larger samples of wider geographic distribution. Rate uniformity may be an issue to consider. While small rate variations occur between different types of scientists, engineers, and analysts, significant rate variations were identified among categories in the Program Operation Services and Scientific Information Services. Program managers, for instance, generally outearn trainers or technical writers, application developers generally outearn data processors. Accordingly, cost estimate biases may be observed in requirements where, for instance, technical writers or trainers significantly outnumber program, budget and/or financial managers. The bias will not be observed in cases with nearly equal numbers of these labor categories. Columns K and L of tab "Source 3, OASIS Blended" provide analysis of this issue. For initial release 1.0 labor rates for ProTech Satellite Domain labor categories were developed considering three sources. This information is provided for reference, but probably unnecessary for IGCE development or price realism/reasonableness determination. (1) Final-year rates from the SciTech IDIQ, delivered by NESDIS CFO acquisition liaison. Different SciTech and ProTech labor categories and, in some cases, levels, necessitated a mapping and blending of SciTech rates. The mapping is found on tab "Source 1, SciTech Blended." (2) GSA Contract-Awarded Labor Category (CALC) rates -- refer to https://calc.gsa.gov. As with SciTech rates, there was not a ready one-to-one relationship to ProTech labor catgories and levels, so mapping and blending was required. Aspects of the mapping and blending are found in "Source 2, GSA CALC Blended." For any given ProTech labor category, the CALC tool offered many different possible mappings and levels. In general, the mapping based on the largest number of contracts was judged to be the most widely representative and used. Note that several higher levels of labor categories were not found to have suitable mappings and therefore left blank. (3) OASIS IDIQ ceiling rates -- refer to https://portal.fas.gsa.gov (registration as a federal employee required).
