Workbook
Name AcademiaAdministrativeSupportCategories: 'Drop-Down Values'!$B$89:$B$90
Name AcademiaConsultantCategories: 'Drop-Down Values'!$B$86
Name AcademiaLaborGroups: [2]Constants!$A$18:$A$21
Name AcademiaLaborGroups: [3]Constants!$A$21:$A$24
Name AcademiaLaborGroups: [4]Constants!$A$21:$A$24
Name AcademiaLaborGroups: 'Drop-Down Values'!$B$52:$B$55
Name AcademiaProjectManagementCategories: 'Drop-Down Values'!$B$66:$B$69
Name AcademiaResearchCategories: 'Drop-Down Values'!$B$72:$B$83
Name ff.dlrs.Base: 'Project Cost Summary'!$H$89
Name ff.dlrs.Op1: 'Project Cost Summary'!$L$89
Name ff.dlrs.Op2: 'Project Cost Summary'!$P$89
Name ff.dlrs.Op3: 'Project Cost Summary'!$T$89
Name ff.dlrs.Op4: 'Project Cost Summary'!$X$89
Name ff.dlrs.Op5: 'Project Cost Summary'!$AB$89
Name Fifth_Phase_Number: '[5]Project Cover Sheet'!$B$36
Name FilteredNames: OFFSET([1]Empl!$O$7,0,0,COUNTA([1]Empl!$O$7:$O$2500),1)
Name First_Phase_Number: '[6]Project Cover Sheet'!$B$32
Name Fourth_Phase_Number: '[5]Project Cover Sheet'!$B$35
Name GeneralConsultantCategories: 'Drop-Down Values'!$B$138
Name GeneralLaborGroups: [2]Constants!$A$24:$A$29
Name GeneralLaborGroups: [3]Constants!$A$27:$A$32
Name GeneralLaborGroups: [4]Constants!$A$27:$A$32
Name GeneralLaborGroups: 'Drop-Down Values'!$B$58:$B$63
Name GeneralManufacturingCategories: 'Drop-Down Values'!$B$123:$B$134
Name GeneralProjectManagementCategories: 'Drop-Down Values'!$B$99:$B$104
Name GeneralScienceandEngineeringCategories: 'Drop-Down Values'!$B$107:$B$112
Name GeneralSoftwareDevelopmentCategories: 'Drop-Down Values'!$B$115:$B$120
Name GeneralSupportCategories: 'Drop-Down Values'!$B$93:$B$96
Name Indirect.Rate.Table: 'Indirect Rates'!$B$9:$L$16
Name IndirectRateCategories: [2]Constants!$A$109:$A$124
Name IndirectRateCategories: [3]Constants!$A$113:$A$128
Name IndirectRateCategories: [4]Constants!$A$121:$A$138
Name IndirectRateCategories: 'Drop-Down Values'!$B$144:$B$160
Name Labor.Rates.Table: 'Labor Rates'!$C$7:$AV$48
Name Labor_Cats_Sorted_Table: 'Drop-Down Values'!$B$142:$B$172
Name LaborCollection: [2]Constants!$A$12
Name LaborCollection: '[7]Drop-Down Values'!$B$46
Name LaborCollection: [3]Constants!$A$15
Name LaborCollection: [4]Constants!$A$15
Name LaborCollection: 'Drop-Down Values'!$B$46
Name NMGRT: #REF!
Name NMGRT: #REF!
Name NMGRT: #REF!
Name NMGRT: #REF!
Name NoBusinessTypeSelected: [2]Constants!$A$15
Name NoBusinessTypeSelected: [3]Constants!$A$18
Name NoBusinessTypeSelected: [4]Constants!$A$18
Name NoBusinessTypeSelected: 'Drop-Down Values'!$B$49
Name Offeror.Bus.Type: '[2]Proposer Constants'!$A$4
Name Offeror.Bus.Type: '[7]Proposer Acct. Data'!$B$4
Name Offeror.Bus.Type: '[3]Submission Info'!$A$4
Name Offeror.Bus.Type: '[4]Proposer Constants'!$A$4
Name Offeror.Bus.Type: INITIALIZATION!$B$12
Name OfferorBusinessTypes: [2]Constants!$A$5:$A$9
Name OfferorBusinessTypes: '[7]Drop-Down Values'!$B$21:$B$25
Name OfferorBusinessTypes: [3]Constants!$A$8:$A$12
Name OfferorBusinessTypes: [4]Constants!$A$8:$A$12
Name OfferorBusinessTypes: 'Drop-Down Values'!$B$21:$B$25
Name OfferorBusType: INITIALIZATION!$B$12
Name Period1_Label: 'Proposer Acct. Data'!$C$11

Sheet Change Notes
B1: Change Notes for Internal Tracking
B3: Version ID | C3: Tab | D3: Changes from Previous
B4: 1.00.00 | C4: All | D4: Adopted DARPA version 1.06.02 with multiple minor revisions to tailor for TRMC T&E/S&T Program needs

Sheet Drop-Down Values
B1: Drop-Down Values for Lists in Workbook
B3: 1.00.00 | C3: First digit change --> prior functions changes. Second digit change --> new function added. Third digit change --> change in spreadsheet that does not affect functionality
B5: BAA # (not used) - Offeror to complete | D5: Y/N | E5: Equipment Type | H5: PoP
D6: Y | E6: Special Test | H6: N/A
D7: N | E7: Special Tooling | H7: 1
B8: Test Tecchnology Area (TTA) Acronym | E8: General Purpose | H8: 2
B9: AAIT | E9: Plant Equipment | H9: 3
B10: AIST | H10: 4
B11: _C4T | H11: 5
B12: CTT | H12: 6
B13: DET | H13: 7
B14: EWT | H14: 8
B15: HSST | H15: 9
B16: SST | H16: 10
B17: SET | H17: 11
H18: 12
H19: 13
B20: General, I2, Picklist of Offeror Business Types | E20: Cell Range Naming Conventions: | H20: 14
B21: Large Business | E21: ThisIsAName = internal constants such as pick-lists | H21: 15
B22: Small Business | E22: This.Is.a.Name = named ranges holding proposer data | H22: 16
B23: Non-Profit | H23: 17
B24: Academia | H24: 18
B25: Lab/FFRDC | H25: 19
H26: 20
H27: 21
H28: 22
B29: Small Business Size Choices | H29: 23
B30: Not Applicable | H30: 24
B31: 1-100
B32: 101-500
B33: 501-1000
B37: SBIR/STTR Phase Choices
B38: Not Applicable
B39: Phase I
B40: Phase II
B41: Phase III
B43: Below Content is for DARPA database comparative information. Not used for TRMC T&E/S&T. Retained for future reference
B45: Labor Collection based on Offeror Business Type Selection | D45: =CONCATENATE("Offeror.Bus.Type is ",Offeror.Bus.Type) -> Offeror.Bus.Type is
B46: =IF(Offeror.Bus.Type = "", "",IF(Offeror.Bus.Type = "Academia","Academia","General")) | C46: Valid values are Academia or General | E46: Add/Change Labor Collection requires Data Validation code change on Labor Rates tab, and new Labor Group list below.
B48: No Business Type Selected | C48: instructional choice
...

Sheet Summary Check Sum
B1: Check Sum of Project Cost Summary From All Phases Build Up Data (ALL data is from other spreadsheets)
B3: Proposer Fiscal Year Labels: | C3: =Period1_Label -> Proposer FY 1 | D3: =Period2_Label -> Proposer FY 2 | E3: =Period3_Label -> Proposer FY 3 | F3: =Period4_Label -> Proposer FY 4 | G3: =Period5_Label -> Proposer FY 5 | H3: =Period6_Label -> Proposer FY 6
B4: Hours Proposed in Each Fiscal Year: | C4: ='Base (Ph1)'!F48+'O-I (Ph2)'!F48+'O-II (Ph3)'!F48+'O-III (Ph4)'!F48+'O-IV (Ph5)'!F48+'O-V (Ph6)'!F48 -> 0 | D4: ='Base (Ph1)'!O48+'O-I (Ph2)'!O48+'O-II (Ph3)'!O48+'O-III (Ph4)'!O48+'O-IV (Ph5)'!O48+'O-V (Ph6)'!O48 -> 0 | E4: ='Base (Ph1)'!X48+'O-I (Ph2)'!X48+'O-II (Ph3)'!X48+'O-III (Ph4)'!X48+'O-IV (Ph5)'!X48+'O-V (Ph6)'!X48 -> 0 | F4: ='Base (Ph1)'!AG48+'O-I (Ph2)'!AG48+'O-II (Ph3)'!AG48+'O-III (Ph4)'!AG48+'O-IV (Ph5)'!AG48+'O-V (Ph6)'!AG48 -> 0 | G4: ='Base (Ph1)'!AP48+'O-I (Ph2)'!AP48+'O-II (Ph3)'!AP48+'O-III (Ph4)'!AP48+'O-IV (Ph5)'!AP48+'O-V (Ph6)'!AP48 -> 0 | H4: ='Base (Ph1)'!AY48+'O-I (Ph2)'!AY48+'O-II (Ph3)'!AY48+'O-III (Ph4)'!AY48+'O-IV (Ph5)'!AY48+'O-V (Ph6)'!AY48 -> 0
D7: Base | E7: Op1 | F7: Op2 | G7: Op3 | H7: Op4 | I7: Op5 | J7: Row Sum
B8: Total Direct Labor Hours | C8: tdlc.hrs | D8: =INDIRECT(CONCATENATE($C8,".",D$7)) -> 0 | E8: =INDIRECT(CONCATENATE($C8,".",E$7)) -> 0 | F8: =INDIRECT(CONCATENATE($C8,".",F$7)) -> 0 | G8: =INDIRECT(CONCATENATE($C8,".",G$7)) -> 0 | H8: =INDIRECT(CONCATENATE($C8,".",H$7)) -> 0 | I8: =INDIRECT(CONCATENATE($C8,".",I$7)) -> 0 | J8: =SUM(D8:I8) -> 0 | L8: Total Direct Labor Costs
B9: Total Direct Labor Costs | C9: tdlc.dlrs | D9: =INDIRECT(CONCATENATE($C9,".",D$7)) -> 0 | E9: =INDIRECT(CONCATENATE($C9,".",E$7)) -> 0 | F9: =INDIRECT(CONCATENATE($C9,".",F$7)) -> 0 | G9: =INDIRECT(CONCATENATE($C9,".",G$7)) -> 0 | H9: =INDIRECT(CONCATENATE($C9,".",H$7)) -> 0 | I9: =INDIRECT(CONCATENATE($C9,".",I$7)) -> 0 | J9: =SUM(D9:I9) -> 0 | L9: Total Fringe Benefit Costs
B10: Total Fringe Benefit Costs | C10: tfbc.dlrs | D10: =INDIRECT(CONCATENATE($C10,".",D$7)) -> 0 | E10: =INDIRECT(CONCATENATE($C10,".",E$7)) -> 0 | F10: =INDIRECT(CONCATENATE($C10,".",F$7)) -> 0 | G10: =INDIRECT(CONCATENATE($C10,".",G$7)) -> 0 | H10: =INDIRECT(CONCATENATE($C10,".",H$7)) -> 0 | I10: =INDIRECT(CONCATENATE($C10,".",I$7)) -> 0 | J10: =SUM(D10:I10) -> 0 | L10: Total Labor Overhead Costs
B11: Total Labor Overhead Costs | C11: tloc.dlrs | D11: =INDIRECT(CONCATENATE($C11,".",D$7)) -> 0 | E11: =INDIRECT(CONCATENATE($C11,".",E$7)) -> 0 | F11: =INDIRECT(CONCATENATE($C11,".",F$7)) -> 0 | G11: =INDIRECT(CONCATENATE($C11,".",G$7)) -> 0 | H11: =INDIRECT(CONCATENATE($C11,".",H$7)) -> 0 | I11: =INDIRECT(CONCATENATE($C11,".",I$7)) -> 0 | J11: =SUM(D11:I11) -> 0 | L11: Total Subcontract Costs
B12: Total Subcontract Costs | C12: tsc.dlrs | D12: =INDIRECT(CONCATENATE($C12,".",D$7)) -> 0 | E12: =INDIRECT(CONCATENATE($C12,".",E$7)) -> 0 | F12: =INDIRECT(CONCATENATE($C12,".",F$7)) -> 0 | G12: =INDIRECT(CONCATENATE($C12,".",G$7)) -> 0 | H12: =INDIRECT(CONCATENATE($C12,".",H$7)) -> 0 | I12: =INDIRECT(CONCATENATE($C12,".",I$7)) -> 0 | J12: =SUM(D12:I12) -> 0 | L12: Total Consultant Costs
B13: Total Consultant Costs | C13: tcc.dlrs | D13: =INDIRECT(CONCATENATE($C13,".",D$7)) -> 0 | E13: =INDIRECT(CONCATENATE($C13,".",E$7)) -> 0 | F13: =INDIRECT(CONCATENATE($C13,".",F$7)) -> 0 | G13: =INDIRECT(CONCATENATE($C13,".",G$7)) -> 0 | H13: =INDIRECT(CONCATENATE($C13,".",H$7)) -> 0 | I13: =INDIRECT(CONCATENATE($C13,".",I$7)) -> 0 | J13: =SUM(D13:I13) -> 0 | L13: Total Other Direct Costs
B14: Total Other Direct Costs | C14: todc.dlrs | D14: =INDIRECT(CONCATENATE($C14,".",D$7)) -> 0 | E14: =INDIRECT(CONCATENATE($C14,".",E$7)) -> 0 | F14: =INDIRECT(CONCATENATE($C14,".",F$7)) -> 0 | G14: =INDIRECT(CONCATENATE($C14,".",G$7)) -> 0 | H14: =INDIRECT(CONCATENATE($C14,".",H$7)) -> 0 | I14: =INDIRECT(CONCATENATE($C14,".",I$7)) -> 0 | J14: =SUM(D14:I14) -> 0 | L14: Total Material Handling Costs
B15: Total Material Handling Costs | C15: tmhc.dlrs | D15: =INDIRECT(CONCATENATE($C15,".",D$7)) -> 0 | E15: =INDIRECT(CONCATENATE($C15,".",E$7)) -> 0 | F15: =INDIRECT(CONCATENATE($C15,".",F$7)) -> 0 | G15: =INDIRECT(CONCATENATE($C15,".",G$7)) -> 0 | H15: =INDIRECT(CONCATENATE($C15,".",H$7)) -> 0 | I15: =INDIRECT(CONCATENATE($C15,".",I$7)) -> 0 | J15: =SUM(D15:I15) -> 0 | L15: Subtotal Costs
B16: Subtotal Costs | C16: sc.dlrs | D16: =INDIRECT(CONCATENATE($C16,".",D$7)) -> 0 | E16: =INDIRECT(CONCATENATE($C16,".",E$7)) -> 0 | F16: =INDIRECT(CONCATENATE($C16,".",F$7)) -> 0 | G16: =INDIRECT(CONCATENATE($C16,".",G$7)) -> 0 | H16: =INDIRECT(CONCATENATE($C16,".",H$7)) -> 0 | I16: =INDIRECT(CONCATENATE($C16,".",I$7)) -> 0 | J16: =SUM(D16:I16) -> 0 | L16: Total G&A Costs
B17: Total G&A Costs | C17: tgac.dlrs | D17: =INDIRECT(CONCATENATE($C17,".",D$7)) -> 0 | E17: =INDIRECT(CONCATENATE($C17,".",E$7)) -> 0 | F17: =INDIRECT(CONCATENATE($C17,".",F$7)) -> 0 | G17: =INDIRECT(CONCATENATE($C17,".",G$7)) -> 0 | H17: =INDIRECT(CONCATENATE($C17,".",H$7)) -> 0 | I17: =INDIRECT(CONCATENATE($C17,".",I$7)) -> 0 | J17: =SUM(D17:I17) -> 0 | L17: Subtotal Costs
B18: Total Cost of Money | C18: tcm.dlrs | D18: =INDIRECT(CONCATENATE($C18,".",D$7)) -> 0 | E18: =INDIRECT(CONCATENATE($C18,".",E$7)) -> 0 | F18: =INDIRECT(CONCATENATE($C18,".",F$7)) -> 0 | G18: =INDIRECT(CONCATENATE($C18,".",G$7)) -> 0 | H18: =INDIRECT(CONCATENATE($C18,".",H$7)) -> 0 | I18: =INDIRECT(CONCATENATE($C18,".",I$7)) -> 0 | J18: =SUM(D18:I18) -> 0 | L18: Total Cost of Money
B19: Fixed Fee | C19: ff.dlrs | D19: =INDIRECT(CONCATENATE($C19,".",D$7)) -> 0 | E19: =INDIRECT(CONCATENATE($C19,".",E$7)) -> 0 | F19: =INDIRECT(CONCATENATE($C19,".",F$7)) -> 0 | G19: =INDIRECT(CONCATENATE($C19,".",G$7)) -> 0 | H19: =INDIRECT(CONCATENATE($C19,".",H$7)) -> 0 | I19: =INDIRECT(CONCATENATE($C19,".",I$7)) -> 0 | J19: =SUM(D19:I19) -> 0 | L19: Total Estimated Costs
B20: Total Estimated Costs Plus Fixed Fee | C20: tecpff.dlrs | D20: =INDIRECT(CONCATENATE($C20,".",D$7)) -> 0 | E20: =INDIRECT(CONCATENATE($C20,".",E$7)) -> 0 | F20: =INDIRECT(CONCATENATE($C20,".",F$7)) -> 0 | G20: =INDIRECT(CONCATENATE($C20,".",G$7)) -> 0 | H20: =INDIRECT(CONCATENATE($C20,".",H$7)) -> 0 | I20: =INDIRECT(CONCATENATE($C20,".",I$7)) -> 0 | L20: Fixed Fee (If proposing a CPFF contract) or Profit
B21: Column Totals | D21: =SUM(D9:D15)+SUM(D17:D19) -> 0 | E21: =SUM(E9:E15)+SUM(E17:E19) -> 0 | F21: =SUM(F9:F15)+SUM(F17:F19) -> 0 | G21: =SUM(G9:G15)+SUM(G17:G19) -> 0 | H21: =SUM(H9:H15)+SUM(H17:H19) -> 0 | I21: =SUM(I9:I15)+SUM(I17:I19) -> 0 | J21: =SUM(J9:J15)+SUM(J17:J19) -> 0 | L21: Total Estimated Costs Plus Fixed Fee
E23: Sum of Column Totals ($) | F23: =SUM(D21:I21) -> 0
E24: Sum of Row Totals ($) | F24: =J21 -> 0
E25: COLUMN TOTALS - ROW TOTALS | F25: =F23-F24 -> 0 | G25: This should be $0. If not, research is needed.

Sheet INITIALIZATION
B1: INTRODUCTION / INITIALIZATION
I2: Contract Structure / Project Phasing
C3: Enter requested data in light yellow cells. | I3: Enter Periods of Performance (PoP) for Project
C4: Enter below information for ues throughout workbook: | I4: Contract | J4: Scope | K4: PoP
B5: Proposer Name: | C5: Proposer's Name (Prime or Sub) | E5: CAGE: | F5: Proposer's CAGE | I5: Base | J5: Phase 1 | L5: months
B6: Top Prime Proposer: | C6: Prime Contractor (Fill-in) (if applicable) | E6: CAGE: | F6: Prime's CAGE | I6: O-I | J6: Phase 2 | L6: months
B7: BAA #: | C7: W900KK-22-R-0012 | E7: TTA acronym: | F7: AAIT | G7: (drop-down list) | I7: O-II | J7: Phase 3 | L7: months
B8: Opportunity Notice #: | C8: Identify the topic response document | I8: O-III | J8: Phase 4 | L8: months
C9: Proposer's Internal Proposal ID | I9: O-IV | J9: Phase 5 | L9: months
I10: O-V | J10: Phase 6 | L10: months
B11: This Organization's Business Type: | D11: Small Business Size Estimate: | J11: Total | K11: =SUM(K5:K10) -> 0 | L11: months
C12: (drop-down-list) | D12: Not Applicable | E12: (drop-down-list)
B13: If Small business is chosen, see content to the right.
B15: Workbook Purpose and Proposer Obligations:
B16: The design and format in the attached worksheets assists Government personnel in the expedited review and evaluation of cost proposals concurrently submitted by multiple proposers. Proposers are reminded that the responsibility for providing adequate supporting data and attachments lies solely with them. Further, the proposer must also bear the burden of proof in establishing reasonableness of proposed costs; therefore, it is in the proposer’s best interest to submit a fully supportable and well-prepared cost proposal. The basis and rationale for all proposed costs should be provided as part of the proposal so that Government personnel can place reliance on the information as current, complete and accurate. Further, for procurement contracts, FAR 15.403-4 sets forth those circumstances in which proposers are required to submit certified cost or pricing data. This spreadsheet should be used for all cost proposals, regardless of award instrument: cooperative agreement, contract, or other transaction.
B17: Completion of this cost proposal workbook per above with the Cost Narrative document enables a rapid cost/price analysis and, if your proposal is selected for award, expedited negotiation and award execution.
B18: The contract base and options (or severable major milestones) are referred throughout this document per the Contract Structure/Project Phasing Table in the top right corner of this tab. Successive Options are represented by 'O-I, O-II, O-III, O-IV, O-V). If a Proposer needs more than 6 Phases, use another workbook to address the remaining needs.
B20: Options: Unpriced Options will not be accepted. Any Option that is not fully priced, will not be included in any resulting award.
B22: Before proceeding to completing other tabs, read the 'General Instructions' tab contents for an overview on the use of each tab and workbook tab color-coding legend. If a row, column, or worksheet in this workbook is not needed for your proposal, either ignore it or hide it; do not delete it.
B24: Summary of other Documentation/Documents Required for Award
B25: Certificate of Current Cost/Pricing Data for Prime if Contract > $2,000,000
B26: Certificate of Current Cost/Pricing Data for each Subcontractor > $2,000,000
B27: If small business or non-traditional defense contractor, Certificate of Current Cost/Pricing Data for each Contract/Subcontractor > $7,500,000
C29: Proposed Project Cost Summary by Cost Type | G29: Proposed Project Cost Summary by Phase Execution
C30: (auto-populated from 'Project Cost Summary' tab) | G30: (auto-populated from 'Project Cost Summary' tab)
C31: ='Project Cost Summary'!C48 -> Total Direct Labor Costs | E31: ='Project Cost Summary'!AE48 -> 0 | I31: Base | J31: Phase 1 | K31: ='Project Cost Summary'!H90 -> 0
C32: ='Project Cost Summary'!C51 -> Total Fringe Benefit Costs | E32: ='Project Cost Summary'!AE51 -> 0 | I32: O-I | J32: Phase 2 | K32: ='Project Cost Summary'!L90 -> 0
C33: ='Project Cost Summary'!C54 -> Total Labor Overhead Costs | E33: ='Project Cost Summary'!AE54 -> 0 | I33: O-II | J33: Phase 3 | K33: ='Project Cost Summary'!P90 -> 0
C34: ='Project Cost Summary'!C60 -> Total Subcontract Costs | E34: ='Project Cost Summary'!AE60 -> 0 | I34: O-III | J34: Phase 4 | K34: ='Project Cost Summary'!T90 -> 0
C35: ='Project Cost Summary'!C66 -> Total Consultant Costs | E35: ='Project Cost Summary'!AE66 -> 0 | I35: O-IV | J35: Phase 5 | K35: ='Project Cost Summary'!X90 -> 0
C36: ='Project Cost Summary'!C72 -> Total Other Direct Costs | E36: ='Project Cost Summary'!AE72 -> 0 | I36: O-V | J36: Phase 6 | K36: ='Project Cost Summary'!AB90 -> 0
C37: ='Project Cost Summary'!C76 -> Total Material Handling Costs | E37: ='Project Cost Summary'!AE76 -> 0 | J37: Total | K37: ='Project Cost Summary'!AE90 -> 0
C38: ='Project Cost Summary'!B77 -> Subtotal Costs | E38: ='Project Cost Summary'!AE77 -> 0
C39: ='Project Cost Summary'!C81 -> Total G&A Costs | E39: ='Project Cost Summary'!AE81 -> 0
C40: ='Project Cost Summary'!B82 -> Subtotal Costs | E40: ='Project Cost Summary'!AE82 -> 0
C41: ='Project Cost Summary'!C86 -> Total Cost of Money | E41: ='Project Cost Summary'!AE86 -> 0
C42: ='Project Cost Summary'!B87 -> Total Estimated Costs | E42: ='Project Cost Summary'!AE87 -> 0
C43: ='Project Cost Summary'!C70 -> Travel | D43: (sub-component of ODCs above) | E43: ='Project Cost Summary'!AE70 -> 0
C44: ='Project Cost Summary'!B89 -> Fixed Fee (If proposing a CPFF contract) or Profit | E44: ='Project Cost Summary'!AE89 -> 0
C45: Total Project Fee Percentage: | D45: ='Project Cost Summary'!AD89 -> #DIV/0!
...

Sheet General Instructions
B1: Overview | C1: TRMC T&E/S&T BAA Standardized Cost Proposal Workbook
B3: Revision Number
B4: =SpreadsheetVersionNumber -> 1.00.00 | C4: Overview Instructions and Notes
B6: Tab Colors
B7: INTRODUCTION / INITIALIZATION | C7: Fill out data cells associated with submitter's and PRIME information (if PRIME is not the submtter).
C8: Enter data associated with the applicable BAA #, Opportunity Notice #, TTA acronym, and each phase's period of performance in months.
C9: Identify the proposal ID # (typically specified in the request for proposal/solutions letter from the Contracting Officer).
C10: Enter type organization using drop-down menu. If small business, include additional info when cell is activated.
C11: Read and follow explanatory information about workbook completion process.
C12: Note that the grey cells for Summary of Proposed Cost tables self-complete on this tab (via links from the Project Cost Summary tab).
B14: General Instructions | C14: The PRIME and all subcontractors (per stipulations within) shall complete this workbook to develop the complete cost/pricing elements breakouts of the cost proposal.
C15: These instructions describe how to use this standardized Cost Proposal workbook to prepare an organization's cost proposal. These instructions do not replace or supersede cost proposal instructions given in the solicitation or announcement.
C16: In addition to the instructions provided below, each tab may have additional guidance and instructions on it either at the top or bottom of the tab (or both).
C17: DO NOT DELETE tabs, rows, or columns that exist in this template. This will damage the structure of the workbook. If you don't want to see a tab, row, or column, use the Hide function.
C18: Input your data in the YELLOW highlighted cells only. Existing data in yellow cells, if any, are provided as illustrative examples or instructions. Delete sample data before submission and populate YELLOW cells as needed.
C19: Tab Color-coding Legend: Orange - Introductory/Informational // Green - Requisite set-up information for cost tables // Purple - Cost Tables (requiring proposer input Light purple - 'Flex' Cost tables for use only when directed - and normally hidden) // Sky Blue - Non-labor build-up worksheets for Subcontactors, Consultants, Materials, Equipment, ODCs (each a separate tab) requiring futher input into cost tables // Olive - other Cost/Projected Expenditure tabs (e.g. Project Cost Summary - no data entry required), Project Spend Plan, Cost by Task (used only when directed - and normally hidden)). // Black - Any tabs created by the Proposer for amplification, calculations, or other uses.
C20: Before entering any detailed proposal data, complete the yellow fields on the 'INTRODUCTION / INITILIALIZATION", 'Proposer Acct. Data, Project Direct Labor Description', 'Labor Rates', and 'Indirect Rates' tabs. On these green-colored tabs, the data sets are a prequisite for completion of other tabs.
C21: Data entered into YELLOW highlighted cells will automatically populate other relevant cells within that worksheet and other tabs.
C22: Grey cells have pre-formatted formulas in them to auto-populate data from other tabs and within the same tab. These formulas should not be changed unless there is specific reason to align with the Proposer's business practices. If any changes are made to grey cell formulas or new formulas are created, create a red outline for the cell as shown in cell B2 on this tab. Either use a comments field for the cell to explain the changes, or enter comments in a 'Formula Update Ledger' at the bottom of the same tab. A Proposer must contact the Contracting Officer to obtain a copy of the workbook if any of these cells need to be unlocked.
C23: If you need to add tabs to create datasets to populate in other tabs or for other explanatory purposes, use BLACK for the tab color and include the following below the data sets: tab purpose statement, notes that provide specific explanations of data cells (as used in exising tabs), and/or any other relavent commentary.
C24: The Proposer is encouraged to create checksum tables where Proposer-created data sets must be transferred for entry into Base (Ph1), O-I (Ph2), O-II (Ph3), O-III (Ph4), O-IV (Ph5), O-V (Ph6), tabs (and Flex tabs, if used). Note that Flex tabs are normally hidden due to estimated infrequent use.
C25: DO NOT add rows to worksheets without first understanding guidance in the 'Workbook Change Instructions' tab. Many workbooks need to be selected together when changes are made to keep formulas and links intact across the workbook.
C26: Build-up (Sky Blue) workbooks typically do NOT have automatic data population into the phase cost tables. Recommend creating/using a check-sum table in each build-up tab for the respective data populated in the applicable phase cost tables.
B28: Workbook Change Instructions | C28: This tab provides guidance if you need to modify the workbook by adding rows on any tab,
C29: This tab will discuss conventions that should be used throughout the workbook. Some may be specified for specified worksheets.
B32: Proposer Accounting Data | C32: The information collected in this tab is used throughout the workbook. After entering type business, the Proposer enters their corporate accounting fiscal year (FY) timeframe and designates the preferred name for six consecutive corparate fiscal years. All labor and other cost information is entered in relation to a specific corporate FY per the submitted project schedule. This is done to ensure indirect charges that apply over a specific corporate FY period are correctly applied to the time-phased costs.
C33: The Proposer's Preferred Label for each fiscal year period will appear on the Labor Rates, Indirect Rates, and all Cost Detail tabs.
C34: This workbook provides six proposer fiscal years, which is typically sufficient for TRMC efforts. If you need more fiscal years (or accounting periods), use a second workbook to add the remaining needs -- do not attempt to add fiscal year periods to this workbook.
B36: Indirect Rates | C36: List each indirect category required to complete the cost proposal. Add rows if additional indirect categories are required.
C37: For each proposer fiscal year/accounting period, list each indirect rate your organization uses in this proposal.
C38: You may choose to create links for the Fringe and Overhead rates entered on this tab to the appropriate cells in the 'Labor Rates' tab. There is no pre-set relationship between these tabs.
C39: Note the requirements for justifying proposed rates and what costs they are applied against for verification.
B41: Direct Labor Categories | C41: Note that Column C of this tab is where labor categories are identified and then used heavily throughout the remainder of the workbook. First list each labor category required for the entire project in this workbook to allow other tabs to properly populate.
C42: This tab is also used to provide a basis for the requirement for the use of the labor categories per amplified information discussed below.
C43: Provide narrative description of related qualifications, duties, and responsibilities that each labor category will perform. Also include concrete tasks that relate to overall phase objectives identified in the Technical Proposal and SOW.
C44: Also note that for each project phase, the labor hours are reflected (in formula cells) from the 'Project Cost Summary' tab. This provides an opportunity for technical review of responsibilities and activities proposed with respect to the calculated Level of Effort (LOE) in the phase cost tables.
B46: Phase Cost Tables: Base, O-I, O-II, O-III, O-IV, O-V | C46: Each phase tab provides for inputs over six corporate accounting time periods to allow for rate changes for direct labor charges and changes in indirect rates over time. For instance, an 18-month phase may be timed in execution such that the Contractor’s labor rates may change over three Contractor fiscal years. This allows for labor escalation to be shown plus any planned adjustments to indirect rates over the intended Phase Period of Performance.
C47: Other than the Direct Labor section, the names or labels that appear in column C of the Base, Options, and Project Cost Summary tabs (after row 54) all come from Proposer entrries in Column C of the Base (Ph I) tab. Enter/change ALL names/labels on the Base tab, even if that particular row is not used for the Base phase. All Phase Cost Table tabs (and the Project Cost Summary tab should have the exact same rows. For example, if you have a particular consultant that will only be involved in Option II, enter that consultant’s name on the Base tab but only enter that consultant’s costs on the Option II tab.
C48: Enter the proposed cost detail for the Base and each Option period (as needed) on the tabs entitled, "Base (Ph1)", "O-I (Ph2)", "O-II - (Ph3)", O-III (Ph4)", "O-IV (Ph5)", and "O-V (Ph6)". The tab entitled, "Project Cost Summary" will automatically populate from the Base and Option tabs. Note that the term 'Phase' will be used throughout this document to represent the correlated programmatic execution of Base and Options.
C49: Input labor hours for each labor category (or further named individual) apportioned across the Proposer FY periods. Input costs for other categories.
...

Sheet Workbook Change Instructions
B1: Workbook Change Instructions
B3: • The instructions that follow apply to the tabs/worksheets that are colored green, purple, sky blue, and olive because these tabs are linked together using references and formulas. The sky blue tabs, such as Subcontractor, Consultants, Travel, etc., provide space for cost proposal details, as required. These tabs also contain tables to assimilate costs per the phase an Proposer FY period and a means to track data integrity between the sky blue data and the costs that mus be represented in the Phase Cost Tables tabs.
B6: Phase Cost Tables Tabs (These include project Phases as identified by Base, Options, an Flex tabs)
C7: • Ensure rows exist for all non-labor cost elements (based on content created in the Sky Blue tabs) by adding rows if necessary under the correct category, naming the source and entering the costs in the appropriate cells. Ensure all indirect costs are associated with and are entered in the correct cells in the respective Proposer FY period. Follow procedures below tab if required to add rows for Phase Cost Tables tabs (and other data linked tabs).
C8: • Proposers may add additional specific cost categories (Subcontractors, ODC types, etc.) as needed, but must ensure those new cost categories also track to the Project Cost Summary tabs. Follow the instructions below to add more rows.
B10: Adding Rows
C11: • This workbook is designed to handle the addition of rows. It cannot handle the addition or removal of columns. As you use the workbook, feel free to use the Excel 'Hide' function to hide rows or columns that seem excessive.
C12: • When you add rows to the spreadsheet, it must be done consistently for all related (and linked) worksheets. The instructions below describe how to add rows for the Labor Rates and Cost Detail tabs.
B14: Add Rows to obtain MORE Labor Categories
C15: • Whenever an additional labor category row is needed (in addition to the 40 provided rows), a row must be added to all related worksheets. The worksheets involved are: Direct labor Categories, Labor Rates, Project Cost Summary, and the Base, O-I, O-II, O-III, O-IV, O-V, and Flex worksheets.
B16: Step #
B17: 1 | C17: First, select any one of the involved worksheets above, EXCEPT the Direct Labor Categories tab.
B18: 2 | C18: Holding down the Ctrl key, multi-select all of the other related worksheets tabs. These tabs will remain selected as you execute steps 3 and 4.
B19: 3 | C19: Highlight one or more rows in the Direct Labor section of the active worksheet. Right click on a highlighted row number and choose the Insert function. This will insert one or more rows in all selected worksheets.
B20: 4 | C20: Select the formula-populated row above the newly inserted blank rows. Using your mouse, grab the dark square in the lower left corner of the column A cell. Drag this down to cover all of the just-created blank rows. This will copy all relevant formulas and formats down into the new rows in all selected worksheets.
B21: 5 | C21: DE-SELECT the involved worksheets by clicking any other (not currently selected) worksheet tab.
B22: 6 | C22: The Direct Labor Categories worksheet can have rows copied from the last row below it for the number needed. Follow step 4 above for this tab to ensure all formulas are updated.
B23: 7 | C23: Update both the Direct Labor Categories and Labor Rates tabs with requisite entries.
B25: Add Rows to provide for MORE Other Cost Category elements
C26: • Whenever an additional cost category row is needed (in addition to the several provided rows), a row must be added to all related worksheets. The worksheets involved are: Project Cost Summary, and the Base, O-I, O-II, O-III, O-IV, O-V, and Flex worksheets. No direct labor-focused tabs are involved.
C27: • All common row labels, such as Subcontractor names, Consultant names, and Indirect Rates, are pulled from the labels of the Base worksheet. This means that when you want to add a row for one Option, you need to add rows to all related worksheets. For example, if you want a particular subcontractor to be involved only with Option 1, you need to name that subcontractor on the Base worksheet and leave all dollar amounts as zero for the Base period.
B28: Step #
B29: 1 | C29: First, select any one of the involved worksheets.
B30: 2 | C30: Holding down the Ctrl key, multi-select all of the other related worksheets tabs. These tabs will remain selected as you execute steps 3 and 4.
B31: 3 | C31: Highlight one or more data rows in the relevant section of the active worksheet. Do not highlight a Title row or a Total row. Right click on a highlighted row number and select the Insert function. This will insert one or more rows in all selected worksheets.
B32: 4 | C32: Select the formula-populated row above the newly inserted blank rows. Using your mouse, grab the dark square in the lower left corner of the column A cell. Drag this down to cover all of the just-created blank rows. This will copy all relevant formulas and formats down into the new rows in all selected worksheets.
B33: 5 | C33: DE-SELECT the involved worksheets by clicking any other (not currently selected) worksheet tab.
B34: 6 | C34: Go to the BASE tab and enter labels in column C for the newly inserted cost category rows. Changing the description on the Base worksheet also updates the description on the other worksheets.

Sheet Proposer Acct. Data
B1: Proposer Accounting Data as Constants (used throughout this workbook)
B2: =INITIALIZATION!C5 -> Proposer's Name (Prime or Sub)
B7: Proposer Accounting Periods
B8: Enter the expected date range of each accounting period from the Proposer's perspective. A period change would represent a change in hourly rates or indirect cost rates.
B10: Color-Codes for Sections (see Note 1):
B11: Proposer's Preferred Label (see Note 2): | C11: Proposer FY 1 | D11: Proposer FY 2 | E11: Proposer FY 3 | F11: Proposer FY 4 | G11: Proposer FY 5 | H11: Proposer FY 6
B12: Corp. Fiscal Year Begin Date (see Note 3): | D12: =EDATE(C12,12) -> 366 | E12: =EDATE(D12,12) -> 731 | F12: =EDATE(E12,12) -> 1096 | G12: =EDATE(F12,12) -> 1461 | H12: =EDATE(G12,12) -> 1827
B13: Corp. Fiscal Year End Date (see Note 3): | D13: =EDATE(C13,12) -> 366 | E13: =EDATE(D13,12) -> 731 | F13: =EDATE(E13,12) -> 1096 | G13: =EDATE(F13,12) -> 1461 | H13: =EDATE(G13,12) -> 1827
B15: Note 1 - Throughout the workbook, the Proposer FY periods are consistently color-coded using the colors above.
B16: This is intended to help visually group cost elements in the correct timeframes.
B18: Note 2 - Proposers should set the Period of Performance for the Base and each Option in cell C1 of the corresponding tabs.
B20: Note 3 - A corporate Fiscal Year Begin Date should be one day after the Fiscal Year End Date of the prior fiscal year (or accounting period). Cells will turn red if this condition is not met.

Sheet Direct Labor Categories
B1: Project Direct Labor Description
B2: =INITIALIZATION!C5 -> Proposer's Name (Prime or Sub)
B6: Category # | C6: (Note 1) Labor Category Title | D6: Qualifications | E6: Duties/Responsibilities | F6: (Note 2) Major Tasks: Phase 1 (Base) | G6: Ph1 Hrs | H6: (Note 2) Major Tasks: Phase 2 (O-I) | I6: Ph 2 Hrs | J6: (Note 2) Major Tasks: Phase 3 (O-II) | K6: Ph 3 Hrs | L6: (Note 2) Major Tasks: Phase 4 (O-III) | M6: Ph 4 Hrs | N6: (Note 2) Major Tasks: Phase 5 (O-IV) | O6: Ph 5 Hrs | P6: (Note 2) Major Tasks: Phase 6 (O-V) | Q6: Ph 6 Hrs | R6: (Note 2) Major Tasks: Flex (if used)
B7: Example or Intructions | C7: Sr. Research Engineer | D7: PhD in Physics or Engineering, 7 - 12 years direct technology related experience. | E7: Performs advanced physics computations related to the modeling and simulation of developed systems. | F7: Identify primary tasks performed during this period by this labor grade/person. If specific to an individual, identify name in the task. | G7: From completed 'Base' tab | H7: Identify primary tasks performed during this period by this labor grade/person. If specific to an individual, identify name in the task activity. | I7: From completed 'O-I' tab | J7: Identify primary tasks performed during this period by this labor grade/person. If specific to an individual, identify name in the task activity. | K7: From completed 'O-II' tab | L7: Identify primary tasks performed during this period by this labor grade/person. If specific to an individual, identify name in the task activity. | M7: From completed 'O-III' tab | N7: Identify primary tasks performed during this period by this labor grade/person. If specific to an individual, identify name in the task activity. | O7: From completed 'O-IV' tab | P7: Identify primary tasks performed during this period by this labor grade/person. If specific to an individual, identify name in the task activity. | Q7: From completed 'O-V' tab | R7: NOT INTENDED FOR USE UNLESS SPECIFIED OR REQUESTED ON A CASE BASIS. If used, follow prior guidance.
B8: 1 | G8: ='Base (Ph1)'!BH8 -> 0 | I8: ='O-I (Ph2)'!BH8 -> 0 | K8: ='O-II (Ph3)'!BH8 -> 0 | M8: ='O-III (Ph4)'!BH8 -> 0 | O8: ='O-IV (Ph5)'!BH8 -> 0 | Q8: ='O-V (Ph6)'!BH8 -> 0
B9: 2 | G9: ='Base (Ph1)'!BH9 -> 0 | I9: ='O-I (Ph2)'!BH9 -> 0 | K9: ='O-II (Ph3)'!BH9 -> 0 | M9: ='O-III (Ph4)'!BH9 -> 0 | O9: ='O-IV (Ph5)'!BH9 -> 0 | Q9: ='O-V (Ph6)'!BH9 -> 0
B10: 3 | G10: ='Base (Ph1)'!BH10 -> 0 | I10: ='O-I (Ph2)'!BH10 -> 0 | K10: ='O-II (Ph3)'!BH10 -> 0 | M10: ='O-III (Ph4)'!BH10 -> 0 | O10: ='O-IV (Ph5)'!BH10 -> 0 | Q10: ='O-V (Ph6)'!BH10 -> 0
B11: 4 | G11: ='Base (Ph1)'!BH11 -> 0 | I11: ='O-I (Ph2)'!BH11 -> 0 | K11: ='O-II (Ph3)'!BH11 -> 0 | M11: ='O-III (Ph4)'!BH11 -> 0 | O11: ='O-IV (Ph5)'!BH11 -> 0 | Q11: ='O-V (Ph6)'!BH11 -> 0
B12: 5 | G12: ='Base (Ph1)'!BH12 -> 0 | I12: ='O-I (Ph2)'!BH12 -> 0 | K12: ='O-II (Ph3)'!BH12 -> 0 | M12: ='O-III (Ph4)'!BH12 -> 0 | O12: ='O-IV (Ph5)'!BH12 -> 0 | Q12: ='O-V (Ph6)'!BH12 -> 0
B13: 6 | G13: ='Base (Ph1)'!BH13 -> 0 | I13: ='O-I (Ph2)'!BH13 -> 0 | K13: ='O-II (Ph3)'!BH13 -> 0 | M13: ='O-III (Ph4)'!BH13 -> 0 | O13: ='O-IV (Ph5)'!BH13 -> 0 | Q13: ='O-V (Ph6)'!BH13 -> 0
B14: 7 | G14: ='Base (Ph1)'!BH14 -> 0 | I14: ='O-I (Ph2)'!BH14 -> 0 | K14: ='O-II (Ph3)'!BH14 -> 0 | M14: ='O-III (Ph4)'!BH14 -> 0 | O14: ='O-IV (Ph5)'!BH14 -> 0 | Q14: ='O-V (Ph6)'!BH14 -> 0
B15: 8 | G15: ='Base (Ph1)'!BH15 -> 0 | I15: ='O-I (Ph2)'!BH15 -> 0 | K15: ='O-II (Ph3)'!BH15 -> 0 | M15: ='O-III (Ph4)'!BH15 -> 0 | O15: ='O-IV (Ph5)'!BH15 -> 0 | Q15: ='O-V (Ph6)'!BH15 -> 0
B16: 9 | G16: ='Base (Ph1)'!BH16 -> 0 | I16: ='O-I (Ph2)'!BH16 -> 0 | K16: ='O-II (Ph3)'!BH16 -> 0 | M16: ='O-III (Ph4)'!BH16 -> 0 | O16: ='O-IV (Ph5)'!BH16 -> 0 | Q16: ='O-V (Ph6)'!BH16 -> 0
B17: 10 | G17: ='Base (Ph1)'!BH17 -> 0 | I17: ='O-I (Ph2)'!BH17 -> 0 | K17: ='O-II (Ph3)'!BH17 -> 0 | M17: ='O-III (Ph4)'!BH17 -> 0 | O17: ='O-IV (Ph5)'!BH17 -> 0 | Q17: ='O-V (Ph6)'!BH17 -> 0
B18: 11 | G18: ='Base (Ph1)'!BH18 -> 0 | I18: ='O-I (Ph2)'!BH18 -> 0 | K18: ='O-II (Ph3)'!BH18 -> 0 | M18: ='O-III (Ph4)'!BH18 -> 0 | O18: ='O-IV (Ph5)'!BH18 -> 0 | Q18: ='O-V (Ph6)'!BH18 -> 0
B19: 12 | G19: ='Base (Ph1)'!BH19 -> 0 | I19: ='O-I (Ph2)'!BH19 -> 0 | K19: ='O-II (Ph3)'!BH19 -> 0 | M19: ='O-III (Ph4)'!BH19 -> 0 | O19: ='O-IV (Ph5)'!BH19 -> 0 | Q19: ='O-V (Ph6)'!BH19 -> 0
... B47: 40 | G47: ='Base (Ph1)'!BH47 -> 0 | I47: ='O-I (Ph2)'!BH47 -> 0 | K47: ='O-II (Ph3)'!BH47 -> 0 | M47: ='O-III (Ph4)'!BH47 -> 0 | O47: ='O-IV (Ph5)'!BH47 -> 0 | Q47: ='O-V (Ph6)'!BH47 -> 0
B49: Note 1: | C49: This is the source tab where each Labor Category Title is automatically pasted into Labor Rates, Summary and Phase Tabs for Base (Ph1), O-I (Ph2), O-II (Ph3), O-III (Ph4), O-IV (Ph5), O-V (Ph6), and Flex (if used).
B52: Note 2: | C52: Expound on tasks summary using the Cost Narrative document with cross references to this tab and the applicable cells.

Sheet Indirect Rates
B1: Indirect Rates
B2: =INITIALIZATION!C5 -> Proposer's Name (Prime or Sub)
D8: =Period1_Label -> Proposer FY 1 | E8: =Period2_Label -> Proposer FY 2 | F8: =Period3_Label -> Proposer FY 3 | G8: =Period4_Label -> Proposer FY 4 | H8: =Period5_Label -> Proposer FY 5 | I8: =Period6_Label -> Proposer FY 6 | J8: Basis of Rate (Note 2)
B9: Proposer's Indirect Rate Name | D9: % Rate | E9: % Rate | F9: % Rate | G9: % Rate | H9: % Rate | I9: % Rate | J9: (Example: FPRA, FPRP, Estimate, etc.) | K9: Applied Against
B10: fringe
B11: labor OH
B12: Matl OH
B13: G&A
B17: Insert additional Indirect Rates above this line | D17: Note 1
B20: Instructions: | C20: • If the rates have been approved/negotiated by a Government agency, provide a copy of the memorandum/agreement. • If the rates have not been approved/negotiated, provide sufficient detail to enable a determination of allowability, allocability and reasonableness of the allocation bases and how the rates are calculated. This information can be provided in your cost volume or add another worksheet tab in this spreadsheet to show calculations. • If composite rates are used, provide the calculations used in deriving the composite rates in your cost volume or add another worksheet tab in this spreadsheet to show calculations.
C21: • Rates are shown to six decimal places to support Cost of Money rate assessments.
B22: Hint: | C22: • To expedite workflow, consider linking these rates to the applicable cells in the phase cost build-up tabs for the Base and Options.
B23: Note 1: | C23: Add additional indirect rate category rows, if needed.
B25: Note 2: | C25: If the proposer does not have a Forward Pricing Rate Agreement (FPRA), Forward Pricing Rate Recommendation (FPRR), or provisional billing rates; in order to assist the Government in evaluating the reasonableness of your proposed indirect rates, please provide the following information:
D26: 1. Proforma data used to develop your proposed indirect rates. This consists of breakout of cost pool and cost base that demonstrate how the indirect rate(s) was derived. This information can be provided in your cost volume or add another worksheet tab in this spreadsheet to show calculations
D27: 2. Information regarding your projections for out years, including your assumptions and method for developing these estimates.

Sheet Labor Rates
C1: Labor Rates
C2: =INITIALIZATION!C5 -> Proposer's Name (Prime or Sub) | BO2: SCROLL STOP
C3: This line is blank to help align row numbers on this tab with the rows on the Base and Options tabs
C4: This line is blank to help align row numbers on this tab with the rows on the Base and Options tabs
F5: =Period1_Label -> Proposer FY 1 | M5: =Period2_Label -> Proposer FY 2 | T5: =Period3_Label -> Proposer FY 3 | AA5: =Period4_Label -> Proposer FY 4 | AH5: =Period5_Label -> Proposer FY 5 | AO5: =Period6_Label -> Proposer FY 6 | AU5: Basis of Labor Rate (Note 1)
C6: Open Text | D6: Open Text | F6: $$$ | H6: % | I6: % | J6: % | K6: Calculated | M6: $$$ | N6: Calculated | O6: % | P6: % | Q6: % | R6: Calculated | T6: $$$ | U6: Calculated | V6: % | W6: % | X6: % | Y6: Calculated | AA6: $$$ | AB6: Calculated | AC6: % | AD6: % | AE6: % | AF6: Calculated | AH6: $$$ | AI6: Calculated | AJ6: % | AK6: % | AL6: % | AM6: Calculated | AO6: $$$ | AP6: Calculated | AQ6: % | AR6: % | AS6: % | AT6: Calculated
C7: Proposer's Labor Category (from Project Direct Labor Descriptions) | D7: Name or Number of People Billing | F7: Hourly Labor Rate | H7: Fringe Benefits Rate | I7: Labor Overhead Rate | J7: =IF(LaborCollection="Academia","F&A Rate","G&A Rate") -> G&A Rate | K7: Fully Loaded Rate | M7: Hourly Labor Rate | N7: Labor Escalation Rate | O7: Fringe Benefits Rate | P7: Labor Overhead Rate | Q7: =IF(LaborCollection="Academia","F&A Rate","G&A Rate") -> G&A Rate | R7: Fully Loaded Rate | T7: Hourly Labor Rate | U7: Labor Escalation Rate | V7: Fringe Benefits Rate | W7: Labor Overhead Rate | X7: =IF(LaborCollection="Academia","F&A Rate","G&A Rate") -> G&A Rate | Y7: Fully Loaded Rate | AA7: Hourly Labor Rate | AB7: Labor Escalation Rate | AC7: Fringe Benefits Rate | AD7: Labor Overhead Rate | AE7: =IF(LaborCollection="Academia","F&A Rate","G&A Rate") -> G&A Rate | AF7: Fully Loaded Rate | AH7: Hourly Labor Rate | AI7: Labor Escalation Rate | AJ7: Fringe Benefits Rate | AK7: Labor Overhead Rate | AL7: =IF(LaborCollection="Academia","F&A Rate","G&A Rate") -> G&A Rate | AM7: Fully Loaded Rate | AO7: Hourly Labor Rate | AP7: Labor Escalation Rate | AQ7: Fringe Benefits Rate | AR7: Labor Overhead Rate | AS7: =IF(LaborCollection="Academia","F&A Rate","G&A Rate") -> G&A Rate | AT7: Fully Loaded Rate | AU7: (Example: FPRA, Individual Payrate, Average for Job Category, etc.)
C8: =IF(ISBLANK('Direct Labor Categories'!C8),"",'Direct Labor Categories'!C8) | K8: =F8*(1+H8)*(1+I8)*(1+J8) -> 0 | N8: =IF(F8=0,"N/A",((M8-F8)/F8)) -> N/A | R8: =M8*(1+O8)*(1+P8)*(1+Q8) -> 0 | U8: =IF(M8=0,"N/A",((T8-M8)/M8)) -> N/A | Y8: =T8*(1+V8)*(1+W8)*(1+X8) -> 0 | AB8: =IF(T8=0,"N/A",((AA8-T8)/T8)) -> N/A | AF8: =AA8*(1+AC8)*(1+AD8)*(1+AE8) -> 0 | AI8: =IF(AA8=0,"N/A",((AH8-AA8)/AA8)) -> N/A | AM8: =AH8*(1+AJ8)*(1+AK8)*(1+AL8) -> 0 | AP8: =IF(AH8=0,"N/A",((AO8-AH8)/AH8)) -> N/A | AT8: =AO8*(1+AQ8)*(1+AR8)*(1+AS8) -> 0
C9: =IF(ISBLANK('Direct Labor Categories'!C9),"",'Direct Labor Categories'!C9) | K9: =F9*(1+H9)*(1+I9)*(1+J9) -> 0 | N9: =IF(F9=0,"N/A",((M9-F9)/F9)) -> N/A | R9: =M9*(1+O9)*(1+P9)*(1+Q9) -> 0 | U9: =IF(M9=0,"N/A",((T9-M9)/M9)) -> N/A | Y9: =T9*(1+V9)*(1+W9)*(1+X9) -> 0 | AB9: =IF(T9=0,"N/A",((AA9-T9)/T9)) -> N/A | AF9: =AA9*(1+AC9)*(1+AD9)*(1+AE9) -> 0 | AI9: =IF(AA9=0,"N/A",((AH9-AA9)/AA9)) -> N/A | AM9: =AH9*(1+AJ9)*(1+AK9)*(1+AL9) -> 0 | AP9: =IF(AH9=0,"N/A",((AO9-AH9)/AH9)) -> N/A | AT9: =AO9*(1+AQ9)*(1+AR9)*(1+AS9) -> 0
C10: =IF(ISBLANK('Direct Labor Categories'!C10),"",'Direct Labor Categories'!C10) | K10: =F10*(1+H10)*(1+I10)*(1+J10) -> 0 | N10: =IF(F10=0,"N/A",((M10-F10)/F10)) -> N/A | R10: =M10*(1+O10)*(1+P10)*(1+Q10) -> 0 | U10: =IF(M10=0,"N/A",((T10-M10)/M10)) -> N/A | Y10: =T10*(1+V10)*(1+W10)*(1+X10) -> 0 | AB10: =IF(T10=0,"N/A",((AA10-T10)/T10)) -> N/A | AF10: =AA10*(1+AC10)*(1+AD10)*(1+AE10) -> 0 | AI10: =IF(AA10=0,"N/A",((AH10-AA10)/AA10)) -> N/A | AM10: =AH10*(1+AJ10)*(1+AK10)*(1+AL10) -> 0 | AP10: =IF(AH10=0,"N/A",((AO10-AH10)/AH10)) -> N/A | AT10: =AO10*(1+AQ10)*(1+AR10)*(1+AS10) -> 0
C11: =IF(ISBLANK('Direct Labor Categories'!C11),"",'Direct Labor Categories'!C11) | K11: =F11*(1+H11)*(1+I11)*(1+J11) -> 0 | N11: =IF(F11=0,"N/A",((M11-F11)/F11)) -> N/A | R11: =M11*(1+O11)*(1+P11)*(1+Q11) -> 0 | U11: =IF(M11=0,"N/A",((T11-M11)/M11)) -> N/A | Y11: =T11*(1+V11)*(1+W11)*(1+X11) -> 0 | AB11: =IF(T11=0,"N/A",((AA11-T11)/T11)) -> N/A | AF11: =AA11*(1+AC11)*(1+AD11)*(1+AE11) -> 0 | AI11: =IF(AA11=0,"N/A",((AH11-AA11)/AA11)) -> N/A | AM11: =AH11*(1+AJ11)*(1+AK11)*(1+AL11) -> 0 | AP11: =IF(AH11=0,"N/A",((AO11-AH11)/AH11)) -> N/A | AT11: =AO11*(1+AQ11)*(1+AR11)*(1+AS11) -> 0
C12: =IF(ISBLANK('Direct Labor Categories'!C12),"",'Direct Labor Categories'!C12) | K12: =F12*(1+H12)*(1+I12)*(1+J12) -> 0 | N12: =IF(F12=0,"N/A",((M12-F12)/F12)) -> N/A | R12: =M12*(1+O12)*(1+P12)*(1+Q12) -> 0 | U12: =IF(M12=0,"N/A",((T12-M12)/M12)) -> N/A | Y12: =T12*(1+V12)*(1+W12)*(1+X12) -> 0 | AB12: =IF(T12=0,"N/A",((AA12-T12)/T12)) -> N/A | AF12: =AA12*(1+AC12)*(1+AD12)*(1+AE12) -> 0 | AI12: =IF(AA12=0,"N/A",((AH12-AA12)/AA12)) -> N/A | AM12: =AH12*(1+AJ12)*(1+AK12)*(1+AL12) -> 0 | AP12: =IF(AH12=0,"N/A",((AO12-AH12)/AH12)) -> N/A | AT12: =AO12*(1+AQ12)*(1+AR12)*(1+AS12) -> 0
C13: =IF(ISBLANK('Direct Labor Categories'!C13),"",'Direct Labor Categories'!C13) | K13: =F13*(1+H13)*(1+I13)*(1+J13) -> 0 | N13: =IF(F13=0,"N/A",((M13-F13)/F13)) -> N/A | R13: =M13*(1+O13)*(1+P13)*(1+Q13) -> 0 | U13: =IF(M13=0,"N/A",((T13-M13)/M13)) -> N/A | Y13: =T13*(1+V13)*(1+W13)*(1+X13) -> 0 | AB13: =IF(T13=0,"N/A",((AA13-T13)/T13)) -> N/A | AF13: =AA13*(1+AC13)*(1+AD13)*(1+AE13) -> 0 | AI13: =IF(AA13=0,"N/A",((AH13-AA13)/AA13)) -> N/A | AM13: =AH13*(1+AJ13)*(1+AK13)*(1+AL13) -> 0 | AP13: =IF(AH13=0,"N/A",((AO13-AH13)/AH13)) -> N/A | AT13: =AO13*(1+AQ13)*(1+AR13)*(1+AS13) -> 0
C14: =IF(ISBLANK('Direct Labor Categories'!C14),"",'Direct Labor Categories'!C14) | K14: =F14*(1+H14)*(1+I14)*(1+J14) -> 0 | N14: =IF(F14=0,"N/A",((M14-F14)/F14)) -> N/A | R14: =M14*(1+O14)*(1+P14)*(1+Q14) -> 0 | U14: =IF(M14=0,"N/A",((T14-M14)/M14)) -> N/A | Y14: =T14*(1+V14)*(1+W14)*(1+X14) -> 0 | AB14: =IF(T14=0,"N/A",((AA14-T14)/T14)) -> N/A | AF14: =AA14*(1+AC14)*(1+AD14)*(1+AE14) -> 0 | AI14: =IF(AA14=0,"N/A",((AH14-AA14)/AA14)) -> N/A | AM14: =AH14*(1+AJ14)*(1+AK14)*(1+AL14) -> 0 | AP14: =IF(AH14=0,"N/A",((AO14-AH14)/AH14)) -> N/A | AT14: =AO14*(1+AQ14)*(1+AR14)*(1+AS14) -> 0
C15: =IF(ISBLANK('Direct Labor Categories'!C15),"",'Direct Labor Categories'!C15) | K15: =F15*(1+H15)*(1+I15)*(1+J15) -> 0 | N15: =IF(F15=0,"N/A",((M15-F15)/F15)) -> N/A | R15: =M15*(1+O15)*(1+P15)*(1+Q15) -> 0 | U15: =IF(M15=0,"N/A",((T15-M15)/M15)) -> N/A | Y15: =T15*(1+V15)*(1+W15)*(1+X15) -> 0 | AB15: =IF(T15=0,"N/A",((AA15-T15)/T15)) -> N/A | AF15: =AA15*(1+AC15)*(1+AD15)*(1+AE15) -> 0 | AI15: =IF(AA15=0,"N/A",((AH15-AA15)/AA15)) -> N/A | AM15: =AH15*(1+AJ15)*(1+AK15)*(1+AL15) -> 0 | AP15: =IF(AH15=0,"N/A",((AO15-AH15)/AH15)) -> N/A | AT15: =AO15*(1+AQ15)*(1+AR15)*(1+AS15) -> 0
C16: =IF(ISBLANK('Direct Labor Categories'!C16),"",'Direct Labor Categories'!C16) | K16: =F16*(1+H16)*(1+I16)*(1+J16) -> 0 | N16: =IF(F16=0,"N/A",((M16-F16)/F16)) -> N/A | R16: =M16*(1+O16)*(1+P16)*(1+Q16) -> 0 | U16: =IF(M16=0,"N/A",((T16-M16)/M16)) -> N/A | Y16: =T16*(1+V16)*(1+W16)*(1+X16) -> 0 | AB16: =IF(T16=0,"N/A",((AA16-T16)/T16)) -> N/A | AF16: =AA16*(1+AC16)*(1+AD16)*(1+AE16) -> 0 | AI16: =IF(AA16=0,"N/A",((AH16-AA16)/AA16)) -> N/A | AM16: =AH16*(1+AJ16)*(1+AK16)*(1+AL16) -> 0 | AP16: =IF(AH16=0,"N/A",((AO16-AH16)/AH16)) -> N/A | AT16: =AO16*(1+AQ16)*(1+AR16)*(1+AS16) -> 0
C17: =IF(ISBLANK('Direct Labor Categories'!C17),"",'Direct Labor Categories'!C17) | K17: =F17*(1+H17)*(1+I17)*(1+J17) -> 0 | N17: =IF(F17=0,"N/A",((M17-F17)/F17)) -> N/A | R17: =M17*(1+O17)*(1+P17)*(1+Q17) -> 0 | U17: =IF(M17=0,"N/A",((T17-M17)/M17)) -> N/A | Y17: =T17*(1+V17)*(1+W17)*(1+X17) -> 0 | AB17: =IF(T17=0,"N/A",((AA17-T17)/T17)) -> N/A | AF17: =AA17*(1+AC17)*(1+AD17)*(1+AE17) -> 0 | AI17: =IF(AA17=0,"N/A",((AH17-AA17)/AA17)) -> N/A | AM17: =AH17*(1+AJ17)*(1+AK17)*(1+AL17) -> 0 | AP17: =IF(AH17=0,"N/A",((AO17-AH17)/AH17)) -> N/A | AT17: =AO17*(1+AQ17)*(1+AR17)*(1+AS17) -> 0
C18: =IF(ISBLANK('Direct Labor Categories'!C18),"",'Direct Labor Categories'!C18) | K18: =F18*(1+H18)*(1+I18)*(1+J18) -> 0 | N18: =IF(F18=0,"N/A",((M18-F18)/F18)) -> N/A | R18: =M18*(1+O18)*(1+P18)*(1+Q18) -> 0 | U18: =IF(M18=0,"N/A",((T18-M18)/M18)) -> N/A | Y18: =T18*(1+V18)*(1+W18)*(1+X18) -> 0 | AB18: =IF(T18=0,"N/A",((AA18-T18)/T18)) -> N/A | AF18: =AA18*(1+AC18)*(1+AD18)*(1+AE18) -> 0 | AI18: =IF(AA18=0,"N/A",((AH18-AA18)/AA18)) -> N/A | AM18: =AH18*(1+AJ18)*(1+AK18)*(1+AL18) -> 0 | AP18: =IF(AH18=0,"N/A",((AO18-AH18)/AH18)) -> N/A | AT18: =AO18*(1+AQ18)*(1+AR18)*(1+AS18) -> 0
C19: =IF(ISBLANK('Direct Labor Categories'!C19),"",'Direct Labor Categories'!C19) | K19: =F19*(1+H19)*(1+I19)*(1+J19) -> 0 | N19: =IF(F19=0,"N/A",((M19-F19)/F19)) -> N/A | R19: =M19*(1+O19)*(1+P19)*(1+Q19) -> 0 | U19: =IF(M19=0,"N/A",((T19-M19)/M19)) -> N/A | Y19: =T19*(1+V19)*(1+W19)*(1+X19) -> 0 | AB19: =IF(T19=0,"N/A",((AA19-T19)/T19)) -> N/A | AF19: =AA19*(1+AC19)*(1+AD19)*(1+AE19) -> 0 | AI19: =IF(AA19=0,"N/A",((AH19-AA19)/AA19)) -> N/A | AM19: =AH19*(1+AJ19)*(1+AK19)*(1+AL19) -> 0 | AP19: =IF(AH19=0,"N/A",((AO19-AH19)/AH19)) -> N/A | AT19: =AO19*(1+AQ19)*(1+AR19)*(1+AS19) -> 0
... C46: =IF(ISBLANK('Direct Labor Categories'!C46),"",'Direct Labor Categories'!C46) | K46: =F46*(1+H46)*(1+I46)*(1+J46) -> 0 | N46: =IF(F46=0,"N/A",((M46-F46)/F46)) -> N/A | R46: =M46*(1+O46)*(1+P46)*(1+Q46) -> 0 | U46: =IF(M46=0,"N/A",((T46-M46)/M46)) -> N/A | Y46: =T46*(1+V46)*(1+W46)*(1+X46) -> 0 | AB46: =IF(T46=0,"N/A",((AA46-T46)/T46)) -> N/A | AF46: =AA46*(1+AC46)*(1+AD46)*(1+AE46) -> 0 | AI46: =IF(AA46=0,"N/A",((AH46-AA46)/AA46)) -> N/A | AM46: =AH46*(1+AJ46)*(1+AK46)*(1+AL46) -> 0 | AP46: =IF(AH46=0,"N/A",((AO46-AH46)/AH46)) -> N/A | AT46: =AO46*(1+AQ46)*(1+AR46)*(1+AS46) -> 0
C47: =IF(ISBLANK('Direct Labor Categories'!C47),"",'Direct Labor Categories'!C47) | F47: 206.66667 | H47: 0.6 | I47: 0.2 | J47: 0.16 | K47: =F47*(1+H47)*(1+I47)*(1+J47) -> 460.288 | N47: =IF(F47=0,"N/A",((M47-F47)/F47)) -> -1 | R47: =M47*(1+O47)*(1+P47)*(1+Q47) -> 0 | U47: =IF(M47=0,"N/A",((T47-M47)/M47)) -> N/A | Y47: =T47*(1+V47)*(1+W47)*(1+X47) -> 0 | AB47: =IF(T47=0,"N/A",((AA47-T47)/T47)) -> N/A | AF47: =AA47*(1+AC47)*(1+AD47)*(1+AE47) -> 0 | AI47: =IF(AA47=0,"N/A",((AH47-AA47)/AA47)) -> N/A | AM47: =AH47*(1+AJ47)*(1+AK47)*(1+AL47) -> 0 | AP47: =IF(AH47=0,"N/A",((AO47-AH47)/AH47)) -> N/A | AT47: =AO47*(1+AQ47)*(1+AR47)*(1+AS47) -> 0
C48: Insert additional Labor Category rows above this line. Also select Base and all Option tabs before inserting new rows. Copy formulas from adjacent rows.
C50: Instructions:
C51: Note 1: | D51: • If the rates have been approved/negotiated by a Government agency, provide a copy of the memorandum/agreement (FPRA/FPRR). • If the rates have not been approved/negotiated, provide sufficient detail to enable a determination of allowability, allocability and reasonableness of the allocation bases and how the rates are calculated. This information can be provided in your cost volume or add another worksheet tab in this spreadsheet to show calculations. • If composite rates are used, provide the calculations used in deriving the composite rates in your cost volume or add another worksheet tab in this spreadsheet to show calculations. • If FPRA is not available, provide back-up documentation for labor rates (e.g., current payroll records)
C79: Scroll Stop

Sheet Project Cost Summary
B1: Project Cost Summary - Total Amount
B2: Proposer | C2: =INITIALIZATION!C5 -> Proposer's Name (Prime or Sub) | AY2: SCROLL STOP
B3: Prime Contractor | C3: =INITIALIZATION!C6 -> Prime Contractor (Fill-in) (if applicable)
G5: BASE | K5: OPTION 1 | O5: OPTION 2 | S5: OPTION 3 | W5: OPTION 4 | AA5: OPTION 5 | AD5: Summary | AE5: & Tot PoP (mo)
B6: Direct Labor (DL) | G6: ='Base (Ph1)'!$D1 -> Enter proposed PoP as "MM/YY to MM/YY" | K6: ='O-I (Ph2)'!$D1 -> Enter proposed PoP as "MM/YY to MM/YY" | O6: ='O-II (Ph3)'!$D1 -> Enter proposed PoP as "MM/YY to MM/YY" | S6: ='O-III (Ph4)'!$D1 -> Enter proposed PoP as "MM/YY to MM/YY" | W6: ='O-IV (Ph5)'!$D1 -> Enter proposed PoP as "MM/YY to MM/YY" | AA6: ='O-V (Ph6)'!$D1 -> Enter proposed PoP as "MM/YY to MM/YY" | AD6: (Note 3) | AE6: =PoP_mos_All -> 0
C7: Proposer's Labor Category (Note 1) | D7: Name (Last, First) | F7: Hours | G7: Rate | H7: Cost | J7: Hours | K7: Rate | L7: Cost | N7: Hours | O7: Rate | P7: Cost | R7: Hours | S7: Rate | T7: Cost | V7: Hours | W7: Rate | X7: Cost | Z7: Hours | AA7: Rate | AB7: Cost | AD7: Total Hours | AE7: Total Cost
C8: =IF(ISBLANK('Labor Rates'!C8),"",'Labor Rates'!C8) | D8: =IF(ISBLANK('Labor Rates'!D8),"",'Labor Rates'!D8) | F8: ='Base (Ph1)'!$BH8 -> 0 | G8: See Base Tab | H8: ='Base (Ph1)'!$BI8 -> 0 | J8: ='O-I (Ph2)'!$BH8 -> 0 | K8: See O-I tab | L8: ='O-I (Ph2)'!$BI8 -> 0 | N8: ='O-II (Ph3)'!$BH8 -> 0 | O8: See O-II tab | P8: ='O-II (Ph3)'!$BI8 -> 0 | R8: ='O-III (Ph4)'!$BH8 -> 0 | S8: See O-III tab | T8: ='O-III (Ph4)'!$BI8 -> 0 | V8: ='O-IV (Ph5)'!$BH8 -> 0 | W8: See O-IV tab | X8: ='O-IV (Ph5)'!$BI8 -> 0 | Z8: ='O-V (Ph6)'!$BH8 -> 0 | AA8: See O-V tab | AB8: ='O-V (Ph6)'!$BI8 -> 0 | AD8: =F8+J8+N8+R8+V8+Z8 -> 0 | AE8: =H8+L8+P8+T8+X8+AB8 -> 0
C9: =IF(ISBLANK('Labor Rates'!C9),"",'Labor Rates'!C9) | D9: =IF(ISBLANK('Labor Rates'!D9),"",'Labor Rates'!D9) | F9: ='Base (Ph1)'!$BH9 -> 0 | G9: See Base Tab | H9: ='Base (Ph1)'!$BI9 -> 0 | J9: ='O-I (Ph2)'!$BH9 -> 0 | K9: See O-I tab | L9: ='O-I (Ph2)'!$BI9 -> 0 | N9: ='O-II (Ph3)'!$BH9 -> 0 | O9: See O-II tab | P9: ='O-II (Ph3)'!$BI9 -> 0 | R9: ='O-III (Ph4)'!$BH9 -> 0 | S9: See O-III tab | T9: ='O-III (Ph4)'!$BI9 -> 0 | V9: ='O-IV (Ph5)'!$BH9 -> 0 | W9: See O-IV tab | X9: ='O-IV (Ph5)'!$BI9 -> 0 | Z9: ='O-V (Ph6)'!$BH9 -> 0 | AA9: See O-V tab | AB9: ='O-V (Ph6)'!$BI9 -> 0 | AD9: =F9+J9+N9+R9+V9+Z9 -> 0 | AE9: =H9+L9+P9+T9+X9+AB9 -> 0
C10: =IF(ISBLANK('Labor Rates'!C10),"",'Labor Rates'!C10) | D10: =IF(ISBLANK('Labor Rates'!D10),"",'Labor Rates'!D10) | F10: ='Base (Ph1)'!$BH10 -> 0 | G10: See Base Tab | H10: ='Base (Ph1)'!$BI10 -> 0 | J10: ='O-I (Ph2)'!$BH10 -> 0 | K10: See O-I tab | L10: ='O-I (Ph2)'!$BI10 -> 0 | N10: ='O-II (Ph3)'!$BH10 -> 0 | O10: See O-II tab | P10: ='O-II (Ph3)'!$BI10 -> 0 | R10: ='O-III (Ph4)'!$BH10 -> 0 | S10: See O-III tab | T10: ='O-III (Ph4)'!$BI10 -> 0 | V10: ='O-IV (Ph5)'!$BH10 -> 0 | W10: See O-IV tab | X10: ='O-IV (Ph5)'!$BI10 -> 0 | Z10: ='O-V (Ph6)'!$BH10 -> 0 | AA10: See O-V tab | AB10: ='O-V (Ph6)'!$BI10 -> 0 | AD10: =F10+J10+N10+R10+V10+Z10 -> 0 | AE10: =H10+L10+P10+T10+X10+AB10 -> 0
C11: =IF(ISBLANK('Labor Rates'!C11),"",'Labor Rates'!C11) | D11: =IF(ISBLANK('Labor Rates'!D11),"",'Labor Rates'!D11) | F11: ='Base (Ph1)'!$BH11 -> 0 | G11: See Base Tab | H11: ='Base (Ph1)'!$BI11 -> 0 | J11: ='O-I (Ph2)'!$BH11 -> 0 | K11: See O-I tab | L11: ='O-I (Ph2)'!$BI11 -> 0 | N11: ='O-II (Ph3)'!$BH11 -> 0 | O11: See O-II tab | P11: ='O-II (Ph3)'!$BI11 -> 0 | R11: ='O-III (Ph4)'!$BH11 -> 0 | S11: See O-III tab | T11: ='O-III (Ph4)'!$BI11 -> 0 | V11: ='O-IV (Ph5)'!$BH11 -> 0 | W11: See O-IV tab | X11: ='O-IV (Ph5)'!$BI11 -> 0 | Z11: ='O-V (Ph6)'!$BH11 -> 0 | AA11: See O-V tab | AB11: ='O-V (Ph6)'!$BI11 -> 0 | AD11: =F11+J11+N11+R11+V11+Z11 -> 0 | AE11: =H11+L11+P11+T11+X11+AB11 -> 0
C12: =IF(ISBLANK('Labor Rates'!C12),"",'Labor Rates'!C12) | D12: =IF(ISBLANK('Labor Rates'!D12),"",'Labor Rates'!D12) | F12: ='Base (Ph1)'!$BH12 -> 0 | G12: See Base Tab | H12: ='Base (Ph1)'!$BI12 -> 0 | J12: ='O-I (Ph2)'!$BH12 -> 0 | K12: See O-I tab | L12: ='O-I (Ph2)'!$BI12 -> 0 | N12: ='O-II (Ph3)'!$BH12 -> 0 | O12: See O-II tab | P12: ='O-II (Ph3)'!$BI12 -> 0 | R12: ='O-III (Ph4)'!$BH12 -> 0 | S12: See O-III tab | T12: ='O-III (Ph4)'!$BI12 -> 0 | V12: ='O-IV (Ph5)'!$BH12 -> 0 | W12: See O-IV tab | X12: ='O-IV (Ph5)'!$BI12 -> 0 | Z12: ='O-V (Ph6)'!$BH12 -> 0 | AA12: See O-V tab | AB12: ='O-V (Ph6)'!$BI12 -> 0 | AD12: =F12+J12+N12+R12+V12+Z12 -> 0 | AE12: =H12+L12+P12+T12+X12+AB12 -> 0
C13: =IF(ISBLANK('Labor Rates'!C13),"",'Labor Rates'!C13) | D13: =IF(ISBLANK('Labor Rates'!D13),"",'Labor Rates'!D13) | F13: ='Base (Ph1)'!$BH13 -> 0 | G13: See Base Tab | H13: ='Base (Ph1)'!$BI13 -> 0 | J13: ='O-I (Ph2)'!$BH13 -> 0 | K13: See O-I tab | L13: ='O-I (Ph2)'!$BI13 -> 0 | N13: ='O-II (Ph3)'!$BH13 -> 0 | O13: See O-II tab | P13: ='O-II (Ph3)'!$BI13 -> 0 | R13: ='O-III (Ph4)'!$BH13 -> 0 | S13: See O-III tab | T13: ='O-III (Ph4)'!$BI13 -> 0 | V13: ='O-IV (Ph5)'!$BH13 -> 0 | W13: See O-IV tab | X13: ='O-IV (Ph5)'!$BI13 -> 0 | Z13: ='O-V (Ph6)'!$BH13 -> 0 | AA13: See O-V tab | AB13: ='O-V (Ph6)'!$BI13 -> 0 | AD13: =F13+J13+N13+R13+V13+Z13 -> 0 | AE13: =H13+L13+P13+T13+X13+AB13 -> 0
C14: =IF(ISBLANK('Labor Rates'!C14),"",'Labor Rates'!C14) | D14: =IF(ISBLANK('Labor Rates'!D14),"",'Labor Rates'!D14) | F14: ='Base (Ph1)'!$BH14 -> 0 | G14: See Base Tab | H14: ='Base (Ph1)'!$BI14 -> 0 | J14: ='O-I (Ph2)'!$BH14 -> 0 | K14: See O-I tab | L14: ='O-I (Ph2)'!$BI14 -> 0 | N14: ='O-II (Ph3)'!$BH14 -> 0 | O14: See O-II tab | P14: ='O-II (Ph3)'!$BI14 -> 0 | R14: ='O-III (Ph4)'!$BH14 -> 0 | S14: See O-III tab | T14: ='O-III (Ph4)'!$BI14 -> 0 | V14: ='O-IV (Ph5)'!$BH14 -> 0 | W14: See O-IV tab | X14: ='O-IV (Ph5)'!$BI14 -> 0 | Z14: ='O-V (Ph6)'!$BH14 -> 0 | AA14: See O-V tab | AB14: ='O-V (Ph6)'!$BI14 -> 0 | AD14: =F14+J14+N14+R14+V14+Z14 -> 0 | AE14: =H14+L14+P14+T14+X14+AB14 -> 0
C15: =IF(ISBLANK('Labor Rates'!C15),"",'Labor Rates'!C15) | D15: =IF(ISBLANK('Labor Rates'!D15),"",'Labor Rates'!D15) | F15: ='Base (Ph1)'!$BH15 -> 0 | G15: See Base Tab | H15: ='Base (Ph1)'!$BI15 -> 0 | J15: ='O-I (Ph2)'!$BH15 -> 0 | K15: See O-I tab | L15: ='O-I (Ph2)'!$BI15 -> 0 | N15: ='O-II (Ph3)'!$BH15 -> 0 | O15: See O-II tab | P15: ='O-II (Ph3)'!$BI15 -> 0 | R15: ='O-III (Ph4)'!$BH15 -> 0 | S15: See O-III tab | T15: ='O-III (Ph4)'!$BI15 -> 0 | V15: ='O-IV (Ph5)'!$BH15 -> 0 | W15: See O-IV tab | X15: ='O-IV (Ph5)'!$BI15 -> 0 | Z15: ='O-V (Ph6)'!$BH15 -> 0 | AA15: See O-V tab | AB15: ='O-V (Ph6)'!$BI15 -> 0 | AD15: =F15+J15+N15+R15+V15+Z15 -> 0 | AE15: =H15+L15+P15+T15+X15+AB15 -> 0
